{"channel":"live_orders_ethusd","interaction_index":752,"natural_form":{"channel":"live_orders_ethusd","order_id":"2044303883104262","order_subtype":5,"order_type":0},"natural_form_sha256":"e9db04b524332cd449d44e1d5f18afcee2a2f72ff591bcda9c29e9c0df07ed04","order_source":"orderbook","orders_submitted":0,"presentation":{"amount":"4.837906","amount_traded":"0","microtimestamp":"1787932602369000","price":"2480.07"},"previous_record_hash":"863f537fb6f0f0d454e0e0a3cbcced00e9b1ccbfe385bd5e4a5926bcd2dc7b73","profit_assessment":null,"record_hash":"10d9c7b6b68979eb244acef0ace1cb3558d9a15fa184d16a94e9c98703ca8c05","recorded_unix_us":1787932602408749,"recorded_utc":"2026-08-28T15:56:42.408749Z","schema_version":"nrrf810.exchange_authored_interactive_closure.v1","source_chain_continuous":true,"source_event":"order_created","source_event_id":"00065a1d-7fa5-83e8-0001-001203000020","source_event_id_unique":true,"source_pre_event_id":"00065a1d-7fa5-83e8-0000-001202000020","translation":"UNFOLD_TO_INF","unfold_event_id":null,"zero_hair":false}
{"channel":"live_orders_btcusd","interaction_index":753,"natural_form":{"channel":"live_orders_btcusd","order_id":"2044303881986057","order_subtype":5,"order_type":0},"natural_form_sha256":"2f332f1405122ce0fa8db088b97bed57b28587c5ddc62219b41c7a97bcd9254f","order_source":"orderbook","orders_submitted":0,"presentation":{"amount":"0.25476924","amount_traded":"0","microtimestamp":"1787932602369000","price":"78502.41"},"previous_record_hash":"10d9c7b6b68979eb244acef0ace1cb3558d9a15fa184d16a94e9c98703ca8c05","profit_assessment":null,"record_hash":"692c25b4ec2fbcf20c1161eea105b86c729f4ed1b6551db23e7ea0a9c077603e","recorded_unix_us":1787932602408779,"recorded_utc":"2026-08-28T15:56:42.408779Z","schema_version":"nrrf810.exchange_authored_interactive_closure.v1","source_chain_continuous":true,"source_event":"order_deleted","source_event_id":"00065a1d-7fa5-83e8-0000-000103000020","source_event_id_unique":true,"source_pre_event_id":"00065a1d-7fa5-8000-0002-000102000020","translation":"FOLD_RETURN_TO_ZERO","unfold_event_id":"00065a1d-7fa1-5598-0002-000103000020","zero_hair":true}
{"channel":"live_orders_btcusd","interaction_index":754,"natural_form":{"channel":"live_orders_btcusd","order_id":"2044303881990146","order_subtype":5,"order_type":0},"natural_form_sha256":"2610f4fee02e36d953729b5589ba33048952c23aa9055eadbeecfc77761cea0e","order_source":"orderbook","orders_submitted":0,"presentation":{"amount":"0.25478772","amount_traded":"0","microtimestamp":"1787932602369000","price":"78496.71"},"previous_record_hash":"692c25b4ec2fbcf20c1161eea105b86c729f4ed1b6551db23e7ea0a9c077603e","profit_assessment":null,"record_hash":"bc8f0280820b86ba38e9f5b429efca3424f62c1a89bc73e79214bf76a7a4f99d","recorded_unix_us":1787932602408804,"recorded_utc":"2026-08-28T15:56:42.408804Z","schema_version":"nrrf810.exchange_authored_interactive_closure.v1","source_chain_continuous":true,"source_event":"order_deleted","source_event_id":"00065a1d-7fa5-83e8-0001-000100000020","source_event_id_unique":true,"source_pre_event_id":"00065a1d-7fa5-83e8-0000-000103000020","translation":"FOLD_RETURN_TO_ZERO","unfold_event_id":"00065a1d-7fa1-5980-0000-000100000020","zero_hair":true}
{"channel":"live_orders_btcusd","interaction_index":755,"natural_form":{"channel":"live_orders_btcusd","order_id":"2044303882002434","order_subtype":5,"order_type":0},"natural_form_sha256":"0aba38903703856ee95da3d52ea0e1b91b1150341e6a6c0992df06148975e9fe","order_source":"orderbook","orders_submitted":0,"presentation":{"amount":"1.27507828","amount_traded":"0","microtimestamp":"1787932602369000","price":"78426.55"},"previous_record_hash":"bc8f0280820b86ba38e9f5b429efca3424f62c1a89bc73e79214bf76a7a4f99d","profit_assessment":null,"record_hash":"d243484dedcf41b4b2bf0fd58a20feb1418495c19541a6884225cf420405918b","recorded_unix_us":1787932602410318,"recorded_utc":"2026-08-28T15:56:42.410318Z","schema_version":"nrrf810.exchange_authored_interactive_closure.v1","source_chain_continuous":true,"source_event":"order_deleted","source_event_id":"00065a1d-7fa5-83e8-0002-000101000020","source_event_id_unique":true,"source_pre_event_id":"00065a1d-7fa5-83e8-0001-000100000020","translation":"FOLD_RETURN_TO_ZERO","unfold_event_id":"00065a1d-7fa1-6538-0000-000101000020","zero_hair":true}
{"channel":"live_orders_btcusd","interaction_index":756,"natural_form":{"channel":"live_orders_btcusd","order_id":"2044303882014723","order_subtype":5,"order_type":0},"natural_form_sha256":"68bbdf263bf5a587d528ddc0f579e00e6b090686b2aac278f54c5e8d30d60d76","order_source":"orderbook","orders_submitted":0,"presentation":{"amount":"1.27541152","amount_traded":"0","microtimestamp":"1787932602370000","price":"78406.06"},"previous_record_hash":"d243484dedcf41b4b2bf0fd58a20feb1418495c19541a6884225cf420405918b","profit_assessment":null,"record_hash":"12a883810d69be24092897c2c19c177818c5618c67bf3655c219c014a5507541","recorded_unix_us":1787932602410346,"recorded_utc":"2026-08-28T15:56:42.410346Z","schema_version":"nrrf810.exchange_authored_interactive_closure.v1","source_chain_continuous":true,"source_event":"order_deleted","source_event_id":"00065a1d-7fa5-87d0-0000-000102000020","source_event_id_unique":true,"source_pre_event_id":"00065a1d-7fa5-83e8-0002-000101000020","translation":"FOLD_RETURN_TO_ZERO","unfold_event_id":"00065a1d-7fa1-70f0-0000-000102000020","zero_hair":true}
{"channel":"live_orders_btcusd","interaction_index":757,"natural_form":{"channel":"live_orders_btcusd","order_id":"2044303882014724","order_subtype":5,"order_type":0},"natural_form_sha256":"9f835f356cc755e2171b3654ddeb84b7575fbde992582357a06361e7e8b223ac","order_source":"orderbook","orders_submitted":0,"presentation":{"amount":"12.76418733","amount_traded":"0","microtimestamp":"1787932602370000","price":"78344.19"},"previous_record_hash":"12a883810d69be24092897c2c19c177818c5618c67bf3655c219c014a5507541","profit_assessment":null,"record_hash":"da051bbce15d445cf1bc6ea479a0e5bccbf2b9ee7d408db0964b4d01e6075385","recorded_unix_us":1787932602410371,"recorded_utc":"2026-08-28T15:56:42.410371Z","schema_version":"nrrf810.exchange_authored_interactive_closure.v1","source_chain_continuous":true,"source_event":"order_deleted","source_event_id":"00065a1d-7fa5-87d0-0001-000103000020","source_event_id_unique":true,"source_pre_event_id":"00065a1d-7fa5-87d0-0000-000102000020","translation":"FOLD_RETURN_TO_ZERO","unfold_event_id":"00065a1d-7fa1-74d8-0000-000103000020","zero_hair":true}
{"channel":"live_orders_btcusd","interaction_index":758,"natural_form":{"channel":"live_orders_btcusd","order_id":"2044303882018821","order_subtype":5,"order_type":0},"natural_form_sha256":"e9dc1c4435ca8e132bf716b76856a415190f60519f1f5ee68b31dfb014dbd68c","order_source":"orderbook","orders_submitted":0,"presentation":{"amount":"1.27567513","amount_traded":"0","microtimestamp":"1787932602370000","price":"78389.86"},"previous_record_hash":"da051bbce15d445cf1bc6ea479a0e5bccbf2b9ee7d408db0964b4d01e6075385","profit_assessment":null,"record_hash":"b4a639de6c28fffb988c455844c8a90159f15823c7f0e8cd7c50a32df0dbc09b","recorded_unix_us":1787932602410523,"recorded_utc":"2026-08-28T15:56:42.410523Z","schema_version":"nrrf810.exchange_authored_interactive_closure.v1","source_chain_continuous":true,"source_event":"order_deleted","source_event_id":"00065a1d-7fa5-87d0-0002-000100000020","source_event_id_unique":true,"source_pre_event_id":"00065a1d-7fa5-87d0-0001-000103000020","translation":"FOLD_RETURN_TO_ZERO","unfold_event_id":"00065a1d-7fa1-78c0-0000-000100000020","zero_hair":true}
{"channel":"live_orders_btcusd","interaction_index":759,"natural_form":{"channel":"live_orders_btcusd","order_id":"2044303882035207","order_subtype":5,"order_type":0},"natural_form_sha256":"6e66bff44df61439df6115460f7b61d767c60d6f4c7e258729bd776f9179ceb4","order_source":"orderbook","orders_submitted":0,"presentation":{"amount":"1.27757154","amount_traded":"0","microtimestamp":"1787932602371000","price":"78273.50"},"previous_record_hash":"b4a639de6c28fffb988c455844c8a90159f15823c7f0e8cd7c50a32df0dbc09b","profit_assessment":null,"record_hash":"700cd7c2cfc9b5af98502d7d747f5b0c2fd9fe19c96437cef0251e976b41c236","recorded_unix_us":1787932602410553,"recorded_utc":"2026-08-28T15:56:42.410553Z","schema_version":"nrrf810.exchange_authored_interactive_closure.v1","source_chain_continuous":true,"source_event":"order_deleted","source_event_id":"00065a1d-7fa5-8bb8-0000-000101000020","source_event_id_unique":true,"source_pre_event_id":"00065a1d-7fa5-87d0-0002-000100000020","translation":"FOLD_RETURN_TO_ZERO","unfold_event_id":"00065a1d-7fa1-8478-0001-000100000020","zero_hair":true}
{"channel":"live_orders_btcusd","interaction_index":760,"natural_form":{"channel":"live_orders_btcusd","order_id":"2044303882096644","order_subtype":5,"order_type":1},"natural_form_sha256":"5d22077be44ef014b9295ed0a015fbcd67c790075fc6d19d98a2cf856573036d","order_source":"orderbook","orders_submitted":0,"presentation":{"amount":"1.27177200","amount_traded":"0","microtimestamp":"1787932602371000","price":"78630.45"},"previous_record_hash":"700cd7c2cfc9b5af98502d7d747f5b0c2fd9fe19c96437cef0251e976b41c236","profit_assessment":null,"record_hash":"6e076feaa24d273a3efec7b38dc9e137d7dbb54fcd8a53bd63ee198890669a22","recorded_unix_us":1787932602410701,"recorded_utc":"2026-08-28T15:56:42.410701Z","schema_version":"nrrf810.exchange_authored_interactive_closure.v1","source_chain_continuous":true,"source_event":"order_deleted","source_event_id":"00065a1d-7fa5-8bb8-0001-000102000020","source_event_id_unique":true,"source_pre_event_id":"00065a1d-7fa5-8bb8-0000-000101000020","translation":"FOLD_RETURN_TO_ZERO","unfold_event_id":"00065a1d-7fa1-c2f8-0000-000101000020","zero_hair":true}
{"channel":"live_orders_btcusd","interaction_index":761,"natural_form":{"channel":"live_orders_btcusd","order_id":"2044303882104841","order_subtype":5,"order_type":0},"natural_form_sha256":"6e28dd2b5311182d4fded92cb2b8132604649a74e8e3071be198f0970b4f9fa7","order_source":"orderbook","orders_submitted":0,"presentation":{"amount":"1.27604867","amount_traded":"0","microtimestamp":"1787932602371000","price":"78366.91"},"previous_record_hash":"6e076feaa24d273a3efec7b38dc9e137d7dbb54fcd8a53bd63ee198890669a22","profit_assessment":null,"record_hash":"48e1e3d76731d5e8becc7ac6dc65d2119860c7893483b25ffabc48c84e1d12e2","recorded_unix_us":1787932602410730,"recorded_utc":"2026-08-28T15:56:42.410730Z","schema_version":"nrrf810.exchange_authored_interactive_closure.v1","source_chain_continuous":true,"source_event":"order_deleted","source_event_id":"00065a1d-7fa5-8bb8-0002-000103000020","source_event_id_unique":true,"source_pre_event_id":"00065a1d-7fa5-8bb8-0001-000102000020","translation":"FOLD_RETURN_TO_ZERO","unfold_event_id":"00065a1d-7fa1-cac8-0000-000100000020","zero_hair":true}
{"channel":"live_orders_btcusd","interaction_index":762,"natural_form":{"channel":"live_orders_btcusd","order_id":"2044303882108933","order_subtype":5,"order_type":1},"natural_form_sha256":"afea37422e778d6590df4b009d5aad1080b9b71e2846588536fc18f213f2b24f","order_source":"orderbook","orders_submitted":0,"presentation":{"amount":"1.26842789","amount_traded":"0","microtimestamp":"1787932602372000","price":"78837.75"},"previous_record_hash":"48e1e3d76731d5e8becc7ac6dc65d2119860c7893483b25ffabc48c84e1d12e2","profit_assessment":null,"record_hash":"a0a9d806bc1c32ee7978a85aec147ea32173a65971b5316d93516eb694bd38e9","recorded_unix_us":1787932602410881,"recorded_utc":"2026-08-28T15:56:42.410881Z","schema_version":"nrrf810.exchange_authored_interactive_closure.v1","source_chain_continuous":true,"source_event":"order_deleted","source_event_id":"00065a1d-7fa5-8fa0-0000-000100000020","source_event_id_unique":true,"source_pre_event_id":"00065a1d-7fa5-8bb8-0002-000103000020","translation":"FOLD_RETURN_TO_ZERO","unfold_event_id":"00065a1d-7fa1-cac8-0001-000101000020","zero_hair":true}
{"channel":"live_orders_btcusd","interaction_index":763,"natural_form":{"channel":"live_orders_btcusd","order_id":"2044303883116554","order_subtype":5,"order_type":1},"natural_form_sha256":"0a5026c619d7f28df2d3c0d273cc13092040891058e47df8ed2087fd79da7629","order_source":"orderbook","orders_submitted":0,"presentation":{"amount":"0.06310787","amount_traded":"0","microtimestamp":"1787932602372000","price":"78520.03"},"previous_record_hash":"a0a9d806bc1c32ee7978a85aec147ea32173a65971b5316d93516eb694bd38e9","profit_assessment":null,"record_hash":"a42dc152c1d60c1cf4d1a1e5ec5f50fbe702e0a577357c7fccab521554edd244","recorded_unix_us":1787932602410911,"recorded_utc":"2026-08-28T15:56:42.410911Z","schema_version":"nrrf810.exchange_authored_interactive_closure.v1","source_chain_continuous":true,"source_event":"order_created","source_event_id":"00065a1d-7fa5-8fa0-0001-000101000020","source_event_id_unique":true,"source_pre_event_id":"00065a1d-7fa5-8fa0-0000-000100000020","translation":"UNFOLD_TO_INF","unfold_event_id":null,"zero_hair":false}
{"channel":"live_orders_btcusd","interaction_index":764,"natural_form":{"channel":"live_orders_btcusd","order_id":"2044303883116554","order_subtype":5,"order_type":1},"natural_form_sha256":"0a5026c619d7f28df2d3c0d273cc13092040891058e47df8ed2087fd79da7629","order_source":"orderbook","orders_submitted":0,"presentation":{"amount":"0.06310787","amount_traded":"0","microtimestamp":"1787932602372000","price":"78520.03"},"previous_record_hash":"a42dc152c1d60c1cf4d1a1e5ec5f50fbe702e0a577357c7fccab521554edd244","profit_assessment":null,"record_hash":"f0e6b3b0506bc84a64394e9809087dcb94c45e9045abcff30b39bfd8ceae871a","recorded_unix_us":1787932602410936,"recorded_utc":"2026-08-28T15:56:42.410936Z","schema_version":"nrrf810.exchange_authored_interactive_closure.v1","source_chain_continuous":true,"source_event":"order_deleted","source_event_id":"00065a1d-7fa5-8fa0-0002-000102000020","source_event_id_unique":true,"source_pre_event_id":"00065a1d-7fa5-8fa0-0001-000101000020","translation":"FOLD_RETURN_TO_ZERO","unfold_event_id":"00065a1d-7fa5-8fa0-0001-000101000020","zero_hair":true}
{"channel":"live_orders_btcusd","interaction_index":765,"natural_form":{"channel":"live_orders_btcusd","order_id":"2044303882113034","order_subtype":5,"order_type":0},"natural_form_sha256":"97e7cfec0547f3be34c957b190ce25886aa58141ea3e57d2688358e76f126520","order_source":"orderbook","orders_submitted":0,"presentation":{"amount":"0.06368171","amount_traded":"0","microtimestamp":"1787932602372000","price":"78515.46"},"previous_record_hash":"f0e6b3b0506bc84a64394e9809087dcb94c45e9045abcff30b39bfd8ceae871a","profit_assessment":null,"record_hash":"b04cb1614a4bd08a2603f90e3499099e93a4c0855d198af2fa4310c1bc11512c","recorded_unix_us":1787932602411090,"recorded_utc":"2026-08-28T15:56:42.411090Z","schema_version":"nrrf810.exchange_authored_interactive_closure.v1","source_chain_continuous":true,"source_event":"order_deleted","source_event_id":"00065a1d-7fa5-8fa0-0003-000103000020","source_event_id_unique":true,"source_pre_event_id":"00065a1d-7fa5-8fa0-0002-000102000020","translation":"FOLD_RETURN_TO_ZERO","unfold_event_id":"00065a1d-7fa1-d298-0000-000103000020","zero_hair":true}
{"channel":"live_orders_btcusd","interaction_index":766,"natural_form":{"channel":"live_orders_btcusd","order_id":"2044303882117122","order_subtype":5,"order_type":0},"natural_form_sha256":"503e79041937b17ba90ab3e6c8fc00d5c0cfadf3b643abfcb1f146055a34eef4","order_source":"orderbook","orders_submitted":0,"presentation":{"amount":"1.27817952","amount_traded":"0","microtimestamp":"1787932602372000","price":"78236.27"},"previous_record_hash":"b04cb1614a4bd08a2603f90e3499099e93a4c0855d198af2fa4310c1bc11512c","profit_assessment":null,"record_hash":"3ca9236481cb0f25ae1d15278050d023d2cc785be4220818513c1447d2834b2e","recorded_unix_us":1787932602411118,"recorded_utc":"2026-08-28T15:56:42.411118Z","schema_version":"nrrf810.exchange_authored_interactive_closure.v1","source_chain_continuous":true,"source_event":"order_deleted","source_event_id":"00065a1d-7fa5-8fa0-0004-000100000020","source_event_id_unique":true,"source_pre_event_id":"00065a1d-7fa5-8fa0-0003-000103000020","translation":"FOLD_RETURN_TO_ZERO","unfold_event_id":"00065a1d-7fa1-d298-0001-000100000020","zero_hair":true}
{"channel":"live_orders_btcusd","interaction_index":767,"natural_form":{"channel":"live_orders_btcusd","order_id":"2044303882178560","order_subtype":5,"order_type":1},"natural_form_sha256":"6e151f0077bae4cca911079b390ac47e1c670caf9cd808f6d5587a30d20334c1","order_source":"orderbook","orders_submitted":0,"presentation":{"amount":"1.27145262","amount_traded":"0","microtimestamp":"1787932602373000","price":"78650.20"},"previous_record_hash":"3ca9236481cb0f25ae1d15278050d023d2cc785be4220818513c1447d2834b2e","profit_assessment":null,"record_hash":"e4c85f1ba51d8afe2e2482b47f6583c368a416ed4f14de7c2d2de29874d18e56","recorded_unix_us":1787932602411241,"recorded_utc":"2026-08-28T15:56:42.411241Z","schema_version":"nrrf810.exchange_authored_interactive_closure.v1","source_chain_continuous":true,"source_event":"order_deleted","source_event_id":"00065a1d-7fa5-9388-0000-000101000020","source_event_id_unique":true,"source_pre_event_id":"00065a1d-7fa5-8fa0-0004-000100000020","translation":"FOLD_RETURN_TO_ZERO","unfold_event_id":"00065a1d-7fa2-0d30-0000-000103000020","zero_hair":true}
{"channel":"live_orders_btcusd","interaction_index":768,"natural_form":{"channel":"live_orders_btcusd","order_id":"2044303882186762","order_subtype":5,"order_type":0},"natural_form_sha256":"d7a4708931494fb7e275f9f5d40755582de7e886c2434a4eaa040e47c7ddbb06","order_source":"orderbook","orders_submitted":0,"presentation":{"amount":"1.27888333","amount_traded":"0","microtimestamp":"1787932602373000","price":"78193.21"},"previous_record_hash":"e4c85f1ba51d8afe2e2482b47f6583c368a416ed4f14de7c2d2de29874d18e56","profit_assessment":null,"record_hash":"9547db917831926946ca974d17eedfc77ba2ef32cb09459fcdaefb80a4160be8","recorded_unix_us":1787932602411271,"recorded_utc":"2026-08-28T15:56:42.411271Z","schema_version":"nrrf810.exchange_authored_interactive_closure.v1","source_chain_continuous":true,"source_event":"order_deleted","source_event_id":"00065a1d-7fa5-9388-0001-000102000020","source_event_id_unique":true,"source_pre_event_id":"00065a1d-7fa5-9388-0000-000101000020","translation":"FOLD_RETURN_TO_ZERO","unfold_event_id":"00065a1d-7fa2-1500-0000-000100000020","zero_hair":true}
{"channel":"live_orders_btcusd","interaction_index":769,"natural_form":{"channel":"live_orders_btcusd","order_id":"2044303883124746","order_subtype":5,"order_type":1},"natural_form_sha256":"6fcc916316de9456b42eb7b2fec9844500d8a1ada726dcde794eb31882f03fe9","order_source":"orderbook","orders_submitted":0,"presentation":{"amount":"0.06310787","amount_traded":"0","microtimestamp":"1787932602374000","price":"78522.39"},"previous_record_hash":"9547db917831926946ca974d17eedfc77ba2ef32cb09459fcdaefb80a4160be8","profit_assessment":null,"record_hash":"d97f74726188db6597c19f8742be0bfc1246ea06561de9018e88174399a76881","recorded_unix_us":1787932602411362,"recorded_utc":"2026-08-28T15:56:42.411362Z","schema_version":"nrrf810.exchange_authored_interactive_closure.v1","source_chain_continuous":true,"source_event":"order_created","source_event_id":"00065a1d-7fa5-9770-0000-000103000020","source_event_id_unique":true,"source_pre_event_id":"00065a1d-7fa5-9388-0001-000102000020","translation":"UNFOLD_TO_INF","unfold_event_id":null,"zero_hair":false}
{"channel":"live_orders_btcusd","interaction_index":770,"natural_form":{"channel":"live_orders_btcusd","order_id":"2044303883124746","order_subtype":5,"order_type":1},"natural_form_sha256":"6fcc916316de9456b42eb7b2fec9844500d8a1ada726dcde794eb31882f03fe9","order_source":"orderbook","orders_submitted":0,"presentation":{"amount":"0.06310787","amount_traded":"0","microtimestamp":"1787932602374000","price":"78522.39"},"previous_record_hash":"d97f74726188db6597c19f8742be0bfc1246ea06561de9018e88174399a76881","profit_assessment":null,"record_hash":"0085eca932b1392ccff224c0aecc9e16340a642d88118a1ba913bc512f04bdad","recorded_unix_us":1787932602411452,"recorded_utc":"2026-08-28T15:56:42.411452Z","schema_version":"nrrf810.exchange_authored_interactive_closure.v1","source_chain_continuous":true,"source_event":"order_deleted","source_event_id":"00065a1d-7fa5-9770-0001-000100000020","source_event_id_unique":true,"source_pre_event_id":"00065a1d-7fa5-9770-0000-000103000020","translation":"FOLD_RETURN_TO_ZERO","unfold_event_id":"00065a1d-7fa5-9770-0000-000103000020","zero_hair":true}
{"channel":"live_orders_btcusd","interaction_index":771,"natural_form":{"channel":"live_orders_btcusd","order_id":"2044303883177995","order_subtype":5,"order_type":0},"natural_form_sha256":"c4fc784e7b583598898eeab145108d90f33f155a8bb975bf2aba32430dbea404","order_source":"orderbook","orders_submitted":0,"presentation":{"amount":"0.00140266","amount_traded":"0","microtimestamp":"1787932602387000","price":"70668.36"},"previous_record_hash":"0085eca932b1392ccff224c0aecc9e16340a642d88118a1ba913bc512f04bdad","profit_assessment":null,"record_hash":"e2cd1e42227278cb26f7c16b1956cba176ef328af9b99a5fa42297bd25cb50d9","recorded_unix_us":1787932602430732,"recorded_utc":"2026-08-28T15:56:42.430732Z","schema_version":"nrrf810.exchange_authored_interactive_closure.v1","source_chain_continuous":true,"source_event":"order_created","source_event_id":"00065a1d-7fa5-ca38-0000-000101000020","source_event_id_unique":true,"source_pre_event_id":"00065a1d-7fa5-9770-0001-000100000020","translation":"UNFOLD_TO_INF","unfold_event_id":null,"zero_hair":false}
{"channel":"live_orders_btcusd","interaction_index":772,"natural_form":{"channel":"live_orders_btcusd","order_id":"2044303883182091","order_subtype":5,"order_type":1},"natural_form_sha256":"1388875d68de7d110f23492603b0902bb025a8c0ef619bf68de372a1ef6805c4","order_source":"orderbook","orders_submitted":0,"presentation":{"amount":"0.10000000","amount_traded":"0","microtimestamp":"1787932602388000","price":"78522.63"},"previous_record_hash":"e2cd1e42227278cb26f7c16b1956cba176ef328af9b99a5fa42297bd25cb50d9","profit_assessment":null,"record_hash":"4dc12acfe060e4d60d61a7565905adbb6eeae2d17e501393d400059927596769","recorded_unix_us":1787932602430822,"recorded_utc":"2026-08-28T15:56:42.430822Z","schema_version":"nrrf810.exchange_authored_interactive_closure.v1","source_chain_continuous":true,"source_event":"order_created","source_event_id":"00065a1d-7fa5-ce20-0000-000102000020","source_event_id_unique":true,"source_pre_event_id":"00065a1d-7fa5-ca38-0000-000101000020","translation":"UNFOLD_TO_INF","unfold_event_id":null,"zero_hair":false}
{"channel":"live_orders_btcusd","interaction_index":773,"natural_form":{"channel":"live_orders_btcusd","order_id":"2044303883182091","order_subtype":5,"order_type":1},"natural_form_sha256":"1388875d68de7d110f23492603b0902bb025a8c0ef619bf68de372a1ef6805c4","order_source":"orderbook","orders_submitted":0,"presentation":{"amount":"0.10000000","amount_traded":"0","microtimestamp":"1787932602388000","price":"78522.63"},"previous_record_hash":"4dc12acfe060e4d60d61a7565905adbb6eeae2d17e501393d400059927596769","profit_assessment":null,"record_hash":"091c36a56691b78c6315f9f75f7390e257c35d31232cbe689c225a27cf64f826","recorded_unix_us":1787932602430914,"recorded_utc":"2026-08-28T15:56:42.430914Z","schema_version":"nrrf810.exchange_authored_interactive_closure.v1","source_chain_continuous":true,"source_event":"order_deleted","source_event_id":"00065a1d-7fa5-ce20-0001-000103000020","source_event_id_unique":true,"source_pre_event_id":"00065a1d-7fa5-ce20-0000-000102000020","translation":"FOLD_RETURN_TO_ZERO","unfold_event_id":"00065a1d-7fa5-ce20-0000-000102000020","zero_hair":true}
{"channel":"live_orders_btcusd","interaction_index":774,"natural_form":{"channel":"live_orders_btcusd","order_id":"2044303882854404","order_subtype":5,"order_type":0},"natural_form_sha256":"867c716673c3e64dbab179a8f5572680b0803755568cbd5545beeac015449c46","order_source":"orderbook","orders_submitted":0,"presentation":{"amount":"0.00140266","amount_traded":"0","microtimestamp":"1787932602398000","price":"70668.36"},"previous_record_hash":"091c36a56691b78c6315f9f75f7390e257c35d31232cbe689c225a27cf64f826","profit_assessment":null,"record_hash":"38e2e57d8415011af313e2ca0e8a160f1c580903157e327c8c7d003a69d4f22d","recorded_unix_us":1787932602448149,"recorded_utc":"2026-08-28T15:56:42.448149Z","schema_version":"nrrf810.exchange_authored_interactive_closure.v1","source_chain_continuous":true,"source_event":"order_deleted","source_event_id":"00065a1d-7fa5-f530-0000-000100000020","source_event_id_unique":true,"source_pre_event_id":"00065a1d-7fa5-ce20-0001-000103000020","translation":"FOLD_RETURN_TO_ZERO","unfold_event_id":"00065a1d-7fa4-91b8-0000-000100000020","zero_hair":true}
{"channel":"live_orders_btcusd","interaction_index":775,"natural_form":{"channel":"live_orders_btcusd","order_id":"2044303883177995","order_subtype":5,"order_type":0},"natural_form_sha256":"c4fc784e7b583598898eeab145108d90f33f155a8bb975bf2aba32430dbea404","order_source":"orderbook","orders_submitted":0,"presentation":{"amount":"0.00140266","amount_traded":"0","microtimestamp":"1787932602398000","price":"70668.36"},"previous_record_hash":"38e2e57d8415011af313e2ca0e8a160f1c580903157e327c8c7d003a69d4f22d","profit_assessment":null,"record_hash":"0958c71bf8a0b1a80a6c6be872458f1c1da328039e643ca7b860118a0c81f503","recorded_unix_us":1787932602484945,"recorded_utc":"2026-08-28T15:56:42.484945Z","schema_version":"nrrf810.exchange_authored_interactive_closure.v1","source_chain_continuous":true,"source_event":"order_deleted","source_event_id":"00065a1d-7fa5-f530-0001-000101000020","source_event_id_unique":true,"source_pre_event_id":"00065a1d-7fa5-f530-0000-000100000020","translation":"FOLD_RETURN_TO_ZERO","unfold_event_id":"00065a1d-7fa5-ca38-0000-000101000020","zero_hair":true}
{"channel":"live_orders_btcusd","interaction_index":776,"natural_form":{"channel":"live_orders_btcusd","order_id":"2044303882530818","order_subtype":5,"order_type":0},"natural_form_sha256":"c25ab10cfadc36c456d1ee6fbfa85ad223d5b1ccdd1caf16442df0f8154fc454","order_source":"orderbook","orders_submitted":0,"presentation":{"amount":"0.00140266","amount_traded":"0","microtimestamp":"1787932602398000","price":"70668.36"},"previous_record_hash":"0958c71bf8a0b1a80a6c6be872458f1c1da328039e643ca7b860118a0c81f503","profit_assessment":null,"record_hash":"e0f9e525decc847a5afb6cca4b1ca7766d11396762d7eaf72d393b08e5d62515","recorded_unix_us":1787932602485157,"recorded_utc":"2026-08-28T15:56:42.485157Z","schema_version":"nrrf810.exchange_authored_interactive_closure.v1","source_chain_continuous":true,"source_event":"order_deleted","source_event_id":"00065a1d-7fa5-f530-0002-000102000020","source_event_id_unique":true,"source_pre_event_id":"00065a1d-7fa5-f530-0001-000101000020","translation":"FOLD_RETURN_TO_ZERO","unfold_event_id":"00065a1d-7fa3-5d20-0000-000100000020","zero_hair":true}
{"channel":"live_orders_ethusd","interaction_index":777,"natural_form":{"channel":"live_orders_ethusd","order_id":"2044303617581071","order_subtype":5,"order_type":0},"natural_form_sha256":"fb3080112c62e51ccc6c04f0efd001900da12693cedba9715d32e2c49f870b3c","order_source":"orderbook","orders_submitted":0,"presentation":{"amount":"0.506200","amount_traded":"0","microtimestamp":"1787932602399000","price":"2476.66"},"previous_record_hash":"e0f9e525decc847a5afb6cca4b1ca7766d11396762d7eaf72d393b08e5d62515","profit_assessment":null,"record_hash":"070995722294f04fa791340df28fa62afc0072859b70f875f08a8408f84f6b73","recorded_unix_us":1787932602485424,"recorded_utc":"2026-08-28T15:56:42.485424Z","schema_version":"nrrf810.exchange_authored_interactive_closure.v1","source_chain_continuous":true,"source_event":"order_deleted","source_event_id":"00065a1d-7fa5-f918-0000-001200000020","source_event_id_unique":true,"source_pre_event_id":"00065a1d-7fa5-83e8-0001-001203000020","translation":"PARTIAL_PRIOR_UNFOLD","unfold_event_id":null,"zero_hair":false}
{"channel":"live_orders_ethusd","interaction_index":778,"natural_form":{"channel":"live_orders_ethusd","order_id":"2044303876309017","order_subtype":5,"order_type":1},"natural_form_sha256":"a8d3bdfb5cc96df83884b39b6cdbc67384dfeabc634e6dbe0c0a5afe4d4445d9","order_source":"orderbook","orders_submitted":0,"presentation":{"amount":"0.506200","amount_traded":"0","microtimestamp":"1787932602400000","price":"2482.58"},"previous_record_hash":"070995722294f04fa791340df28fa62afc0072859b70f875f08a8408f84f6b73","profit_assessment":null,"record_hash":"dd3b7bff73a7ee847b6d4b7ab7ca0976da5159b21bec702e3083cb7d811e3fc9","recorded_unix_us":1787932602485469,"recorded_utc":"2026-08-28T15:56:42.485469Z","schema_version":"nrrf810.exchange_authored_interactive_closure.v1","source_chain_continuous":true,"source_event":"order_deleted","source_event_id":"00065a1d-7fa5-fd00-0000-001201000020","source_event_id_unique":true,"source_pre_event_id":"00065a1d-7fa5-f918-0000-001200000020","translation":"PARTIAL_PRIOR_UNFOLD","unfold_event_id":null,"zero_hair":false}
{"channel":"live_orders_ethbtc","interaction_index":779,"natural_form":{"channel":"live_orders_ethbtc","order_id":"2044303881531399","order_subtype":5,"order_type":1},"natural_form_sha256":"ed4f7ea7c2cc9468d3344c7d970bed8b43da43b46727ad564672bac5a91dedf2","order_source":"orderbook","orders_submitted":0,"presentation":{"amount":"0.60448710","amount_traded":"0","microtimestamp":"1787932602403000","price":"0.03160362"},"previous_record_hash":"dd3b7bff73a7ee847b6d4b7ab7ca0976da5159b21bec702e3083cb7d811e3fc9","profit_assessment":null,"record_hash":"55273a536110bb5ad6b94a2854d504fabba91d1e4ec0a42a45d02670922d0f69","recorded_unix_us":1787932602485556,"recorded_utc":"2026-08-28T15:56:42.485556Z","schema_version":"nrrf810.exchange_authored_interactive_closure.v1","source_chain_continuous":true,"source_event":"order_deleted","source_event_id":"00065a1d-7fa6-08b8-0000-001100000020","source_event_id_unique":true,"source_pre_event_id":"00065a1d-7fa3-a758-0000-001103000020","translation":"FOLD_RETURN_TO_ZERO","unfold_event_id":"00065a1d-7f9f-a7e8-0000-001102000020","zero_hair":true}
{"channel":"live_orders_ethbtc","interaction_index":780,"natural_form":{"channel":"live_orders_ethbtc","order_id":"2044303881543680","order_subtype":5,"order_type":1},"natural_form_sha256":"f1fa93a33e654422c0b6bdd323e5786702af4d2fa5cdd1f62951866b9aac0e1a","order_source":"orderbook","orders_submitted":0,"presentation":{"amount":"1.00736500","amount_traded":"0","microtimestamp":"1787932602403000","price":"0.03160719"},"previous_record_hash":"55273a536110bb5ad6b94a2854d504fabba91d1e4ec0a42a45d02670922d0f69","profit_assessment":null,"record_hash":"96e9106e2207c77c7b6b1a681a460ab07a4673234739d99c6e3311d2a95b2d9e","recorded_unix_us":1787932602485841,"recorded_utc":"2026-08-28T15:56:42.485841Z","schema_version":"nrrf810.exchange_authored_interactive_closure.v1","source_chain_continuous":true,"source_event":"order_deleted","source_event_id":"00065a1d-7fa6-08b8-0001-001101000020","source_event_id_unique":true,"source_pre_event_id":"00065a1d-7fa6-08b8-0000-001100000020","translation":"FOLD_RETURN_TO_ZERO","unfold_event_id":"00065a1d-7f9f-afb8-0000-001103000020","zero_hair":true}
{"channel":"live_orders_ethbtc","interaction_index":781,"natural_form":{"channel":"live_orders_ethbtc","order_id":"2044303881547776","order_subtype":5,"order_type":1},"natural_form_sha256":"cb32e055813a9c6e8a7ff7c9d07ae240edc60d44fb5e161127d7365df67b0b75","order_source":"orderbook","orders_submitted":0,"presentation":{"amount":"2.01406611","amount_traded":"0","microtimestamp":"1787932602403000","price":"0.03161760"},"previous_record_hash":"96e9106e2207c77c7b6b1a681a460ab07a4673234739d99c6e3311d2a95b2d9e","profit_assessment":null,"record_hash":"0a604128de61c9282e2e5977225e40fbbca094d0134b40fde52ba0ffa212872d","recorded_unix_us":1787932602485894,"recorded_utc":"2026-08-28T15:56:42.485894Z","schema_version":"nrrf810.exchange_authored_interactive_closure.v1","source_chain_continuous":true,"source_event":"order_deleted","source_event_id":"00065a1d-7fa6-08b8-0002-001102000020","source_event_id_unique":true,"source_pre_event_id":"00065a1d-7fa6-08b8-0001-001101000020","translation":"FOLD_RETURN_TO_ZERO","unfold_event_id":"00065a1d-7f9f-b3a0-0000-001100000020","zero_hair":true}
{"channel":"live_orders_ethbtc","interaction_index":782,"natural_form":{"channel":"live_orders_ethbtc","order_id":"2044303881560074","order_subtype":5,"order_type":1},"natural_form_sha256":"a5410b368bd5913408c9756dd7789278053739c9b18730216b555b6123071af2","order_source":"orderbook","orders_submitted":0,"presentation":{"amount":"4.02232075","amount_traded":"0","microtimestamp":"1787932602404000","price":"0.03165997"},"previous_record_hash":"0a604128de61c9282e2e5977225e40fbbca094d0134b40fde52ba0ffa212872d","profit_assessment":null,"record_hash":"f8250ddb850314c501f68b07465628ac1b6f54c5554984b9af090286c6ea7eea","recorded_unix_us":1787932602485924,"recorded_utc":"2026-08-28T15:56:42.485924Z","schema_version":"nrrf810.exchange_authored_interactive_closure.v1","source_chain_continuous":true,"source_event":"order_deleted","source_event_id":"00065a1d-7fa6-0ca0-0000-001103000020","source_event_id_unique":true,"source_pre_event_id":"00065a1d-7fa6-08b8-0002-001102000020","translation":"FOLD_RETURN_TO_ZERO","unfold_event_id":"00065a1d-7f9f-bf58-0000-001101000020","zero_hair":true}
{"channel":"live_orders_ethbtc","interaction_index":783,"natural_form":{"channel":"live_orders_ethbtc","order_id":"2044303881768960","order_subtype":5,"order_type":1},"natural_form_sha256":"0567498f546575dcb1815214c1eec193dbf009c088880b541b6e68518bd0ca0a","order_source":"orderbook","orders_submitted":0,"presentation":{"amount":"3.02055629","amount_traded":"0","microtimestamp":"1787932602404000","price":"0.03162186"},"previous_record_hash":"f8250ddb850314c501f68b07465628ac1b6f54c5554984b9af090286c6ea7eea","profit_assessment":null,"record_hash":"266a6bdf091f28c7120f28468ff0a2c17b5b6c987806c00a04d66a9f24d5c015","recorded_unix_us":1787932602485953,"recorded_utc":"2026-08-28T15:56:42.485953Z","schema_version":"nrrf810.exchange_authored_interactive_closure.v1","source_chain_continuous":true,"source_event":"order_deleted","source_event_id":"00065a1d-7fa6-0ca0-0001-001100000020","source_event_id_unique":true,"source_pre_event_id":"00065a1d-7fa6-0ca0-0000-001103000020","translation":"FOLD_RETURN_TO_ZERO","unfold_event_id":"00065a1d-7fa0-8690-0000-001101000020","zero_hair":true}
{"channel":"live_orders_ethbtc","interaction_index":784,"natural_form":{"channel":"live_orders_ethbtc","order_id":"2044303881768966","order_subtype":5,"order_type":0},"natural_form_sha256":"504bffdafb03463859bd9d6d7e7430d096f826a7b129d9de07056ad7cbb0a95f","order_source":"orderbook","orders_submitted":0,"presentation":{"amount":"0.60475617","amount_traded":"0","microtimestamp":"1787932602404000","price":"0.03158982"},"previous_record_hash":"266a6bdf091f28c7120f28468ff0a2c17b5b6c987806c00a04d66a9f24d5c015","profit_assessment":null,"record_hash":"71fdb864ace1eacc5ccafd62a8f98eae35ad0ed3af202ca6f9453242735e227c","recorded_unix_us":1787932602485980,"recorded_utc":"2026-08-28T15:56:42.485980Z","schema_version":"nrrf810.exchange_authored_interactive_closure.v1","source_chain_continuous":true,"source_event":"order_deleted","source_event_id":"00065a1d-7fa6-0ca0-0002-001101000020","source_event_id_unique":true,"source_pre_event_id":"00065a1d-7fa6-0ca0-0001-001100000020","translation":"FOLD_RETURN_TO_ZERO","unfold_event_id":"00065a1d-7fa0-8a78-0000-001103000020","zero_hair":true}
{"channel":"live_orders_ethbtc","interaction_index":785,"natural_form":{"channel":"live_orders_ethbtc","order_id":"2044303881773058","order_subtype":5,"order_type":0},"natural_form_sha256":"f04c16aad04bcfe62b9d16224dcd3645fb70a7f6cf8c25060d2f0259976a2f70","order_source":"orderbook","orders_submitted":0,"presentation":{"amount":"1.00801353","amount_traded":"0","microtimestamp":"1787932602405000","price":"0.03158534"},"previous_record_hash":"71fdb864ace1eacc5ccafd62a8f98eae35ad0ed3af202ca6f9453242735e227c","profit_assessment":null,"record_hash":"5e1584d369033eb54ddb9de0790de3b45cdf86b8af7e51f0e62a394e83d834c0","recorded_unix_us":1787932602486212,"recorded_utc":"2026-08-28T15:56:42.486212Z","schema_version":"nrrf810.exchange_authored_interactive_closure.v1","source_chain_continuous":true,"source_event":"order_deleted","source_event_id":"00065a1d-7fa6-1088-0000-001102000020","source_event_id_unique":true,"source_pre_event_id":"00065a1d-7fa6-0ca0-0002-001101000020","translation":"FOLD_RETURN_TO_ZERO","unfold_event_id":"00065a1d-7fa0-8a78-0001-001100000020","zero_hair":true}
{"channel":"live_orders_ethbtc","interaction_index":786,"natural_form":{"channel":"live_orders_ethbtc","order_id":"2044303881773063","order_subtype":5,"order_type":0},"natural_form_sha256":"6d30619b688f6a64834f5ab92d0785eb7349ec2e25adecf77adecc18c4365b94","order_source":"orderbook","orders_submitted":0,"presentation":{"amount":"2.01629689","amount_traded":"0","microtimestamp":"1787932602405000","price":"0.03157941"},"previous_record_hash":"5e1584d369033eb54ddb9de0790de3b45cdf86b8af7e51f0e62a394e83d834c0","profit_assessment":null,"record_hash":"84027b13ee9118d74e86bdd6ab3b237d6ef6e793b147ff90efc631abadc55c3f","recorded_unix_us":1787932602486265,"recorded_utc":"2026-08-28T15:56:42.486265Z","schema_version":"nrrf810.exchange_authored_interactive_closure.v1","source_chain_continuous":true,"source_event":"order_deleted","source_event_id":"00065a1d-7fa6-1088-0001-001103000020","source_event_id_unique":true,"source_pre_event_id":"00065a1d-7fa6-1088-0000-001102000020","translation":"FOLD_RETURN_TO_ZERO","unfold_event_id":"00065a1d-7fa0-8a78-0002-001101000020","zero_hair":true}
{"channel":"live_orders_ethbtc","interaction_index":787,"natural_form":{"channel":"live_orders_ethbtc","order_id":"2044303881777153","order_subtype":5,"order_type":0},"natural_form_sha256":"c286a5d44fe1315b9aa97f64ef881b5ed01848e4d506a61dbcc6d4316b6b8510","order_source":"orderbook","orders_submitted":0,"presentation":{"amount":"3.02537254","amount_traded":"0","microtimestamp":"1787932602405000","price":"0.03156999"},"previous_record_hash":"84027b13ee9118d74e86bdd6ab3b237d6ef6e793b147ff90efc631abadc55c3f","profit_assessment":null,"record_hash":"0f1edf8fbf9025aea642d3b7592c39433e52e33f1ddfdf33cb80baeb3f0d4f7b","recorded_unix_us":1787932602486301,"recorded_utc":"2026-08-28T15:56:42.486301Z","schema_version":"nrrf810.exchange_authored_interactive_closure.v1","source_chain_continuous":true,"source_event":"order_deleted","source_event_id":"00065a1d-7fa6-1088-0002-001100000020","source_event_id_unique":true,"source_pre_event_id":"00065a1d-7fa6-1088-0001-001103000020","translation":"FOLD_RETURN_TO_ZERO","unfold_event_id":"00065a1d-7fa0-8e60-0000-001102000020","zero_hair":true}
{"channel":"live_orders_ethbtc","interaction_index":788,"natural_form":{"channel":"live_orders_ethbtc","order_id":"2044303881785349","order_subtype":5,"order_type":0},"natural_form_sha256":"9bbe6ee2927b5db5005105feee7c970f6e67a5e43e9bcc4bbd37a14e1cc42d22","order_source":"orderbook","orders_submitted":0,"presentation":{"amount":"4.03662068","amount_traded":"0","microtimestamp":"1787932602406000","price":"0.03154857"},"previous_record_hash":"0f1edf8fbf9025aea642d3b7592c39433e52e33f1ddfdf33cb80baeb3f0d4f7b","profit_assessment":null,"record_hash":"e5ddb01fd155e70244fcf621dba30a7cfdad68e9597f8eca196c0e3183540368","recorded_unix_us":1787932602486332,"recorded_utc":"2026-08-28T15:56:42.486332Z","schema_version":"nrrf810.exchange_authored_interactive_closure.v1","source_chain_continuous":true,"source_event":"order_deleted","source_event_id":"00065a1d-7fa6-1470-0000-001101000020","source_event_id_unique":true,"source_pre_event_id":"00065a1d-7fa6-1088-0002-001100000020","translation":"FOLD_RETURN_TO_ZERO","unfold_event_id":"00065a1d-7fa0-9a18-0000-001103000020","zero_hair":true}
{"channel":"live_orders_btcusd","interaction_index":789,"natural_form":{"channel":"live_orders_btcusd","order_id":"2044303883259907","order_subtype":5,"order_type":1},"natural_form_sha256":"48c5ed9abd093fa5f9c084de26ebe97cbba9677f4af8b8ad116962a63a5b75f0","order_source":"orderbook","orders_submitted":0,"presentation":{"amount":"0.10000000","amount_traded":"0","microtimestamp":"1787932602406000","price":"78522.62"},"previous_record_hash":"e5ddb01fd155e70244fcf621dba30a7cfdad68e9597f8eca196c0e3183540368","profit_assessment":null,"record_hash":"c388348e009fb2c2c5ec9b973b8fdf74c68a66b764a511bd8f692947b22720bb","recorded_unix_us":1787932602486445,"recorded_utc":"2026-08-28T15:56:42.486445Z","schema_version":"nrrf810.exchange_authored_interactive_closure.v1","source_chain_continuous":true,"source_event":"order_created","source_event_id":"00065a1d-7fa6-1470-0000-000103000020","source_event_id_unique":true,"source_pre_event_id":"00065a1d-7fa5-f530-0002-000102000020","translation":"UNFOLD_TO_INF","unfold_event_id":null,"zero_hair":false}
{"channel":"live_orders_btcusd","interaction_index":790,"natural_form":{"channel":"live_orders_btcusd","order_id":"2044303883259907","order_subtype":5,"order_type":1},"natural_form_sha256":"48c5ed9abd093fa5f9c084de26ebe97cbba9677f4af8b8ad116962a63a5b75f0","order_source":"orderbook","orders_submitted":0,"presentation":{"amount":"0.10000000","amount_traded":"0","microtimestamp":"1787932602406000","price":"78522.62"},"previous_record_hash":"c388348e009fb2c2c5ec9b973b8fdf74c68a66b764a511bd8f692947b22720bb","profit_assessment":null,"record_hash":"dc4c0ed8065beec9facb46dacf2e12e5aff224e75ee619f5e08ec386a09463ee","recorded_unix_us":1787932602486570,"recorded_utc":"2026-08-28T15:56:42.486570Z","schema_version":"nrrf810.exchange_authored_interactive_closure.v1","source_chain_continuous":true,"source_event":"order_deleted","source_event_id":"00065a1d-7fa6-1470-0001-000100000020","source_event_id_unique":true,"source_pre_event_id":"00065a1d-7fa6-1470-0000-000103000020","translation":"FOLD_RETURN_TO_ZERO","unfold_event_id":"00065a1d-7fa6-1470-0000-000103000020","zero_hair":true}
{"channel":"live_orders_btcusd","interaction_index":791,"natural_form":{"channel":"live_orders_btcusd","order_id":"2044303883264008","order_subtype":5,"order_type":1},"natural_form_sha256":"0f88ebf91cbfd6028e451e76ea0d7251ced88c11ebc2927b2bb659b3f68b3027","order_source":"orderbook","orders_submitted":0,"presentation":{"amount":"0.06310787","amount_traded":"0","microtimestamp":"1787932602408000","price":"78520.10"},"previous_record_hash":"dc4c0ed8065beec9facb46dacf2e12e5aff224e75ee619f5e08ec386a09463ee","profit_assessment":null,"record_hash":"06757fc86dee64a9e22e7d87616431a6a1649ee5588ea591970b1442afbde3d2","recorded_unix_us":1787932602486677,"recorded_utc":"2026-08-28T15:56:42.486677Z","schema_version":"nrrf810.exchange_authored_interactive_closure.v1","source_chain_continuous":true,"source_event":"order_created","source_event_id":"00065a1d-7fa6-1c40-0000-000101000020","source_event_id_unique":true,"source_pre_event_id":"00065a1d-7fa6-1470-0001-000100000020","translation":"UNFOLD_TO_INF","unfold_event_id":null,"zero_hair":false}
{"channel":"live_orders_btcusd","interaction_index":792,"natural_form":{"channel":"live_orders_btcusd","order_id":"2044303883264008","order_subtype":5,"order_type":1},"natural_form_sha256":"0f88ebf91cbfd6028e451e76ea0d7251ced88c11ebc2927b2bb659b3f68b3027","order_source":"orderbook","orders_submitted":0,"presentation":{"amount":"0.06310787","amount_traded":"0","microtimestamp":"1787932602408000","price":"78520.10"},"previous_record_hash":"06757fc86dee64a9e22e7d87616431a6a1649ee5588ea591970b1442afbde3d2","profit_assessment":null,"record_hash":"90a2ab45259e9420b9817e26130f6e02f87b90589e93959c8bed22790d54906c","recorded_unix_us":1787932602486775,"recorded_utc":"2026-08-28T15:56:42.486775Z","schema_version":"nrrf810.exchange_authored_interactive_closure.v1","source_chain_continuous":true,"source_event":"order_deleted","source_event_id":"00065a1d-7fa6-1c40-0001-000102000020","source_event_id_unique":true,"source_pre_event_id":"00065a1d-7fa6-1c40-0000-000101000020","translation":"FOLD_RETURN_TO_ZERO","unfold_event_id":"00065a1d-7fa6-1c40-0000-000101000020","zero_hair":true}
{"channel":"live_orders_btcusd","interaction_index":793,"natural_form":{"channel":"live_orders_btcusd","order_id":"2044303883268098","order_subtype":5,"order_type":1},"natural_form_sha256":"b8953e33d22856cc1cf7c3e282df95fb1cf2136cab90587de3381e0a65c7ae85","order_source":"orderbook","orders_submitted":0,"presentation":{"amount":"0.06310787","amount_traded":"0","microtimestamp":"1787932602408000","price":"78522.46"},"previous_record_hash":"90a2ab45259e9420b9817e26130f6e02f87b90589e93959c8bed22790d54906c","profit_assessment":null,"record_hash":"ea56fc2d2929079f6d75cc3585babbb5199335121c1bf4616ebd2d7e1a81bcc6","recorded_unix_us":1787932602486866,"recorded_utc":"2026-08-28T15:56:42.486866Z","schema_version":"nrrf810.exchange_authored_interactive_closure.v1","source_chain_continuous":true,"source_event":"order_created","source_event_id":"00065a1d-7fa6-1c40-0002-000103000020","source_event_id_unique":true,"source_pre_event_id":"00065a1d-7fa6-1c40-0001-000102000020","translation":"UNFOLD_TO_INF","unfold_event_id":null,"zero_hair":false}
{"channel":"live_orders_btcusd","interaction_index":794,"natural_form":{"channel":"live_orders_btcusd","order_id":"2044303883268098","order_subtype":5,"order_type":1},"natural_form_sha256":"b8953e33d22856cc1cf7c3e282df95fb1cf2136cab90587de3381e0a65c7ae85","order_source":"orderbook","orders_submitted":0,"presentation":{"amount":"0.06310787","amount_traded":"0","microtimestamp":"1787932602408000","price":"78522.46"},"previous_record_hash":"ea56fc2d2929079f6d75cc3585babbb5199335121c1bf4616ebd2d7e1a81bcc6","profit_assessment":null,"record_hash":"caff4d67459310c4900eb400d1799f663994d616857226ff6209ba005a3bf2b7","recorded_unix_us":1787932602486951,"recorded_utc":"2026-08-28T15:56:42.486951Z","schema_version":"nrrf810.exchange_authored_interactive_closure.v1","source_chain_continuous":true,"source_event":"order_deleted","source_event_id":"00065a1d-7fa6-1c40-0003-000100000020","source_event_id_unique":true,"source_pre_event_id":"00065a1d-7fa6-1c40-0002-000103000020","translation":"FOLD_RETURN_TO_ZERO","unfold_event_id":"00065a1d-7fa6-1c40-0002-000103000020","zero_hair":true}
{"channel":"live_orders_ethusd","interaction_index":795,"natural_form":{"channel":"live_orders_ethusd","order_id":"2044303816470529","order_subtype":5,"order_type":0},"natural_form_sha256":"046a4bc8d17d870d2803b991c917621a292f44191ad0990c147abc3efe36d179","order_source":"orderbook","orders_submitted":0,"presentation":{"amount":"6.985269","amount_traded":"0","microtimestamp":"1787932602415000","price":"2477.88"},"previous_record_hash":"caff4d67459310c4900eb400d1799f663994d616857226ff6209ba005a3bf2b7","profit_assessment":null,"record_hash":"7828c42dc4f95bc7a85dd1ac1c4c480753cda3bc22393d68cca07818f7809081","recorded_unix_us":1787932602487508,"recorded_utc":"2026-08-28T15:56:42.487508Z","schema_version":"nrrf810.exchange_authored_interactive_closure.v1","source_chain_continuous":true,"source_event":"order_deleted","source_event_id":"00065a1d-7fa6-3798-0000-001202000020","source_event_id_unique":true,"source_pre_event_id":"00065a1d-7fa5-fd00-0000-001201000020","translation":"PARTIAL_PRIOR_UNFOLD","unfold_event_id":null,"zero_hair":false}
{"channel":"live_orders_btcusd","interaction_index":796,"natural_form":{"channel":"live_orders_btcusd","order_id":"2044303883321354","order_subtype":5,"order_type":1},"natural_form_sha256":"535d1bcb287991467cf50b49caf9f99bcf8b6a21a21acb8413b5e3ec07f4a0be","order_source":"orderbook","orders_submitted":0,"presentation":{"amount":"0.10000000","amount_traded":"0","microtimestamp":"1787932602422000","price":"78522.63"},"previous_record_hash":"7828c42dc4f95bc7a85dd1ac1c4c480753cda3bc22393d68cca07818f7809081","profit_assessment":null,"record_hash":"53efb7fa92792f3d52f638d19d218522899e9dbff6ac220d2ec98f2e39234a95","recorded_unix_us":1787932602487548,"recorded_utc":"2026-08-28T15:56:42.487548Z","schema_version":"nrrf810.exchange_authored_interactive_closure.v1","source_chain_continuous":true,"source_event":"order_created","source_event_id":"00065a1d-7fa6-52f0-0000-000101000020","source_event_id_unique":true,"source_pre_event_id":"00065a1d-7fa6-1c40-0003-000100000020","translation":"UNFOLD_TO_INF","unfold_event_id":null,"zero_hair":false}
{"channel":"live_orders_btcusd","interaction_index":797,"natural_form":{"channel":"live_orders_btcusd","order_id":"2044303883321354","order_subtype":5,"order_type":1},"natural_form_sha256":"535d1bcb287991467cf50b49caf9f99bcf8b6a21a21acb8413b5e3ec07f4a0be","order_source":"orderbook","orders_submitted":0,"presentation":{"amount":"0.10000000","amount_traded":"0","microtimestamp":"1787932602422000","price":"78522.63"},"previous_record_hash":"53efb7fa92792f3d52f638d19d218522899e9dbff6ac220d2ec98f2e39234a95","profit_assessment":null,"record_hash":"881f2dc121eee4cc0cbb2d1338c62044652b7bb5246639f3a68f5cca5f5c4ed2","recorded_unix_us":1787932602553927,"recorded_utc":"2026-08-28T15:56:42.553927Z","schema_version":"nrrf810.exchange_authored_interactive_closure.v1","source_chain_continuous":true,"source_event":"order_deleted","source_event_id":"00065a1d-7fa6-52f0-0001-000102000020","source_event_id_unique":true,"source_pre_event_id":"00065a1d-7fa6-52f0-0000-000101000020","translation":"FOLD_RETURN_TO_ZERO","unfold_event_id":"00065a1d-7fa6-52f0-0000-000101000020","zero_hair":true}
{"channel":"live_orders_ethusd","interaction_index":798,"natural_form":{"channel":"live_orders_ethusd","order_id":"2044303882899463","order_subtype":5,"order_type":0},"natural_form_sha256":"a67b1a2993780de4b1782b9b07754e69dc1170862318f14ddca5441153471254","order_source":"orderbook","orders_submitted":0,"presentation":{"amount":"0.403089","amount_traded":"0","microtimestamp":"1787932602426000","price":"2480.07"},"previous_record_hash":"881f2dc121eee4cc0cbb2d1338c62044652b7bb5246639f3a68f5cca5f5c4ed2","profit_assessment":null,"record_hash":"8b73a6f9130597a4f70335c07fedb99d1be0d93ef17a16a13f6dde0cdc6ab0c3","recorded_unix_us":1787932602554398,"recorded_utc":"2026-08-28T15:56:42.554398Z","schema_version":"nrrf810.exchange_authored_interactive_closure.v1","source_chain_continuous":true,"source_event":"order_deleted","source_event_id":"00065a1d-7fa6-6290-0000-001203000020","source_event_id_unique":true,"source_pre_event_id":"00065a1d-7fa6-3798-0000-001202000020","translation":"FOLD_RETURN_TO_ZERO","unfold_event_id":"00065a1d-7fa4-bcb0-0000-001200000020","zero_hair":true}
{"channel":"live_orders_btcusd","interaction_index":799,"natural_form":{"channel":"live_orders_btcusd","order_id":"2044303883350020","order_subtype":0,"order_type":0},"natural_form_sha256":"c31f4b1f57ae315e907dc8b8ad15f668a9e2df72496458c03b7f7c98534d8438","order_source":"orderbook","orders_submitted":0,"presentation":{"amount":"0.00006631","amount_traded":"0","microtimestamp":"1787932602428000","price":"76167.00"},"previous_record_hash":"8b73a6f9130597a4f70335c07fedb99d1be0d93ef17a16a13f6dde0cdc6ab0c3","profit_assessment":null,"record_hash":"2f15deac7d18a5ebf635783d2f6e61fec25bf28a913f7d3749ed8a9a6c679471","recorded_unix_us":1787932602554572,"recorded_utc":"2026-08-28T15:56:42.554572Z","schema_version":"nrrf810.exchange_authored_interactive_closure.v1","source_chain_continuous":true,"source_event":"order_created","source_event_id":"00065a1d-7fa6-6a60-0000-000103000020","source_event_id_unique":true,"source_pre_event_id":"00065a1d-7fa6-52f0-0001-000102000020","translation":"UNFOLD_TO_INF","unfold_event_id":null,"zero_hair":false}
{"channel":"live_orders_ethusd","interaction_index":800,"natural_form":{"channel":"live_orders_ethusd","order_id":"2044303883358220","order_subtype":5,"order_type":0},"natural_form_sha256":"b11464f80cdda6cff53a81f4e65427953f0980824b7e0ffc7b509c1821288da2","order_source":"orderbook","orders_submitted":0,"presentation":{"amount":"7.967962","amount_traded":"0","microtimestamp":"1787932602431000","price":"2476.96"},"previous_record_hash":"2f15deac7d18a5ebf635783d2f6e61fec25bf28a913f7d3749ed8a9a6c679471","profit_assessment":null,"record_hash":"b4743a26650233017640d556af711c45c3b51d42737dd57b663d00912b637f22","recorded_unix_us":1787932602554727,"recorded_utc":"2026-08-28T15:56:42.554727Z","schema_version":"nrrf810.exchange_authored_interactive_closure.v1","source_chain_continuous":true,"source_event":"order_created","source_event_id":"00065a1d-7fa6-7618-0000-001200000020","source_event_id_unique":true,"source_pre_event_id":"00065a1d-7fa6-6290-0000-001203000020","translation":"UNFOLD_TO_INF","unfold_event_id":null,"zero_hair":false}
{"channel":"live_orders_btcusd","interaction_index":801,"natural_form":{"channel":"live_orders_btcusd","order_id":"2044303883362316","order_subtype":5,"order_type":1},"natural_form_sha256":"b808f7e1eb9ac2ad80462ea97dd67ce9a36659be26381edac25edbcbbd49bc44","order_source":"orderbook","orders_submitted":0,"presentation":{"amount":"1.27113313","amount_traded":"0","microtimestamp":"1787932602432000","price":"78669.97"},"previous_record_hash":"b4743a26650233017640d556af711c45c3b51d42737dd57b663d00912b637f22","profit_assessment":null,"record_hash":"cf8bccedd9bdccd9108df266fadf87dcf0386ccf1cd4cc168b2e1193a2535fc1","recorded_unix_us":1787932602554861,"recorded_utc":"2026-08-28T15:56:42.554861Z","schema_version":"nrrf810.exchange_authored_interactive_closure.v1","source_chain_continuous":true,"source_event":"order_created","source_event_id":"00065a1d-7fa6-7a00-0000-000100000020","source_event_id_unique":true,"source_pre_event_id":"00065a1d-7fa6-6a60-0000-000103000020","translation":"UNFOLD_TO_INF","unfold_event_id":null,"zero_hair":false}
{"channel":"live_orders_ethusd","interaction_index":802,"natural_form":{"channel":"live_orders_ethusd","order_id":"2044303883374610","order_subtype":5,"order_type":0},"natural_form_sha256":"f59c8a1878fd156fa4cf9045754876812f6fafc07844833d9cc8ed1302dbc6b4","order_source":"orderbook","orders_submitted":0,"presentation":{"amount":"0.403094","amount_traded":"0","microtimestamp":"1787932602435000","price":"2480.02"},"previous_record_hash":"cf8bccedd9bdccd9108df266fadf87dcf0386ccf1cd4cc168b2e1193a2535fc1","profit_assessment":null,"record_hash":"b0f6c8f2bed56cabe125d37b5aa6c29ce8fd32c4fa920c9d82b079d8c53ed2c7","recorded_unix_us":1787932602554990,"recorded_utc":"2026-08-28T15:56:42.554990Z","schema_version":"nrrf810.exchange_authored_interactive_closure.v1","source_chain_continuous":true,"source_event":"order_created","source_event_id":"00065a1d-7fa6-85b8-0000-001201000020","source_event_id_unique":true,"source_pre_event_id":"00065a1d-7fa6-7618-0000-001200000020","translation":"UNFOLD_TO_INF","unfold_event_id":null,"zero_hair":false}
{"channel":"live_orders_btcusd","interaction_index":803,"natural_form":{"channel":"live_orders_btcusd","order_id":"2044303883390996","order_subtype":5,"order_type":1},"natural_form_sha256":"9159df94b514cd85907943b7f407892385f97c3b6cc5b2f210df27957979c0b8","order_source":"orderbook","orders_submitted":0,"presentation":{"amount":"0.10000000","amount_traded":"0","microtimestamp":"1787932602439000","price":"78522.62"},"previous_record_hash":"b0f6c8f2bed56cabe125d37b5aa6c29ce8fd32c4fa920c9d82b079d8c53ed2c7","profit_assessment":null,"record_hash":"79c66785cd655a97dda32e18bb982ab0d5faa0d8fa757866e32c90b27e56d545","recorded_unix_us":1787932602555128,"recorded_utc":"2026-08-28T15:56:42.555128Z","schema_version":"nrrf810.exchange_authored_interactive_closure.v1","source_chain_continuous":true,"source_event":"order_created","source_event_id":"00065a1d-7fa6-9558-0000-000101000020","source_event_id_unique":true,"source_pre_event_id":"00065a1d-7fa6-7a00-0000-000100000020","translation":"UNFOLD_TO_INF","unfold_event_id":null,"zero_hair":false}
{"channel":"live_orders_btcusd","interaction_index":804,"natural_form":{"channel":"live_orders_btcusd","order_id":"2044303883390996","order_subtype":5,"order_type":1},"natural_form_sha256":"9159df94b514cd85907943b7f407892385f97c3b6cc5b2f210df27957979c0b8","order_source":"orderbook","orders_submitted":0,"presentation":{"amount":"0.10000000","amount_traded":"0","microtimestamp":"1787932602439000","price":"78522.62"},"previous_record_hash":"79c66785cd655a97dda32e18bb982ab0d5faa0d8fa757866e32c90b27e56d545","profit_assessment":null,"record_hash":"2d908cc7a517a0e768db6c6d210d1710bcc4a0fd173cf2ed410b611aa3933cd1","recorded_unix_us":1787932602555245,"recorded_utc":"2026-08-28T15:56:42.555245Z","schema_version":"nrrf810.exchange_authored_interactive_closure.v1","source_chain_continuous":true,"source_event":"order_deleted","source_event_id":"00065a1d-7fa6-9558-0001-000102000020","source_event_id_unique":true,"source_pre_event_id":"00065a1d-7fa6-9558-0000-000101000020","translation":"FOLD_RETURN_TO_ZERO","unfold_event_id":"00065a1d-7fa6-9558-0000-000101000020","zero_hair":true}
{"channel":"live_orders_btcusd","interaction_index":805,"natural_form":{"channel":"live_orders_btcusd","order_id":"2044303883395093","order_subtype":5,"order_type":1},"natural_form_sha256":"6e2bcb60720eb58ee7771297c2887065b37c569cbcc0b4cbd8942780cc31f47f","order_source":"orderbook","orders_submitted":0,"presentation":{"amount":"0.06310787","amount_traded":"0","microtimestamp":"1787932602439000","price":"78520.30"},"previous_record_hash":"2d908cc7a517a0e768db6c6d210d1710bcc4a0fd173cf2ed410b611aa3933cd1","profit_assessment":null,"record_hash":"0782b3fcd114f5b9fe6c3d7fcaa564b796b4c2122e2475180e82159f36912ef2","recorded_unix_us":1787932602555355,"recorded_utc":"2026-08-28T15:56:42.555355Z","schema_version":"nrrf810.exchange_authored_interactive_closure.v1","source_chain_continuous":true,"source_event":"order_created","source_event_id":"00065a1d-7fa6-9558-0002-000103000020","source_event_id_unique":true,"source_pre_event_id":"00065a1d-7fa6-9558-0001-000102000020","translation":"UNFOLD_TO_INF","unfold_event_id":null,"zero_hair":false}
{"channel":"live_orders_btcusd","interaction_index":806,"natural_form":{"channel":"live_orders_btcusd","order_id":"2044303883395093","order_subtype":5,"order_type":1},"natural_form_sha256":"6e2bcb60720eb58ee7771297c2887065b37c569cbcc0b4cbd8942780cc31f47f","order_source":"orderbook","orders_submitted":0,"presentation":{"amount":"0.06310787","amount_traded":"0","microtimestamp":"1787932602439000","price":"78520.30"},"previous_record_hash":"0782b3fcd114f5b9fe6c3d7fcaa564b796b4c2122e2475180e82159f36912ef2","profit_assessment":null,"record_hash":"551cf429f197beef6f77db6117ecef2df82db5241eb77344d21a90a0401dc553","recorded_unix_us":1787932602555459,"recorded_utc":"2026-08-28T15:56:42.555459Z","schema_version":"nrrf810.exchange_authored_interactive_closure.v1","source_chain_continuous":true,"source_event":"order_deleted","source_event_id":"00065a1d-7fa6-9558-0003-000100000020","source_event_id_unique":true,"source_pre_event_id":"00065a1d-7fa6-9558-0002-000103000020","translation":"FOLD_RETURN_TO_ZERO","unfold_event_id":"00065a1d-7fa6-9558-0002-000103000020","zero_hair":true}
{"channel":"live_orders_btcusd","interaction_index":807,"natural_form":{"channel":"live_orders_btcusd","order_id":"2044303883411464","order_subtype":4,"order_type":1},"natural_form_sha256":"c31a86b9279841475bb34e768440ae4189a8f6bd11f8443f7d4d964f5a50cc36","order_source":"orderbook","orders_submitted":0,"presentation":{"amount":"0.00006244","amount_traded":"0","microtimestamp":"1787932602443000","price":"80878.00"},"previous_record_hash":"551cf429f197beef6f77db6117ecef2df82db5241eb77344d21a90a0401dc553","profit_assessment":null,"record_hash":"da41cc71f34a6927fbbf1d5f2ba20ce4a3f3a0dcb04adb2d5de41118c441d3e4","recorded_unix_us":1787932602555605,"recorded_utc":"2026-08-28T15:56:42.555605Z","schema_version":"nrrf810.exchange_authored_interactive_closure.v1","source_chain_continuous":true,"source_event":"order_created","source_event_id":"00065a1d-7fa6-a4f8-0000-000101000020","source_event_id_unique":true,"source_pre_event_id":"00065a1d-7fa6-9558-0003-000100000020","translation":"UNFOLD_TO_INF","unfold_event_id":null,"zero_hair":false}
{"channel":"live_orders_btcusd","interaction_index":808,"natural_form":{"channel":"live_orders_btcusd","order_id":"2044303883411464","order_subtype":4,"order_type":1},"natural_form_sha256":"c31a86b9279841475bb34e768440ae4189a8f6bd11f8443f7d4d964f5a50cc36","order_source":"orderbook","orders_submitted":0,"presentation":{"amount":"0.00006244","amount_traded":"0","microtimestamp":"1787932602443000","price":"80878.00"},"previous_record_hash":"da41cc71f34a6927fbbf1d5f2ba20ce4a3f3a0dcb04adb2d5de41118c441d3e4","profit_assessment":null,"record_hash":"0522119875b3c739ae753b0be4dd95615295dfabcf8c239a585272f1261474a9","recorded_unix_us":1787932602555649,"recorded_utc":"2026-08-28T15:56:42.555649Z","schema_version":"nrrf810.exchange_authored_interactive_closure.v1","source_chain_continuous":true,"source_event":"order_deleted","source_event_id":"00065a1d-7fa6-a4f8-0001-000102000020","source_event_id_unique":true,"source_pre_event_id":"00065a1d-7fa6-a4f8-0000-000101000020","translation":"FOLD_RETURN_TO_ZERO","unfold_event_id":"00065a1d-7fa6-a4f8-0000-000101000020","zero_hair":true}
{"channel":"live_orders_ethbtc","interaction_index":809,"natural_form":{"channel":"live_orders_ethbtc","order_id":"2044303883431937","order_subtype":5,"order_type":1},"natural_form_sha256":"59a30027e850b2d5fd9bed822a81bb0b54ffba6ad34f5d7344c163b2d8115c7d","order_source":"orderbook","orders_submitted":0,"presentation":{"amount":"0.60448710","amount_traded":"0","microtimestamp":"1787932602448000","price":"0.03160362"},"previous_record_hash":"0522119875b3c739ae753b0be4dd95615295dfabcf8c239a585272f1261474a9","profit_assessment":null,"record_hash":"ed66fb73c1467b6f6d45db3c478202be6ef466151cc717a8f3edc2a41c6df9a8","recorded_unix_us":1787932602555762,"recorded_utc":"2026-08-28T15:56:42.555762Z","schema_version":"nrrf810.exchange_authored_interactive_closure.v1","source_chain_continuous":true,"source_event":"order_created","source_event_id":"00065a1d-7fa6-b880-0000-001102000020","source_event_id_unique":true,"source_pre_event_id":"00065a1d-7fa6-1470-0000-001101000020","translation":"UNFOLD_TO_INF","unfold_event_id":null,"zero_hair":false}
{"channel":"live_orders_btcusd","interaction_index":810,"natural_form":{"channel":"live_orders_btcusd","order_id":"2044303883464718","order_subtype":5,"order_type":1},"natural_form_sha256":"d47788fb98b2def879343e72faedee7d90a08e4bdfbf18a9db4c9d1f08a0e036","order_source":"orderbook","orders_submitted":0,"presentation":{"amount":"0.10000000","amount_traded":"0","microtimestamp":"1787932602457000","price":"78522.63"},"previous_record_hash":"ed66fb73c1467b6f6d45db3c478202be6ef466151cc717a8f3edc2a41c6df9a8","profit_assessment":null,"record_hash":"d9b520d4e3801757a8c0963fdec9c92804da578a04281eae80e36ad0d6245d35","recorded_unix_us":1787932602555867,"recorded_utc":"2026-08-28T15:56:42.555867Z","schema_version":"nrrf810.exchange_authored_interactive_closure.v1","source_chain_continuous":true,"source_event":"order_created","source_event_id":"00065a1d-7fa6-dba8-0000-000103000020","source_event_id_unique":true,"source_pre_event_id":"00065a1d-7fa6-a4f8-0001-000102000020","translation":"UNFOLD_TO_INF","unfold_event_id":null,"zero_hair":false}
{"channel":"live_orders_btcusd","interaction_index":811,"natural_form":{"channel":"live_orders_btcusd","order_id":"2044303883464718","order_subtype":5,"order_type":1},"natural_form_sha256":"d47788fb98b2def879343e72faedee7d90a08e4bdfbf18a9db4c9d1f08a0e036","order_source":"orderbook","orders_submitted":0,"presentation":{"amount":"0.10000000","amount_traded":"0","microtimestamp":"1787932602457000","price":"78522.63"},"previous_record_hash":"d9b520d4e3801757a8c0963fdec9c92804da578a04281eae80e36ad0d6245d35","profit_assessment":null,"record_hash":"a60b77f70fed33a2a8d7928d26e644d9099edba27e49e73f2a90c7b564752134","recorded_unix_us":1787932602555971,"recorded_utc":"2026-08-28T15:56:42.555971Z","schema_version":"nrrf810.exchange_authored_interactive_closure.v1","source_chain_continuous":true,"source_event":"order_deleted","source_event_id":"00065a1d-7fa6-dba8-0001-000100000020","source_event_id_unique":true,"source_pre_event_id":"00065a1d-7fa6-dba8-0000-000103000020","translation":"FOLD_RETURN_TO_ZERO","unfold_event_id":"00065a1d-7fa6-dba8-0000-000103000020","zero_hair":true}
{"channel":"live_orders_ethbtc","interaction_index":812,"natural_form":{"channel":"live_orders_ethbtc","order_id":"2044303883493384","order_subtype":5,"order_type":1},"natural_form_sha256":"abc59cfe1f9f563aa398317971234e03078ae4f39c645c8207fdbab8838047bf","order_source":"orderbook","orders_submitted":0,"presentation":{"amount":"1.00736500","amount_traded":"0","microtimestamp":"1787932602463000","price":"0.03160719"},"previous_record_hash":"a60b77f70fed33a2a8d7928d26e644d9099edba27e49e73f2a90c7b564752134","profit_assessment":null,"record_hash":"e6956e753d733ccf26a489675bed9de4e6788ac9ce1b4587e2eddea1507cc6c5","recorded_unix_us":1787932602556103,"recorded_utc":"2026-08-28T15:56:42.556103Z","schema_version":"nrrf810.exchange_authored_interactive_closure.v1","source_chain_continuous":true,"source_event":"order_created","source_event_id":"00065a1d-7fa6-f318-0000-001103000020","source_event_id_unique":true,"source_pre_event_id":"00065a1d-7fa6-b880-0000-001102000020","translation":"UNFOLD_TO_INF","unfold_event_id":null,"zero_hair":false}
{"channel":"live_orders_ethbtc","interaction_index":813,"natural_form":{"channel":"live_orders_ethbtc","order_id":"2044303883497482","order_subtype":5,"order_type":1},"natural_form_sha256":"a00235208885f78bbe9ab2fd6dec79d3300ce2e32404bf21ce20fb2696bfdb76","order_source":"orderbook","orders_submitted":0,"presentation":{"amount":"2.01406611","amount_traded":"0","microtimestamp":"1787932602465000","price":"0.03161760"},"previous_record_hash":"e6956e753d733ccf26a489675bed9de4e6788ac9ce1b4587e2eddea1507cc6c5","profit_assessment":null,"record_hash":"a4ae27f1a47c0bd81ba4fc65769d50fae6b0adfabe0fe09b4dfc2296efd5cde0","recorded_unix_us":1787932602556221,"recorded_utc":"2026-08-28T15:56:42.556221Z","schema_version":"nrrf810.exchange_authored_interactive_closure.v1","source_chain_continuous":true,"source_event":"order_created","source_event_id":"00065a1d-7fa6-fae8-0000-001100000020","source_event_id_unique":true,"source_pre_event_id":"00065a1d-7fa6-f318-0000-001103000020","translation":"UNFOLD_TO_INF","unfold_event_id":null,"zero_hair":false}
{"channel":"live_orders_btcusd","interaction_index":814,"natural_form":{"channel":"live_orders_btcusd","order_id":"2044303883501577","order_subtype":5,"order_type":0},"natural_form_sha256":"7cdcbb1692471ecd1ca18773abf569892db2a21b88e51913a4616d63fe973c94","order_source":"orderbook","orders_submitted":0,"presentation":{"amount":"0.00140266","amount_traded":"0","microtimestamp":"1787932602466000","price":"70666.76"},"previous_record_hash":"a4ae27f1a47c0bd81ba4fc65769d50fae6b0adfabe0fe09b4dfc2296efd5cde0","profit_assessment":null,"record_hash":"f72a7284cd035e9c165e98b6beedc9292e24837b81e664977faed9b6d793d57c","recorded_unix_us":1787932602556358,"recorded_utc":"2026-08-28T15:56:42.556358Z","schema_version":"nrrf810.exchange_authored_interactive_closure.v1","source_chain_continuous":true,"source_event":"order_created","source_event_id":"00065a1d-7fa6-fed0-0000-000101000020","source_event_id_unique":true,"source_pre_event_id":"00065a1d-7fa6-dba8-0001-000100000020","translation":"UNFOLD_TO_INF","unfold_event_id":null,"zero_hair":false}
{"channel":"live_orders_ethbtc","interaction_index":815,"natural_form":{"channel":"live_orders_ethbtc","order_id":"2044303883501576","order_subtype":5,"order_type":1},"natural_form_sha256":"053eec1138a89019705f5acd0b320e53d30a9cdab79e769c0a7fafb1953659dc","order_source":"orderbook","orders_submitted":0,"presentation":{"amount":"3.02055629","amount_traded":"0","microtimestamp":"1787932602466000","price":"0.03162186"},"previous_record_hash":"f72a7284cd035e9c165e98b6beedc9292e24837b81e664977faed9b6d793d57c","profit_assessment":null,"record_hash":"a8d143974d6926525db7607dda774e90820abb7b6a6ab713fbe200c1c4865f7d","recorded_unix_us":1787932602556465,"recorded_utc":"2026-08-28T15:56:42.556465Z","schema_version":"nrrf810.exchange_authored_interactive_closure.v1","source_chain_continuous":true,"source_event":"order_created","source_event_id":"00065a1d-7fa6-fed0-0000-001101000020","source_event_id_unique":true,"source_pre_event_id":"00065a1d-7fa6-fae8-0000-001100000020","translation":"UNFOLD_TO_INF","unfold_event_id":null,"zero_hair":false}
{"channel":"live_orders_ethbtc","interaction_index":816,"natural_form":{"channel":"live_orders_ethbtc","order_id":"2044303883505675","order_subtype":5,"order_type":0},"natural_form_sha256":"5019bd33d08d64fc20f6bf1af7a4cb4fff006a6024cb2308e407f157b5a3ef76","order_source":"orderbook","orders_submitted":0,"presentation":{"amount":"0.60475617","amount_traded":"0","microtimestamp":"1787932602467000","price":"0.03158982"},"previous_record_hash":"a8d143974d6926525db7607dda774e90820abb7b6a6ab713fbe200c1c4865f7d","profit_assessment":null,"record_hash":"a89d72ef0d797f43737e3550ebeab74750675a3bce5e606b9c5091af2ab8f709","recorded_unix_us":1787932602556623,"recorded_utc":"2026-08-28T15:56:42.556623Z","schema_version":"nrrf810.exchange_authored_interactive_closure.v1","source_chain_continuous":true,"source_event":"order_created","source_event_id":"00065a1d-7fa7-02b8-0000-001102000020","source_event_id_unique":true,"source_pre_event_id":"00065a1d-7fa6-fed0-0000-001101000020","translation":"UNFOLD_TO_INF","unfold_event_id":null,"zero_hair":false}
{"channel":"live_orders_ethbtc","interaction_index":817,"natural_form":{"channel":"live_orders_ethbtc","order_id":"2044303883509763","order_subtype":5,"order_type":0},"natural_form_sha256":"7cf574864f0edb740aad731c650a4c6896539b6f542b342e581c9ebf23f71c5f","order_source":"orderbook","orders_submitted":0,"presentation":{"amount":"1.00801353","amount_traded":"0","microtimestamp":"1787932602467000","price":"0.03158534"},"previous_record_hash":"a89d72ef0d797f43737e3550ebeab74750675a3bce5e606b9c5091af2ab8f709","profit_assessment":null,"record_hash":"4bad11e7f9fb9cc2e165ba09d840ab1112ad5c47172f930f6e66137c7fde0e21","recorded_unix_us":1787932602556660,"recorded_utc":"2026-08-28T15:56:42.556660Z","schema_version":"nrrf810.exchange_authored_interactive_closure.v1","source_chain_continuous":true,"source_event":"order_created","source_event_id":"00065a1d-7fa7-02b8-0001-001103000020","source_event_id_unique":true,"source_pre_event_id":"00065a1d-7fa7-02b8-0000-001102000020","translation":"UNFOLD_TO_INF","unfold_event_id":null,"zero_hair":false}
{"channel":"live_orders_ethbtc","interaction_index":818,"natural_form":{"channel":"live_orders_ethbtc","order_id":"2044303883509765","order_subtype":5,"order_type":1},"natural_form_sha256":"acbde9fbb3ac66c9d82d3ed58912f19e082c75c6ba8adb1c9ac74865d3bec207","order_source":"orderbook","orders_submitted":0,"presentation":{"amount":"4.02232075","amount_traded":"0","microtimestamp":"1787932602467000","price":"0.03165997"},"previous_record_hash":"4bad11e7f9fb9cc2e165ba09d840ab1112ad5c47172f930f6e66137c7fde0e21","profit_assessment":null,"record_hash":"23d2b09564c6172f0ef98292da8e95dd9dec744c5af92d060526a07c017e7a4b","recorded_unix_us":1787932602556763,"recorded_utc":"2026-08-28T15:56:42.556763Z","schema_version":"nrrf810.exchange_authored_interactive_closure.v1","source_chain_continuous":true,"source_event":"order_created","source_event_id":"00065a1d-7fa7-02b8-0002-001100000020","source_event_id_unique":true,"source_pre_event_id":"00065a1d-7fa7-02b8-0001-001103000020","translation":"UNFOLD_TO_INF","unfold_event_id":null,"zero_hair":false}
{"channel":"live_orders_btcusd","interaction_index":819,"natural_form":{"channel":"live_orders_btcusd","order_id":"2044303883513867","order_subtype":5,"order_type":1},"natural_form_sha256":"f9ad79b25bd67943d75d49056f2a95fbb11625e233d88dc5ea2c9def24a7983b","order_source":"orderbook","orders_submitted":0,"presentation":{"amount":"0.06310787","amount_traded":"0","microtimestamp":"1787932602468000","price":"78520.18"},"previous_record_hash":"23d2b09564c6172f0ef98292da8e95dd9dec744c5af92d060526a07c017e7a4b","profit_assessment":null,"record_hash":"090b87d9cb1975e186da846820584928cf3d06e9ace23d57e0b00b9e786fb1b3","recorded_unix_us":1787932602556882,"recorded_utc":"2026-08-28T15:56:42.556882Z","schema_version":"nrrf810.exchange_authored_interactive_closure.v1","source_chain_continuous":true,"source_event":"order_created","source_event_id":"00065a1d-7fa7-06a0-0000-000102000020","source_event_id_unique":true,"source_pre_event_id":"00065a1d-7fa6-fed0-0000-000101000020","translation":"UNFOLD_TO_INF","unfold_event_id":null,"zero_hair":false}
{"channel":"live_orders_btcusd","interaction_index":820,"natural_form":{"channel":"live_orders_btcusd","order_id":"2044303883513867","order_subtype":5,"order_type":1},"natural_form_sha256":"f9ad79b25bd67943d75d49056f2a95fbb11625e233d88dc5ea2c9def24a7983b","order_source":"orderbook","orders_submitted":0,"presentation":{"amount":"0.06310787","amount_traded":"0","microtimestamp":"1787932602468000","price":"78520.18"},"previous_record_hash":"090b87d9cb1975e186da846820584928cf3d06e9ace23d57e0b00b9e786fb1b3","profit_assessment":null,"record_hash":"87190ec94faccef8192f81dd59bed60a78307ad7e7880f760fe9aa3ed5b313e0","recorded_unix_us":1787932602556981,"recorded_utc":"2026-08-28T15:56:42.556981Z","schema_version":"nrrf810.exchange_authored_interactive_closure.v1","source_chain_continuous":true,"source_event":"order_deleted","source_event_id":"00065a1d-7fa7-06a0-0001-000103000020","source_event_id_unique":true,"source_pre_event_id":"00065a1d-7fa7-06a0-0000-000102000020","translation":"FOLD_RETURN_TO_ZERO","unfold_event_id":"00065a1d-7fa7-06a0-0000-000102000020","zero_hair":true}
{"channel":"live_orders_btcusd","interaction_index":821,"natural_form":{"channel":"live_orders_btcusd","order_id":"2044303878725651","order_subtype":5,"order_type":0},"natural_form_sha256":"74066d9252197cb501989873a45204a3a3bc052a4ce95021a6389008f2e59313","order_source":"orderbook","orders_submitted":0,"presentation":{"amount":"0.00254770","amount_traded":"0","microtimestamp":"1787932602469000","price":"78502.27"},"previous_record_hash":"87190ec94faccef8192f81dd59bed60a78307ad7e7880f760fe9aa3ed5b313e0","profit_assessment":null,"record_hash":"c86f3275f4c9f41c5f549cfdc4d4cb53edda209315ca1e53cb824192a681cebe","recorded_unix_us":1787932602557224,"recorded_utc":"2026-08-28T15:56:42.557224Z","schema_version":"nrrf810.exchange_authored_interactive_closure.v1","source_chain_continuous":true,"source_event":"order_deleted","source_event_id":"00065a1d-7fa7-0a88-0000-000100000020","source_event_id_unique":true,"source_pre_event_id":"00065a1d-7fa7-06a0-0001-000103000020","translation":"FOLD_RETURN_TO_ZERO","unfold_event_id":"00065a1d-7f95-3420-0000-000103000020","zero_hair":true}
{"channel":"live_orders_ethbtc","interaction_index":822,"natural_form":{"channel":"live_orders_ethbtc","order_id":"2044303883517953","order_subtype":5,"order_type":0},"natural_form_sha256":"6bb65668152924ab4eca86f48753f76a927ff2e84492e495f8e0608295bc7063","order_source":"orderbook","orders_submitted":0,"presentation":{"amount":"2.01629689","amount_traded":"0","microtimestamp":"1787932602469000","price":"0.03157941"},"previous_record_hash":"c86f3275f4c9f41c5f549cfdc4d4cb53edda209315ca1e53cb824192a681cebe","profit_assessment":null,"record_hash":"86693329207467705f4515ac176da3f60ce383e92536dbb3b68818ad670055dd","recorded_unix_us":1787932602557259,"recorded_utc":"2026-08-28T15:56:42.557259Z","schema_version":"nrrf810.exchange_authored_interactive_closure.v1","source_chain_continuous":true,"source_event":"order_created","source_event_id":"00065a1d-7fa7-0a88-0000-001101000020","source_event_id_unique":true,"source_pre_event_id":"00065a1d-7fa7-02b8-0002-001100000020","translation":"UNFOLD_TO_INF","unfold_event_id":null,"zero_hair":false}
{"channel":"live_orders_btcusd","interaction_index":823,"natural_form":{"channel":"live_orders_btcusd","order_id":"2044303883517952","order_subtype":5,"order_type":1},"natural_form_sha256":"f94d6e9c97c77fbd3fd82fddde59eff022cf6cde31a86f33cd2302090d8302d2","order_source":"orderbook","orders_submitted":0,"presentation":{"amount":"0.06310787","amount_traded":"0","microtimestamp":"1787932602469000","price":"78522.54"},"previous_record_hash":"86693329207467705f4515ac176da3f60ce383e92536dbb3b68818ad670055dd","profit_assessment":null,"record_hash":"ef41623bb81c306d0af31334e3db2dd0ea806e8d9fe6936068cda31e915ea9ba","recorded_unix_us":1787932602557287,"recorded_utc":"2026-08-28T15:56:42.557287Z","schema_version":"nrrf810.exchange_authored_interactive_closure.v1","source_chain_continuous":true,"source_event":"order_created","source_event_id":"00065a1d-7fa7-0a88-0001-000101000020","source_event_id_unique":true,"source_pre_event_id":"00065a1d-7fa7-0a88-0000-000100000020","translation":"UNFOLD_TO_INF","unfold_event_id":null,"zero_hair":false}
{"channel":"live_orders_btcusd","interaction_index":824,"natural_form":{"channel":"live_orders_btcusd","order_id":"2044303883517952","order_subtype":5,"order_type":1},"natural_form_sha256":"f94d6e9c97c77fbd3fd82fddde59eff022cf6cde31a86f33cd2302090d8302d2","order_source":"orderbook","orders_submitted":0,"presentation":{"amount":"0.06310787","amount_traded":"0","microtimestamp":"1787932602469000","price":"78522.54"},"previous_record_hash":"ef41623bb81c306d0af31334e3db2dd0ea806e8d9fe6936068cda31e915ea9ba","profit_assessment":null,"record_hash":"a57a6b1914008c38ef47d65af009a642e4bf9131619dd022fc125c2ef5576e40","recorded_unix_us":1787932602557346,"recorded_utc":"2026-08-28T15:56:42.557346Z","schema_version":"nrrf810.exchange_authored_interactive_closure.v1","source_chain_continuous":true,"source_event":"order_deleted","source_event_id":"00065a1d-7fa7-0a88-0002-000102000020","source_event_id_unique":true,"source_pre_event_id":"00065a1d-7fa7-0a88-0001-000101000020","translation":"FOLD_RETURN_TO_ZERO","unfold_event_id":"00065a1d-7fa7-0a88-0001-000101000020","zero_hair":true}
{"channel":"live_orders_ethbtc","interaction_index":825,"natural_form":{"channel":"live_orders_ethbtc","order_id":"2044303883517972","order_subtype":5,"order_type":0},"natural_form_sha256":"1dd461dbdc300088ecaa9c978d4a0bcae0e29ecffb27fc9514828e9765dab539","order_source":"orderbook","orders_submitted":0,"presentation":{"amount":"3.02537254","amount_traded":"0","microtimestamp":"1787932602470000","price":"0.03156999"},"previous_record_hash":"a57a6b1914008c38ef47d65af009a642e4bf9131619dd022fc125c2ef5576e40","profit_assessment":null,"record_hash":"b6130fdc68fe8dd6944cc4c74e8dca95d737df7d0692877907b3ee3189bbc277","recorded_unix_us":1787932602557454,"recorded_utc":"2026-08-28T15:56:42.557454Z","schema_version":"nrrf810.exchange_authored_interactive_closure.v1","source_chain_continuous":true,"source_event":"order_created","source_event_id":"00065a1d-7fa7-0e70-0000-001102000020","source_event_id_unique":true,"source_pre_event_id":"00065a1d-7fa7-0a88-0000-001101000020","translation":"UNFOLD_TO_INF","unfold_event_id":null,"zero_hair":false}
{"channel":"live_orders_ethbtc","interaction_index":826,"natural_form":{"channel":"live_orders_ethbtc","order_id":"2044303883522052","order_subtype":5,"order_type":0},"natural_form_sha256":"3153b031c26b07249acb7c5533f019464d8cd1286de8a0ba14421656c989319c","order_source":"orderbook","orders_submitted":0,"presentation":{"amount":"4.03662068","amount_traded":"0","microtimestamp":"1787932602470000","price":"0.03154857"},"previous_record_hash":"b6130fdc68fe8dd6944cc4c74e8dca95d737df7d0692877907b3ee3189bbc277","profit_assessment":null,"record_hash":"d6ab5b6f954c6f7c312174e8ddaed559ef7eb214f28d67f877c535fbe58125d5","recorded_unix_us":1787932602557554,"recorded_utc":"2026-08-28T15:56:42.557554Z","schema_version":"nrrf810.exchange_authored_interactive_closure.v1","source_chain_continuous":true,"source_event":"order_created","source_event_id":"00065a1d-7fa7-0e70-0001-001103000020","source_event_id_unique":true,"source_pre_event_id":"00065a1d-7fa7-0e70-0000-001102000020","translation":"UNFOLD_TO_INF","unfold_event_id":null,"zero_hair":false}
{"channel":"live_orders_ethusd","interaction_index":827,"natural_form":{"channel":"live_orders_ethusd","order_id":"2044303881940997","order_subtype":5,"order_type":0},"natural_form_sha256":"2c596c39bbcd67c9eaf724b69544ef10770d8a0a577c83d3b54cdf73a79ef3f5","order_source":"orderbook","orders_submitted":0,"presentation":{"amount":"0.042508","amount_traded":"0","microtimestamp":"1787932602471000","price":"2480.80"},"previous_record_hash":"d6ab5b6f954c6f7c312174e8ddaed559ef7eb214f28d67f877c535fbe58125d5","profit_assessment":null,"record_hash":"78eeee20083cc19aefe68edb8e1991b035cdec7e6e978f4e9cfcbac05995b56a","recorded_unix_us":1787932602557651,"recorded_utc":"2026-08-28T15:56:42.557651Z","schema_version":"nrrf810.exchange_authored_interactive_closure.v1","source_chain_continuous":true,"source_event":"order_deleted","source_event_id":"00065a1d-7fa7-1258-0000-001202000020","source_event_id_unique":true,"source_pre_event_id":"00065a1d-7fa6-85b8-0000-001201000020","translation":"FOLD_RETURN_TO_ZERO","unfold_event_id":"00065a1d-7fa1-2e88-0000-001201000020","zero_hair":true}
{"channel":"live_orders_btcusd","interaction_index":828,"natural_form":{"channel":"live_orders_btcusd","order_id":"2044303883530245","order_subtype":5,"order_type":1},"natural_form_sha256":"be88327798ab85c46cd0b0fe634997fe1dbee56b16965742de92f2861ee0ef6f","order_source":"orderbook","orders_submitted":0,"presentation":{"amount":"0.10000000","amount_traded":"0","microtimestamp":"1787932602472000","price":"78522.62"},"previous_record_hash":"78eeee20083cc19aefe68edb8e1991b035cdec7e6e978f4e9cfcbac05995b56a","profit_assessment":null,"record_hash":"d673fc8d20c93aaa5640829cfa3fa7ceaf9c6ad88db8d6907af07779365a50ee","recorded_unix_us":1787932602557817,"recorded_utc":"2026-08-28T15:56:42.557817Z","schema_version":"nrrf810.exchange_authored_interactive_closure.v1","source_chain_continuous":true,"source_event":"order_created","source_event_id":"00065a1d-7fa7-1640-0000-000103000020","source_event_id_unique":true,"source_pre_event_id":"00065a1d-7fa7-0a88-0002-000102000020","translation":"UNFOLD_TO_INF","unfold_event_id":null,"zero_hair":false}
{"channel":"live_orders_btcusd","interaction_index":829,"natural_form":{"channel":"live_orders_btcusd","order_id":"2044303883530245","order_subtype":5,"order_type":1},"natural_form_sha256":"be88327798ab85c46cd0b0fe634997fe1dbee56b16965742de92f2861ee0ef6f","order_source":"orderbook","orders_submitted":0,"presentation":{"amount":"0.10000000","amount_traded":"0","microtimestamp":"1787932602472000","price":"78522.62"},"previous_record_hash":"d673fc8d20c93aaa5640829cfa3fa7ceaf9c6ad88db8d6907af07779365a50ee","profit_assessment":null,"record_hash":"72891adf52e632e706ea035d93ea63237a505482fedc842b9884b34d9f5a2f08","recorded_unix_us":1787932602557851,"recorded_utc":"2026-08-28T15:56:42.557851Z","schema_version":"nrrf810.exchange_authored_interactive_closure.v1","source_chain_continuous":true,"source_event":"order_deleted","source_event_id":"00065a1d-7fa7-1640-0001-000100000020","source_event_id_unique":true,"source_pre_event_id":"00065a1d-7fa7-1640-0000-000103000020","translation":"FOLD_RETURN_TO_ZERO","unfold_event_id":"00065a1d-7fa7-1640-0000-000103000020","zero_hair":true}
{"channel":"live_orders_ethusd","interaction_index":830,"natural_form":{"channel":"live_orders_ethusd","order_id":"2044303881945090","order_subtype":5,"order_type":1},"natural_form_sha256":"b12054c37442433535f54533f94bb28d6bb73f217fde7a20f8b0595eebe0035e","order_source":"orderbook","orders_submitted":0,"presentation":{"amount":"0.043646","amount_traded":"0","microtimestamp":"1787932602473000","price":"2480.89"},"previous_record_hash":"72891adf52e632e706ea035d93ea63237a505482fedc842b9884b34d9f5a2f08","profit_assessment":null,"record_hash":"21d7b5f70e452343cec6f833b09428c111b674599cec99672fc2847609d34a25","recorded_unix_us":1787932602557979,"recorded_utc":"2026-08-28T15:56:42.557979Z","schema_version":"nrrf810.exchange_authored_interactive_closure.v1","source_chain_continuous":true,"source_event":"order_deleted","source_event_id":"00065a1d-7fa7-1a28-0000-001203000020","source_event_id_unique":true,"source_pre_event_id":"00065a1d-7fa7-1258-0000-001202000020","translation":"FOLD_RETURN_TO_ZERO","unfold_event_id":"00065a1d-7fa1-2e88-0001-001202000020","zero_hair":true}
{"channel":"live_orders_btcusd","interaction_index":831,"natural_form":{"channel":"live_orders_btcusd","order_id":"2044303876603911","order_subtype":5,"order_type":1},"natural_form_sha256":"16924cabef115a0aaf558df6a43497ccf3cc689b2bdaeaa218658264c0f0f048","order_source":"orderbook","orders_submitted":0,"presentation":{"amount":"0.00254701","amount_traded":"0","microtimestamp":"1787932602473000","price":"78523.42"},"previous_record_hash":"21d7b5f70e452343cec6f833b09428c111b674599cec99672fc2847609d34a25","profit_assessment":null,"record_hash":"4738ca9efc790b557f02c9cecbef5939f525152ebd514da8012d1ce976c4b8b8","recorded_unix_us":1787932602558108,"recorded_utc":"2026-08-28T15:56:42.558108Z","schema_version":"nrrf810.exchange_authored_interactive_closure.v1","source_chain_continuous":true,"source_event":"order_deleted","source_event_id":"00065a1d-7fa7-1a28-0000-000101000020","source_event_id_unique":true,"source_pre_event_id":"00065a1d-7fa7-1640-0001-000100000020","translation":"PARTIAL_PRIOR_UNFOLD","unfold_event_id":null,"zero_hair":false}
{"channel":"live_orders_ethusd","interaction_index":832,"natural_form":{"channel":"live_orders_ethusd","order_id":"2044303881039873","order_subtype":5,"order_type":0},"natural_form_sha256":"fe3016eb1590b0d2dd379056b4d7b9a7d8c9baaaa407c6efbf8eb0b3a26f626a","order_source":"orderbook","orders_submitted":0,"presentation":{"amount":"0.336955","amount_traded":"0","microtimestamp":"1787932602487000","price":"2480.15"},"previous_record_hash":"4738ca9efc790b557f02c9cecbef5939f525152ebd514da8012d1ce976c4b8b8","profit_assessment":null,"record_hash":"73245aa2c3e59dda4ff8bca7771d15303f0d976f68bad504073bd1f120b3b4a7","recorded_unix_us":1787932602612852,"recorded_utc":"2026-08-28T15:56:42.612852Z","schema_version":"nrrf810.exchange_authored_interactive_closure.v1","source_chain_continuous":true,"source_event":"order_deleted","source_event_id":"00065a1d-7fa7-50d8-0000-001200000020","source_event_id_unique":true,"source_pre_event_id":"00065a1d-7fa7-1a28-0000-001203000020","translation":"FOLD_RETURN_TO_ZERO","unfold_event_id":"00065a1d-7f9d-cf40-0000-001201000020","zero_hair":true}
{"channel":"live_orders_ethusd","interaction_index":833,"natural_form":{"channel":"live_orders_ethusd","order_id":"2044303882694659","order_subtype":5,"order_type":0},"natural_form_sha256":"b3e4a141bc59eaf1c3b1f65f0dc164d3e8394ae4212d0e9ab323da5ad600eb5d","order_source":"orderbook","orders_submitted":0,"presentation":{"amount":"0.403086","amount_traded":"0","microtimestamp":"1787932602491000","price":"2480.16"},"previous_record_hash":"73245aa2c3e59dda4ff8bca7771d15303f0d976f68bad504073bd1f120b3b4a7","profit_assessment":null,"record_hash":"307aaf41436922edacf713281703704d1ce42222b1fd62959a34d17bcc74c20d","recorded_unix_us":1787932602720771,"recorded_utc":"2026-08-28T15:56:42.720771Z","schema_version":"nrrf810.exchange_authored_interactive_closure.v1","source_chain_continuous":true,"source_event":"order_deleted","source_event_id":"00065a1d-7fa7-6078-0000-001201000020","source_event_id_unique":true,"source_pre_event_id":"00065a1d-7fa7-50d8-0000-001200000020","translation":"FOLD_RETURN_TO_ZERO","unfold_event_id":"00065a1d-7fa3-f960-0000-001203000020","zero_hair":true}
{"channel":"live_orders_ethusd","interaction_index":834,"natural_form":{"channel":"live_orders_ethusd","order_id":"2044303883616265","order_subtype":5,"order_type":1},"natural_form_sha256":"b7286c925ccb009d0d71fdd77ed000f088679dd136cab55c95915ddfe3fc123b","order_source":"orderbook","orders_submitted":0,"presentation":{"amount":"0.041769","amount_traded":"0","microtimestamp":"1787932602494000","price":"2480.85"},"previous_record_hash":"307aaf41436922edacf713281703704d1ce42222b1fd62959a34d17bcc74c20d","profit_assessment":null,"record_hash":"e9dbfa1611075aeb9ebe9d547c7ace301470a41c343ea782399f35c5a5cc2a73","recorded_unix_us":1787932602720887,"recorded_utc":"2026-08-28T15:56:42.720887Z","schema_version":"nrrf810.exchange_authored_interactive_closure.v1","source_chain_continuous":true,"source_event":"order_created","source_event_id":"00065a1d-7fa7-6c30-0000-001202000020","source_event_id_unique":true,"source_pre_event_id":"00065a1d-7fa7-6078-0000-001201000020","translation":"UNFOLD_TO_INF","unfold_event_id":null,"zero_hair":false}
{"channel":"live_orders_ethusd","interaction_index":835,"natural_form":{"channel":"live_orders_ethusd","order_id":"2044303883636739","order_subtype":5,"order_type":0},"natural_form_sha256":"5e7b5889bdfcc9df1e88348d4de85e42579ccd3e00a43cb8c63de0ced48b0e38","order_source":"orderbook","orders_submitted":0,"presentation":{"amount":"0.044416","amount_traded":"0","microtimestamp":"1787932602498000","price":"2480.75"},"previous_record_hash":"e9dbfa1611075aeb9ebe9d547c7ace301470a41c343ea782399f35c5a5cc2a73","profit_assessment":null,"record_hash":"85cad2ce9fad50535d7576f6928f21ea34e26b172d2e4017da48b14e5fc4bd57","recorded_unix_us":1787932602721010,"recorded_utc":"2026-08-28T15:56:42.721010Z","schema_version":"nrrf810.exchange_authored_interactive_closure.v1","source_chain_continuous":true,"source_event":"order_created","source_event_id":"00065a1d-7fa7-7bd0-0000-001203000020","source_event_id_unique":true,"source_pre_event_id":"00065a1d-7fa7-6c30-0000-001202000020","translation":"UNFOLD_TO_INF","unfold_event_id":null,"zero_hair":false}
{"channel":"live_orders_ethusd","interaction_index":836,"natural_form":{"channel":"live_orders_ethusd","order_id":"2044303883640834","order_subtype":5,"order_type":0},"natural_form_sha256":"009b919e507ee4f1283261dc347b10628b1e6adb4a9525960f8205d200e79027","order_source":"orderbook","orders_submitted":0,"presentation":{"amount":"0.509959","amount_traded":"0","microtimestamp":"1787932602499000","price":"2480.22"},"previous_record_hash":"85cad2ce9fad50535d7576f6928f21ea34e26b172d2e4017da48b14e5fc4bd57","profit_assessment":null,"record_hash":"45380f99bb1fb32046bca21aea2a8cbc238cad7bf193134bf345ff88534c5bbe","recorded_unix_us":1787932602721051,"recorded_utc":"2026-08-28T15:56:42.721051Z","schema_version":"nrrf810.exchange_authored_interactive_closure.v1","source_chain_continuous":true,"source_event":"order_created","source_event_id":"00065a1d-7fa7-7fb8-0000-001200000020","source_event_id_unique":true,"source_pre_event_id":"00065a1d-7fa7-7bd0-0000-001203000020","translation":"UNFOLD_TO_INF","unfold_event_id":null,"zero_hair":false}
{"channel":"live_orders_ethusd","interaction_index":837,"natural_form":{"channel":"live_orders_ethusd","order_id":"2044303883644928","order_subtype":5,"order_type":0},"natural_form_sha256":"6071641cdd33636ece3e02c7bfaeb2039664be0f9a469cd37823d72bf1311e0e","order_source":"orderbook","orders_submitted":0,"presentation":{"amount":"0.403096","amount_traded":"0","microtimestamp":"1787932602500000","price":"2480.22"},"previous_record_hash":"45380f99bb1fb32046bca21aea2a8cbc238cad7bf193134bf345ff88534c5bbe","profit_assessment":null,"record_hash":"6e9011f3700c38e56b26db576af63ed2dc5c8bd44fa7a48c506ef6f079fca00c","recorded_unix_us":1787932602721156,"recorded_utc":"2026-08-28T15:56:42.721156Z","schema_version":"nrrf810.exchange_authored_interactive_closure.v1","source_chain_continuous":true,"source_event":"order_created","source_event_id":"00065a1d-7fa7-83a0-0000-001201000020","source_event_id_unique":true,"source_pre_event_id":"00065a1d-7fa7-7fb8-0000-001200000020","translation":"UNFOLD_TO_INF","unfold_event_id":null,"zero_hair":false}
{"channel":"live_orders_btcusd","interaction_index":838,"natural_form":{"channel":"live_orders_btcusd","order_id":"2044303883649025","order_subtype":5,"order_type":1},"natural_form_sha256":"78c4c5af5e7b8dbd9870c093d566c807afc49d026ef8a51a07ec03987341c543","order_source":"orderbook","orders_submitted":0,"presentation":{"amount":"0.10000000","amount_traded":"0","microtimestamp":"1787932602501000","price":"78522.63"},"previous_record_hash":"6e9011f3700c38e56b26db576af63ed2dc5c8bd44fa7a48c506ef6f079fca00c","profit_assessment":null,"record_hash":"245e9b3dc79f9aad82955f990417363f013e8f543aa58228d4c7bb414457a692","recorded_unix_us":1787932602721291,"recorded_utc":"2026-08-28T15:56:42.721291Z","schema_version":"nrrf810.exchange_authored_interactive_closure.v1","source_chain_continuous":true,"source_event":"order_created","source_event_id":"00065a1d-7fa7-8788-0000-000102000020","source_event_id_unique":true,"source_pre_event_id":"00065a1d-7fa7-1a28-0000-000101000020","translation":"UNFOLD_TO_INF","unfold_event_id":null,"zero_hair":false}
{"channel":"live_orders_btcusd","interaction_index":839,"natural_form":{"channel":"live_orders_btcusd","order_id":"2044303883649025","order_subtype":5,"order_type":1},"natural_form_sha256":"78c4c5af5e7b8dbd9870c093d566c807afc49d026ef8a51a07ec03987341c543","order_source":"orderbook","orders_submitted":0,"presentation":{"amount":"0.10000000","amount_traded":"0","microtimestamp":"1787932602501000","price":"78522.63"},"previous_record_hash":"245e9b3dc79f9aad82955f990417363f013e8f543aa58228d4c7bb414457a692","profit_assessment":null,"record_hash":"c5b960b4ec59da8ac88ef9d87a8e92509e50686fae89ab34d9462a63e0eaba51","recorded_unix_us":1787932602721319,"recorded_utc":"2026-08-28T15:56:42.721319Z","schema_version":"nrrf810.exchange_authored_interactive_closure.v1","source_chain_continuous":true,"source_event":"order_deleted","source_event_id":"00065a1d-7fa7-8788-0001-000103000020","source_event_id_unique":true,"source_pre_event_id":"00065a1d-7fa7-8788-0000-000102000020","translation":"FOLD_RETURN_TO_ZERO","unfold_event_id":"00065a1d-7fa7-8788-0000-000102000020","zero_hair":true}
{"channel":"live_orders_btcusd","interaction_index":840,"natural_form":{"channel":"live_orders_btcusd","order_id":"2044303883649029","order_subtype":5,"order_type":1},"natural_form_sha256":"3a8d305e64bff57cdc46e976d0861295bf939fdd63a62f5599582d092ce6d83b","order_source":"orderbook","orders_submitted":0,"presentation":{"amount":"0.06310787","amount_traded":"0","microtimestamp":"1787932602502000","price":"78522.42"},"previous_record_hash":"c5b960b4ec59da8ac88ef9d87a8e92509e50686fae89ab34d9462a63e0eaba51","profit_assessment":null,"record_hash":"be39ac50b9e64a29ad22dd549158b8f991088ce1665c55928c213b3e0d0e88a9","recorded_unix_us":1787932602721472,"recorded_utc":"2026-08-28T15:56:42.721472Z","schema_version":"nrrf810.exchange_authored_interactive_closure.v1","source_chain_continuous":true,"source_event":"order_created","source_event_id":"00065a1d-7fa7-8b70-0000-000100000020","source_event_id_unique":true,"source_pre_event_id":"00065a1d-7fa7-8788-0001-000103000020","translation":"UNFOLD_TO_INF","unfold_event_id":null,"zero_hair":false}
{"channel":"live_orders_btcusd","interaction_index":841,"natural_form":{"channel":"live_orders_btcusd","order_id":"2044303883649029","order_subtype":5,"order_type":1},"natural_form_sha256":"3a8d305e64bff57cdc46e976d0861295bf939fdd63a62f5599582d092ce6d83b","order_source":"orderbook","orders_submitted":0,"presentation":{"amount":"0.06310787","amount_traded":"0","microtimestamp":"1787932602502000","price":"78522.42"},"previous_record_hash":"be39ac50b9e64a29ad22dd549158b8f991088ce1665c55928c213b3e0d0e88a9","profit_assessment":null,"record_hash":"f5b300b9c1fa0304fa831f503cf0e79e7f660dc87a9224873c485b21e8307918","recorded_unix_us":1787932602721507,"recorded_utc":"2026-08-28T15:56:42.721507Z","schema_version":"nrrf810.exchange_authored_interactive_closure.v1","source_chain_continuous":true,"source_event":"order_deleted","source_event_id":"00065a1d-7fa7-8b70-0001-000101000020","source_event_id_unique":true,"source_pre_event_id":"00065a1d-7fa7-8b70-0000-000100000020","translation":"FOLD_RETURN_TO_ZERO","unfold_event_id":"00065a1d-7fa7-8b70-0000-000100000020","zero_hair":true}
{"channel":"live_orders_btcusd","interaction_index":842,"natural_form":{"channel":"live_orders_btcusd","order_id":"2044303883653123","order_subtype":5,"order_type":1},"natural_form_sha256":"f2e3d9e758090d4907000777892c06bf8a8176a7b8b971d87c402ac2c6a81fca","order_source":"orderbook","orders_submitted":0,"presentation":{"amount":"0.06310787","amount_traded":"0","microtimestamp":"1787932602502000","price":"78520.06"},"previous_record_hash":"f5b300b9c1fa0304fa831f503cf0e79e7f660dc87a9224873c485b21e8307918","profit_assessment":null,"record_hash":"23102e4452161e00a5489e7b993fe867213136fa7a61f7a76fa6200c1bb12723","recorded_unix_us":1787932602721625,"recorded_utc":"2026-08-28T15:56:42.721625Z","schema_version":"nrrf810.exchange_authored_interactive_closure.v1","source_chain_continuous":true,"source_event":"order_created","source_event_id":"00065a1d-7fa7-8b70-0002-000102000020","source_event_id_unique":true,"source_pre_event_id":"00065a1d-7fa7-8b70-0001-000101000020","translation":"UNFOLD_TO_INF","unfold_event_id":null,"zero_hair":false}
{"channel":"live_orders_btcusd","interaction_index":843,"natural_form":{"channel":"live_orders_btcusd","order_id":"2044303883653123","order_subtype":5,"order_type":1},"natural_form_sha256":"f2e3d9e758090d4907000777892c06bf8a8176a7b8b971d87c402ac2c6a81fca","order_source":"orderbook","orders_submitted":0,"presentation":{"amount":"0.06310787","amount_traded":"0","microtimestamp":"1787932602502000","price":"78520.06"},"previous_record_hash":"23102e4452161e00a5489e7b993fe867213136fa7a61f7a76fa6200c1bb12723","profit_assessment":null,"record_hash":"77b939d6afd0776f469ee5df84d5c95acd8638fc607761a7d2ea9d433a7abaca","recorded_unix_us":1787932602721653,"recorded_utc":"2026-08-28T15:56:42.721653Z","schema_version":"nrrf810.exchange_authored_interactive_closure.v1","source_chain_continuous":true,"source_event":"order_deleted","source_event_id":"00065a1d-7fa7-8b70-0003-000103000020","source_event_id_unique":true,"source_pre_event_id":"00065a1d-7fa7-8b70-0002-000102000020","translation":"FOLD_RETURN_TO_ZERO","unfold_event_id":"00065a1d-7fa7-8b70-0002-000102000020","zero_hair":true}
{"channel":"live_orders_btcusd","interaction_index":844,"natural_form":{"channel":"live_orders_btcusd","order_id":"2044303883702276","order_subtype":5,"order_type":1},"natural_form_sha256":"df0a6eecd5885f162db79efad5076831eebae80960e09591755b0aa41cd7cd16","order_source":"orderbook","orders_submitted":0,"presentation":{"amount":"0.10000000","amount_traded":"0","microtimestamp":"1787932602515000","price":"78522.62"},"previous_record_hash":"77b939d6afd0776f469ee5df84d5c95acd8638fc607761a7d2ea9d433a7abaca","profit_assessment":null,"record_hash":"5adabbd1dbeeb8c64b65c7b32def7bcf508ad3c9ef8f557cb096784f596a6794","recorded_unix_us":1787932602721771,"recorded_utc":"2026-08-28T15:56:42.721771Z","schema_version":"nrrf810.exchange_authored_interactive_closure.v1","source_chain_continuous":true,"source_event":"order_created","source_event_id":"00065a1d-7fa7-be38-0000-000100000020","source_event_id_unique":true,"source_pre_event_id":"00065a1d-7fa7-8b70-0003-000103000020","translation":"UNFOLD_TO_INF","unfold_event_id":null,"zero_hair":false}
{"channel":"live_orders_btcusd","interaction_index":845,"natural_form":{"channel":"live_orders_btcusd","order_id":"2044303883702276","order_subtype":5,"order_type":1},"natural_form_sha256":"df0a6eecd5885f162db79efad5076831eebae80960e09591755b0aa41cd7cd16","order_source":"orderbook","orders_submitted":0,"presentation":{"amount":"0.10000000","amount_traded":"0","microtimestamp":"1787932602515000","price":"78522.62"},"previous_record_hash":"5adabbd1dbeeb8c64b65c7b32def7bcf508ad3c9ef8f557cb096784f596a6794","profit_assessment":null,"record_hash":"a30ea79a063106aba94786f1927984852a0cbfbb113d304c16ecb4c53a55cc69","recorded_unix_us":1787932602721799,"recorded_utc":"2026-08-28T15:56:42.721799Z","schema_version":"nrrf810.exchange_authored_interactive_closure.v1","source_chain_continuous":true,"source_event":"order_deleted","source_event_id":"00065a1d-7fa7-be38-0001-000101000020","source_event_id_unique":true,"source_pre_event_id":"00065a1d-7fa7-be38-0000-000100000020","translation":"FOLD_RETURN_TO_ZERO","unfold_event_id":"00065a1d-7fa7-be38-0000-000100000020","zero_hair":true}
{"channel":"live_orders_btcusd","interaction_index":846,"natural_form":{"channel":"live_orders_btcusd","order_id":"2044303883714560","order_subtype":5,"order_type":1},"natural_form_sha256":"fd48c6d3730c5f2252c6b56c388b7717990bc332f08b421bec537e900b357a29","order_source":"orderbook","orders_submitted":0,"presentation":{"amount":"0.06367384","amount_traded":"0","microtimestamp":"1787932602517000","price":"78525.19"},"previous_record_hash":"a30ea79a063106aba94786f1927984852a0cbfbb113d304c16ecb4c53a55cc69","profit_assessment":null,"record_hash":"0c7a189d205eac03a4e82971843b68b05b48a323060156c01d23fe2fbc90074a","recorded_unix_us":1787932602722681,"recorded_utc":"2026-08-28T15:56:42.722681Z","schema_version":"nrrf810.exchange_authored_interactive_closure.v1","source_chain_continuous":true,"source_event":"order_created","source_event_id":"00065a1d-7fa7-c608-0000-000102000020","source_event_id_unique":true,"source_pre_event_id":"00065a1d-7fa7-be38-0001-000101000020","translation":"UNFOLD_TO_INF","unfold_event_id":null,"zero_hair":false}
{"channel":"live_orders_btcusd","interaction_index":847,"natural_form":{"channel":"live_orders_btcusd","order_id":"2044303883714561","order_subtype":5,"order_type":1},"natural_form_sha256":"6153078f53cd3f0f562c826f17c5a150222f40ace8887fc5c39f43aaf26c9434","order_source":"orderbook","orders_submitted":0,"presentation":{"amount":"0.06367563","amount_traded":"0","microtimestamp":"1787932602518000","price":"78522.98"},"previous_record_hash":"0c7a189d205eac03a4e82971843b68b05b48a323060156c01d23fe2fbc90074a","profit_assessment":null,"record_hash":"8eeb7291e2454079ef93077804dad75fa51f0b313576635ac710407606681b5d","recorded_unix_us":1787932602722791,"recorded_utc":"2026-08-28T15:56:42.722791Z","schema_version":"nrrf810.exchange_authored_interactive_closure.v1","source_chain_continuous":true,"source_event":"order_created","source_event_id":"00065a1d-7fa7-c9f0-0000-000103000020","source_event_id_unique":true,"source_pre_event_id":"00065a1d-7fa7-c608-0000-000102000020","translation":"UNFOLD_TO_INF","unfold_event_id":null,"zero_hair":false}
{"channel":"live_orders_ethusd","interaction_index":848,"natural_form":{"channel":"live_orders_ethusd","order_id":"2044303501205504","order_subtype":5,"order_type":0},"natural_form_sha256":"78160a78a4b8bbb38d983947567e6d8a9325d6e87b3bffba33f271c238c34ac1","order_source":"orderbook","orders_submitted":0,"presentation":{"amount":"0.010000","amount_traded":"0","microtimestamp":"1787932602519000","price":"2469.50"},"previous_record_hash":"8eeb7291e2454079ef93077804dad75fa51f0b313576635ac710407606681b5d","profit_assessment":null,"record_hash":"47fa396b74632bc0da307cbe9b2416783b61ada2bfcc47d8c61964735f5484e4","recorded_unix_us":1787932602722921,"recorded_utc":"2026-08-28T15:56:42.722921Z","schema_version":"nrrf810.exchange_authored_interactive_closure.v1","source_chain_continuous":true,"source_event":"order_deleted","source_event_id":"00065a1d-7fa7-cdd8-0000-001202000020","source_event_id_unique":true,"source_pre_event_id":"00065a1d-7fa7-83a0-0000-001201000020","translation":"PARTIAL_PRIOR_UNFOLD","unfold_event_id":null,"zero_hair":false}
{"channel":"live_orders_btcusd","interaction_index":849,"natural_form":{"channel":"live_orders_btcusd","order_id":"2044303883722752","order_subtype":5,"order_type":0},"natural_form_sha256":"43bd3f1f54af80e476b936af1238ddd47c5be67432100cac419649eb6b1a1cb5","order_source":"orderbook","orders_submitted":0,"presentation":{"amount":"0.12000000","amount_traded":"0","microtimestamp":"1787932602519000","price":"78508.87"},"previous_record_hash":"47fa396b74632bc0da307cbe9b2416783b61ada2bfcc47d8c61964735f5484e4","profit_assessment":null,"record_hash":"bcd912c0b2a4ba73857d61cac539c59a3b1fa77818f2cd3cf65d399cb15b1ca0","recorded_unix_us":1787932602722952,"recorded_utc":"2026-08-28T15:56:42.722952Z","schema_version":"nrrf810.exchange_authored_interactive_closure.v1","source_chain_continuous":true,"source_event":"order_created","source_event_id":"00065a1d-7fa7-cdd8-0000-000100000020","source_event_id_unique":true,"source_pre_event_id":"00065a1d-7fa7-c9f0-0000-000103000020","translation":"UNFOLD_TO_INF","unfold_event_id":null,"zero_hair":false}
{"channel":"live_orders_btcusd","interaction_index":850,"natural_form":{"channel":"live_orders_btcusd","order_id":"2044303880900611","order_subtype":5,"order_type":0},"natural_form_sha256":"73afd6f4a07bb9e343d823a4ebc9f4f218873d75833f3a99c1e99c146671259c","order_source":"orderbook","orders_submitted":0,"presentation":{"amount":"0.12000000","amount_traded":"0","microtimestamp":"1787932602521000","price":"78508.22"},"previous_record_hash":"bcd912c0b2a4ba73857d61cac539c59a3b1fa77818f2cd3cf65d399cb15b1ca0","profit_assessment":null,"record_hash":"a6fe8081459c9818f68d8087e73a5e72c30b826b9de22804641585b962541706","recorded_unix_us":1787932602723039,"recorded_utc":"2026-08-28T15:56:42.723039Z","schema_version":"nrrf810.exchange_authored_interactive_closure.v1","source_chain_continuous":true,"source_event":"order_deleted","source_event_id":"00065a1d-7fa7-d5a8-0000-000101000020","source_event_id_unique":true,"source_pre_event_id":"00065a1d-7fa7-cdd8-0000-000100000020","translation":"FOLD_RETURN_TO_ZERO","unfold_event_id":"00065a1d-7f9d-4a70-0000-000103000020","zero_hair":true}
{"channel":"live_orders_btcusd","interaction_index":851,"natural_form":{"channel":"live_orders_btcusd","order_id":"2044303883739137","order_subtype":5,"order_type":1},"natural_form_sha256":"275684d6dc01dd080b06d767e73405df2409688e863ebbea47c6e5374652cc10","order_source":"orderbook","orders_submitted":0,"presentation":{"amount":"0.25467128","amount_traded":"0","microtimestamp":"1787932602523000","price":"78532.61"},"previous_record_hash":"a6fe8081459c9818f68d8087e73a5e72c30b826b9de22804641585b962541706","profit_assessment":null,"record_hash":"074fe4e0bd9e5df70b79a825fb9299cd0c9c68205bac917ae23a14dc06f36767","recorded_unix_us":1787932602723126,"recorded_utc":"2026-08-28T15:56:42.723126Z","schema_version":"nrrf810.exchange_authored_interactive_closure.v1","source_chain_continuous":true,"source_event":"order_created","source_event_id":"00065a1d-7fa7-dd78-0000-000102000020","source_event_id_unique":true,"source_pre_event_id":"00065a1d-7fa7-d5a8-0000-000101000020","translation":"UNFOLD_TO_INF","unfold_event_id":null,"zero_hair":false}
{"channel":"live_orders_btcusd","interaction_index":852,"natural_form":{"channel":"live_orders_btcusd","order_id":"2044303883747328","order_subtype":5,"order_type":1},"natural_form_sha256":"6970f2a5026ccb2c367c1deeb0d4e95ba5e54bbc4356caa7b2f739c532e727e7","order_source":"orderbook","orders_submitted":0,"presentation":{"amount":"1.27209222","amount_traded":"0","microtimestamp":"1787932602526000","price":"78610.66"},"previous_record_hash":"074fe4e0bd9e5df70b79a825fb9299cd0c9c68205bac917ae23a14dc06f36767","profit_assessment":null,"record_hash":"1b5e9225650438f13c5b37a9b9c47122deb768112b4ff854da9552359ac0ef7b","recorded_unix_us":1787932602723245,"recorded_utc":"2026-08-28T15:56:42.723245Z","schema_version":"nrrf810.exchange_authored_interactive_closure.v1","source_chain_continuous":true,"source_event":"order_created","source_event_id":"00065a1d-7fa7-e930-0000-000103000020","source_event_id_unique":true,"source_pre_event_id":"00065a1d-7fa7-dd78-0000-000102000020","translation":"UNFOLD_TO_INF","unfold_event_id":null,"zero_hair":false}
{"channel":"live_orders_btcusd","interaction_index":853,"natural_form":{"channel":"live_orders_btcusd","order_id":"2044303883747329","order_subtype":5,"order_type":1},"natural_form_sha256":"296d1cb4a0a323cc2a428b0132017e22fb75b1af875463acaff9b37e726d17bd","order_source":"orderbook","orders_submitted":0,"presentation":{"amount":"0.25466146","amount_traded":"0","microtimestamp":"1787932602526000","price":"78535.64"},"previous_record_hash":"1b5e9225650438f13c5b37a9b9c47122deb768112b4ff854da9552359ac0ef7b","profit_assessment":null,"record_hash":"b02b291791af1bb6f6e6c949b5dd10333db31a66b2e6046b1a67f452d442206f","recorded_unix_us":1787932602723274,"recorded_utc":"2026-08-28T15:56:42.723274Z","schema_version":"nrrf810.exchange_authored_interactive_closure.v1","source_chain_continuous":true,"source_event":"order_created","source_event_id":"00065a1d-7fa7-e930-0001-000100000020","source_event_id_unique":true,"source_pre_event_id":"00065a1d-7fa7-e930-0000-000103000020","translation":"UNFOLD_TO_INF","unfold_event_id":null,"zero_hair":false}
{"channel":"live_orders_btcusd","interaction_index":854,"natural_form":{"channel":"live_orders_btcusd","order_id":"2044303883751424","order_subtype":5,"order_type":1},"natural_form_sha256":"678f79a9931d54b54b2ce0e59b9e9a09b5d18939ea07c665ffbe44f4bf39be78","order_source":"orderbook","orders_submitted":0,"presentation":{"amount":"12.70451953","amount_traded":"0","microtimestamp":"1787932602526000","price":"78712.15"},"previous_record_hash":"b02b291791af1bb6f6e6c949b5dd10333db31a66b2e6046b1a67f452d442206f","profit_assessment":null,"record_hash":"4640c310d44e58c9a093d3fb20b6710a3cf66967f54c1265504f19e3f437f162","recorded_unix_us":1787932602723362,"recorded_utc":"2026-08-28T15:56:42.723362Z","schema_version":"nrrf810.exchange_authored_interactive_closure.v1","source_chain_continuous":true,"source_event":"order_created","source_event_id":"00065a1d-7fa7-e930-0002-000101000020","source_event_id_unique":true,"source_pre_event_id":"00065a1d-7fa7-e930-0001-000100000020","translation":"UNFOLD_TO_INF","unfold_event_id":null,"zero_hair":false}
{"channel":"live_orders_btcusd","interaction_index":855,"natural_form":{"channel":"live_orders_btcusd","order_id":"2044303882887181","order_subtype":5,"order_type":0},"natural_form_sha256":"4c92c813b470fdf1dcaa431fe4a741aac20cb23234834718128d0bdfc113cb95","order_source":"orderbook","orders_submitted":0,"presentation":{"amount":"0.19103770","amount_traded":"0","microtimestamp":"1787932602528000","price":"78485.00"},"previous_record_hash":"4640c310d44e58c9a093d3fb20b6710a3cf66967f54c1265504f19e3f437f162","profit_assessment":null,"record_hash":"123e3cf4b40d786b9c0b93152693eb69c823288f7a1350b1588d9e9370a27f25","recorded_unix_us":1787932602723513,"recorded_utc":"2026-08-28T15:56:42.723513Z","schema_version":"nrrf810.exchange_authored_interactive_closure.v1","source_chain_continuous":true,"source_event":"order_deleted","source_event_id":"00065a1d-7fa7-f100-0000-000102000020","source_event_id_unique":true,"source_pre_event_id":"00065a1d-7fa7-e930-0002-000101000020","translation":"FOLD_RETURN_TO_ZERO","unfold_event_id":"00065a1d-7fa4-b4e0-0000-000101000020","zero_hair":true}
{"channel":"live_orders_btcusd","interaction_index":856,"natural_form":{"channel":"live_orders_btcusd","order_id":"2044303883759619","order_subtype":5,"order_type":1},"natural_form_sha256":"df17850bf4cbe90ff96bf5a6f4a3e34a1d6e3b6c39c395db6d46fa8b88a00d5b","order_source":"orderbook","orders_submitted":0,"presentation":{"amount":"0.06310787","amount_traded":"0","microtimestamp":"1787932602528000","price":"78522.42"},"previous_record_hash":"123e3cf4b40d786b9c0b93152693eb69c823288f7a1350b1588d9e9370a27f25","profit_assessment":null,"record_hash":"2e04ffb08c311f9db671d477c0ac364f463788367838e459b4f696784a9cb74b","recorded_unix_us":1787932602723542,"recorded_utc":"2026-08-28T15:56:42.723542Z","schema_version":"nrrf810.exchange_authored_interactive_closure.v1","source_chain_continuous":true,"source_event":"order_created","source_event_id":"00065a1d-7fa7-f100-0001-000103000020","source_event_id_unique":true,"source_pre_event_id":"00065a1d-7fa7-f100-0000-000102000020","translation":"UNFOLD_TO_INF","unfold_event_id":null,"zero_hair":false}
{"channel":"live_orders_btcusd","interaction_index":857,"natural_form":{"channel":"live_orders_btcusd","order_id":"2044303883759619","order_subtype":5,"order_type":1},"natural_form_sha256":"df17850bf4cbe90ff96bf5a6f4a3e34a1d6e3b6c39c395db6d46fa8b88a00d5b","order_source":"orderbook","orders_submitted":0,"presentation":{"amount":"0.06310787","amount_traded":"0","microtimestamp":"1787932602528000","price":"78522.42"},"previous_record_hash":"2e04ffb08c311f9db671d477c0ac364f463788367838e459b4f696784a9cb74b","profit_assessment":null,"record_hash":"ba9ffd90eb828f46019f2fd861a7357e824f43a2d9d0eeb066ec50b16624d2ef","recorded_unix_us":1787932602723569,"recorded_utc":"2026-08-28T15:56:42.723569Z","schema_version":"nrrf810.exchange_authored_interactive_closure.v1","source_chain_continuous":true,"source_event":"order_deleted","source_event_id":"00065a1d-7fa7-f100-0002-000100000020","source_event_id_unique":true,"source_pre_event_id":"00065a1d-7fa7-f100-0001-000103000020","translation":"FOLD_RETURN_TO_ZERO","unfold_event_id":"00065a1d-7fa7-f100-0001-000103000020","zero_hair":true}
{"channel":"live_orders_btcusd","interaction_index":858,"natural_form":{"channel":"live_orders_btcusd","order_id":"2044303883780096","order_subtype":5,"order_type":1},"natural_form_sha256":"5764d5f04a97be276b582579a60681ba8e7b9146e9b04c351552184dea101828","order_source":"orderbook","orders_submitted":0,"presentation":{"amount":"0.10000000","amount_traded":"0","microtimestamp":"1787932602533000","price":"78522.63"},"previous_record_hash":"ba9ffd90eb828f46019f2fd861a7357e824f43a2d9d0eeb066ec50b16624d2ef","profit_assessment":null,"record_hash":"ad5079ed65364bd255298c692f9d270d3af16023afd4edb74867a8e1ad45f70a","recorded_unix_us":1787932602723661,"recorded_utc":"2026-08-28T15:56:42.723661Z","schema_version":"nrrf810.exchange_authored_interactive_closure.v1","source_chain_continuous":true,"source_event":"order_created","source_event_id":"00065a1d-7fa8-0488-0000-000101000020","source_event_id_unique":true,"source_pre_event_id":"00065a1d-7fa7-f100-0002-000100000020","translation":"UNFOLD_TO_INF","unfold_event_id":null,"zero_hair":false}
{"channel":"live_orders_btcusd","interaction_index":859,"natural_form":{"channel":"live_orders_btcusd","order_id":"2044303883780096","order_subtype":5,"order_type":1},"natural_form_sha256":"5764d5f04a97be276b582579a60681ba8e7b9146e9b04c351552184dea101828","order_source":"orderbook","orders_submitted":0,"presentation":{"amount":"0.10000000","amount_traded":"0","microtimestamp":"1787932602533000","price":"78522.63"},"previous_record_hash":"ad5079ed65364bd255298c692f9d270d3af16023afd4edb74867a8e1ad45f70a","profit_assessment":null,"record_hash":"e86aae822bd2f47766faa9dbe3ab7c557ba25ee3483e3eb337f28676d2eb4059","recorded_unix_us":1787932602723743,"recorded_utc":"2026-08-28T15:56:42.723743Z","schema_version":"nrrf810.exchange_authored_interactive_closure.v1","source_chain_continuous":true,"source_event":"order_deleted","source_event_id":"00065a1d-7fa8-0488-0001-000102000020","source_event_id_unique":true,"source_pre_event_id":"00065a1d-7fa8-0488-0000-000101000020","translation":"FOLD_RETURN_TO_ZERO","unfold_event_id":"00065a1d-7fa8-0488-0000-000101000020","zero_hair":true}
{"channel":"live_orders_btcusd","interaction_index":860,"natural_form":{"channel":"live_orders_btcusd","order_id":"2044303883784192","order_subtype":5,"order_type":0},"natural_form_sha256":"95ba080be7cb3d17441f75408e9376a6ba8517b4662241e8fd8c3fc2c6f7c0eb","order_source":"orderbook","orders_submitted":0,"presentation":{"amount":"0.00254770","amount_traded":"0","microtimestamp":"1787932602535000","price":"78502.27"},"previous_record_hash":"e86aae822bd2f47766faa9dbe3ab7c557ba25ee3483e3eb337f28676d2eb4059","profit_assessment":null,"record_hash":"d63a3417cb59f1d31ac354b209363aa55d46b5470ecabb83a517895d216cc50c","recorded_unix_us":1787932602723877,"recorded_utc":"2026-08-28T15:56:42.723877Z","schema_version":"nrrf810.exchange_authored_interactive_closure.v1","source_chain_continuous":true,"source_event":"order_created","source_event_id":"00065a1d-7fa8-0c58-0000-000103000020","source_event_id_unique":true,"source_pre_event_id":"00065a1d-7fa8-0488-0001-000102000020","translation":"UNFOLD_TO_INF","unfold_event_id":null,"zero_hair":false}
{"channel":"live_orders_btcusd","interaction_index":861,"natural_form":{"channel":"live_orders_btcusd","order_id":"2044303883788289","order_subtype":5,"order_type":1},"natural_form_sha256":"f4e3090b39ed8ac30d8fa4fd85430664d40f0691d4e05b5fc1fc2e3287dbff3c","order_source":"orderbook","orders_submitted":0,"presentation":{"amount":"1.26970017","amount_traded":"0","microtimestamp":"1787932602535000","price":"78758.76"},"previous_record_hash":"d63a3417cb59f1d31ac354b209363aa55d46b5470ecabb83a517895d216cc50c","profit_assessment":null,"record_hash":"b27f65322682103172a208f19e3625712aa06542a5cb9ddfeb7673904734d15a","recorded_unix_us":1787932602723906,"recorded_utc":"2026-08-28T15:56:42.723906Z","schema_version":"nrrf810.exchange_authored_interactive_closure.v1","source_chain_continuous":true,"source_event":"order_created","source_event_id":"00065a1d-7fa8-0c58-0001-000100000020","source_event_id_unique":true,"source_pre_event_id":"00065a1d-7fa8-0c58-0000-000103000020","translation":"UNFOLD_TO_INF","unfold_event_id":null,"zero_hair":false}
{"channel":"live_orders_btcusd","interaction_index":862,"natural_form":{"channel":"live_orders_btcusd","order_id":"2044303883804675","order_subtype":5,"order_type":0},"natural_form_sha256":"0d52b3ce333d659076743ba9536ee72f475a000c9205f5f8f16fa158a2ca7696","order_source":"orderbook","orders_submitted":0,"presentation":{"amount":"0.19103750","amount_traded":"0","microtimestamp":"1787932602540000","price":"78485.88"},"previous_record_hash":"b27f65322682103172a208f19e3625712aa06542a5cb9ddfeb7673904734d15a","profit_assessment":null,"record_hash":"7fd1bed45a86742e4f5fe99015b5263aea20afe52c318c83068b206eae5cd83c","recorded_unix_us":1787932602724016,"recorded_utc":"2026-08-28T15:56:42.724016Z","schema_version":"nrrf810.exchange_authored_interactive_closure.v1","source_chain_continuous":true,"source_event":"order_created","source_event_id":"00065a1d-7fa8-1fe0-0000-000101000020","source_event_id_unique":true,"source_pre_event_id":"00065a1d-7fa8-0c58-0001-000100000020","translation":"UNFOLD_TO_INF","unfold_event_id":null,"zero_hair":false}
{"channel":"live_orders_btcusd","interaction_index":863,"natural_form":{"channel":"live_orders_btcusd","order_id":"2044303883808770","order_subtype":5,"order_type":1},"natural_form_sha256":"f105d2f5025a1e1b1d0c40820b78ffded8c8ca22bc377539f7db81d592d462c0","order_source":"orderbook","orders_submitted":0,"presentation":{"amount":"1.26840120","amount_traded":"0","microtimestamp":"1787932602541000","price":"78839.41"},"previous_record_hash":"7fd1bed45a86742e4f5fe99015b5263aea20afe52c318c83068b206eae5cd83c","profit_assessment":null,"record_hash":"50e10b786c26e9ee05abcf4097ca7dbc1a17f9c7502dbf4aeda7396cc677b4a0","recorded_unix_us":1787932602724178,"recorded_utc":"2026-08-28T15:56:42.724178Z","schema_version":"nrrf810.exchange_authored_interactive_closure.v1","source_chain_continuous":true,"source_event":"order_created","source_event_id":"00065a1d-7fa8-23c8-0000-000102000020","source_event_id_unique":true,"source_pre_event_id":"00065a1d-7fa8-1fe0-0000-000101000020","translation":"UNFOLD_TO_INF","unfold_event_id":null,"zero_hair":false}
{"channel":"live_orders_btcusd","interaction_index":864,"natural_form":{"channel":"live_orders_btcusd","order_id":"2044303883812868","order_subtype":5,"order_type":0},"natural_form_sha256":"949f9a1184c1b730d3e58d792b6029b046149fc53a034ce888ca05e66d0040cf","order_source":"orderbook","orders_submitted":0,"presentation":{"amount":"0.06367953","amount_traded":"0","microtimestamp":"1787932602541000","price":"78518.15"},"previous_record_hash":"50e10b786c26e9ee05abcf4097ca7dbc1a17f9c7502dbf4aeda7396cc677b4a0","profit_assessment":null,"record_hash":"9916c6db5352413c70cbf89537ad4bb5af2928ce2a15bbff03f77c66404acda5","recorded_unix_us":1787932602724232,"recorded_utc":"2026-08-28T15:56:42.724232Z","schema_version":"nrrf810.exchange_authored_interactive_closure.v1","source_chain_continuous":true,"source_event":"order_created","source_event_id":"00065a1d-7fa8-23c8-0001-000103000020","source_event_id_unique":true,"source_pre_event_id":"00065a1d-7fa8-23c8-0000-000102000020","translation":"UNFOLD_TO_INF","unfold_event_id":null,"zero_hair":false}
{"channel":"live_orders_btcusd","interaction_index":865,"natural_form":{"channel":"live_orders_btcusd","order_id":"2044303883816968","order_subtype":5,"order_type":1},"natural_form_sha256":"ac1869c0b2748ddb5340b89afc74dff11411e18abc474df211b2e5de18cccd61","order_source":"orderbook","orders_submitted":0,"presentation":{"amount":"0.06310787","amount_traded":"0","microtimestamp":"1787932602542000","price":"78520.06"},"previous_record_hash":"9916c6db5352413c70cbf89537ad4bb5af2928ce2a15bbff03f77c66404acda5","profit_assessment":null,"record_hash":"b372b75fffb456be00962f348e41f24457beec0c4214efc4bab8b698f1203032","recorded_unix_us":1787932602724341,"recorded_utc":"2026-08-28T15:56:42.724341Z","schema_version":"nrrf810.exchange_authored_interactive_closure.v1","source_chain_continuous":true,"source_event":"order_created","source_event_id":"00065a1d-7fa8-27b0-0000-000100000020","source_event_id_unique":true,"source_pre_event_id":"00065a1d-7fa8-23c8-0001-000103000020","translation":"UNFOLD_TO_INF","unfold_event_id":null,"zero_hair":false}
{"channel":"live_orders_btcusd","interaction_index":866,"natural_form":{"channel":"live_orders_btcusd","order_id":"2044303883816968","order_subtype":5,"order_type":1},"natural_form_sha256":"ac1869c0b2748ddb5340b89afc74dff11411e18abc474df211b2e5de18cccd61","order_source":"orderbook","orders_submitted":0,"presentation":{"amount":"0.06310787","amount_traded":"0","microtimestamp":"1787932602542000","price":"78520.06"},"previous_record_hash":"b372b75fffb456be00962f348e41f24457beec0c4214efc4bab8b698f1203032","profit_assessment":null,"record_hash":"4226561b06dded1d11c976a356833fa67bd66f41e50a9dbe7bda2a2ab5bc836f","recorded_unix_us":1787932602724440,"recorded_utc":"2026-08-28T15:56:42.724440Z","schema_version":"nrrf810.exchange_authored_interactive_closure.v1","source_chain_continuous":true,"source_event":"order_deleted","source_event_id":"00065a1d-7fa8-27b0-0001-000101000020","source_event_id_unique":true,"source_pre_event_id":"00065a1d-7fa8-27b0-0000-000100000020","translation":"FOLD_RETURN_TO_ZERO","unfold_event_id":"00065a1d-7fa8-27b0-0000-000100000020","zero_hair":true}
{"channel":"live_orders_btcusd","interaction_index":867,"natural_form":{"channel":"live_orders_btcusd","order_id":"2044303883837446","order_subtype":5,"order_type":0},"natural_form_sha256":"8c77fd5267b7f460edc60abcf6a306c893be17b54955bbbdb6f6d76b58ceff43","order_source":"orderbook","orders_submitted":0,"presentation":{"amount":"0.00140266","amount_traded":"0","microtimestamp":"1787932602547000","price":"70666.76"},"previous_record_hash":"4226561b06dded1d11c976a356833fa67bd66f41e50a9dbe7bda2a2ab5bc836f","profit_assessment":null,"record_hash":"4e36b2777e4937bdb9cbb714e00a8d33db2d8f19c9c2a46e049121c56453d54f","recorded_unix_us":1787932602724590,"recorded_utc":"2026-08-28T15:56:42.724590Z","schema_version":"nrrf810.exchange_authored_interactive_closure.v1","source_chain_continuous":true,"source_event":"order_created","source_event_id":"00065a1d-7fa8-3b38-0000-000102000020","source_event_id_unique":true,"source_pre_event_id":"00065a1d-7fa8-27b0-0001-000101000020","translation":"UNFOLD_TO_INF","unfold_event_id":null,"zero_hair":false}
{"channel":"live_orders_ethbtc","interaction_index":868,"natural_form":{"channel":"live_orders_ethbtc","order_id":"2044303876780035","order_subtype":0,"order_type":0},"natural_form_sha256":"f6da6dd04dc650aa5b7d24e76d4aed21f93c1887b2a85c771ed5bf6b613bf9cc","order_source":"orderbook","orders_submitted":0,"presentation":{"amount":"1.50014000","amount_traded":"0","microtimestamp":"1787932602549000","price":"0.03017117"},"previous_record_hash":"4e36b2777e4937bdb9cbb714e00a8d33db2d8f19c9c2a46e049121c56453d54f","profit_assessment":null,"record_hash":"383d346c5db6e8f285f498b811b1c84b23c89a0967702345b8f57f0bd0ceb288","recorded_unix_us":1787932602724717,"recorded_utc":"2026-08-28T15:56:42.724717Z","schema_version":"nrrf810.exchange_authored_interactive_closure.v1","source_chain_continuous":true,"source_event":"order_deleted","source_event_id":"00065a1d-7fa8-4308-0000-001100000020","source_event_id_unique":true,"source_pre_event_id":"00065a1d-7fa7-0e70-0001-001103000020","translation":"PARTIAL_PRIOR_UNFOLD","unfold_event_id":null,"zero_hair":false}
{"channel":"live_orders_btcusd","interaction_index":869,"natural_form":{"channel":"live_orders_btcusd","order_id":"2044303883849734","order_subtype":5,"order_type":1},"natural_form_sha256":"fd96c6b681b4f48207f48e8be47d7cb82b4417e74558ba3deef3b4b866ecf419","order_source":"orderbook","orders_submitted":0,"presentation":{"amount":"0.10000000","amount_traded":"0","microtimestamp":"1787932602551000","price":"78522.62"},"previous_record_hash":"383d346c5db6e8f285f498b811b1c84b23c89a0967702345b8f57f0bd0ceb288","profit_assessment":null,"record_hash":"f5364801adbb3f4da9e9b64dd7101524e3aa6fedd5dfeb9ded58576c422a36d1","recorded_unix_us":1787932602724836,"recorded_utc":"2026-08-28T15:56:42.724836Z","schema_version":"nrrf810.exchange_authored_interactive_closure.v1","source_chain_continuous":true,"source_event":"order_created","source_event_id":"00065a1d-7fa8-4ad8-0000-000103000020","source_event_id_unique":true,"source_pre_event_id":"00065a1d-7fa8-3b38-0000-000102000020","translation":"UNFOLD_TO_INF","unfold_event_id":null,"zero_hair":false}
{"channel":"live_orders_btcusd","interaction_index":870,"natural_form":{"channel":"live_orders_btcusd","order_id":"2044303883849734","order_subtype":5,"order_type":1},"natural_form_sha256":"fd96c6b681b4f48207f48e8be47d7cb82b4417e74558ba3deef3b4b866ecf419","order_source":"orderbook","orders_submitted":0,"presentation":{"amount":"0.10000000","amount_traded":"0","microtimestamp":"1787932602551000","price":"78522.62"},"previous_record_hash":"f5364801adbb3f4da9e9b64dd7101524e3aa6fedd5dfeb9ded58576c422a36d1","profit_assessment":null,"record_hash":"b5e5c7f9d10df431dd1a61e9a1c63086d398ac297d39f814b98212a9c4c8bb53","recorded_unix_us":1787932602724933,"recorded_utc":"2026-08-28T15:56:42.724933Z","schema_version":"nrrf810.exchange_authored_interactive_closure.v1","source_chain_continuous":true,"source_event":"order_deleted","source_event_id":"00065a1d-7fa8-4ad8-0001-000100000020","source_event_id_unique":true,"source_pre_event_id":"00065a1d-7fa8-4ad8-0000-000103000020","translation":"FOLD_RETURN_TO_ZERO","unfold_event_id":"00065a1d-7fa8-4ad8-0000-000103000020","zero_hair":true}
{"channel":"live_orders_btcusd","interaction_index":871,"natural_form":{"channel":"live_orders_btcusd","order_id":"2044303883866122","order_subtype":5,"order_type":0},"natural_form_sha256":"31a68f6cdedbb516df850561d44f0206c4a907fbde22d56d3996b30cb4957a32","order_source":"orderbook","orders_submitted":0,"presentation":{"amount":"0.06368171","amount_traded":"0","microtimestamp":"1787932602555000","price":"78515.46"},"previous_record_hash":"b5e5c7f9d10df431dd1a61e9a1c63086d398ac297d39f814b98212a9c4c8bb53","profit_assessment":null,"record_hash":"c6ec830ceaad3011fb5c7e56b3eefdd5c4ee4c5c9db8a7743378fdea502296f9","recorded_unix_us":1787932602725075,"recorded_utc":"2026-08-28T15:56:42.725075Z","schema_version":"nrrf810.exchange_authored_interactive_closure.v1","source_chain_continuous":true,"source_event":"order_created","source_event_id":"00065a1d-7fa8-5a78-0000-000101000020","source_event_id_unique":true,"source_pre_event_id":"00065a1d-7fa8-4ad8-0001-000100000020","translation":"UNFOLD_TO_INF","unfold_event_id":null,"zero_hair":false}
{"channel":"live_orders_btcusd","interaction_index":872,"natural_form":{"channel":"live_orders_btcusd","order_id":"2044303883870209","order_subtype":5,"order_type":0},"natural_form_sha256":"5bb292bef2f936ce4a9d443d1b561f75278b343f749d888a39b6d3334428ca86","order_source":"orderbook","orders_submitted":0,"presentation":{"amount":"0.25476924","amount_traded":"0","microtimestamp":"1787932602556000","price":"78502.41"},"previous_record_hash":"c6ec830ceaad3011fb5c7e56b3eefdd5c4ee4c5c9db8a7743378fdea502296f9","profit_assessment":null,"record_hash":"fd39b7499a156b429769bd6de2704686b47a5666ba8650649ed30e192d6770f5","recorded_unix_us":1787932602725106,"recorded_utc":"2026-08-28T15:56:42.725106Z","schema_version":"nrrf810.exchange_authored_interactive_closure.v1","source_chain_continuous":true,"source_event":"order_created","source_event_id":"00065a1d-7fa8-5e60-0000-000102000020","source_event_id_unique":true,"source_pre_event_id":"00065a1d-7fa8-5a78-0000-000101000020","translation":"UNFOLD_TO_INF","unfold_event_id":null,"zero_hair":false}
{"channel":"live_orders_btcusd","interaction_index":873,"natural_form":{"channel":"live_orders_btcusd","order_id":"2044303883874305","order_subtype":5,"order_type":1},"natural_form_sha256":"7df7636f026e1deaf08569542dca9c6ad905965973cb3c61d327e5d4e7da1853","order_source":"orderbook","orders_submitted":0,"presentation":{"amount":"0.06310787","amount_traded":"0","microtimestamp":"1787932602556000","price":"78522.42"},"previous_record_hash":"fd39b7499a156b429769bd6de2704686b47a5666ba8650649ed30e192d6770f5","profit_assessment":null,"record_hash":"13a548903ef77016a4589bffa7558bb8821f5261745eb8feb0b0b7ce255a1b87","recorded_unix_us":1787932602725200,"recorded_utc":"2026-08-28T15:56:42.725200Z","schema_version":"nrrf810.exchange_authored_interactive_closure.v1","source_chain_continuous":true,"source_event":"order_created","source_event_id":"00065a1d-7fa8-5e60-0001-000103000020","source_event_id_unique":true,"source_pre_event_id":"00065a1d-7fa8-5e60-0000-000102000020","translation":"UNFOLD_TO_INF","unfold_event_id":null,"zero_hair":false}
{"channel":"live_orders_btcusd","interaction_index":874,"natural_form":{"channel":"live_orders_btcusd","order_id":"2044303883874305","order_subtype":5,"order_type":1},"natural_form_sha256":"7df7636f026e1deaf08569542dca9c6ad905965973cb3c61d327e5d4e7da1853","order_source":"orderbook","orders_submitted":0,"presentation":{"amount":"0.06310787","amount_traded":"0","microtimestamp":"1787932602556000","price":"78522.42"},"previous_record_hash":"13a548903ef77016a4589bffa7558bb8821f5261745eb8feb0b0b7ce255a1b87","profit_assessment":null,"record_hash":"7eac4458bbd77baf30c366030a78665f2640fc0993b6c4a5b2b616c311ca118b","recorded_unix_us":1787932602725310,"recorded_utc":"2026-08-28T15:56:42.725310Z","schema_version":"nrrf810.exchange_authored_interactive_closure.v1","source_chain_continuous":true,"source_event":"order_deleted","source_event_id":"00065a1d-7fa8-5e60-0002-000100000020","source_event_id_unique":true,"source_pre_event_id":"00065a1d-7fa8-5e60-0001-000103000020","translation":"FOLD_RETURN_TO_ZERO","unfold_event_id":"00065a1d-7fa8-5e60-0001-000103000020","zero_hair":true}
{"channel":"live_orders_ethusd","interaction_index":875,"natural_form":{"channel":"live_orders_ethusd","order_id":"2044303883882502","order_subtype":5,"order_type":0},"natural_form_sha256":"d81ca9ed159c7b1eb0ab41598e4ca5215c825f09113df8729859687cdf2d7928","order_source":"orderbook","orders_submitted":0,"presentation":{"amount":"2.540413","amount_traded":"0","microtimestamp":"1787932602559000","price":"2455.46"},"previous_record_hash":"7eac4458bbd77baf30c366030a78665f2640fc0993b6c4a5b2b616c311ca118b","profit_assessment":null,"record_hash":"527a957068c83325f9d21246913cb79daef0d145f5d58b585a803e53ca837d5b","recorded_unix_us":1787932602739367,"recorded_utc":"2026-08-28T15:56:42.739367Z","schema_version":"nrrf810.exchange_authored_interactive_closure.v1","source_chain_continuous":true,"source_event":"order_created","source_event_id":"00065a1d-7fa8-6a18-0000-001203000020","source_event_id_unique":true,"source_pre_event_id":"00065a1d-7fa7-cdd8-0000-001202000020","translation":"UNFOLD_TO_INF","unfold_event_id":null,"zero_hair":false}
{"channel":"live_orders_btcusd","interaction_index":876,"natural_form":{"channel":"live_orders_btcusd","order_id":"2044303883882503","order_subtype":5,"order_type":1},"natural_form_sha256":"d6b8ecb74777821a81d1fd5b1f91c6d5ed8e5c2e9334894059571fbb537654b1","order_source":"orderbook","orders_submitted":0,"presentation":{"amount":"0.12000000","amount_traded":"0","microtimestamp":"1787932602559000","price":"78541.00"},"previous_record_hash":"527a957068c83325f9d21246913cb79daef0d145f5d58b585a803e53ca837d5b","profit_assessment":null,"record_hash":"dfb5378929c4dd6bb15b7b66c1eddcc9d293f02f3fddf5fd8e201f1b731caea8","recorded_unix_us":1787932602739562,"recorded_utc":"2026-08-28T15:56:42.739562Z","schema_version":"nrrf810.exchange_authored_interactive_closure.v1","source_chain_continuous":true,"source_event":"order_created","source_event_id":"00065a1d-7fa8-6a18-0000-000101000020","source_event_id_unique":true,"source_pre_event_id":"00065a1d-7fa8-5e60-0002-000100000020","translation":"UNFOLD_TO_INF","unfold_event_id":null,"zero_hair":false}
{"channel":"live_orders_btcusd","interaction_index":877,"natural_form":{"channel":"live_orders_btcusd","order_id":"2044303883882503","order_subtype":5,"order_type":1},"natural_form_sha256":"d6b8ecb74777821a81d1fd5b1f91c6d5ed8e5c2e9334894059571fbb537654b1","order_source":"orderbook","orders_submitted":0,"presentation":{"amount":"0.12000000","amount_traded":"0","microtimestamp":"1787932602565000","price":"78541.00"},"previous_record_hash":"dfb5378929c4dd6bb15b7b66c1eddcc9d293f02f3fddf5fd8e201f1b731caea8","profit_assessment":null,"record_hash":"8a460eeacdd04c78d3fbec18eccad48a6abe65351da48037a8f84dc7bf753645","recorded_unix_us":1787932602739737,"recorded_utc":"2026-08-28T15:56:42.739737Z","schema_version":"nrrf810.exchange_authored_interactive_closure.v1","source_chain_continuous":true,"source_event":"order_deleted","source_event_id":"00065a1d-7fa8-8188-0000-000102000020","source_event_id_unique":true,"source_pre_event_id":"00065a1d-7fa8-6a18-0000-000101000020","translation":"FOLD_RETURN_TO_ZERO","unfold_event_id":"00065a1d-7fa8-6a18-0000-000101000020","zero_hair":true}
{"channel":"live_orders_btcusd","interaction_index":878,"natural_form":{"channel":"live_orders_btcusd","order_id":"2044303883919360","order_subtype":5,"order_type":0},"natural_form_sha256":"32c160eab5c6ebdbf05aa95de9a9eba6ca1160b44ca71d43146c0281612c8310","order_source":"orderbook","orders_submitted":0,"presentation":{"amount":"0.25478772","amount_traded":"0","microtimestamp":"1787932602567000","price":"78496.71"},"previous_record_hash":"8a460eeacdd04c78d3fbec18eccad48a6abe65351da48037a8f84dc7bf753645","profit_assessment":null,"record_hash":"e288e409e108b5a615d2533dd9f6bea8f9e1c549ad9388c806e911f84af1dcf0","recorded_unix_us":1787932602739874,"recorded_utc":"2026-08-28T15:56:42.739874Z","schema_version":"nrrf810.exchange_authored_interactive_closure.v1","source_chain_continuous":true,"source_event":"order_created","source_event_id":"00065a1d-7fa8-8958-0000-000103000020","source_event_id_unique":true,"source_pre_event_id":"00065a1d-7fa8-8188-0000-000102000020","translation":"UNFOLD_TO_INF","unfold_event_id":null,"zero_hair":false}
{"channel":"live_orders_btcusd","interaction_index":879,"natural_form":{"channel":"live_orders_btcusd","order_id":"2044303883927552","order_subtype":5,"order_type":0},"natural_form_sha256":"b4c387808ef4748616b52561d9ce8eeed5a9d26434a9bdca2287f705e33f8e53","order_source":"orderbook","orders_submitted":0,"presentation":{"amount":"1.27507828","amount_traded":"0","microtimestamp":"1787932602569000","price":"78426.55"},"previous_record_hash":"e288e409e108b5a615d2533dd9f6bea8f9e1c549ad9388c806e911f84af1dcf0","profit_assessment":null,"record_hash":"85027e3818c97e444b202f503944a91d3d5c1cd7c35e503694e0f42f350540ff","recorded_unix_us":1787932602739992,"recorded_utc":"2026-08-28T15:56:42.739992Z","schema_version":"nrrf810.exchange_authored_interactive_closure.v1","source_chain_continuous":true,"source_event":"order_created","source_event_id":"00065a1d-7fa8-9128-0000-000100000020","source_event_id_unique":true,"source_pre_event_id":"00065a1d-7fa8-8958-0000-000103000020","translation":"UNFOLD_TO_INF","unfold_event_id":null,"zero_hair":false}
{"channel":"live_orders_ethusd","interaction_index":880,"natural_form":{"channel":"live_orders_ethusd","order_id":"2044303883931649","order_subtype":5,"order_type":0},"natural_form_sha256":"e6c34cfd4130b2222326c458c1dd36ba70328f73c64cc712d4cd1d9d4132b66c","order_source":"orderbook","orders_submitted":0,"presentation":{"amount":"0.010000","amount_traded":"0","microtimestamp":"1787932602570000","price":"2470.54"},"previous_record_hash":"85027e3818c97e444b202f503944a91d3d5c1cd7c35e503694e0f42f350540ff","profit_assessment":null,"record_hash":"f3a325617ff77ac6db0fe3d941e7a7bb5837f525231e4638f00240dc4a685312","recorded_unix_us":1787932602740150,"recorded_utc":"2026-08-28T15:56:42.740150Z","schema_version":"nrrf810.exchange_authored_interactive_closure.v1","source_chain_continuous":true,"source_event":"order_created","source_event_id":"00065a1d-7fa8-9510-0000-001200000020","source_event_id_unique":true,"source_pre_event_id":"00065a1d-7fa8-6a18-0000-001203000020","translation":"UNFOLD_TO_INF","unfold_event_id":null,"zero_hair":false}
{"channel":"live_orders_ethbtc","interaction_index":881,"natural_form":{"channel":"live_orders_ethbtc","order_id":"2044303883931650","order_subtype":5,"order_type":1},"natural_form_sha256":"c606b72e8f97d5c651c6cb63ad98da2c84d95d8cac1992d38fcc641d79597b57","order_source":"orderbook","orders_submitted":0,"presentation":{"amount":"2.01528391","amount_traded":"0","microtimestamp":"1787932602571000","price":"0.03160361"},"previous_record_hash":"f3a325617ff77ac6db0fe3d941e7a7bb5837f525231e4638f00240dc4a685312","profit_assessment":null,"record_hash":"2ca71216371badf7f11460c2e03253c02d09237596214d5f2544c293e821cd4f","recorded_unix_us":1787932602740291,"recorded_utc":"2026-08-28T15:56:42.740291Z","schema_version":"nrrf810.exchange_authored_interactive_closure.v1","source_chain_continuous":true,"source_event":"order_created","source_event_id":"00065a1d-7fa8-98f8-0000-001101000020","source_event_id_unique":true,"source_pre_event_id":"00065a1d-7fa8-4308-0000-001100000020","translation":"UNFOLD_TO_INF","unfold_event_id":null,"zero_hair":false}
{"channel":"live_orders_btcusd","interaction_index":882,"natural_form":{"channel":"live_orders_btcusd","order_id":"2044303883939840","order_subtype":5,"order_type":1},"natural_form_sha256":"6f674bef375e7d556a56c08132d4286dc06ecbea78ae4e1503b780eca882e665","order_source":"orderbook","orders_submitted":0,"presentation":{"amount":"0.10000000","amount_traded":"0","microtimestamp":"1787932602572000","price":"78522.63"},"previous_record_hash":"2ca71216371badf7f11460c2e03253c02d09237596214d5f2544c293e821cd4f","profit_assessment":null,"record_hash":"eb56033fd6c87766412e78ca34fe64604d8384c74dcde8b7e8d3d8b45292c05b","recorded_unix_us":1787932602740422,"recorded_utc":"2026-08-28T15:56:42.740422Z","schema_version":"nrrf810.exchange_authored_interactive_closure.v1","source_chain_continuous":true,"source_event":"order_created","source_event_id":"00065a1d-7fa8-9ce0-0000-000101000020","source_event_id_unique":true,"source_pre_event_id":"00065a1d-7fa8-9128-0000-000100000020","translation":"UNFOLD_TO_INF","unfold_event_id":null,"zero_hair":false}
{"channel":"live_orders_btcusd","interaction_index":883,"natural_form":{"channel":"live_orders_btcusd","order_id":"2044303883939840","order_subtype":5,"order_type":1},"natural_form_sha256":"6f674bef375e7d556a56c08132d4286dc06ecbea78ae4e1503b780eca882e665","order_source":"orderbook","orders_submitted":0,"presentation":{"amount":"0.10000000","amount_traded":"0","microtimestamp":"1787932602572000","price":"78522.63"},"previous_record_hash":"eb56033fd6c87766412e78ca34fe64604d8384c74dcde8b7e8d3d8b45292c05b","profit_assessment":null,"record_hash":"2a83f0d5fb9d4fade8952c499257d747de04c3a5af84b35191356b3112f4eb5d","recorded_unix_us":1787932602740532,"recorded_utc":"2026-08-28T15:56:42.740532Z","schema_version":"nrrf810.exchange_authored_interactive_closure.v1","source_chain_continuous":true,"source_event":"order_deleted","source_event_id":"00065a1d-7fa8-9ce0-0001-000102000020","source_event_id_unique":true,"source_pre_event_id":"00065a1d-7fa8-9ce0-0000-000101000020","translation":"FOLD_RETURN_TO_ZERO","unfold_event_id":"00065a1d-7fa8-9ce0-0000-000101000020","zero_hair":true}
{"channel":"live_orders_btcusd","interaction_index":884,"natural_form":{"channel":"live_orders_btcusd","order_id":"2044303883948035","order_subtype":5,"order_type":0},"natural_form_sha256":"88d81dec8f29c13939f1f4f130f099bd755f874328ea8d2b786a48f247d770c4","order_source":"orderbook","orders_submitted":0,"presentation":{"amount":"1.27541152","amount_traded":"0","microtimestamp":"1787932602574000","price":"78406.06"},"previous_record_hash":"2a83f0d5fb9d4fade8952c499257d747de04c3a5af84b35191356b3112f4eb5d","profit_assessment":null,"record_hash":"092de81d26abb98166415910cf5145509d40cefcffbac7514ea3631057a5d28f","recorded_unix_us":1787932602740670,"recorded_utc":"2026-08-28T15:56:42.740670Z","schema_version":"nrrf810.exchange_authored_interactive_closure.v1","source_chain_continuous":true,"source_event":"order_created","source_event_id":"00065a1d-7fa8-a4b0-0000-000103000020","source_event_id_unique":true,"source_pre_event_id":"00065a1d-7fa8-9ce0-0001-000102000020","translation":"UNFOLD_TO_INF","unfold_event_id":null,"zero_hair":false}
{"channel":"live_orders_btcusd","interaction_index":885,"natural_form":{"channel":"live_orders_btcusd","order_id":"2044303883952129","order_subtype":5,"order_type":0},"natural_form_sha256":"8a4de45586deb91c6f500cb4a239c71b0b3d048d9945a47b9de2e312889826f5","order_source":"orderbook","orders_submitted":0,"presentation":{"amount":"1.27567513","amount_traded":"0","microtimestamp":"1787932602575000","price":"78389.86"},"previous_record_hash":"092de81d26abb98166415910cf5145509d40cefcffbac7514ea3631057a5d28f","profit_assessment":null,"record_hash":"0111c0fcbeb708eb97785749bc553e4621bfeeb3b538700941ef5a78b7bbb36a","recorded_unix_us":1787932602740799,"recorded_utc":"2026-08-28T15:56:42.740799Z","schema_version":"nrrf810.exchange_authored_interactive_closure.v1","source_chain_continuous":true,"source_event":"order_created","source_event_id":"00065a1d-7fa8-a898-0000-000100000020","source_event_id_unique":true,"source_pre_event_id":"00065a1d-7fa8-a4b0-0000-000103000020","translation":"UNFOLD_TO_INF","unfold_event_id":null,"zero_hair":false}
{"channel":"live_orders_btcusd","interaction_index":886,"natural_form":{"channel":"live_orders_btcusd","order_id":"2044303883501577","order_subtype":5,"order_type":0},"natural_form_sha256":"7cdcbb1692471ecd1ca18773abf569892db2a21b88e51913a4616d63fe973c94","order_source":"orderbook","orders_submitted":0,"presentation":{"amount":"0.00140266","amount_traded":"0","microtimestamp":"1787932602576000","price":"70666.76"},"previous_record_hash":"0111c0fcbeb708eb97785749bc553e4621bfeeb3b538700941ef5a78b7bbb36a","profit_assessment":null,"record_hash":"23b1dbd71a1c0122a34be1614558fb5dcfc0591b6ef6d9745a8eab56938944b2","recorded_unix_us":1787932602740932,"recorded_utc":"2026-08-28T15:56:42.740932Z","schema_version":"nrrf810.exchange_authored_interactive_closure.v1","source_chain_continuous":true,"source_event":"order_deleted","source_event_id":"00065a1d-7fa8-ac80-0000-000101000020","source_event_id_unique":true,"source_pre_event_id":"00065a1d-7fa8-a898-0000-000100000020","translation":"FOLD_RETURN_TO_ZERO","unfold_event_id":"00065a1d-7fa6-fed0-0000-000101000020","zero_hair":true}
{"channel":"live_orders_btcusd","interaction_index":887,"natural_form":{"channel":"live_orders_btcusd","order_id":"2044303883837446","order_subtype":5,"order_type":0},"natural_form_sha256":"8c77fd5267b7f460edc60abcf6a306c893be17b54955bbbdb6f6d76b58ceff43","order_source":"orderbook","orders_submitted":0,"presentation":{"amount":"0.00140266","amount_traded":"0","microtimestamp":"1787932602576000","price":"70666.76"},"previous_record_hash":"23b1dbd71a1c0122a34be1614558fb5dcfc0591b6ef6d9745a8eab56938944b2","profit_assessment":null,"record_hash":"8107e970280dbc118831602d86de643837ecadf737b65013b3d0ae96a299fbf3","recorded_unix_us":1787932602741191,"recorded_utc":"2026-08-28T15:56:42.741191Z","schema_version":"nrrf810.exchange_authored_interactive_closure.v1","source_chain_continuous":true,"source_event":"order_deleted","source_event_id":"00065a1d-7fa8-ac80-0001-000102000020","source_event_id_unique":true,"source_pre_event_id":"00065a1d-7fa8-ac80-0000-000101000020","translation":"FOLD_RETURN_TO_ZERO","unfold_event_id":"00065a1d-7fa8-3b38-0000-000102000020","zero_hair":true}
{"channel":"live_orders_btcusd","interaction_index":888,"natural_form":{"channel":"live_orders_btcusd","order_id":"2044303883956229","order_subtype":5,"order_type":0},"natural_form_sha256":"578d19df1cef3f06edc9813ebbf91612bb61f96e4d72dea8b35c374dcf2c0868","order_source":"orderbook","orders_submitted":0,"presentation":{"amount":"12.76418733","amount_traded":"0","microtimestamp":"1787932602576000","price":"78344.19"},"previous_record_hash":"8107e970280dbc118831602d86de643837ecadf737b65013b3d0ae96a299fbf3","profit_assessment":null,"record_hash":"52a2726ec76ff26bcc8246c731c0d89c5caf128de0b09cb93fe1d42c728c25c3","recorded_unix_us":1787932602741245,"recorded_utc":"2026-08-28T15:56:42.741245Z","schema_version":"nrrf810.exchange_authored_interactive_closure.v1","source_chain_continuous":true,"source_event":"order_created","source_event_id":"00065a1d-7fa8-ac80-0002-000103000020","source_event_id_unique":true,"source_pre_event_id":"00065a1d-7fa8-ac80-0001-000102000020","translation":"UNFOLD_TO_INF","unfold_event_id":null,"zero_hair":false}
{"channel":"live_orders_btcusd","interaction_index":889,"natural_form":{"channel":"live_orders_btcusd","order_id":"2044303883960321","order_subtype":4,"order_type":1},"natural_form_sha256":"fc294cecf1b2ad38e33c82defa78b163a9cfb2f80730372f8cca17192e478656","order_source":"orderbook","orders_submitted":0,"presentation":{"amount":"0.02791000","amount_traded":"0","microtimestamp":"1787932602578000","price":"78513.40"},"previous_record_hash":"52a2726ec76ff26bcc8246c731c0d89c5caf128de0b09cb93fe1d42c728c25c3","profit_assessment":null,"record_hash":"2f7c0feed6c3fbca641ae3cc7aefdc90216529f587b5c3002e179291eb5d7755","recorded_unix_us":1787932602741361,"recorded_utc":"2026-08-28T15:56:42.741361Z","schema_version":"nrrf810.exchange_authored_interactive_closure.v1","source_chain_continuous":true,"source_event":"order_created","source_event_id":"00065a1d-7fa8-b450-0000-000100000020","source_event_id_unique":true,"source_pre_event_id":"00065a1d-7fa8-ac80-0002-000103000020","translation":"UNFOLD_TO_INF","unfold_event_id":null,"zero_hair":false}
{"channel":"live_orders_btcusd","interaction_index":890,"natural_form":{"channel":"live_orders_btcusd","order_id":"2044303883960321","order_subtype":4,"order_type":1},"natural_form_sha256":"fc294cecf1b2ad38e33c82defa78b163a9cfb2f80730372f8cca17192e478656","order_source":"orderbook","orders_submitted":0,"presentation":{"amount":"0","amount_traded":"0.02791000","microtimestamp":"1787932602578000","price":"78522.63"},"previous_record_hash":"2f7c0feed6c3fbca641ae3cc7aefdc90216529f587b5c3002e179291eb5d7755","profit_assessment":null,"record_hash":"769c5e8686099a37e1e65bcae04a19ded772693b89792aac0a789e92d45c9d8a","recorded_unix_us":1787932602741395,"recorded_utc":"2026-08-28T15:56:42.741395Z","schema_version":"nrrf810.exchange_authored_interactive_closure.v1","source_chain_continuous":true,"source_event":"order_deleted","source_event_id":"00065a1d-7fa8-b450-0001-000101000020","source_event_id_unique":true,"source_pre_event_id":"00065a1d-7fa8-b450-0000-000100000020","translation":"FOLD_RETURN_TO_ZERO","unfold_event_id":"00065a1d-7fa8-b450-0000-000100000020","zero_hair":true}
{"channel":"live_orders_btcusd","interaction_index":891,"natural_form":{"channel":"live_orders_btcusd","order_id":"2044303819288576","order_subtype":5,"order_type":0},"natural_form_sha256":"b51e0d9ee88623fe1518775a4ba92dfe00068c9e09d56b98689f2ebeed123750","order_source":"orderbook","orders_submitted":0,"presentation":{"amount":"0.03222098","amount_traded":"0.02791000","microtimestamp":"1787932602578000","price":"78522.63"},"previous_record_hash":"769c5e8686099a37e1e65bcae04a19ded772693b89792aac0a789e92d45c9d8a","profit_assessment":null,"record_hash":"2783a81c9397983da87e16bd88212e403c803c1bd4001b751a2188fc3ef3cbe0","recorded_unix_us":1787932602741424,"recorded_utc":"2026-08-28T15:56:42.741424Z","schema_version":"nrrf810.exchange_authored_interactive_closure.v1","source_chain_continuous":true,"source_event":"order_changed","source_event_id":"00065a1d-7fa8-b450-0002-000102000020","source_event_id_unique":true,"source_pre_event_id":"00065a1d-7fa8-b450-0001-000101000020","translation":"PARTIAL_PRIOR_UNFOLD","unfold_event_id":null,"zero_hair":false}
{"channel":"live_orders_ethusd","interaction_index":892,"natural_form":{"channel":"live_orders_ethusd","order_id":"2044303882268672","order_subtype":5,"order_type":0},"natural_form_sha256":"5143b5825235a46273fcf89e0d0c2224d1ce7b694021b8b4d6f5e6a456514d13","order_source":"orderbook","orders_submitted":0,"presentation":{"amount":"0.595025","amount_traded":"0","microtimestamp":"1787932602579000","price":"2480.16"},"previous_record_hash":"2783a81c9397983da87e16bd88212e403c803c1bd4001b751a2188fc3ef3cbe0","profit_assessment":null,"record_hash":"f7c08ae89cffa65d861740d8f5cd6d125d2c5d50b56d534542db45ca06825f33","recorded_unix_us":1787932602741576,"recorded_utc":"2026-08-28T15:56:42.741576Z","schema_version":"nrrf810.exchange_authored_interactive_closure.v1","source_chain_continuous":true,"source_event":"order_deleted","source_event_id":"00065a1d-7fa8-b838-0000-001201000020","source_event_id_unique":true,"source_pre_event_id":"00065a1d-7fa8-9510-0000-001200000020","translation":"FOLD_RETURN_TO_ZERO","unfold_event_id":"00065a1d-7fa2-6320-0000-001201000020","zero_hair":true}
{"channel":"live_orders_btcusd","interaction_index":893,"natural_form":{"channel":"live_orders_btcusd","order_id":"2044303883968513","order_subtype":5,"order_type":0},"natural_form_sha256":"890f36abd5960921c8022003ca848bfc5b380f848f8aec4e5f28db0f28affd66","order_source":"orderbook","orders_submitted":0,"presentation":{"amount":"1.27757154","amount_traded":"0","microtimestamp":"1787932602579000","price":"78273.50"},"previous_record_hash":"f7c08ae89cffa65d861740d8f5cd6d125d2c5d50b56d534542db45ca06825f33","profit_assessment":null,"record_hash":"bb6c3660757673d963a3bbdec125d8af774e3c23f7ae40a1c35986a2038eb205","recorded_unix_us":1787932602741623,"recorded_utc":"2026-08-28T15:56:42.741623Z","schema_version":"nrrf810.exchange_authored_interactive_closure.v1","source_chain_continuous":true,"source_event":"order_created","source_event_id":"00065a1d-7fa8-b838-0000-000103000020","source_event_id_unique":true,"source_pre_event_id":"00065a1d-7fa8-b450-0002-000102000020","translation":"UNFOLD_TO_INF","unfold_event_id":null,"zero_hair":false}
{"channel":"live_orders_ethusd","interaction_index":894,"natural_form":{"channel":"live_orders_ethusd","order_id":"2044303883968516","order_subtype":5,"order_type":0},"natural_form_sha256":"0416b5fd7afa7a9f5b94cb7b4bdee78d31709d595aa4bdeb224000a584ed327e","order_source":"orderbook","orders_submitted":0,"presentation":{"amount":"0.007000","amount_traded":"0","microtimestamp":"1787932602579000","price":"2180.54"},"previous_record_hash":"bb6c3660757673d963a3bbdec125d8af774e3c23f7ae40a1c35986a2038eb205","profit_assessment":null,"record_hash":"3ebe23c0b0c73f4382e5e13510db5c21ea1b5b44dbc5e9b8a4370f1976459d23","recorded_unix_us":1787932602741861,"recorded_utc":"2026-08-28T15:56:42.741861Z","schema_version":"nrrf810.exchange_authored_interactive_closure.v1","source_chain_continuous":true,"source_event":"order_created","source_event_id":"00065a1d-7fa8-b838-0001-001202000020","source_event_id_unique":true,"source_pre_event_id":"00065a1d-7fa8-b838-0000-001201000020","translation":"UNFOLD_TO_INF","unfold_event_id":null,"zero_hair":false}
{"channel":"live_orders_ethusd","interaction_index":895,"natural_form":{"channel":"live_orders_ethusd","order_id":"2044303883984900","order_subtype":5,"order_type":1},"natural_form_sha256":"2d814b53412c0fb0b264fcd32b52d236200cb3536106e05179d61f2b47a7902d","order_source":"orderbook","orders_submitted":0,"presentation":{"amount":"12.087822","amount_traded":"0","microtimestamp":"1787932602584000","price":"2481.84"},"previous_record_hash":"3ebe23c0b0c73f4382e5e13510db5c21ea1b5b44dbc5e9b8a4370f1976459d23","profit_assessment":null,"record_hash":"0b21fce7a54a0fa1296dfc50c207b93a23d5abea03c3375fc6bf961a251f4597","recorded_unix_us":1787932602741893,"recorded_utc":"2026-08-28T15:56:42.741893Z","schema_version":"nrrf810.exchange_authored_interactive_closure.v1","source_chain_continuous":true,"source_event":"order_created","source_event_id":"00065a1d-7fa8-cbc0-0000-001203000020","source_event_id_unique":true,"source_pre_event_id":"00065a1d-7fa8-b838-0001-001202000020","translation":"UNFOLD_TO_INF","unfold_event_id":null,"zero_hair":false}
{"channel":"live_orders_btcusd","interaction_index":896,"natural_form":{"channel":"live_orders_btcusd","order_id":"2044303883984903","order_subtype":5,"order_type":1},"natural_form_sha256":"c911d230826c69edef4845a0b1b633aa3a6fb39d5e64c36538d1e08d92504c2c","order_source":"orderbook","orders_submitted":0,"presentation":{"amount":"0.06310787","amount_traded":"0","microtimestamp":"1787932602584000","price":"78521.60"},"previous_record_hash":"0b21fce7a54a0fa1296dfc50c207b93a23d5abea03c3375fc6bf961a251f4597","profit_assessment":null,"record_hash":"254a6d335ef1b3d9095eae74f4ac100ffae4a67861835b1157a2f456a9e13f01","recorded_unix_us":1787932602742008,"recorded_utc":"2026-08-28T15:56:42.742008Z","schema_version":"nrrf810.exchange_authored_interactive_closure.v1","source_chain_continuous":true,"source_event":"order_created","source_event_id":"00065a1d-7fa8-cbc0-0000-000100000020","source_event_id_unique":true,"source_pre_event_id":"00065a1d-7fa8-b838-0000-000103000020","translation":"UNFOLD_TO_INF","unfold_event_id":null,"zero_hair":false}
{"channel":"live_orders_btcusd","interaction_index":897,"natural_form":{"channel":"live_orders_btcusd","order_id":"2044303883984903","order_subtype":5,"order_type":1},"natural_form_sha256":"c911d230826c69edef4845a0b1b633aa3a6fb39d5e64c36538d1e08d92504c2c","order_source":"orderbook","orders_submitted":0,"presentation":{"amount":"0.06310787","amount_traded":"0","microtimestamp":"1787932602584000","price":"78521.60"},"previous_record_hash":"254a6d335ef1b3d9095eae74f4ac100ffae4a67861835b1157a2f456a9e13f01","profit_assessment":null,"record_hash":"9781ef667741eead2b434e8a2869fde221e5ca886e378aac878273773fe2d72c","recorded_unix_us":1787932602742042,"recorded_utc":"2026-08-28T15:56:42.742042Z","schema_version":"nrrf810.exchange_authored_interactive_closure.v1","source_chain_continuous":true,"source_event":"order_deleted","source_event_id":"00065a1d-7fa8-cbc0-0001-000101000020","source_event_id_unique":true,"source_pre_event_id":"00065a1d-7fa8-cbc0-0000-000100000020","translation":"FOLD_RETURN_TO_ZERO","unfold_event_id":"00065a1d-7fa8-cbc0-0000-000100000020","zero_hair":true}
{"channel":"live_orders_ethusd","interaction_index":898,"natural_form":{"channel":"live_orders_ethusd","order_id":"2044303883988997","order_subtype":5,"order_type":1},"natural_form_sha256":"28997b984353f396beea78ecc0edf0e959fe99f49155d69461522d42671a25bd","order_source":"orderbook","orders_submitted":0,"presentation":{"amount":"12.086444","amount_traded":"0","microtimestamp":"1787932602584000","price":"2482.12"},"previous_record_hash":"9781ef667741eead2b434e8a2869fde221e5ca886e378aac878273773fe2d72c","profit_assessment":null,"record_hash":"ea72a21148a4c0a6f6915141f8fcc8552bf78fd1373df0ef12e8706d4e4cc261","recorded_unix_us":1787932602742071,"recorded_utc":"2026-08-28T15:56:42.742071Z","schema_version":"nrrf810.exchange_authored_interactive_closure.v1","source_chain_continuous":true,"source_event":"order_created","source_event_id":"00065a1d-7fa8-cbc0-0001-001200000020","source_event_id_unique":true,"source_pre_event_id":"00065a1d-7fa8-cbc0-0000-001203000020","translation":"UNFOLD_TO_INF","unfold_event_id":null,"zero_hair":false}
{"channel":"live_orders_ethusd","interaction_index":899,"natural_form":{"channel":"live_orders_ethusd","order_id":"2044303883374610","order_subtype":5,"order_type":0},"natural_form_sha256":"f59c8a1878fd156fa4cf9045754876812f6fafc07844833d9cc8ed1302dbc6b4","order_source":"orderbook","orders_submitted":0,"presentation":{"amount":"0.403094","amount_traded":"0","microtimestamp":"1787932602585000","price":"2480.02"},"previous_record_hash":"ea72a21148a4c0a6f6915141f8fcc8552bf78fd1373df0ef12e8706d4e4cc261","profit_assessment":null,"record_hash":"f5451b69850f7f8d1e6ea2d7452eefa359610e1d35b11921b536c3a3e8f23b71","recorded_unix_us":1787932602742174,"recorded_utc":"2026-08-28T15:56:42.742174Z","schema_version":"nrrf810.exchange_authored_interactive_closure.v1","source_chain_continuous":true,"source_event":"order_deleted","source_event_id":"00065a1d-7fa8-cfa8-0000-001201000020","source_event_id_unique":true,"source_pre_event_id":"00065a1d-7fa8-cbc0-0001-001200000020","translation":"FOLD_RETURN_TO_ZERO","unfold_event_id":"00065a1d-7fa6-85b8-0000-001201000020","zero_hair":true}
{"channel":"live_orders_ethusd","interaction_index":900,"natural_form":{"channel":"live_orders_ethusd","order_id":"2044303884001280","order_subtype":5,"order_type":1},"natural_form_sha256":"d3d4d7a62cac593f9a607df0959f785424c6ba771cd20d13ef8f23f68749e4e2","order_source":"orderbook","orders_submitted":0,"presentation":{"amount":"4.028412","amount_traded":"0","microtimestamp":"1787932602587000","price":"2482.37"},"previous_record_hash":"f5451b69850f7f8d1e6ea2d7452eefa359610e1d35b11921b536c3a3e8f23b71","profit_assessment":null,"record_hash":"c0893f911e249a8ef3637abf94d44ddfce841bb0247cc93d23066796525ca4bc","recorded_unix_us":1787932602742263,"recorded_utc":"2026-08-28T15:56:42.742263Z","schema_version":"nrrf810.exchange_authored_interactive_closure.v1","source_chain_continuous":true,"source_event":"order_created","source_event_id":"00065a1d-7fa8-d778-0000-001202000020","source_event_id_unique":true,"source_pre_event_id":"00065a1d-7fa8-cfa8-0000-001201000020","translation":"UNFOLD_TO_INF","unfold_event_id":null,"zero_hair":false}
{"channel":"live_orders_ethusd","interaction_index":901,"natural_form":{"channel":"live_orders_ethusd","order_id":"2044303884005376","order_subtype":5,"order_type":1},"natural_form_sha256":"46a2a0edca09104092786f71f8e8e055261954e7eb9ca20c0b162aef314d9a94","order_source":"orderbook","orders_submitted":0,"presentation":{"amount":"4.027018","amount_traded":"0","microtimestamp":"1787932602588000","price":"2483.23"},"previous_record_hash":"c0893f911e249a8ef3637abf94d44ddfce841bb0247cc93d23066796525ca4bc","profit_assessment":null,"record_hash":"f7378166674b523f7363acf5cee97e8b9e2320df696751344d30df22177152c8","recorded_unix_us":1787932602742356,"recorded_utc":"2026-08-28T15:56:42.742356Z","schema_version":"nrrf810.exchange_authored_interactive_closure.v1","source_chain_continuous":true,"source_event":"order_created","source_event_id":"00065a1d-7fa8-db60-0000-001203000020","source_event_id_unique":true,"source_pre_event_id":"00065a1d-7fa8-d778-0000-001202000020","translation":"UNFOLD_TO_INF","unfold_event_id":null,"zero_hair":false}
{"channel":"live_orders_btcusd","interaction_index":902,"natural_form":{"channel":"live_orders_btcusd","order_id":"2044303884005377","order_subtype":5,"order_type":1},"natural_form_sha256":"b221a03a9356bac450022145750a33df3934296c484a7d4ed9efc4adb085c9b9","order_source":"orderbook","orders_submitted":0,"presentation":{"amount":"0.10000000","amount_traded":"0","microtimestamp":"1787932602588000","price":"78522.62"},"previous_record_hash":"f7378166674b523f7363acf5cee97e8b9e2320df696751344d30df22177152c8","profit_assessment":null,"record_hash":"b20bf6621ba484517c8ed5de8b10ced2d3bdd3dce7558313e2666ab8abaaad33","recorded_unix_us":1787932602742469,"recorded_utc":"2026-08-28T15:56:42.742469Z","schema_version":"nrrf810.exchange_authored_interactive_closure.v1","source_chain_continuous":true,"source_event":"order_created","source_event_id":"00065a1d-7fa8-db60-0000-000102000020","source_event_id_unique":true,"source_pre_event_id":"00065a1d-7fa8-cbc0-0001-000101000020","translation":"UNFOLD_TO_INF","unfold_event_id":null,"zero_hair":false}
{"channel":"live_orders_btcusd","interaction_index":903,"natural_form":{"channel":"live_orders_btcusd","order_id":"2044303884005377","order_subtype":5,"order_type":1},"natural_form_sha256":"b221a03a9356bac450022145750a33df3934296c484a7d4ed9efc4adb085c9b9","order_source":"orderbook","orders_submitted":0,"presentation":{"amount":"0.10000000","amount_traded":"0","microtimestamp":"1787932602588000","price":"78522.62"},"previous_record_hash":"b20bf6621ba484517c8ed5de8b10ced2d3bdd3dce7558313e2666ab8abaaad33","profit_assessment":null,"record_hash":"54b14373d06d4795314412a09efc0e2d2fb70ac2b70675313cb0acdcad4e6984","recorded_unix_us":1787932602742504,"recorded_utc":"2026-08-28T15:56:42.742504Z","schema_version":"nrrf810.exchange_authored_interactive_closure.v1","source_chain_continuous":true,"source_event":"order_deleted","source_event_id":"00065a1d-7fa8-db60-0001-000103000020","source_event_id_unique":true,"source_pre_event_id":"00065a1d-7fa8-db60-0000-000102000020","translation":"FOLD_RETURN_TO_ZERO","unfold_event_id":"00065a1d-7fa8-db60-0000-000102000020","zero_hair":true}
{"channel":"live_orders_ethusd","interaction_index":904,"natural_form":{"channel":"live_orders_ethusd","order_id":"2044303884009473","order_subtype":5,"order_type":1},"natural_form_sha256":"3aa1b7b6372c943515df85f94b1ceea7c20a93da944b311c7d721b1f6de118b6","order_source":"orderbook","orders_submitted":0,"presentation":{"amount":"10.065070","amount_traded":"0","microtimestamp":"1787932602589000","price":"2483.84"},"previous_record_hash":"54b14373d06d4795314412a09efc0e2d2fb70ac2b70675313cb0acdcad4e6984","profit_assessment":null,"record_hash":"dcc533ac13dbd15b8e1384ec7ca118eab7cd2d52523b202a66923644aa25f518","recorded_unix_us":1787932602742595,"recorded_utc":"2026-08-28T15:56:42.742595Z","schema_version":"nrrf810.exchange_authored_interactive_closure.v1","source_chain_continuous":true,"source_event":"order_created","source_event_id":"00065a1d-7fa8-df48-0000-001200000020","source_event_id_unique":true,"source_pre_event_id":"00065a1d-7fa8-db60-0000-001203000020","translation":"UNFOLD_TO_INF","unfold_event_id":null,"zero_hair":false}
{"channel":"live_orders_ethusd","interaction_index":905,"natural_form":{"channel":"live_orders_ethusd","order_id":"2044303884009474","order_subtype":5,"order_type":1},"natural_form_sha256":"d0dafe4140bd034a1687cab1c9af0da2a087f37025e5a505ff829b2c05782882","order_source":"orderbook","orders_submitted":0,"presentation":{"amount":"10.057184","amount_traded":"0","microtimestamp":"1787932602589000","price":"2485.79"},"previous_record_hash":"dcc533ac13dbd15b8e1384ec7ca118eab7cd2d52523b202a66923644aa25f518","profit_assessment":null,"record_hash":"b25cc580d68c6601a85aa2f7cf8d635ee5cde9d89d09fb92e83e826699ab957c","recorded_unix_us":1787932602742717,"recorded_utc":"2026-08-28T15:56:42.742717Z","schema_version":"nrrf810.exchange_authored_interactive_closure.v1","source_chain_continuous":true,"source_event":"order_created","source_event_id":"00065a1d-7fa8-df48-0001-001201000020","source_event_id_unique":true,"source_pre_event_id":"00065a1d-7fa8-df48-0000-001200000020","translation":"UNFOLD_TO_INF","unfold_event_id":null,"zero_hair":false}
{"channel":"live_orders_ethusd","interaction_index":906,"natural_form":{"channel":"live_orders_ethusd","order_id":"2044303884009475","order_subtype":5,"order_type":0},"natural_form_sha256":"61ca56c7645e6990766978e899de6eb0c315bcca538818978eb7df564e0981f6","order_source":"orderbook","orders_submitted":0,"presentation":{"amount":"0.598466","amount_traded":"0","microtimestamp":"1787932602590000","price":"2480.22"},"previous_record_hash":"b25cc580d68c6601a85aa2f7cf8d635ee5cde9d89d09fb92e83e826699ab957c","profit_assessment":null,"record_hash":"6a92618a01f97b026ed3e3b2f2fa594b9e28db275f928e6d12e1441118be36ba","recorded_unix_us":1787932602742749,"recorded_utc":"2026-08-28T15:56:42.742749Z","schema_version":"nrrf810.exchange_authored_interactive_closure.v1","source_chain_continuous":true,"source_event":"order_created","source_event_id":"00065a1d-7fa8-e330-0000-001202000020","source_event_id_unique":true,"source_pre_event_id":"00065a1d-7fa8-df48-0001-001201000020","translation":"UNFOLD_TO_INF","unfold_event_id":null,"zero_hair":false}
{"channel":"live_orders_ethusd","interaction_index":907,"natural_form":{"channel":"live_orders_ethusd","order_id":"2044303884013568","order_subtype":5,"order_type":1},"natural_form_sha256":"75efbb3331d914610d230e089c3acd0b430da71a6510225590b0f7bf005efae7","order_source":"orderbook","orders_submitted":0,"presentation":{"amount":"20.088574","amount_traded":"0","microtimestamp":"1787932602591000","price":"2488.98"},"previous_record_hash":"6a92618a01f97b026ed3e3b2f2fa594b9e28db275f928e6d12e1441118be36ba","profit_assessment":null,"record_hash":"9c0693da449e15717b3d1a5d1fd67b742f5359ec3d6ba0034be524a3459c4ef0","recorded_unix_us":1787932602742849,"recorded_utc":"2026-08-28T15:56:42.742849Z","schema_version":"nrrf810.exchange_authored_interactive_closure.v1","source_chain_continuous":true,"source_event":"order_created","source_event_id":"00065a1d-7fa8-e718-0000-001203000020","source_event_id_unique":true,"source_pre_event_id":"00065a1d-7fa8-e330-0000-001202000020","translation":"UNFOLD_TO_INF","unfold_event_id":null,"zero_hair":false}
{"channel":"live_orders_ethusd","interaction_index":908,"natural_form":{"channel":"live_orders_ethusd","order_id":"2044303884017666","order_subtype":5,"order_type":1},"natural_form_sha256":"5708c9f4187f830cd444494ae46f7ad0f2ddfff1fd5907c0906c5edb8237c7a3","order_source":"orderbook","orders_submitted":0,"presentation":{"amount":"20.097242","amount_traded":"0","microtimestamp":"1787932602591000","price":"2487.91"},"previous_record_hash":"9c0693da449e15717b3d1a5d1fd67b742f5359ec3d6ba0034be524a3459c4ef0","profit_assessment":null,"record_hash":"3459ebe027f82abde4ac9f5d1c03303e24529d4aaa27a2fc444976a87b866362","recorded_unix_us":1787932602742968,"recorded_utc":"2026-08-28T15:56:42.742968Z","schema_version":"nrrf810.exchange_authored_interactive_closure.v1","source_chain_continuous":true,"source_event":"order_created","source_event_id":"00065a1d-7fa8-e718-0001-001200000020","source_event_id_unique":true,"source_pre_event_id":"00065a1d-7fa8-e718-0000-001203000020","translation":"UNFOLD_TO_INF","unfold_event_id":null,"zero_hair":false}
{"channel":"live_orders_ethusd","interaction_index":909,"natural_form":{"channel":"live_orders_ethusd","order_id":"2044303884025861","order_subtype":5,"order_type":1},"natural_form_sha256":"003e738cc0177af962dac006968363300fa62730dca2879e89eac6d795bc7d1f","order_source":"orderbook","orders_submitted":0,"presentation":{"amount":"40.092050","amount_traded":"0","microtimestamp":"1787932602594000","price":"2494.27"},"previous_record_hash":"3459ebe027f82abde4ac9f5d1c03303e24529d4aaa27a2fc444976a87b866362","profit_assessment":null,"record_hash":"54075d9636eb4e457cc3e519f0982fe109f110fc015bc8d047988c7869c94914","recorded_unix_us":1787932602743053,"recorded_utc":"2026-08-28T15:56:42.743053Z","schema_version":"nrrf810.exchange_authored_interactive_closure.v1","source_chain_continuous":true,"source_event":"order_created","source_event_id":"00065a1d-7fa8-f2d0-0000-001201000020","source_event_id_unique":true,"source_pre_event_id":"00065a1d-7fa8-e718-0001-001200000020","translation":"UNFOLD_TO_INF","unfold_event_id":null,"zero_hair":false}
{"channel":"live_orders_ethusd","interaction_index":910,"natural_form":{"channel":"live_orders_ethusd","order_id":"2044303884025862","order_subtype":5,"order_type":1},"natural_form_sha256":"179edc2bfabe33c75e016629ef4754fc12fcef81379ea0d0eb29f0bcaa0b74af","order_source":"orderbook","orders_submitted":0,"presentation":{"amount":"39.969006","amount_traded":"0","microtimestamp":"1787932602594000","price":"2501.94"},"previous_record_hash":"54075d9636eb4e457cc3e519f0982fe109f110fc015bc8d047988c7869c94914","profit_assessment":null,"record_hash":"6067d16e869cd5eaccfcd1e0e13eb6da3c06ff02249b793ba678c179482edcac","recorded_unix_us":1787932602743283,"recorded_utc":"2026-08-28T15:56:42.743283Z","schema_version":"nrrf810.exchange_authored_interactive_closure.v1","source_chain_continuous":true,"source_event":"order_created","source_event_id":"00065a1d-7fa8-f2d0-0001-001202000020","source_event_id_unique":true,"source_pre_event_id":"00065a1d-7fa8-f2d0-0000-001201000020","translation":"UNFOLD_TO_INF","unfold_event_id":null,"zero_hair":false}
{"channel":"live_orders_btcusd","interaction_index":911,"natural_form":{"channel":"live_orders_btcusd","order_id":"2044303882784773","order_subtype":5,"order_type":0},"natural_form_sha256":"c22fccd3f3e199243b458ecc6414d5046413fd4191beef9bf7e0d7d56c1635ef","order_source":"orderbook","orders_submitted":0,"presentation":{"amount":"0.26750492","amount_traded":"0","microtimestamp":"1787932602595000","price":"78485.89"},"previous_record_hash":"6067d16e869cd5eaccfcd1e0e13eb6da3c06ff02249b793ba678c179482edcac","profit_assessment":null,"record_hash":"4c981f9814e94f22064df2412368dc3785733eebaa31b47e1ee1448ce8145190","recorded_unix_us":1787932602743314,"recorded_utc":"2026-08-28T15:56:42.743314Z","schema_version":"nrrf810.exchange_authored_interactive_closure.v1","source_chain_continuous":true,"source_event":"order_deleted","source_event_id":"00065a1d-7fa8-f6b8-0000-000100000020","source_event_id_unique":true,"source_pre_event_id":"00065a1d-7fa8-db60-0001-000103000020","translation":"FOLD_RETURN_TO_ZERO","unfold_event_id":"00065a1d-7fa4-4f50-0003-000100000020","zero_hair":true}
{"channel":"live_orders_btcusd","interaction_index":912,"natural_form":{"channel":"live_orders_btcusd","order_id":"2044303884034048","order_subtype":5,"order_type":0},"natural_form_sha256":"9cfae2c445acaf98ed2122ef586fa83100b9c7cb48abd3359073402bf90d21b6","order_source":"orderbook","orders_submitted":0,"presentation":{"amount":"0.26750492","amount_traded":"0","microtimestamp":"1787932602595000","price":"78485.89"},"previous_record_hash":"4c981f9814e94f22064df2412368dc3785733eebaa31b47e1ee1448ce8145190","profit_assessment":null,"record_hash":"6e21eaf2db99e8abafd0b8f0eec3a9c306b841adc6d4f8dc32768feb6a95cd6c","recorded_unix_us":1787932602743340,"recorded_utc":"2026-08-28T15:56:42.743340Z","schema_version":"nrrf810.exchange_authored_interactive_closure.v1","source_chain_continuous":true,"source_event":"order_created","source_event_id":"00065a1d-7fa8-f6b8-0001-000101000020","source_event_id_unique":true,"source_pre_event_id":"00065a1d-7fa8-f6b8-0000-000100000020","translation":"UNFOLD_TO_INF","unfold_event_id":null,"zero_hair":false}
{"channel":"live_orders_ethusd","interaction_index":913,"natural_form":{"channel":"live_orders_ethusd","order_id":"2044303884034049","order_subtype":5,"order_type":0},"natural_form_sha256":"664827c15c3ab863c782fc0de8b6ede5a615235af708b6a0aa4c94504c8f8796","order_source":"orderbook","orders_submitted":0,"presentation":{"amount":"0.403091","amount_traded":"0","microtimestamp":"1787932602595000","price":"2480.10"},"previous_record_hash":"6e21eaf2db99e8abafd0b8f0eec3a9c306b841adc6d4f8dc32768feb6a95cd6c","profit_assessment":null,"record_hash":"b4c9994242d3d38d72b0d13ebce537a97eba744143d1c834191882caf65b0914","recorded_unix_us":1787932602743365,"recorded_utc":"2026-08-28T15:56:42.743365Z","schema_version":"nrrf810.exchange_authored_interactive_closure.v1","source_chain_continuous":true,"source_event":"order_created","source_event_id":"00065a1d-7fa8-f6b8-0000-001203000020","source_event_id_unique":true,"source_pre_event_id":"00065a1d-7fa8-f2d0-0001-001202000020","translation":"UNFOLD_TO_INF","unfold_event_id":null,"zero_hair":false}
{"channel":"live_orders_ethusd","interaction_index":914,"natural_form":{"channel":"live_orders_ethusd","order_id":"2044303884042241","order_subtype":5,"order_type":0},"natural_form_sha256":"d0f26ef857db01e244ac842e2a7610969ebbb78b55f2f54dab0fe841430dd387","order_source":"orderbook","orders_submitted":0,"presentation":{"amount":"12.095621","amount_traded":"0","microtimestamp":"1787932602598000","price":"2480.23"},"previous_record_hash":"b4c9994242d3d38d72b0d13ebce537a97eba744143d1c834191882caf65b0914","profit_assessment":null,"record_hash":"e6f0ca702c2a2d3bef1a8ee4637842ec4fb7eb3068f23f8324727abb52b70213","recorded_unix_us":1787932602743489,"recorded_utc":"2026-08-28T15:56:42.743489Z","schema_version":"nrrf810.exchange_authored_interactive_closure.v1","source_chain_continuous":true,"source_event":"order_created","source_event_id":"00065a1d-7fa9-0270-0000-001200000020","source_event_id_unique":true,"source_pre_event_id":"00065a1d-7fa8-f6b8-0000-001203000020","translation":"UNFOLD_TO_INF","unfold_event_id":null,"zero_hair":false}
{"channel":"live_orders_btcusd","interaction_index":915,"natural_form":{"channel":"live_orders_btcusd","order_id":"2044303884046336","order_subtype":5,"order_type":1},"natural_form_sha256":"cb821dc76815371532783dafb28d73eb452bc6646681e33960d88b3faf4b4844","order_source":"orderbook","orders_submitted":0,"presentation":{"amount":"1.27177200","amount_traded":"0","microtimestamp":"1787932602598000","price":"78630.45"},"previous_record_hash":"e6f0ca702c2a2d3bef1a8ee4637842ec4fb7eb3068f23f8324727abb52b70213","profit_assessment":null,"record_hash":"7063482546329e49ca70e181fbd204a502305ad9cee1dd2b1a6e4562cf0f55a7","recorded_unix_us":1787932602743521,"recorded_utc":"2026-08-28T15:56:42.743521Z","schema_version":"nrrf810.exchange_authored_interactive_closure.v1","source_chain_continuous":true,"source_event":"order_created","source_event_id":"00065a1d-7fa9-0270-0000-000102000020","source_event_id_unique":true,"source_pre_event_id":"00065a1d-7fa8-f6b8-0001-000101000020","translation":"UNFOLD_TO_INF","unfold_event_id":null,"zero_hair":false}
{"channel":"live_orders_ethusd","interaction_index":916,"natural_form":{"channel":"live_orders_ethusd","order_id":"2044303884050432","order_subtype":5,"order_type":0},"natural_form_sha256":"6bed7639397fdd3e997ce7167d66f1b1b08dec38880ed91f47a58fade908ff2c","order_source":"orderbook","orders_submitted":0,"presentation":{"amount":"12.096984","amount_traded":"0","microtimestamp":"1787932602599000","price":"2479.95"},"previous_record_hash":"7063482546329e49ca70e181fbd204a502305ad9cee1dd2b1a6e4562cf0f55a7","profit_assessment":null,"record_hash":"9e9a6b8b933a4b56f26ee13ae7082407d01b7dec67bf981121b87d19319f76bf","recorded_unix_us":1787932602743813,"recorded_utc":"2026-08-28T15:56:42.743813Z","schema_version":"nrrf810.exchange_authored_interactive_closure.v1","source_chain_continuous":true,"source_event":"order_created","source_event_id":"00065a1d-7fa9-0658-0000-001201000020","source_event_id_unique":true,"source_pre_event_id":"00065a1d-7fa9-0270-0000-001200000020","translation":"UNFOLD_TO_INF","unfold_event_id":null,"zero_hair":false}
{"channel":"live_orders_ethusd","interaction_index":917,"natural_form":{"channel":"live_orders_ethusd","order_id":"2044303884050433","order_subtype":5,"order_type":0},"natural_form_sha256":"6e301c26c614ed4c619e8308784ad81455f3006992c9f825ec0caf2aaf6bc890","order_source":"orderbook","orders_submitted":0,"presentation":{"amount":"4.032745","amount_traded":"0","microtimestamp":"1787932602599000","price":"2479.70"},"previous_record_hash":"9e9a6b8b933a4b56f26ee13ae7082407d01b7dec67bf981121b87d19319f76bf","profit_assessment":null,"record_hash":"3f6dcd4f85bef962f4aeac518c779d650a834b6dee82bace3910fd061880870f","recorded_unix_us":1787932602743842,"recorded_utc":"2026-08-28T15:56:42.743842Z","schema_version":"nrrf810.exchange_authored_interactive_closure.v1","source_chain_continuous":true,"source_event":"order_created","source_event_id":"00065a1d-7fa9-0658-0001-001202000020","source_event_id_unique":true,"source_pre_event_id":"00065a1d-7fa9-0658-0000-001201000020","translation":"UNFOLD_TO_INF","unfold_event_id":null,"zero_hair":false}
{"channel":"live_orders_btcusd","interaction_index":918,"natural_form":{"channel":"live_orders_btcusd","order_id":"2044303884054532","order_subtype":5,"order_type":1},"natural_form_sha256":"339b5d24e01a55f44630df921af56f50e360904f6223e8832651b6e6b4a89909","order_source":"orderbook","orders_submitted":0,"presentation":{"amount":"1.26842789","amount_traded":"0","microtimestamp":"1787932602601000","price":"78837.75"},"previous_record_hash":"3f6dcd4f85bef962f4aeac518c779d650a834b6dee82bace3910fd061880870f","profit_assessment":null,"record_hash":"09c371fe030b9d23ccde9de37555895c4dc4102db49450c4a7201dd7e6f8b5e2","recorded_unix_us":1787932602743864,"recorded_utc":"2026-08-28T15:56:42.743864Z","schema_version":"nrrf810.exchange_authored_interactive_closure.v1","source_chain_continuous":true,"source_event":"order_created","source_event_id":"00065a1d-7fa9-0e28-0000-000103000020","source_event_id_unique":true,"source_pre_event_id":"00065a1d-7fa9-0270-0000-000102000020","translation":"UNFOLD_TO_INF","unfold_event_id":null,"zero_hair":false}
{"channel":"live_orders_btcusd","interaction_index":919,"natural_form":{"channel":"live_orders_btcusd","order_id":"2044303884058625","order_subtype":5,"order_type":0},"natural_form_sha256":"ca0d00d1d5f6e5036b146728d27c0e9119e967f91ac2adf48774ee0b97a8f67a","order_source":"orderbook","orders_submitted":0,"presentation":{"amount":"1.27604867","amount_traded":"0","microtimestamp":"1787932602601000","price":"78366.91"},"previous_record_hash":"09c371fe030b9d23ccde9de37555895c4dc4102db49450c4a7201dd7e6f8b5e2","profit_assessment":null,"record_hash":"f684a83cb14684c9557f12dfd9c06d3e1f6e7fcf23f9f1cebdfef5245bca8bfe","recorded_unix_us":1787932602743885,"recorded_utc":"2026-08-28T15:56:42.743885Z","schema_version":"nrrf810.exchange_authored_interactive_closure.v1","source_chain_continuous":true,"source_event":"order_created","source_event_id":"00065a1d-7fa9-0e28-0001-000100000020","source_event_id_unique":true,"source_pre_event_id":"00065a1d-7fa9-0e28-0000-000103000020","translation":"UNFOLD_TO_INF","unfold_event_id":null,"zero_hair":false}
{"channel":"live_orders_btcusd","interaction_index":920,"natural_form":{"channel":"live_orders_btcusd","order_id":"2044303884066816","order_subtype":4,"order_type":0},"natural_form_sha256":"44bfe3a0bb5a8e9ad52b846dbca0acc027265a292b27739a25e0690ca4551e80","order_source":"orderbook","orders_submitted":0,"presentation":{"amount":"0.00006631","amount_traded":"0","microtimestamp":"1787932602603000","price":"76166.96"},"previous_record_hash":"f684a83cb14684c9557f12dfd9c06d3e1f6e7fcf23f9f1cebdfef5245bca8bfe","profit_assessment":null,"record_hash":"02c277f6893afbac35d38c181372aacd8b9fcadf31f2c0a38447bc236083fd65","recorded_unix_us":1787932602743909,"recorded_utc":"2026-08-28T15:56:42.743909Z","schema_version":"nrrf810.exchange_authored_interactive_closure.v1","source_chain_continuous":true,"source_event":"order_created","source_event_id":"00065a1d-7fa9-15f8-0000-000101000020","source_event_id_unique":true,"source_pre_event_id":"00065a1d-7fa9-0e28-0001-000100000020","translation":"UNFOLD_TO_INF","unfold_event_id":null,"zero_hair":false}
{"channel":"live_orders_btcusd","interaction_index":921,"natural_form":{"channel":"live_orders_btcusd","order_id":"2044303884066816","order_subtype":4,"order_type":0},"natural_form_sha256":"44bfe3a0bb5a8e9ad52b846dbca0acc027265a292b27739a25e0690ca4551e80","order_source":"orderbook","orders_submitted":0,"presentation":{"amount":"0.00006631","amount_traded":"0","microtimestamp":"1787932602603000","price":"76166.96"},"previous_record_hash":"02c277f6893afbac35d38c181372aacd8b9fcadf31f2c0a38447bc236083fd65","profit_assessment":null,"record_hash":"5d58ac81bf5a80068681284dec0aad9605d7a65a73753e98332f75ca68a2d847","recorded_unix_us":1787932602743930,"recorded_utc":"2026-08-28T15:56:42.743930Z","schema_version":"nrrf810.exchange_authored_interactive_closure.v1","source_chain_continuous":true,"source_event":"order_deleted","source_event_id":"00065a1d-7fa9-15f8-0001-000102000020","source_event_id_unique":true,"source_pre_event_id":"00065a1d-7fa9-15f8-0000-000101000020","translation":"FOLD_RETURN_TO_ZERO","unfold_event_id":"00065a1d-7fa9-15f8-0000-000101000020","zero_hair":true}
{"channel":"live_orders_ethusd","interaction_index":922,"natural_form":{"channel":"live_orders_ethusd","order_id":"2044303884066817","order_subtype":5,"order_type":0},"natural_form_sha256":"8554793aa5b48c6afeb87b1448782a5a1651b53e0f0c99744324bb562292f630","order_source":"orderbook","orders_submitted":0,"presentation":{"amount":"4.033601","amount_traded":"0","microtimestamp":"1787932602604000","price":"2479.17"},"previous_record_hash":"5d58ac81bf5a80068681284dec0aad9605d7a65a73753e98332f75ca68a2d847","profit_assessment":null,"record_hash":"9aac5d0ab2bdc0d1db7eb66cc7714ca71e99878c19eeaa3065be575be9c82298","recorded_unix_us":1787932602743954,"recorded_utc":"2026-08-28T15:56:42.743954Z","schema_version":"nrrf810.exchange_authored_interactive_closure.v1","source_chain_continuous":true,"source_event":"order_created","source_event_id":"00065a1d-7fa9-19e0-0000-001203000020","source_event_id_unique":true,"source_pre_event_id":"00065a1d-7fa9-0658-0001-001202000020","translation":"UNFOLD_TO_INF","unfold_event_id":null,"zero_hair":false}
{"channel":"live_orders_btcusd","interaction_index":923,"natural_form":{"channel":"live_orders_btcusd","order_id":"2044303884066818","order_subtype":5,"order_type":0},"natural_form_sha256":"460c10a58b92901052f0127dc702c3eb3bc5f98824f4b71987112f9692c448c8","order_source":"orderbook","orders_submitted":0,"presentation":{"amount":"1.27817952","amount_traded":"0","microtimestamp":"1787932602604000","price":"78236.27"},"previous_record_hash":"9aac5d0ab2bdc0d1db7eb66cc7714ca71e99878c19eeaa3065be575be9c82298","profit_assessment":null,"record_hash":"1d2c9e5f774ea64ca6887227f04f9405966535399770913c4ab010cb1871d455","recorded_unix_us":1787932602743976,"recorded_utc":"2026-08-28T15:56:42.743976Z","schema_version":"nrrf810.exchange_authored_interactive_closure.v1","source_chain_continuous":true,"source_event":"order_created","source_event_id":"00065a1d-7fa9-19e0-0000-000103000020","source_event_id_unique":true,"source_pre_event_id":"00065a1d-7fa9-15f8-0001-000102000020","translation":"UNFOLD_TO_INF","unfold_event_id":null,"zero_hair":false}
{"channel":"live_orders_ethusd","interaction_index":924,"natural_form":{"channel":"live_orders_ethusd","order_id":"2044303884079105","order_subtype":5,"order_type":0},"natural_form_sha256":"65da590afe14528d6594f6ffa8675089399f9d1da096f29095c59e48dd63c5f4","order_source":"orderbook","orders_submitted":0,"presentation":{"amount":"10.090138","amount_traded":"0","microtimestamp":"1787932602606000","price":"2477.66"},"previous_record_hash":"1d2c9e5f774ea64ca6887227f04f9405966535399770913c4ab010cb1871d455","profit_assessment":null,"record_hash":"0518cbe293dd3c3487d2cd93807c147c6897c001b076d978152327ee9a18e100","recorded_unix_us":1787932602744181,"recorded_utc":"2026-08-28T15:56:42.744181Z","schema_version":"nrrf810.exchange_authored_interactive_closure.v1","source_chain_continuous":true,"source_event":"order_created","source_event_id":"00065a1d-7fa9-21b0-0000-001200000020","source_event_id_unique":true,"source_pre_event_id":"00065a1d-7fa9-19e0-0000-001203000020","translation":"UNFOLD_TO_INF","unfold_event_id":null,"zero_hair":false}
{"channel":"live_orders_btcusd","interaction_index":925,"natural_form":{"channel":"live_orders_btcusd","order_id":"2044303884079107","order_subtype":5,"order_type":1},"natural_form_sha256":"9b5d328eac3c93e0ff61bc75e286af46d445c84984fd593e28ff1d1670256006","order_source":"orderbook","orders_submitted":0,"presentation":{"amount":"0.00254699","amount_traded":"0","microtimestamp":"1787932602607000","price":"78524.12"},"previous_record_hash":"0518cbe293dd3c3487d2cd93807c147c6897c001b076d978152327ee9a18e100","profit_assessment":null,"record_hash":"c31ff97a2e989b7135f56c40154a2da3d016e9a821608de232eab09fe0d1e55e","recorded_unix_us":1787932602744212,"recorded_utc":"2026-08-28T15:56:42.744212Z","schema_version":"nrrf810.exchange_authored_interactive_closure.v1","source_chain_continuous":true,"source_event":"order_created","source_event_id":"00065a1d-7fa9-2598-0000-000100000020","source_event_id_unique":true,"source_pre_event_id":"00065a1d-7fa9-19e0-0000-000103000020","translation":"UNFOLD_TO_INF","unfold_event_id":null,"zero_hair":false}
{"channel":"live_orders_ethusd","interaction_index":926,"natural_form":{"channel":"live_orders_ethusd","order_id":"2044303884091394","order_subtype":5,"order_type":0},"natural_form_sha256":"1f6c688bd38c1bb7d464f409f469b92fe01f6b7e0dedf747f0d24255035ea5fb","order_source":"orderbook","orders_submitted":0,"presentation":{"amount":"10.095101","amount_traded":"0","microtimestamp":"1787932602610000","price":"2476.44"},"previous_record_hash":"c31ff97a2e989b7135f56c40154a2da3d016e9a821608de232eab09fe0d1e55e","profit_assessment":null,"record_hash":"f5882c016d9a37f9c2610497510d9296308e4f7c0b3a4f5bdc071afdfa643181","recorded_unix_us":1787932602744235,"recorded_utc":"2026-08-28T15:56:42.744235Z","schema_version":"nrrf810.exchange_authored_interactive_closure.v1","source_chain_continuous":true,"source_event":"order_created","source_event_id":"00065a1d-7fa9-3150-0000-001201000020","source_event_id_unique":true,"source_pre_event_id":"00065a1d-7fa9-21b0-0000-001200000020","translation":"UNFOLD_TO_INF","unfold_event_id":null,"zero_hair":false}
{"channel":"live_orders_ethusd","interaction_index":927,"natural_form":{"channel":"live_orders_ethusd","order_id":"2044303884095493","order_subtype":5,"order_type":0},"natural_form_sha256":"209adfd5318c71d3463c2987845ccefcc30f73b3b3f2f26a6ff04e41d9cff4e3","order_source":"orderbook","orders_submitted":0,"presentation":{"amount":"20.204386","amount_traded":"0","microtimestamp":"1787932602611000","price":"2474.71"},"previous_record_hash":"f5882c016d9a37f9c2610497510d9296308e4f7c0b3a4f5bdc071afdfa643181","profit_assessment":null,"record_hash":"f6f1c08b0bdd6c8a090ae76993bfae9dd7da8a27caaaf4240ad593f57ac5e673","recorded_unix_us":1787932602744300,"recorded_utc":"2026-08-28T15:56:42.744300Z","schema_version":"nrrf810.exchange_authored_interactive_closure.v1","source_chain_continuous":true,"source_event":"order_created","source_event_id":"00065a1d-7fa9-3538-0000-001202000020","source_event_id_unique":true,"source_pre_event_id":"00065a1d-7fa9-3150-0000-001201000020","translation":"UNFOLD_TO_INF","unfold_event_id":null,"zero_hair":false}
{"channel":"live_orders_ethusd","interaction_index":928,"natural_form":{"channel":"live_orders_ethusd","order_id":"2044303884099584","order_subtype":5,"order_type":0},"natural_form_sha256":"72acd458b7ce90d502e95baacb5c4d533f535a698ad2b1fba12a15ced94c7ce4","order_source":"orderbook","orders_submitted":0,"presentation":{"amount":"40.528033","amount_traded":"0","microtimestamp":"1787932602612000","price":"2467.42"},"previous_record_hash":"f6f1c08b0bdd6c8a090ae76993bfae9dd7da8a27caaaf4240ad593f57ac5e673","profit_assessment":null,"record_hash":"9551e063189bb9b8c0077c34645a20393d22599a94a9f1ab20a807a577d26c56","recorded_unix_us":1787932602744324,"recorded_utc":"2026-08-28T15:56:42.744324Z","schema_version":"nrrf810.exchange_authored_interactive_closure.v1","source_chain_continuous":true,"source_event":"order_created","source_event_id":"00065a1d-7fa9-3920-0000-001203000020","source_event_id_unique":true,"source_pre_event_id":"00065a1d-7fa9-3538-0000-001202000020","translation":"UNFOLD_TO_INF","unfold_event_id":null,"zero_hair":false}
{"channel":"live_orders_ethusd","interaction_index":929,"natural_form":{"channel":"live_orders_ethusd","order_id":"2044303884099585","order_subtype":5,"order_type":0},"natural_form_sha256":"df95233e9a533b2e481bc9c346340d3a39b36dbd260f9dfb244879ee96a251c4","order_source":"orderbook","orders_submitted":0,"presentation":{"amount":"40.650432","amount_traded":"0","microtimestamp":"1787932602612000","price":"2459.99"},"previous_record_hash":"9551e063189bb9b8c0077c34645a20393d22599a94a9f1ab20a807a577d26c56","profit_assessment":null,"record_hash":"3127a3d7538a687ef7b5945826ef44d609f20c2979a78bff47472583e9839ea0","recorded_unix_us":1787932602744430,"recorded_utc":"2026-08-28T15:56:42.744430Z","schema_version":"nrrf810.exchange_authored_interactive_closure.v1","source_chain_continuous":true,"source_event":"order_created","source_event_id":"00065a1d-7fa9-3920-0001-001200000020","source_event_id_unique":true,"source_pre_event_id":"00065a1d-7fa9-3920-0000-001203000020","translation":"UNFOLD_TO_INF","unfold_event_id":null,"zero_hair":false}
{"channel":"live_orders_btcusd","interaction_index":930,"natural_form":{"channel":"live_orders_btcusd","order_id":"2044303884132354","order_subtype":5,"order_type":1},"natural_form_sha256":"21f99ccd0e8d79294118a0b63523216014eb463af68a3a7572c6cb982ad69d46","order_source":"orderbook","orders_submitted":0,"presentation":{"amount":"0.10000000","amount_traded":"0","microtimestamp":"1787932602620000","price":"78522.63"},"previous_record_hash":"3127a3d7538a687ef7b5945826ef44d609f20c2979a78bff47472583e9839ea0","profit_assessment":null,"record_hash":"3a5d9f7b1ccb196403aecc378b2aa723711aa86dee7d60f3f4e1dd9e2d933682","recorded_unix_us":1787932602744568,"recorded_utc":"2026-08-28T15:56:42.744568Z","schema_version":"nrrf810.exchange_authored_interactive_closure.v1","source_chain_continuous":true,"source_event":"order_created","source_event_id":"00065a1d-7fa9-5860-0000-000101000020","source_event_id_unique":true,"source_pre_event_id":"00065a1d-7fa9-2598-0000-000100000020","translation":"UNFOLD_TO_INF","unfold_event_id":null,"zero_hair":false}
{"channel":"live_orders_btcusd","interaction_index":931,"natural_form":{"channel":"live_orders_btcusd","order_id":"2044303884132354","order_subtype":5,"order_type":1},"natural_form_sha256":"21f99ccd0e8d79294118a0b63523216014eb463af68a3a7572c6cb982ad69d46","order_source":"orderbook","orders_submitted":0,"presentation":{"amount":"0.10000000","amount_traded":"0","microtimestamp":"1787932602620000","price":"78522.63"},"previous_record_hash":"3a5d9f7b1ccb196403aecc378b2aa723711aa86dee7d60f3f4e1dd9e2d933682","profit_assessment":null,"record_hash":"e10db693fbeeb48b44ef1749e6c063d2ea20db458689877ab08b6cc2749830a5","recorded_unix_us":1787932602744594,"recorded_utc":"2026-08-28T15:56:42.744594Z","schema_version":"nrrf810.exchange_authored_interactive_closure.v1","source_chain_continuous":true,"source_event":"order_deleted","source_event_id":"00065a1d-7fa9-5860-0001-000102000020","source_event_id_unique":true,"source_pre_event_id":"00065a1d-7fa9-5860-0000-000101000020","translation":"FOLD_RETURN_TO_ZERO","unfold_event_id":"00065a1d-7fa9-5860-0000-000101000020","zero_hair":true}
{"channel":"live_orders_btcusd","interaction_index":932,"natural_form":{"channel":"live_orders_btcusd","order_id":"2044303884136448","order_subtype":5,"order_type":1},"natural_form_sha256":"cd010d21db3abfea49b9dbeab6045518cd60766f8874efcd9421e95ecee79903","order_source":"orderbook","orders_submitted":0,"presentation":{"amount":"0.06310787","amount_traded":"0","microtimestamp":"1787932602620000","price":"78520.22"},"previous_record_hash":"e10db693fbeeb48b44ef1749e6c063d2ea20db458689877ab08b6cc2749830a5","profit_assessment":null,"record_hash":"bbca9b5613c453f2754618f5a55b0e6a21ee8cd33feb3a68b3f59ca0000b255b","recorded_unix_us":1787932602744616,"recorded_utc":"2026-08-28T15:56:42.744616Z","schema_version":"nrrf810.exchange_authored_interactive_closure.v1","source_chain_continuous":true,"source_event":"order_created","source_event_id":"00065a1d-7fa9-5860-0002-000103000020","source_event_id_unique":true,"source_pre_event_id":"00065a1d-7fa9-5860-0001-000102000020","translation":"UNFOLD_TO_INF","unfold_event_id":null,"zero_hair":false}
{"channel":"live_orders_btcusd","interaction_index":933,"natural_form":{"channel":"live_orders_btcusd","order_id":"2044303884136448","order_subtype":5,"order_type":1},"natural_form_sha256":"cd010d21db3abfea49b9dbeab6045518cd60766f8874efcd9421e95ecee79903","order_source":"orderbook","orders_submitted":0,"presentation":{"amount":"0.06310787","amount_traded":"0","microtimestamp":"1787932602620000","price":"78520.22"},"previous_record_hash":"bbca9b5613c453f2754618f5a55b0e6a21ee8cd33feb3a68b3f59ca0000b255b","profit_assessment":null,"record_hash":"8bbe59f89829a25ac43714cc32f62218c2321f2cf7305c68444d969d27908f42","recorded_unix_us":1787932602744698,"recorded_utc":"2026-08-28T15:56:42.744698Z","schema_version":"nrrf810.exchange_authored_interactive_closure.v1","source_chain_continuous":true,"source_event":"order_deleted","source_event_id":"00065a1d-7fa9-5860-0003-000100000020","source_event_id_unique":true,"source_pre_event_id":"00065a1d-7fa9-5860-0002-000103000020","translation":"FOLD_RETURN_TO_ZERO","unfold_event_id":"00065a1d-7fa9-5860-0002-000103000020","zero_hair":true}
{"channel":"live_orders_btcusd","interaction_index":934,"natural_form":{"channel":"live_orders_btcusd","order_id":"2044303884140545","order_subtype":5,"order_type":1},"natural_form_sha256":"a2ea7c6f4481c86213520562fa6646ec513053dff4547a10d77635b5738429e4","order_source":"orderbook","orders_submitted":0,"presentation":{"amount":"0.06310787","amount_traded":"0","microtimestamp":"1787932602621000","price":"78522.58"},"previous_record_hash":"8bbe59f89829a25ac43714cc32f62218c2321f2cf7305c68444d969d27908f42","profit_assessment":null,"record_hash":"4b2e2d7f18f146775f811d9415805419ee5f0aa5b6ad86e10f943bc57dc47417","recorded_unix_us":1787932602744813,"recorded_utc":"2026-08-28T15:56:42.744813Z","schema_version":"nrrf810.exchange_authored_interactive_closure.v1","source_chain_continuous":true,"source_event":"order_created","source_event_id":"00065a1d-7fa9-5c48-0000-000101000020","source_event_id_unique":true,"source_pre_event_id":"00065a1d-7fa9-5860-0003-000100000020","translation":"UNFOLD_TO_INF","unfold_event_id":null,"zero_hair":false}
{"channel":"live_orders_btcusd","interaction_index":935,"natural_form":{"channel":"live_orders_btcusd","order_id":"2044303884140545","order_subtype":5,"order_type":1},"natural_form_sha256":"a2ea7c6f4481c86213520562fa6646ec513053dff4547a10d77635b5738429e4","order_source":"orderbook","orders_submitted":0,"presentation":{"amount":"0.06310787","amount_traded":"0","microtimestamp":"1787932602621000","price":"78522.58"},"previous_record_hash":"4b2e2d7f18f146775f811d9415805419ee5f0aa5b6ad86e10f943bc57dc47417","profit_assessment":null,"record_hash":"8e98925ae14196fc3a9e1abfdfd2a880e0d47e27e015305653886fe1a7b033c6","recorded_unix_us":1787932602744839,"recorded_utc":"2026-08-28T15:56:42.744839Z","schema_version":"nrrf810.exchange_authored_interactive_closure.v1","source_chain_continuous":true,"source_event":"order_deleted","source_event_id":"00065a1d-7fa9-5c48-0001-000102000020","source_event_id_unique":true,"source_pre_event_id":"00065a1d-7fa9-5c48-0000-000101000020","translation":"FOLD_RETURN_TO_ZERO","unfold_event_id":"00065a1d-7fa9-5c48-0000-000101000020","zero_hair":true}
{"channel":"live_orders_btcusd","interaction_index":936,"natural_form":{"channel":"live_orders_btcusd","order_id":"2044303884173314","order_subtype":5,"order_type":0},"natural_form_sha256":"323cc26d482f7192bea8980027b200612a3bb83edc19652a536360c07f52893a","order_source":"orderbook","orders_submitted":0,"presentation":{"amount":"0.00140266","amount_traded":"0","microtimestamp":"1787932602629000","price":"70668.36"},"previous_record_hash":"8e98925ae14196fc3a9e1abfdfd2a880e0d47e27e015305653886fe1a7b033c6","profit_assessment":null,"record_hash":"9e74b262f1964dd759dd05824855a999c9440860d90c3d03a263c5a86b1ea507","recorded_unix_us":1787932602744922,"recorded_utc":"2026-08-28T15:56:42.744922Z","schema_version":"nrrf810.exchange_authored_interactive_closure.v1","source_chain_continuous":true,"source_event":"order_created","source_event_id":"00065a1d-7fa9-7b88-0000-000103000020","source_event_id_unique":true,"source_pre_event_id":"00065a1d-7fa9-5c48-0001-000102000020","translation":"UNFOLD_TO_INF","unfold_event_id":null,"zero_hair":false}
{"channel":"live_orders_ethusd","interaction_index":937,"natural_form":{"channel":"live_orders_ethusd","order_id":"2044303884173315","order_subtype":5,"order_type":1},"natural_form_sha256":"b9c62086ee106dc28ebe98cd34ef9bd8e92de491e2dac3b09e4767b8e7cccd3a","order_source":"orderbook","orders_submitted":0,"presentation":{"amount":"4.028003","amount_traded":"0","microtimestamp":"1787932602629000","price":"2482.62"},"previous_record_hash":"9e74b262f1964dd759dd05824855a999c9440860d90c3d03a263c5a86b1ea507","profit_assessment":null,"record_hash":"959361e776749bf851c58b23fe8d2a84c7c11eb94b9739ba5996f8110778569b","recorded_unix_us":1787932602745037,"recorded_utc":"2026-08-28T15:56:42.745037Z","schema_version":"nrrf810.exchange_authored_interactive_closure.v1","source_chain_continuous":true,"source_event":"order_created","source_event_id":"00065a1d-7fa9-7b88-0000-001201000020","source_event_id_unique":true,"source_pre_event_id":"00065a1d-7fa9-3920-0001-001200000020","translation":"UNFOLD_TO_INF","unfold_event_id":null,"zero_hair":false}
{"channel":"live_orders_btcusd","interaction_index":938,"natural_form":{"channel":"live_orders_btcusd","order_id":"2044303884173316","order_subtype":5,"order_type":1},"natural_form_sha256":"d96789769e41783aab23c44ccfa613df9ad1b3a18c374f3e8361cceec3aaf424","order_source":"orderbook","orders_submitted":0,"presentation":{"amount":"1.27145262","amount_traded":"0","microtimestamp":"1787932602629000","price":"78650.20"},"previous_record_hash":"959361e776749bf851c58b23fe8d2a84c7c11eb94b9739ba5996f8110778569b","profit_assessment":null,"record_hash":"5052c7a2b3a8b83779f4d10cfc7e1cb7b807cd54014d6e8c19ca30747d48fbaf","recorded_unix_us":1787932602745066,"recorded_utc":"2026-08-28T15:56:42.745066Z","schema_version":"nrrf810.exchange_authored_interactive_closure.v1","source_chain_continuous":true,"source_event":"order_created","source_event_id":"00065a1d-7fa9-7b88-0001-000100000020","source_event_id_unique":true,"source_pre_event_id":"00065a1d-7fa9-7b88-0000-000103000020","translation":"UNFOLD_TO_INF","unfold_event_id":null,"zero_hair":false}
{"channel":"live_orders_ethusd","interaction_index":939,"natural_form":{"channel":"live_orders_ethusd","order_id":"2044303884189696","order_subtype":5,"order_type":0},"natural_form_sha256":"ed5b1fae6bfd89ed9a559df4f04e407320bd0399eff62589a9abd99f3fe64dd1","order_source":"orderbook","orders_submitted":0,"presentation":{"amount":"20.215084","amount_traded":"0","microtimestamp":"1787932602634000","price":"2473.40"},"previous_record_hash":"5052c7a2b3a8b83779f4d10cfc7e1cb7b807cd54014d6e8c19ca30747d48fbaf","profit_assessment":null,"record_hash":"37e22e0c25f7efc53f5b3c79bc55ddb32745723fafe4fd5e5dd576dac0e3c3ff","recorded_unix_us":1787932602745141,"recorded_utc":"2026-08-28T15:56:42.745141Z","schema_version":"nrrf810.exchange_authored_interactive_closure.v1","source_chain_continuous":true,"source_event":"order_created","source_event_id":"00065a1d-7fa9-8f10-0000-001202000020","source_event_id_unique":true,"source_pre_event_id":"00065a1d-7fa9-7b88-0000-001201000020","translation":"UNFOLD_TO_INF","unfold_event_id":null,"zero_hair":false}
