{"channel":"live_orders_btcusd","interaction_index":189,"natural_form":{"channel":"live_orders_btcusd","order_id":"2044303879548929","order_subtype":5,"order_type":1},"natural_form_sha256":"753006870356c8f3488f29a36a25d0aa6a38e3e18cf606e261ac42c4e027c37c","order_source":"orderbook","orders_submitted":0,"presentation":{"amount":"0.10000000","amount_traded":"0","microtimestamp":"1787932601500000","price":"78522.63"},"previous_record_hash":"0488e7a9fa9e8df1ab08297ae1bbcd9836327eb51b109a91c36712e88e661ffb","profit_assessment":null,"record_hash":"6b63ed06bf7232820ab02125092f82258f02fb9f72819d43c63226d0389a6f14","recorded_unix_us":1787932601568907,"recorded_utc":"2026-08-28T15:56:41.568907Z","schema_version":"nrrf810.exchange_authored_interactive_closure.v1","source_chain_continuous":true,"source_event":"order_created","source_event_id":"00065a1d-7f98-4160-0000-000103000020","source_event_id_unique":true,"source_pre_event_id":"00065a1d-7f98-3990-0000-000102000020","translation":"UNFOLD_TO_INF","unfold_event_id":null,"zero_hair":false}
{"channel":"live_orders_btcusd","interaction_index":190,"natural_form":{"channel":"live_orders_btcusd","order_id":"2044303879548929","order_subtype":5,"order_type":1},"natural_form_sha256":"753006870356c8f3488f29a36a25d0aa6a38e3e18cf606e261ac42c4e027c37c","order_source":"orderbook","orders_submitted":0,"presentation":{"amount":"0.10000000","amount_traded":"0","microtimestamp":"1787932601500000","price":"78522.63"},"previous_record_hash":"6b63ed06bf7232820ab02125092f82258f02fb9f72819d43c63226d0389a6f14","profit_assessment":null,"record_hash":"78287d6f2a22e9ca7ad7d1b2956e55c30379a7ec14ca4dc36176c052437702ee","recorded_unix_us":1787932601568994,"recorded_utc":"2026-08-28T15:56:41.568994Z","schema_version":"nrrf810.exchange_authored_interactive_closure.v1","source_chain_continuous":true,"source_event":"order_deleted","source_event_id":"00065a1d-7f98-4160-0001-000100000020","source_event_id_unique":true,"source_pre_event_id":"00065a1d-7f98-4160-0000-000103000020","translation":"FOLD_RETURN_TO_ZERO","unfold_event_id":"00065a1d-7f98-4160-0000-000103000020","zero_hair":true}
{"channel":"live_orders_ethusd","interaction_index":191,"natural_form":{"channel":"live_orders_ethusd","order_id":"2044303879569410","order_subtype":5,"order_type":0},"natural_form_sha256":"51efc4c71e43c0a35d89de80a583f162f3d9372e5bcd85adaf733ba7d19e437a","order_source":"orderbook","orders_submitted":0,"presentation":{"amount":"0.403104","amount_traded":"0","microtimestamp":"1787932601505000","price":"2479.66"},"previous_record_hash":"78287d6f2a22e9ca7ad7d1b2956e55c30379a7ec14ca4dc36176c052437702ee","profit_assessment":null,"record_hash":"0857e4b1b6067e2eb9753222bf390b2b10bc94d56f0ef0e75d06545f682e237e","recorded_unix_us":1787932601569119,"recorded_utc":"2026-08-28T15:56:41.569119Z","schema_version":"nrrf810.exchange_authored_interactive_closure.v1","source_chain_continuous":true,"source_event":"order_created","source_event_id":"00065a1d-7f98-54e8-0000-001202000020","source_event_id_unique":true,"source_pre_event_id":"00065a1d-7f98-4160-0000-001201000020","translation":"UNFOLD_TO_INF","unfold_event_id":null,"zero_hair":false}
{"channel":"live_orders_btcusd","interaction_index":192,"natural_form":{"channel":"live_orders_btcusd","order_id":"2044303879569417","order_subtype":5,"order_type":0},"natural_form_sha256":"3e4452c6b208afd9062e83f4d822cee3ad0ef7a59632fa14255da715c0256beb","order_source":"orderbook","orders_submitted":0,"presentation":{"amount":"0.00140266","amount_traded":"0","microtimestamp":"1787932601506000","price":"70666.88"},"previous_record_hash":"0857e4b1b6067e2eb9753222bf390b2b10bc94d56f0ef0e75d06545f682e237e","profit_assessment":null,"record_hash":"5c2daee483c58cf50b15dc6c9d98b350866c68bcdf36f6d9431eae3f94ce6323","recorded_unix_us":1787932601569218,"recorded_utc":"2026-08-28T15:56:41.569218Z","schema_version":"nrrf810.exchange_authored_interactive_closure.v1","source_chain_continuous":true,"source_event":"order_created","source_event_id":"00065a1d-7f98-58d0-0000-000101000020","source_event_id_unique":true,"source_pre_event_id":"00065a1d-7f98-4160-0001-000100000020","translation":"UNFOLD_TO_INF","unfold_event_id":null,"zero_hair":false}
{"channel":"live_orders_ethusd","interaction_index":193,"natural_form":{"channel":"live_orders_ethusd","order_id":"2044303879606276","order_subtype":5,"order_type":1},"natural_form_sha256":"2736d8a7e356c86ed6b9df4e7898518a33026ec285532bdf7f796805923bcd03","order_source":"orderbook","orders_submitted":0,"presentation":{"amount":"12.088820","amount_traded":"0","microtimestamp":"1787932601514000","price":"2481.64"},"previous_record_hash":"5c2daee483c58cf50b15dc6c9d98b350866c68bcdf36f6d9431eae3f94ce6323","profit_assessment":null,"record_hash":"238843a3132e494565d66f92229574c8bb849621f636bf639ed47c09344e0a6d","recorded_unix_us":1787932601569315,"recorded_utc":"2026-08-28T15:56:41.569315Z","schema_version":"nrrf810.exchange_authored_interactive_closure.v1","source_chain_continuous":true,"source_event":"order_created","source_event_id":"00065a1d-7f98-7810-0000-001203000020","source_event_id_unique":true,"source_pre_event_id":"00065a1d-7f98-54e8-0000-001202000020","translation":"UNFOLD_TO_INF","unfold_event_id":null,"zero_hair":false}
{"channel":"live_orders_ethusd","interaction_index":194,"natural_form":{"channel":"live_orders_ethusd","order_id":"2044303879610369","order_subtype":5,"order_type":1},"natural_form_sha256":"0a2971196fa34e35921eca3650571a7c63ddb0d17b1b624f59c291d0843fb9dd","order_source":"orderbook","orders_submitted":0,"presentation":{"amount":"12.087458","amount_traded":"0","microtimestamp":"1787932601516000","price":"2481.92"},"previous_record_hash":"238843a3132e494565d66f92229574c8bb849621f636bf639ed47c09344e0a6d","profit_assessment":null,"record_hash":"547d128cc75e08581dabf55459270b9b7144157f3b3c0a25db9e5bcf2cc493b3","recorded_unix_us":1787932601569456,"recorded_utc":"2026-08-28T15:56:41.569456Z","schema_version":"nrrf810.exchange_authored_interactive_closure.v1","source_chain_continuous":true,"source_event":"order_created","source_event_id":"00065a1d-7f98-7fe0-0000-001200000020","source_event_id_unique":true,"source_pre_event_id":"00065a1d-7f98-7810-0000-001203000020","translation":"UNFOLD_TO_INF","unfold_event_id":null,"zero_hair":false}
{"channel":"live_orders_btcusd","interaction_index":195,"natural_form":{"channel":"live_orders_btcusd","order_id":"2044303879614464","order_subtype":5,"order_type":0},"natural_form_sha256":"ee9a943e3ae067e2da0f67df3f3f7b1203af5cb648e2a9ba86674c80874748ed","order_source":"orderbook","orders_submitted":0,"presentation":{"amount":"0.06368105","amount_traded":"0","microtimestamp":"1787932601516000","price":"78516.28"},"previous_record_hash":"547d128cc75e08581dabf55459270b9b7144157f3b3c0a25db9e5bcf2cc493b3","profit_assessment":null,"record_hash":"46116adc1b9e9b859b8d8255b884e04742f8044c4ac9f8bb6c531cff1be327a9","recorded_unix_us":1787932601569483,"recorded_utc":"2026-08-28T15:56:41.569483Z","schema_version":"nrrf810.exchange_authored_interactive_closure.v1","source_chain_continuous":true,"source_event":"order_created","source_event_id":"00065a1d-7f98-7fe0-0000-000102000020","source_event_id_unique":true,"source_pre_event_id":"00065a1d-7f98-58d0-0000-000101000020","translation":"UNFOLD_TO_INF","unfold_event_id":null,"zero_hair":false}
{"channel":"live_orders_ethusd","interaction_index":196,"natural_form":{"channel":"live_orders_ethusd","order_id":"2044303879614465","order_subtype":5,"order_type":1},"natural_form_sha256":"cf6cce89d916a11eb65cebfb21deaf9574e40bbee11232117c5d79501b3877a1","order_source":"orderbook","orders_submitted":0,"presentation":{"amount":"10.065070","amount_traded":"0","microtimestamp":"1787932601517000","price":"2483.84"},"previous_record_hash":"46116adc1b9e9b859b8d8255b884e04742f8044c4ac9f8bb6c531cff1be327a9","profit_assessment":null,"record_hash":"1800e314e0505a93b70586f00f8f9381745f0bed4b320b964ec01547f41840cc","recorded_unix_us":1787932601569578,"recorded_utc":"2026-08-28T15:56:41.569578Z","schema_version":"nrrf810.exchange_authored_interactive_closure.v1","source_chain_continuous":true,"source_event":"order_created","source_event_id":"00065a1d-7f98-83c8-0000-001201000020","source_event_id_unique":true,"source_pre_event_id":"00065a1d-7f98-7fe0-0000-001200000020","translation":"UNFOLD_TO_INF","unfold_event_id":null,"zero_hair":false}
{"channel":"live_orders_ethusd","interaction_index":197,"natural_form":{"channel":"live_orders_ethusd","order_id":"2044303879622656","order_subtype":5,"order_type":1},"natural_form_sha256":"1c344e02a80ae39cc3f410a2483a67ae64c9d0ef922a6229a08b940efc552c95","order_source":"orderbook","orders_submitted":0,"presentation":{"amount":"4.028874","amount_traded":"0","microtimestamp":"1787932601518000","price":"2482.09"},"previous_record_hash":"1800e314e0505a93b70586f00f8f9381745f0bed4b320b964ec01547f41840cc","profit_assessment":null,"record_hash":"d865b95f8361d2096f065a1edd4ba0e79b4cc408a59ee628d7ee93bf720c575b","recorded_unix_us":1787932601569709,"recorded_utc":"2026-08-28T15:56:41.569709Z","schema_version":"nrrf810.exchange_authored_interactive_closure.v1","source_chain_continuous":true,"source_event":"order_created","source_event_id":"00065a1d-7f98-87b0-0000-001202000020","source_event_id_unique":true,"source_pre_event_id":"00065a1d-7f98-83c8-0000-001201000020","translation":"UNFOLD_TO_INF","unfold_event_id":null,"zero_hair":false}
{"channel":"live_orders_ethusd","interaction_index":198,"natural_form":{"channel":"live_orders_ethusd","order_id":"2044303879622658","order_subtype":5,"order_type":1},"natural_form_sha256":"fa50fae9c62c37e37afc699aed7c0842a8ddb4845be10fa43fa6ac224b872bd5","order_source":"orderbook","orders_submitted":0,"presentation":{"amount":"10.057184","amount_traded":"0","microtimestamp":"1787932601518000","price":"2485.79"},"previous_record_hash":"d865b95f8361d2096f065a1edd4ba0e79b4cc408a59ee628d7ee93bf720c575b","profit_assessment":null,"record_hash":"609a94f5a3f1d015a652002443dd83b566f8c5a2478e368e39e81cdc07d32fdd","recorded_unix_us":1787932601569750,"recorded_utc":"2026-08-28T15:56:41.569750Z","schema_version":"nrrf810.exchange_authored_interactive_closure.v1","source_chain_continuous":true,"source_event":"order_created","source_event_id":"00065a1d-7f98-87b0-0001-001203000020","source_event_id_unique":true,"source_pre_event_id":"00065a1d-7f98-87b0-0000-001202000020","translation":"UNFOLD_TO_INF","unfold_event_id":null,"zero_hair":false}
{"channel":"live_orders_ethusd","interaction_index":199,"natural_form":{"channel":"live_orders_ethusd","order_id":"2044303879622659","order_subtype":5,"order_type":1},"natural_form_sha256":"72022db2b1160cc2c5cb8f94fc08f22dddd3823141337a2d16931c459ff6ae8a","order_source":"orderbook","orders_submitted":0,"presentation":{"amount":"20.097242","amount_traded":"0","microtimestamp":"1787932601519000","price":"2487.91"},"previous_record_hash":"609a94f5a3f1d015a652002443dd83b566f8c5a2478e368e39e81cdc07d32fdd","profit_assessment":null,"record_hash":"e902cae20d8f4d417a6f691be34ae5c5687934f94311e078fd309754ff1fa826","recorded_unix_us":1787932601569777,"recorded_utc":"2026-08-28T15:56:41.569777Z","schema_version":"nrrf810.exchange_authored_interactive_closure.v1","source_chain_continuous":true,"source_event":"order_created","source_event_id":"00065a1d-7f98-8b98-0000-001200000020","source_event_id_unique":true,"source_pre_event_id":"00065a1d-7f98-87b0-0001-001203000020","translation":"UNFOLD_TO_INF","unfold_event_id":null,"zero_hair":false}
{"channel":"live_orders_ethusd","interaction_index":200,"natural_form":{"channel":"live_orders_ethusd","order_id":"2044303879626752","order_subtype":5,"order_type":1},"natural_form_sha256":"9c271bb39a9565db9910264f6c64c586501200c68a1440647fd0e9e0a6b83edc","order_source":"orderbook","orders_submitted":0,"presentation":{"amount":"20.088574","amount_traded":"0","microtimestamp":"1787932601519000","price":"2488.98"},"previous_record_hash":"e902cae20d8f4d417a6f691be34ae5c5687934f94311e078fd309754ff1fa826","profit_assessment":null,"record_hash":"d4a67f741ec1d15648795dee8a93c8c61c98d9f3508dcef43d9343f15e47a6e6","recorded_unix_us":1787932601569878,"recorded_utc":"2026-08-28T15:56:41.569878Z","schema_version":"nrrf810.exchange_authored_interactive_closure.v1","source_chain_continuous":true,"source_event":"order_created","source_event_id":"00065a1d-7f98-8b98-0001-001201000020","source_event_id_unique":true,"source_pre_event_id":"00065a1d-7f98-8b98-0000-001200000020","translation":"UNFOLD_TO_INF","unfold_event_id":null,"zero_hair":false}
{"channel":"live_orders_ethusd","interaction_index":201,"natural_form":{"channel":"live_orders_ethusd","order_id":"2044303879630850","order_subtype":5,"order_type":1},"natural_form_sha256":"2d0059a9ac8ec1ec8ff00f6c57ed412057e6851b37989c7ae28a16e51122f767","order_source":"orderbook","orders_submitted":0,"presentation":{"amount":"39.969006","amount_traded":"0","microtimestamp":"1787932601521000","price":"2501.94"},"previous_record_hash":"d4a67f741ec1d15648795dee8a93c8c61c98d9f3508dcef43d9343f15e47a6e6","profit_assessment":null,"record_hash":"6f601ebdec54156ab3a12354f98d378da9a2e39c46e530898093cbeaca265bb8","recorded_unix_us":1787932601586981,"recorded_utc":"2026-08-28T15:56:41.586981Z","schema_version":"nrrf810.exchange_authored_interactive_closure.v1","source_chain_continuous":true,"source_event":"order_created","source_event_id":"00065a1d-7f98-9368-0000-001202000020","source_event_id_unique":true,"source_pre_event_id":"00065a1d-7f98-8b98-0001-001201000020","translation":"UNFOLD_TO_INF","unfold_event_id":null,"zero_hair":false}
{"channel":"live_orders_ethusd","interaction_index":202,"natural_form":{"channel":"live_orders_ethusd","order_id":"2044303879634947","order_subtype":5,"order_type":1},"natural_form_sha256":"59eb385cbd286aec6db473476b7c0ec7618d3eea5ae19079e3e7ed246fe9d032","order_source":"orderbook","orders_submitted":0,"presentation":{"amount":"40.092050","amount_traded":"0","microtimestamp":"1787932601521000","price":"2494.27"},"previous_record_hash":"6f601ebdec54156ab3a12354f98d378da9a2e39c46e530898093cbeaca265bb8","profit_assessment":null,"record_hash":"65a950cd3439cdfd553110255ff44cebc5a884b1ec8404a431a44c63b096cc96","recorded_unix_us":1787932601587070,"recorded_utc":"2026-08-28T15:56:41.587070Z","schema_version":"nrrf810.exchange_authored_interactive_closure.v1","source_chain_continuous":true,"source_event":"order_created","source_event_id":"00065a1d-7f98-9368-0001-001203000020","source_event_id_unique":true,"source_pre_event_id":"00065a1d-7f98-9368-0000-001202000020","translation":"UNFOLD_TO_INF","unfold_event_id":null,"zero_hair":false}
{"channel":"live_orders_ethusd","interaction_index":203,"natural_form":{"channel":"live_orders_ethusd","order_id":"2044303879634948","order_subtype":5,"order_type":0},"natural_form_sha256":"488ac5e78008b16ec81c0bd80eb793e790ecf5a6ef056a30001f29583b0a77f3","order_source":"orderbook","orders_submitted":0,"presentation":{"amount":"4.033204","amount_traded":"0","microtimestamp":"1787932601521000","price":"2479.41"},"previous_record_hash":"65a950cd3439cdfd553110255ff44cebc5a884b1ec8404a431a44c63b096cc96","profit_assessment":null,"record_hash":"886d8ca34fae4409c056756e0b276f01f8745efb50fc43061a5e07d51ba89a3e","recorded_unix_us":1787932601587101,"recorded_utc":"2026-08-28T15:56:41.587101Z","schema_version":"nrrf810.exchange_authored_interactive_closure.v1","source_chain_continuous":true,"source_event":"order_created","source_event_id":"00065a1d-7f98-9368-0002-001200000020","source_event_id_unique":true,"source_pre_event_id":"00065a1d-7f98-9368-0001-001203000020","translation":"UNFOLD_TO_INF","unfold_event_id":null,"zero_hair":false}
{"channel":"live_orders_btcusd","interaction_index":204,"natural_form":{"channel":"live_orders_btcusd","order_id":"2044303879651332","order_subtype":5,"order_type":1},"natural_form_sha256":"eabf5967ee31211da2771a8eefdd0d402fe5a85649d5d6de1c60777f3b80d366","order_source":"orderbook","orders_submitted":0,"presentation":{"amount":"0.10000000","amount_traded":"0","microtimestamp":"1787932601526000","price":"78522.62"},"previous_record_hash":"886d8ca34fae4409c056756e0b276f01f8745efb50fc43061a5e07d51ba89a3e","profit_assessment":null,"record_hash":"ce043b2c23007667c6aaa93fc662fa01908040a39a567d3a5cf1e55f6ae2f5db","recorded_unix_us":1787932601587567,"recorded_utc":"2026-08-28T15:56:41.587567Z","schema_version":"nrrf810.exchange_authored_interactive_closure.v1","source_chain_continuous":true,"source_event":"order_created","source_event_id":"00065a1d-7f98-a6f0-0000-000103000020","source_event_id_unique":true,"source_pre_event_id":"00065a1d-7f98-7fe0-0000-000102000020","translation":"UNFOLD_TO_INF","unfold_event_id":null,"zero_hair":false}
{"channel":"live_orders_btcusd","interaction_index":205,"natural_form":{"channel":"live_orders_btcusd","order_id":"2044303879651332","order_subtype":5,"order_type":1},"natural_form_sha256":"eabf5967ee31211da2771a8eefdd0d402fe5a85649d5d6de1c60777f3b80d366","order_source":"orderbook","orders_submitted":0,"presentation":{"amount":"0.10000000","amount_traded":"0","microtimestamp":"1787932601526000","price":"78522.62"},"previous_record_hash":"ce043b2c23007667c6aaa93fc662fa01908040a39a567d3a5cf1e55f6ae2f5db","profit_assessment":null,"record_hash":"08c1080cdcbad5d5f99405c44d7bf93d2c71b2170fcf006585b209b47b5ca595","recorded_unix_us":1787932601587614,"recorded_utc":"2026-08-28T15:56:41.587614Z","schema_version":"nrrf810.exchange_authored_interactive_closure.v1","source_chain_continuous":true,"source_event":"order_deleted","source_event_id":"00065a1d-7f98-a6f0-0001-000100000020","source_event_id_unique":true,"source_pre_event_id":"00065a1d-7f98-a6f0-0000-000103000020","translation":"FOLD_RETURN_TO_ZERO","unfold_event_id":"00065a1d-7f98-a6f0-0000-000103000020","zero_hair":true}
{"channel":"live_orders_ethusd","interaction_index":206,"natural_form":{"channel":"live_orders_ethusd","order_id":"2044303879704578","order_subtype":5,"order_type":1},"natural_form_sha256":"19bdb9b2d10b6f71270de71d63bfa34722b791ceabc6a61cb5e32e0c961c950c","order_source":"orderbook","orders_submitted":0,"presentation":{"amount":"4.028412","amount_traded":"0","microtimestamp":"1787932601538000","price":"2482.37"},"previous_record_hash":"08c1080cdcbad5d5f99405c44d7bf93d2c71b2170fcf006585b209b47b5ca595","profit_assessment":null,"record_hash":"c32b6d5f590a7fd0956ec82eb67907ae78fe5ecc7d74ceddd38531ee2642dc2d","recorded_unix_us":1787932601587639,"recorded_utc":"2026-08-28T15:56:41.587639Z","schema_version":"nrrf810.exchange_authored_interactive_closure.v1","source_chain_continuous":true,"source_event":"order_created","source_event_id":"00065a1d-7f98-d5d0-0000-001201000020","source_event_id_unique":true,"source_pre_event_id":"00065a1d-7f98-9368-0002-001200000020","translation":"UNFOLD_TO_INF","unfold_event_id":null,"zero_hair":false}
{"channel":"live_orders_ethusd","interaction_index":207,"natural_form":{"channel":"live_orders_ethusd","order_id":"2044303879704580","order_subtype":5,"order_type":1},"natural_form_sha256":"7705ec5f64b4019a8bcdca662e5f99f65e496652cc8e06f36766de0737db7df7","order_source":"orderbook","orders_submitted":0,"presentation":{"amount":"20.077182","amount_traded":"0","microtimestamp":"1787932601539000","price":"2490.39"},"previous_record_hash":"c32b6d5f590a7fd0956ec82eb67907ae78fe5ecc7d74ceddd38531ee2642dc2d","profit_assessment":null,"record_hash":"b1a0d33594d21ba2882f286e7ac0521332057cd5d424b2c25df3b031a2080f79","recorded_unix_us":1787932601587662,"recorded_utc":"2026-08-28T15:56:41.587662Z","schema_version":"nrrf810.exchange_authored_interactive_closure.v1","source_chain_continuous":true,"source_event":"order_created","source_event_id":"00065a1d-7f98-d9b8-0000-001202000020","source_event_id_unique":true,"source_pre_event_id":"00065a1d-7f98-d5d0-0000-001201000020","translation":"UNFOLD_TO_INF","unfold_event_id":null,"zero_hair":false}
{"channel":"live_orders_btcusd","interaction_index":208,"natural_form":{"channel":"live_orders_btcusd","order_id":"2044303879569417","order_subtype":5,"order_type":0},"natural_form_sha256":"3e4452c6b208afd9062e83f4d822cee3ad0ef7a59632fa14255da715c0256beb","order_source":"orderbook","orders_submitted":0,"presentation":{"amount":"0.00140266","amount_traded":"0","microtimestamp":"1787932601539000","price":"70666.88"},"previous_record_hash":"b1a0d33594d21ba2882f286e7ac0521332057cd5d424b2c25df3b031a2080f79","profit_assessment":null,"record_hash":"404af7e5129e64e907d757d1a8118a582e392acf6417c353500d0038dd075822","recorded_unix_us":1787932601587684,"recorded_utc":"2026-08-28T15:56:41.587684Z","schema_version":"nrrf810.exchange_authored_interactive_closure.v1","source_chain_continuous":true,"source_event":"order_deleted","source_event_id":"00065a1d-7f98-d9b8-0000-000101000020","source_event_id_unique":true,"source_pre_event_id":"00065a1d-7f98-a6f0-0001-000100000020","translation":"FOLD_RETURN_TO_ZERO","unfold_event_id":"00065a1d-7f98-58d0-0000-000101000020","zero_hair":true}
{"channel":"live_orders_ethusd","interaction_index":209,"natural_form":{"channel":"live_orders_ethusd","order_id":"2044303879704581","order_subtype":5,"order_type":1},"natural_form_sha256":"2c014a489f0c93bbb1b138c0dde4c9f7bc231e2273743d3a72c4c6fe7db4c1ad","order_source":"orderbook","orders_submitted":0,"presentation":{"amount":"10.062547","amount_traded":"0","microtimestamp":"1787932601539000","price":"2484.47"},"previous_record_hash":"404af7e5129e64e907d757d1a8118a582e392acf6417c353500d0038dd075822","profit_assessment":null,"record_hash":"4b0667964760d8296e8053d32dffbad175474717c43b17af7835464d2b389896","recorded_unix_us":1787932601587758,"recorded_utc":"2026-08-28T15:56:41.587758Z","schema_version":"nrrf810.exchange_authored_interactive_closure.v1","source_chain_continuous":true,"source_event":"order_created","source_event_id":"00065a1d-7f98-d9b8-0001-001203000020","source_event_id_unique":true,"source_pre_event_id":"00065a1d-7f98-d9b8-0000-001202000020","translation":"UNFOLD_TO_INF","unfold_event_id":null,"zero_hair":false}
{"channel":"live_orders_ethusd","interaction_index":210,"natural_form":{"channel":"live_orders_ethusd","order_id":"2044303879708681","order_subtype":5,"order_type":1},"natural_form_sha256":"b432b999080d19c7042260cb672872af48c8bef6c4c06a7feb0b02a7772f17d2","order_source":"orderbook","orders_submitted":0,"presentation":{"amount":"40.051178","amount_traded":"0","microtimestamp":"1787932601540000","price":"2496.81"},"previous_record_hash":"4b0667964760d8296e8053d32dffbad175474717c43b17af7835464d2b389896","profit_assessment":null,"record_hash":"8a7181b3f369d407b70717ee556aac43e7213c074486f3c786ebca92843c3f56","recorded_unix_us":1787932601587862,"recorded_utc":"2026-08-28T15:56:41.587862Z","schema_version":"nrrf810.exchange_authored_interactive_closure.v1","source_chain_continuous":true,"source_event":"order_created","source_event_id":"00065a1d-7f98-dda0-0000-001200000020","source_event_id_unique":true,"source_pre_event_id":"00065a1d-7f98-d9b8-0001-001203000020","translation":"UNFOLD_TO_INF","unfold_event_id":null,"zero_hair":false}
{"channel":"live_orders_btcusd","interaction_index":211,"natural_form":{"channel":"live_orders_btcusd","order_id":"2044303879733256","order_subtype":5,"order_type":1},"natural_form_sha256":"5f4182c8337952a8e0dac6ef763dd3a3dced1424255efe104eff8e559a3f591e","order_source":"orderbook","orders_submitted":0,"presentation":{"amount":"0.06310787","amount_traded":"0","microtimestamp":"1787932601546000","price":"78520.44"},"previous_record_hash":"8a7181b3f369d407b70717ee556aac43e7213c074486f3c786ebca92843c3f56","profit_assessment":null,"record_hash":"66c8b90a4010c90adbd463d38c1cc37375a2647641d47d26f8840d8e89654116","recorded_unix_us":1787932601587909,"recorded_utc":"2026-08-28T15:56:41.587909Z","schema_version":"nrrf810.exchange_authored_interactive_closure.v1","source_chain_continuous":true,"source_event":"order_created","source_event_id":"00065a1d-7f98-f510-0000-000102000020","source_event_id_unique":true,"source_pre_event_id":"00065a1d-7f98-d9b8-0000-000101000020","translation":"UNFOLD_TO_INF","unfold_event_id":null,"zero_hair":false}
{"channel":"live_orders_btcusd","interaction_index":212,"natural_form":{"channel":"live_orders_btcusd","order_id":"2044303879733256","order_subtype":5,"order_type":1},"natural_form_sha256":"5f4182c8337952a8e0dac6ef763dd3a3dced1424255efe104eff8e559a3f591e","order_source":"orderbook","orders_submitted":0,"presentation":{"amount":"0.06310787","amount_traded":"0","microtimestamp":"1787932601546000","price":"78520.44"},"previous_record_hash":"66c8b90a4010c90adbd463d38c1cc37375a2647641d47d26f8840d8e89654116","profit_assessment":null,"record_hash":"a6103427fba6231c29abd7c81e36359d4fa297202d671d6c38289b0ce5c4b29d","recorded_unix_us":1787932601587933,"recorded_utc":"2026-08-28T15:56:41.587933Z","schema_version":"nrrf810.exchange_authored_interactive_closure.v1","source_chain_continuous":true,"source_event":"order_deleted","source_event_id":"00065a1d-7f98-f510-0001-000103000020","source_event_id_unique":true,"source_pre_event_id":"00065a1d-7f98-f510-0000-000102000020","translation":"FOLD_RETURN_TO_ZERO","unfold_event_id":"00065a1d-7f98-f510-0000-000102000020","zero_hair":true}
{"channel":"live_orders_btcusd","interaction_index":213,"natural_form":{"channel":"live_orders_btcusd","order_id":"2044303879757827","order_subtype":5,"order_type":1},"natural_form_sha256":"685f5960e70c7f52a0bab596e2db0d06d0e9390871ab2528d34e17cb53662521","order_source":"orderbook","orders_submitted":0,"presentation":{"amount":"0.10000000","amount_traded":"0","microtimestamp":"1787932601552000","price":"78522.63"},"previous_record_hash":"a6103427fba6231c29abd7c81e36359d4fa297202d671d6c38289b0ce5c4b29d","profit_assessment":null,"record_hash":"fc801335ad83e90a8aaa07299a088779716d73533cda342018344f551770c1b7","recorded_unix_us":1787932601593002,"recorded_utc":"2026-08-28T15:56:41.593002Z","schema_version":"nrrf810.exchange_authored_interactive_closure.v1","source_chain_continuous":true,"source_event":"order_created","source_event_id":"00065a1d-7f99-0c80-0000-000100000020","source_event_id_unique":true,"source_pre_event_id":"00065a1d-7f98-f510-0001-000103000020","translation":"UNFOLD_TO_INF","unfold_event_id":null,"zero_hair":false}
{"channel":"live_orders_btcusd","interaction_index":214,"natural_form":{"channel":"live_orders_btcusd","order_id":"2044303879757827","order_subtype":5,"order_type":1},"natural_form_sha256":"685f5960e70c7f52a0bab596e2db0d06d0e9390871ab2528d34e17cb53662521","order_source":"orderbook","orders_submitted":0,"presentation":{"amount":"0.10000000","amount_traded":"0","microtimestamp":"1787932601552000","price":"78522.63"},"previous_record_hash":"fc801335ad83e90a8aaa07299a088779716d73533cda342018344f551770c1b7","profit_assessment":null,"record_hash":"77c8bdcefab5daf52d706a5815c42fd637b8ad5fbdd3703e9e16dc4f4dda9993","recorded_unix_us":1787932601593032,"recorded_utc":"2026-08-28T15:56:41.593032Z","schema_version":"nrrf810.exchange_authored_interactive_closure.v1","source_chain_continuous":true,"source_event":"order_deleted","source_event_id":"00065a1d-7f99-0c80-0001-000101000020","source_event_id_unique":true,"source_pre_event_id":"00065a1d-7f99-0c80-0000-000100000020","translation":"FOLD_RETURN_TO_ZERO","unfold_event_id":"00065a1d-7f99-0c80-0000-000100000020","zero_hair":true}
{"channel":"live_orders_ethusd","interaction_index":215,"natural_form":{"channel":"live_orders_ethusd","order_id":"2044303879774213","order_subtype":5,"order_type":1},"natural_form_sha256":"3704e7599ecaeec8a2763ad11bda05b079e81d553f6bda34c61b774199f557f9","order_source":"orderbook","orders_submitted":0,"presentation":{"amount":"4.028003","amount_traded":"0","microtimestamp":"1787932601556000","price":"2482.62"},"previous_record_hash":"77c8bdcefab5daf52d706a5815c42fd637b8ad5fbdd3703e9e16dc4f4dda9993","profit_assessment":null,"record_hash":"1bab611fd2c00cc5fe718afe927d33c5ef141fd31bff947f11ce1b1aa43dfcc7","recorded_unix_us":1787932601593178,"recorded_utc":"2026-08-28T15:56:41.593178Z","schema_version":"nrrf810.exchange_authored_interactive_closure.v1","source_chain_continuous":true,"source_event":"order_created","source_event_id":"00065a1d-7f99-1c20-0000-001201000020","source_event_id_unique":true,"source_pre_event_id":"00065a1d-7f98-dda0-0000-001200000020","translation":"UNFOLD_TO_INF","unfold_event_id":null,"zero_hair":false}
{"channel":"live_orders_ethusd","interaction_index":216,"natural_form":{"channel":"live_orders_ethusd","order_id":"2044303879778310","order_subtype":5,"order_type":1},"natural_form_sha256":"52e858aa8aec79cffbc18050f0a763bcf732df5d34bcf34525d6875334c32932","order_source":"orderbook","orders_submitted":0,"presentation":{"amount":"10.059779","amount_traded":"0","microtimestamp":"1787932601557000","price":"2485.15"},"previous_record_hash":"1bab611fd2c00cc5fe718afe927d33c5ef141fd31bff947f11ce1b1aa43dfcc7","profit_assessment":null,"record_hash":"3b8046f908f1e030e23a1cd566f137636a1167eebde60b96b5bf752466336250","recorded_unix_us":1787932601593225,"recorded_utc":"2026-08-28T15:56:41.593225Z","schema_version":"nrrf810.exchange_authored_interactive_closure.v1","source_chain_continuous":true,"source_event":"order_created","source_event_id":"00065a1d-7f99-2008-0000-001202000020","source_event_id_unique":true,"source_pre_event_id":"00065a1d-7f99-1c20-0000-001201000020","translation":"UNFOLD_TO_INF","unfold_event_id":null,"zero_hair":false}
{"channel":"live_orders_ethusd","interaction_index":217,"natural_form":{"channel":"live_orders_ethusd","order_id":"2044303879782401","order_subtype":5,"order_type":1},"natural_form_sha256":"92963990ade07ea12dedde23c76cc6ccf1e3ed9923279db0b7b768a3066380cb","order_source":"orderbook","orders_submitted":0,"presentation":{"amount":"20.063885","amount_traded":"0","microtimestamp":"1787932601557000","price":"2492.04"},"previous_record_hash":"3b8046f908f1e030e23a1cd566f137636a1167eebde60b96b5bf752466336250","profit_assessment":null,"record_hash":"0569cbba6112c4155eab4e6cf0685cfd88c80623021bc97a631d2baa19494a62","recorded_unix_us":1787932601593362,"recorded_utc":"2026-08-28T15:56:41.593362Z","schema_version":"nrrf810.exchange_authored_interactive_closure.v1","source_chain_continuous":true,"source_event":"order_created","source_event_id":"00065a1d-7f99-2008-0001-001203000020","source_event_id_unique":true,"source_pre_event_id":"00065a1d-7f99-2008-0000-001202000020","translation":"UNFOLD_TO_INF","unfold_event_id":null,"zero_hair":false}
{"channel":"live_orders_ethusd","interaction_index":218,"natural_form":{"channel":"live_orders_ethusd","order_id":"2044303879786499","order_subtype":5,"order_type":1},"natural_form_sha256":"59df011270ad6d134ac89a2d150bf92e108ed492c2ae3cf3cea758c3498bb5df","order_source":"orderbook","orders_submitted":0,"presentation":{"amount":"40.010118","amount_traded":"0","microtimestamp":"1787932601559000","price":"2499.37"},"previous_record_hash":"0569cbba6112c4155eab4e6cf0685cfd88c80623021bc97a631d2baa19494a62","profit_assessment":null,"record_hash":"38c85710c77ed63226a248bea49f73b248afa81f419960dfa11efb586e015368","recorded_unix_us":1787932601593392,"recorded_utc":"2026-08-28T15:56:41.593392Z","schema_version":"nrrf810.exchange_authored_interactive_closure.v1","source_chain_continuous":true,"source_event":"order_created","source_event_id":"00065a1d-7f99-27d8-0000-001200000020","source_event_id_unique":true,"source_pre_event_id":"00065a1d-7f99-2008-0001-001203000020","translation":"UNFOLD_TO_INF","unfold_event_id":null,"zero_hair":false}
{"channel":"live_orders_btcusd","interaction_index":219,"natural_form":{"channel":"live_orders_btcusd","order_id":"2044303879794694","order_subtype":5,"order_type":1},"natural_form_sha256":"f5db8ff95910ca68a79b6ef94465f4c278f14d3832bca6832089239f6cd40c9c","order_source":"orderbook","orders_submitted":0,"presentation":{"amount":"0.10000000","amount_traded":"0","microtimestamp":"1787932601561000","price":"78522.62"},"previous_record_hash":"38c85710c77ed63226a248bea49f73b248afa81f419960dfa11efb586e015368","profit_assessment":null,"record_hash":"ece987dc462ec84f99e9b4c08d31cb9e5c0c31a2ee08e346e099e757a5462c87","recorded_unix_us":1787932601606244,"recorded_utc":"2026-08-28T15:56:41.606244Z","schema_version":"nrrf810.exchange_authored_interactive_closure.v1","source_chain_continuous":true,"source_event":"order_created","source_event_id":"00065a1d-7f99-2fa8-0000-000102000020","source_event_id_unique":true,"source_pre_event_id":"00065a1d-7f99-0c80-0001-000101000020","translation":"UNFOLD_TO_INF","unfold_event_id":null,"zero_hair":false}
{"channel":"live_orders_btcusd","interaction_index":220,"natural_form":{"channel":"live_orders_btcusd","order_id":"2044303879794694","order_subtype":5,"order_type":1},"natural_form_sha256":"f5db8ff95910ca68a79b6ef94465f4c278f14d3832bca6832089239f6cd40c9c","order_source":"orderbook","orders_submitted":0,"presentation":{"amount":"0.10000000","amount_traded":"0","microtimestamp":"1787932601561000","price":"78522.62"},"previous_record_hash":"ece987dc462ec84f99e9b4c08d31cb9e5c0c31a2ee08e346e099e757a5462c87","profit_assessment":null,"record_hash":"352e1a4e6d450cea5764353e59e569a4c04162eb10e088b216160321b9541f9f","recorded_unix_us":1787932601606324,"recorded_utc":"2026-08-28T15:56:41.606324Z","schema_version":"nrrf810.exchange_authored_interactive_closure.v1","source_chain_continuous":true,"source_event":"order_deleted","source_event_id":"00065a1d-7f99-2fa8-0001-000103000020","source_event_id_unique":true,"source_pre_event_id":"00065a1d-7f99-2fa8-0000-000102000020","translation":"FOLD_RETURN_TO_ZERO","unfold_event_id":"00065a1d-7f99-2fa8-0000-000102000020","zero_hair":true}
{"channel":"live_orders_btcusd","interaction_index":221,"natural_form":{"channel":"live_orders_btcusd","order_id":"2044303879835654","order_subtype":5,"order_type":0},"natural_form_sha256":"cf78951fd19eb28753d5ca28ff28ef96852c03de158385ca34f4d38fcdbf1e36","order_source":"orderbook","orders_submitted":0,"presentation":{"amount":"1.20000000","amount_traded":"0","microtimestamp":"1787932601571000","price":"78482.00"},"previous_record_hash":"352e1a4e6d450cea5764353e59e569a4c04162eb10e088b216160321b9541f9f","profit_assessment":null,"record_hash":"ca5313d9546274f8060cedb3509be627f627e774d344edeb63285302f01549f1","recorded_unix_us":1787932601606455,"recorded_utc":"2026-08-28T15:56:41.606455Z","schema_version":"nrrf810.exchange_authored_interactive_closure.v1","source_chain_continuous":true,"source_event":"order_created","source_event_id":"00065a1d-7f99-56b8-0000-000100000020","source_event_id_unique":true,"source_pre_event_id":"00065a1d-7f99-2fa8-0001-000103000020","translation":"UNFOLD_TO_INF","unfold_event_id":null,"zero_hair":false}
{"channel":"live_orders_btcusd","interaction_index":222,"natural_form":{"channel":"live_orders_btcusd","order_id":"2044303879839747","order_subtype":5,"order_type":1},"natural_form_sha256":"8686126597e356ba5fb3d89cd4d468e9a762a8674c7a9c636cdd04a1b216427d","order_source":"orderbook","orders_submitted":0,"presentation":{"amount":"0.06310787","amount_traded":"0","microtimestamp":"1787932601572000","price":"78520.35"},"previous_record_hash":"ca5313d9546274f8060cedb3509be627f627e774d344edeb63285302f01549f1","profit_assessment":null,"record_hash":"a467f99cb9ad8246d4859891490811a7a56dd2c9675942725429cfb9504e3c96","recorded_unix_us":1787932601606522,"recorded_utc":"2026-08-28T15:56:41.606522Z","schema_version":"nrrf810.exchange_authored_interactive_closure.v1","source_chain_continuous":true,"source_event":"order_created","source_event_id":"00065a1d-7f99-5aa0-0000-000101000020","source_event_id_unique":true,"source_pre_event_id":"00065a1d-7f99-56b8-0000-000100000020","translation":"UNFOLD_TO_INF","unfold_event_id":null,"zero_hair":false}
{"channel":"live_orders_btcusd","interaction_index":223,"natural_form":{"channel":"live_orders_btcusd","order_id":"2044303879839747","order_subtype":5,"order_type":1},"natural_form_sha256":"8686126597e356ba5fb3d89cd4d468e9a762a8674c7a9c636cdd04a1b216427d","order_source":"orderbook","orders_submitted":0,"presentation":{"amount":"0.06310787","amount_traded":"0","microtimestamp":"1787932601572000","price":"78520.35"},"previous_record_hash":"a467f99cb9ad8246d4859891490811a7a56dd2c9675942725429cfb9504e3c96","profit_assessment":null,"record_hash":"61806af7e2eed24e5487e4b9657b0e07ddb30c6e1fa0ff0a9ef9171bf0865ea7","recorded_unix_us":1787932601606549,"recorded_utc":"2026-08-28T15:56:41.606549Z","schema_version":"nrrf810.exchange_authored_interactive_closure.v1","source_chain_continuous":true,"source_event":"order_deleted","source_event_id":"00065a1d-7f99-5aa0-0001-000102000020","source_event_id_unique":true,"source_pre_event_id":"00065a1d-7f99-5aa0-0000-000101000020","translation":"FOLD_RETURN_TO_ZERO","unfold_event_id":"00065a1d-7f99-5aa0-0000-000101000020","zero_hair":true}
{"channel":"live_orders_ethusd","interaction_index":224,"natural_form":{"channel":"live_orders_ethusd","order_id":"2044303879847937","order_subtype":5,"order_type":1},"natural_form_sha256":"2e377e95f8925722d8e03c2af5517681a5fca59325fdcf93a80d021ff5116f9a","order_source":"orderbook","orders_submitted":0,"presentation":{"amount":"4.027586","amount_traded":"0","microtimestamp":"1787932601573000","price":"2482.88"},"previous_record_hash":"61806af7e2eed24e5487e4b9657b0e07ddb30c6e1fa0ff0a9ef9171bf0865ea7","profit_assessment":null,"record_hash":"e841ebc416049ff7271d8698ac0a0f34c3cbd48e2120e5c96d840b0c1d8363c5","recorded_unix_us":1787932601606627,"recorded_utc":"2026-08-28T15:56:41.606627Z","schema_version":"nrrf810.exchange_authored_interactive_closure.v1","source_chain_continuous":true,"source_event":"order_created","source_event_id":"00065a1d-7f99-5e88-0000-001201000020","source_event_id_unique":true,"source_pre_event_id":"00065a1d-7f99-27d8-0000-001200000020","translation":"UNFOLD_TO_INF","unfold_event_id":null,"zero_hair":false}
{"channel":"live_orders_btcusd","interaction_index":225,"natural_form":{"channel":"live_orders_btcusd","order_id":"2044303879860225","order_subtype":5,"order_type":1},"natural_form_sha256":"c4ec89c351e881c6e86eae8be2e4aedc6ce1dc4a6c0affa4fbbae22fad8f6c69","order_source":"orderbook","orders_submitted":0,"presentation":{"amount":"1.20000000","amount_traded":"0","microtimestamp":"1787932601577000","price":"78525.00"},"previous_record_hash":"e841ebc416049ff7271d8698ac0a0f34c3cbd48e2120e5c96d840b0c1d8363c5","profit_assessment":null,"record_hash":"0ec1eefe8ee6be2eef2de97ebc5bf7f1ccc61ab20e2744a7f96fe5c5df74c9fd","recorded_unix_us":1787932601624968,"recorded_utc":"2026-08-28T15:56:41.624968Z","schema_version":"nrrf810.exchange_authored_interactive_closure.v1","source_chain_continuous":true,"source_event":"order_created","source_event_id":"00065a1d-7f99-6e28-0000-000103000020","source_event_id_unique":true,"source_pre_event_id":"00065a1d-7f99-5aa0-0001-000102000020","translation":"UNFOLD_TO_INF","unfold_event_id":null,"zero_hair":false}
{"channel":"live_orders_ethusd","interaction_index":226,"natural_form":{"channel":"live_orders_ethusd","order_id":"2044303877263369","order_subtype":5,"order_type":1},"natural_form_sha256":"71fb44fe0dbfefb98dcd851486b71730f640a198de50da7404fe5da8d50ef832","order_source":"orderbook","orders_submitted":0,"presentation":{"amount":"5.000000","amount_traded":"0","microtimestamp":"1787932601580000","price":"2481.49"},"previous_record_hash":"0ec1eefe8ee6be2eef2de97ebc5bf7f1ccc61ab20e2744a7f96fe5c5df74c9fd","profit_assessment":null,"record_hash":"64304f5c4a5af6e1fc1759a19318c35baf6a7bc95ab5cdde9b4e3ea97a66e340","recorded_unix_us":1787932601625158,"recorded_utc":"2026-08-28T15:56:41.625158Z","schema_version":"nrrf810.exchange_authored_interactive_closure.v1","source_chain_continuous":true,"source_event":"order_deleted","source_event_id":"00065a1d-7f99-79e0-0000-001202000020","source_event_id_unique":true,"source_pre_event_id":"00065a1d-7f99-5e88-0000-001201000020","translation":"PARTIAL_PRIOR_UNFOLD","unfold_event_id":null,"zero_hair":false}
{"channel":"live_orders_ethusd","interaction_index":227,"natural_form":{"channel":"live_orders_ethusd","order_id":"2044303877292039","order_subtype":5,"order_type":1},"natural_form_sha256":"c06d12bf9c4b55e15cf71d73cc72af7fe42187bebeb7b10a9d9eb52118a4867f","order_source":"orderbook","orders_submitted":0,"presentation":{"amount":"5.000000","amount_traded":"0","microtimestamp":"1787932601580000","price":"2481.74"},"previous_record_hash":"64304f5c4a5af6e1fc1759a19318c35baf6a7bc95ab5cdde9b4e3ea97a66e340","profit_assessment":null,"record_hash":"8d496be113814244d746031d74b3b557adf2b0264a64a75d850a56d161a185da","recorded_unix_us":1787932601625261,"recorded_utc":"2026-08-28T15:56:41.625261Z","schema_version":"nrrf810.exchange_authored_interactive_closure.v1","source_chain_continuous":true,"source_event":"order_deleted","source_event_id":"00065a1d-7f99-79e0-0001-001203000020","source_event_id_unique":true,"source_pre_event_id":"00065a1d-7f99-79e0-0000-001202000020","translation":"PARTIAL_PRIOR_UNFOLD","unfold_event_id":null,"zero_hair":false}
{"channel":"live_orders_btcusd","interaction_index":228,"natural_form":{"channel":"live_orders_btcusd","order_id":"2044303879913472","order_subtype":5,"order_type":1},"natural_form_sha256":"c647dd41bfac149db37fa903bffc2e0b7d6f43c8b5cf740caa6d77f04a0c26a7","order_source":"orderbook","orders_submitted":0,"presentation":{"amount":"0.10000000","amount_traded":"0","microtimestamp":"1787932601589000","price":"78522.63"},"previous_record_hash":"8d496be113814244d746031d74b3b557adf2b0264a64a75d850a56d161a185da","profit_assessment":null,"record_hash":"c70676b6ee7e8eb57e1fa183908aed4ca970cef019c947e20ddcbff55c01ddcf","recorded_unix_us":1787932601625362,"recorded_utc":"2026-08-28T15:56:41.625362Z","schema_version":"nrrf810.exchange_authored_interactive_closure.v1","source_chain_continuous":true,"source_event":"order_created","source_event_id":"00065a1d-7f99-9d08-0000-000100000020","source_event_id_unique":true,"source_pre_event_id":"00065a1d-7f99-6e28-0000-000103000020","translation":"UNFOLD_TO_INF","unfold_event_id":null,"zero_hair":false}
{"channel":"live_orders_btcusd","interaction_index":229,"natural_form":{"channel":"live_orders_btcusd","order_id":"2044303879913472","order_subtype":5,"order_type":1},"natural_form_sha256":"c647dd41bfac149db37fa903bffc2e0b7d6f43c8b5cf740caa6d77f04a0c26a7","order_source":"orderbook","orders_submitted":0,"presentation":{"amount":"0.10000000","amount_traded":"0","microtimestamp":"1787932601589000","price":"78522.63"},"previous_record_hash":"c70676b6ee7e8eb57e1fa183908aed4ca970cef019c947e20ddcbff55c01ddcf","profit_assessment":null,"record_hash":"8c970c6919bb7c88a9be591a5e796d3ab842ebd5d60f1ac778e7a08fa07b730e","recorded_unix_us":1787932601625449,"recorded_utc":"2026-08-28T15:56:41.625449Z","schema_version":"nrrf810.exchange_authored_interactive_closure.v1","source_chain_continuous":true,"source_event":"order_deleted","source_event_id":"00065a1d-7f99-9d08-0001-000101000020","source_event_id_unique":true,"source_pre_event_id":"00065a1d-7f99-9d08-0000-000100000020","translation":"FOLD_RETURN_TO_ZERO","unfold_event_id":"00065a1d-7f99-9d08-0000-000100000020","zero_hair":true}
{"channel":"live_orders_btcusd","interaction_index":230,"natural_form":{"channel":"live_orders_btcusd","order_id":"2044303879917571","order_subtype":5,"order_type":0},"natural_form_sha256":"66032732daa1ca466ffa06883cdb292e88d6c8ab3a0a50be8ef43601c2c2646f","order_source":"orderbook","orders_submitted":0,"presentation":{"amount":"0.00140266","amount_traded":"0","microtimestamp":"1787932601590000","price":"70667.51"},"previous_record_hash":"8c970c6919bb7c88a9be591a5e796d3ab842ebd5d60f1ac778e7a08fa07b730e","profit_assessment":null,"record_hash":"73a85bd57bf34cd39ea95596ec9604165a5072414c6854df018ea24a84309861","recorded_unix_us":1787932601630093,"recorded_utc":"2026-08-28T15:56:41.630093Z","schema_version":"nrrf810.exchange_authored_interactive_closure.v1","source_chain_continuous":true,"source_event":"order_created","source_event_id":"00065a1d-7f99-a0f0-0000-000102000020","source_event_id_unique":true,"source_pre_event_id":"00065a1d-7f99-9d08-0001-000101000020","translation":"UNFOLD_TO_INF","unfold_event_id":null,"zero_hair":false}
{"channel":"live_orders_btcusd","interaction_index":231,"natural_form":{"channel":"live_orders_btcusd","order_id":"2044303859847183","order_subtype":0,"order_type":1},"natural_form_sha256":"0699699c7e5e2bc071e865163e63c7d57f2ca407d3465d4cf53a076ef0e353c9","order_source":"orderbook","orders_submitted":0,"presentation":{"amount":"0.06310787","amount_traded":"0","microtimestamp":"1787932601594000","price":"78550.86"},"previous_record_hash":"73a85bd57bf34cd39ea95596ec9604165a5072414c6854df018ea24a84309861","profit_assessment":null,"record_hash":"e21e7ff9b96f76fc01a9b7bab47b089afe74cd40b4b26666c228657fbaf70682","recorded_unix_us":1787932601630218,"recorded_utc":"2026-08-28T15:56:41.630218Z","schema_version":"nrrf810.exchange_authored_interactive_closure.v1","source_chain_continuous":true,"source_event":"order_deleted","source_event_id":"00065a1d-7f99-b090-0000-000103000020","source_event_id_unique":true,"source_pre_event_id":"00065a1d-7f99-a0f0-0000-000102000020","translation":"PARTIAL_PRIOR_UNFOLD","unfold_event_id":null,"zero_hair":false}
{"channel":"live_orders_btcusd","interaction_index":232,"natural_form":{"channel":"live_orders_btcusd","order_id":"2044303879962625","order_subtype":5,"order_type":1},"natural_form_sha256":"767d6e503576839004d0f1848b717f27811852eb052466f0d2c070c0982d1f69","order_source":"orderbook","orders_submitted":0,"presentation":{"amount":"0.06310787","amount_traded":"0","microtimestamp":"1787932601602000","price":"78520.22"},"previous_record_hash":"e21e7ff9b96f76fc01a9b7bab47b089afe74cd40b4b26666c228657fbaf70682","profit_assessment":null,"record_hash":"e1fa6bc48b79917a2a652a21d21a1f52390e71b94a23ce2b007f07b80ef5fed5","recorded_unix_us":1787932601630361,"recorded_utc":"2026-08-28T15:56:41.630361Z","schema_version":"nrrf810.exchange_authored_interactive_closure.v1","source_chain_continuous":true,"source_event":"order_created","source_event_id":"00065a1d-7f99-cfd0-0000-000100000020","source_event_id_unique":true,"source_pre_event_id":"00065a1d-7f99-b090-0000-000103000020","translation":"UNFOLD_TO_INF","unfold_event_id":null,"zero_hair":false}
{"channel":"live_orders_btcusd","interaction_index":233,"natural_form":{"channel":"live_orders_btcusd","order_id":"2044303879962625","order_subtype":5,"order_type":1},"natural_form_sha256":"767d6e503576839004d0f1848b717f27811852eb052466f0d2c070c0982d1f69","order_source":"orderbook","orders_submitted":0,"presentation":{"amount":"0.06310787","amount_traded":"0","microtimestamp":"1787932601602000","price":"78520.22"},"previous_record_hash":"e1fa6bc48b79917a2a652a21d21a1f52390e71b94a23ce2b007f07b80ef5fed5","profit_assessment":null,"record_hash":"b292e380e6058135a4369c52a3e1eae4a2eb0a6e517ae584452090679d9b8d2d","recorded_unix_us":1787932601630391,"recorded_utc":"2026-08-28T15:56:41.630391Z","schema_version":"nrrf810.exchange_authored_interactive_closure.v1","source_chain_continuous":true,"source_event":"order_deleted","source_event_id":"00065a1d-7f99-cfd0-0001-000101000020","source_event_id_unique":true,"source_pre_event_id":"00065a1d-7f99-cfd0-0000-000100000020","translation":"FOLD_RETURN_TO_ZERO","unfold_event_id":"00065a1d-7f99-cfd0-0000-000100000020","zero_hair":true}
{"channel":"live_orders_btcusd","interaction_index":234,"natural_form":{"channel":"live_orders_btcusd","order_id":"2044303879974913","order_subtype":5,"order_type":1},"natural_form_sha256":"f6373899d9d1a377f3421ab71da83a8ab54c25e0866d10958174521ffc9370b5","order_source":"orderbook","orders_submitted":0,"presentation":{"amount":"0.10000000","amount_traded":"0","microtimestamp":"1787932601604000","price":"78522.62"},"previous_record_hash":"b292e380e6058135a4369c52a3e1eae4a2eb0a6e517ae584452090679d9b8d2d","profit_assessment":null,"record_hash":"9f8510cfb1ec6ce2c82ca4978078fcd85b5a9010db9c68e7e66e1b88694f05a4","recorded_unix_us":1787932601648900,"recorded_utc":"2026-08-28T15:56:41.648900Z","schema_version":"nrrf810.exchange_authored_interactive_closure.v1","source_chain_continuous":true,"source_event":"order_created","source_event_id":"00065a1d-7f99-d7a0-0000-000102000020","source_event_id_unique":true,"source_pre_event_id":"00065a1d-7f99-cfd0-0001-000101000020","translation":"UNFOLD_TO_INF","unfold_event_id":null,"zero_hair":false}
{"channel":"live_orders_btcusd","interaction_index":235,"natural_form":{"channel":"live_orders_btcusd","order_id":"2044303879974913","order_subtype":5,"order_type":1},"natural_form_sha256":"f6373899d9d1a377f3421ab71da83a8ab54c25e0866d10958174521ffc9370b5","order_source":"orderbook","orders_submitted":0,"presentation":{"amount":"0.10000000","amount_traded":"0","microtimestamp":"1787932601604000","price":"78522.62"},"previous_record_hash":"9f8510cfb1ec6ce2c82ca4978078fcd85b5a9010db9c68e7e66e1b88694f05a4","profit_assessment":null,"record_hash":"c9ef632aad2bc2fe98a5ac83ff4a55fcf04dbb8b68c15fb4b0cfa4b3b0a1f72e","recorded_unix_us":1787932601649128,"recorded_utc":"2026-08-28T15:56:41.649128Z","schema_version":"nrrf810.exchange_authored_interactive_closure.v1","source_chain_continuous":true,"source_event":"order_deleted","source_event_id":"00065a1d-7f99-d7a0-0001-000103000020","source_event_id_unique":true,"source_pre_event_id":"00065a1d-7f99-d7a0-0000-000102000020","translation":"FOLD_RETURN_TO_ZERO","unfold_event_id":"00065a1d-7f99-d7a0-0000-000102000020","zero_hair":true}
{"channel":"live_orders_btcusd","interaction_index":236,"natural_form":{"channel":"live_orders_btcusd","order_id":"2044303879979008","order_subtype":5,"order_type":1},"natural_form_sha256":"78709ae4e05060076a691a6e7f7fac5a9636de4d69c404ee93f325dd221cf592","order_source":"orderbook","orders_submitted":0,"presentation":{"amount":"0.06310787","amount_traded":"0","microtimestamp":"1787932601606000","price":"78522.58"},"previous_record_hash":"c9ef632aad2bc2fe98a5ac83ff4a55fcf04dbb8b68c15fb4b0cfa4b3b0a1f72e","profit_assessment":null,"record_hash":"c9207c8712a42e43bb4e47d035b46029e31e3b1bd78aee06abe8a1f05ae8072e","recorded_unix_us":1787932601649175,"recorded_utc":"2026-08-28T15:56:41.649175Z","schema_version":"nrrf810.exchange_authored_interactive_closure.v1","source_chain_continuous":true,"source_event":"order_created","source_event_id":"00065a1d-7f99-df70-0000-000100000020","source_event_id_unique":true,"source_pre_event_id":"00065a1d-7f99-d7a0-0001-000103000020","translation":"UNFOLD_TO_INF","unfold_event_id":null,"zero_hair":false}
{"channel":"live_orders_btcusd","interaction_index":237,"natural_form":{"channel":"live_orders_btcusd","order_id":"2044303879979008","order_subtype":5,"order_type":1},"natural_form_sha256":"78709ae4e05060076a691a6e7f7fac5a9636de4d69c404ee93f325dd221cf592","order_source":"orderbook","orders_submitted":0,"presentation":{"amount":"0.06310787","amount_traded":"0","microtimestamp":"1787932601606000","price":"78522.58"},"previous_record_hash":"c9207c8712a42e43bb4e47d035b46029e31e3b1bd78aee06abe8a1f05ae8072e","profit_assessment":null,"record_hash":"5c0f38a1b6e7e1effcae527f73503ab5a704f758d4da970744dfa552f79826e6","recorded_unix_us":1787932601649293,"recorded_utc":"2026-08-28T15:56:41.649293Z","schema_version":"nrrf810.exchange_authored_interactive_closure.v1","source_chain_continuous":true,"source_event":"order_deleted","source_event_id":"00065a1d-7f99-df70-0001-000101000020","source_event_id_unique":true,"source_pre_event_id":"00065a1d-7f99-df70-0000-000100000020","translation":"FOLD_RETURN_TO_ZERO","unfold_event_id":"00065a1d-7f99-df70-0000-000100000020","zero_hair":true}
{"channel":"live_orders_btcusd","interaction_index":238,"natural_form":{"channel":"live_orders_btcusd","order_id":"2044303880036355","order_subtype":5,"order_type":1},"natural_form_sha256":"7128e40f70510ef891d8e4e0117a612ca238d2e2e2aeabbbb3f08637dd63c517","order_source":"orderbook","orders_submitted":0,"presentation":{"amount":"0.10000000","amount_traded":"0","microtimestamp":"1787932601619000","price":"78522.63"},"previous_record_hash":"5c0f38a1b6e7e1effcae527f73503ab5a704f758d4da970744dfa552f79826e6","profit_assessment":null,"record_hash":"fba48400f5330ec2bf830b6cda0101f2aec4d2a3c74b46489a39fc732a782ce6","recorded_unix_us":1787932601663126,"recorded_utc":"2026-08-28T15:56:41.663126Z","schema_version":"nrrf810.exchange_authored_interactive_closure.v1","source_chain_continuous":true,"source_event":"order_created","source_event_id":"00065a1d-7f9a-1238-0000-000102000020","source_event_id_unique":true,"source_pre_event_id":"00065a1d-7f99-df70-0001-000101000020","translation":"UNFOLD_TO_INF","unfold_event_id":null,"zero_hair":false}
{"channel":"live_orders_btcusd","interaction_index":239,"natural_form":{"channel":"live_orders_btcusd","order_id":"2044303880036355","order_subtype":5,"order_type":1},"natural_form_sha256":"7128e40f70510ef891d8e4e0117a612ca238d2e2e2aeabbbb3f08637dd63c517","order_source":"orderbook","orders_submitted":0,"presentation":{"amount":"0.10000000","amount_traded":"0","microtimestamp":"1787932601619000","price":"78522.63"},"previous_record_hash":"fba48400f5330ec2bf830b6cda0101f2aec4d2a3c74b46489a39fc732a782ce6","profit_assessment":null,"record_hash":"8a63c7c7e747f712c7cefb6c42c14cf702b617c47de5c456e89ac6c241fb7a39","recorded_unix_us":1787932601663238,"recorded_utc":"2026-08-28T15:56:41.663238Z","schema_version":"nrrf810.exchange_authored_interactive_closure.v1","source_chain_continuous":true,"source_event":"order_deleted","source_event_id":"00065a1d-7f9a-1238-0001-000103000020","source_event_id_unique":true,"source_pre_event_id":"00065a1d-7f9a-1238-0000-000102000020","translation":"FOLD_RETURN_TO_ZERO","unfold_event_id":"00065a1d-7f9a-1238-0000-000102000020","zero_hair":true}
{"channel":"live_orders_ethbtc","interaction_index":240,"natural_form":{"channel":"live_orders_ethbtc","order_id":"2044303844184069","order_subtype":5,"order_type":1},"natural_form_sha256":"0b4700cc70286bfab431699a3691e39236b79ebcca31dd7bff8efe45cc84fb41","order_source":"orderbook","orders_submitted":0,"presentation":{"amount":"0.13516584","amount_traded":"0","microtimestamp":"1787932601637000","price":"0.03429999"},"previous_record_hash":"8a63c7c7e747f712c7cefb6c42c14cf702b617c47de5c456e89ac6c241fb7a39","profit_assessment":null,"record_hash":"681743c9cb8baf468194a10ebb4b37a30cd58473fd9930effcfaf9525aa8508e","recorded_unix_us":1787932601676242,"recorded_utc":"2026-08-28T15:56:41.676242Z","schema_version":"nrrf810.exchange_authored_interactive_closure.v1","source_chain_continuous":true,"source_event":"order_deleted","source_event_id":"00065a1d-7f9a-5888-0000-001102000020","source_event_id_unique":true,"source_pre_event_id":"00065a1d-7f97-1498-0000-001101000020","translation":"PARTIAL_PRIOR_UNFOLD","unfold_event_id":null,"zero_hair":false}
{"channel":"live_orders_btcusd","interaction_index":241,"natural_form":{"channel":"live_orders_btcusd","order_id":"2044303877484546","order_subtype":5,"order_type":0},"natural_form_sha256":"eb1f535455d655ccdd6ae56b5738612adca72f01fe7a0de546c8a4a16dc8d634","order_source":"orderbook","orders_submitted":0,"presentation":{"amount":"0.35667323","amount_traded":"0","microtimestamp":"1787932601641000","price":"78486.82"},"previous_record_hash":"681743c9cb8baf468194a10ebb4b37a30cd58473fd9930effcfaf9525aa8508e","profit_assessment":null,"record_hash":"df0564268d3f5eff7d425380367eb58e27e109507c0d106d809f31438b217224","recorded_unix_us":1787932601676442,"recorded_utc":"2026-08-28T15:56:41.676442Z","schema_version":"nrrf810.exchange_authored_interactive_closure.v1","source_chain_continuous":true,"source_event":"order_deleted","source_event_id":"00065a1d-7f9a-6828-0000-000100000020","source_event_id_unique":true,"source_pre_event_id":"00065a1d-7f9a-1238-0001-000103000020","translation":"PARTIAL_PRIOR_UNFOLD","unfold_event_id":null,"zero_hair":false}
{"channel":"live_orders_btcusd","interaction_index":242,"natural_form":{"channel":"live_orders_btcusd","order_id":"2044303880122368","order_subtype":5,"order_type":0},"natural_form_sha256":"d08f4daef6a50bf09b00a2b9048b5e566174683e3d03e956d373bec3057135ef","order_source":"orderbook","orders_submitted":0,"presentation":{"amount":"0.26750492","amount_traded":"0","microtimestamp":"1787932601641000","price":"78486.82"},"previous_record_hash":"df0564268d3f5eff7d425380367eb58e27e109507c0d106d809f31438b217224","profit_assessment":null,"record_hash":"87bf27e4d01efe0a7af18f8c996af424f960c474877fc7ea92cb792928bdcf09","recorded_unix_us":1787932601676560,"recorded_utc":"2026-08-28T15:56:41.676560Z","schema_version":"nrrf810.exchange_authored_interactive_closure.v1","source_chain_continuous":true,"source_event":"order_created","source_event_id":"00065a1d-7f9a-6828-0001-000101000020","source_event_id_unique":true,"source_pre_event_id":"00065a1d-7f9a-6828-0000-000100000020","translation":"UNFOLD_TO_INF","unfold_event_id":null,"zero_hair":false}
{"channel":"live_orders_ethbtc","interaction_index":243,"natural_form":{"channel":"live_orders_ethbtc","order_id":"2044303880138752","order_subtype":5,"order_type":0},"natural_form_sha256":"9e2e81258a82960328f931bb2b32d863a52d1ab50624ae55f57b60e29665ddc2","order_source":"orderbook","orders_submitted":0,"presentation":{"amount":"0.60475617","amount_traded":"0","microtimestamp":"1787932601645000","price":"0.03158982"},"previous_record_hash":"87bf27e4d01efe0a7af18f8c996af424f960c474877fc7ea92cb792928bdcf09","profit_assessment":null,"record_hash":"f6018351b5692e5b72d42faab6e0b68818ae4a368122b25bf7b9f8caf2c4dc37","recorded_unix_us":1787932601676644,"recorded_utc":"2026-08-28T15:56:41.676644Z","schema_version":"nrrf810.exchange_authored_interactive_closure.v1","source_chain_continuous":true,"source_event":"order_created","source_event_id":"00065a1d-7f9a-77c8-0000-001103000020","source_event_id_unique":true,"source_pre_event_id":"00065a1d-7f9a-5888-0000-001102000020","translation":"UNFOLD_TO_INF","unfold_event_id":null,"zero_hair":false}
{"channel":"live_orders_btcusd","interaction_index":244,"natural_form":{"channel":"live_orders_btcusd","order_id":"2044303880151042","order_subtype":5,"order_type":1},"natural_form_sha256":"488c35db59d462d1a4f2da4d14bfc64c84cf9b12d50c2908598db0de14c369b6","order_source":"orderbook","orders_submitted":0,"presentation":{"amount":"0.06310787","amount_traded":"0","microtimestamp":"1787932601648000","price":"78520.32"},"previous_record_hash":"f6018351b5692e5b72d42faab6e0b68818ae4a368122b25bf7b9f8caf2c4dc37","profit_assessment":null,"record_hash":"4ecf9048f7ef023665e9344714a4a68958b85fcc1c0762a11ff96b563754f9f7","recorded_unix_us":1787932601676752,"recorded_utc":"2026-08-28T15:56:41.676752Z","schema_version":"nrrf810.exchange_authored_interactive_closure.v1","source_chain_continuous":true,"source_event":"order_created","source_event_id":"00065a1d-7f9a-8380-0000-000102000020","source_event_id_unique":true,"source_pre_event_id":"00065a1d-7f9a-6828-0001-000101000020","translation":"UNFOLD_TO_INF","unfold_event_id":null,"zero_hair":false}
{"channel":"live_orders_btcusd","interaction_index":245,"natural_form":{"channel":"live_orders_btcusd","order_id":"2044303880151042","order_subtype":5,"order_type":1},"natural_form_sha256":"488c35db59d462d1a4f2da4d14bfc64c84cf9b12d50c2908598db0de14c369b6","order_source":"orderbook","orders_submitted":0,"presentation":{"amount":"0.06310787","amount_traded":"0","microtimestamp":"1787932601648000","price":"78520.32"},"previous_record_hash":"4ecf9048f7ef023665e9344714a4a68958b85fcc1c0762a11ff96b563754f9f7","profit_assessment":null,"record_hash":"e30f7598a564ed466435bfecc8aa26af47fe6484097d50c1469d037a6268473b","recorded_unix_us":1787932601676779,"recorded_utc":"2026-08-28T15:56:41.676779Z","schema_version":"nrrf810.exchange_authored_interactive_closure.v1","source_chain_continuous":true,"source_event":"order_deleted","source_event_id":"00065a1d-7f9a-8380-0001-000103000020","source_event_id_unique":true,"source_pre_event_id":"00065a1d-7f9a-8380-0000-000102000020","translation":"FOLD_RETURN_TO_ZERO","unfold_event_id":"00065a1d-7f9a-8380-0000-000102000020","zero_hair":true}
{"channel":"live_orders_ethusd","interaction_index":246,"natural_form":{"channel":"live_orders_ethusd","order_id":"2044303880155139","order_subtype":5,"order_type":1},"natural_form_sha256":"61bdb6df5db13871e01ebea08a7d20dcbc2f7c9156b7792c39f210215d71c6b3","order_source":"orderbook","orders_submitted":0,"presentation":{"amount":"5.000000","amount_traded":"0","microtimestamp":"1787932601648000","price":"2481.48"},"previous_record_hash":"e30f7598a564ed466435bfecc8aa26af47fe6484097d50c1469d037a6268473b","profit_assessment":null,"record_hash":"62e044f88020973d38fb27e64c8ece61d35b5a4bbf34b960598b165d9fad6abc","recorded_unix_us":1787932601676906,"recorded_utc":"2026-08-28T15:56:41.676906Z","schema_version":"nrrf810.exchange_authored_interactive_closure.v1","source_chain_continuous":true,"source_event":"order_created","source_event_id":"00065a1d-7f9a-8380-0000-001200000020","source_event_id_unique":true,"source_pre_event_id":"00065a1d-7f99-79e0-0001-001203000020","translation":"UNFOLD_TO_INF","unfold_event_id":null,"zero_hair":false}
{"channel":"live_orders_btcusd","interaction_index":247,"natural_form":{"channel":"live_orders_btcusd","order_id":"2044303880159233","order_subtype":5,"order_type":1},"natural_form_sha256":"95501bd1b3f7a20c8fb3947cb2d00a6b5861edb5b4b79947ea62d354a3fa5a83","order_source":"orderbook","orders_submitted":0,"presentation":{"amount":"0.10000000","amount_traded":"0","microtimestamp":"1787932601649000","price":"78522.62"},"previous_record_hash":"62e044f88020973d38fb27e64c8ece61d35b5a4bbf34b960598b165d9fad6abc","profit_assessment":null,"record_hash":"93e618c09f550615d9d371c5ecf569765f11a6fc7ed252e586de68b871986814","recorded_unix_us":1787932601691193,"recorded_utc":"2026-08-28T15:56:41.691193Z","schema_version":"nrrf810.exchange_authored_interactive_closure.v1","source_chain_continuous":true,"source_event":"order_created","source_event_id":"00065a1d-7f9a-8768-0000-000100000020","source_event_id_unique":true,"source_pre_event_id":"00065a1d-7f9a-8380-0001-000103000020","translation":"UNFOLD_TO_INF","unfold_event_id":null,"zero_hair":false}
{"channel":"live_orders_btcusd","interaction_index":248,"natural_form":{"channel":"live_orders_btcusd","order_id":"2044303880159233","order_subtype":5,"order_type":1},"natural_form_sha256":"95501bd1b3f7a20c8fb3947cb2d00a6b5861edb5b4b79947ea62d354a3fa5a83","order_source":"orderbook","orders_submitted":0,"presentation":{"amount":"0.10000000","amount_traded":"0","microtimestamp":"1787932601649000","price":"78522.62"},"previous_record_hash":"93e618c09f550615d9d371c5ecf569765f11a6fc7ed252e586de68b871986814","profit_assessment":null,"record_hash":"86f91822b2361dd5197644428a44837807491ab18ae301900b3f61b992120018","recorded_unix_us":1787932601691587,"recorded_utc":"2026-08-28T15:56:41.691587Z","schema_version":"nrrf810.exchange_authored_interactive_closure.v1","source_chain_continuous":true,"source_event":"order_deleted","source_event_id":"00065a1d-7f9a-8768-0001-000101000020","source_event_id_unique":true,"source_pre_event_id":"00065a1d-7f9a-8768-0000-000100000020","translation":"FOLD_RETURN_TO_ZERO","unfold_event_id":"00065a1d-7f9a-8768-0000-000100000020","zero_hair":true}
{"channel":"live_orders_btcusd","interaction_index":249,"natural_form":{"channel":"live_orders_btcusd","order_id":"2044303880212480","order_subtype":5,"order_type":1},"natural_form_sha256":"ebdf62751d863d6b1d545b8379b6a51d4eac4cef3bdafeb957fbc663267d5548","order_source":"orderbook","orders_submitted":0,"presentation":{"amount":"0.10000000","amount_traded":"0","microtimestamp":"1787932601662000","price":"78522.63"},"previous_record_hash":"86f91822b2361dd5197644428a44837807491ab18ae301900b3f61b992120018","profit_assessment":null,"record_hash":"27325d6e7ff5576ab1608a84ef4893fed9e62dce52a7a280dd37c559d02968e8","recorded_unix_us":1787932601705366,"recorded_utc":"2026-08-28T15:56:41.705366Z","schema_version":"nrrf810.exchange_authored_interactive_closure.v1","source_chain_continuous":true,"source_event":"order_created","source_event_id":"00065a1d-7f9a-ba30-0000-000102000020","source_event_id_unique":true,"source_pre_event_id":"00065a1d-7f9a-8768-0001-000101000020","translation":"UNFOLD_TO_INF","unfold_event_id":null,"zero_hair":false}
{"channel":"live_orders_btcusd","interaction_index":250,"natural_form":{"channel":"live_orders_btcusd","order_id":"2044303880212480","order_subtype":5,"order_type":1},"natural_form_sha256":"ebdf62751d863d6b1d545b8379b6a51d4eac4cef3bdafeb957fbc663267d5548","order_source":"orderbook","orders_submitted":0,"presentation":{"amount":"0.10000000","amount_traded":"0","microtimestamp":"1787932601662000","price":"78522.63"},"previous_record_hash":"27325d6e7ff5576ab1608a84ef4893fed9e62dce52a7a280dd37c559d02968e8","profit_assessment":null,"record_hash":"8f24a96a7874429f72ccde3303930204de0ccbc03230a54174e251eef91c87e4","recorded_unix_us":1787932601705399,"recorded_utc":"2026-08-28T15:56:41.705399Z","schema_version":"nrrf810.exchange_authored_interactive_closure.v1","source_chain_continuous":true,"source_event":"order_deleted","source_event_id":"00065a1d-7f9a-ba30-0001-000103000020","source_event_id_unique":true,"source_pre_event_id":"00065a1d-7f9a-ba30-0000-000102000020","translation":"FOLD_RETURN_TO_ZERO","unfold_event_id":"00065a1d-7f9a-ba30-0000-000102000020","zero_hair":true}
{"channel":"live_orders_ethbtc","interaction_index":251,"natural_form":{"channel":"live_orders_ethbtc","order_id":"2044303800680448","order_subtype":5,"order_type":0},"natural_form_sha256":"c5ec611b35ce031db04744bc0bfb544ffd40e652c3bcc7b1eda37f2810d4dbdc","order_source":"orderbook","orders_submitted":0,"presentation":{"amount":"0.18113665","amount_traded":"0","microtimestamp":"1787932601666000","price":"0.03020011"},"previous_record_hash":"8f24a96a7874429f72ccde3303930204de0ccbc03230a54174e251eef91c87e4","profit_assessment":null,"record_hash":"cb90c9c130b0d458378c40ca0137f9016100b5614d8920cf83753352d874eff1","recorded_unix_us":1787932601705516,"recorded_utc":"2026-08-28T15:56:41.705516Z","schema_version":"nrrf810.exchange_authored_interactive_closure.v1","source_chain_continuous":true,"source_event":"order_deleted","source_event_id":"00065a1d-7f9a-c9d0-0000-001100000020","source_event_id_unique":true,"source_pre_event_id":"00065a1d-7f9a-77c8-0000-001103000020","translation":"PARTIAL_PRIOR_UNFOLD","unfold_event_id":null,"zero_hair":false}
{"channel":"live_orders_ethbtc","interaction_index":252,"natural_form":{"channel":"live_orders_ethbtc","order_id":"2044303790809101","order_subtype":5,"order_type":0},"natural_form_sha256":"fe1ff3a38b095f5996f286916f66e7532f3741937d682f07ce0d580640905a6a","order_source":"orderbook","orders_submitted":0,"presentation":{"amount":"0.08102965","amount_traded":"0","microtimestamp":"1787932601667000","price":"0.03020009"},"previous_record_hash":"cb90c9c130b0d458378c40ca0137f9016100b5614d8920cf83753352d874eff1","profit_assessment":null,"record_hash":"84d09f793c2c6e5e69e81e2fa5b84dd2614d877ac8d61ab641020d8bafda4713","recorded_unix_us":1787932601705628,"recorded_utc":"2026-08-28T15:56:41.705628Z","schema_version":"nrrf810.exchange_authored_interactive_closure.v1","source_chain_continuous":true,"source_event":"order_deleted","source_event_id":"00065a1d-7f9a-cdb8-0000-001101000020","source_event_id_unique":true,"source_pre_event_id":"00065a1d-7f9a-c9d0-0000-001100000020","translation":"PARTIAL_PRIOR_UNFOLD","unfold_event_id":null,"zero_hair":false}
{"channel":"live_orders_btcusd","interaction_index":253,"natural_form":{"channel":"live_orders_btcusd","order_id":"2044303880228867","order_subtype":5,"order_type":0},"natural_form_sha256":"0c6e0cf0afcdbbca9cc2ef99afa47adc50be7709ad182e7d65393c57ac4e89c6","order_source":"orderbook","orders_submitted":0,"presentation":{"amount":"0.00140266","amount_traded":"0","microtimestamp":"1787932601667000","price":"70667.51"},"previous_record_hash":"84d09f793c2c6e5e69e81e2fa5b84dd2614d877ac8d61ab641020d8bafda4713","profit_assessment":null,"record_hash":"5dff3cd257bd406ecf340a39738a61a28fded28d4207f101990f863472a6940b","recorded_unix_us":1787932601705732,"recorded_utc":"2026-08-28T15:56:41.705732Z","schema_version":"nrrf810.exchange_authored_interactive_closure.v1","source_chain_continuous":true,"source_event":"order_created","source_event_id":"00065a1d-7f9a-cdb8-0000-000100000020","source_event_id_unique":true,"source_pre_event_id":"00065a1d-7f9a-ba30-0001-000103000020","translation":"UNFOLD_TO_INF","unfold_event_id":null,"zero_hair":false}
{"channel":"live_orders_btcusd","interaction_index":254,"natural_form":{"channel":"live_orders_btcusd","order_id":"2044303880253440","order_subtype":5,"order_type":1},"natural_form_sha256":"61036675fe9d69ce37284d1cbab67e5761a6d6c242656a4581d5a58f485e956c","order_source":"orderbook","orders_submitted":0,"presentation":{"amount":"0.06310787","amount_traded":"0","microtimestamp":"1787932601673000","price":"78520.04"},"previous_record_hash":"5dff3cd257bd406ecf340a39738a61a28fded28d4207f101990f863472a6940b","profit_assessment":null,"record_hash":"8203d63c9ede4e29974a987decc505ded4407829f4c247a6c2ebac49f76d6479","recorded_unix_us":1787932601705835,"recorded_utc":"2026-08-28T15:56:41.705835Z","schema_version":"nrrf810.exchange_authored_interactive_closure.v1","source_chain_continuous":true,"source_event":"order_created","source_event_id":"00065a1d-7f9a-e528-0000-000101000020","source_event_id_unique":true,"source_pre_event_id":"00065a1d-7f9a-cdb8-0000-000100000020","translation":"UNFOLD_TO_INF","unfold_event_id":null,"zero_hair":false}
{"channel":"live_orders_btcusd","interaction_index":255,"natural_form":{"channel":"live_orders_btcusd","order_id":"2044303880253440","order_subtype":5,"order_type":1},"natural_form_sha256":"61036675fe9d69ce37284d1cbab67e5761a6d6c242656a4581d5a58f485e956c","order_source":"orderbook","orders_submitted":0,"presentation":{"amount":"0.06310787","amount_traded":"0","microtimestamp":"1787932601673000","price":"78520.04"},"previous_record_hash":"8203d63c9ede4e29974a987decc505ded4407829f4c247a6c2ebac49f76d6479","profit_assessment":null,"record_hash":"c68e68f9a211acabf3bda1fdd359b904acc5185c9198cb5dbe368023c1530424","recorded_unix_us":1787932601705949,"recorded_utc":"2026-08-28T15:56:41.705949Z","schema_version":"nrrf810.exchange_authored_interactive_closure.v1","source_chain_continuous":true,"source_event":"order_deleted","source_event_id":"00065a1d-7f9a-e528-0001-000102000020","source_event_id_unique":true,"source_pre_event_id":"00065a1d-7f9a-e528-0000-000101000020","translation":"FOLD_RETURN_TO_ZERO","unfold_event_id":"00065a1d-7f9a-e528-0000-000101000020","zero_hair":true}
{"channel":"live_orders_btcusd","interaction_index":256,"natural_form":{"channel":"live_orders_btcusd","order_id":"2044303880261632","order_subtype":5,"order_type":1},"natural_form_sha256":"acf0411fa7ddf38e3bb6cb822fac302afcc98bdf0d65885c4e24f19c2b8400d7","order_source":"orderbook","orders_submitted":0,"presentation":{"amount":"0.06310787","amount_traded":"0","microtimestamp":"1787932601675000","price":"78522.40"},"previous_record_hash":"c68e68f9a211acabf3bda1fdd359b904acc5185c9198cb5dbe368023c1530424","profit_assessment":null,"record_hash":"2cf77764f3754197ea35969c05126ac2e8788c037b3ef47feb5c4096f52d401c","recorded_unix_us":1787932601713827,"recorded_utc":"2026-08-28T15:56:41.713827Z","schema_version":"nrrf810.exchange_authored_interactive_closure.v1","source_chain_continuous":true,"source_event":"order_created","source_event_id":"00065a1d-7f9a-ecf8-0000-000103000020","source_event_id_unique":true,"source_pre_event_id":"00065a1d-7f9a-e528-0001-000102000020","translation":"UNFOLD_TO_INF","unfold_event_id":null,"zero_hair":false}
{"channel":"live_orders_btcusd","interaction_index":257,"natural_form":{"channel":"live_orders_btcusd","order_id":"2044303880261632","order_subtype":5,"order_type":1},"natural_form_sha256":"acf0411fa7ddf38e3bb6cb822fac302afcc98bdf0d65885c4e24f19c2b8400d7","order_source":"orderbook","orders_submitted":0,"presentation":{"amount":"0.06310787","amount_traded":"0","microtimestamp":"1787932601675000","price":"78522.40"},"previous_record_hash":"2cf77764f3754197ea35969c05126ac2e8788c037b3ef47feb5c4096f52d401c","profit_assessment":null,"record_hash":"94aeba8673ae1b76601d7b81c9b4de2b7eadd7994451dc23bc016e9f4bd66e05","recorded_unix_us":1787932601714032,"recorded_utc":"2026-08-28T15:56:41.714032Z","schema_version":"nrrf810.exchange_authored_interactive_closure.v1","source_chain_continuous":true,"source_event":"order_deleted","source_event_id":"00065a1d-7f9a-ecf8-0001-000100000020","source_event_id_unique":true,"source_pre_event_id":"00065a1d-7f9a-ecf8-0000-000103000020","translation":"FOLD_RETURN_TO_ZERO","unfold_event_id":"00065a1d-7f9a-ecf8-0000-000103000020","zero_hair":true}
{"channel":"live_orders_ethusd","interaction_index":258,"natural_form":{"channel":"live_orders_ethusd","order_id":"2044303878684678","order_subtype":5,"order_type":0},"natural_form_sha256":"13c442beb84de690b9a3f4fb7feeae37f9303f7430728d56c550ec61cdbc8140","order_source":"orderbook","orders_submitted":0,"presentation":{"amount":"0.403103","amount_traded":"0","microtimestamp":"1787932601684000","price":"2480.01"},"previous_record_hash":"94aeba8673ae1b76601d7b81c9b4de2b7eadd7994451dc23bc016e9f4bd66e05","profit_assessment":null,"record_hash":"c64c88ba9502c8a06996446c14c5b6a4b3e81b93843b41c00c2da3194ce3ff77","recorded_unix_us":1787932601717231,"recorded_utc":"2026-08-28T15:56:41.717231Z","schema_version":"nrrf810.exchange_authored_interactive_closure.v1","source_chain_continuous":true,"source_event":"order_deleted","source_event_id":"00065a1d-7f9b-1020-0000-001201000020","source_event_id_unique":true,"source_pre_event_id":"00065a1d-7f9a-8380-0000-001200000020","translation":"FOLD_RETURN_TO_ZERO","unfold_event_id":"00065a1d-7f95-0928-0000-001200000020","zero_hair":true}
{"channel":"live_orders_btcusd","interaction_index":259,"natural_form":{"channel":"live_orders_btcusd","order_id":"2044303880318976","order_subtype":5,"order_type":1},"natural_form_sha256":"071faba15c7ca2582ea85e6175488a7974e8fc6d01d630c7fed8bc177ca1e120","order_source":"orderbook","orders_submitted":0,"presentation":{"amount":"0.10000000","amount_traded":"0","microtimestamp":"1787932601688000","price":"78522.62"},"previous_record_hash":"c64c88ba9502c8a06996446c14c5b6a4b3e81b93843b41c00c2da3194ce3ff77","profit_assessment":null,"record_hash":"5681c20857cfa865592c0210f8b8912a96d68b3c04e2c40c24d3f1729fe74c09","recorded_unix_us":1787932601749792,"recorded_utc":"2026-08-28T15:56:41.749792Z","schema_version":"nrrf810.exchange_authored_interactive_closure.v1","source_chain_continuous":true,"source_event":"order_created","source_event_id":"00065a1d-7f9b-1fc0-0000-000101000020","source_event_id_unique":true,"source_pre_event_id":"00065a1d-7f9a-ecf8-0001-000100000020","translation":"UNFOLD_TO_INF","unfold_event_id":null,"zero_hair":false}
{"channel":"live_orders_btcusd","interaction_index":260,"natural_form":{"channel":"live_orders_btcusd","order_id":"2044303880318976","order_subtype":5,"order_type":1},"natural_form_sha256":"071faba15c7ca2582ea85e6175488a7974e8fc6d01d630c7fed8bc177ca1e120","order_source":"orderbook","orders_submitted":0,"presentation":{"amount":"0.10000000","amount_traded":"0","microtimestamp":"1787932601688000","price":"78522.62"},"previous_record_hash":"5681c20857cfa865592c0210f8b8912a96d68b3c04e2c40c24d3f1729fe74c09","profit_assessment":null,"record_hash":"660d2ae0edf1a730a5985085fe7f771c671c521a3e45c29a5389d2d48fc7cfe8","recorded_unix_us":1787932601749866,"recorded_utc":"2026-08-28T15:56:41.749866Z","schema_version":"nrrf810.exchange_authored_interactive_closure.v1","source_chain_continuous":true,"source_event":"order_deleted","source_event_id":"00065a1d-7f9b-1fc0-0001-000102000020","source_event_id_unique":true,"source_pre_event_id":"00065a1d-7f9b-1fc0-0000-000101000020","translation":"FOLD_RETURN_TO_ZERO","unfold_event_id":"00065a1d-7f9b-1fc0-0000-000101000020","zero_hair":true}
{"channel":"live_orders_ethusd","interaction_index":261,"natural_form":{"channel":"live_orders_ethusd","order_id":"2044303880323082","order_subtype":5,"order_type":0},"natural_form_sha256":"2b1e2289aacfef003a1bf281276a3ed953d64ba467b8e43710d05aecfd41de76","order_source":"orderbook","orders_submitted":0,"presentation":{"amount":"0.403104","amount_traded":"0","microtimestamp":"1787932601690000","price":"2480.15"},"previous_record_hash":"660d2ae0edf1a730a5985085fe7f771c671c521a3e45c29a5389d2d48fc7cfe8","profit_assessment":null,"record_hash":"e0773a1d06eb37873335ceb2fc4a64f90d6381cde8b30cd03e72a248679e64d4","recorded_unix_us":1787932601753278,"recorded_utc":"2026-08-28T15:56:41.753278Z","schema_version":"nrrf810.exchange_authored_interactive_closure.v1","source_chain_continuous":true,"source_event":"order_created","source_event_id":"00065a1d-7f9b-2790-0000-001202000020","source_event_id_unique":true,"source_pre_event_id":"00065a1d-7f9b-1020-0000-001201000020","translation":"UNFOLD_TO_INF","unfold_event_id":null,"zero_hair":false}
{"channel":"live_orders_ethusd","interaction_index":262,"natural_form":{"channel":"live_orders_ethusd","order_id":"2044303878041600","order_subtype":5,"order_type":0},"natural_form_sha256":"aa1e2c89df0f5a9f9cb7f1d8d180ebeffaa8211c5bf50b1042fe967597307e38","order_source":"orderbook","orders_submitted":0,"presentation":{"amount":"4.034022","amount_traded":"0","microtimestamp":"1787932601698000","price":"2478.91"},"previous_record_hash":"e0773a1d06eb37873335ceb2fc4a64f90d6381cde8b30cd03e72a248679e64d4","profit_assessment":null,"record_hash":"e9f73684bf307517e3b3343369ffb2d48eafc66c4d5c85b6c0f221de3fd5b458","recorded_unix_us":1787932601753351,"recorded_utc":"2026-08-28T15:56:41.753351Z","schema_version":"nrrf810.exchange_authored_interactive_closure.v1","source_chain_continuous":true,"source_event":"order_deleted","source_event_id":"00065a1d-7f9b-46d0-0000-001203000020","source_event_id_unique":true,"source_pre_event_id":"00065a1d-7f9b-2790-0000-001202000020","translation":"PARTIAL_PRIOR_UNFOLD","unfold_event_id":null,"zero_hair":false}
{"channel":"live_orders_btcusd","interaction_index":263,"natural_form":{"channel":"live_orders_btcusd","order_id":"2044303880359937","order_subtype":5,"order_type":1},"natural_form_sha256":"7f0f29608f07c463f96cdb2e4accc1486078c09c224626d5d5087e2d19a6d07a","order_source":"orderbook","orders_submitted":0,"presentation":{"amount":"0.10000000","amount_traded":"0","microtimestamp":"1787932601698000","price":"78522.63"},"previous_record_hash":"e9f73684bf307517e3b3343369ffb2d48eafc66c4d5c85b6c0f221de3fd5b458","profit_assessment":null,"record_hash":"6579efcdbb3c400810df65d89c59ea4374a9e3b6a44727e8a2c368e8c11e302a","recorded_unix_us":1787932601753376,"recorded_utc":"2026-08-28T15:56:41.753376Z","schema_version":"nrrf810.exchange_authored_interactive_closure.v1","source_chain_continuous":true,"source_event":"order_created","source_event_id":"00065a1d-7f9b-46d0-0000-000103000020","source_event_id_unique":true,"source_pre_event_id":"00065a1d-7f9b-1fc0-0001-000102000020","translation":"UNFOLD_TO_INF","unfold_event_id":null,"zero_hair":false}
{"channel":"live_orders_btcusd","interaction_index":264,"natural_form":{"channel":"live_orders_btcusd","order_id":"2044303880359937","order_subtype":5,"order_type":1},"natural_form_sha256":"7f0f29608f07c463f96cdb2e4accc1486078c09c224626d5d5087e2d19a6d07a","order_source":"orderbook","orders_submitted":0,"presentation":{"amount":"0.10000000","amount_traded":"0","microtimestamp":"1787932601698000","price":"78522.63"},"previous_record_hash":"6579efcdbb3c400810df65d89c59ea4374a9e3b6a44727e8a2c368e8c11e302a","profit_assessment":null,"record_hash":"e69ed9358b3674d42136ac664f5f435574e0a07bd56fda73a1ddf4670aaa2437","recorded_unix_us":1787932601753398,"recorded_utc":"2026-08-28T15:56:41.753398Z","schema_version":"nrrf810.exchange_authored_interactive_closure.v1","source_chain_continuous":true,"source_event":"order_deleted","source_event_id":"00065a1d-7f9b-46d0-0001-000100000020","source_event_id_unique":true,"source_pre_event_id":"00065a1d-7f9b-46d0-0000-000103000020","translation":"FOLD_RETURN_TO_ZERO","unfold_event_id":"00065a1d-7f9b-46d0-0000-000103000020","zero_hair":true}
{"channel":"live_orders_ethusd","interaction_index":265,"natural_form":{"channel":"live_orders_ethusd","order_id":"2044303878041604","order_subtype":5,"order_type":0},"natural_form_sha256":"a9a889646e03f6e50e951d7bf342e79aa1c25f4f4b7c916df7df10e858de9b4b","order_source":"orderbook","orders_submitted":0,"presentation":{"amount":"20.215084","amount_traded":"0","microtimestamp":"1787932601698000","price":"2473.40"},"previous_record_hash":"e69ed9358b3674d42136ac664f5f435574e0a07bd56fda73a1ddf4670aaa2437","profit_assessment":null,"record_hash":"fc21291868f9086be9707763f451f246ea1451a7d269d7f5cee2c34d87d25da9","recorded_unix_us":1787932601753418,"recorded_utc":"2026-08-28T15:56:41.753418Z","schema_version":"nrrf810.exchange_authored_interactive_closure.v1","source_chain_continuous":true,"source_event":"order_deleted","source_event_id":"00065a1d-7f9b-46d0-0001-001200000020","source_event_id_unique":true,"source_pre_event_id":"00065a1d-7f9b-46d0-0000-001203000020","translation":"PARTIAL_PRIOR_UNFOLD","unfold_event_id":null,"zero_hair":false}
{"channel":"live_orders_ethusd","interaction_index":266,"natural_form":{"channel":"live_orders_ethusd","order_id":"2044303878041611","order_subtype":5,"order_type":0},"natural_form_sha256":"4649c4c90c10f1d9cf11a11922a3d4e37b9da91615369eaaeff7da9d138be7f7","order_source":"orderbook","orders_submitted":0,"presentation":{"amount":"40.568517","amount_traded":"0","microtimestamp":"1787932601699000","price":"2464.96"},"previous_record_hash":"fc21291868f9086be9707763f451f246ea1451a7d269d7f5cee2c34d87d25da9","profit_assessment":null,"record_hash":"c4bdce3166574ea8a21df60ca0874b702f47c9ec269f4e11243df36fc31e9490","recorded_unix_us":1787932601753505,"recorded_utc":"2026-08-28T15:56:41.753505Z","schema_version":"nrrf810.exchange_authored_interactive_closure.v1","source_chain_continuous":true,"source_event":"order_deleted","source_event_id":"00065a1d-7f9b-4ab8-0000-001201000020","source_event_id_unique":true,"source_pre_event_id":"00065a1d-7f9b-46d0-0001-001200000020","translation":"PARTIAL_PRIOR_UNFOLD","unfold_event_id":null,"zero_hair":false}
{"channel":"live_orders_btcusd","interaction_index":267,"natural_form":{"channel":"live_orders_btcusd","order_id":"2044303878631428","order_subtype":5,"order_type":0},"natural_form_sha256":"adc4786058f6cabbb6f19277b52f8c3f5981af7676a2b1056c4b9266fd3aa608","order_source":"orderbook","orders_submitted":0,"presentation":{"amount":"0.19103753","amount_traded":"0","microtimestamp":"1787932601699000","price":"78483.49"},"previous_record_hash":"c4bdce3166574ea8a21df60ca0874b702f47c9ec269f4e11243df36fc31e9490","profit_assessment":null,"record_hash":"65e7c84fb74cc4195125b158511356ad5efc341732792bc56d62cd1ddffcbe4f","recorded_unix_us":1787932601753647,"recorded_utc":"2026-08-28T15:56:41.753647Z","schema_version":"nrrf810.exchange_authored_interactive_closure.v1","source_chain_continuous":true,"source_event":"order_deleted","source_event_id":"00065a1d-7f9b-4ab8-0000-000101000020","source_event_id_unique":true,"source_pre_event_id":"00065a1d-7f9b-46d0-0001-000100000020","translation":"FOLD_RETURN_TO_ZERO","unfold_event_id":"00065a1d-7f94-d660-0000-000102000020","zero_hair":true}
{"channel":"live_orders_ethusd","interaction_index":268,"natural_form":{"channel":"live_orders_ethusd","order_id":"2044303878041612","order_subtype":5,"order_type":0},"natural_form_sha256":"f292de335f35658ad01df93f4d447a1e6f1b198abf2ad1c3f53103c076c11f5b","order_source":"orderbook","orders_submitted":0,"presentation":{"amount":"10.092689","amount_traded":"0","microtimestamp":"1787932601699000","price":"2477.04"},"previous_record_hash":"65e7c84fb74cc4195125b158511356ad5efc341732792bc56d62cd1ddffcbe4f","profit_assessment":null,"record_hash":"bb6e67d42aeb735b272d01706ba0c41c06496fbe64613f6cdb063142449dda3e","recorded_unix_us":1787932601872565,"recorded_utc":"2026-08-28T15:56:41.872565Z","schema_version":"nrrf810.exchange_authored_interactive_closure.v1","source_chain_continuous":true,"source_event":"order_deleted","source_event_id":"00065a1d-7f9b-4ab8-0001-001202000020","source_event_id_unique":true,"source_pre_event_id":"00065a1d-7f9b-4ab8-0000-001201000020","translation":"PARTIAL_PRIOR_UNFOLD","unfold_event_id":null,"zero_hair":false}
{"channel":"live_orders_ethusd","interaction_index":269,"natural_form":{"channel":"live_orders_ethusd","order_id":"2044303878045704","order_subtype":5,"order_type":0},"natural_form_sha256":"7b06ad49a9517f5cb0d23622e920ddd9c41873eea01ea5d24f3181d9b6a785aa","order_source":"orderbook","orders_submitted":0,"presentation":{"amount":"10.097738","amount_traded":"0","microtimestamp":"1787932601699000","price":"2475.80"},"previous_record_hash":"bb6e67d42aeb735b272d01706ba0c41c06496fbe64613f6cdb063142449dda3e","profit_assessment":null,"record_hash":"ed86d49d9598f375acc86e79caafabee252edef00770a2a9cdd521c3df92881a","recorded_unix_us":1787932601872608,"recorded_utc":"2026-08-28T15:56:41.872608Z","schema_version":"nrrf810.exchange_authored_interactive_closure.v1","source_chain_continuous":true,"source_event":"order_deleted","source_event_id":"00065a1d-7f9b-4ab8-0002-001203000020","source_event_id_unique":true,"source_pre_event_id":"00065a1d-7f9b-4ab8-0001-001202000020","translation":"PARTIAL_PRIOR_UNFOLD","unfold_event_id":null,"zero_hair":false}
{"channel":"live_orders_ethusd","interaction_index":270,"natural_form":{"channel":"live_orders_ethusd","order_id":"2044303878115334","order_subtype":5,"order_type":0},"natural_form_sha256":"2b3e68f8606ace64941d2a69da4badbd18e9ca72dd44ceb38beb53df752f63f9","order_source":"orderbook","orders_submitted":0,"presentation":{"amount":"4.034214","amount_traded":"0","microtimestamp":"1787932601700000","price":"2478.79"},"previous_record_hash":"ed86d49d9598f375acc86e79caafabee252edef00770a2a9cdd521c3df92881a","profit_assessment":null,"record_hash":"e2b935262d5d5325459cc0adda9863c4e647b058245022ff13bf9388740d0134","recorded_unix_us":1787932601872734,"recorded_utc":"2026-08-28T15:56:41.872734Z","schema_version":"nrrf810.exchange_authored_interactive_closure.v1","source_chain_continuous":true,"source_event":"order_deleted","source_event_id":"00065a1d-7f9b-4ea0-0000-001200000020","source_event_id_unique":true,"source_pre_event_id":"00065a1d-7f9b-4ab8-0002-001203000020","translation":"PARTIAL_PRIOR_UNFOLD","unfold_event_id":null,"zero_hair":false}
{"channel":"live_orders_ethusd","interaction_index":271,"natural_form":{"channel":"live_orders_ethusd","order_id":"2044303878115341","order_subtype":5,"order_type":0},"natural_form_sha256":"97e79463c3dc3a73f933e3beae105b7bbafe2883e44867c5d545a98cbe00c2fa","order_source":"orderbook","orders_submitted":0,"presentation":{"amount":"20.225289","amount_traded":"0","microtimestamp":"1787932601700000","price":"2472.15"},"previous_record_hash":"e2b935262d5d5325459cc0adda9863c4e647b058245022ff13bf9388740d0134","profit_assessment":null,"record_hash":"b6cccd2bc47a3e07b70ce2be515973cd8fec63784912c184e05f162e5c4bfd27","recorded_unix_us":1787932601872782,"recorded_utc":"2026-08-28T15:56:41.872782Z","schema_version":"nrrf810.exchange_authored_interactive_closure.v1","source_chain_continuous":true,"source_event":"order_deleted","source_event_id":"00065a1d-7f9b-4ea0-0001-001201000020","source_event_id_unique":true,"source_pre_event_id":"00065a1d-7f9b-4ea0-0000-001200000020","translation":"PARTIAL_PRIOR_UNFOLD","unfold_event_id":null,"zero_hair":false}
{"channel":"live_orders_ethusd","interaction_index":272,"natural_form":{"channel":"live_orders_ethusd","order_id":"2044303878119437","order_subtype":5,"order_type":0},"natural_form_sha256":"2d817d9c4a01f6805a25e45e683c078e4ed576719cd12bb7d8e05a54c82da82b","order_source":"orderbook","orders_submitted":0,"presentation":{"amount":"40.609081","amount_traded":"0","microtimestamp":"1787932601700000","price":"2462.50"},"previous_record_hash":"b6cccd2bc47a3e07b70ce2be515973cd8fec63784912c184e05f162e5c4bfd27","profit_assessment":null,"record_hash":"34637292e31225d44f3feab2bcb2e99f740873dd07bf92915352a8874c29ee00","recorded_unix_us":1787932601872872,"recorded_utc":"2026-08-28T15:56:41.872872Z","schema_version":"nrrf810.exchange_authored_interactive_closure.v1","source_chain_continuous":true,"source_event":"order_deleted","source_event_id":"00065a1d-7f9b-4ea0-0002-001202000020","source_event_id_unique":true,"source_pre_event_id":"00065a1d-7f9b-4ea0-0001-001201000020","translation":"PARTIAL_PRIOR_UNFOLD","unfold_event_id":null,"zero_hair":false}
{"channel":"live_orders_ethusd","interaction_index":273,"natural_form":{"channel":"live_orders_ethusd","order_id":"2044303878213635","order_subtype":5,"order_type":0},"natural_form_sha256":"17635897d7e09886bb7125a3ab26144c31fc8151c0ca82129ede6bb2ece40520","order_source":"orderbook","orders_submitted":0,"presentation":{"amount":"20.235437","amount_traded":"0","microtimestamp":"1787932601701000","price":"2470.91"},"previous_record_hash":"34637292e31225d44f3feab2bcb2e99f740873dd07bf92915352a8874c29ee00","profit_assessment":null,"record_hash":"83fafaa33087b990f3fb9fb08eefef9bb059822218ef56445df518f7a12d2512","recorded_unix_us":1787932601873002,"recorded_utc":"2026-08-28T15:56:41.873002Z","schema_version":"nrrf810.exchange_authored_interactive_closure.v1","source_chain_continuous":true,"source_event":"order_deleted","source_event_id":"00065a1d-7f9b-5288-0000-001203000020","source_event_id_unique":true,"source_pre_event_id":"00065a1d-7f9b-4ea0-0002-001202000020","translation":"FOLD_RETURN_TO_ZERO","unfold_event_id":"00065a1d-7f93-47f0-0000-001203000020","zero_hair":true}
{"channel":"live_orders_ethusd","interaction_index":274,"natural_form":{"channel":"live_orders_ethusd","order_id":"2044303878287371","order_subtype":5,"order_type":0},"natural_form_sha256":"0afdda0e1d600148324cb5b1221c22f7ef4c64f50dc1752741fa3a1b0d3bb2d1","order_source":"orderbook","orders_submitted":0,"presentation":{"amount":"10.090138","amount_traded":"0","microtimestamp":"1787932601701000","price":"2477.66"},"previous_record_hash":"83fafaa33087b990f3fb9fb08eefef9bb059822218ef56445df518f7a12d2512","profit_assessment":null,"record_hash":"9d5b075f60220189cdadfd3d1511f296a3f1a86c9778c84508efed53508f5070","recorded_unix_us":1787932601873031,"recorded_utc":"2026-08-28T15:56:41.873031Z","schema_version":"nrrf810.exchange_authored_interactive_closure.v1","source_chain_continuous":true,"source_event":"order_deleted","source_event_id":"00065a1d-7f9b-5288-0001-001200000020","source_event_id_unique":true,"source_pre_event_id":"00065a1d-7f9b-5288-0000-001203000020","translation":"FOLD_RETURN_TO_ZERO","unfold_event_id":"00065a1d-7f93-9228-0000-001201000020","zero_hair":true}
{"channel":"live_orders_ethusd","interaction_index":275,"natural_form":{"channel":"live_orders_ethusd","order_id":"2044303878291460","order_subtype":5,"order_type":0},"natural_form_sha256":"b0d9dd036dc012db61a60df3d210831661e5dc4bc9ae33816650887c3a81a420","order_source":"orderbook","orders_submitted":0,"presentation":{"amount":"10.095101","amount_traded":"0","microtimestamp":"1787932601702000","price":"2476.44"},"previous_record_hash":"9d5b075f60220189cdadfd3d1511f296a3f1a86c9778c84508efed53508f5070","profit_assessment":null,"record_hash":"6e76d6315e361c1229be5a6d5a23a80ea771b218f990e2c439f1a4505c6f93bc","recorded_unix_us":1787932601873158,"recorded_utc":"2026-08-28T15:56:41.873158Z","schema_version":"nrrf810.exchange_authored_interactive_closure.v1","source_chain_continuous":true,"source_event":"order_deleted","source_event_id":"00065a1d-7f9b-5670-0000-001201000020","source_event_id_unique":true,"source_pre_event_id":"00065a1d-7f9b-5288-0001-001200000020","translation":"FOLD_RETURN_TO_ZERO","unfold_event_id":"00065a1d-7f93-9228-0001-001202000020","zero_hair":true}
{"channel":"live_orders_ethusd","interaction_index":276,"natural_form":{"channel":"live_orders_ethusd","order_id":"2044303877025794","order_subtype":5,"order_type":0},"natural_form_sha256":"94ad54e3e721cc52a610f0b9c03ee1634e32b7e2b0a3458771f74df863fed991","order_source":"orderbook","orders_submitted":0,"presentation":{"amount":"5.000000","amount_traded":"0","microtimestamp":"1787932601702000","price":"2480.78"},"previous_record_hash":"6e76d6315e361c1229be5a6d5a23a80ea771b218f990e2c439f1a4505c6f93bc","profit_assessment":null,"record_hash":"33f8266582650029c63dfa9ea845a63d3906666f68b5612c4ee81ab2744104cb","recorded_unix_us":1787932601873183,"recorded_utc":"2026-08-28T15:56:41.873183Z","schema_version":"nrrf810.exchange_authored_interactive_closure.v1","source_chain_continuous":true,"source_event":"order_deleted","source_event_id":"00065a1d-7f9b-5670-0001-001202000020","source_event_id_unique":true,"source_pre_event_id":"00065a1d-7f9b-5670-0000-001201000020","translation":"PARTIAL_PRIOR_UNFOLD","unfold_event_id":null,"zero_hair":false}
{"channel":"live_orders_ethusd","interaction_index":277,"natural_form":{"channel":"live_orders_ethusd","order_id":"2044303878291467","order_subtype":5,"order_type":0},"natural_form_sha256":"08a6430ec2dcf149e52808e6112b03d3ceceb00b8837cca59e634250c8de61a7","order_source":"orderbook","orders_submitted":0,"presentation":{"amount":"40.650432","amount_traded":"0","microtimestamp":"1787932601702000","price":"2459.99"},"previous_record_hash":"33f8266582650029c63dfa9ea845a63d3906666f68b5612c4ee81ab2744104cb","profit_assessment":null,"record_hash":"df35a332f99d8a96441c4d49534bfd8995b0acfec7d5953fa42dc83e514a4e25","recorded_unix_us":1787932601873203,"recorded_utc":"2026-08-28T15:56:41.873203Z","schema_version":"nrrf810.exchange_authored_interactive_closure.v1","source_chain_continuous":true,"source_event":"order_deleted","source_event_id":"00065a1d-7f9b-5670-0002-001203000020","source_event_id_unique":true,"source_pre_event_id":"00065a1d-7f9b-5670-0001-001202000020","translation":"FOLD_RETURN_TO_ZERO","unfold_event_id":"00065a1d-7f93-9610-0000-001203000020","zero_hair":true}
{"channel":"live_orders_ethusd","interaction_index":278,"natural_form":{"channel":"live_orders_ethusd","order_id":"2044303878295552","order_subtype":5,"order_type":0},"natural_form_sha256":"c9ae39924c2d431a723ed23a4f27d60d7e619e094b4f40dbf8f507454b6dd6d4","order_source":"orderbook","orders_submitted":0,"presentation":{"amount":"4.033601","amount_traded":"0","microtimestamp":"1787932601702000","price":"2479.17"},"previous_record_hash":"df35a332f99d8a96441c4d49534bfd8995b0acfec7d5953fa42dc83e514a4e25","profit_assessment":null,"record_hash":"657a30764dd257a1050a0487d854cee851e956e6cf55d79d33fcfe0c0fa1adc4","recorded_unix_us":1787932601873313,"recorded_utc":"2026-08-28T15:56:41.873313Z","schema_version":"nrrf810.exchange_authored_interactive_closure.v1","source_chain_continuous":true,"source_event":"order_deleted","source_event_id":"00065a1d-7f9b-5670-0003-001200000020","source_event_id_unique":true,"source_pre_event_id":"00065a1d-7f9b-5670-0002-001203000020","translation":"FOLD_RETURN_TO_ZERO","unfold_event_id":"00065a1d-7f93-9610-0001-001200000020","zero_hair":true}
{"channel":"live_orders_ethusd","interaction_index":279,"natural_form":{"channel":"live_orders_ethusd","order_id":"2044303878295553","order_subtype":5,"order_type":0},"natural_form_sha256":"c73d6dc8867fa3d3f3ea8779f6845e9fcc692f165d59ab5816847d80270cd94e","order_source":"orderbook","orders_submitted":0,"presentation":{"amount":"20.204386","amount_traded":"0","microtimestamp":"1787932601703000","price":"2474.71"},"previous_record_hash":"657a30764dd257a1050a0487d854cee851e956e6cf55d79d33fcfe0c0fa1adc4","profit_assessment":null,"record_hash":"88d9eeecf263ed2ccc4f23e266315375f64db80eb34d34967c656f327509bf3e","recorded_unix_us":1787932601873429,"recorded_utc":"2026-08-28T15:56:41.873429Z","schema_version":"nrrf810.exchange_authored_interactive_closure.v1","source_chain_continuous":true,"source_event":"order_deleted","source_event_id":"00065a1d-7f9b-5a58-0000-001201000020","source_event_id_unique":true,"source_pre_event_id":"00065a1d-7f9b-5670-0003-001200000020","translation":"FOLD_RETURN_TO_ZERO","unfold_event_id":"00065a1d-7f93-9610-0002-001201000020","zero_hair":true}
{"channel":"live_orders_ethusd","interaction_index":280,"natural_form":{"channel":"live_orders_ethusd","order_id":"2044303878295557","order_subtype":5,"order_type":0},"natural_form_sha256":"46b6d772704f836767f3b509a793fd0415533135cd5e8684ccb2ce206f6f1648","order_source":"orderbook","orders_submitted":0,"presentation":{"amount":"40.528033","amount_traded":"0","microtimestamp":"1787932601703000","price":"2467.42"},"previous_record_hash":"88d9eeecf263ed2ccc4f23e266315375f64db80eb34d34967c656f327509bf3e","profit_assessment":null,"record_hash":"41e868aee98e17c83c0e3eedb9146aae4a0f8d789c5368b648f1f09e58d3b056","recorded_unix_us":1787932601873460,"recorded_utc":"2026-08-28T15:56:41.873460Z","schema_version":"nrrf810.exchange_authored_interactive_closure.v1","source_chain_continuous":true,"source_event":"order_deleted","source_event_id":"00065a1d-7f9b-5a58-0001-001202000020","source_event_id_unique":true,"source_pre_event_id":"00065a1d-7f9b-5a58-0000-001201000020","translation":"FOLD_RETURN_TO_ZERO","unfold_event_id":"00065a1d-7f93-9610-0003-001202000020","zero_hair":true}
{"channel":"live_orders_ethusd","interaction_index":281,"natural_form":{"channel":"live_orders_ethusd","order_id":"2044303878365186","order_subtype":5,"order_type":0},"natural_form_sha256":"d0494a0e3a2cffb427791294f7ab9243f47d2eac735bb400f8e1885aef04b206","order_source":"orderbook","orders_submitted":0,"presentation":{"amount":"12.096906","amount_traded":"0","microtimestamp":"1787932601703000","price":"2479.97"},"previous_record_hash":"41e868aee98e17c83c0e3eedb9146aae4a0f8d789c5368b648f1f09e58d3b056","profit_assessment":null,"record_hash":"15894ad8898405ab4cf66cb6d2939a951e9c8ffb261ed91aca484212f5606dde","recorded_unix_us":1787932601873618,"recorded_utc":"2026-08-28T15:56:41.873618Z","schema_version":"nrrf810.exchange_authored_interactive_closure.v1","source_chain_continuous":true,"source_event":"order_deleted","source_event_id":"00065a1d-7f9b-5a58-0002-001203000020","source_event_id_unique":true,"source_pre_event_id":"00065a1d-7f9b-5a58-0001-001202000020","translation":"FOLD_RETURN_TO_ZERO","unfold_event_id":"00065a1d-7f93-d878-0000-001203000020","zero_hair":true}
{"channel":"live_orders_ethusd","interaction_index":282,"natural_form":{"channel":"live_orders_ethusd","order_id":"2044303878365189","order_subtype":5,"order_type":0},"natural_form_sha256":"22ab3c3af390adaff0bde43c6886c3dedb978ae06713969be8a01b78871b1780","order_source":"orderbook","orders_submitted":0,"presentation":{"amount":"12.098474","amount_traded":"0","microtimestamp":"1787932601704000","price":"2479.65"},"previous_record_hash":"15894ad8898405ab4cf66cb6d2939a951e9c8ffb261ed91aca484212f5606dde","profit_assessment":null,"record_hash":"64b442f2126ecb72b869b1a0047ba20bafafa5e1cfc3d05bffab28ffe097ef6e","recorded_unix_us":1787932601873650,"recorded_utc":"2026-08-28T15:56:41.873650Z","schema_version":"nrrf810.exchange_authored_interactive_closure.v1","source_chain_continuous":true,"source_event":"order_deleted","source_event_id":"00065a1d-7f9b-5e40-0000-001200000020","source_event_id_unique":true,"source_pre_event_id":"00065a1d-7f9b-5a58-0002-001203000020","translation":"FOLD_RETURN_TO_ZERO","unfold_event_id":"00065a1d-7f93-d878-0001-001200000020","zero_hair":true}
{"channel":"live_orders_ethusd","interaction_index":283,"natural_form":{"channel":"live_orders_ethusd","order_id":"2044303879606276","order_subtype":5,"order_type":1},"natural_form_sha256":"2736d8a7e356c86ed6b9df4e7898518a33026ec285532bdf7f796805923bcd03","order_source":"orderbook","orders_submitted":0,"presentation":{"amount":"12.088820","amount_traded":"0","microtimestamp":"1787932601704000","price":"2481.64"},"previous_record_hash":"64b442f2126ecb72b869b1a0047ba20bafafa5e1cfc3d05bffab28ffe097ef6e","profit_assessment":null,"record_hash":"1f49cace553745c2dad9cc93c6273bc41e259101d36fe46c3f0082e67535e799","recorded_unix_us":1787932601873678,"recorded_utc":"2026-08-28T15:56:41.873678Z","schema_version":"nrrf810.exchange_authored_interactive_closure.v1","source_chain_continuous":true,"source_event":"order_deleted","source_event_id":"00065a1d-7f9b-5e40-0001-001201000020","source_event_id_unique":true,"source_pre_event_id":"00065a1d-7f9b-5e40-0000-001200000020","translation":"FOLD_RETURN_TO_ZERO","unfold_event_id":"00065a1d-7f98-7810-0000-001203000020","zero_hair":true}
{"channel":"live_orders_ethusd","interaction_index":284,"natural_form":{"channel":"live_orders_ethusd","order_id":"2044303879610369","order_subtype":5,"order_type":1},"natural_form_sha256":"0a2971196fa34e35921eca3650571a7c63ddb0d17b1b624f59c291d0843fb9dd","order_source":"orderbook","orders_submitted":0,"presentation":{"amount":"12.087458","amount_traded":"0","microtimestamp":"1787932601704000","price":"2481.92"},"previous_record_hash":"1f49cace553745c2dad9cc93c6273bc41e259101d36fe46c3f0082e67535e799","profit_assessment":null,"record_hash":"fe4738e592b75392502eec06d26a774a9a15ea9f079338c4c08cda0efecb3602","recorded_unix_us":1787932601873778,"recorded_utc":"2026-08-28T15:56:41.873778Z","schema_version":"nrrf810.exchange_authored_interactive_closure.v1","source_chain_continuous":true,"source_event":"order_deleted","source_event_id":"00065a1d-7f9b-5e40-0002-001202000020","source_event_id_unique":true,"source_pre_event_id":"00065a1d-7f9b-5e40-0001-001201000020","translation":"FOLD_RETURN_TO_ZERO","unfold_event_id":"00065a1d-7f98-7fe0-0000-001200000020","zero_hair":true}
{"channel":"live_orders_ethusd","interaction_index":285,"natural_form":{"channel":"live_orders_ethusd","order_id":"2044303879614465","order_subtype":5,"order_type":1},"natural_form_sha256":"cf6cce89d916a11eb65cebfb21deaf9574e40bbee11232117c5d79501b3877a1","order_source":"orderbook","orders_submitted":0,"presentation":{"amount":"10.065070","amount_traded":"0","microtimestamp":"1787932601705000","price":"2483.84"},"previous_record_hash":"fe4738e592b75392502eec06d26a774a9a15ea9f079338c4c08cda0efecb3602","profit_assessment":null,"record_hash":"25c8bc10ce106b1aa53fa4396b8b35fb4cca666dcbe5c4178456b29eadb657b0","recorded_unix_us":1787932601873929,"recorded_utc":"2026-08-28T15:56:41.873929Z","schema_version":"nrrf810.exchange_authored_interactive_closure.v1","source_chain_continuous":true,"source_event":"order_deleted","source_event_id":"00065a1d-7f9b-6228-0000-001203000020","source_event_id_unique":true,"source_pre_event_id":"00065a1d-7f9b-5e40-0002-001202000020","translation":"FOLD_RETURN_TO_ZERO","unfold_event_id":"00065a1d-7f98-83c8-0000-001201000020","zero_hair":true}
{"channel":"live_orders_ethusd","interaction_index":286,"natural_form":{"channel":"live_orders_ethusd","order_id":"2044303879622656","order_subtype":5,"order_type":1},"natural_form_sha256":"1c344e02a80ae39cc3f410a2483a67ae64c9d0ef922a6229a08b940efc552c95","order_source":"orderbook","orders_submitted":0,"presentation":{"amount":"4.028874","amount_traded":"0","microtimestamp":"1787932601705000","price":"2482.09"},"previous_record_hash":"25c8bc10ce106b1aa53fa4396b8b35fb4cca666dcbe5c4178456b29eadb657b0","profit_assessment":null,"record_hash":"3b0927c37276c090d52d9eefb8acb4225f913e7792edf8b7cb09128f7593080b","recorded_unix_us":1787932601873960,"recorded_utc":"2026-08-28T15:56:41.873960Z","schema_version":"nrrf810.exchange_authored_interactive_closure.v1","source_chain_continuous":true,"source_event":"order_deleted","source_event_id":"00065a1d-7f9b-6228-0001-001200000020","source_event_id_unique":true,"source_pre_event_id":"00065a1d-7f9b-6228-0000-001203000020","translation":"FOLD_RETURN_TO_ZERO","unfold_event_id":"00065a1d-7f98-87b0-0000-001202000020","zero_hair":true}
{"channel":"live_orders_ethusd","interaction_index":287,"natural_form":{"channel":"live_orders_ethusd","order_id":"2044303879622658","order_subtype":5,"order_type":1},"natural_form_sha256":"fa50fae9c62c37e37afc699aed7c0842a8ddb4845be10fa43fa6ac224b872bd5","order_source":"orderbook","orders_submitted":0,"presentation":{"amount":"10.057184","amount_traded":"0","microtimestamp":"1787932601705000","price":"2485.79"},"previous_record_hash":"3b0927c37276c090d52d9eefb8acb4225f913e7792edf8b7cb09128f7593080b","profit_assessment":null,"record_hash":"4aa9fe965c68a3e5d55c9cbe52e65b04fccf1ab42ac7d6040ffc03a9833dc785","recorded_unix_us":1787932601874114,"recorded_utc":"2026-08-28T15:56:41.874114Z","schema_version":"nrrf810.exchange_authored_interactive_closure.v1","source_chain_continuous":true,"source_event":"order_deleted","source_event_id":"00065a1d-7f9b-6228-0002-001201000020","source_event_id_unique":true,"source_pre_event_id":"00065a1d-7f9b-6228-0001-001200000020","translation":"FOLD_RETURN_TO_ZERO","unfold_event_id":"00065a1d-7f98-87b0-0001-001203000020","zero_hair":true}
{"channel":"live_orders_ethusd","interaction_index":288,"natural_form":{"channel":"live_orders_ethusd","order_id":"2044303879622659","order_subtype":5,"order_type":1},"natural_form_sha256":"72022db2b1160cc2c5cb8f94fc08f22dddd3823141337a2d16931c459ff6ae8a","order_source":"orderbook","orders_submitted":0,"presentation":{"amount":"20.097242","amount_traded":"0","microtimestamp":"1787932601706000","price":"2487.91"},"previous_record_hash":"4aa9fe965c68a3e5d55c9cbe52e65b04fccf1ab42ac7d6040ffc03a9833dc785","profit_assessment":null,"record_hash":"9383984f7d86585bf32eca9d0fc1ab8c1150663517140db42f2ad5112cd01483","recorded_unix_us":1787932601874196,"recorded_utc":"2026-08-28T15:56:41.874196Z","schema_version":"nrrf810.exchange_authored_interactive_closure.v1","source_chain_continuous":true,"source_event":"order_deleted","source_event_id":"00065a1d-7f9b-6610-0000-001202000020","source_event_id_unique":true,"source_pre_event_id":"00065a1d-7f9b-6228-0002-001201000020","translation":"FOLD_RETURN_TO_ZERO","unfold_event_id":"00065a1d-7f98-8b98-0000-001200000020","zero_hair":true}
{"channel":"live_orders_ethusd","interaction_index":289,"natural_form":{"channel":"live_orders_ethusd","order_id":"2044303879626752","order_subtype":5,"order_type":1},"natural_form_sha256":"9c271bb39a9565db9910264f6c64c586501200c68a1440647fd0e9e0a6b83edc","order_source":"orderbook","orders_submitted":0,"presentation":{"amount":"20.088574","amount_traded":"0","microtimestamp":"1787932601706000","price":"2488.98"},"previous_record_hash":"9383984f7d86585bf32eca9d0fc1ab8c1150663517140db42f2ad5112cd01483","profit_assessment":null,"record_hash":"8d8fae3afe87fe4833536a756a3dd5ca9ca21a28e34cfeea751bf3554e93c48f","recorded_unix_us":1787932601874227,"recorded_utc":"2026-08-28T15:56:41.874227Z","schema_version":"nrrf810.exchange_authored_interactive_closure.v1","source_chain_continuous":true,"source_event":"order_deleted","source_event_id":"00065a1d-7f9b-6610-0001-001203000020","source_event_id_unique":true,"source_pre_event_id":"00065a1d-7f9b-6610-0000-001202000020","translation":"FOLD_RETURN_TO_ZERO","unfold_event_id":"00065a1d-7f98-8b98-0001-001201000020","zero_hair":true}
{"channel":"live_orders_ethusd","interaction_index":290,"natural_form":{"channel":"live_orders_ethusd","order_id":"2044303879630850","order_subtype":5,"order_type":1},"natural_form_sha256":"2d0059a9ac8ec1ec8ff00f6c57ed412057e6851b37989c7ae28a16e51122f767","order_source":"orderbook","orders_submitted":0,"presentation":{"amount":"39.969006","amount_traded":"0","microtimestamp":"1787932601706000","price":"2501.94"},"previous_record_hash":"8d8fae3afe87fe4833536a756a3dd5ca9ca21a28e34cfeea751bf3554e93c48f","profit_assessment":null,"record_hash":"e398e13ef0d434fcb648f12cb66ca6aebc8780116df907d167ac4cfc61a3f720","recorded_unix_us":1787932601874435,"recorded_utc":"2026-08-28T15:56:41.874435Z","schema_version":"nrrf810.exchange_authored_interactive_closure.v1","source_chain_continuous":true,"source_event":"order_deleted","source_event_id":"00065a1d-7f9b-6610-0002-001200000020","source_event_id_unique":true,"source_pre_event_id":"00065a1d-7f9b-6610-0001-001203000020","translation":"FOLD_RETURN_TO_ZERO","unfold_event_id":"00065a1d-7f98-9368-0000-001202000020","zero_hair":true}
{"channel":"live_orders_ethusd","interaction_index":291,"natural_form":{"channel":"live_orders_ethusd","order_id":"2044303879634947","order_subtype":5,"order_type":1},"natural_form_sha256":"59eb385cbd286aec6db473476b7c0ec7618d3eea5ae19079e3e7ed246fe9d032","order_source":"orderbook","orders_submitted":0,"presentation":{"amount":"40.092050","amount_traded":"0","microtimestamp":"1787932601707000","price":"2494.27"},"previous_record_hash":"e398e13ef0d434fcb648f12cb66ca6aebc8780116df907d167ac4cfc61a3f720","profit_assessment":null,"record_hash":"2e8b81b27810b51565d6f9dbc7e5288553741b51a967defd6a4ec58a05763578","recorded_unix_us":1787932601874465,"recorded_utc":"2026-08-28T15:56:41.874465Z","schema_version":"nrrf810.exchange_authored_interactive_closure.v1","source_chain_continuous":true,"source_event":"order_deleted","source_event_id":"00065a1d-7f9b-69f8-0000-001201000020","source_event_id_unique":true,"source_pre_event_id":"00065a1d-7f9b-6610-0002-001200000020","translation":"FOLD_RETURN_TO_ZERO","unfold_event_id":"00065a1d-7f98-9368-0001-001203000020","zero_hair":true}
{"channel":"live_orders_ethusd","interaction_index":292,"natural_form":{"channel":"live_orders_ethusd","order_id":"2044303879634948","order_subtype":5,"order_type":0},"natural_form_sha256":"488ac5e78008b16ec81c0bd80eb793e790ecf5a6ef056a30001f29583b0a77f3","order_source":"orderbook","orders_submitted":0,"presentation":{"amount":"4.033204","amount_traded":"0","microtimestamp":"1787932601707000","price":"2479.41"},"previous_record_hash":"2e8b81b27810b51565d6f9dbc7e5288553741b51a967defd6a4ec58a05763578","profit_assessment":null,"record_hash":"6688cc0f6c53abd5a3bdced06668a1b5a2c9f08b76a95dbcfe6ff47c9110c77f","recorded_unix_us":1787932601874491,"recorded_utc":"2026-08-28T15:56:41.874491Z","schema_version":"nrrf810.exchange_authored_interactive_closure.v1","source_chain_continuous":true,"source_event":"order_deleted","source_event_id":"00065a1d-7f9b-69f8-0001-001202000020","source_event_id_unique":true,"source_pre_event_id":"00065a1d-7f9b-69f8-0000-001201000020","translation":"FOLD_RETURN_TO_ZERO","unfold_event_id":"00065a1d-7f98-9368-0002-001200000020","zero_hair":true}
{"channel":"live_orders_ethusd","interaction_index":293,"natural_form":{"channel":"live_orders_ethusd","order_id":"2044303879704578","order_subtype":5,"order_type":1},"natural_form_sha256":"19bdb9b2d10b6f71270de71d63bfa34722b791ceabc6a61cb5e32e0c961c950c","order_source":"orderbook","orders_submitted":0,"presentation":{"amount":"4.028412","amount_traded":"0","microtimestamp":"1787932601707000","price":"2482.37"},"previous_record_hash":"6688cc0f6c53abd5a3bdced06668a1b5a2c9f08b76a95dbcfe6ff47c9110c77f","profit_assessment":null,"record_hash":"3414c29fd4b3098ca71cba48a2a1f0dc7a0a7bf9acd60317e92d9110d5e9aef0","recorded_unix_us":1787932601874516,"recorded_utc":"2026-08-28T15:56:41.874516Z","schema_version":"nrrf810.exchange_authored_interactive_closure.v1","source_chain_continuous":true,"source_event":"order_deleted","source_event_id":"00065a1d-7f9b-69f8-0002-001203000020","source_event_id_unique":true,"source_pre_event_id":"00065a1d-7f9b-69f8-0001-001202000020","translation":"FOLD_RETURN_TO_ZERO","unfold_event_id":"00065a1d-7f98-d5d0-0000-001201000020","zero_hair":true}
{"channel":"live_orders_ethusd","interaction_index":294,"natural_form":{"channel":"live_orders_ethusd","order_id":"2044303879704580","order_subtype":5,"order_type":1},"natural_form_sha256":"7705ec5f64b4019a8bcdca662e5f99f65e496652cc8e06f36766de0737db7df7","order_source":"orderbook","orders_submitted":0,"presentation":{"amount":"20.077182","amount_traded":"0","microtimestamp":"1787932601708000","price":"2490.39"},"previous_record_hash":"3414c29fd4b3098ca71cba48a2a1f0dc7a0a7bf9acd60317e92d9110d5e9aef0","profit_assessment":null,"record_hash":"afa5bcbea48920ed0fb1582898241911d25d3f3441012e6e765a795d9ca2eaa2","recorded_unix_us":1787932601874642,"recorded_utc":"2026-08-28T15:56:41.874642Z","schema_version":"nrrf810.exchange_authored_interactive_closure.v1","source_chain_continuous":true,"source_event":"order_deleted","source_event_id":"00065a1d-7f9b-6de0-0000-001200000020","source_event_id_unique":true,"source_pre_event_id":"00065a1d-7f9b-69f8-0002-001203000020","translation":"FOLD_RETURN_TO_ZERO","unfold_event_id":"00065a1d-7f98-d9b8-0000-001202000020","zero_hair":true}
{"channel":"live_orders_ethusd","interaction_index":295,"natural_form":{"channel":"live_orders_ethusd","order_id":"2044303879704581","order_subtype":5,"order_type":1},"natural_form_sha256":"2c014a489f0c93bbb1b138c0dde4c9f7bc231e2273743d3a72c4c6fe7db4c1ad","order_source":"orderbook","orders_submitted":0,"presentation":{"amount":"10.062547","amount_traded":"0","microtimestamp":"1787932601708000","price":"2484.47"},"previous_record_hash":"afa5bcbea48920ed0fb1582898241911d25d3f3441012e6e765a795d9ca2eaa2","profit_assessment":null,"record_hash":"39fdc7b788b191b766d56a93a8a613543f5e7d452981509d5b429a972969b9c9","recorded_unix_us":1787932601874670,"recorded_utc":"2026-08-28T15:56:41.874670Z","schema_version":"nrrf810.exchange_authored_interactive_closure.v1","source_chain_continuous":true,"source_event":"order_deleted","source_event_id":"00065a1d-7f9b-6de0-0001-001201000020","source_event_id_unique":true,"source_pre_event_id":"00065a1d-7f9b-6de0-0000-001200000020","translation":"FOLD_RETURN_TO_ZERO","unfold_event_id":"00065a1d-7f98-d9b8-0001-001203000020","zero_hair":true}
{"channel":"live_orders_ethusd","interaction_index":296,"natural_form":{"channel":"live_orders_ethusd","order_id":"2044303879708681","order_subtype":5,"order_type":1},"natural_form_sha256":"b432b999080d19c7042260cb672872af48c8bef6c4c06a7feb0b02a7772f17d2","order_source":"orderbook","orders_submitted":0,"presentation":{"amount":"40.051178","amount_traded":"0","microtimestamp":"1787932601708000","price":"2496.81"},"previous_record_hash":"39fdc7b788b191b766d56a93a8a613543f5e7d452981509d5b429a972969b9c9","profit_assessment":null,"record_hash":"7e81edb67451f7c28bbf5200267ed1cff2e372bf256b95b3df4edf365c967562","recorded_unix_us":1787932601874765,"recorded_utc":"2026-08-28T15:56:41.874765Z","schema_version":"nrrf810.exchange_authored_interactive_closure.v1","source_chain_continuous":true,"source_event":"order_deleted","source_event_id":"00065a1d-7f9b-6de0-0002-001202000020","source_event_id_unique":true,"source_pre_event_id":"00065a1d-7f9b-6de0-0001-001201000020","translation":"FOLD_RETURN_TO_ZERO","unfold_event_id":"00065a1d-7f98-dda0-0000-001200000020","zero_hair":true}
{"channel":"live_orders_ethusd","interaction_index":297,"natural_form":{"channel":"live_orders_ethusd","order_id":"2044303879774213","order_subtype":5,"order_type":1},"natural_form_sha256":"3704e7599ecaeec8a2763ad11bda05b079e81d553f6bda34c61b774199f557f9","order_source":"orderbook","orders_submitted":0,"presentation":{"amount":"4.028003","amount_traded":"0","microtimestamp":"1787932601709000","price":"2482.62"},"previous_record_hash":"7e81edb67451f7c28bbf5200267ed1cff2e372bf256b95b3df4edf365c967562","profit_assessment":null,"record_hash":"3efb4fed595369d54b0d5ca8bbd5678e32318be06f6d845d73baa6bf40eb298b","recorded_unix_us":1787932601874788,"recorded_utc":"2026-08-28T15:56:41.874788Z","schema_version":"nrrf810.exchange_authored_interactive_closure.v1","source_chain_continuous":true,"source_event":"order_deleted","source_event_id":"00065a1d-7f9b-71c8-0000-001203000020","source_event_id_unique":true,"source_pre_event_id":"00065a1d-7f9b-6de0-0002-001202000020","translation":"FOLD_RETURN_TO_ZERO","unfold_event_id":"00065a1d-7f99-1c20-0000-001201000020","zero_hair":true}
{"channel":"live_orders_btcusd","interaction_index":298,"natural_form":{"channel":"live_orders_btcusd","order_id":"2044303880404997","order_subtype":4,"order_type":0},"natural_form_sha256":"ecca24cb960a3960be38e569392f4bbde36d1b2487a37c8a5fa8e0871f63f383","order_source":"orderbook","orders_submitted":0,"presentation":{"amount":"0.00006631","amount_traded":"0","microtimestamp":"1787932601709000","price":"76166.96"},"previous_record_hash":"3efb4fed595369d54b0d5ca8bbd5678e32318be06f6d845d73baa6bf40eb298b","profit_assessment":null,"record_hash":"5816565bf3f4a74cc32d3302ae8b9f7806362a4525d4e8b83f3320db1fcedbe6","recorded_unix_us":1787932601874907,"recorded_utc":"2026-08-28T15:56:41.874907Z","schema_version":"nrrf810.exchange_authored_interactive_closure.v1","source_chain_continuous":true,"source_event":"order_created","source_event_id":"00065a1d-7f9b-71c8-0000-000102000020","source_event_id_unique":true,"source_pre_event_id":"00065a1d-7f9b-4ab8-0000-000101000020","translation":"UNFOLD_TO_INF","unfold_event_id":null,"zero_hair":false}
{"channel":"live_orders_btcusd","interaction_index":299,"natural_form":{"channel":"live_orders_btcusd","order_id":"2044303880404997","order_subtype":4,"order_type":0},"natural_form_sha256":"ecca24cb960a3960be38e569392f4bbde36d1b2487a37c8a5fa8e0871f63f383","order_source":"orderbook","orders_submitted":0,"presentation":{"amount":"0.00006631","amount_traded":"0","microtimestamp":"1787932601709000","price":"76166.96"},"previous_record_hash":"5816565bf3f4a74cc32d3302ae8b9f7806362a4525d4e8b83f3320db1fcedbe6","profit_assessment":null,"record_hash":"61ee8562c37139f83365576ce3b68c4d3ad496089b16e7d389d29cee77df178d","recorded_unix_us":1787932601874969,"recorded_utc":"2026-08-28T15:56:41.874969Z","schema_version":"nrrf810.exchange_authored_interactive_closure.v1","source_chain_continuous":true,"source_event":"order_deleted","source_event_id":"00065a1d-7f9b-71c8-0001-000103000020","source_event_id_unique":true,"source_pre_event_id":"00065a1d-7f9b-71c8-0000-000102000020","translation":"FOLD_RETURN_TO_ZERO","unfold_event_id":"00065a1d-7f9b-71c8-0000-000102000020","zero_hair":true}
{"channel":"live_orders_ethusd","interaction_index":300,"natural_form":{"channel":"live_orders_ethusd","order_id":"2044303879778310","order_subtype":5,"order_type":1},"natural_form_sha256":"52e858aa8aec79cffbc18050f0a763bcf732df5d34bcf34525d6875334c32932","order_source":"orderbook","orders_submitted":0,"presentation":{"amount":"10.059779","amount_traded":"0","microtimestamp":"1787932601709000","price":"2485.15"},"previous_record_hash":"61ee8562c37139f83365576ce3b68c4d3ad496089b16e7d389d29cee77df178d","profit_assessment":null,"record_hash":"c61f84cf8ddb96064794b620b67a83ee942c07fdeac35ceaddc00be3e12101b9","recorded_unix_us":1787932601874992,"recorded_utc":"2026-08-28T15:56:41.874992Z","schema_version":"nrrf810.exchange_authored_interactive_closure.v1","source_chain_continuous":true,"source_event":"order_deleted","source_event_id":"00065a1d-7f9b-71c8-0001-001200000020","source_event_id_unique":true,"source_pre_event_id":"00065a1d-7f9b-71c8-0000-001203000020","translation":"FOLD_RETURN_TO_ZERO","unfold_event_id":"00065a1d-7f99-2008-0000-001202000020","zero_hair":true}
{"channel":"live_orders_ethusd","interaction_index":301,"natural_form":{"channel":"live_orders_ethusd","order_id":"2044303879782401","order_subtype":5,"order_type":1},"natural_form_sha256":"92963990ade07ea12dedde23c76cc6ccf1e3ed9923279db0b7b768a3066380cb","order_source":"orderbook","orders_submitted":0,"presentation":{"amount":"20.063885","amount_traded":"0","microtimestamp":"1787932601709000","price":"2492.04"},"previous_record_hash":"c61f84cf8ddb96064794b620b67a83ee942c07fdeac35ceaddc00be3e12101b9","profit_assessment":null,"record_hash":"9eb80c66dcd7add75fed43f7d1064803a2bd1fcad6976df4656b7bc307531bfa","recorded_unix_us":1787932601875086,"recorded_utc":"2026-08-28T15:56:41.875086Z","schema_version":"nrrf810.exchange_authored_interactive_closure.v1","source_chain_continuous":true,"source_event":"order_deleted","source_event_id":"00065a1d-7f9b-71c8-0002-001201000020","source_event_id_unique":true,"source_pre_event_id":"00065a1d-7f9b-71c8-0001-001200000020","translation":"FOLD_RETURN_TO_ZERO","unfold_event_id":"00065a1d-7f99-2008-0001-001203000020","zero_hair":true}
{"channel":"live_orders_ethusd","interaction_index":302,"natural_form":{"channel":"live_orders_ethusd","order_id":"2044303879786499","order_subtype":5,"order_type":1},"natural_form_sha256":"59df011270ad6d134ac89a2d150bf92e108ed492c2ae3cf3cea758c3498bb5df","order_source":"orderbook","orders_submitted":0,"presentation":{"amount":"40.010118","amount_traded":"0","microtimestamp":"1787932601710000","price":"2499.37"},"previous_record_hash":"9eb80c66dcd7add75fed43f7d1064803a2bd1fcad6976df4656b7bc307531bfa","profit_assessment":null,"record_hash":"65f6fb42c4c88370329c3d3856383844b15bd41bd31694bb019708708e3dd76b","recorded_unix_us":1787932601875110,"recorded_utc":"2026-08-28T15:56:41.875110Z","schema_version":"nrrf810.exchange_authored_interactive_closure.v1","source_chain_continuous":true,"source_event":"order_deleted","source_event_id":"00065a1d-7f9b-75b0-0000-001202000020","source_event_id_unique":true,"source_pre_event_id":"00065a1d-7f9b-71c8-0002-001201000020","translation":"FOLD_RETURN_TO_ZERO","unfold_event_id":"00065a1d-7f99-27d8-0000-001200000020","zero_hair":true}
{"channel":"live_orders_ethusd","interaction_index":303,"natural_form":{"channel":"live_orders_ethusd","order_id":"2044303879847937","order_subtype":5,"order_type":1},"natural_form_sha256":"2e377e95f8925722d8e03c2af5517681a5fca59325fdcf93a80d021ff5116f9a","order_source":"orderbook","orders_submitted":0,"presentation":{"amount":"4.027586","amount_traded":"0","microtimestamp":"1787932601710000","price":"2482.88"},"previous_record_hash":"65f6fb42c4c88370329c3d3856383844b15bd41bd31694bb019708708e3dd76b","profit_assessment":null,"record_hash":"6db0592f86436e121523b92cd55a5d79d31bb7efcc48bc16acd9868fe3be7cec","recorded_unix_us":1787932601875225,"recorded_utc":"2026-08-28T15:56:41.875225Z","schema_version":"nrrf810.exchange_authored_interactive_closure.v1","source_chain_continuous":true,"source_event":"order_deleted","source_event_id":"00065a1d-7f9b-75b0-0001-001203000020","source_event_id_unique":true,"source_pre_event_id":"00065a1d-7f9b-75b0-0000-001202000020","translation":"FOLD_RETURN_TO_ZERO","unfold_event_id":"00065a1d-7f99-5e88-0000-001201000020","zero_hair":true}
{"channel":"live_orders_btcusd","interaction_index":304,"natural_form":{"channel":"live_orders_btcusd","order_id":"2044303880413187","order_subtype":5,"order_type":0},"natural_form_sha256":"308644fdb383a40f213043e855731f7fd6f4452a9885ce527a5e7dd6424adb23","order_source":"orderbook","orders_submitted":0,"presentation":{"amount":"0.19103830","amount_traded":"0","microtimestamp":"1787932601711000","price":"78482.99"},"previous_record_hash":"6db0592f86436e121523b92cd55a5d79d31bb7efcc48bc16acd9868fe3be7cec","profit_assessment":null,"record_hash":"1fcdc96b4f23ccefe2f679bee8b4bdc5748fe99216ce6a535d3cab09b4022df6","recorded_unix_us":1787932601875247,"recorded_utc":"2026-08-28T15:56:41.875247Z","schema_version":"nrrf810.exchange_authored_interactive_closure.v1","source_chain_continuous":true,"source_event":"order_created","source_event_id":"00065a1d-7f9b-7998-0000-000100000020","source_event_id_unique":true,"source_pre_event_id":"00065a1d-7f9b-71c8-0001-000103000020","translation":"UNFOLD_TO_INF","unfold_event_id":null,"zero_hair":false}
{"channel":"live_orders_btcusd","interaction_index":305,"natural_form":{"channel":"live_orders_btcusd","order_id":"2044303880417287","order_subtype":5,"order_type":1},"natural_form_sha256":"59671abac5aeb21376c4af14107dc40afd8b1906d2322e514d64134af5214481","order_source":"orderbook","orders_submitted":0,"presentation":{"amount":"0.06310787","amount_traded":"0","microtimestamp":"1787932601712000","price":"78520.20"},"previous_record_hash":"1fcdc96b4f23ccefe2f679bee8b4bdc5748fe99216ce6a535d3cab09b4022df6","profit_assessment":null,"record_hash":"15eb1f685f0b7299650184f48ffcd8d87064989d81c4bd140473954b0a9d33a9","recorded_unix_us":1787932601875342,"recorded_utc":"2026-08-28T15:56:41.875342Z","schema_version":"nrrf810.exchange_authored_interactive_closure.v1","source_chain_continuous":true,"source_event":"order_created","source_event_id":"00065a1d-7f9b-7d80-0000-000101000020","source_event_id_unique":true,"source_pre_event_id":"00065a1d-7f9b-7998-0000-000100000020","translation":"UNFOLD_TO_INF","unfold_event_id":null,"zero_hair":false}
{"channel":"live_orders_btcusd","interaction_index":306,"natural_form":{"channel":"live_orders_btcusd","order_id":"2044303880417287","order_subtype":5,"order_type":1},"natural_form_sha256":"59671abac5aeb21376c4af14107dc40afd8b1906d2322e514d64134af5214481","order_source":"orderbook","orders_submitted":0,"presentation":{"amount":"0.06310787","amount_traded":"0","microtimestamp":"1787932601712000","price":"78520.20"},"previous_record_hash":"15eb1f685f0b7299650184f48ffcd8d87064989d81c4bd140473954b0a9d33a9","profit_assessment":null,"record_hash":"831405658c1645869231ac923b0bdafb9e2de84adf18b1716b8186b887545a3c","recorded_unix_us":1787932601875369,"recorded_utc":"2026-08-28T15:56:41.875369Z","schema_version":"nrrf810.exchange_authored_interactive_closure.v1","source_chain_continuous":true,"source_event":"order_deleted","source_event_id":"00065a1d-7f9b-7d80-0001-000102000020","source_event_id_unique":true,"source_pre_event_id":"00065a1d-7f9b-7d80-0000-000101000020","translation":"FOLD_RETURN_TO_ZERO","unfold_event_id":"00065a1d-7f9b-7d80-0000-000101000020","zero_hair":true}
{"channel":"live_orders_btcusd","interaction_index":307,"natural_form":{"channel":"live_orders_btcusd","order_id":"2044303880417290","order_subtype":5,"order_type":1},"natural_form_sha256":"fe431621025a1d1d1b5451cde2397bb7f927f72f3eff22bfa07e3bce7926f8a9","order_source":"orderbook","orders_submitted":0,"presentation":{"amount":"0.06310787","amount_traded":"0","microtimestamp":"1787932601713000","price":"78522.56"},"previous_record_hash":"831405658c1645869231ac923b0bdafb9e2de84adf18b1716b8186b887545a3c","profit_assessment":null,"record_hash":"b5c42f76292214f4b2bf162952703d3b18ebb23a56c6216842f93c2497bb610a","recorded_unix_us":1787932601875443,"recorded_utc":"2026-08-28T15:56:41.875443Z","schema_version":"nrrf810.exchange_authored_interactive_closure.v1","source_chain_continuous":true,"source_event":"order_created","source_event_id":"00065a1d-7f9b-8168-0000-000103000020","source_event_id_unique":true,"source_pre_event_id":"00065a1d-7f9b-7d80-0001-000102000020","translation":"UNFOLD_TO_INF","unfold_event_id":null,"zero_hair":false}
{"channel":"live_orders_btcusd","interaction_index":308,"natural_form":{"channel":"live_orders_btcusd","order_id":"2044303880417290","order_subtype":5,"order_type":1},"natural_form_sha256":"fe431621025a1d1d1b5451cde2397bb7f927f72f3eff22bfa07e3bce7926f8a9","order_source":"orderbook","orders_submitted":0,"presentation":{"amount":"0.06310787","amount_traded":"0","microtimestamp":"1787932601713000","price":"78522.56"},"previous_record_hash":"b5c42f76292214f4b2bf162952703d3b18ebb23a56c6216842f93c2497bb610a","profit_assessment":null,"record_hash":"e9735fafac177cdbf84565f25a524865aa669b5008cfaa321f6699a5b8be9e86","recorded_unix_us":1787932601875559,"recorded_utc":"2026-08-28T15:56:41.875559Z","schema_version":"nrrf810.exchange_authored_interactive_closure.v1","source_chain_continuous":true,"source_event":"order_deleted","source_event_id":"00065a1d-7f9b-8168-0001-000100000020","source_event_id_unique":true,"source_pre_event_id":"00065a1d-7f9b-8168-0000-000103000020","translation":"FOLD_RETURN_TO_ZERO","unfold_event_id":"00065a1d-7f9b-8168-0000-000103000020","zero_hair":true}
{"channel":"live_orders_btcusd","interaction_index":309,"natural_form":{"channel":"live_orders_btcusd","order_id":"2044303880556544","order_subtype":5,"order_type":0},"natural_form_sha256":"d5f6d6a099730706d8b6f5f5cfe9e836329eff788b4131d7fe08f83869316124","order_source":"orderbook","orders_submitted":0,"presentation":{"amount":"0.00140266","amount_traded":"0","microtimestamp":"1787932601746000","price":"70667.51"},"previous_record_hash":"e9735fafac177cdbf84565f25a524865aa669b5008cfaa321f6699a5b8be9e86","profit_assessment":null,"record_hash":"76d9afa9c81cfd1c414b1081e67a76b80252c436f79e824dfc3d7d1c0a97f983","recorded_unix_us":1787932601875582,"recorded_utc":"2026-08-28T15:56:41.875582Z","schema_version":"nrrf810.exchange_authored_interactive_closure.v1","source_chain_continuous":true,"source_event":"order_created","source_event_id":"00065a1d-7f9c-0250-0000-000101000020","source_event_id_unique":true,"source_pre_event_id":"00065a1d-7f9b-8168-0001-000100000020","translation":"UNFOLD_TO_INF","unfold_event_id":null,"zero_hair":false}
{"channel":"live_orders_btcusd","interaction_index":310,"natural_form":{"channel":"live_orders_btcusd","order_id":"2044303880560653","order_subtype":5,"order_type":1},"natural_form_sha256":"bce35b3fa5e119b4c4d28cac2e085562c35ce65f4b1f2df2a6e7fdabfeee513e","order_source":"orderbook","orders_submitted":0,"presentation":{"amount":"0.10000000","amount_traded":"0","microtimestamp":"1787932601747000","price":"78522.62"},"previous_record_hash":"76d9afa9c81cfd1c414b1081e67a76b80252c436f79e824dfc3d7d1c0a97f983","profit_assessment":null,"record_hash":"ef6cf90a6c6e411cf65091369c2acfe24bd24e8e71114f4654a3eb648cc25a00","recorded_unix_us":1787932601875685,"recorded_utc":"2026-08-28T15:56:41.875685Z","schema_version":"nrrf810.exchange_authored_interactive_closure.v1","source_chain_continuous":true,"source_event":"order_created","source_event_id":"00065a1d-7f9c-0638-0000-000102000020","source_event_id_unique":true,"source_pre_event_id":"00065a1d-7f9c-0250-0000-000101000020","translation":"UNFOLD_TO_INF","unfold_event_id":null,"zero_hair":false}
{"channel":"live_orders_btcusd","interaction_index":311,"natural_form":{"channel":"live_orders_btcusd","order_id":"2044303880560653","order_subtype":5,"order_type":1},"natural_form_sha256":"bce35b3fa5e119b4c4d28cac2e085562c35ce65f4b1f2df2a6e7fdabfeee513e","order_source":"orderbook","orders_submitted":0,"presentation":{"amount":"0.10000000","amount_traded":"0","microtimestamp":"1787932601747000","price":"78522.62"},"previous_record_hash":"ef6cf90a6c6e411cf65091369c2acfe24bd24e8e71114f4654a3eb648cc25a00","profit_assessment":null,"record_hash":"18bc61a52887749e84d6a46ec9b098d16013e1237c7748e010ce119a623ed556","recorded_unix_us":1787932601875717,"recorded_utc":"2026-08-28T15:56:41.875717Z","schema_version":"nrrf810.exchange_authored_interactive_closure.v1","source_chain_continuous":true,"source_event":"order_deleted","source_event_id":"00065a1d-7f9c-0638-0001-000103000020","source_event_id_unique":true,"source_pre_event_id":"00065a1d-7f9c-0638-0000-000102000020","translation":"FOLD_RETURN_TO_ZERO","unfold_event_id":"00065a1d-7f9c-0638-0000-000102000020","zero_hair":true}
{"channel":"live_orders_ethbtc","interaction_index":312,"natural_form":{"channel":"live_orders_ethbtc","order_id":"2044303878811654","order_subtype":5,"order_type":1},"natural_form_sha256":"102ddd71a43f3d7e3a6669375399c86a3ec5e02a7d32f9bfacdbb86366495057","order_source":"orderbook","orders_submitted":0,"presentation":{"amount":"2.01528391","amount_traded":"0","microtimestamp":"1787932601751000","price":"0.03160301"},"previous_record_hash":"18bc61a52887749e84d6a46ec9b098d16013e1237c7748e010ce119a623ed556","profit_assessment":null,"record_hash":"73c356ebd6aa25295de706f0d26fa7659ffc4d0898b32288e4379c2489246ae5","recorded_unix_us":1787932601875800,"recorded_utc":"2026-08-28T15:56:41.875800Z","schema_version":"nrrf810.exchange_authored_interactive_closure.v1","source_chain_continuous":true,"source_event":"order_deleted","source_event_id":"00065a1d-7f9c-15d8-0000-001102000020","source_event_id_unique":true,"source_pre_event_id":"00065a1d-7f9a-cdb8-0000-001101000020","translation":"FOLD_RETURN_TO_ZERO","unfold_event_id":"00065a1d-7f95-8240-0000-001100000020","zero_hair":true}
{"channel":"live_orders_ethusd","interaction_index":313,"natural_form":{"channel":"live_orders_ethusd","order_id":"2044303874117635","order_subtype":5,"order_type":1},"natural_form_sha256":"d1701cdb4b5b15c65f07cb4d52f94f47419b4ccdea8af83a43c9a76a6cafa181","order_source":"orderbook","orders_submitted":0,"presentation":{"amount":"2.014812","amount_traded":"0","microtimestamp":"1787932601751000","price":"2481.66"},"previous_record_hash":"73c356ebd6aa25295de706f0d26fa7659ffc4d0898b32288e4379c2489246ae5","profit_assessment":null,"record_hash":"06c195b020ece168311225f7fad217688069dbfffb2edf83c9d31648b717fa0d","recorded_unix_us":1787932601875964,"recorded_utc":"2026-08-28T15:56:41.875964Z","schema_version":"nrrf810.exchange_authored_interactive_closure.v1","source_chain_continuous":true,"source_event":"order_deleted","source_event_id":"00065a1d-7f9c-15d8-0000-001200000020","source_event_id_unique":true,"source_pre_event_id":"00065a1d-7f9b-75b0-0001-001203000020","translation":"PARTIAL_PRIOR_UNFOLD","unfold_event_id":null,"zero_hair":false}
{"channel":"live_orders_btcusd","interaction_index":314,"natural_form":{"channel":"live_orders_btcusd","order_id":"2044303880589315","order_subtype":5,"order_type":1},"natural_form_sha256":"7fbba6e9d67bdd02cfb0b5e70078bba7b1d90487849952f9c9ba9a689474d321","order_source":"orderbook","orders_submitted":0,"presentation":{"amount":"0.10000000","amount_traded":"0","microtimestamp":"1787932601754000","price":"78522.63"},"previous_record_hash":"06c195b020ece168311225f7fad217688069dbfffb2edf83c9d31648b717fa0d","profit_assessment":null,"record_hash":"211b23636442cd12794e27d681be11ffc7954f647ad726b907f6bf9045a8bd9c","recorded_unix_us":1787932601875987,"recorded_utc":"2026-08-28T15:56:41.875987Z","schema_version":"nrrf810.exchange_authored_interactive_closure.v1","source_chain_continuous":true,"source_event":"order_created","source_event_id":"00065a1d-7f9c-2190-0000-000100000020","source_event_id_unique":true,"source_pre_event_id":"00065a1d-7f9c-0638-0001-000103000020","translation":"UNFOLD_TO_INF","unfold_event_id":null,"zero_hair":false}
{"channel":"live_orders_btcusd","interaction_index":315,"natural_form":{"channel":"live_orders_btcusd","order_id":"2044303880589315","order_subtype":5,"order_type":1},"natural_form_sha256":"7fbba6e9d67bdd02cfb0b5e70078bba7b1d90487849952f9c9ba9a689474d321","order_source":"orderbook","orders_submitted":0,"presentation":{"amount":"0.10000000","amount_traded":"0","microtimestamp":"1787932601754000","price":"78522.63"},"previous_record_hash":"211b23636442cd12794e27d681be11ffc7954f647ad726b907f6bf9045a8bd9c","profit_assessment":null,"record_hash":"539639d0d6d5dd73105a01d26d0258a8c45b237b7329db991e8e4f98eaddd468","recorded_unix_us":1787932601876090,"recorded_utc":"2026-08-28T15:56:41.876090Z","schema_version":"nrrf810.exchange_authored_interactive_closure.v1","source_chain_continuous":true,"source_event":"order_deleted","source_event_id":"00065a1d-7f9c-2190-0001-000101000020","source_event_id_unique":true,"source_pre_event_id":"00065a1d-7f9c-2190-0000-000100000020","translation":"FOLD_RETURN_TO_ZERO","unfold_event_id":"00065a1d-7f9c-2190-0000-000100000020","zero_hair":true}
{"channel":"live_orders_btcusd","interaction_index":316,"natural_form":{"channel":"live_orders_btcusd","order_id":"2044303880593408","order_subtype":0,"order_type":1},"natural_form_sha256":"53b89e08cc019503db3577729e90819173501a1823c0b3387ce5f5ef5161c705","order_source":"orderbook","orders_submitted":0,"presentation":{"amount":"0.01273518","amount_traded":"0","microtimestamp":"1787932601755000","price":"80486.00"},"previous_record_hash":"539639d0d6d5dd73105a01d26d0258a8c45b237b7329db991e8e4f98eaddd468","profit_assessment":null,"record_hash":"b35a69b9b0c89cdf74f6dca25b25d167ccaaae8a967e311ce9bca4ddf12dd9eb","recorded_unix_us":1787932601876113,"recorded_utc":"2026-08-28T15:56:41.876113Z","schema_version":"nrrf810.exchange_authored_interactive_closure.v1","source_chain_continuous":true,"source_event":"order_created","source_event_id":"00065a1d-7f9c-2578-0000-000102000020","source_event_id_unique":true,"source_pre_event_id":"00065a1d-7f9c-2190-0001-000101000020","translation":"UNFOLD_TO_INF","unfold_event_id":null,"zero_hair":false}
{"channel":"live_orders_btcusd","interaction_index":317,"natural_form":{"channel":"live_orders_btcusd","order_id":"2044303879917571","order_subtype":5,"order_type":0},"natural_form_sha256":"66032732daa1ca466ffa06883cdb292e88d6c8ab3a0a50be8ef43601c2c2646f","order_source":"orderbook","orders_submitted":0,"presentation":{"amount":"0.00140266","amount_traded":"0","microtimestamp":"1787932601758000","price":"70667.51"},"previous_record_hash":"b35a69b9b0c89cdf74f6dca25b25d167ccaaae8a967e311ce9bca4ddf12dd9eb","profit_assessment":null,"record_hash":"7bcc115f0e2a02145ebc6383afa3bff0e117fa8a9fdbb6612f7e61238686df17","recorded_unix_us":1787932601876225,"recorded_utc":"2026-08-28T15:56:41.876225Z","schema_version":"nrrf810.exchange_authored_interactive_closure.v1","source_chain_continuous":true,"source_event":"order_deleted","source_event_id":"00065a1d-7f9c-3130-0000-000103000020","source_event_id_unique":true,"source_pre_event_id":"00065a1d-7f9c-2578-0000-000102000020","translation":"FOLD_RETURN_TO_ZERO","unfold_event_id":"00065a1d-7f99-a0f0-0000-000102000020","zero_hair":true}
{"channel":"live_orders_ethusd","interaction_index":318,"natural_form":{"channel":"live_orders_ethusd","order_id":"2044303864287236","order_subtype":5,"order_type":0},"natural_form_sha256":"dd243fb7ad241b23a81d3fc3e2c8de79670b0303f8d5a522f1eb8f9ae88e605c","order_source":"orderbook","orders_submitted":0,"presentation":{"amount":"11.694045","amount_traded":"0","microtimestamp":"1787932601762000","price":"2475.90"},"previous_record_hash":"7bcc115f0e2a02145ebc6383afa3bff0e117fa8a9fdbb6612f7e61238686df17","profit_assessment":null,"record_hash":"c6085139d57c9398e7923554c7e6f2d532518fe59cdb716d98159bd8ac1688df","recorded_unix_us":1787932601876289,"recorded_utc":"2026-08-28T15:56:41.876289Z","schema_version":"nrrf810.exchange_authored_interactive_closure.v1","source_chain_continuous":true,"source_event":"order_deleted","source_event_id":"00065a1d-7f9c-40d0-0000-001201000020","source_event_id_unique":true,"source_pre_event_id":"00065a1d-7f9c-15d8-0000-001200000020","translation":"PARTIAL_PRIOR_UNFOLD","unfold_event_id":null,"zero_hair":false}
{"channel":"live_orders_ethusd","interaction_index":319,"natural_form":{"channel":"live_orders_ethusd","order_id":"2044303880617994","order_subtype":5,"order_type":0},"natural_form_sha256":"1b14eb71129c28dce574817cc35848a2807c4bce907d1d86ac5b5075fa7fd9b7","order_source":"orderbook","orders_submitted":0,"presentation":{"amount":"11.691606","amount_traded":"0","microtimestamp":"1787932601762000","price":"2475.90"},"previous_record_hash":"c6085139d57c9398e7923554c7e6f2d532518fe59cdb716d98159bd8ac1688df","profit_assessment":null,"record_hash":"3898960eb286b068c445eb8f8543690d02f3430be00ba5883b36b5375ddffe55","recorded_unix_us":1787932601876313,"recorded_utc":"2026-08-28T15:56:41.876313Z","schema_version":"nrrf810.exchange_authored_interactive_closure.v1","source_chain_continuous":true,"source_event":"order_created","source_event_id":"00065a1d-7f9c-40d0-0001-001202000020","source_event_id_unique":true,"source_pre_event_id":"00065a1d-7f9c-40d0-0000-001201000020","translation":"UNFOLD_TO_INF","unfold_event_id":null,"zero_hair":false}
{"channel":"live_orders_ethusd","interaction_index":320,"natural_form":{"channel":"live_orders_ethusd","order_id":"2044303876444170","order_subtype":5,"order_type":0},"natural_form_sha256":"344a0e3c7b20744d6ebd2b217e8f288456617845c7726d36388f0181cb9b72dd","order_source":"orderbook","orders_submitted":0,"presentation":{"amount":"0.042033","amount_traded":"0","microtimestamp":"1787932601763000","price":"2480.57"},"previous_record_hash":"3898960eb286b068c445eb8f8543690d02f3430be00ba5883b36b5375ddffe55","profit_assessment":null,"record_hash":"7e894df54d58bfe15e25e00ce58037911e963b638d3b7a0fbc91e6a132638812","recorded_unix_us":1787932601876407,"recorded_utc":"2026-08-28T15:56:41.876407Z","schema_version":"nrrf810.exchange_authored_interactive_closure.v1","source_chain_continuous":true,"source_event":"order_deleted","source_event_id":"00065a1d-7f9c-44b8-0000-001203000020","source_event_id_unique":true,"source_pre_event_id":"00065a1d-7f9c-40d0-0001-001202000020","translation":"PARTIAL_PRIOR_UNFOLD","unfold_event_id":null,"zero_hair":false}
{"channel":"live_orders_ethusd","interaction_index":321,"natural_form":{"channel":"live_orders_ethusd","order_id":"2044303880622094","order_subtype":5,"order_type":0},"natural_form_sha256":"e378abf8043b93b9d81d74329e7428d48f63bd0b4169973e043efe38a3da3ee8","order_source":"orderbook","orders_submitted":0,"presentation":{"amount":"4.034022","amount_traded":"0","microtimestamp":"1787932601763000","price":"2478.91"},"previous_record_hash":"7e894df54d58bfe15e25e00ce58037911e963b638d3b7a0fbc91e6a132638812","profit_assessment":null,"record_hash":"322c8d5c179f9f33b94f598779a35363bbde22999313cba8451c65623eda531e","recorded_unix_us":1787932601876431,"recorded_utc":"2026-08-28T15:56:41.876431Z","schema_version":"nrrf810.exchange_authored_interactive_closure.v1","source_chain_continuous":true,"source_event":"order_created","source_event_id":"00065a1d-7f9c-44b8-0001-001200000020","source_event_id_unique":true,"source_pre_event_id":"00065a1d-7f9c-44b8-0000-001203000020","translation":"UNFOLD_TO_INF","unfold_event_id":null,"zero_hair":false}
{"channel":"live_orders_btcusd","interaction_index":322,"natural_form":{"channel":"live_orders_btcusd","order_id":"2044303880630275","order_subtype":5,"order_type":1},"natural_form_sha256":"c9ac80af8ec8136d6625201af7f3fc054ca634ba167b194268d2e80591e649da","order_source":"orderbook","orders_submitted":0,"presentation":{"amount":"0.06310787","amount_traded":"0","microtimestamp":"1787932601764000","price":"78520.16"},"previous_record_hash":"322c8d5c179f9f33b94f598779a35363bbde22999313cba8451c65623eda531e","profit_assessment":null,"record_hash":"b057b439f6d932398743e009366b98c49f2e381bd15a3e9930f3315d2210ac68","recorded_unix_us":1787932601876543,"recorded_utc":"2026-08-28T15:56:41.876543Z","schema_version":"nrrf810.exchange_authored_interactive_closure.v1","source_chain_continuous":true,"source_event":"order_created","source_event_id":"00065a1d-7f9c-48a0-0000-000100000020","source_event_id_unique":true,"source_pre_event_id":"00065a1d-7f9c-3130-0000-000103000020","translation":"UNFOLD_TO_INF","unfold_event_id":null,"zero_hair":false}
{"channel":"live_orders_btcusd","interaction_index":323,"natural_form":{"channel":"live_orders_btcusd","order_id":"2044303880630275","order_subtype":5,"order_type":1},"natural_form_sha256":"c9ac80af8ec8136d6625201af7f3fc054ca634ba167b194268d2e80591e649da","order_source":"orderbook","orders_submitted":0,"presentation":{"amount":"0.06310787","amount_traded":"0","microtimestamp":"1787932601764000","price":"78520.16"},"previous_record_hash":"b057b439f6d932398743e009366b98c49f2e381bd15a3e9930f3315d2210ac68","profit_assessment":null,"record_hash":"35e2d4fbc7a508971c1242d9c14a8c6ba463fea3e22f56c937be34d68f4d6f5b","recorded_unix_us":1787932601876565,"recorded_utc":"2026-08-28T15:56:41.876565Z","schema_version":"nrrf810.exchange_authored_interactive_closure.v1","source_chain_continuous":true,"source_event":"order_deleted","source_event_id":"00065a1d-7f9c-48a0-0001-000101000020","source_event_id_unique":true,"source_pre_event_id":"00065a1d-7f9c-48a0-0000-000100000020","translation":"FOLD_RETURN_TO_ZERO","unfold_event_id":"00065a1d-7f9c-48a0-0000-000100000020","zero_hair":true}
{"channel":"live_orders_ethusd","interaction_index":324,"natural_form":{"channel":"live_orders_ethusd","order_id":"2044303880634375","order_subtype":5,"order_type":0},"natural_form_sha256":"c102fffda3100ea78422ef44f88b47c1db2e1d0a1d957e740213bdc0209d53c8","order_source":"orderbook","orders_submitted":0,"presentation":{"amount":"5.000000","amount_traded":"0","microtimestamp":"1787932601766000","price":"2480.77"},"previous_record_hash":"35e2d4fbc7a508971c1242d9c14a8c6ba463fea3e22f56c937be34d68f4d6f5b","profit_assessment":null,"record_hash":"a759c8bf402d07de6b9fa67e881d3a361c55f49f539ca44a91e45e0032735224","recorded_unix_us":1787932601876648,"recorded_utc":"2026-08-28T15:56:41.876648Z","schema_version":"nrrf810.exchange_authored_interactive_closure.v1","source_chain_continuous":true,"source_event":"order_created","source_event_id":"00065a1d-7f9c-5070-0000-001201000020","source_event_id_unique":true,"source_pre_event_id":"00065a1d-7f9c-44b8-0001-001200000020","translation":"UNFOLD_TO_INF","unfold_event_id":null,"zero_hair":false}
{"channel":"live_orders_btcusd","interaction_index":325,"natural_form":{"channel":"live_orders_btcusd","order_id":"2044303880634380","order_subtype":5,"order_type":1},"natural_form_sha256":"988458b9ce796c42c8d9685963655a887f2a4a3457300d679c2c23def283db65","order_source":"orderbook","orders_submitted":0,"presentation":{"amount":"0.06310787","amount_traded":"0","microtimestamp":"1787932601766000","price":"78522.52"},"previous_record_hash":"a759c8bf402d07de6b9fa67e881d3a361c55f49f539ca44a91e45e0032735224","profit_assessment":null,"record_hash":"52253fdc0cefd740420062cbe06a1e3e9633823441503c801ef539e7f84a923b","recorded_unix_us":1787932601876732,"recorded_utc":"2026-08-28T15:56:41.876732Z","schema_version":"nrrf810.exchange_authored_interactive_closure.v1","source_chain_continuous":true,"source_event":"order_created","source_event_id":"00065a1d-7f9c-5070-0000-000102000020","source_event_id_unique":true,"source_pre_event_id":"00065a1d-7f9c-48a0-0001-000101000020","translation":"UNFOLD_TO_INF","unfold_event_id":null,"zero_hair":false}
{"channel":"live_orders_btcusd","interaction_index":326,"natural_form":{"channel":"live_orders_btcusd","order_id":"2044303880634380","order_subtype":5,"order_type":1},"natural_form_sha256":"988458b9ce796c42c8d9685963655a887f2a4a3457300d679c2c23def283db65","order_source":"orderbook","orders_submitted":0,"presentation":{"amount":"0.06310787","amount_traded":"0","microtimestamp":"1787932601766000","price":"78522.52"},"previous_record_hash":"52253fdc0cefd740420062cbe06a1e3e9633823441503c801ef539e7f84a923b","profit_assessment":null,"record_hash":"037c5980ea9f3f19eb12020e13bc3b76b9f94a73c2e7ce74e5bb64c6de345957","recorded_unix_us":1787932601876756,"recorded_utc":"2026-08-28T15:56:41.876756Z","schema_version":"nrrf810.exchange_authored_interactive_closure.v1","source_chain_continuous":true,"source_event":"order_deleted","source_event_id":"00065a1d-7f9c-5070-0001-000103000020","source_event_id_unique":true,"source_pre_event_id":"00065a1d-7f9c-5070-0000-000102000020","translation":"FOLD_RETURN_TO_ZERO","unfold_event_id":"00065a1d-7f9c-5070-0000-000102000020","zero_hair":true}
{"channel":"live_orders_ethusd","interaction_index":327,"natural_form":{"channel":"live_orders_ethusd","order_id":"2044303880155139","order_subtype":5,"order_type":1},"natural_form_sha256":"61bdb6df5db13871e01ebea08a7d20dcbc2f7c9156b7792c39f210215d71c6b3","order_source":"orderbook","orders_submitted":0,"presentation":{"amount":"5.000000","amount_traded":"0","microtimestamp":"1787932601770000","price":"2481.48"},"previous_record_hash":"037c5980ea9f3f19eb12020e13bc3b76b9f94a73c2e7ce74e5bb64c6de345957","profit_assessment":null,"record_hash":"5098b3d2fb608e390d5983c92d3ccd8d9473d89ee57a2960419a68e57756c6ef","recorded_unix_us":1787932601876835,"recorded_utc":"2026-08-28T15:56:41.876835Z","schema_version":"nrrf810.exchange_authored_interactive_closure.v1","source_chain_continuous":true,"source_event":"order_deleted","source_event_id":"00065a1d-7f9c-6010-0000-001202000020","source_event_id_unique":true,"source_pre_event_id":"00065a1d-7f9c-5070-0000-001201000020","translation":"FOLD_RETURN_TO_ZERO","unfold_event_id":"00065a1d-7f9a-8380-0000-001200000020","zero_hair":true}
{"channel":"live_orders_ethusd","interaction_index":328,"natural_form":{"channel":"live_orders_ethusd","order_id":"2044303878246406","order_subtype":5,"order_type":1},"natural_form_sha256":"cdd01c75bebe5242621802a88aa166c7f0240efd94ccb81b50ceae1c56d963e9","order_source":"orderbook","orders_submitted":0,"presentation":{"amount":"6.000000","amount_traded":"0","microtimestamp":"1787932601770000","price":"2482.48"},"previous_record_hash":"5098b3d2fb608e390d5983c92d3ccd8d9473d89ee57a2960419a68e57756c6ef","profit_assessment":null,"record_hash":"5ec65913ef0fe5ffed0863b51147b27fb82f3aae570c74b0718d8d8b058462e3","recorded_unix_us":1787932601876939,"recorded_utc":"2026-08-28T15:56:41.876939Z","schema_version":"nrrf810.exchange_authored_interactive_closure.v1","source_chain_continuous":true,"source_event":"order_deleted","source_event_id":"00065a1d-7f9c-6010-0001-001203000020","source_event_id_unique":true,"source_pre_event_id":"00065a1d-7f9c-6010-0000-001202000020","translation":"FOLD_RETURN_TO_ZERO","unfold_event_id":"00065a1d-7f93-6b18-0000-001200000020","zero_hair":true}
{"channel":"live_orders_ethusd","interaction_index":329,"natural_form":{"channel":"live_orders_ethusd","order_id":"2044303876861955","order_subtype":5,"order_type":1},"natural_form_sha256":"d438195e6d1d6872317fd8ef4ade912abed8e56eb5f253cc7a5f4859766aaffb","order_source":"orderbook","orders_submitted":0,"presentation":{"amount":"0.042001","amount_traded":"0","microtimestamp":"1787932601778000","price":"2480.82"},"previous_record_hash":"5ec65913ef0fe5ffed0863b51147b27fb82f3aae570c74b0718d8d8b058462e3","profit_assessment":null,"record_hash":"fc005458bd75c746360a4a6e6c60c14c395e9ad60b2b15a2ae8cd08c87eb59c9","recorded_unix_us":1787932601876961,"recorded_utc":"2026-08-28T15:56:41.876961Z","schema_version":"nrrf810.exchange_authored_interactive_closure.v1","source_chain_continuous":true,"source_event":"order_deleted","source_event_id":"00065a1d-7f9c-7f50-0000-001200000020","source_event_id_unique":true,"source_pre_event_id":"00065a1d-7f9c-6010-0001-001203000020","translation":"PARTIAL_PRIOR_UNFOLD","unfold_event_id":null,"zero_hair":false}
{"channel":"live_orders_btcusd","interaction_index":330,"natural_form":{"channel":"live_orders_btcusd","order_id":"2044303880699904","order_subtype":5,"order_type":1},"natural_form_sha256":"2ec30da9e15b6a783a4873c92dd5b29d291a9c871df3e8e025383423cff99e45","order_source":"orderbook","orders_submitted":0,"presentation":{"amount":"0.10000000","amount_traded":"0","microtimestamp":"1787932601781000","price":"78522.62"},"previous_record_hash":"fc005458bd75c746360a4a6e6c60c14c395e9ad60b2b15a2ae8cd08c87eb59c9","profit_assessment":null,"record_hash":"9ed2134335e5f0a1360743f26657213317add3371b686d0fe993dcc1b21336f9","recorded_unix_us":1787932601877054,"recorded_utc":"2026-08-28T15:56:41.877054Z","schema_version":"nrrf810.exchange_authored_interactive_closure.v1","source_chain_continuous":true,"source_event":"order_created","source_event_id":"00065a1d-7f9c-8b08-0000-000100000020","source_event_id_unique":true,"source_pre_event_id":"00065a1d-7f9c-5070-0001-000103000020","translation":"UNFOLD_TO_INF","unfold_event_id":null,"zero_hair":false}
{"channel":"live_orders_btcusd","interaction_index":331,"natural_form":{"channel":"live_orders_btcusd","order_id":"2044303880699904","order_subtype":5,"order_type":1},"natural_form_sha256":"2ec30da9e15b6a783a4873c92dd5b29d291a9c871df3e8e025383423cff99e45","order_source":"orderbook","orders_submitted":0,"presentation":{"amount":"0.10000000","amount_traded":"0","microtimestamp":"1787932601781000","price":"78522.62"},"previous_record_hash":"9ed2134335e5f0a1360743f26657213317add3371b686d0fe993dcc1b21336f9","profit_assessment":null,"record_hash":"c87b7b12c0d3ef5930837374d0a005738480da10f051e5295d036989f0fac67b","recorded_unix_us":1787932601877078,"recorded_utc":"2026-08-28T15:56:41.877078Z","schema_version":"nrrf810.exchange_authored_interactive_closure.v1","source_chain_continuous":true,"source_event":"order_deleted","source_event_id":"00065a1d-7f9c-8b08-0001-000101000020","source_event_id_unique":true,"source_pre_event_id":"00065a1d-7f9c-8b08-0000-000100000020","translation":"FOLD_RETURN_TO_ZERO","unfold_event_id":"00065a1d-7f9c-8b08-0000-000100000020","zero_hair":true}
{"channel":"live_orders_ethusd","interaction_index":332,"natural_form":{"channel":"live_orders_ethusd","order_id":"2044303880699914","order_subtype":5,"order_type":1},"natural_form_sha256":"32efaac14d67225286ad4834aa8c4eb304c5da0ed16b0900894941e64fa7837f","order_source":"orderbook","orders_submitted":0,"presentation":{"amount":"12.088820","amount_traded":"0","microtimestamp":"1787932601782000","price":"2481.64"},"previous_record_hash":"c87b7b12c0d3ef5930837374d0a005738480da10f051e5295d036989f0fac67b","profit_assessment":null,"record_hash":"dfe57339100fa2b4de2f4d1ca2f2a751f95b3c95afc61712623dbd16137b208a","recorded_unix_us":1787932601877195,"recorded_utc":"2026-08-28T15:56:41.877195Z","schema_version":"nrrf810.exchange_authored_interactive_closure.v1","source_chain_continuous":true,"source_event":"order_created","source_event_id":"00065a1d-7f9c-8ef0-0000-001201000020","source_event_id_unique":true,"source_pre_event_id":"00065a1d-7f9c-7f50-0000-001200000020","translation":"UNFOLD_TO_INF","unfold_event_id":null,"zero_hair":false}
{"channel":"live_orders_ethusd","interaction_index":333,"natural_form":{"channel":"live_orders_ethusd","order_id":"2044303880699915","order_subtype":5,"order_type":0},"natural_form_sha256":"c2e6bc33a47eaf768162261888c517e383ea183fd72a7de71e93e98db250246e","order_source":"orderbook","orders_submitted":0,"presentation":{"amount":"0.041163","amount_traded":"0","microtimestamp":"1787932601782000","price":"2480.68"},"previous_record_hash":"dfe57339100fa2b4de2f4d1ca2f2a751f95b3c95afc61712623dbd16137b208a","profit_assessment":null,"record_hash":"32887ce72cbb8baced3775e7609e23d4fb64db73a01d380ee4b18ae1058d8b00","recorded_unix_us":1787932601877218,"recorded_utc":"2026-08-28T15:56:41.877218Z","schema_version":"nrrf810.exchange_authored_interactive_closure.v1","source_chain_continuous":true,"source_event":"order_created","source_event_id":"00065a1d-7f9c-8ef0-0001-001202000020","source_event_id_unique":true,"source_pre_event_id":"00065a1d-7f9c-8ef0-0000-001201000020","translation":"UNFOLD_TO_INF","unfold_event_id":null,"zero_hair":false}
{"channel":"live_orders_ethusd","interaction_index":334,"natural_form":{"channel":"live_orders_ethusd","order_id":"2044303880704004","order_subtype":5,"order_type":0},"natural_form_sha256":"4458886dd9443b555fdfac4bd3644e01bb4925950877db8692c88767a8f2fce0","order_source":"orderbook","orders_submitted":0,"presentation":{"amount":"5.000000","amount_traded":"0","microtimestamp":"1787932601782000","price":"2479.95"},"previous_record_hash":"32887ce72cbb8baced3775e7609e23d4fb64db73a01d380ee4b18ae1058d8b00","profit_assessment":null,"record_hash":"3a2c6b9578f799b30402e683baab64c6cac15c7cf0555351f81e60494f0f21e1","recorded_unix_us":1787932601877287,"recorded_utc":"2026-08-28T15:56:41.877287Z","schema_version":"nrrf810.exchange_authored_interactive_closure.v1","source_chain_continuous":true,"source_event":"order_created","source_event_id":"00065a1d-7f9c-8ef0-0002-001203000020","source_event_id_unique":true,"source_pre_event_id":"00065a1d-7f9c-8ef0-0001-001202000020","translation":"UNFOLD_TO_INF","unfold_event_id":null,"zero_hair":false}
{"channel":"live_orders_ethusd","interaction_index":335,"natural_form":{"channel":"live_orders_ethusd","order_id":"2044303880704008","order_subtype":5,"order_type":1},"natural_form_sha256":"7f7942d7018731d1e7d7091c0e8cd6a20a70d54d7ef7aa21f379433d931b151b","order_source":"orderbook","orders_submitted":0,"presentation":{"amount":"12.087458","amount_traded":"0","microtimestamp":"1787932601783000","price":"2481.92"},"previous_record_hash":"3a2c6b9578f799b30402e683baab64c6cac15c7cf0555351f81e60494f0f21e1","profit_assessment":null,"record_hash":"0c6548ce50aad141f49da6cef15b53607d2dc596fb10b3ee1545cd92d818ea89","recorded_unix_us":1787932601877410,"recorded_utc":"2026-08-28T15:56:41.877410Z","schema_version":"nrrf810.exchange_authored_interactive_closure.v1","source_chain_continuous":true,"source_event":"order_created","source_event_id":"00065a1d-7f9c-92d8-0000-001200000020","source_event_id_unique":true,"source_pre_event_id":"00065a1d-7f9c-8ef0-0002-001203000020","translation":"UNFOLD_TO_INF","unfold_event_id":null,"zero_hair":false}
{"channel":"live_orders_ethusd","interaction_index":336,"natural_form":{"channel":"live_orders_ethusd","order_id":"2044303880716294","order_subtype":5,"order_type":0},"natural_form_sha256":"f875c707cc24f9d6ad3fbcc080f448a02717164dcc1f2dba5026c9de8bb1453d","order_source":"orderbook","orders_submitted":0,"presentation":{"amount":"6.000000","amount_traded":"0","microtimestamp":"1787932601786000","price":"2479.70"},"previous_record_hash":"0c6548ce50aad141f49da6cef15b53607d2dc596fb10b3ee1545cd92d818ea89","profit_assessment":null,"record_hash":"8b6ab0829d71330d95931349cc2f785e0afae4cfc4e076ccc7a00bae91bd0ea8","recorded_unix_us":1787932601877432,"recorded_utc":"2026-08-28T15:56:41.877432Z","schema_version":"nrrf810.exchange_authored_interactive_closure.v1","source_chain_continuous":true,"source_event":"order_created","source_event_id":"00065a1d-7f9c-9e90-0000-001201000020","source_event_id_unique":true,"source_pre_event_id":"00065a1d-7f9c-92d8-0000-001200000020","translation":"UNFOLD_TO_INF","unfold_event_id":null,"zero_hair":false}
{"channel":"live_orders_btcusd","interaction_index":337,"natural_form":{"channel":"live_orders_btcusd","order_id":"2044303878279172","order_subtype":5,"order_type":0},"natural_form_sha256":"6d706412054707e096890d565cd6ef6247f285cc955adfbf8f645f4b1058641f","order_source":"orderbook","orders_submitted":0,"presentation":{"amount":"0.63679790","amount_traded":"0","microtimestamp":"1787932601786000","price":"78480.38"},"previous_record_hash":"8b6ab0829d71330d95931349cc2f785e0afae4cfc4e076ccc7a00bae91bd0ea8","profit_assessment":null,"record_hash":"5ef7c2d76e4ba4d15bf8fb798cc9d547f8a97f986d4cdfb67462091120d1dbb1","recorded_unix_us":1787932601877549,"recorded_utc":"2026-08-28T15:56:41.877549Z","schema_version":"nrrf810.exchange_authored_interactive_closure.v1","source_chain_continuous":true,"source_event":"order_deleted","source_event_id":"00065a1d-7f9c-9e90-0000-000102000020","source_event_id_unique":true,"source_pre_event_id":"00065a1d-7f9c-8b08-0001-000101000020","translation":"FOLD_RETURN_TO_ZERO","unfold_event_id":"00065a1d-7f93-8670-0000-000100000020","zero_hair":true}
{"channel":"live_orders_btcusd","interaction_index":338,"natural_form":{"channel":"live_orders_btcusd","order_id":"2044303878283264","order_subtype":5,"order_type":0},"natural_form_sha256":"f7e06971054d5f66b74303984b3e58b2e75f7c2955003d188da8e71a501d36d1","order_source":"orderbook","orders_submitted":0,"presentation":{"amount":"0.50943832","amount_traded":"0","microtimestamp":"1787932601787000","price":"78478.42"},"previous_record_hash":"5ef7c2d76e4ba4d15bf8fb798cc9d547f8a97f986d4cdfb67462091120d1dbb1","profit_assessment":null,"record_hash":"d1599008e8331b43e13b173425ec766af2464fdfb4e0f4cbf1bbf26bf095ad1f","recorded_unix_us":1787932601877573,"recorded_utc":"2026-08-28T15:56:41.877573Z","schema_version":"nrrf810.exchange_authored_interactive_closure.v1","source_chain_continuous":true,"source_event":"order_deleted","source_event_id":"00065a1d-7f9c-a278-0000-000103000020","source_event_id_unique":true,"source_pre_event_id":"00065a1d-7f9c-9e90-0000-000102000020","translation":"FOLD_RETURN_TO_ZERO","unfold_event_id":"00065a1d-7f93-8a58-0000-000101000020","zero_hair":true}
{"channel":"live_orders_ethusd","interaction_index":339,"natural_form":{"channel":"live_orders_ethusd","order_id":"2044303880724484","order_subtype":5,"order_type":1},"natural_form_sha256":"7dbb03934c0e3605cbc047891169b3914f12fed1c04b7df7aacfc5de22bb878c","order_source":"orderbook","orders_submitted":0,"presentation":{"amount":"4.028874","amount_traded":"0","microtimestamp":"1787932601787000","price":"2482.09"},"previous_record_hash":"d1599008e8331b43e13b173425ec766af2464fdfb4e0f4cbf1bbf26bf095ad1f","profit_assessment":null,"record_hash":"ef97be2e47e766b76624d0524e0150d4a154abd10273cebc287c47524cc29ebe","recorded_unix_us":1787932601877684,"recorded_utc":"2026-08-28T15:56:41.877684Z","schema_version":"nrrf810.exchange_authored_interactive_closure.v1","source_chain_continuous":true,"source_event":"order_created","source_event_id":"00065a1d-7f9c-a278-0000-001202000020","source_event_id_unique":true,"source_pre_event_id":"00065a1d-7f9c-9e90-0000-001201000020","translation":"UNFOLD_TO_INF","unfold_event_id":null,"zero_hair":false}
{"channel":"live_orders_ethusd","interaction_index":340,"natural_form":{"channel":"live_orders_ethusd","order_id":"2044303880728576","order_subtype":5,"order_type":1},"natural_form_sha256":"70169ba87056285c91118d507920bdfb8410e9a9d633a811d8d7481e31f48b8c","order_source":"orderbook","orders_submitted":0,"presentation":{"amount":"10.057184","amount_traded":"0","microtimestamp":"1787932601788000","price":"2485.79"},"previous_record_hash":"ef97be2e47e766b76624d0524e0150d4a154abd10273cebc287c47524cc29ebe","profit_assessment":null,"record_hash":"dce1165b169e5facefe65d61b484568b99fb745a2b00d638afba0909705cad21","recorded_unix_us":1787932601877745,"recorded_utc":"2026-08-28T15:56:41.877745Z","schema_version":"nrrf810.exchange_authored_interactive_closure.v1","source_chain_continuous":true,"source_event":"order_created","source_event_id":"00065a1d-7f9c-a660-0000-001203000020","source_event_id_unique":true,"source_pre_event_id":"00065a1d-7f9c-a278-0000-001202000020","translation":"UNFOLD_TO_INF","unfold_event_id":null,"zero_hair":false}
{"channel":"live_orders_ethusd","interaction_index":341,"natural_form":{"channel":"live_orders_ethusd","order_id":"2044303880728580","order_subtype":5,"order_type":1},"natural_form_sha256":"cfe76a8daf3b16b06c46c0de38dd4562474c8beed479c2662c0732b9ebe5d684","order_source":"orderbook","orders_submitted":0,"presentation":{"amount":"10.065070","amount_traded":"0","microtimestamp":"1787932601789000","price":"2483.84"},"previous_record_hash":"dce1165b169e5facefe65d61b484568b99fb745a2b00d638afba0909705cad21","profit_assessment":null,"record_hash":"f3c8cbd034f7a4c4108e53e566b7b88853963bb8f99fd981d77f9e9e5ffa12ff","recorded_unix_us":1787932601877769,"recorded_utc":"2026-08-28T15:56:41.877769Z","schema_version":"nrrf810.exchange_authored_interactive_closure.v1","source_chain_continuous":true,"source_event":"order_created","source_event_id":"00065a1d-7f9c-aa48-0000-001200000020","source_event_id_unique":true,"source_pre_event_id":"00065a1d-7f9c-a660-0000-001203000020","translation":"UNFOLD_TO_INF","unfold_event_id":null,"zero_hair":false}
{"channel":"live_orders_ethusd","interaction_index":342,"natural_form":{"channel":"live_orders_ethusd","order_id":"2044303880728581","order_subtype":5,"order_type":1},"natural_form_sha256":"7900d392b9e9a89fdfcda86c730071f194e24ea07efbb7a0bbd16096dadba4d9","order_source":"orderbook","orders_submitted":0,"presentation":{"amount":"20.097242","amount_traded":"0","microtimestamp":"1787932601789000","price":"2487.91"},"previous_record_hash":"f3c8cbd034f7a4c4108e53e566b7b88853963bb8f99fd981d77f9e9e5ffa12ff","profit_assessment":null,"record_hash":"02e82d880b0019320adf93850b0761ace1d67c9900625441a538b4ba412a87c8","recorded_unix_us":1787932601877881,"recorded_utc":"2026-08-28T15:56:41.877881Z","schema_version":"nrrf810.exchange_authored_interactive_closure.v1","source_chain_continuous":true,"source_event":"order_created","source_event_id":"00065a1d-7f9c-aa48-0001-001201000020","source_event_id_unique":true,"source_pre_event_id":"00065a1d-7f9c-aa48-0000-001200000020","translation":"UNFOLD_TO_INF","unfold_event_id":null,"zero_hair":false}
{"channel":"live_orders_ethusd","interaction_index":343,"natural_form":{"channel":"live_orders_ethusd","order_id":"2044303880732678","order_subtype":5,"order_type":1},"natural_form_sha256":"156934d00a20142a8337942bf031212ac508d883774aed9ca91a0ef74b408a62","order_source":"orderbook","orders_submitted":0,"presentation":{"amount":"20.088574","amount_traded":"0","microtimestamp":"1787932601789000","price":"2488.98"},"previous_record_hash":"02e82d880b0019320adf93850b0761ace1d67c9900625441a538b4ba412a87c8","profit_assessment":null,"record_hash":"1a52d6261b13a2884145a7c6327c540a7251752f046e1704e51692d8d9bd5cd6","recorded_unix_us":1787932601877904,"recorded_utc":"2026-08-28T15:56:41.877904Z","schema_version":"nrrf810.exchange_authored_interactive_closure.v1","source_chain_continuous":true,"source_event":"order_created","source_event_id":"00065a1d-7f9c-aa48-0002-001202000020","source_event_id_unique":true,"source_pre_event_id":"00065a1d-7f9c-aa48-0001-001201000020","translation":"UNFOLD_TO_INF","unfold_event_id":null,"zero_hair":false}
{"channel":"live_orders_ethusd","interaction_index":344,"natural_form":{"channel":"live_orders_ethusd","order_id":"2044303879569410","order_subtype":5,"order_type":0},"natural_form_sha256":"51efc4c71e43c0a35d89de80a583f162f3d9372e5bcd85adaf733ba7d19e437a","order_source":"orderbook","orders_submitted":0,"presentation":{"amount":"0.403104","amount_traded":"0","microtimestamp":"1787932601791000","price":"2479.66"},"previous_record_hash":"1a52d6261b13a2884145a7c6327c540a7251752f046e1704e51692d8d9bd5cd6","profit_assessment":null,"record_hash":"53fd22c81e0a7d87cc06f1ec6a1d923099373d2b1f40721be47733bd5c8290a9","recorded_unix_us":1787932601878015,"recorded_utc":"2026-08-28T15:56:41.878015Z","schema_version":"nrrf810.exchange_authored_interactive_closure.v1","source_chain_continuous":true,"source_event":"order_deleted","source_event_id":"00065a1d-7f9c-b218-0000-001203000020","source_event_id_unique":true,"source_pre_event_id":"00065a1d-7f9c-aa48-0002-001202000020","translation":"FOLD_RETURN_TO_ZERO","unfold_event_id":"00065a1d-7f98-54e8-0000-001202000020","zero_hair":true}
{"channel":"live_orders_ethusd","interaction_index":345,"natural_form":{"channel":"live_orders_ethusd","order_id":"2044303880736780","order_subtype":5,"order_type":1},"natural_form_sha256":"95deb7c22b424eee170a30984e8aeb816a7b253437d7e662d44f2f9e9206dfec","order_source":"orderbook","orders_submitted":0,"presentation":{"amount":"39.969006","amount_traded":"0","microtimestamp":"1787932601791000","price":"2501.94"},"previous_record_hash":"53fd22c81e0a7d87cc06f1ec6a1d923099373d2b1f40721be47733bd5c8290a9","profit_assessment":null,"record_hash":"83ee3e68377e353e393d6d385cbc515de7102a397cce7e0fd46f5a8b27c21106","recorded_unix_us":1787932601878078,"recorded_utc":"2026-08-28T15:56:41.878078Z","schema_version":"nrrf810.exchange_authored_interactive_closure.v1","source_chain_continuous":true,"source_event":"order_created","source_event_id":"00065a1d-7f9c-b218-0001-001200000020","source_event_id_unique":true,"source_pre_event_id":"00065a1d-7f9c-b218-0000-001203000020","translation":"UNFOLD_TO_INF","unfold_event_id":null,"zero_hair":false}
{"channel":"live_orders_ethusd","interaction_index":346,"natural_form":{"channel":"live_orders_ethusd","order_id":"2044303880740872","order_subtype":5,"order_type":1},"natural_form_sha256":"aad563d3dfa91e35bc6394d0180921e8f6ab2af6ae8af6c8137abebab96029fd","order_source":"orderbook","orders_submitted":0,"presentation":{"amount":"40.092050","amount_traded":"0","microtimestamp":"1787932601792000","price":"2494.27"},"previous_record_hash":"83ee3e68377e353e393d6d385cbc515de7102a397cce7e0fd46f5a8b27c21106","profit_assessment":null,"record_hash":"66af5ba5ef3669be9c3aad7ad3a110d949cec791cfb4d2e737b8b8b90c5cea8e","recorded_unix_us":1787932601878117,"recorded_utc":"2026-08-28T15:56:41.878117Z","schema_version":"nrrf810.exchange_authored_interactive_closure.v1","source_chain_continuous":true,"source_event":"order_created","source_event_id":"00065a1d-7f9c-b600-0000-001201000020","source_event_id_unique":true,"source_pre_event_id":"00065a1d-7f9c-b218-0001-001200000020","translation":"UNFOLD_TO_INF","unfold_event_id":null,"zero_hair":false}
{"channel":"live_orders_ethusd","interaction_index":347,"natural_form":{"channel":"live_orders_ethusd","order_id":"2044303880744966","order_subtype":5,"order_type":0},"natural_form_sha256":"c4ae6be0dcdebe2db34f9f897612dc1488b8d509ac95d419e80c8ba7f64a4733","order_source":"orderbook","orders_submitted":0,"presentation":{"amount":"12.098474","amount_traded":"0","microtimestamp":"1787932601793000","price":"2479.65"},"previous_record_hash":"66af5ba5ef3669be9c3aad7ad3a110d949cec791cfb4d2e737b8b8b90c5cea8e","profit_assessment":null,"record_hash":"96ff61903a7b1dd84b89aeb0d51f4e42530fcdcb071e55ac255df6e86593024c","recorded_unix_us":1787932601878227,"recorded_utc":"2026-08-28T15:56:41.878227Z","schema_version":"nrrf810.exchange_authored_interactive_closure.v1","source_chain_continuous":true,"source_event":"order_created","source_event_id":"00065a1d-7f9c-b9e8-0000-001202000020","source_event_id_unique":true,"source_pre_event_id":"00065a1d-7f9c-b600-0000-001201000020","translation":"UNFOLD_TO_INF","unfold_event_id":null,"zero_hair":false}
{"channel":"live_orders_ethusd","interaction_index":348,"natural_form":{"channel":"live_orders_ethusd","order_id":"2044303880749056","order_subtype":5,"order_type":0},"natural_form_sha256":"29d3de6c68cf788928c9d280a25647aaf2041d9e1e0553d5bf10c441889ef540","order_source":"orderbook","orders_submitted":0,"presentation":{"amount":"12.096906","amount_traded":"0","microtimestamp":"1787932601793000","price":"2479.97"},"previous_record_hash":"96ff61903a7b1dd84b89aeb0d51f4e42530fcdcb071e55ac255df6e86593024c","profit_assessment":null,"record_hash":"6558d7c62b5a871d3de1973f3d1bc5d6fa2314a706181c7877201f0b881c5b33","recorded_unix_us":1787932601878289,"recorded_utc":"2026-08-28T15:56:41.878289Z","schema_version":"nrrf810.exchange_authored_interactive_closure.v1","source_chain_continuous":true,"source_event":"order_created","source_event_id":"00065a1d-7f9c-b9e8-0001-001203000020","source_event_id_unique":true,"source_pre_event_id":"00065a1d-7f9c-b9e8-0000-001202000020","translation":"UNFOLD_TO_INF","unfold_event_id":null,"zero_hair":false}
{"channel":"live_orders_ethusd","interaction_index":349,"natural_form":{"channel":"live_orders_ethusd","order_id":"2044303880753154","order_subtype":5,"order_type":0},"natural_form_sha256":"e56de15aebb8927c38ca1a8868066f521e3d0b574dee795edb483ec968a9a36a","order_source":"orderbook","orders_submitted":0,"presentation":{"amount":"10.095101","amount_traded":"0","microtimestamp":"1787932601794000","price":"2476.44"},"previous_record_hash":"6558d7c62b5a871d3de1973f3d1bc5d6fa2314a706181c7877201f0b881c5b33","profit_assessment":null,"record_hash":"c5454ad0ebf6c3caf36834f8d340cbea6b5716d73df95da1082e0b38e540b112","recorded_unix_us":1787932601878311,"recorded_utc":"2026-08-28T15:56:41.878311Z","schema_version":"nrrf810.exchange_authored_interactive_closure.v1","source_chain_continuous":true,"source_event":"order_created","source_event_id":"00065a1d-7f9c-bdd0-0000-001200000020","source_event_id_unique":true,"source_pre_event_id":"00065a1d-7f9c-b9e8-0001-001203000020","translation":"UNFOLD_TO_INF","unfold_event_id":null,"zero_hair":false}
{"channel":"live_orders_btcusd","interaction_index":350,"natural_form":{"channel":"live_orders_btcusd","order_id":"2044303880753152","order_subtype":5,"order_type":1},"natural_form_sha256":"2f72aa3793ef8a25ceb3e7d5f7780499afba34b12fab25a4394fbf0258f3a529","order_source":"orderbook","orders_submitted":0,"presentation":{"amount":"0.10000000","amount_traded":"0","microtimestamp":"1787932601794000","price":"78522.63"},"previous_record_hash":"c5454ad0ebf6c3caf36834f8d340cbea6b5716d73df95da1082e0b38e540b112","profit_assessment":null,"record_hash":"2496a427f1f16e7a8a139ebef068ea6b694068e8d251da79306aadb3a11ed350","recorded_unix_us":1787932601878423,"recorded_utc":"2026-08-28T15:56:41.878423Z","schema_version":"nrrf810.exchange_authored_interactive_closure.v1","source_chain_continuous":true,"source_event":"order_created","source_event_id":"00065a1d-7f9c-bdd0-0000-000100000020","source_event_id_unique":true,"source_pre_event_id":"00065a1d-7f9c-a278-0000-000103000020","translation":"UNFOLD_TO_INF","unfold_event_id":null,"zero_hair":false}
{"channel":"live_orders_btcusd","interaction_index":351,"natural_form":{"channel":"live_orders_btcusd","order_id":"2044303880753152","order_subtype":5,"order_type":1},"natural_form_sha256":"2f72aa3793ef8a25ceb3e7d5f7780499afba34b12fab25a4394fbf0258f3a529","order_source":"orderbook","orders_submitted":0,"presentation":{"amount":"0.10000000","amount_traded":"0","microtimestamp":"1787932601794000","price":"78522.63"},"previous_record_hash":"2496a427f1f16e7a8a139ebef068ea6b694068e8d251da79306aadb3a11ed350","profit_assessment":null,"record_hash":"86b5be8ba28f85c2206e62db006540ed035570aa6841558f622144b13ab72b59","recorded_unix_us":1787932601878483,"recorded_utc":"2026-08-28T15:56:41.878483Z","schema_version":"nrrf810.exchange_authored_interactive_closure.v1","source_chain_continuous":true,"source_event":"order_deleted","source_event_id":"00065a1d-7f9c-bdd0-0001-000101000020","source_event_id_unique":true,"source_pre_event_id":"00065a1d-7f9c-bdd0-0000-000100000020","translation":"FOLD_RETURN_TO_ZERO","unfold_event_id":"00065a1d-7f9c-bdd0-0000-000100000020","zero_hair":true}
{"channel":"live_orders_ethusd","interaction_index":352,"natural_form":{"channel":"live_orders_ethusd","order_id":"2044303880753156","order_subtype":5,"order_type":0},"natural_form_sha256":"e384fac2a1b1e23f43d3d2eeebcc2f4d6a358a3c76c53aaaf96f7660885ea5c4","order_source":"orderbook","orders_submitted":0,"presentation":{"amount":"4.033204","amount_traded":"0","microtimestamp":"1787932601794000","price":"2479.41"},"previous_record_hash":"86b5be8ba28f85c2206e62db006540ed035570aa6841558f622144b13ab72b59","profit_assessment":null,"record_hash":"ab18ebc81370bc7ca928ac72ac352dad224071c27b69a883ea795f0662913b8a","recorded_unix_us":1787932601878506,"recorded_utc":"2026-08-28T15:56:41.878506Z","schema_version":"nrrf810.exchange_authored_interactive_closure.v1","source_chain_continuous":true,"source_event":"order_created","source_event_id":"00065a1d-7f9c-bdd0-0001-001201000020","source_event_id_unique":true,"source_pre_event_id":"00065a1d-7f9c-bdd0-0000-001200000020","translation":"UNFOLD_TO_INF","unfold_event_id":null,"zero_hair":false}
{"channel":"live_orders_btcusd","interaction_index":353,"natural_form":{"channel":"live_orders_btcusd","order_id":"2044303880753158","order_subtype":5,"order_type":1},"natural_form_sha256":"ba06685fc170e4ab9480a5a7c91da1232e5bcd8f96b074d0f80bbba5252377d3","order_source":"orderbook","orders_submitted":0,"presentation":{"amount":"0.06310787","amount_traded":"0","microtimestamp":"1787932601795000","price":"78520.18"},"previous_record_hash":"ab18ebc81370bc7ca928ac72ac352dad224071c27b69a883ea795f0662913b8a","profit_assessment":null,"record_hash":"27213fb622735aac491e6bc8d7bf13aa12981b14ff36f28547e26fd5a614ea2e","recorded_unix_us":1787932601878599,"recorded_utc":"2026-08-28T15:56:41.878599Z","schema_version":"nrrf810.exchange_authored_interactive_closure.v1","source_chain_continuous":true,"source_event":"order_created","source_event_id":"00065a1d-7f9c-c1b8-0000-000102000020","source_event_id_unique":true,"source_pre_event_id":"00065a1d-7f9c-bdd0-0001-000101000020","translation":"UNFOLD_TO_INF","unfold_event_id":null,"zero_hair":false}
{"channel":"live_orders_btcusd","interaction_index":354,"natural_form":{"channel":"live_orders_btcusd","order_id":"2044303880753158","order_subtype":5,"order_type":1},"natural_form_sha256":"ba06685fc170e4ab9480a5a7c91da1232e5bcd8f96b074d0f80bbba5252377d3","order_source":"orderbook","orders_submitted":0,"presentation":{"amount":"0.06310787","amount_traded":"0","microtimestamp":"1787932601795000","price":"78520.18"},"previous_record_hash":"27213fb622735aac491e6bc8d7bf13aa12981b14ff36f28547e26fd5a614ea2e","profit_assessment":null,"record_hash":"b7177b5eb6494c3ce4f14409a9298efb05564a913d7716c186a9ef2bee30b6fb","recorded_unix_us":1787932601878623,"recorded_utc":"2026-08-28T15:56:41.878623Z","schema_version":"nrrf810.exchange_authored_interactive_closure.v1","source_chain_continuous":true,"source_event":"order_deleted","source_event_id":"00065a1d-7f9c-c1b8-0001-000103000020","source_event_id_unique":true,"source_pre_event_id":"00065a1d-7f9c-c1b8-0000-000102000020","translation":"FOLD_RETURN_TO_ZERO","unfold_event_id":"00065a1d-7f9c-c1b8-0000-000102000020","zero_hair":true}
{"channel":"live_orders_ethusd","interaction_index":355,"natural_form":{"channel":"live_orders_ethusd","order_id":"2044303880753160","order_subtype":5,"order_type":0},"natural_form_sha256":"2e13a6bada2bcf44801adf1e1979d87fddc693a00c5aac2999aea3734728485a","order_source":"orderbook","orders_submitted":0,"presentation":{"amount":"10.090138","amount_traded":"0","microtimestamp":"1787932601795000","price":"2477.66"},"previous_record_hash":"b7177b5eb6494c3ce4f14409a9298efb05564a913d7716c186a9ef2bee30b6fb","profit_assessment":null,"record_hash":"6b99c0c2d702494f42077937c3e2028ae97e6b6d0dc7241a681e5170ad08c78d","recorded_unix_us":1787932601878718,"recorded_utc":"2026-08-28T15:56:41.878718Z","schema_version":"nrrf810.exchange_authored_interactive_closure.v1","source_chain_continuous":true,"source_event":"order_created","source_event_id":"00065a1d-7f9c-c1b8-0000-001202000020","source_event_id_unique":true,"source_pre_event_id":"00065a1d-7f9c-bdd0-0001-001201000020","translation":"UNFOLD_TO_INF","unfold_event_id":null,"zero_hair":false}
{"channel":"live_orders_ethusd","interaction_index":356,"natural_form":{"channel":"live_orders_ethusd","order_id":"2044303880753159","order_subtype":5,"order_type":0},"natural_form_sha256":"f1331951cb83acbcc42797c9e10ab7092eaeba1418585f6c629f2762614bbf32","order_source":"orderbook","orders_submitted":0,"presentation":{"amount":"20.204386","amount_traded":"0","microtimestamp":"1787932601795000","price":"2474.71"},"previous_record_hash":"6b99c0c2d702494f42077937c3e2028ae97e6b6d0dc7241a681e5170ad08c78d","profit_assessment":null,"record_hash":"c2597e79c81894bf3e22b6cadde70a7a18f6607959b5bd4de127684e783f3d5a","recorded_unix_us":1787932601878740,"recorded_utc":"2026-08-28T15:56:41.878740Z","schema_version":"nrrf810.exchange_authored_interactive_closure.v1","source_chain_continuous":true,"source_event":"order_created","source_event_id":"00065a1d-7f9c-c1b8-0001-001203000020","source_event_id_unique":true,"source_pre_event_id":"00065a1d-7f9c-c1b8-0000-001202000020","translation":"UNFOLD_TO_INF","unfold_event_id":null,"zero_hair":false}
{"channel":"live_orders_ethusd","interaction_index":357,"natural_form":{"channel":"live_orders_ethusd","order_id":"2044303880757250","order_subtype":5,"order_type":0},"natural_form_sha256":"cff8f30f6ce1e3a79be3fafb2a1fdf2dd393a3ae135e84b2626625dc821fccf9","order_source":"orderbook","orders_submitted":0,"presentation":{"amount":"4.033601","amount_traded":"0","microtimestamp":"1787932601795000","price":"2479.17"},"previous_record_hash":"c2597e79c81894bf3e22b6cadde70a7a18f6607959b5bd4de127684e783f3d5a","profit_assessment":null,"record_hash":"a9e01ed8ea8396f757cbbcf32d6435defbe3c8a4340970e9057a576977027dc9","recorded_unix_us":1787932601878851,"recorded_utc":"2026-08-28T15:56:41.878851Z","schema_version":"nrrf810.exchange_authored_interactive_closure.v1","source_chain_continuous":true,"source_event":"order_created","source_event_id":"00065a1d-7f9c-c1b8-0002-001200000020","source_event_id_unique":true,"source_pre_event_id":"00065a1d-7f9c-c1b8-0001-001203000020","translation":"UNFOLD_TO_INF","unfold_event_id":null,"zero_hair":false}
{"channel":"live_orders_btcusd","interaction_index":358,"natural_form":{"channel":"live_orders_btcusd","order_id":"2044303880761355","order_subtype":5,"order_type":1},"natural_form_sha256":"1efa180e7a8139c842f3dd5a0ad6768ec10fa4d4d8411fcfc4c553d7f3d92b5f","order_source":"orderbook","orders_submitted":0,"presentation":{"amount":"0.06310787","amount_traded":"0","microtimestamp":"1787932601796000","price":"78522.54"},"previous_record_hash":"a9e01ed8ea8396f757cbbcf32d6435defbe3c8a4340970e9057a576977027dc9","profit_assessment":null,"record_hash":"aa5b563b407ac2b3cf50ad7c359e761d0ec3a4337e06dff93818d0f932025887","recorded_unix_us":1787932601878913,"recorded_utc":"2026-08-28T15:56:41.878913Z","schema_version":"nrrf810.exchange_authored_interactive_closure.v1","source_chain_continuous":true,"source_event":"order_created","source_event_id":"00065a1d-7f9c-c5a0-0000-000100000020","source_event_id_unique":true,"source_pre_event_id":"00065a1d-7f9c-c1b8-0001-000103000020","translation":"UNFOLD_TO_INF","unfold_event_id":null,"zero_hair":false}
{"channel":"live_orders_btcusd","interaction_index":359,"natural_form":{"channel":"live_orders_btcusd","order_id":"2044303880761355","order_subtype":5,"order_type":1},"natural_form_sha256":"1efa180e7a8139c842f3dd5a0ad6768ec10fa4d4d8411fcfc4c553d7f3d92b5f","order_source":"orderbook","orders_submitted":0,"presentation":{"amount":"0.06310787","amount_traded":"0","microtimestamp":"1787932601796000","price":"78522.54"},"previous_record_hash":"aa5b563b407ac2b3cf50ad7c359e761d0ec3a4337e06dff93818d0f932025887","profit_assessment":null,"record_hash":"1d2d960e787b419ad49088621cf8bff71d42e07c2ac940ee126081bda04bbe4e","recorded_unix_us":1787932601878936,"recorded_utc":"2026-08-28T15:56:41.878936Z","schema_version":"nrrf810.exchange_authored_interactive_closure.v1","source_chain_continuous":true,"source_event":"order_deleted","source_event_id":"00065a1d-7f9c-c5a0-0001-000101000020","source_event_id_unique":true,"source_pre_event_id":"00065a1d-7f9c-c5a0-0000-000100000020","translation":"FOLD_RETURN_TO_ZERO","unfold_event_id":"00065a1d-7f9c-c5a0-0000-000100000020","zero_hair":true}
{"channel":"live_orders_btcusd","interaction_index":360,"natural_form":{"channel":"live_orders_btcusd","order_id":"2044303880765442","order_subtype":5,"order_type":0},"natural_form_sha256":"9d0415b8be6b967cc5ff42fcf599c127a4d73d20a88aea502d8998ebdb759eb9","order_source":"orderbook","orders_submitted":0,"presentation":{"amount":"0.50943592","amount_traded":"0","microtimestamp":"1787932601797000","price":"78479.72"},"previous_record_hash":"1d2d960e787b419ad49088621cf8bff71d42e07c2ac940ee126081bda04bbe4e","profit_assessment":null,"record_hash":"fa0b0edc4e44b83f5f458bb167cfa0723e23b521f768fe813a810e54d85b7f87","recorded_unix_us":1787932601879048,"recorded_utc":"2026-08-28T15:56:41.879048Z","schema_version":"nrrf810.exchange_authored_interactive_closure.v1","source_chain_continuous":true,"source_event":"order_created","source_event_id":"00065a1d-7f9c-c988-0000-000102000020","source_event_id_unique":true,"source_pre_event_id":"00065a1d-7f9c-c5a0-0001-000101000020","translation":"UNFOLD_TO_INF","unfold_event_id":null,"zero_hair":false}
{"channel":"live_orders_btcusd","interaction_index":361,"natural_form":{"channel":"live_orders_btcusd","order_id":"2044303880769540","order_subtype":5,"order_type":0},"natural_form_sha256":"896e54d91dbe3579fae1dfb6f783c82f757a1f07982c5c58002af02abcc1bc82","order_source":"orderbook","orders_submitted":0,"presentation":{"amount":"0.63679490","amount_traded":"0","microtimestamp":"1787932601798000","price":"78481.68"},"previous_record_hash":"fa0b0edc4e44b83f5f458bb167cfa0723e23b521f768fe813a810e54d85b7f87","profit_assessment":null,"record_hash":"d281a7d61c1c73503f3c7652200656455ba1dd31dce2ee0cea835d16cc91566c","recorded_unix_us":1787932601879071,"recorded_utc":"2026-08-28T15:56:41.879071Z","schema_version":"nrrf810.exchange_authored_interactive_closure.v1","source_chain_continuous":true,"source_event":"order_created","source_event_id":"00065a1d-7f9c-cd70-0000-000103000020","source_event_id_unique":true,"source_pre_event_id":"00065a1d-7f9c-c988-0000-000102000020","translation":"UNFOLD_TO_INF","unfold_event_id":null,"zero_hair":false}
{"channel":"live_orders_btcusd","interaction_index":362,"natural_form":{"channel":"live_orders_btcusd","order_id":"2044303880413187","order_subtype":5,"order_type":0},"natural_form_sha256":"308644fdb383a40f213043e855731f7fd6f4452a9885ce527a5e7dd6424adb23","order_source":"orderbook","orders_submitted":0,"presentation":{"amount":"0.19103830","amount_traded":"0","microtimestamp":"1787932601800000","price":"78482.99"},"previous_record_hash":"d281a7d61c1c73503f3c7652200656455ba1dd31dce2ee0cea835d16cc91566c","profit_assessment":null,"record_hash":"c71ac90dac5854b7c1575c89b11306f55cce8c0bab1173f7928b36429eb02981","recorded_unix_us":1787932601879150,"recorded_utc":"2026-08-28T15:56:41.879150Z","schema_version":"nrrf810.exchange_authored_interactive_closure.v1","source_chain_continuous":true,"source_event":"order_deleted","source_event_id":"00065a1d-7f9c-d540-0000-000100000020","source_event_id_unique":true,"source_pre_event_id":"00065a1d-7f9c-cd70-0000-000103000020","translation":"FOLD_RETURN_TO_ZERO","unfold_event_id":"00065a1d-7f9b-7998-0000-000100000020","zero_hair":true}
{"channel":"live_orders_ethusd","interaction_index":363,"natural_form":{"channel":"live_orders_ethusd","order_id":"2044303880777729","order_subtype":5,"order_type":0},"natural_form_sha256":"4a2c52856f11340efc5f26bcf411f140625f88112db9786f56da127c923d8074","order_source":"orderbook","orders_submitted":0,"presentation":{"amount":"0.403101","amount_traded":"0","microtimestamp":"1787932601800000","price":"2479.80"},"previous_record_hash":"c71ac90dac5854b7c1575c89b11306f55cce8c0bab1173f7928b36429eb02981","profit_assessment":null,"record_hash":"db97f00710efe617a637a23bd5b930ab1244cebd1de945d64b81fd216e04da82","recorded_unix_us":1787932601879257,"recorded_utc":"2026-08-28T15:56:41.879257Z","schema_version":"nrrf810.exchange_authored_interactive_closure.v1","source_chain_continuous":true,"source_event":"order_created","source_event_id":"00065a1d-7f9c-d540-0000-001201000020","source_event_id_unique":true,"source_pre_event_id":"00065a1d-7f9c-c1b8-0002-001200000020","translation":"UNFOLD_TO_INF","unfold_event_id":null,"zero_hair":false}
{"channel":"live_orders_ethusd","interaction_index":364,"natural_form":{"channel":"live_orders_ethusd","order_id":"2044303880785925","order_subtype":5,"order_type":1},"natural_form_sha256":"24567b42ae1f751fe8f49c09e531849c342d5ed84c85cdec1eb88db351f58ee4","order_source":"orderbook","orders_submitted":0,"presentation":{"amount":"0.044018","amount_traded":"0","microtimestamp":"1787932601803000","price":"2480.82"},"previous_record_hash":"db97f00710efe617a637a23bd5b930ab1244cebd1de945d64b81fd216e04da82","profit_assessment":null,"record_hash":"b706cbdecce40c13d459c17e764f05dff676d7b84a94afee35915aad82b49c2a","recorded_unix_us":1787932601879279,"recorded_utc":"2026-08-28T15:56:41.879279Z","schema_version":"nrrf810.exchange_authored_interactive_closure.v1","source_chain_continuous":true,"source_event":"order_created","source_event_id":"00065a1d-7f9c-e0f8-0000-001202000020","source_event_id_unique":true,"source_pre_event_id":"00065a1d-7f9c-d540-0000-001201000020","translation":"UNFOLD_TO_INF","unfold_event_id":null,"zero_hair":false}
{"channel":"live_orders_ethusd","interaction_index":365,"natural_form":{"channel":"live_orders_ethusd","order_id":"2044303879004165","order_subtype":5,"order_type":0},"natural_form_sha256":"6c7ce6b078455690095181b15b1ac6ade197846398809c0372deaefc8b6afafe","order_source":"orderbook","orders_submitted":0,"presentation":{"amount":"1.184652","amount_traded":"0","microtimestamp":"1787932601809000","price":"2480.14"},"previous_record_hash":"b706cbdecce40c13d459c17e764f05dff676d7b84a94afee35915aad82b49c2a","profit_assessment":null,"record_hash":"806376f2145e5ee292d9f51e44f20177a1b1ca6af248a6ae6a6f39ef92b7bea3","recorded_unix_us":1787932601879391,"recorded_utc":"2026-08-28T15:56:41.879391Z","schema_version":"nrrf810.exchange_authored_interactive_closure.v1","source_chain_continuous":true,"source_event":"order_deleted","source_event_id":"00065a1d-7f9c-f868-0000-001203000020","source_event_id_unique":true,"source_pre_event_id":"00065a1d-7f9c-e0f8-0000-001202000020","translation":"FOLD_RETURN_TO_ZERO","unfold_event_id":"00065a1d-7f96-39d8-0000-001201000020","zero_hair":true}
{"channel":"live_orders_ethusd","interaction_index":366,"natural_form":{"channel":"live_orders_ethusd","order_id":"2044303880814602","order_subtype":5,"order_type":0},"natural_form_sha256":"a3c727c6d4def29fd9f584b0b3770bb977795de697d6a19ece515015b37cf27d","order_source":"orderbook","orders_submitted":0,"presentation":{"amount":"40.528033","amount_traded":"0","microtimestamp":"1787932601809000","price":"2467.42"},"previous_record_hash":"806376f2145e5ee292d9f51e44f20177a1b1ca6af248a6ae6a6f39ef92b7bea3","profit_assessment":null,"record_hash":"43b4a1881acd93612c345e38e217b096f8822ac6c1920c841a5e9ea650b5c564","recorded_unix_us":1787932601879452,"recorded_utc":"2026-08-28T15:56:41.879452Z","schema_version":"nrrf810.exchange_authored_interactive_closure.v1","source_chain_continuous":true,"source_event":"order_created","source_event_id":"00065a1d-7f9c-f868-0001-001200000020","source_event_id_unique":true,"source_pre_event_id":"00065a1d-7f9c-f868-0000-001203000020","translation":"UNFOLD_TO_INF","unfold_event_id":null,"zero_hair":false}
{"channel":"live_orders_btcusd","interaction_index":367,"natural_form":{"channel":"live_orders_btcusd","order_id":"2044303880818695","order_subtype":5,"order_type":0},"natural_form_sha256":"761a57c01d42a0d4a7bdee896871bc304407fa16b82c7e7c2704dfc21dd38e37","order_source":"orderbook","orders_submitted":0,"presentation":{"amount":"0.19103785","amount_traded":"0","microtimestamp":"1787932601811000","price":"78484.09"},"previous_record_hash":"43b4a1881acd93612c345e38e217b096f8822ac6c1920c841a5e9ea650b5c564","profit_assessment":null,"record_hash":"d2d3f14e65b4167c2e8ac79f23977f2041731235397db00fb4ed4c1a8f143316","recorded_unix_us":1787932601879481,"recorded_utc":"2026-08-28T15:56:41.879481Z","schema_version":"nrrf810.exchange_authored_interactive_closure.v1","source_chain_continuous":true,"source_event":"order_created","source_event_id":"00065a1d-7f9d-0038-0000-000101000020","source_event_id_unique":true,"source_pre_event_id":"00065a1d-7f9c-d540-0000-000100000020","translation":"UNFOLD_TO_INF","unfold_event_id":null,"zero_hair":false}
{"channel":"live_orders_btcusd","interaction_index":368,"natural_form":{"channel":"live_orders_btcusd","order_id":"2044303880826884","order_subtype":5,"order_type":1},"natural_form_sha256":"2e3a348a318e1d3b8efaf4f3cfcf7427a072dbca4fc41f72af0ae558046dd87e","order_source":"orderbook","orders_submitted":0,"presentation":{"amount":"0.10000000","amount_traded":"0","microtimestamp":"1787932601812000","price":"78522.62"},"previous_record_hash":"d2d3f14e65b4167c2e8ac79f23977f2041731235397db00fb4ed4c1a8f143316","profit_assessment":null,"record_hash":"e320fc4eae7cb45d904846443ac6a25fe0da93be2296a083ad05b31758226f06","recorded_unix_us":1787932601879576,"recorded_utc":"2026-08-28T15:56:41.879576Z","schema_version":"nrrf810.exchange_authored_interactive_closure.v1","source_chain_continuous":true,"source_event":"order_created","source_event_id":"00065a1d-7f9d-0420-0000-000102000020","source_event_id_unique":true,"source_pre_event_id":"00065a1d-7f9d-0038-0000-000101000020","translation":"UNFOLD_TO_INF","unfold_event_id":null,"zero_hair":false}
{"channel":"live_orders_btcusd","interaction_index":369,"natural_form":{"channel":"live_orders_btcusd","order_id":"2044303880826884","order_subtype":5,"order_type":1},"natural_form_sha256":"2e3a348a318e1d3b8efaf4f3cfcf7427a072dbca4fc41f72af0ae558046dd87e","order_source":"orderbook","orders_submitted":0,"presentation":{"amount":"0.10000000","amount_traded":"0","microtimestamp":"1787932601812000","price":"78522.62"},"previous_record_hash":"e320fc4eae7cb45d904846443ac6a25fe0da93be2296a083ad05b31758226f06","profit_assessment":null,"record_hash":"0f665d343bfca9c79e4d574a7fd859c9a2d803dad6e6caf5af917d3a5bb861f0","recorded_unix_us":1787932601879599,"recorded_utc":"2026-08-28T15:56:41.879599Z","schema_version":"nrrf810.exchange_authored_interactive_closure.v1","source_chain_continuous":true,"source_event":"order_deleted","source_event_id":"00065a1d-7f9d-0420-0001-000103000020","source_event_id_unique":true,"source_pre_event_id":"00065a1d-7f9d-0420-0000-000102000020","translation":"FOLD_RETURN_TO_ZERO","unfold_event_id":"00065a1d-7f9d-0420-0000-000102000020","zero_hair":true}
{"channel":"live_orders_ethusd","interaction_index":370,"natural_form":{"channel":"live_orders_ethusd","order_id":"2044303880880129","order_subtype":5,"order_type":0},"natural_form_sha256":"86c88665626c214b5ecbabfcbf667136adf02f699d4b81d9f7daabfcdeb418e3","order_source":"orderbook","orders_submitted":0,"presentation":{"amount":"8.000000","amount_traded":"0","microtimestamp":"1787932601825000","price":"2478.96"},"previous_record_hash":"0f665d343bfca9c79e4d574a7fd859c9a2d803dad6e6caf5af917d3a5bb861f0","profit_assessment":null,"record_hash":"25e7550a89e0d80cfb57fb10f3623c9d60d426d2cbd70757cae715e5cbe15b81","recorded_unix_us":1787932601879713,"recorded_utc":"2026-08-28T15:56:41.879713Z","schema_version":"nrrf810.exchange_authored_interactive_closure.v1","source_chain_continuous":true,"source_event":"order_created","source_event_id":"00065a1d-7f9d-36e8-0000-001201000020","source_event_id_unique":true,"source_pre_event_id":"00065a1d-7f9c-f868-0001-001200000020","translation":"UNFOLD_TO_INF","unfold_event_id":null,"zero_hair":false}
{"channel":"live_orders_ethusd","interaction_index":371,"natural_form":{"channel":"live_orders_ethusd","order_id":"2044303880880134","order_subtype":5,"order_type":0},"natural_form_sha256":"45db0ff7f684e17a0a7739b4700ae4f7133a516d30445dd0c2dcf1e23aaf00f0","order_source":"orderbook","orders_submitted":0,"presentation":{"amount":"40.650432","amount_traded":"0","microtimestamp":"1787932601825000","price":"2459.99"},"previous_record_hash":"25e7550a89e0d80cfb57fb10f3623c9d60d426d2cbd70757cae715e5cbe15b81","profit_assessment":null,"record_hash":"33f11be0f994cd03a29de242f14a9c3bb8db4ecbbd7f48d1c0361ed7a1dd1893","recorded_unix_us":1787932601879741,"recorded_utc":"2026-08-28T15:56:41.879741Z","schema_version":"nrrf810.exchange_authored_interactive_closure.v1","source_chain_continuous":true,"source_event":"order_created","source_event_id":"00065a1d-7f9d-36e8-0001-001202000020","source_event_id_unique":true,"source_pre_event_id":"00065a1d-7f9d-36e8-0000-001201000020","translation":"UNFOLD_TO_INF","unfold_event_id":null,"zero_hair":false}
{"channel":"live_orders_btcusd","interaction_index":372,"natural_form":{"channel":"live_orders_btcusd","order_id":"2044303880880133","order_subtype":5,"order_type":0},"natural_form_sha256":"a85495aca8a26f7169691256005ccf06dcc82c255c9fb5346d30903ae3fd30e0","order_source":"orderbook","orders_submitted":0,"presentation":{"amount":"0.00140266","amount_traded":"0","microtimestamp":"1787932601825000","price":"70667.51"},"previous_record_hash":"33f11be0f994cd03a29de242f14a9c3bb8db4ecbbd7f48d1c0361ed7a1dd1893","profit_assessment":null,"record_hash":"d9ce7de60855a95712af9f7ad8d17f9cb9b3ea4ea6be016a1b88e850b6870a5b","recorded_unix_us":1787932601879853,"recorded_utc":"2026-08-28T15:56:41.879853Z","schema_version":"nrrf810.exchange_authored_interactive_closure.v1","source_chain_continuous":true,"source_event":"order_created","source_event_id":"00065a1d-7f9d-36e8-0000-000100000020","source_event_id_unique":true,"source_pre_event_id":"00065a1d-7f9d-0420-0001-000103000020","translation":"UNFOLD_TO_INF","unfold_event_id":null,"zero_hair":false}
{"channel":"live_orders_btcusd","interaction_index":373,"natural_form":{"channel":"live_orders_btcusd","order_id":"2044303880888320","order_subtype":5,"order_type":1},"natural_form_sha256":"6fa891ecb2bc1efa81546f24fe84feb28dfd500aea0f0e14701062caaa08e524","order_source":"orderbook","orders_submitted":0,"presentation":{"amount":"0.10000000","amount_traded":"0","microtimestamp":"1787932601827000","price":"78522.63"},"previous_record_hash":"d9ce7de60855a95712af9f7ad8d17f9cb9b3ea4ea6be016a1b88e850b6870a5b","profit_assessment":null,"record_hash":"dca79db6eae8dc94df9fba3f8d2170bca4a837b242837fa9321275d8c133d0df","recorded_unix_us":1787932601879914,"recorded_utc":"2026-08-28T15:56:41.879914Z","schema_version":"nrrf810.exchange_authored_interactive_closure.v1","source_chain_continuous":true,"source_event":"order_created","source_event_id":"00065a1d-7f9d-3eb8-0000-000101000020","source_event_id_unique":true,"source_pre_event_id":"00065a1d-7f9d-36e8-0000-000100000020","translation":"UNFOLD_TO_INF","unfold_event_id":null,"zero_hair":false}
{"channel":"live_orders_btcusd","interaction_index":374,"natural_form":{"channel":"live_orders_btcusd","order_id":"2044303880888320","order_subtype":5,"order_type":1},"natural_form_sha256":"6fa891ecb2bc1efa81546f24fe84feb28dfd500aea0f0e14701062caaa08e524","order_source":"orderbook","orders_submitted":0,"presentation":{"amount":"0.10000000","amount_traded":"0","microtimestamp":"1787932601827000","price":"78522.63"},"previous_record_hash":"dca79db6eae8dc94df9fba3f8d2170bca4a837b242837fa9321275d8c133d0df","profit_assessment":null,"record_hash":"d989eabfd04d3944c901ac5c043543135adb6bee7f3d7e3f1281c2f1c3c64015","recorded_unix_us":1787932601879937,"recorded_utc":"2026-08-28T15:56:41.879937Z","schema_version":"nrrf810.exchange_authored_interactive_closure.v1","source_chain_continuous":true,"source_event":"order_deleted","source_event_id":"00065a1d-7f9d-3eb8-0001-000102000020","source_event_id_unique":true,"source_pre_event_id":"00065a1d-7f9d-3eb8-0000-000101000020","translation":"FOLD_RETURN_TO_ZERO","unfold_event_id":"00065a1d-7f9d-3eb8-0000-000101000020","zero_hair":true}
{"channel":"live_orders_ethusd","interaction_index":375,"natural_form":{"channel":"live_orders_ethusd","order_id":"2044303880892424","order_subtype":0,"order_type":0},"natural_form_sha256":"6725ac793424b29b84df6d775ef24a4a0d0e3f0aceb244d81d9293bd5d542cb3","order_source":"orderbook","orders_submitted":0,"presentation":{"amount":"2.016386","amount_traded":"0","microtimestamp":"1787932601829000","price":"2480.09"},"previous_record_hash":"d989eabfd04d3944c901ac5c043543135adb6bee7f3d7e3f1281c2f1c3c64015","profit_assessment":null,"record_hash":"61de699aa90da14278ef693b4ddfbfebb5237cec0f0fc10f0be95f12bf30730b","recorded_unix_us":1787932601880017,"recorded_utc":"2026-08-28T15:56:41.880017Z","schema_version":"nrrf810.exchange_authored_interactive_closure.v1","source_chain_continuous":true,"source_event":"order_created","source_event_id":"00065a1d-7f9d-4688-0000-001203000020","source_event_id_unique":true,"source_pre_event_id":"00065a1d-7f9d-36e8-0001-001202000020","translation":"UNFOLD_TO_INF","unfold_event_id":null,"zero_hair":false}
{"channel":"live_orders_btcusd","interaction_index":376,"natural_form":{"channel":"live_orders_btcusd","order_id":"2044303880900611","order_subtype":5,"order_type":0},"natural_form_sha256":"73afd6f4a07bb9e343d823a4ebc9f4f218873d75833f3a99c1e99c146671259c","order_source":"orderbook","orders_submitted":0,"presentation":{"amount":"0.12000000","amount_traded":"0","microtimestamp":"1787932601830000","price":"78508.22"},"previous_record_hash":"61de699aa90da14278ef693b4ddfbfebb5237cec0f0fc10f0be95f12bf30730b","profit_assessment":null,"record_hash":"f30ca1fee133d7c145149e95da9b0f7f499458761721bf349079ce9092823968","recorded_unix_us":1787932601880091,"recorded_utc":"2026-08-28T15:56:41.880091Z","schema_version":"nrrf810.exchange_authored_interactive_closure.v1","source_chain_continuous":true,"source_event":"order_created","source_event_id":"00065a1d-7f9d-4a70-0000-000103000020","source_event_id_unique":true,"source_pre_event_id":"00065a1d-7f9d-3eb8-0001-000102000020","translation":"UNFOLD_TO_INF","unfold_event_id":null,"zero_hair":false}
