{"channel":"live_orders_btcusd","interaction_index":377,"natural_form":{"channel":"live_orders_btcusd","order_id":"2044303878418442","order_subtype":5,"order_type":0},"natural_form_sha256":"7e53b6d324b50e21c1df8a55c0bde12df8e6525f078cd6f34b568ea3fb0e8a0a","order_source":"orderbook","orders_submitted":0,"presentation":{"amount":"0.12000000","amount_traded":"0","microtimestamp":"1787932601832000","price":"78507.07"},"previous_record_hash":"f30ca1fee133d7c145149e95da9b0f7f499458761721bf349079ce9092823968","profit_assessment":null,"record_hash":"997ce24dbe3e32b7ffa44e55b0f1056a67d12ceae24b552811c70119796d2188","recorded_unix_us":1787932601880150,"recorded_utc":"2026-08-28T15:56:41.880150Z","schema_version":"nrrf810.exchange_authored_interactive_closure.v1","source_chain_continuous":true,"source_event":"order_deleted","source_event_id":"00065a1d-7f9d-5240-0000-000100000020","source_event_id_unique":true,"source_pre_event_id":"00065a1d-7f9d-4a70-0000-000103000020","translation":"FOLD_RETURN_TO_ZERO","unfold_event_id":"00065a1d-7f94-0f28-0000-000102000020","zero_hair":true}
{"channel":"live_orders_ethusd","interaction_index":378,"natural_form":{"channel":"live_orders_ethusd","order_id":"2044303867875332","order_subtype":5,"order_type":1},"natural_form_sha256":"7317f6ef0d1fae5131e506bd822f048d19da9d60eab3862f98d71eedaf125f0a","order_source":"orderbook","orders_submitted":0,"presentation":{"amount":"5.283004","amount_traded":"0","microtimestamp":"1787932601835000","price":"2482.03"},"previous_record_hash":"997ce24dbe3e32b7ffa44e55b0f1056a67d12ceae24b552811c70119796d2188","profit_assessment":null,"record_hash":"bd78c4d58cc33a4be68b560e50c6d2a4dc96e8330e48413bbb597a302c751292","recorded_unix_us":1787932601880226,"recorded_utc":"2026-08-28T15:56:41.880226Z","schema_version":"nrrf810.exchange_authored_interactive_closure.v1","source_chain_continuous":true,"source_event":"order_deleted","source_event_id":"00065a1d-7f9d-5df8-0000-001200000020","source_event_id_unique":true,"source_pre_event_id":"00065a1d-7f9d-4688-0000-001203000020","translation":"PARTIAL_PRIOR_UNFOLD","unfold_event_id":null,"zero_hair":false}
{"channel":"live_orders_ethusd","interaction_index":379,"natural_form":{"channel":"live_orders_ethusd","order_id":"2044303880699914","order_subtype":5,"order_type":1},"natural_form_sha256":"32efaac14d67225286ad4834aa8c4eb304c5da0ed16b0900894941e64fa7837f","order_source":"orderbook","orders_submitted":0,"presentation":{"amount":"12.088820","amount_traded":"0","microtimestamp":"1787932601837000","price":"2481.64"},"previous_record_hash":"bd78c4d58cc33a4be68b560e50c6d2a4dc96e8330e48413bbb597a302c751292","profit_assessment":null,"record_hash":"7304c42cf5b8f16fde8e78e5629ddbcdaade3093276734ce3ebd84e843d36d5d","recorded_unix_us":1787932601881053,"recorded_utc":"2026-08-28T15:56:41.881053Z","schema_version":"nrrf810.exchange_authored_interactive_closure.v1","source_chain_continuous":true,"source_event":"order_deleted","source_event_id":"00065a1d-7f9d-65c8-0000-001201000020","source_event_id_unique":true,"source_pre_event_id":"00065a1d-7f9d-5df8-0000-001200000020","translation":"FOLD_RETURN_TO_ZERO","unfold_event_id":"00065a1d-7f9c-8ef0-0000-001201000020","zero_hair":true}
{"channel":"live_orders_ethusd","interaction_index":380,"natural_form":{"channel":"live_orders_ethusd","order_id":"2044303880933376","order_subtype":5,"order_type":1},"natural_form_sha256":"9a2c089a90a1f17f5421e61d2dde62df352459db61eaf76a1676c4d8f397c3e0","order_source":"orderbook","orders_submitted":0,"presentation":{"amount":"5.000000","amount_traded":"0","microtimestamp":"1787932601838000","price":"2481.51"},"previous_record_hash":"7304c42cf5b8f16fde8e78e5629ddbcdaade3093276734ce3ebd84e843d36d5d","profit_assessment":null,"record_hash":"00a16729dfe50b2fc9ae52b8f1f0ef0491b95b61338b1706a5f208cec05a2bd5","recorded_unix_us":1787932601881260,"recorded_utc":"2026-08-28T15:56:41.881260Z","schema_version":"nrrf810.exchange_authored_interactive_closure.v1","source_chain_continuous":true,"source_event":"order_created","source_event_id":"00065a1d-7f9d-69b0-0000-001202000020","source_event_id_unique":true,"source_pre_event_id":"00065a1d-7f9d-65c8-0000-001201000020","translation":"UNFOLD_TO_INF","unfold_event_id":null,"zero_hair":false}
{"channel":"live_orders_ethusd","interaction_index":381,"natural_form":{"channel":"live_orders_ethusd","order_id":"2044303880724484","order_subtype":5,"order_type":1},"natural_form_sha256":"7dbb03934c0e3605cbc047891169b3914f12fed1c04b7df7aacfc5de22bb878c","order_source":"orderbook","orders_submitted":0,"presentation":{"amount":"4.028874","amount_traded":"0","microtimestamp":"1787932601838000","price":"2482.09"},"previous_record_hash":"00a16729dfe50b2fc9ae52b8f1f0ef0491b95b61338b1706a5f208cec05a2bd5","profit_assessment":null,"record_hash":"dc4cb5a94a87235669c2eaaa898b6a2887238dd937ae4e8bd091123793fbf443","recorded_unix_us":1787932601881285,"recorded_utc":"2026-08-28T15:56:41.881285Z","schema_version":"nrrf810.exchange_authored_interactive_closure.v1","source_chain_continuous":true,"source_event":"order_deleted","source_event_id":"00065a1d-7f9d-69b0-0001-001203000020","source_event_id_unique":true,"source_pre_event_id":"00065a1d-7f9d-69b0-0000-001202000020","translation":"FOLD_RETURN_TO_ZERO","unfold_event_id":"00065a1d-7f9c-a278-0000-001202000020","zero_hair":true}
{"channel":"live_orders_btcusd","interaction_index":382,"natural_form":{"channel":"live_orders_btcusd","order_id":"2044303880228867","order_subtype":5,"order_type":0},"natural_form_sha256":"0c6e0cf0afcdbbca9cc2ef99afa47adc50be7709ad182e7d65393c57ac4e89c6","order_source":"orderbook","orders_submitted":0,"presentation":{"amount":"0.00140266","amount_traded":"0","microtimestamp":"1787932601838000","price":"70667.51"},"previous_record_hash":"dc4cb5a94a87235669c2eaaa898b6a2887238dd937ae4e8bd091123793fbf443","profit_assessment":null,"record_hash":"91be4cf851c8803441b23bff88f2b34b9b3e1e9a082d3b7f70e0706626d9986c","recorded_unix_us":1787932601881306,"recorded_utc":"2026-08-28T15:56:41.881306Z","schema_version":"nrrf810.exchange_authored_interactive_closure.v1","source_chain_continuous":true,"source_event":"order_deleted","source_event_id":"00065a1d-7f9d-69b0-0000-000101000020","source_event_id_unique":true,"source_pre_event_id":"00065a1d-7f9d-5240-0000-000100000020","translation":"FOLD_RETURN_TO_ZERO","unfold_event_id":"00065a1d-7f9a-cdb8-0000-000100000020","zero_hair":true}
{"channel":"live_orders_ethusd","interaction_index":383,"natural_form":{"channel":"live_orders_ethusd","order_id":"2044303880749056","order_subtype":5,"order_type":0},"natural_form_sha256":"29d3de6c68cf788928c9d280a25647aaf2041d9e1e0553d5bf10c441889ef540","order_source":"orderbook","orders_submitted":0,"presentation":{"amount":"12.096906","amount_traded":"0","microtimestamp":"1787932601839000","price":"2479.97"},"previous_record_hash":"91be4cf851c8803441b23bff88f2b34b9b3e1e9a082d3b7f70e0706626d9986c","profit_assessment":null,"record_hash":"9ee282c23d1b34a060f89ee823e7a01b3c231b8f8f647f964fb1ba00dde7c26e","recorded_unix_us":1787932601881326,"recorded_utc":"2026-08-28T15:56:41.881326Z","schema_version":"nrrf810.exchange_authored_interactive_closure.v1","source_chain_continuous":true,"source_event":"order_deleted","source_event_id":"00065a1d-7f9d-6d98-0000-001200000020","source_event_id_unique":true,"source_pre_event_id":"00065a1d-7f9d-69b0-0001-001203000020","translation":"FOLD_RETURN_TO_ZERO","unfold_event_id":"00065a1d-7f9c-b9e8-0001-001203000020","zero_hair":true}
{"channel":"live_orders_ethusd","interaction_index":384,"natural_form":{"channel":"live_orders_ethusd","order_id":"2044303880937472","order_subtype":5,"order_type":1},"natural_form_sha256":"1e466829d9c722bbc05b397737b2ba79c2065d7e9e46dea80c0ec24e0dc38de5","order_source":"orderbook","orders_submitted":0,"presentation":{"amount":"6.000000","amount_traded":"0","microtimestamp":"1787932601839000","price":"2482.50"},"previous_record_hash":"9ee282c23d1b34a060f89ee823e7a01b3c231b8f8f647f964fb1ba00dde7c26e","profit_assessment":null,"record_hash":"96c70c7dc4bc790fe04bc264eaa272f54e49d8be245e6b055b6fe16eaabf380e","recorded_unix_us":1787932601881389,"recorded_utc":"2026-08-28T15:56:41.881389Z","schema_version":"nrrf810.exchange_authored_interactive_closure.v1","source_chain_continuous":true,"source_event":"order_created","source_event_id":"00065a1d-7f9d-6d98-0001-001201000020","source_event_id_unique":true,"source_pre_event_id":"00065a1d-7f9d-6d98-0000-001200000020","translation":"UNFOLD_TO_INF","unfold_event_id":null,"zero_hair":false}
{"channel":"live_orders_ethusd","interaction_index":385,"natural_form":{"channel":"live_orders_ethusd","order_id":"2044303880744966","order_subtype":5,"order_type":0},"natural_form_sha256":"c4ae6be0dcdebe2db34f9f897612dc1488b8d509ac95d419e80c8ba7f64a4733","order_source":"orderbook","orders_submitted":0,"presentation":{"amount":"12.098474","amount_traded":"0","microtimestamp":"1787932601839000","price":"2479.65"},"previous_record_hash":"96c70c7dc4bc790fe04bc264eaa272f54e49d8be245e6b055b6fe16eaabf380e","profit_assessment":null,"record_hash":"a93db3a60ee55390dc563ee4752834962fe4709c4b9cc7757726294a3c555f3c","recorded_unix_us":1787932601881487,"recorded_utc":"2026-08-28T15:56:41.881487Z","schema_version":"nrrf810.exchange_authored_interactive_closure.v1","source_chain_continuous":true,"source_event":"order_deleted","source_event_id":"00065a1d-7f9d-6d98-0002-001202000020","source_event_id_unique":true,"source_pre_event_id":"00065a1d-7f9d-6d98-0001-001201000020","translation":"FOLD_RETURN_TO_ZERO","unfold_event_id":"00065a1d-7f9c-b9e8-0000-001202000020","zero_hair":true}
{"channel":"live_orders_btcusd","interaction_index":386,"natural_form":{"channel":"live_orders_btcusd","order_id":"2044303880941571","order_subtype":5,"order_type":1},"natural_form_sha256":"17a268d8b9b04e53719560f457bbc564dbb689c26deb119dc9224f6cafcd8a55","order_source":"orderbook","orders_submitted":0,"presentation":{"amount":"0.06310787","amount_traded":"0","microtimestamp":"1787932601840000","price":"78520.44"},"previous_record_hash":"a93db3a60ee55390dc563ee4752834962fe4709c4b9cc7757726294a3c555f3c","profit_assessment":null,"record_hash":"ad483961b9f5f7e51abb23ef1715d0ba189c74b5a234a6bc14020b787b7fe9f3","recorded_unix_us":1787932601881510,"recorded_utc":"2026-08-28T15:56:41.881510Z","schema_version":"nrrf810.exchange_authored_interactive_closure.v1","source_chain_continuous":true,"source_event":"order_created","source_event_id":"00065a1d-7f9d-7180-0000-000102000020","source_event_id_unique":true,"source_pre_event_id":"00065a1d-7f9d-69b0-0000-000101000020","translation":"UNFOLD_TO_INF","unfold_event_id":null,"zero_hair":false}
{"channel":"live_orders_btcusd","interaction_index":387,"natural_form":{"channel":"live_orders_btcusd","order_id":"2044303880941571","order_subtype":5,"order_type":1},"natural_form_sha256":"17a268d8b9b04e53719560f457bbc564dbb689c26deb119dc9224f6cafcd8a55","order_source":"orderbook","orders_submitted":0,"presentation":{"amount":"0.06310787","amount_traded":"0","microtimestamp":"1787932601840000","price":"78520.44"},"previous_record_hash":"ad483961b9f5f7e51abb23ef1715d0ba189c74b5a234a6bc14020b787b7fe9f3","profit_assessment":null,"record_hash":"7d3ed0adb4d8ad9dd4a7be24ba6a4993dceb0a4785f79511bc0b7c4a88de3d6c","recorded_unix_us":1787932601881626,"recorded_utc":"2026-08-28T15:56:41.881626Z","schema_version":"nrrf810.exchange_authored_interactive_closure.v1","source_chain_continuous":true,"source_event":"order_deleted","source_event_id":"00065a1d-7f9d-7180-0001-000103000020","source_event_id_unique":true,"source_pre_event_id":"00065a1d-7f9d-7180-0000-000102000020","translation":"FOLD_RETURN_TO_ZERO","unfold_event_id":"00065a1d-7f9d-7180-0000-000102000020","zero_hair":true}
{"channel":"live_orders_ethusd","interaction_index":388,"natural_form":{"channel":"live_orders_ethusd","order_id":"2044303880945679","order_subtype":5,"order_type":1},"natural_form_sha256":"ebd648ba955215dbb95a53fc5cd531f58d92724deb60a1706ece15df5eb82a30","order_source":"orderbook","orders_submitted":0,"presentation":{"amount":"5.000000","amount_traded":"0","microtimestamp":"1787932601842000","price":"2481.76"},"previous_record_hash":"7d3ed0adb4d8ad9dd4a7be24ba6a4993dceb0a4785f79511bc0b7c4a88de3d6c","profit_assessment":null,"record_hash":"19ac124166ae517961845799845e909b18576c00d55ca59347ead792b76aacac","recorded_unix_us":1787932601881649,"recorded_utc":"2026-08-28T15:56:41.881649Z","schema_version":"nrrf810.exchange_authored_interactive_closure.v1","source_chain_continuous":true,"source_event":"order_created","source_event_id":"00065a1d-7f9d-7950-0000-001203000020","source_event_id_unique":true,"source_pre_event_id":"00065a1d-7f9d-6d98-0002-001202000020","translation":"UNFOLD_TO_INF","unfold_event_id":null,"zero_hair":false}
{"channel":"live_orders_btcusd","interaction_index":389,"natural_form":{"channel":"live_orders_btcusd","order_id":"2044303880769540","order_subtype":5,"order_type":0},"natural_form_sha256":"896e54d91dbe3579fae1dfb6f783c82f757a1f07982c5c58002af02abcc1bc82","order_source":"orderbook","orders_submitted":0,"presentation":{"amount":"0.63679490","amount_traded":"0","microtimestamp":"1787932601849000","price":"78481.68"},"previous_record_hash":"19ac124166ae517961845799845e909b18576c00d55ca59347ead792b76aacac","profit_assessment":null,"record_hash":"4cddf3a10f4f0648528e21f6026056eb296d8a381a2e85c046e6b6b1a8b5b616","recorded_unix_us":1787932601894485,"recorded_utc":"2026-08-28T15:56:41.894485Z","schema_version":"nrrf810.exchange_authored_interactive_closure.v1","source_chain_continuous":true,"source_event":"order_deleted","source_event_id":"00065a1d-7f9d-94a8-0000-000100000020","source_event_id_unique":true,"source_pre_event_id":"00065a1d-7f9d-7180-0001-000103000020","translation":"FOLD_RETURN_TO_ZERO","unfold_event_id":"00065a1d-7f9c-cd70-0000-000103000020","zero_hair":true}
{"channel":"live_orders_btcusd","interaction_index":390,"natural_form":{"channel":"live_orders_btcusd","order_id":"2044303880765442","order_subtype":5,"order_type":0},"natural_form_sha256":"9d0415b8be6b967cc5ff42fcf599c127a4d73d20a88aea502d8998ebdb759eb9","order_source":"orderbook","orders_submitted":0,"presentation":{"amount":"0.50943592","amount_traded":"0","microtimestamp":"1787932601850000","price":"78479.72"},"previous_record_hash":"4cddf3a10f4f0648528e21f6026056eb296d8a381a2e85c046e6b6b1a8b5b616","profit_assessment":null,"record_hash":"461976aced801ebebc5131038ae07cdfe49e04eff417d44cf299a057689746c8","recorded_unix_us":1787932601894519,"recorded_utc":"2026-08-28T15:56:41.894519Z","schema_version":"nrrf810.exchange_authored_interactive_closure.v1","source_chain_continuous":true,"source_event":"order_deleted","source_event_id":"00065a1d-7f9d-9890-0000-000101000020","source_event_id_unique":true,"source_pre_event_id":"00065a1d-7f9d-94a8-0000-000100000020","translation":"FOLD_RETURN_TO_ZERO","unfold_event_id":"00065a1d-7f9c-c988-0000-000102000020","zero_hair":true}
{"channel":"live_orders_btcusd","interaction_index":391,"natural_form":{"channel":"live_orders_btcusd","order_id":"2044303880990722","order_subtype":0,"order_type":1},"natural_form_sha256":"336b8d1243068b5e077b0b08d4e53ab5d62c6142fad466c78c315662e4074c4b","order_source":"orderbook","orders_submitted":0,"presentation":{"amount":"0.06310787","amount_traded":"0","microtimestamp":"1787932601852000","price":"78549.20"},"previous_record_hash":"461976aced801ebebc5131038ae07cdfe49e04eff417d44cf299a057689746c8","profit_assessment":null,"record_hash":"b3e120ad06ecd05cb7d94fda33520150e6dabd3c1527bb7d35b72e47737b1ff6","recorded_unix_us":1787932601894609,"recorded_utc":"2026-08-28T15:56:41.894609Z","schema_version":"nrrf810.exchange_authored_interactive_closure.v1","source_chain_continuous":true,"source_event":"order_created","source_event_id":"00065a1d-7f9d-a060-0000-000102000020","source_event_id_unique":true,"source_pre_event_id":"00065a1d-7f9d-9890-0000-000101000020","translation":"UNFOLD_TO_INF","unfold_event_id":null,"zero_hair":false}
{"channel":"live_orders_ethusd","interaction_index":392,"natural_form":{"channel":"live_orders_ethusd","order_id":"2044303877296132","order_subtype":5,"order_type":0},"natural_form_sha256":"82319904814c427612715aaa833fda3e79e9c75f98f53c002c50cc7eb96bc4ec","order_source":"orderbook","orders_submitted":0,"presentation":{"amount":"0.594864","amount_traded":"0","microtimestamp":"1787932601853000","price":"2479.80"},"previous_record_hash":"b3e120ad06ecd05cb7d94fda33520150e6dabd3c1527bb7d35b72e47737b1ff6","profit_assessment":null,"record_hash":"c643e5e3913e6431f7940a29a9b39646fb18dbcb59fdbe71d668411c25d4f45a","recorded_unix_us":1787932601894695,"recorded_utc":"2026-08-28T15:56:41.894695Z","schema_version":"nrrf810.exchange_authored_interactive_closure.v1","source_chain_continuous":true,"source_event":"order_deleted","source_event_id":"00065a1d-7f9d-a448-0000-001200000020","source_event_id_unique":true,"source_pre_event_id":"00065a1d-7f9d-7950-0000-001203000020","translation":"PARTIAL_PRIOR_UNFOLD","unfold_event_id":null,"zero_hair":false}
{"channel":"live_orders_ethusd","interaction_index":393,"natural_form":{"channel":"live_orders_ethusd","order_id":"2044303878631432","order_subtype":5,"order_type":0},"natural_form_sha256":"bdf635465c32766347c03f4034afe58a30d12a1e25f52cba507c73a468a0371f","order_source":"orderbook","orders_submitted":0,"presentation":{"amount":"0.262273","amount_traded":"0","microtimestamp":"1787932601854000","price":"2480.01"},"previous_record_hash":"c643e5e3913e6431f7940a29a9b39646fb18dbcb59fdbe71d668411c25d4f45a","profit_assessment":null,"record_hash":"48ff79bdfad6a86a373bf5f984d889f467b57a28927db5219f13430867ca6ba9","recorded_unix_us":1787932601906882,"recorded_utc":"2026-08-28T15:56:41.906882Z","schema_version":"nrrf810.exchange_authored_interactive_closure.v1","source_chain_continuous":true,"source_event":"order_deleted","source_event_id":"00065a1d-7f9d-a830-0000-001201000020","source_event_id_unique":true,"source_pre_event_id":"00065a1d-7f9d-a448-0000-001200000020","translation":"FOLD_RETURN_TO_ZERO","unfold_event_id":"00065a1d-7f94-da48-0000-001203000020","zero_hair":true}
{"channel":"live_orders_ethusd","interaction_index":394,"natural_form":{"channel":"live_orders_ethusd","order_id":"2044303880699915","order_subtype":5,"order_type":0},"natural_form_sha256":"c2e6bc33a47eaf768162261888c517e383ea183fd72a7de71e93e98db250246e","order_source":"orderbook","orders_submitted":0,"presentation":{"amount":"0.041163","amount_traded":"0","microtimestamp":"1787932601859000","price":"2480.68"},"previous_record_hash":"48ff79bdfad6a86a373bf5f984d889f467b57a28927db5219f13430867ca6ba9","profit_assessment":null,"record_hash":"239ba72160e4186c95c512e02498539b602aaef0292e291fec59c46b77432e2f","recorded_unix_us":1787932601906966,"recorded_utc":"2026-08-28T15:56:41.906966Z","schema_version":"nrrf810.exchange_authored_interactive_closure.v1","source_chain_continuous":true,"source_event":"order_deleted","source_event_id":"00065a1d-7f9d-bbb8-0000-001202000020","source_event_id_unique":true,"source_pre_event_id":"00065a1d-7f9d-a830-0000-001201000020","translation":"FOLD_RETURN_TO_ZERO","unfold_event_id":"00065a1d-7f9c-8ef0-0001-001202000020","zero_hair":true}
{"channel":"live_orders_btcusd","interaction_index":395,"natural_form":{"channel":"live_orders_btcusd","order_id":"2044303881019403","order_subtype":5,"order_type":0},"natural_form_sha256":"27b04db54d44a105c9881a9702218c44d7b25092b2e95904a435282b6fa657a3","order_source":"orderbook","orders_submitted":0,"presentation":{"amount":"0.63679333","amount_traded":"0","microtimestamp":"1787932601860000","price":"78482.58"},"previous_record_hash":"239ba72160e4186c95c512e02498539b602aaef0292e291fec59c46b77432e2f","profit_assessment":null,"record_hash":"62bbd478fe03fe1a896317c5df7e131f4e90b4d3abc1dc20d83c03d98d8db5c7","recorded_unix_us":1787932601907070,"recorded_utc":"2026-08-28T15:56:41.907070Z","schema_version":"nrrf810.exchange_authored_interactive_closure.v1","source_chain_continuous":true,"source_event":"order_created","source_event_id":"00065a1d-7f9d-bfa0-0000-000103000020","source_event_id_unique":true,"source_pre_event_id":"00065a1d-7f9d-a060-0000-000102000020","translation":"UNFOLD_TO_INF","unfold_event_id":null,"zero_hair":false}
{"channel":"live_orders_ethusd","interaction_index":396,"natural_form":{"channel":"live_orders_ethusd","order_id":"2044303880704008","order_subtype":5,"order_type":1},"natural_form_sha256":"7f7942d7018731d1e7d7091c0e8cd6a20a70d54d7ef7aa21f379433d931b151b","order_source":"orderbook","orders_submitted":0,"presentation":{"amount":"12.087458","amount_traded":"0","microtimestamp":"1787932601860000","price":"2481.92"},"previous_record_hash":"62bbd478fe03fe1a896317c5df7e131f4e90b4d3abc1dc20d83c03d98d8db5c7","profit_assessment":null,"record_hash":"1df156b9b994d9a3a17a2cb8e357ff7893372a75d503432cd3ba909b4b3242ff","recorded_unix_us":1787932601907186,"recorded_utc":"2026-08-28T15:56:41.907186Z","schema_version":"nrrf810.exchange_authored_interactive_closure.v1","source_chain_continuous":true,"source_event":"order_deleted","source_event_id":"00065a1d-7f9d-bfa0-0000-001203000020","source_event_id_unique":true,"source_pre_event_id":"00065a1d-7f9d-bbb8-0000-001202000020","translation":"FOLD_RETURN_TO_ZERO","unfold_event_id":"00065a1d-7f9c-92d8-0000-001200000020","zero_hair":true}
{"channel":"live_orders_btcusd","interaction_index":397,"natural_form":{"channel":"live_orders_btcusd","order_id":"2044303881023494","order_subtype":5,"order_type":0},"natural_form_sha256":"f5342056f98d60f7b6915a9975d75ace5eedd32d98cbb91871b42279d54381e1","order_source":"orderbook","orders_submitted":0,"presentation":{"amount":"0.50943466","amount_traded":"0","microtimestamp":"1787932601860000","price":"78480.62"},"previous_record_hash":"1df156b9b994d9a3a17a2cb8e357ff7893372a75d503432cd3ba909b4b3242ff","profit_assessment":null,"record_hash":"61d79fbe71b5984b9aa2fdc2ede7d3ae3502496c74c8eb676c6f69100de4c888","recorded_unix_us":1787932601907213,"recorded_utc":"2026-08-28T15:56:41.907213Z","schema_version":"nrrf810.exchange_authored_interactive_closure.v1","source_chain_continuous":true,"source_event":"order_created","source_event_id":"00065a1d-7f9d-bfa0-0001-000100000020","source_event_id_unique":true,"source_pre_event_id":"00065a1d-7f9d-bfa0-0000-000103000020","translation":"UNFOLD_TO_INF","unfold_event_id":null,"zero_hair":false}
{"channel":"live_orders_btcusd","interaction_index":398,"natural_form":{"channel":"live_orders_btcusd","order_id":"2044303881023503","order_subtype":5,"order_type":1},"natural_form_sha256":"24c3a9661a3bb832cbb4223e72ca183a801abd8ea740137d5229bc77f4f6c4b5","order_source":"orderbook","orders_submitted":0,"presentation":{"amount":"0.10000000","amount_traded":"0","microtimestamp":"1787932601861000","price":"78522.62"},"previous_record_hash":"61d79fbe71b5984b9aa2fdc2ede7d3ae3502496c74c8eb676c6f69100de4c888","profit_assessment":null,"record_hash":"a87b90c67a0792b133608e3e925c96953716327165c95e7051abd5b50d29a1bc","recorded_unix_us":1787932601907336,"recorded_utc":"2026-08-28T15:56:41.907336Z","schema_version":"nrrf810.exchange_authored_interactive_closure.v1","source_chain_continuous":true,"source_event":"order_created","source_event_id":"00065a1d-7f9d-c388-0000-000101000020","source_event_id_unique":true,"source_pre_event_id":"00065a1d-7f9d-bfa0-0001-000100000020","translation":"UNFOLD_TO_INF","unfold_event_id":null,"zero_hair":false}
{"channel":"live_orders_btcusd","interaction_index":399,"natural_form":{"channel":"live_orders_btcusd","order_id":"2044303881023503","order_subtype":5,"order_type":1},"natural_form_sha256":"24c3a9661a3bb832cbb4223e72ca183a801abd8ea740137d5229bc77f4f6c4b5","order_source":"orderbook","orders_submitted":0,"presentation":{"amount":"0.10000000","amount_traded":"0","microtimestamp":"1787932601861000","price":"78522.62"},"previous_record_hash":"a87b90c67a0792b133608e3e925c96953716327165c95e7051abd5b50d29a1bc","profit_assessment":null,"record_hash":"0f2806465e39b2a9b872a72ac81e43714752ec06d742d14f48a1815acf4c737c","recorded_unix_us":1787932601907360,"recorded_utc":"2026-08-28T15:56:41.907360Z","schema_version":"nrrf810.exchange_authored_interactive_closure.v1","source_chain_continuous":true,"source_event":"order_deleted","source_event_id":"00065a1d-7f9d-c388-0001-000102000020","source_event_id_unique":true,"source_pre_event_id":"00065a1d-7f9d-c388-0000-000101000020","translation":"FOLD_RETURN_TO_ZERO","unfold_event_id":"00065a1d-7f9d-c388-0000-000101000020","zero_hair":true}
{"channel":"live_orders_btcusd","interaction_index":400,"natural_form":{"channel":"live_orders_btcusd","order_id":"2044303881027597","order_subtype":5,"order_type":1},"natural_form_sha256":"dfa27cddad9f90cf9533673d85c92e77c5bc438f18d90391e654f454ab7b72a6","order_source":"orderbook","orders_submitted":0,"presentation":{"amount":"0.10000000","amount_traded":"0","microtimestamp":"1787932601861000","price":"78522.63"},"previous_record_hash":"0f2806465e39b2a9b872a72ac81e43714752ec06d742d14f48a1815acf4c737c","profit_assessment":null,"record_hash":"68b938fe7e570d8edffa8047211bd2b1e96c726c653fd94d5c1553e6337fcba7","recorded_unix_us":1787932601907461,"recorded_utc":"2026-08-28T15:56:41.907461Z","schema_version":"nrrf810.exchange_authored_interactive_closure.v1","source_chain_continuous":true,"source_event":"order_created","source_event_id":"00065a1d-7f9d-c388-0002-000103000020","source_event_id_unique":true,"source_pre_event_id":"00065a1d-7f9d-c388-0001-000102000020","translation":"UNFOLD_TO_INF","unfold_event_id":null,"zero_hair":false}
{"channel":"live_orders_btcusd","interaction_index":401,"natural_form":{"channel":"live_orders_btcusd","order_id":"2044303881027597","order_subtype":5,"order_type":1},"natural_form_sha256":"dfa27cddad9f90cf9533673d85c92e77c5bc438f18d90391e654f454ab7b72a6","order_source":"orderbook","orders_submitted":0,"presentation":{"amount":"0.10000000","amount_traded":"0","microtimestamp":"1787932601861000","price":"78522.63"},"previous_record_hash":"68b938fe7e570d8edffa8047211bd2b1e96c726c653fd94d5c1553e6337fcba7","profit_assessment":null,"record_hash":"f7b31b8c966bca8f78943579945880e3d329d078062103c1057f3daffd37d290","recorded_unix_us":1787932601907485,"recorded_utc":"2026-08-28T15:56:41.907485Z","schema_version":"nrrf810.exchange_authored_interactive_closure.v1","source_chain_continuous":true,"source_event":"order_deleted","source_event_id":"00065a1d-7f9d-c388-0003-000100000020","source_event_id_unique":true,"source_pre_event_id":"00065a1d-7f9d-c388-0002-000103000020","translation":"FOLD_RETURN_TO_ZERO","unfold_event_id":"00065a1d-7f9d-c388-0002-000103000020","zero_hair":true}
{"channel":"live_orders_ethbtc","interaction_index":402,"natural_form":{"channel":"live_orders_ethbtc","order_id":"2044303881027606","order_subtype":5,"order_type":1},"natural_form_sha256":"3a182b78ae8d238e4a90dc4aaaf04658a36237d05101229914242c77361b6329","order_source":"orderbook","orders_submitted":0,"presentation":{"amount":"2.01528391","amount_traded":"0","microtimestamp":"1787932601862000","price":"0.03160299"},"previous_record_hash":"f7b31b8c966bca8f78943579945880e3d329d078062103c1057f3daffd37d290","profit_assessment":null,"record_hash":"9ab7710d9965af2753f58cfe756713d1ecd2d0f7fdc8d8726b3846a11fce6db5","recorded_unix_us":1787932601907569,"recorded_utc":"2026-08-28T15:56:41.907569Z","schema_version":"nrrf810.exchange_authored_interactive_closure.v1","source_chain_continuous":true,"source_event":"order_created","source_event_id":"00065a1d-7f9d-c770-0000-001103000020","source_event_id_unique":true,"source_pre_event_id":"00065a1d-7f9c-15d8-0000-001102000020","translation":"UNFOLD_TO_INF","unfold_event_id":null,"zero_hair":false}
{"channel":"live_orders_ethusd","interaction_index":403,"natural_form":{"channel":"live_orders_ethusd","order_id":"2044303881031692","order_subtype":5,"order_type":1},"natural_form_sha256":"ae9c390830a984eb79a0d547e916708c386b9c69fd09d5cd1a4289de73e46111","order_source":"orderbook","orders_submitted":0,"presentation":{"amount":"2.015283","amount_traded":"0","microtimestamp":"1787932601862000","price":"2481.36"},"previous_record_hash":"9ab7710d9965af2753f58cfe756713d1ecd2d0f7fdc8d8726b3846a11fce6db5","profit_assessment":null,"record_hash":"342bf8b77f78a2fa042c3cb5b8fd2009136d5614eac8c51015560780ae4fbbb5","recorded_unix_us":1787932601907647,"recorded_utc":"2026-08-28T15:56:41.907647Z","schema_version":"nrrf810.exchange_authored_interactive_closure.v1","source_chain_continuous":true,"source_event":"order_created","source_event_id":"00065a1d-7f9d-c770-0000-001200000020","source_event_id_unique":true,"source_pre_event_id":"00065a1d-7f9d-bfa0-0000-001203000020","translation":"UNFOLD_TO_INF","unfold_event_id":null,"zero_hair":false}
{"channel":"live_orders_ethusd","interaction_index":404,"natural_form":{"channel":"live_orders_ethusd","order_id":"2044303881039873","order_subtype":5,"order_type":0},"natural_form_sha256":"fe3016eb1590b0d2dd379056b4d7b9a7d8c9baaaa407c6efbf8eb0b3a26f626a","order_source":"orderbook","orders_submitted":0,"presentation":{"amount":"0.336955","amount_traded":"0","microtimestamp":"1787932601864000","price":"2480.15"},"previous_record_hash":"342bf8b77f78a2fa042c3cb5b8fd2009136d5614eac8c51015560780ae4fbbb5","profit_assessment":null,"record_hash":"b416b3315a435cff3ad9be58e5a0e77df9ab30ee1ca795632a5523c2fcb405f3","recorded_unix_us":1787932601912176,"recorded_utc":"2026-08-28T15:56:41.912176Z","schema_version":"nrrf810.exchange_authored_interactive_closure.v1","source_chain_continuous":true,"source_event":"order_created","source_event_id":"00065a1d-7f9d-cf40-0000-001201000020","source_event_id_unique":true,"source_pre_event_id":"00065a1d-7f9d-c770-0000-001200000020","translation":"UNFOLD_TO_INF","unfold_event_id":null,"zero_hair":false}
{"channel":"live_orders_ethusd","interaction_index":405,"natural_form":{"channel":"live_orders_ethusd","order_id":"2044303881039878","order_subtype":5,"order_type":0},"natural_form_sha256":"1b83b7d784302e5a55557cca610bd8c8bc6534fb15b052b8adb62aa7a5723213","order_source":"orderbook","orders_submitted":0,"presentation":{"amount":"0.527206","amount_traded":"0","microtimestamp":"1787932601864000","price":"2480.02"},"previous_record_hash":"b416b3315a435cff3ad9be58e5a0e77df9ab30ee1ca795632a5523c2fcb405f3","profit_assessment":null,"record_hash":"e31871f5863ca42b74c2c4ec8ed178c2fce853050d6e7d5613bdf365ded37610","recorded_unix_us":1787932601920100,"recorded_utc":"2026-08-28T15:56:41.920100Z","schema_version":"nrrf810.exchange_authored_interactive_closure.v1","source_chain_continuous":true,"source_event":"order_created","source_event_id":"00065a1d-7f9d-cf40-0001-001202000020","source_event_id_unique":true,"source_pre_event_id":"00065a1d-7f9d-cf40-0000-001201000020","translation":"UNFOLD_TO_INF","unfold_event_id":null,"zero_hair":false}
{"channel":"live_orders_btcusd","interaction_index":406,"natural_form":{"channel":"live_orders_btcusd","order_id":"2044303879614464","order_subtype":5,"order_type":0},"natural_form_sha256":"ee9a943e3ae067e2da0f67df3f3f7b1203af5cb648e2a9ba86674c80874748ed","order_source":"orderbook","orders_submitted":0,"presentation":{"amount":"0.06368105","amount_traded":"0","microtimestamp":"1787932601867000","price":"78516.28"},"previous_record_hash":"e31871f5863ca42b74c2c4ec8ed178c2fce853050d6e7d5613bdf365ded37610","profit_assessment":null,"record_hash":"ea362d2219ee62457fca7fef28a3de5309a4f16d8784d795ad418c1dc40975ab","recorded_unix_us":1787932601920127,"recorded_utc":"2026-08-28T15:56:41.920127Z","schema_version":"nrrf810.exchange_authored_interactive_closure.v1","source_chain_continuous":true,"source_event":"order_deleted","source_event_id":"00065a1d-7f9d-daf8-0000-000101000020","source_event_id_unique":true,"source_pre_event_id":"00065a1d-7f9d-c388-0003-000100000020","translation":"FOLD_RETURN_TO_ZERO","unfold_event_id":"00065a1d-7f98-7fe0-0000-000102000020","zero_hair":true}
{"channel":"live_orders_btcusd","interaction_index":407,"natural_form":{"channel":"live_orders_btcusd","order_id":"2044303878021120","order_subtype":5,"order_type":1},"natural_form_sha256":"7e7071a6deb6805fc27a8b4066520255aebc98014b59e088af67d24924d65782","order_source":"orderbook","orders_submitted":0,"presentation":{"amount":"1.27113313","amount_traded":"0","microtimestamp":"1787932601869000","price":"78669.97"},"previous_record_hash":"ea362d2219ee62457fca7fef28a3de5309a4f16d8784d795ad418c1dc40975ab","profit_assessment":null,"record_hash":"ead0198d4e30180a0163ea212bd2105d2105fb79d47d78cd3c53f4683c83b5b3","recorded_unix_us":1787932601920209,"recorded_utc":"2026-08-28T15:56:41.920209Z","schema_version":"nrrf810.exchange_authored_interactive_closure.v1","source_chain_continuous":true,"source_event":"order_deleted","source_event_id":"00065a1d-7f9d-e2c8-0000-000102000020","source_event_id_unique":true,"source_pre_event_id":"00065a1d-7f9d-daf8-0000-000101000020","translation":"PARTIAL_PRIOR_UNFOLD","unfold_event_id":null,"zero_hair":false}
{"channel":"live_orders_ethusd","interaction_index":408,"natural_form":{"channel":"live_orders_ethusd","order_id":"2044303880945679","order_subtype":5,"order_type":1},"natural_form_sha256":"ebd648ba955215dbb95a53fc5cd531f58d92724deb60a1706ece15df5eb82a30","order_source":"orderbook","orders_submitted":0,"presentation":{"amount":"5.000000","amount_traded":"0","microtimestamp":"1787932601870000","price":"2481.76"},"previous_record_hash":"ead0198d4e30180a0163ea212bd2105d2105fb79d47d78cd3c53f4683c83b5b3","profit_assessment":null,"record_hash":"ed5113edbb758411a32373351ebcad503fc5305bbd90e78383c9227ee4248959","recorded_unix_us":1787932601920336,"recorded_utc":"2026-08-28T15:56:41.920336Z","schema_version":"nrrf810.exchange_authored_interactive_closure.v1","source_chain_continuous":true,"source_event":"order_deleted","source_event_id":"00065a1d-7f9d-e6b0-0000-001203000020","source_event_id_unique":true,"source_pre_event_id":"00065a1d-7f9d-cf40-0001-001202000020","translation":"FOLD_RETURN_TO_ZERO","unfold_event_id":"00065a1d-7f9d-7950-0000-001203000020","zero_hair":true}
{"channel":"live_orders_btcusd","interaction_index":409,"natural_form":{"channel":"live_orders_btcusd","order_id":"2044303879241730","order_subtype":5,"order_type":1},"natural_form_sha256":"af69d7049695141aa724513145f886aa02707e40dc3af73a6f5236f75a44c32a","order_source":"orderbook","orders_submitted":0,"presentation":{"amount":"0.06367563","amount_traded":"0","microtimestamp":"1787932601870000","price":"78522.98"},"previous_record_hash":"ed5113edbb758411a32373351ebcad503fc5305bbd90e78383c9227ee4248959","profit_assessment":null,"record_hash":"88163560336735782bc3ea07a0aaf10c4e8a00dc39d784c4fd2e6d175754d5af","recorded_unix_us":1787932601920402,"recorded_utc":"2026-08-28T15:56:41.920402Z","schema_version":"nrrf810.exchange_authored_interactive_closure.v1","source_chain_continuous":true,"source_event":"order_deleted","source_event_id":"00065a1d-7f9d-e6b0-0000-000103000020","source_event_id_unique":true,"source_pre_event_id":"00065a1d-7f9d-e2c8-0000-000102000020","translation":"FOLD_RETURN_TO_ZERO","unfold_event_id":"00065a1d-7f97-1c68-0000-000102000020","zero_hair":true}
{"channel":"live_orders_ethusd","interaction_index":410,"natural_form":{"channel":"live_orders_ethusd","order_id":"2044303880937472","order_subtype":5,"order_type":1},"natural_form_sha256":"1e466829d9c722bbc05b397737b2ba79c2065d7e9e46dea80c0ec24e0dc38de5","order_source":"orderbook","orders_submitted":0,"presentation":{"amount":"6.000000","amount_traded":"0","microtimestamp":"1787932601870000","price":"2482.50"},"previous_record_hash":"88163560336735782bc3ea07a0aaf10c4e8a00dc39d784c4fd2e6d175754d5af","profit_assessment":null,"record_hash":"c4ecfca981dde64703acd29dd70856a180187312f2c250258b708bd54e6dad79","recorded_unix_us":1787932601920427,"recorded_utc":"2026-08-28T15:56:41.920427Z","schema_version":"nrrf810.exchange_authored_interactive_closure.v1","source_chain_continuous":true,"source_event":"order_deleted","source_event_id":"00065a1d-7f9d-e6b0-0001-001200000020","source_event_id_unique":true,"source_pre_event_id":"00065a1d-7f9d-e6b0-0000-001203000020","translation":"FOLD_RETURN_TO_ZERO","unfold_event_id":"00065a1d-7f9d-6d98-0001-001201000020","zero_hair":true}
{"channel":"live_orders_btcusd","interaction_index":411,"natural_form":{"channel":"live_orders_btcusd","order_id":"2044303879331844","order_subtype":5,"order_type":1},"natural_form_sha256":"fe23d4ba7ccb1ad354aced06d6e211e930ba6cfbc75d8357d751d399979af648","order_source":"orderbook","orders_submitted":0,"presentation":{"amount":"0.06367384","amount_traded":"0","microtimestamp":"1787932601870000","price":"78525.19"},"previous_record_hash":"c4ecfca981dde64703acd29dd70856a180187312f2c250258b708bd54e6dad79","profit_assessment":null,"record_hash":"e7bda2ebee6090d0bec473cb7ae1b5c831e306315e3864afbc208f7bdf708199","recorded_unix_us":1787932601920543,"recorded_utc":"2026-08-28T15:56:41.920543Z","schema_version":"nrrf810.exchange_authored_interactive_closure.v1","source_chain_continuous":true,"source_event":"order_deleted","source_event_id":"00065a1d-7f9d-e6b0-0001-000100000020","source_event_id_unique":true,"source_pre_event_id":"00065a1d-7f9d-e6b0-0000-000103000020","translation":"FOLD_RETURN_TO_ZERO","unfold_event_id":"00065a1d-7f97-7258-0000-000101000020","zero_hair":true}
{"channel":"live_orders_btcusd","interaction_index":412,"natural_form":{"channel":"live_orders_btcusd","order_id":"2044303879331849","order_subtype":5,"order_type":1},"natural_form_sha256":"d72be876c85d9d795e6188bf8c5232848e217e7781792d69beceb321a39f92e0","order_source":"orderbook","orders_submitted":0,"presentation":{"amount":"0.25467128","amount_traded":"0","microtimestamp":"1787932601871000","price":"78532.61"},"previous_record_hash":"e7bda2ebee6090d0bec473cb7ae1b5c831e306315e3864afbc208f7bdf708199","profit_assessment":null,"record_hash":"43301329fe060a7dc41050c3e89856fefc192fc7b17a757dd8a82788b68ffe7e","recorded_unix_us":1787932601920605,"recorded_utc":"2026-08-28T15:56:41.920605Z","schema_version":"nrrf810.exchange_authored_interactive_closure.v1","source_chain_continuous":true,"source_event":"order_deleted","source_event_id":"00065a1d-7f9d-ea98-0000-000101000020","source_event_id_unique":true,"source_pre_event_id":"00065a1d-7f9d-e6b0-0001-000100000020","translation":"FOLD_RETURN_TO_ZERO","unfold_event_id":"00065a1d-7f97-7640-0000-000102000020","zero_hair":true}
{"channel":"live_orders_ethusd","interaction_index":413,"natural_form":{"channel":"live_orders_ethusd","order_id":"2044303880933376","order_subtype":5,"order_type":1},"natural_form_sha256":"9a2c089a90a1f17f5421e61d2dde62df352459db61eaf76a1676c4d8f397c3e0","order_source":"orderbook","orders_submitted":0,"presentation":{"amount":"5.000000","amount_traded":"0","microtimestamp":"1787932601871000","price":"2481.51"},"previous_record_hash":"43301329fe060a7dc41050c3e89856fefc192fc7b17a757dd8a82788b68ffe7e","profit_assessment":null,"record_hash":"8b2e48f098912dba5c3e55692a51bdab69d8bdc52de19276c5b9144a5040fee8","recorded_unix_us":1787932601920630,"recorded_utc":"2026-08-28T15:56:41.920630Z","schema_version":"nrrf810.exchange_authored_interactive_closure.v1","source_chain_continuous":true,"source_event":"order_deleted","source_event_id":"00065a1d-7f9d-ea98-0000-001201000020","source_event_id_unique":true,"source_pre_event_id":"00065a1d-7f9d-e6b0-0001-001200000020","translation":"FOLD_RETURN_TO_ZERO","unfold_event_id":"00065a1d-7f9d-69b0-0000-001202000020","zero_hair":true}
{"channel":"live_orders_btcusd","interaction_index":414,"natural_form":{"channel":"live_orders_btcusd","order_id":"2044303879335936","order_subtype":5,"order_type":1},"natural_form_sha256":"71b2fb5d1acee2ee116d5df16738c22a6a81e8b0e3c8bb65fb8f4725d24ddc18","order_source":"orderbook","orders_submitted":0,"presentation":{"amount":"0.25466146","amount_traded":"0","microtimestamp":"1787932601871000","price":"78535.64"},"previous_record_hash":"8b2e48f098912dba5c3e55692a51bdab69d8bdc52de19276c5b9144a5040fee8","profit_assessment":null,"record_hash":"367f9c7dc2e978686783b8746473e2aa0a08e2885df103d3501077d214c1eada","recorded_unix_us":1787932601920749,"recorded_utc":"2026-08-28T15:56:41.920749Z","schema_version":"nrrf810.exchange_authored_interactive_closure.v1","source_chain_continuous":true,"source_event":"order_deleted","source_event_id":"00065a1d-7f9d-ea98-0001-000102000020","source_event_id_unique":true,"source_pre_event_id":"00065a1d-7f9d-ea98-0000-000101000020","translation":"FOLD_RETURN_TO_ZERO","unfold_event_id":"00065a1d-7f97-7640-0001-000103000020","zero_hair":true}
{"channel":"live_orders_btcusd","interaction_index":415,"natural_form":{"channel":"live_orders_btcusd","order_id":"2044303879340045","order_subtype":5,"order_type":1},"natural_form_sha256":"f9d09e58822611588bc4de63fec5b66e68f4b3861d702003bbf1f84d7fd5fe9f","order_source":"orderbook","orders_submitted":0,"presentation":{"amount":"1.27209222","amount_traded":"0","microtimestamp":"1787932601871000","price":"78610.66"},"previous_record_hash":"367f9c7dc2e978686783b8746473e2aa0a08e2885df103d3501077d214c1eada","profit_assessment":null,"record_hash":"c9ca6e00d07e3c5981346d6603ef14b48b9b0e85b9cd03f3dbb9bb9ddb7df128","recorded_unix_us":1787932601920773,"recorded_utc":"2026-08-28T15:56:41.920773Z","schema_version":"nrrf810.exchange_authored_interactive_closure.v1","source_chain_continuous":true,"source_event":"order_deleted","source_event_id":"00065a1d-7f9d-ea98-0002-000103000020","source_event_id_unique":true,"source_pre_event_id":"00065a1d-7f9d-ea98-0001-000102000020","translation":"FOLD_RETURN_TO_ZERO","unfold_event_id":"00065a1d-7f97-7e10-0001-000101000020","zero_hair":true}
{"channel":"live_orders_btcusd","interaction_index":416,"natural_form":{"channel":"live_orders_btcusd","order_id":"2044303879340046","order_subtype":5,"order_type":1},"natural_form_sha256":"6ff070f89d23e86278e796c005dc8c7c1e700f4ba32fa0d6ce03393ea7238cff","order_source":"orderbook","orders_submitted":0,"presentation":{"amount":"12.70451953","amount_traded":"0","microtimestamp":"1787932601872000","price":"78712.15"},"previous_record_hash":"c9ca6e00d07e3c5981346d6603ef14b48b9b0e85b9cd03f3dbb9bb9ddb7df128","profit_assessment":null,"record_hash":"503d61c7adf9e0c97376f11ef6bba4c4fe6ecd929b20da2b321b737f15b78825","recorded_unix_us":1787932601920792,"recorded_utc":"2026-08-28T15:56:41.920792Z","schema_version":"nrrf810.exchange_authored_interactive_closure.v1","source_chain_continuous":true,"source_event":"order_deleted","source_event_id":"00065a1d-7f9d-ee80-0000-000100000020","source_event_id_unique":true,"source_pre_event_id":"00065a1d-7f9d-ea98-0002-000103000020","translation":"FOLD_RETURN_TO_ZERO","unfold_event_id":"00065a1d-7f97-7e10-0000-000100000020","zero_hair":true}
{"channel":"live_orders_btcusd","interaction_index":417,"natural_form":{"channel":"live_orders_btcusd","order_id":"2044303879352320","order_subtype":5,"order_type":1},"natural_form_sha256":"79ca6e9d65bbb1f223266644ec14c5cadafd6777f437e4c75ca0f7ab69bb666c","order_source":"orderbook","orders_submitted":0,"presentation":{"amount":"1.26970017","amount_traded":"0","microtimestamp":"1787932601872000","price":"78758.76"},"previous_record_hash":"503d61c7adf9e0c97376f11ef6bba4c4fe6ecd929b20da2b321b737f15b78825","profit_assessment":null,"record_hash":"c35435b0b3b67b4bf1e2d235512e4f3ce3d6a16f2b5c3a6f2fcc53e64624a612","recorded_unix_us":1787932601921026,"recorded_utc":"2026-08-28T15:56:41.921026Z","schema_version":"nrrf810.exchange_authored_interactive_closure.v1","source_chain_continuous":true,"source_event":"order_deleted","source_event_id":"00065a1d-7f9d-ee80-0001-000101000020","source_event_id_unique":true,"source_pre_event_id":"00065a1d-7f9d-ee80-0000-000100000020","translation":"FOLD_RETURN_TO_ZERO","unfold_event_id":"00065a1d-7f97-85e0-0000-000100000020","zero_hair":true}
{"channel":"live_orders_btcusd","interaction_index":418,"natural_form":{"channel":"live_orders_btcusd","order_id":"2044303879356416","order_subtype":5,"order_type":1},"natural_form_sha256":"2687321c37d14fa88fa3224a39d3528944ef9aaf5f7e4fb6986e917bfe48b4ea","order_source":"orderbook","orders_submitted":0,"presentation":{"amount":"1.26840120","amount_traded":"0","microtimestamp":"1787932601872000","price":"78839.41"},"previous_record_hash":"c35435b0b3b67b4bf1e2d235512e4f3ce3d6a16f2b5c3a6f2fcc53e64624a612","profit_assessment":null,"record_hash":"8592267be21db67ac176e6b111802d0deace9e7f3862cbd876bd499c573bb48d","recorded_unix_us":1787932601921047,"recorded_utc":"2026-08-28T15:56:41.921047Z","schema_version":"nrrf810.exchange_authored_interactive_closure.v1","source_chain_continuous":true,"source_event":"order_deleted","source_event_id":"00065a1d-7f9d-ee80-0002-000102000020","source_event_id_unique":true,"source_pre_event_id":"00065a1d-7f9d-ee80-0001-000101000020","translation":"FOLD_RETURN_TO_ZERO","unfold_event_id":"00065a1d-7f97-89c8-0001-000102000020","zero_hair":true}
{"channel":"live_orders_btcusd","interaction_index":419,"natural_form":{"channel":"live_orders_btcusd","order_id":"2044303879360522","order_subtype":5,"order_type":0},"natural_form_sha256":"cd1c86be8baf49cab239b2192012cb36449ea86cdbd6c8715d1a936a3637acef","order_source":"orderbook","orders_submitted":0,"presentation":{"amount":"0.25476924","amount_traded":"0","microtimestamp":"1787932601873000","price":"78502.41"},"previous_record_hash":"8592267be21db67ac176e6b111802d0deace9e7f3862cbd876bd499c573bb48d","profit_assessment":null,"record_hash":"128c199dd75cc379b3aba0ba0e1ed9d2e064ee90f2f0fc629160974dc2b1ea20","recorded_unix_us":1787932601921066,"recorded_utc":"2026-08-28T15:56:41.921066Z","schema_version":"nrrf810.exchange_authored_interactive_closure.v1","source_chain_continuous":true,"source_event":"order_deleted","source_event_id":"00065a1d-7f9d-f268-0000-000103000020","source_event_id_unique":true,"source_pre_event_id":"00065a1d-7f9d-ee80-0002-000102000020","translation":"FOLD_RETURN_TO_ZERO","unfold_event_id":"00065a1d-7f97-9198-0000-000100000020","zero_hair":true}
{"channel":"live_orders_btcusd","interaction_index":420,"natural_form":{"channel":"live_orders_btcusd","order_id":"2044303879364609","order_subtype":5,"order_type":0},"natural_form_sha256":"6fe8430574062210accbfb351e82c369bc35b11b26c9d4036cb7de4c1af8b639","order_source":"orderbook","orders_submitted":0,"presentation":{"amount":"0.25478772","amount_traded":"0","microtimestamp":"1787932601873000","price":"78496.71"},"previous_record_hash":"128c199dd75cc379b3aba0ba0e1ed9d2e064ee90f2f0fc629160974dc2b1ea20","profit_assessment":null,"record_hash":"744dfa5365d49f4189a24c74c371a50df465fa10c24713a516c6e37f7b6d7a2b","recorded_unix_us":1787932601921086,"recorded_utc":"2026-08-28T15:56:41.921086Z","schema_version":"nrrf810.exchange_authored_interactive_closure.v1","source_chain_continuous":true,"source_event":"order_deleted","source_event_id":"00065a1d-7f9d-f268-0001-000100000020","source_event_id_unique":true,"source_pre_event_id":"00065a1d-7f9d-f268-0000-000103000020","translation":"FOLD_RETURN_TO_ZERO","unfold_event_id":"00065a1d-7f97-9198-0001-000101000020","zero_hair":true}
{"channel":"live_orders_btcusd","interaction_index":421,"natural_form":{"channel":"live_orders_btcusd","order_id":"2044303879368706","order_subtype":5,"order_type":0},"natural_form_sha256":"bf12bf516e3729bb374cc370454310911955074ccc548185b67508bab7fca92c","order_source":"orderbook","orders_submitted":0,"presentation":{"amount":"1.27507828","amount_traded":"0","microtimestamp":"1787932601873000","price":"78426.55"},"previous_record_hash":"744dfa5365d49f4189a24c74c371a50df465fa10c24713a516c6e37f7b6d7a2b","profit_assessment":null,"record_hash":"66abc186dd3af02440e2fe79875c793ff693e86212bbb1b5f5ee3b7b2e9b8365","recorded_unix_us":1787932601921106,"recorded_utc":"2026-08-28T15:56:41.921106Z","schema_version":"nrrf810.exchange_authored_interactive_closure.v1","source_chain_continuous":true,"source_event":"order_deleted","source_event_id":"00065a1d-7f9d-f268-0002-000101000020","source_event_id_unique":true,"source_pre_event_id":"00065a1d-7f9d-f268-0001-000100000020","translation":"FOLD_RETURN_TO_ZERO","unfold_event_id":"00065a1d-7f97-9580-0000-000102000020","zero_hair":true}
{"channel":"live_orders_btcusd","interaction_index":422,"natural_form":{"channel":"live_orders_btcusd","order_id":"2044303879372801","order_subtype":5,"order_type":0},"natural_form_sha256":"c93e5d3ea3f9380e3eb45363e2eb28874986ca39dc0f8aba7b82d106668d4dcf","order_source":"orderbook","orders_submitted":0,"presentation":{"amount":"1.27541152","amount_traded":"0","microtimestamp":"1787932601874000","price":"78406.06"},"previous_record_hash":"66abc186dd3af02440e2fe79875c793ff693e86212bbb1b5f5ee3b7b2e9b8365","profit_assessment":null,"record_hash":"73abc09a8b898932a0cd4ea527351db332f806e08f8817d040b05e39d7813af7","recorded_unix_us":1787932601921128,"recorded_utc":"2026-08-28T15:56:41.921128Z","schema_version":"nrrf810.exchange_authored_interactive_closure.v1","source_chain_continuous":true,"source_event":"order_deleted","source_event_id":"00065a1d-7f9d-f650-0000-000102000020","source_event_id_unique":true,"source_pre_event_id":"00065a1d-7f9d-f268-0002-000101000020","translation":"FOLD_RETURN_TO_ZERO","unfold_event_id":"00065a1d-7f97-9968-0001-000100000020","zero_hair":true}
{"channel":"live_orders_btcusd","interaction_index":423,"natural_form":{"channel":"live_orders_btcusd","order_id":"2044303879376897","order_subtype":5,"order_type":0},"natural_form_sha256":"bcd838997f01375306bc2fdfd20c28312f5ce8173e4aa81704c5ec9081d99d36","order_source":"orderbook","orders_submitted":0,"presentation":{"amount":"12.76418733","amount_traded":"0","microtimestamp":"1787932601874000","price":"78344.19"},"previous_record_hash":"73abc09a8b898932a0cd4ea527351db332f806e08f8817d040b05e39d7813af7","profit_assessment":null,"record_hash":"0b989122ccb9a4511c5cc4daeb36b53a58df4a92fe757c17cf9924f50b365942","recorded_unix_us":1787932601921148,"recorded_utc":"2026-08-28T15:56:41.921148Z","schema_version":"nrrf810.exchange_authored_interactive_closure.v1","source_chain_continuous":true,"source_event":"order_deleted","source_event_id":"00065a1d-7f9d-f650-0001-000103000020","source_event_id_unique":true,"source_pre_event_id":"00065a1d-7f9d-f650-0000-000102000020","translation":"FOLD_RETURN_TO_ZERO","unfold_event_id":"00065a1d-7f97-9d50-0001-000102000020","zero_hair":true}
{"channel":"live_orders_btcusd","interaction_index":424,"natural_form":{"channel":"live_orders_btcusd","order_id":"2044303879376898","order_subtype":5,"order_type":0},"natural_form_sha256":"d94b9bf5f8b399a0e2ed508c7717d75066d2f74e02ae4ac588a749cbf31b2044","order_source":"orderbook","orders_submitted":0,"presentation":{"amount":"1.27567513","amount_traded":"0","microtimestamp":"1787932601874000","price":"78389.86"},"previous_record_hash":"0b989122ccb9a4511c5cc4daeb36b53a58df4a92fe757c17cf9924f50b365942","profit_assessment":null,"record_hash":"901c05f34b699ec24c6aff327419f1c1ef7e0c4b816255a2ffda0eb10afb5c38","recorded_unix_us":1787932601921251,"recorded_utc":"2026-08-28T15:56:41.921251Z","schema_version":"nrrf810.exchange_authored_interactive_closure.v1","source_chain_continuous":true,"source_event":"order_deleted","source_event_id":"00065a1d-7f9d-f650-0002-000100000020","source_event_id_unique":true,"source_pre_event_id":"00065a1d-7f9d-f650-0001-000103000020","translation":"FOLD_RETURN_TO_ZERO","unfold_event_id":"00065a1d-7f97-9d50-0000-000101000020","zero_hair":true}
{"channel":"live_orders_btcusd","interaction_index":425,"natural_form":{"channel":"live_orders_btcusd","order_id":"2044303879380996","order_subtype":5,"order_type":0},"natural_form_sha256":"d8d23bd7444f3a523cfc7d57b23d31cdb662c41641a684994393c451261da38b","order_source":"orderbook","orders_submitted":0,"presentation":{"amount":"1.27757154","amount_traded":"0","microtimestamp":"1787932601875000","price":"78273.50"},"previous_record_hash":"901c05f34b699ec24c6aff327419f1c1ef7e0c4b816255a2ffda0eb10afb5c38","profit_assessment":null,"record_hash":"3da676c8c9acd5e31d81a395d10253885306e58e2497aa76ace9e7ea8014814f","recorded_unix_us":1787932601921274,"recorded_utc":"2026-08-28T15:56:41.921274Z","schema_version":"nrrf810.exchange_authored_interactive_closure.v1","source_chain_continuous":true,"source_event":"order_deleted","source_event_id":"00065a1d-7f9d-fa38-0000-000101000020","source_event_id_unique":true,"source_pre_event_id":"00065a1d-7f9d-f650-0002-000100000020","translation":"FOLD_RETURN_TO_ZERO","unfold_event_id":"00065a1d-7f97-a138-0000-000103000020","zero_hair":true}
{"channel":"live_orders_btcusd","interaction_index":426,"natural_form":{"channel":"live_orders_btcusd","order_id":"2044303881084928","order_subtype":5,"order_type":1},"natural_form_sha256":"a174d089747754e2b53a0ab2296f9389f3aebe8ea2db20dd04f1a1ed32fbc288","order_source":"orderbook","orders_submitted":0,"presentation":{"amount":"0.06310787","amount_traded":"0","microtimestamp":"1787932601875000","price":"78522.24"},"previous_record_hash":"3da676c8c9acd5e31d81a395d10253885306e58e2497aa76ace9e7ea8014814f","profit_assessment":null,"record_hash":"134007c1fc693b6b629509f9df821e190b79cb71deaf3ce3fdf8744184974ec3","recorded_unix_us":1787932601921348,"recorded_utc":"2026-08-28T15:56:41.921348Z","schema_version":"nrrf810.exchange_authored_interactive_closure.v1","source_chain_continuous":true,"source_event":"order_created","source_event_id":"00065a1d-7f9d-fa38-0001-000102000020","source_event_id_unique":true,"source_pre_event_id":"00065a1d-7f9d-fa38-0000-000101000020","translation":"UNFOLD_TO_INF","unfold_event_id":null,"zero_hair":false}
{"channel":"live_orders_btcusd","interaction_index":427,"natural_form":{"channel":"live_orders_btcusd","order_id":"2044303881084928","order_subtype":5,"order_type":1},"natural_form_sha256":"a174d089747754e2b53a0ab2296f9389f3aebe8ea2db20dd04f1a1ed32fbc288","order_source":"orderbook","orders_submitted":0,"presentation":{"amount":"0.06310787","amount_traded":"0","microtimestamp":"1787932601875000","price":"78522.24"},"previous_record_hash":"134007c1fc693b6b629509f9df821e190b79cb71deaf3ce3fdf8744184974ec3","profit_assessment":null,"record_hash":"e556bfcba25d35f14d80321c97c175eb1e359c16f2bf781c687ace111344ee42","recorded_unix_us":1787932601921548,"recorded_utc":"2026-08-28T15:56:41.921548Z","schema_version":"nrrf810.exchange_authored_interactive_closure.v1","source_chain_continuous":true,"source_event":"order_deleted","source_event_id":"00065a1d-7f9d-fa38-0002-000103000020","source_event_id_unique":true,"source_pre_event_id":"00065a1d-7f9d-fa38-0001-000102000020","translation":"FOLD_RETURN_TO_ZERO","unfold_event_id":"00065a1d-7f9d-fa38-0001-000102000020","zero_hair":true}
{"channel":"live_orders_btcusd","interaction_index":428,"natural_form":{"channel":"live_orders_btcusd","order_id":"2044303879450628","order_subtype":5,"order_type":1},"natural_form_sha256":"58bdba9d939f5924bf94eaa427d988d2af2363b8f8085cc73e988f8c525114f8","order_source":"orderbook","orders_submitted":0,"presentation":{"amount":"1.26842789","amount_traded":"0","microtimestamp":"1787932601875000","price":"78837.75"},"previous_record_hash":"e556bfcba25d35f14d80321c97c175eb1e359c16f2bf781c687ace111344ee42","profit_assessment":null,"record_hash":"8623a919bc26ec8aef8c486a974957c086446c2889d6dc09893a438a2da68596","recorded_unix_us":1787932601921569,"recorded_utc":"2026-08-28T15:56:41.921569Z","schema_version":"nrrf810.exchange_authored_interactive_closure.v1","source_chain_continuous":true,"source_event":"order_deleted","source_event_id":"00065a1d-7f9d-fa38-0003-000100000020","source_event_id_unique":true,"source_pre_event_id":"00065a1d-7f9d-fa38-0002-000103000020","translation":"FOLD_RETURN_TO_ZERO","unfold_event_id":"00065a1d-7f97-e3a0-0002-000102000020","zero_hair":true}
{"channel":"live_orders_ethusd","interaction_index":429,"natural_form":{"channel":"live_orders_ethusd","order_id":"2044303881084943","order_subtype":5,"order_type":1},"natural_form_sha256":"9de452757b94cfce96c341390eaee6a333e1fa504f1552087e1d6200a2b7847e","order_source":"orderbook","orders_submitted":0,"presentation":{"amount":"4.028412","amount_traded":"0","microtimestamp":"1787932601876000","price":"2482.37"},"previous_record_hash":"8623a919bc26ec8aef8c486a974957c086446c2889d6dc09893a438a2da68596","profit_assessment":null,"record_hash":"9ecc4d5b1bc7332ca7256eb26d25727c8b233209980fab3690bda415ce61adf1","recorded_unix_us":1787932601921588,"recorded_utc":"2026-08-28T15:56:41.921588Z","schema_version":"nrrf810.exchange_authored_interactive_closure.v1","source_chain_continuous":true,"source_event":"order_created","source_event_id":"00065a1d-7f9d-fe20-0000-001202000020","source_event_id_unique":true,"source_pre_event_id":"00065a1d-7f9d-ea98-0000-001201000020","translation":"UNFOLD_TO_INF","unfold_event_id":null,"zero_hair":false}
{"channel":"live_orders_btcusd","interaction_index":430,"natural_form":{"channel":"live_orders_btcusd","order_id":"2044303879450629","order_subtype":5,"order_type":1},"natural_form_sha256":"7f371b9acdd49bfad77846356d9fcffa22434a87098a29767216b0dab13b9819","order_source":"orderbook","orders_submitted":0,"presentation":{"amount":"1.27177200","amount_traded":"0","microtimestamp":"1787932601876000","price":"78630.45"},"previous_record_hash":"9ecc4d5b1bc7332ca7256eb26d25727c8b233209980fab3690bda415ce61adf1","profit_assessment":null,"record_hash":"40deb98832dcd3f8310271a55b20c56f48b86d23dcf6ba8a3843e57cd0519837","recorded_unix_us":1787932601921608,"recorded_utc":"2026-08-28T15:56:41.921608Z","schema_version":"nrrf810.exchange_authored_interactive_closure.v1","source_chain_continuous":true,"source_event":"order_deleted","source_event_id":"00065a1d-7f9d-fe20-0000-000101000020","source_event_id_unique":true,"source_pre_event_id":"00065a1d-7f9d-fa38-0003-000100000020","translation":"FOLD_RETURN_TO_ZERO","unfold_event_id":"00065a1d-7f97-e3a0-0004-000100000020","zero_hair":true}
{"channel":"live_orders_btcusd","interaction_index":431,"natural_form":{"channel":"live_orders_btcusd","order_id":"2044303879458820","order_subtype":5,"order_type":0},"natural_form_sha256":"27fd4d7d82025ef63988d6dc4f7f2f85c8488f167dc1653bbe55b04539cd65e2","order_source":"orderbook","orders_submitted":0,"presentation":{"amount":"0.06368334","amount_traded":"0","microtimestamp":"1787932601876000","price":"78513.46"},"previous_record_hash":"40deb98832dcd3f8310271a55b20c56f48b86d23dcf6ba8a3843e57cd0519837","profit_assessment":null,"record_hash":"316d15a92bf82e0058240a061ebf341d8d9dc0d460cf41291e8989b071acfdf7","recorded_unix_us":1787932601921629,"recorded_utc":"2026-08-28T15:56:41.921629Z","schema_version":"nrrf810.exchange_authored_interactive_closure.v1","source_chain_continuous":true,"source_event":"order_deleted","source_event_id":"00065a1d-7f9d-fe20-0001-000102000020","source_event_id_unique":true,"source_pre_event_id":"00065a1d-7f9d-fe20-0000-000101000020","translation":"FOLD_RETURN_TO_ZERO","unfold_event_id":"00065a1d-7f97-ef58-0000-000101000020","zero_hair":true}
{"channel":"live_orders_ethusd","interaction_index":432,"natural_form":{"channel":"live_orders_ethusd","order_id":"2044303881089031","order_subtype":5,"order_type":1},"natural_form_sha256":"7ffd01d535af99ec9911fcf4a15bbeb9039421d70e3c5a293beb9cb1756d5bae","order_source":"orderbook","orders_submitted":0,"presentation":{"amount":"4.027018","amount_traded":"0","microtimestamp":"1787932601876000","price":"2483.23"},"previous_record_hash":"316d15a92bf82e0058240a061ebf341d8d9dc0d460cf41291e8989b071acfdf7","profit_assessment":null,"record_hash":"37667acf3390d2188d90eb1a37e73a6ef98b4f4359ea06bdae57a0031e3a4140","recorded_unix_us":1787932601921649,"recorded_utc":"2026-08-28T15:56:41.921649Z","schema_version":"nrrf810.exchange_authored_interactive_closure.v1","source_chain_continuous":true,"source_event":"order_created","source_event_id":"00065a1d-7f9d-fe20-0001-001203000020","source_event_id_unique":true,"source_pre_event_id":"00065a1d-7f9d-fe20-0000-001202000020","translation":"UNFOLD_TO_INF","unfold_event_id":null,"zero_hair":false}
{"channel":"live_orders_btcusd","interaction_index":433,"natural_form":{"channel":"live_orders_btcusd","order_id":"2044303879467021","order_subtype":5,"order_type":0},"natural_form_sha256":"3160722b0632f38e0f1fc18f96d4fa7c115c4fe059ab31f9b3bc1dadbd3e77ea","order_source":"orderbook","orders_submitted":0,"presentation":{"amount":"1.27604867","amount_traded":"0","microtimestamp":"1787932601876000","price":"78366.91"},"previous_record_hash":"37667acf3390d2188d90eb1a37e73a6ef98b4f4359ea06bdae57a0031e3a4140","profit_assessment":null,"record_hash":"b2c335b39e6b077ddc49e61d8fd769d89830330bbb8102b4df93ff2ad1791681","recorded_unix_us":1787932601921795,"recorded_utc":"2026-08-28T15:56:41.921795Z","schema_version":"nrrf810.exchange_authored_interactive_closure.v1","source_chain_continuous":true,"source_event":"order_deleted","source_event_id":"00065a1d-7f9d-fe20-0002-000103000020","source_event_id_unique":true,"source_pre_event_id":"00065a1d-7f9d-fe20-0001-000102000020","translation":"FOLD_RETURN_TO_ZERO","unfold_event_id":"00065a1d-7f97-f728-0000-000102000020","zero_hair":true}
{"channel":"live_orders_btcusd","interaction_index":434,"natural_form":{"channel":"live_orders_btcusd","order_id":"2044303879475200","order_subtype":5,"order_type":0},"natural_form_sha256":"e56b245f5328f053017abda68217223c6de00ca44f296918a86ccfc7d317acf8","order_source":"orderbook","orders_submitted":0,"presentation":{"amount":"1.27817952","amount_traded":"0","microtimestamp":"1787932601877000","price":"78236.27"},"previous_record_hash":"b2c335b39e6b077ddc49e61d8fd769d89830330bbb8102b4df93ff2ad1791681","profit_assessment":null,"record_hash":"a1bd14dc8fc7184bfbed81e690036a9b8d91871e83a7c23de689d285fda19ded","recorded_unix_us":1787932601921818,"recorded_utc":"2026-08-28T15:56:41.921818Z","schema_version":"nrrf810.exchange_authored_interactive_closure.v1","source_chain_continuous":true,"source_event":"order_deleted","source_event_id":"00065a1d-7f9e-0208-0000-000100000020","source_event_id_unique":true,"source_pre_event_id":"00065a1d-7f9d-fe20-0002-000103000020","translation":"FOLD_RETURN_TO_ZERO","unfold_event_id":"00065a1d-7f97-fb10-0000-000103000020","zero_hair":true}
{"channel":"live_orders_btcusd","interaction_index":435,"natural_form":{"channel":"live_orders_btcusd","order_id":"2044303879536647","order_subtype":5,"order_type":1},"natural_form_sha256":"4ec4a2ba7e9d349fea635a19cdbcb6df78512c01d70d0b90facb4786d03fd206","order_source":"orderbook","orders_submitted":0,"presentation":{"amount":"1.27145262","amount_traded":"0","microtimestamp":"1787932601877000","price":"78650.20"},"previous_record_hash":"a1bd14dc8fc7184bfbed81e690036a9b8d91871e83a7c23de689d285fda19ded","profit_assessment":null,"record_hash":"be2a21bb81878e0f10b6dce15f71aacd251a10dd140c2f52eabddf1f3d6a7e27","recorded_unix_us":1787932601927078,"recorded_utc":"2026-08-28T15:56:41.927078Z","schema_version":"nrrf810.exchange_authored_interactive_closure.v1","source_chain_continuous":true,"source_event":"order_deleted","source_event_id":"00065a1d-7f9e-0208-0001-000101000020","source_event_id_unique":true,"source_pre_event_id":"00065a1d-7f9e-0208-0000-000100000020","translation":"FOLD_RETURN_TO_ZERO","unfold_event_id":"00065a1d-7f98-35a8-0000-000101000020","zero_hair":true}
{"channel":"live_orders_btcusd","interaction_index":436,"natural_form":{"channel":"live_orders_btcusd","order_id":"2044303879540737","order_subtype":5,"order_type":0},"natural_form_sha256":"b86039ddf39e57ef83903a13a2c44f9d4db9c64d1c06cef684b9848a73d9e62d","order_source":"orderbook","orders_submitted":0,"presentation":{"amount":"1.27888333","amount_traded":"0","microtimestamp":"1787932601878000","price":"78193.21"},"previous_record_hash":"be2a21bb81878e0f10b6dce15f71aacd251a10dd140c2f52eabddf1f3d6a7e27","profit_assessment":null,"record_hash":"91d483b15cf8e22aea199a6e4d18408a33fa728724cd756d2d137e0114828f6d","recorded_unix_us":1787932601944375,"recorded_utc":"2026-08-28T15:56:41.944375Z","schema_version":"nrrf810.exchange_authored_interactive_closure.v1","source_chain_continuous":true,"source_event":"order_deleted","source_event_id":"00065a1d-7f9e-05f0-0000-000102000020","source_event_id_unique":true,"source_pre_event_id":"00065a1d-7f9e-0208-0001-000101000020","translation":"FOLD_RETURN_TO_ZERO","unfold_event_id":"00065a1d-7f98-3990-0000-000102000020","zero_hair":true}
{"channel":"live_orders_ethusd","interaction_index":437,"natural_form":{"channel":"live_orders_ethusd","order_id":"2044303881031692","order_subtype":5,"order_type":1},"natural_form_sha256":"ae9c390830a984eb79a0d547e916708c386b9c69fd09d5cd1a4289de73e46111","order_source":"orderbook","orders_submitted":0,"presentation":{"amount":"2.015283","amount_traded":"0","microtimestamp":"1787932601879000","price":"2481.36"},"previous_record_hash":"91d483b15cf8e22aea199a6e4d18408a33fa728724cd756d2d137e0114828f6d","profit_assessment":null,"record_hash":"41ca1e754b583eb74ec5e7b1159629069c425a64663bb90195f0ac805f25794a","recorded_unix_us":1787932601944554,"recorded_utc":"2026-08-28T15:56:41.944554Z","schema_version":"nrrf810.exchange_authored_interactive_closure.v1","source_chain_continuous":true,"source_event":"order_deleted","source_event_id":"00065a1d-7f9e-09d8-0000-001200000020","source_event_id_unique":true,"source_pre_event_id":"00065a1d-7f9d-fe20-0001-001203000020","translation":"FOLD_RETURN_TO_ZERO","unfold_event_id":"00065a1d-7f9d-c770-0000-001200000020","zero_hair":true}
{"channel":"live_orders_ethusd","interaction_index":438,"natural_form":{"channel":"live_orders_ethusd","order_id":"2044303881105408","order_subtype":5,"order_type":0},"natural_form_sha256":"b880ae9b75f06473fa7703c07135be4e0f86e4320ad0470e476cf3d2df4f8eea","order_source":"orderbook","orders_submitted":0,"presentation":{"amount":"0.043541","amount_traded":"0","microtimestamp":"1787932601880000","price":"2480.62"},"previous_record_hash":"41ca1e754b583eb74ec5e7b1159629069c425a64663bb90195f0ac805f25794a","profit_assessment":null,"record_hash":"afde56ac28e06babb931ce408f426e6a08ea9893ca073d6201ea403c962d257f","recorded_unix_us":1787932601944664,"recorded_utc":"2026-08-28T15:56:41.944664Z","schema_version":"nrrf810.exchange_authored_interactive_closure.v1","source_chain_continuous":true,"source_event":"order_created","source_event_id":"00065a1d-7f9e-0dc0-0000-001201000020","source_event_id_unique":true,"source_pre_event_id":"00065a1d-7f9e-09d8-0000-001200000020","translation":"UNFOLD_TO_INF","unfold_event_id":null,"zero_hair":false}
{"channel":"live_orders_ethusd","interaction_index":439,"natural_form":{"channel":"live_orders_ethusd","order_id":"2044303881105415","order_subtype":5,"order_type":1},"natural_form_sha256":"1dec016ed42f0f02cdb24b82fe334f3d4e609a202954d402c9325c7788346ccb","order_source":"orderbook","orders_submitted":0,"presentation":{"amount":"20.077182","amount_traded":"0","microtimestamp":"1787932601881000","price":"2490.39"},"previous_record_hash":"afde56ac28e06babb931ce408f426e6a08ea9893ca073d6201ea403c962d257f","profit_assessment":null,"record_hash":"d9b719a99ada4b85e5847672629ecf62c2a7677083d3f101486a8cbb6ffe9d55","recorded_unix_us":1787932601944744,"recorded_utc":"2026-08-28T15:56:41.944744Z","schema_version":"nrrf810.exchange_authored_interactive_closure.v1","source_chain_continuous":true,"source_event":"order_created","source_event_id":"00065a1d-7f9e-11a8-0000-001202000020","source_event_id_unique":true,"source_pre_event_id":"00065a1d-7f9e-0dc0-0000-001201000020","translation":"UNFOLD_TO_INF","unfold_event_id":null,"zero_hair":false}
{"channel":"live_orders_ethusd","interaction_index":440,"natural_form":{"channel":"live_orders_ethusd","order_id":"2044303881113600","order_subtype":5,"order_type":1},"natural_form_sha256":"4adaf0a0dc70b9dba1716b25ea6d5082f186a5d57f2d539aadc1133617b19b76","order_source":"orderbook","orders_submitted":0,"presentation":{"amount":"10.062547","amount_traded":"0","microtimestamp":"1787932601882000","price":"2484.47"},"previous_record_hash":"d9b719a99ada4b85e5847672629ecf62c2a7677083d3f101486a8cbb6ffe9d55","profit_assessment":null,"record_hash":"a0d075f90c479104ea3aa471cafc4c70a54a7d2935a1c9edb191da7baa6da673","recorded_unix_us":1787932601944842,"recorded_utc":"2026-08-28T15:56:41.944842Z","schema_version":"nrrf810.exchange_authored_interactive_closure.v1","source_chain_continuous":true,"source_event":"order_created","source_event_id":"00065a1d-7f9e-1590-0000-001203000020","source_event_id_unique":true,"source_pre_event_id":"00065a1d-7f9e-11a8-0000-001202000020","translation":"UNFOLD_TO_INF","unfold_event_id":null,"zero_hair":false}
{"channel":"live_orders_ethbtc","interaction_index":441,"natural_form":{"channel":"live_orders_ethbtc","order_id":"2044303881027606","order_subtype":5,"order_type":1},"natural_form_sha256":"3a182b78ae8d238e4a90dc4aaaf04658a36237d05101229914242c77361b6329","order_source":"orderbook","orders_submitted":0,"presentation":{"amount":"2.01528391","amount_traded":"0","microtimestamp":"1787932601882000","price":"0.03160299"},"previous_record_hash":"a0d075f90c479104ea3aa471cafc4c70a54a7d2935a1c9edb191da7baa6da673","profit_assessment":null,"record_hash":"30e1303d17cc61e43e843612d5a55a028702be504128ced7846e6c2231518985","recorded_unix_us":1787932601944870,"recorded_utc":"2026-08-28T15:56:41.944870Z","schema_version":"nrrf810.exchange_authored_interactive_closure.v1","source_chain_continuous":true,"source_event":"order_deleted","source_event_id":"00065a1d-7f9e-1590-0000-001100000020","source_event_id_unique":true,"source_pre_event_id":"00065a1d-7f9d-c770-0000-001103000020","translation":"FOLD_RETURN_TO_ZERO","unfold_event_id":"00065a1d-7f9d-c770-0000-001103000020","zero_hair":true}
{"channel":"live_orders_ethusd","interaction_index":442,"natural_form":{"channel":"live_orders_ethusd","order_id":"2044303881117697","order_subtype":5,"order_type":0},"natural_form_sha256":"424dfb6be312d3114d56b90e0d53fea9741232d26e410697a2020fe852f1c421","order_source":"orderbook","orders_submitted":0,"presentation":{"amount":"4.034214","amount_traded":"0","microtimestamp":"1787932601883000","price":"2478.79"},"previous_record_hash":"30e1303d17cc61e43e843612d5a55a028702be504128ced7846e6c2231518985","profit_assessment":null,"record_hash":"202585c70a7f59954e8d6c2240d5c3015241b6d59bf45123963912ee58414b2f","recorded_unix_us":1787932601944967,"recorded_utc":"2026-08-28T15:56:41.944967Z","schema_version":"nrrf810.exchange_authored_interactive_closure.v1","source_chain_continuous":true,"source_event":"order_created","source_event_id":"00065a1d-7f9e-1978-0000-001200000020","source_event_id_unique":true,"source_pre_event_id":"00065a1d-7f9e-1590-0000-001203000020","translation":"UNFOLD_TO_INF","unfold_event_id":null,"zero_hair":false}
{"channel":"live_orders_ethusd","interaction_index":443,"natural_form":{"channel":"live_orders_ethusd","order_id":"2044303881117701","order_subtype":5,"order_type":1},"natural_form_sha256":"ca632b75641aff51dbd96bb753bd84cd34cbc4d9255810c6585f58d560eefbdb","order_source":"orderbook","orders_submitted":0,"presentation":{"amount":"40.051178","amount_traded":"0","microtimestamp":"1787932601883000","price":"2496.81"},"previous_record_hash":"202585c70a7f59954e8d6c2240d5c3015241b6d59bf45123963912ee58414b2f","profit_assessment":null,"record_hash":"c98141a5bffac4f47d84360eed7c9652f59e11e0d48dbf9cd4423642b3aff144","recorded_unix_us":1787932601944993,"recorded_utc":"2026-08-28T15:56:41.944993Z","schema_version":"nrrf810.exchange_authored_interactive_closure.v1","source_chain_continuous":true,"source_event":"order_created","source_event_id":"00065a1d-7f9e-1978-0001-001201000020","source_event_id_unique":true,"source_pre_event_id":"00065a1d-7f9e-1978-0000-001200000020","translation":"UNFOLD_TO_INF","unfold_event_id":null,"zero_hair":false}
{"channel":"live_orders_ethbtc","interaction_index":444,"natural_form":{"channel":"live_orders_ethbtc","order_id":"2044303879073795","order_subtype":5,"order_type":1},"natural_form_sha256":"2cd3ba6ea67ac5b5e19d37dcc590f76804268b65e1db3f2caff9a2ce8c770ef4","order_source":"orderbook","orders_submitted":0,"presentation":{"amount":"0.60450317","amount_traded":"0","microtimestamp":"1787932601884000","price":"0.03160300"},"previous_record_hash":"c98141a5bffac4f47d84360eed7c9652f59e11e0d48dbf9cd4423642b3aff144","profit_assessment":null,"record_hash":"7ced2c56d748f95aa3c2464c0dbf465dd64469e15123669da8cec01a787b5f79","recorded_unix_us":1787932601945060,"recorded_utc":"2026-08-28T15:56:41.945060Z","schema_version":"nrrf810.exchange_authored_interactive_closure.v1","source_chain_continuous":true,"source_event":"order_deleted","source_event_id":"00065a1d-7f9e-1d60-0000-001101000020","source_event_id_unique":true,"source_pre_event_id":"00065a1d-7f9e-1590-0000-001100000020","translation":"FOLD_RETURN_TO_ZERO","unfold_event_id":"00065a1d-7f96-7c40-0000-001103000020","zero_hair":true}
{"channel":"live_orders_ethbtc","interaction_index":445,"natural_form":{"channel":"live_orders_ethbtc","order_id":"2044303879073800","order_subtype":5,"order_type":1},"natural_form_sha256":"165f4f8704a07837f48a2e4fd6c1f2bfd7936a9ff10a30b76998179d112a3a91","order_source":"orderbook","orders_submitted":0,"presentation":{"amount":"4.02232075","amount_traded":"0","microtimestamp":"1787932601885000","price":"0.03165997"},"previous_record_hash":"7ced2c56d748f95aa3c2464c0dbf465dd64469e15123669da8cec01a787b5f79","profit_assessment":null,"record_hash":"d2e87a13f8394b8e5cc1d87077a2b212a255ad10c48c8d58937a7a05248e78db","recorded_unix_us":1787932601945152,"recorded_utc":"2026-08-28T15:56:41.945152Z","schema_version":"nrrf810.exchange_authored_interactive_closure.v1","source_chain_continuous":true,"source_event":"order_deleted","source_event_id":"00065a1d-7f9e-2148-0000-001102000020","source_event_id_unique":true,"source_pre_event_id":"00065a1d-7f9e-1d60-0000-001101000020","translation":"FOLD_RETURN_TO_ZERO","unfold_event_id":"00065a1d-7f96-8028-0000-001100000020","zero_hair":true}
{"channel":"live_orders_ethbtc","interaction_index":446,"natural_form":{"channel":"live_orders_ethbtc","order_id":"2044303879147520","order_subtype":5,"order_type":1},"natural_form_sha256":"d9b8a3dcc939b920db32efa022f920f77aeea84331270a656ef8b8a5b87e470b","order_source":"orderbook","orders_submitted":0,"presentation":{"amount":"2.01386943","amount_traded":"0","microtimestamp":"1787932601885000","price":"0.03161840"},"previous_record_hash":"d2e87a13f8394b8e5cc1d87077a2b212a255ad10c48c8d58937a7a05248e78db","profit_assessment":null,"record_hash":"9a19d6059751b9c7d41f27cd3852469dc6afb71cb31c6a2fb050033ab3fc1b90","recorded_unix_us":1787932601945176,"recorded_utc":"2026-08-28T15:56:41.945176Z","schema_version":"nrrf810.exchange_authored_interactive_closure.v1","source_chain_continuous":true,"source_event":"order_deleted","source_event_id":"00065a1d-7f9e-2148-0001-001103000020","source_event_id_unique":true,"source_pre_event_id":"00065a1d-7f9e-2148-0000-001102000020","translation":"FOLD_RETURN_TO_ZERO","unfold_event_id":"00065a1d-7f96-c678-0000-001101000020","zero_hair":true}
{"channel":"live_orders_ethbtc","interaction_index":447,"natural_form":{"channel":"live_orders_ethbtc","order_id":"2044303879155717","order_subtype":5,"order_type":1},"natural_form_sha256":"2502a0f483f223556f8a518f941bdb2ba482d1105dd977c32bab676efe054b4c","order_source":"orderbook","orders_submitted":0,"presentation":{"amount":"1.00740464","amount_traded":"0","microtimestamp":"1787932601885000","price":"0.03160452"},"previous_record_hash":"9a19d6059751b9c7d41f27cd3852469dc6afb71cb31c6a2fb050033ab3fc1b90","profit_assessment":null,"record_hash":"244fd29e7c00a5e1f83182ae0566b215d80668e509b31414877e949605ed2c3e","recorded_unix_us":1787932601945265,"recorded_utc":"2026-08-28T15:56:41.945265Z","schema_version":"nrrf810.exchange_authored_interactive_closure.v1","source_chain_continuous":true,"source_event":"order_deleted","source_event_id":"00065a1d-7f9e-2148-0002-001100000020","source_event_id_unique":true,"source_pre_event_id":"00065a1d-7f9e-2148-0001-001103000020","translation":"FOLD_RETURN_TO_ZERO","unfold_event_id":"00065a1d-7f96-ca60-0000-001102000020","zero_hair":true}
{"channel":"live_orders_ethbtc","interaction_index":448,"natural_form":{"channel":"live_orders_ethbtc","order_id":"2044303879163906","order_subtype":5,"order_type":1},"natural_form_sha256":"abffb0ecbed071c5e8a4912659916075dbd8257930f93473f2bc48a98789a33d","order_source":"orderbook","orders_submitted":0,"presentation":{"amount":"3.02055629","amount_traded":"0","microtimestamp":"1787932601886000","price":"0.03162186"},"previous_record_hash":"244fd29e7c00a5e1f83182ae0566b215d80668e509b31414877e949605ed2c3e","profit_assessment":null,"record_hash":"71449326e6a6fc029b9fb472e46b7846b32337dba225db09be404b889286f30b","recorded_unix_us":1787932601945522,"recorded_utc":"2026-08-28T15:56:41.945522Z","schema_version":"nrrf810.exchange_authored_interactive_closure.v1","source_chain_continuous":true,"source_event":"order_deleted","source_event_id":"00065a1d-7f9e-2530-0000-001101000020","source_event_id_unique":true,"source_pre_event_id":"00065a1d-7f9e-2148-0002-001100000020","translation":"FOLD_RETURN_TO_ZERO","unfold_event_id":"00065a1d-7f96-d230-0000-001103000020","zero_hair":true}
{"channel":"live_orders_ethusd","interaction_index":449,"natural_form":{"channel":"live_orders_ethusd","order_id":"2044303881129985","order_subtype":5,"order_type":0},"natural_form_sha256":"9c8f0717fc5ec4cec07958a89ac7e70b2336ca50ed71278a88a4be0a2239ac77","order_source":"orderbook","orders_submitted":0,"presentation":{"amount":"20.215084","amount_traded":"0","microtimestamp":"1787932601886000","price":"2473.40"},"previous_record_hash":"71449326e6a6fc029b9fb472e46b7846b32337dba225db09be404b889286f30b","profit_assessment":null,"record_hash":"1782522719befe96fce78787b6ba516ee9323813c9c74e237424041d897884d8","recorded_unix_us":1787932601945560,"recorded_utc":"2026-08-28T15:56:41.945560Z","schema_version":"nrrf810.exchange_authored_interactive_closure.v1","source_chain_continuous":true,"source_event":"order_created","source_event_id":"00065a1d-7f9e-2530-0000-001202000020","source_event_id_unique":true,"source_pre_event_id":"00065a1d-7f9e-1978-0001-001201000020","translation":"UNFOLD_TO_INF","unfold_event_id":null,"zero_hair":false}
{"channel":"live_orders_ethbtc","interaction_index":450,"natural_form":{"channel":"live_orders_ethbtc","order_id":"2044303879176196","order_subtype":5,"order_type":0},"natural_form_sha256":"48825783a9ae2d02d93f38d1110f2549d91cb149918ab7b0cbc1a836d133dc27","order_source":"orderbook","orders_submitted":0,"presentation":{"amount":"1.00801353","amount_traded":"0","microtimestamp":"1787932601886000","price":"0.03158534"},"previous_record_hash":"1782522719befe96fce78787b6ba516ee9323813c9c74e237424041d897884d8","profit_assessment":null,"record_hash":"2710d97d62978f7f6a4ecc6b307afee268abfd8acc7eb28818bd133501c63264","recorded_unix_us":1787932601945586,"recorded_utc":"2026-08-28T15:56:41.945586Z","schema_version":"nrrf810.exchange_authored_interactive_closure.v1","source_chain_continuous":true,"source_event":"order_deleted","source_event_id":"00065a1d-7f9e-2530-0001-001102000020","source_event_id_unique":true,"source_pre_event_id":"00065a1d-7f9e-2530-0000-001101000020","translation":"FOLD_RETURN_TO_ZERO","unfold_event_id":"00065a1d-7f96-dde8-0000-001100000020","zero_hair":true}
{"channel":"live_orders_ethusd","interaction_index":451,"natural_form":{"channel":"live_orders_ethusd","order_id":"2044303881129986","order_subtype":5,"order_type":0},"natural_form_sha256":"12a5b218aa077bf84cb60fe0de0b7d6915f86c790ec57a4ff1e456e93df8ed0a","order_source":"orderbook","orders_submitted":0,"presentation":{"amount":"10.092689","amount_traded":"0","microtimestamp":"1787932601886000","price":"2477.04"},"previous_record_hash":"2710d97d62978f7f6a4ecc6b307afee268abfd8acc7eb28818bd133501c63264","profit_assessment":null,"record_hash":"139c905eeed69537e90e1710ff8b79191a49dafae0020d69001dc43ccb1d1955","recorded_unix_us":1787932601945689,"recorded_utc":"2026-08-28T15:56:41.945689Z","schema_version":"nrrf810.exchange_authored_interactive_closure.v1","source_chain_continuous":true,"source_event":"order_created","source_event_id":"00065a1d-7f9e-2530-0001-001203000020","source_event_id_unique":true,"source_pre_event_id":"00065a1d-7f9e-2530-0000-001202000020","translation":"UNFOLD_TO_INF","unfold_event_id":null,"zero_hair":false}
{"channel":"live_orders_ethbtc","interaction_index":452,"natural_form":{"channel":"live_orders_ethbtc","order_id":"2044303879176203","order_subtype":5,"order_type":0},"natural_form_sha256":"bbf2bfb8bfd93ed3eea20bf34393738d18813251452933e567c8a7e76aebe6e5","order_source":"orderbook","orders_submitted":0,"presentation":{"amount":"2.01629689","amount_traded":"0","microtimestamp":"1787932601886000","price":"0.03157941"},"previous_record_hash":"139c905eeed69537e90e1710ff8b79191a49dafae0020d69001dc43ccb1d1955","profit_assessment":null,"record_hash":"292f856e28a08540a20f56441e704f72006ab7da6a7f4be11fbdf754d4655d5c","recorded_unix_us":1787932601945721,"recorded_utc":"2026-08-28T15:56:41.945721Z","schema_version":"nrrf810.exchange_authored_interactive_closure.v1","source_chain_continuous":true,"source_event":"order_deleted","source_event_id":"00065a1d-7f9e-2530-0002-001103000020","source_event_id_unique":true,"source_pre_event_id":"00065a1d-7f9e-2530-0001-001102000020","translation":"FOLD_RETURN_TO_ZERO","unfold_event_id":"00065a1d-7f96-e1d0-0000-001101000020","zero_hair":true}
{"channel":"live_orders_ethbtc","interaction_index":453,"natural_form":{"channel":"live_orders_ethbtc","order_id":"2044303879184384","order_subtype":5,"order_type":0},"natural_form_sha256":"3e81e6e5c42dc17974b26a44d710b73041530cc0ef0d3efa665c4016090aeccd","order_source":"orderbook","orders_submitted":0,"presentation":{"amount":"3.02537254","amount_traded":"0","microtimestamp":"1787932601887000","price":"0.03156999"},"previous_record_hash":"292f856e28a08540a20f56441e704f72006ab7da6a7f4be11fbdf754d4655d5c","profit_assessment":null,"record_hash":"bc70e624002aca490bcd076e71133690b6f8eeaa50c0f8c0ba6ce006495fd838","recorded_unix_us":1787932601945880,"recorded_utc":"2026-08-28T15:56:41.945880Z","schema_version":"nrrf810.exchange_authored_interactive_closure.v1","source_chain_continuous":true,"source_event":"order_deleted","source_event_id":"00065a1d-7f9e-2918-0000-001100000020","source_event_id_unique":true,"source_pre_event_id":"00065a1d-7f9e-2530-0002-001103000020","translation":"FOLD_RETURN_TO_ZERO","unfold_event_id":"00065a1d-7f96-e5b8-0001-001103000020","zero_hair":true}
{"channel":"live_orders_ethbtc","interaction_index":454,"natural_form":{"channel":"live_orders_ethbtc","order_id":"2044303879233536","order_subtype":5,"order_type":0},"natural_form_sha256":"21a9144de3ec4f03c11559e0277c2665cb96b08f66cb7a143e916f07cf24cc2a","order_source":"orderbook","orders_submitted":0,"presentation":{"amount":"4.03662068","amount_traded":"0","microtimestamp":"1787932601887000","price":"0.03154857"},"previous_record_hash":"bc70e624002aca490bcd076e71133690b6f8eeaa50c0f8c0ba6ce006495fd838","profit_assessment":null,"record_hash":"a50f0e902ed24458f2eb09eabd1c3471dfa011bebe139dcd7696f5c9a9cc08ad","recorded_unix_us":1787932601945913,"recorded_utc":"2026-08-28T15:56:41.945913Z","schema_version":"nrrf810.exchange_authored_interactive_closure.v1","source_chain_continuous":true,"source_event":"order_deleted","source_event_id":"00065a1d-7f9e-2918-0001-001101000020","source_event_id_unique":true,"source_pre_event_id":"00065a1d-7f9e-2918-0000-001100000020","translation":"FOLD_RETURN_TO_ZERO","unfold_event_id":"00065a1d-7f97-1498-0000-001101000020","zero_hair":true}
{"channel":"live_orders_ethbtc","interaction_index":455,"natural_form":{"channel":"live_orders_ethbtc","order_id":"2044303880138752","order_subtype":5,"order_type":0},"natural_form_sha256":"9e2e81258a82960328f931bb2b32d863a52d1ab50624ae55f57b60e29665ddc2","order_source":"orderbook","orders_submitted":0,"presentation":{"amount":"0.60475617","amount_traded":"0","microtimestamp":"1787932601887000","price":"0.03158982"},"previous_record_hash":"a50f0e902ed24458f2eb09eabd1c3471dfa011bebe139dcd7696f5c9a9cc08ad","profit_assessment":null,"record_hash":"e463472d56f2aace13786ec7e75c948bc7ada7992213ae5aeffcf1aab43fc957","recorded_unix_us":1787932601946023,"recorded_utc":"2026-08-28T15:56:41.946023Z","schema_version":"nrrf810.exchange_authored_interactive_closure.v1","source_chain_continuous":true,"source_event":"order_deleted","source_event_id":"00065a1d-7f9e-2918-0002-001102000020","source_event_id_unique":true,"source_pre_event_id":"00065a1d-7f9e-2918-0001-001101000020","translation":"FOLD_RETURN_TO_ZERO","unfold_event_id":"00065a1d-7f9a-77c8-0000-001103000020","zero_hair":true}
{"channel":"live_orders_ethusd","interaction_index":456,"natural_form":{"channel":"live_orders_ethusd","order_id":"2044303881138178","order_subtype":5,"order_type":0},"natural_form_sha256":"58e0d0aba00dbd7e7e1d993d8356badd745867445df1760e1f0340ba3214c85b","order_source":"orderbook","orders_submitted":0,"presentation":{"amount":"40.568517","amount_traded":"0","microtimestamp":"1787932601888000","price":"2464.96"},"previous_record_hash":"e463472d56f2aace13786ec7e75c948bc7ada7992213ae5aeffcf1aab43fc957","profit_assessment":null,"record_hash":"db975b5e60567a70ec8363855d69ef90e473096e44be135d95f4e250b3c13723","recorded_unix_us":1787932601946051,"recorded_utc":"2026-08-28T15:56:41.946051Z","schema_version":"nrrf810.exchange_authored_interactive_closure.v1","source_chain_continuous":true,"source_event":"order_created","source_event_id":"00065a1d-7f9e-2d00-0000-001200000020","source_event_id_unique":true,"source_pre_event_id":"00065a1d-7f9e-2530-0001-001203000020","translation":"UNFOLD_TO_INF","unfold_event_id":null,"zero_hair":false}
{"channel":"live_orders_btcusd","interaction_index":457,"natural_form":{"channel":"live_orders_btcusd","order_id":"2044303880818695","order_subtype":5,"order_type":0},"natural_form_sha256":"761a57c01d42a0d4a7bdee896871bc304407fa16b82c7e7c2704dfc21dd38e37","order_source":"orderbook","orders_submitted":0,"presentation":{"amount":"0.19103785","amount_traded":"0","microtimestamp":"1787932601890000","price":"78484.09"},"previous_record_hash":"db975b5e60567a70ec8363855d69ef90e473096e44be135d95f4e250b3c13723","profit_assessment":null,"record_hash":"9bd760eadfefbfaefbc516e9fda9c1c207c7f25c7951d0eaa94cef5a86d9f17a","recorded_unix_us":1787932601946153,"recorded_utc":"2026-08-28T15:56:41.946153Z","schema_version":"nrrf810.exchange_authored_interactive_closure.v1","source_chain_continuous":true,"source_event":"order_deleted","source_event_id":"00065a1d-7f9e-34d0-0000-000103000020","source_event_id_unique":true,"source_pre_event_id":"00065a1d-7f9e-05f0-0000-000102000020","translation":"FOLD_RETURN_TO_ZERO","unfold_event_id":"00065a1d-7f9d-0038-0000-000101000020","zero_hair":true}
{"channel":"live_orders_ethusd","interaction_index":458,"natural_form":{"channel":"live_orders_ethusd","order_id":"2044303881142283","order_subtype":5,"order_type":0},"natural_form_sha256":"4bb26b0d217dc279ce40f98a368d10c9dd0d7b775dbac86df1cd1fed4f4294ad","order_source":"orderbook","orders_submitted":0,"presentation":{"amount":"10.097738","amount_traded":"0","microtimestamp":"1787932601890000","price":"2475.80"},"previous_record_hash":"9bd760eadfefbfaefbc516e9fda9c1c207c7f25c7951d0eaa94cef5a86d9f17a","profit_assessment":null,"record_hash":"1ad4e02263b3bd15c5950f6486be19b0cc6b9ad79383f174b844d093e92016a8","recorded_unix_us":1787932601946177,"recorded_utc":"2026-08-28T15:56:41.946177Z","schema_version":"nrrf810.exchange_authored_interactive_closure.v1","source_chain_continuous":true,"source_event":"order_created","source_event_id":"00065a1d-7f9e-34d0-0000-001201000020","source_event_id_unique":true,"source_pre_event_id":"00065a1d-7f9e-2d00-0000-001200000020","translation":"UNFOLD_TO_INF","unfold_event_id":null,"zero_hair":false}
{"channel":"live_orders_ethusd","interaction_index":459,"natural_form":{"channel":"live_orders_ethusd","order_id":"2044303881105408","order_subtype":5,"order_type":0},"natural_form_sha256":"b880ae9b75f06473fa7703c07135be4e0f86e4320ad0470e476cf3d2df4f8eea","order_source":"orderbook","orders_submitted":0,"presentation":{"amount":"0.043541","amount_traded":"0","microtimestamp":"1787932601893000","price":"2480.62"},"previous_record_hash":"1ad4e02263b3bd15c5950f6486be19b0cc6b9ad79383f174b844d093e92016a8","profit_assessment":null,"record_hash":"20dabb804e14094bd60b183a77ef56493fd1401c14c478c52be06b49d7c60f8a","recorded_unix_us":1787932601946252,"recorded_utc":"2026-08-28T15:56:41.946252Z","schema_version":"nrrf810.exchange_authored_interactive_closure.v1","source_chain_continuous":true,"source_event":"order_deleted","source_event_id":"00065a1d-7f9e-4088-0000-001202000020","source_event_id_unique":true,"source_pre_event_id":"00065a1d-7f9e-34d0-0000-001201000020","translation":"FOLD_RETURN_TO_ZERO","unfold_event_id":"00065a1d-7f9e-0dc0-0000-001201000020","zero_hair":true}
{"channel":"live_orders_btcusd","interaction_index":460,"natural_form":{"channel":"live_orders_btcusd","order_id":"2044303881162753","order_subtype":5,"order_type":1},"natural_form_sha256":"dc8ca2a75825f2516bddd0ee274ff284d7a6797d9a56001708257aa5857f9922","order_source":"orderbook","orders_submitted":0,"presentation":{"amount":"0.10000000","amount_traded":"0","microtimestamp":"1787932601894000","price":"78522.62"},"previous_record_hash":"20dabb804e14094bd60b183a77ef56493fd1401c14c478c52be06b49d7c60f8a","profit_assessment":null,"record_hash":"9dcfebdd979afdc51e8c7849bca57e05dcedbedb72f31da42710282f7bc8c67a","recorded_unix_us":1787932601946341,"recorded_utc":"2026-08-28T15:56:41.946341Z","schema_version":"nrrf810.exchange_authored_interactive_closure.v1","source_chain_continuous":true,"source_event":"order_created","source_event_id":"00065a1d-7f9e-4470-0000-000100000020","source_event_id_unique":true,"source_pre_event_id":"00065a1d-7f9e-34d0-0000-000103000020","translation":"UNFOLD_TO_INF","unfold_event_id":null,"zero_hair":false}
{"channel":"live_orders_btcusd","interaction_index":461,"natural_form":{"channel":"live_orders_btcusd","order_id":"2044303881162753","order_subtype":5,"order_type":1},"natural_form_sha256":"dc8ca2a75825f2516bddd0ee274ff284d7a6797d9a56001708257aa5857f9922","order_source":"orderbook","orders_submitted":0,"presentation":{"amount":"0.10000000","amount_traded":"0","microtimestamp":"1787932601894000","price":"78522.62"},"previous_record_hash":"9dcfebdd979afdc51e8c7849bca57e05dcedbedb72f31da42710282f7bc8c67a","profit_assessment":null,"record_hash":"9a4161b0e21a3b675f51bfd8bb5ab277f595363bdaf5af13890dd1d032341658","recorded_unix_us":1787932601946548,"recorded_utc":"2026-08-28T15:56:41.946548Z","schema_version":"nrrf810.exchange_authored_interactive_closure.v1","source_chain_continuous":true,"source_event":"order_deleted","source_event_id":"00065a1d-7f9e-4470-0001-000101000020","source_event_id_unique":true,"source_pre_event_id":"00065a1d-7f9e-4470-0000-000100000020","translation":"FOLD_RETURN_TO_ZERO","unfold_event_id":"00065a1d-7f9e-4470-0000-000100000020","zero_hair":true}
{"channel":"live_orders_btcusd","interaction_index":462,"natural_form":{"channel":"live_orders_btcusd","order_id":"2044303881166852","order_subtype":5,"order_type":1},"natural_form_sha256":"dc8ec3d0b2ea7e796787811b747f980c271569b30bcb67906feaf7c8f55c1e45","order_source":"orderbook","orders_submitted":0,"presentation":{"amount":"0.10000000","amount_traded":"0","microtimestamp":"1787932601895000","price":"78522.63"},"previous_record_hash":"9a4161b0e21a3b675f51bfd8bb5ab277f595363bdaf5af13890dd1d032341658","profit_assessment":null,"record_hash":"e43e8e7281885db7d90e40c3027a025ce2cf785814e2c790ff0cc5c7abce983a","recorded_unix_us":1787932601946572,"recorded_utc":"2026-08-28T15:56:41.946572Z","schema_version":"nrrf810.exchange_authored_interactive_closure.v1","source_chain_continuous":true,"source_event":"order_created","source_event_id":"00065a1d-7f9e-4858-0000-000102000020","source_event_id_unique":true,"source_pre_event_id":"00065a1d-7f9e-4470-0001-000101000020","translation":"UNFOLD_TO_INF","unfold_event_id":null,"zero_hair":false}
{"channel":"live_orders_btcusd","interaction_index":463,"natural_form":{"channel":"live_orders_btcusd","order_id":"2044303881166852","order_subtype":5,"order_type":1},"natural_form_sha256":"dc8ec3d0b2ea7e796787811b747f980c271569b30bcb67906feaf7c8f55c1e45","order_source":"orderbook","orders_submitted":0,"presentation":{"amount":"0.10000000","amount_traded":"0","microtimestamp":"1787932601895000","price":"78522.63"},"previous_record_hash":"e43e8e7281885db7d90e40c3027a025ce2cf785814e2c790ff0cc5c7abce983a","profit_assessment":null,"record_hash":"5e471fd88f5dc30f33c6c6e46dec1c32269400f59350103a48ff7a3cbafb0305","recorded_unix_us":1787932601946592,"recorded_utc":"2026-08-28T15:56:41.946592Z","schema_version":"nrrf810.exchange_authored_interactive_closure.v1","source_chain_continuous":true,"source_event":"order_deleted","source_event_id":"00065a1d-7f9e-4858-0001-000103000020","source_event_id_unique":true,"source_pre_event_id":"00065a1d-7f9e-4858-0000-000102000020","translation":"FOLD_RETURN_TO_ZERO","unfold_event_id":"00065a1d-7f9e-4858-0000-000102000020","zero_hair":true}
{"channel":"live_orders_ethbtc","interaction_index":464,"natural_form":{"channel":"live_orders_ethbtc","order_id":"2044303872139264","order_subtype":5,"order_type":1},"natural_form_sha256":"e8e39e714ef50eab79f7181e4141fa92087fed2b29e66a9967fcc22989b2e71c","order_source":"orderbook","orders_submitted":0,"presentation":{"amount":"1.56076612","amount_traded":"0","microtimestamp":"1787932601896000","price":"0.03317759"},"previous_record_hash":"5e471fd88f5dc30f33c6c6e46dec1c32269400f59350103a48ff7a3cbafb0305","profit_assessment":null,"record_hash":"bad5e05c55a699ac14305ba1b726d27fabd796e7710ca35e61f5e8f3d94f477b","recorded_unix_us":1787932601946612,"recorded_utc":"2026-08-28T15:56:41.946612Z","schema_version":"nrrf810.exchange_authored_interactive_closure.v1","source_chain_continuous":true,"source_event":"order_deleted","source_event_id":"00065a1d-7f9e-4c40-0000-001103000020","source_event_id_unique":true,"source_pre_event_id":"00065a1d-7f9e-2918-0002-001102000020","translation":"PARTIAL_PRIOR_UNFOLD","unfold_event_id":null,"zero_hair":false}
{"channel":"live_orders_btcusd","interaction_index":465,"natural_form":{"channel":"live_orders_btcusd","order_id":"2044303881175053","order_subtype":5,"order_type":0},"natural_form_sha256":"35dc680f1a7505a1eaba930b8ff910d4ea9b40dcd543c386d29d48fdfa2cf5b5","order_source":"orderbook","orders_submitted":0,"presentation":{"amount":"0.06368031","amount_traded":"0","microtimestamp":"1787932601898000","price":"78517.20"},"previous_record_hash":"bad5e05c55a699ac14305ba1b726d27fabd796e7710ca35e61f5e8f3d94f477b","profit_assessment":null,"record_hash":"f4c7622df3f20a2242835f8859863c39b00450123d55095873d322e7c88ff72c","recorded_unix_us":1787932601946729,"recorded_utc":"2026-08-28T15:56:41.946729Z","schema_version":"nrrf810.exchange_authored_interactive_closure.v1","source_chain_continuous":true,"source_event":"order_created","source_event_id":"00065a1d-7f9e-5410-0000-000100000020","source_event_id_unique":true,"source_pre_event_id":"00065a1d-7f9e-4858-0001-000103000020","translation":"UNFOLD_TO_INF","unfold_event_id":null,"zero_hair":false}
{"channel":"live_orders_btcusd","interaction_index":466,"natural_form":{"channel":"live_orders_btcusd","order_id":"2044303881191426","order_subtype":5,"order_type":0},"natural_form_sha256":"d0aacac317399e5afbd6b5206d888ebb855d30bc785dbc4b66a39fa0407fa443","order_source":"orderbook","orders_submitted":0,"presentation":{"amount":"0.19103753","amount_traded":"0","microtimestamp":"1787932601901000","price":"78485.11"},"previous_record_hash":"f4c7622df3f20a2242835f8859863c39b00450123d55095873d322e7c88ff72c","profit_assessment":null,"record_hash":"aa55e1188068b4dd98c2d295a9ac49c685499c2354a06c3b915e05378fc607e2","recorded_unix_us":1787932601946760,"recorded_utc":"2026-08-28T15:56:41.946760Z","schema_version":"nrrf810.exchange_authored_interactive_closure.v1","source_chain_continuous":true,"source_event":"order_created","source_event_id":"00065a1d-7f9e-5fc8-0000-000101000020","source_event_id_unique":true,"source_pre_event_id":"00065a1d-7f9e-5410-0000-000100000020","translation":"UNFOLD_TO_INF","unfold_event_id":null,"zero_hair":false}
{"channel":"live_orders_btcusd","interaction_index":467,"natural_form":{"channel":"live_orders_btcusd","order_id":"2044303880880133","order_subtype":5,"order_type":0},"natural_form_sha256":"a85495aca8a26f7169691256005ccf06dcc82c255c9fb5346d30903ae3fd30e0","order_source":"orderbook","orders_submitted":0,"presentation":{"amount":"0.00140266","amount_traded":"0","microtimestamp":"1787932601904000","price":"70667.51"},"previous_record_hash":"aa55e1188068b4dd98c2d295a9ac49c685499c2354a06c3b915e05378fc607e2","profit_assessment":null,"record_hash":"7f2e19656309cbf60ea7828cf7c4c12de389ce82423deb0f191f922af6060f7c","recorded_unix_us":1787932601946888,"recorded_utc":"2026-08-28T15:56:41.946888Z","schema_version":"nrrf810.exchange_authored_interactive_closure.v1","source_chain_continuous":true,"source_event":"order_deleted","source_event_id":"00065a1d-7f9e-6b80-0000-000102000020","source_event_id_unique":true,"source_pre_event_id":"00065a1d-7f9e-5fc8-0000-000101000020","translation":"FOLD_RETURN_TO_ZERO","unfold_event_id":"00065a1d-7f9d-36e8-0000-000100000020","zero_hair":true}
{"channel":"live_orders_btcusd","interaction_index":468,"natural_form":{"channel":"live_orders_btcusd","order_id":"2044303880556544","order_subtype":5,"order_type":0},"natural_form_sha256":"d5f6d6a099730706d8b6f5f5cfe9e836329eff788b4131d7fe08f83869316124","order_source":"orderbook","orders_submitted":0,"presentation":{"amount":"0.00140266","amount_traded":"0","microtimestamp":"1787932601904000","price":"70667.51"},"previous_record_hash":"7f2e19656309cbf60ea7828cf7c4c12de389ce82423deb0f191f922af6060f7c","profit_assessment":null,"record_hash":"e73d9eb0e05ce10ff1036bc8f1cc5b367cf3c61026fc6e75e9326a532d709309","recorded_unix_us":1787932601946912,"recorded_utc":"2026-08-28T15:56:41.946912Z","schema_version":"nrrf810.exchange_authored_interactive_closure.v1","source_chain_continuous":true,"source_event":"order_deleted","source_event_id":"00065a1d-7f9e-6b80-0001-000103000020","source_event_id_unique":true,"source_pre_event_id":"00065a1d-7f9e-6b80-0000-000102000020","translation":"FOLD_RETURN_TO_ZERO","unfold_event_id":"00065a1d-7f9c-0250-0000-000101000020","zero_hair":true}
{"channel":"live_orders_btcusd","interaction_index":469,"natural_form":{"channel":"live_orders_btcusd","order_id":"2044303881207816","order_subtype":5,"order_type":0},"natural_form_sha256":"c10908825e24d5bd3704b05546d0a05d1d6b6b86ef8c7a0d8f2609c3415ff0fa","order_source":"orderbook","orders_submitted":0,"presentation":{"amount":"0.00140266","amount_traded":"0","microtimestamp":"1787932601906000","price":"70667.51"},"previous_record_hash":"e73d9eb0e05ce10ff1036bc8f1cc5b367cf3c61026fc6e75e9326a532d709309","profit_assessment":null,"record_hash":"fb2f57d627981e8364b98085d174703bf74609f82d062fa5eeff9d4a84af0f58","recorded_unix_us":1787932601946969,"recorded_utc":"2026-08-28T15:56:41.946969Z","schema_version":"nrrf810.exchange_authored_interactive_closure.v1","source_chain_continuous":true,"source_event":"order_created","source_event_id":"00065a1d-7f9e-7350-0000-000100000020","source_event_id_unique":true,"source_pre_event_id":"00065a1d-7f9e-6b80-0001-000103000020","translation":"UNFOLD_TO_INF","unfold_event_id":null,"zero_hair":false}
{"channel":"live_orders_btcusd","interaction_index":470,"natural_form":{"channel":"live_orders_btcusd","order_id":"2044303881207816","order_subtype":5,"order_type":0},"natural_form_sha256":"c10908825e24d5bd3704b05546d0a05d1d6b6b86ef8c7a0d8f2609c3415ff0fa","order_source":"orderbook","orders_submitted":0,"presentation":{"amount":"0.00140266","amount_traded":"0","microtimestamp":"1787932601909000","price":"70667.51"},"previous_record_hash":"fb2f57d627981e8364b98085d174703bf74609f82d062fa5eeff9d4a84af0f58","profit_assessment":null,"record_hash":"3d31088bf952f3ea6d24a78af39926dda763929ee21f77f0610971ffa2fc1853","recorded_unix_us":1787932601947085,"recorded_utc":"2026-08-28T15:56:41.947085Z","schema_version":"nrrf810.exchange_authored_interactive_closure.v1","source_chain_continuous":true,"source_event":"order_deleted","source_event_id":"00065a1d-7f9e-7f08-0000-000101000020","source_event_id_unique":true,"source_pre_event_id":"00065a1d-7f9e-7350-0000-000100000020","translation":"FOLD_RETURN_TO_ZERO","unfold_event_id":"00065a1d-7f9e-7350-0000-000100000020","zero_hair":true}
{"channel":"live_orders_ethusd","interaction_index":471,"natural_form":{"channel":"live_orders_ethusd","order_id":"2044303881240580","order_subtype":5,"order_type":1},"natural_form_sha256":"161a666f1f1c458cbdf5652c8a619ddae5a83b3591af0556b0af22de46c48ae9","order_source":"orderbook","orders_submitted":0,"presentation":{"amount":"12.086599","amount_traded":"0","microtimestamp":"1787932601913000","price":"2482.09"},"previous_record_hash":"3d31088bf952f3ea6d24a78af39926dda763929ee21f77f0610971ffa2fc1853","profit_assessment":null,"record_hash":"9b24e57004f04c4c7f2762f8ac10b55a759446364cdc7c93e0fed1dc98c35329","recorded_unix_us":1787932601960277,"recorded_utc":"2026-08-28T15:56:41.960277Z","schema_version":"nrrf810.exchange_authored_interactive_closure.v1","source_chain_continuous":true,"source_event":"order_created","source_event_id":"00065a1d-7f9e-8ea8-0000-001203000020","source_event_id_unique":true,"source_pre_event_id":"00065a1d-7f9e-4088-0000-001202000020","translation":"UNFOLD_TO_INF","unfold_event_id":null,"zero_hair":false}
{"channel":"live_orders_btcusd","interaction_index":472,"natural_form":{"channel":"live_orders_btcusd","order_id":"2044303881240586","order_subtype":5,"order_type":1},"natural_form_sha256":"a01ba4519d3f52a9abe39e2fd1bbe69039d405a59ee863e6eba47448f1628abd","order_source":"orderbook","orders_submitted":0,"presentation":{"amount":"0.06310787","amount_traded":"0","microtimestamp":"1787932601914000","price":"78521.24"},"previous_record_hash":"9b24e57004f04c4c7f2762f8ac10b55a759446364cdc7c93e0fed1dc98c35329","profit_assessment":null,"record_hash":"66bb4bbda13b1b96b8fb0d85a9057811f0f0b65c4b63023312e03a0c7e34d118","recorded_unix_us":1787932601960458,"recorded_utc":"2026-08-28T15:56:41.960458Z","schema_version":"nrrf810.exchange_authored_interactive_closure.v1","source_chain_continuous":true,"source_event":"order_created","source_event_id":"00065a1d-7f9e-9290-0000-000102000020","source_event_id_unique":true,"source_pre_event_id":"00065a1d-7f9e-7f08-0000-000101000020","translation":"UNFOLD_TO_INF","unfold_event_id":null,"zero_hair":false}
{"channel":"live_orders_btcusd","interaction_index":473,"natural_form":{"channel":"live_orders_btcusd","order_id":"2044303881240586","order_subtype":5,"order_type":1},"natural_form_sha256":"a01ba4519d3f52a9abe39e2fd1bbe69039d405a59ee863e6eba47448f1628abd","order_source":"orderbook","orders_submitted":0,"presentation":{"amount":"0.06310787","amount_traded":"0","microtimestamp":"1787932601914000","price":"78521.24"},"previous_record_hash":"66bb4bbda13b1b96b8fb0d85a9057811f0f0b65c4b63023312e03a0c7e34d118","profit_assessment":null,"record_hash":"19c1f13224f8ac1c03a0d9c4f4f7713a67a66126b9288c00753c82e2b4f72c7c","recorded_unix_us":1787932601960499,"recorded_utc":"2026-08-28T15:56:41.960499Z","schema_version":"nrrf810.exchange_authored_interactive_closure.v1","source_chain_continuous":true,"source_event":"order_deleted","source_event_id":"00065a1d-7f9e-9290-0001-000103000020","source_event_id_unique":true,"source_pre_event_id":"00065a1d-7f9e-9290-0000-000102000020","translation":"FOLD_RETURN_TO_ZERO","unfold_event_id":"00065a1d-7f9e-9290-0000-000102000020","zero_hair":true}
{"channel":"live_orders_ethusd","interaction_index":474,"natural_form":{"channel":"live_orders_ethusd","order_id":"2044303881244674","order_subtype":5,"order_type":1},"natural_form_sha256":"c0eb005599c497e7f32e6e1a1e3e9b82772394e8874b781727aacfadf18937d6","order_source":"orderbook","orders_submitted":0,"presentation":{"amount":"4.028003","amount_traded":"0","microtimestamp":"1787932601914000","price":"2482.62"},"previous_record_hash":"19c1f13224f8ac1c03a0d9c4f4f7713a67a66126b9288c00753c82e2b4f72c7c","profit_assessment":null,"record_hash":"ca44097b357a7628a11b81cefe944dfad70d6f3ac5e026116550b19a684f8ea3","recorded_unix_us":1787932601960584,"recorded_utc":"2026-08-28T15:56:41.960584Z","schema_version":"nrrf810.exchange_authored_interactive_closure.v1","source_chain_continuous":true,"source_event":"order_created","source_event_id":"00065a1d-7f9e-9290-0000-001200000020","source_event_id_unique":true,"source_pre_event_id":"00065a1d-7f9e-8ea8-0000-001203000020","translation":"UNFOLD_TO_INF","unfold_event_id":null,"zero_hair":false}
{"channel":"live_orders_ethusd","interaction_index":475,"natural_form":{"channel":"live_orders_ethusd","order_id":"2044303881244675","order_subtype":5,"order_type":0},"natural_form_sha256":"3cc74411f7ee47b287eb241a2212021bba7c41950b2785af33ee56a382a902d7","order_source":"orderbook","orders_submitted":0,"presentation":{"amount":"0.043457","amount_traded":"0","microtimestamp":"1787932601914000","price":"2480.73"},"previous_record_hash":"ca44097b357a7628a11b81cefe944dfad70d6f3ac5e026116550b19a684f8ea3","profit_assessment":null,"record_hash":"d0711d7542c1ff26cb9feddf1c9b1cc5655485678e80a9437f981092ff11e392","recorded_unix_us":1787932601960660,"recorded_utc":"2026-08-28T15:56:41.960660Z","schema_version":"nrrf810.exchange_authored_interactive_closure.v1","source_chain_continuous":true,"source_event":"order_created","source_event_id":"00065a1d-7f9e-9290-0001-001201000020","source_event_id_unique":true,"source_pre_event_id":"00065a1d-7f9e-9290-0000-001200000020","translation":"UNFOLD_TO_INF","unfold_event_id":null,"zero_hair":false}
{"channel":"live_orders_ethusd","interaction_index":476,"natural_form":{"channel":"live_orders_ethusd","order_id":"2044303881244688","order_subtype":5,"order_type":1},"natural_form_sha256":"02658ad873068450f9d68e2b07499ffb58ff2764c6feb6a57dd66bab9318ff79","order_source":"orderbook","orders_submitted":0,"presentation":{"amount":"10.059779","amount_traded":"0","microtimestamp":"1787932601915000","price":"2485.15"},"previous_record_hash":"d0711d7542c1ff26cb9feddf1c9b1cc5655485678e80a9437f981092ff11e392","profit_assessment":null,"record_hash":"7014fec9c3037ded268f73a3f8397fc612ad497f8dfeac57994ea6eaf2a6537e","recorded_unix_us":1787932601960734,"recorded_utc":"2026-08-28T15:56:41.960734Z","schema_version":"nrrf810.exchange_authored_interactive_closure.v1","source_chain_continuous":true,"source_event":"order_created","source_event_id":"00065a1d-7f9e-9678-0000-001202000020","source_event_id_unique":true,"source_pre_event_id":"00065a1d-7f9e-9290-0001-001201000020","translation":"UNFOLD_TO_INF","unfold_event_id":null,"zero_hair":false}
{"channel":"live_orders_ethusd","interaction_index":477,"natural_form":{"channel":"live_orders_ethusd","order_id":"2044303881252867","order_subtype":5,"order_type":1},"natural_form_sha256":"11f7659d1d62ad535b4c446e0bcf664f3d9248f2b06f6e98f74d81e232000660","order_source":"orderbook","orders_submitted":0,"presentation":{"amount":"12.087961","amount_traded":"0","microtimestamp":"1787932601916000","price":"2481.81"},"previous_record_hash":"7014fec9c3037ded268f73a3f8397fc612ad497f8dfeac57994ea6eaf2a6537e","profit_assessment":null,"record_hash":"435ab84c8e75e4dc5beefcc442fce5003d70454e516bb9a39d680dba8014fdf8","recorded_unix_us":1787932601960804,"recorded_utc":"2026-08-28T15:56:41.960804Z","schema_version":"nrrf810.exchange_authored_interactive_closure.v1","source_chain_continuous":true,"source_event":"order_created","source_event_id":"00065a1d-7f9e-9a60-0000-001203000020","source_event_id_unique":true,"source_pre_event_id":"00065a1d-7f9e-9678-0000-001202000020","translation":"UNFOLD_TO_INF","unfold_event_id":null,"zero_hair":false}
{"channel":"live_orders_ethusd","interaction_index":478,"natural_form":{"channel":"live_orders_ethusd","order_id":"2044303881297922","order_subtype":5,"order_type":1},"natural_form_sha256":"928e9518853b286d68dcfaf51943e77580041a6ab63db4fa233ba965c5fa58ae","order_source":"orderbook","orders_submitted":0,"presentation":{"amount":"20.063885","amount_traded":"0","microtimestamp":"1787932601927000","price":"2492.04"},"previous_record_hash":"435ab84c8e75e4dc5beefcc442fce5003d70454e516bb9a39d680dba8014fdf8","profit_assessment":null,"record_hash":"2589085fe24ec9580c89c6e4d7bdfc6cf0dd68fc9cd9c07a2ebe2d33f87bc5d9","recorded_unix_us":1787932601976517,"recorded_utc":"2026-08-28T15:56:41.976517Z","schema_version":"nrrf810.exchange_authored_interactive_closure.v1","source_chain_continuous":true,"source_event":"order_created","source_event_id":"00065a1d-7f9e-c558-0000-001200000020","source_event_id_unique":true,"source_pre_event_id":"00065a1d-7f9e-9a60-0000-001203000020","translation":"UNFOLD_TO_INF","unfold_event_id":null,"zero_hair":false}
{"channel":"live_orders_btcusd","interaction_index":479,"natural_form":{"channel":"live_orders_btcusd","order_id":"2044303881297923","order_subtype":5,"order_type":1},"natural_form_sha256":"b31bbb40bae59f650ad6f74d755372c36106fa166ef8598d7a80a4e52814678c","order_source":"orderbook","orders_submitted":0,"presentation":{"amount":"0.10000000","amount_traded":"0","microtimestamp":"1787932601928000","price":"78522.62"},"previous_record_hash":"2589085fe24ec9580c89c6e4d7bdfc6cf0dd68fc9cd9c07a2ebe2d33f87bc5d9","profit_assessment":null,"record_hash":"e689b68cc8397f59aeb221061671a2a6e9d7f42e6d074e3448a3d0371fcc5c5e","recorded_unix_us":1787932601977017,"recorded_utc":"2026-08-28T15:56:41.977017Z","schema_version":"nrrf810.exchange_authored_interactive_closure.v1","source_chain_continuous":true,"source_event":"order_created","source_event_id":"00065a1d-7f9e-c940-0000-000100000020","source_event_id_unique":true,"source_pre_event_id":"00065a1d-7f9e-9290-0001-000103000020","translation":"UNFOLD_TO_INF","unfold_event_id":null,"zero_hair":false}
{"channel":"live_orders_btcusd","interaction_index":480,"natural_form":{"channel":"live_orders_btcusd","order_id":"2044303881297923","order_subtype":5,"order_type":1},"natural_form_sha256":"b31bbb40bae59f650ad6f74d755372c36106fa166ef8598d7a80a4e52814678c","order_source":"orderbook","orders_submitted":0,"presentation":{"amount":"0.10000000","amount_traded":"0","microtimestamp":"1787932601928000","price":"78522.62"},"previous_record_hash":"e689b68cc8397f59aeb221061671a2a6e9d7f42e6d074e3448a3d0371fcc5c5e","profit_assessment":null,"record_hash":"42e8a65623111bde9b2c5826a0ce19824110edf9684fd98089419effe958eac0","recorded_unix_us":1787932601977073,"recorded_utc":"2026-08-28T15:56:41.977073Z","schema_version":"nrrf810.exchange_authored_interactive_closure.v1","source_chain_continuous":true,"source_event":"order_deleted","source_event_id":"00065a1d-7f9e-c940-0001-000101000020","source_event_id_unique":true,"source_pre_event_id":"00065a1d-7f9e-c940-0000-000100000020","translation":"FOLD_RETURN_TO_ZERO","unfold_event_id":"00065a1d-7f9e-c940-0000-000100000020","zero_hair":true}
{"channel":"live_orders_ethusd","interaction_index":481,"natural_form":{"channel":"live_orders_ethusd","order_id":"2044303881302021","order_subtype":5,"order_type":0},"natural_form_sha256":"dbb7455894a90e33c66f709fa260ffb01200295cc4f712ab171e0fc12c582f81","order_source":"orderbook","orders_submitted":0,"presentation":{"amount":"12.096046","amount_traded":"0","microtimestamp":"1787932601929000","price":"2480.14"},"previous_record_hash":"42e8a65623111bde9b2c5826a0ce19824110edf9684fd98089419effe958eac0","profit_assessment":null,"record_hash":"a76e7babc3b7ce2d6ac036e90385ac58e74a431a37d0a759c749dac4539d8c42","recorded_unix_us":1787932601977102,"recorded_utc":"2026-08-28T15:56:41.977102Z","schema_version":"nrrf810.exchange_authored_interactive_closure.v1","source_chain_continuous":true,"source_event":"order_created","source_event_id":"00065a1d-7f9e-cd28-0000-001201000020","source_event_id_unique":true,"source_pre_event_id":"00065a1d-7f9e-c558-0000-001200000020","translation":"UNFOLD_TO_INF","unfold_event_id":null,"zero_hair":false}
{"channel":"live_orders_ethusd","interaction_index":482,"natural_form":{"channel":"live_orders_ethusd","order_id":"2044303881306112","order_subtype":5,"order_type":1},"natural_form_sha256":"f84e429699388a7502f88fdfe3f9104855c16a8e56a90eaf6d5f66a497edfc35","order_source":"orderbook","orders_submitted":0,"presentation":{"amount":"40.010118","amount_traded":"0","microtimestamp":"1787932601929000","price":"2499.37"},"previous_record_hash":"a76e7babc3b7ce2d6ac036e90385ac58e74a431a37d0a759c749dac4539d8c42","profit_assessment":null,"record_hash":"1fff3b447706a585d3b9647e34017fd824f2287f58a860dc6f148dfd175ebc5c","recorded_unix_us":1787932601985556,"recorded_utc":"2026-08-28T15:56:41.985556Z","schema_version":"nrrf810.exchange_authored_interactive_closure.v1","source_chain_continuous":true,"source_event":"order_created","source_event_id":"00065a1d-7f9e-cd28-0001-001202000020","source_event_id_unique":true,"source_pre_event_id":"00065a1d-7f9e-cd28-0000-001201000020","translation":"UNFOLD_TO_INF","unfold_event_id":null,"zero_hair":false}
{"channel":"live_orders_btcusd","interaction_index":483,"natural_form":{"channel":"live_orders_btcusd","order_id":"2044303881306113","order_subtype":5,"order_type":1},"natural_form_sha256":"87268e43dafc5fb9ed9cbebfb0325861596851c70bdfe9ec987b24790c5b2000","order_source":"orderbook","orders_submitted":0,"presentation":{"amount":"0.10000000","amount_traded":"0","microtimestamp":"1787932601929000","price":"78522.63"},"previous_record_hash":"1fff3b447706a585d3b9647e34017fd824f2287f58a860dc6f148dfd175ebc5c","profit_assessment":null,"record_hash":"1b9deb2d00bce582a7d2225753a15386e3884080d583ac0795db2ae8852b393c","recorded_unix_us":1787932601985792,"recorded_utc":"2026-08-28T15:56:41.985792Z","schema_version":"nrrf810.exchange_authored_interactive_closure.v1","source_chain_continuous":true,"source_event":"order_created","source_event_id":"00065a1d-7f9e-cd28-0000-000102000020","source_event_id_unique":true,"source_pre_event_id":"00065a1d-7f9e-c940-0001-000101000020","translation":"UNFOLD_TO_INF","unfold_event_id":null,"zero_hair":false}
{"channel":"live_orders_btcusd","interaction_index":484,"natural_form":{"channel":"live_orders_btcusd","order_id":"2044303881306113","order_subtype":5,"order_type":1},"natural_form_sha256":"87268e43dafc5fb9ed9cbebfb0325861596851c70bdfe9ec987b24790c5b2000","order_source":"orderbook","orders_submitted":0,"presentation":{"amount":"0.10000000","amount_traded":"0","microtimestamp":"1787932601929000","price":"78522.63"},"previous_record_hash":"1b9deb2d00bce582a7d2225753a15386e3884080d583ac0795db2ae8852b393c","profit_assessment":null,"record_hash":"ec1880c2429b8f96d4b21a2aab65c89928cb1f11136a3a542ae375a67c80c50d","recorded_unix_us":1787932601985924,"recorded_utc":"2026-08-28T15:56:41.985924Z","schema_version":"nrrf810.exchange_authored_interactive_closure.v1","source_chain_continuous":true,"source_event":"order_deleted","source_event_id":"00065a1d-7f9e-cd28-0001-000103000020","source_event_id_unique":true,"source_pre_event_id":"00065a1d-7f9e-cd28-0000-000102000020","translation":"FOLD_RETURN_TO_ZERO","unfold_event_id":"00065a1d-7f9e-cd28-0000-000102000020","zero_hair":true}
{"channel":"live_orders_ethusd","interaction_index":485,"natural_form":{"channel":"live_orders_ethusd","order_id":"2044303881322500","order_subtype":5,"order_type":0},"natural_form_sha256":"cb2142d2b4a280a3a20d76f6edb5f3838eee64eba6bb41be356cf666036ced73","order_source":"orderbook","orders_submitted":0,"presentation":{"amount":"12.097180","amount_traded":"0","microtimestamp":"1787932601933000","price":"2479.91"},"previous_record_hash":"ec1880c2429b8f96d4b21a2aab65c89928cb1f11136a3a542ae375a67c80c50d","profit_assessment":null,"record_hash":"1a1133c9083e2f336a8c012c120247ab4b7e21558c2a54e5fe620609d4474204","recorded_unix_us":1787932601986036,"recorded_utc":"2026-08-28T15:56:41.986036Z","schema_version":"nrrf810.exchange_authored_interactive_closure.v1","source_chain_continuous":true,"source_event":"order_created","source_event_id":"00065a1d-7f9e-dcc8-0000-001203000020","source_event_id_unique":true,"source_pre_event_id":"00065a1d-7f9e-cd28-0001-001202000020","translation":"UNFOLD_TO_INF","unfold_event_id":null,"zero_hair":false}
{"channel":"live_orders_ethusd","interaction_index":486,"natural_form":{"channel":"live_orders_ethusd","order_id":"2044303881347095","order_subtype":5,"order_type":0},"natural_form_sha256":"8900a8fc481300b28d1d89fa9387751bf643441ea59fe387c6e759ee8f8917e3","order_source":"orderbook","orders_submitted":0,"presentation":{"amount":"20.225289","amount_traded":"0","microtimestamp":"1787932601940000","price":"2472.15"},"previous_record_hash":"1a1133c9083e2f336a8c012c120247ab4b7e21558c2a54e5fe620609d4474204","profit_assessment":null,"record_hash":"329326334fec9029ae44a03ca079c8717c0e56d27e19c75e3dd6c6d2b2dadc76","recorded_unix_us":1787932601986152,"recorded_utc":"2026-08-28T15:56:41.986152Z","schema_version":"nrrf810.exchange_authored_interactive_closure.v1","source_chain_continuous":true,"source_event":"order_created","source_event_id":"00065a1d-7f9e-f820-0000-001200000020","source_event_id_unique":true,"source_pre_event_id":"00065a1d-7f9e-dcc8-0000-001203000020","translation":"UNFOLD_TO_INF","unfold_event_id":null,"zero_hair":false}
{"channel":"live_orders_ethusd","interaction_index":487,"natural_form":{"channel":"live_orders_ethusd","order_id":"2044303881355264","order_subtype":5,"order_type":0},"natural_form_sha256":"6c9cc2408a5dadf899536fa4cad6a8a394e2e328b5cfde7469dad2a382d3fc31","order_source":"orderbook","orders_submitted":0,"presentation":{"amount":"40.609081","amount_traded":"0","microtimestamp":"1787932601941000","price":"2462.50"},"previous_record_hash":"329326334fec9029ae44a03ca079c8717c0e56d27e19c75e3dd6c6d2b2dadc76","profit_assessment":null,"record_hash":"e4d44cabfb74a27528f8f36494346ad956a4c9eba03ea5a401145651ad1a28c5","recorded_unix_us":1787932601986252,"recorded_utc":"2026-08-28T15:56:41.986252Z","schema_version":"nrrf810.exchange_authored_interactive_closure.v1","source_chain_continuous":true,"source_event":"order_created","source_event_id":"00065a1d-7f9e-fc08-0000-001201000020","source_event_id_unique":true,"source_pre_event_id":"00065a1d-7f9e-f820-0000-001200000020","translation":"UNFOLD_TO_INF","unfold_event_id":null,"zero_hair":false}
{"channel":"live_orders_ethusd","interaction_index":488,"natural_form":{"channel":"live_orders_ethusd","order_id":"2044303881359361","order_subtype":5,"order_type":1},"natural_form_sha256":"f656b42d8cb2b85d767df30cf1d186e9d8e30a81fa1d685e5c45a2f19b644ea8","order_source":"orderbook","orders_submitted":0,"presentation":{"amount":"5.000000","amount_traded":"0","microtimestamp":"1787932601942000","price":"2481.77"},"previous_record_hash":"e4d44cabfb74a27528f8f36494346ad956a4c9eba03ea5a401145651ad1a28c5","profit_assessment":null,"record_hash":"ae7b9c09d9055bf6feb8aa65c5dc283bc43312afbf905824ca3d28e695beb108","recorded_unix_us":1787932601986364,"recorded_utc":"2026-08-28T15:56:41.986364Z","schema_version":"nrrf810.exchange_authored_interactive_closure.v1","source_chain_continuous":true,"source_event":"order_created","source_event_id":"00065a1d-7f9e-fff0-0000-001202000020","source_event_id_unique":true,"source_pre_event_id":"00065a1d-7f9e-fc08-0000-001201000020","translation":"UNFOLD_TO_INF","unfold_event_id":null,"zero_hair":false}
{"channel":"live_orders_ethusd","interaction_index":489,"natural_form":{"channel":"live_orders_ethusd","order_id":"2044303881359362","order_subtype":5,"order_type":1},"natural_form_sha256":"9fbe4ea1b300f0fd2a8974812db1b3fb0d91fb7e3ebfeecf0d43ee0de5a01a30","order_source":"orderbook","orders_submitted":0,"presentation":{"amount":"5.000000","amount_traded":"0","microtimestamp":"1787932601942000","price":"2481.52"},"previous_record_hash":"ae7b9c09d9055bf6feb8aa65c5dc283bc43312afbf905824ca3d28e695beb108","profit_assessment":null,"record_hash":"64768698b5e5cdaf327e59eddfce453506f59c3d428744b57aab59e1831d2e42","recorded_unix_us":1787932601986471,"recorded_utc":"2026-08-28T15:56:41.986471Z","schema_version":"nrrf810.exchange_authored_interactive_closure.v1","source_chain_continuous":true,"source_event":"order_created","source_event_id":"00065a1d-7f9e-fff0-0001-001203000020","source_event_id_unique":true,"source_pre_event_id":"00065a1d-7f9e-fff0-0000-001202000020","translation":"UNFOLD_TO_INF","unfold_event_id":null,"zero_hair":false}
{"channel":"live_orders_btcusd","interaction_index":490,"natural_form":{"channel":"live_orders_btcusd","order_id":"2044303881019403","order_subtype":5,"order_type":0},"natural_form_sha256":"27b04db54d44a105c9881a9702218c44d7b25092b2e95904a435282b6fa657a3","order_source":"orderbook","orders_submitted":0,"presentation":{"amount":"0.63679333","amount_traded":"0","microtimestamp":"1787932601948000","price":"78482.58"},"previous_record_hash":"64768698b5e5cdaf327e59eddfce453506f59c3d428744b57aab59e1831d2e42","profit_assessment":null,"record_hash":"010afe15eb7c0e463ea2da7c9f9a49d1cbd64575d4feb00093070b5036770dec","recorded_unix_us":1787932601995443,"recorded_utc":"2026-08-28T15:56:41.995443Z","schema_version":"nrrf810.exchange_authored_interactive_closure.v1","source_chain_continuous":true,"source_event":"order_deleted","source_event_id":"00065a1d-7f9f-1760-0000-000100000020","source_event_id_unique":true,"source_pre_event_id":"00065a1d-7f9e-cd28-0001-000103000020","translation":"FOLD_RETURN_TO_ZERO","unfold_event_id":"00065a1d-7f9d-bfa0-0000-000103000020","zero_hair":true}
{"channel":"live_orders_ethbtc","interaction_index":491,"natural_form":{"channel":"live_orders_ethbtc","order_id":"2044303881400320","order_subtype":5,"order_type":0},"natural_form_sha256":"73a5a8f4cff68538533aa29f4c255adbb9f4b74221f82856a92f60cb1692d864","order_source":"orderbook","orders_submitted":0,"presentation":{"amount":"0.24452731","amount_traded":"0","microtimestamp":"1787932601952000","price":"0.03020013"},"previous_record_hash":"010afe15eb7c0e463ea2da7c9f9a49d1cbd64575d4feb00093070b5036770dec","profit_assessment":null,"record_hash":"bb498a1f5453d8bf08f1b2076d679986361ff7adabc6a662726c651531f51d77","recorded_unix_us":1787932601995636,"recorded_utc":"2026-08-28T15:56:41.995636Z","schema_version":"nrrf810.exchange_authored_interactive_closure.v1","source_chain_continuous":true,"source_event":"order_created","source_event_id":"00065a1d-7f9f-2700-0000-001100000020","source_event_id_unique":true,"source_pre_event_id":"00065a1d-7f9e-4c40-0000-001103000020","translation":"UNFOLD_TO_INF","unfold_event_id":null,"zero_hair":false}
{"channel":"live_orders_btcusd","interaction_index":492,"natural_form":{"channel":"live_orders_btcusd","order_id":"2044303880122368","order_subtype":5,"order_type":0},"natural_form_sha256":"d08f4daef6a50bf09b00a2b9048b5e566174683e3d03e956d373bec3057135ef","order_source":"orderbook","orders_submitted":0,"presentation":{"amount":"0.26750492","amount_traded":"0","microtimestamp":"1787932601958000","price":"78482.59"},"previous_record_hash":"bb498a1f5453d8bf08f1b2076d679986361ff7adabc6a662726c651531f51d77","profit_assessment":null,"record_hash":"cc0f510954dd3664db68fe08a5492f48d6c82c11f854d55f8dd3269204e0759b","recorded_unix_us":1787932601995802,"recorded_utc":"2026-08-28T15:56:41.995802Z","schema_version":"nrrf810.exchange_authored_interactive_closure.v1","source_chain_continuous":true,"source_event":"order_deleted","source_event_id":"00065a1d-7f9f-3e70-0000-000101000020","source_event_id_unique":true,"source_pre_event_id":"00065a1d-7f9f-1760-0000-000100000020","translation":"FOLD_RETURN_TO_ZERO","unfold_event_id":"00065a1d-7f9a-6828-0001-000101000020","zero_hair":true}
{"channel":"live_orders_btcusd","interaction_index":493,"natural_form":{"channel":"live_orders_btcusd","order_id":"2044303881424900","order_subtype":5,"order_type":0},"natural_form_sha256":"26906b328e17dd42c7f79d4942d2103d0183f4e118ff38780636884eb7800173","order_source":"orderbook","orders_submitted":0,"presentation":{"amount":"0.26750492","amount_traded":"0","microtimestamp":"1787932601958000","price":"78482.59"},"previous_record_hash":"cc0f510954dd3664db68fe08a5492f48d6c82c11f854d55f8dd3269204e0759b","profit_assessment":null,"record_hash":"a1120e4174ef4e5444638e6795d20551366c792de0af0f1029aae778da0c4dbb","recorded_unix_us":1787932601995842,"recorded_utc":"2026-08-28T15:56:41.995842Z","schema_version":"nrrf810.exchange_authored_interactive_closure.v1","source_chain_continuous":true,"source_event":"order_created","source_event_id":"00065a1d-7f9f-3e70-0001-000102000020","source_event_id_unique":true,"source_pre_event_id":"00065a1d-7f9f-3e70-0000-000101000020","translation":"UNFOLD_TO_INF","unfold_event_id":null,"zero_hair":false}
{"channel":"live_orders_btcusd","interaction_index":494,"natural_form":{"channel":"live_orders_btcusd","order_id":"2044303881428997","order_subtype":5,"order_type":0},"natural_form_sha256":"d8f893affbe1c79a34057124a008c5ef4201d720f2fe23183db16064b3b43ae2","order_source":"orderbook","orders_submitted":0,"presentation":{"amount":"0.63679897","amount_traded":"0","microtimestamp":"1787932601959000","price":"78483.23"},"previous_record_hash":"a1120e4174ef4e5444638e6795d20551366c792de0af0f1029aae778da0c4dbb","profit_assessment":null,"record_hash":"afc748c4e4492821222af9796bb68db7a933477592ea54201219c8b5eea21eb6","recorded_unix_us":1787932601995939,"recorded_utc":"2026-08-28T15:56:41.995939Z","schema_version":"nrrf810.exchange_authored_interactive_closure.v1","source_chain_continuous":true,"source_event":"order_created","source_event_id":"00065a1d-7f9f-4258-0000-000103000020","source_event_id_unique":true,"source_pre_event_id":"00065a1d-7f9f-3e70-0001-000102000020","translation":"UNFOLD_TO_INF","unfold_event_id":null,"zero_hair":false}
{"channel":"live_orders_ethusd","interaction_index":495,"natural_form":{"channel":"live_orders_ethusd","order_id":"2044303881441288","order_subtype":5,"order_type":1},"natural_form_sha256":"eae264c4f2a21a2e7e8f4b1273732cb05e714b91f0d7943fb21ca25d9a32a4cb","order_source":"orderbook","orders_submitted":0,"presentation":{"amount":"4.027586","amount_traded":"0","microtimestamp":"1787932601963000","price":"2482.88"},"previous_record_hash":"afc748c4e4492821222af9796bb68db7a933477592ea54201219c8b5eea21eb6","profit_assessment":null,"record_hash":"ca21c5bb2aaa6ce7274d3c7d1ef4d48fde7a7fd5cb8a865f50519d7b23c22675","recorded_unix_us":1787932602009170,"recorded_utc":"2026-08-28T15:56:42.009170Z","schema_version":"nrrf810.exchange_authored_interactive_closure.v1","source_chain_continuous":true,"source_event":"order_created","source_event_id":"00065a1d-7f9f-51f8-0000-001200000020","source_event_id_unique":true,"source_pre_event_id":"00065a1d-7f9e-fff0-0001-001203000020","translation":"UNFOLD_TO_INF","unfold_event_id":null,"zero_hair":false}
{"channel":"live_orders_ethbtc","interaction_index":496,"natural_form":{"channel":"live_orders_ethbtc","order_id":"2044303881453575","order_subtype":5,"order_type":1},"natural_form_sha256":"1f42049fc7349be07af011624e47612702223e99e6031cf17a323f97aee43f62","order_source":"orderbook","orders_submitted":0,"presentation":{"amount":"0.20969786","amount_traded":"0","microtimestamp":"1787932601966000","price":"0.03348999"},"previous_record_hash":"ca21c5bb2aaa6ce7274d3c7d1ef4d48fde7a7fd5cb8a865f50519d7b23c22675","profit_assessment":null,"record_hash":"3da1f3b792c3fde1d4fe3559ce34b77e252feb2d6290653695e609047d4f195b","recorded_unix_us":1787932602009390,"recorded_utc":"2026-08-28T15:56:42.009390Z","schema_version":"nrrf810.exchange_authored_interactive_closure.v1","source_chain_continuous":true,"source_event":"order_created","source_event_id":"00065a1d-7f9f-5db0-0000-001101000020","source_event_id_unique":true,"source_pre_event_id":"00065a1d-7f9f-2700-0000-001100000020","translation":"UNFOLD_TO_INF","unfold_event_id":null,"zero_hair":false}
{"channel":"live_orders_ethusd","interaction_index":497,"natural_form":{"channel":"live_orders_ethusd","order_id":"2044303881457666","order_subtype":5,"order_type":0},"natural_form_sha256":"704314872c59d6ee8c1d80a4914be9067fc753261341493ca99061a78dd2357d","order_source":"orderbook","orders_submitted":0,"presentation":{"amount":"20.235437","amount_traded":"0","microtimestamp":"1787932601966000","price":"2470.91"},"previous_record_hash":"3da1f3b792c3fde1d4fe3559ce34b77e252feb2d6290653695e609047d4f195b","profit_assessment":null,"record_hash":"312da06c634cb4e4288b8a7485565b57ef6c415b59232231e502fa47706bab3b","recorded_unix_us":1787932602009519,"recorded_utc":"2026-08-28T15:56:42.009519Z","schema_version":"nrrf810.exchange_authored_interactive_closure.v1","source_chain_continuous":true,"source_event":"order_created","source_event_id":"00065a1d-7f9f-5db0-0000-001201000020","source_event_id_unique":true,"source_pre_event_id":"00065a1d-7f9f-51f8-0000-001200000020","translation":"UNFOLD_TO_INF","unfold_event_id":null,"zero_hair":false}
{"channel":"live_orders_btcusd","interaction_index":498,"natural_form":{"channel":"live_orders_btcusd","order_id":"2044303881457676","order_subtype":5,"order_type":1},"natural_form_sha256":"eb2baf841588485f7549dae5d8592fc10c8ae00403fa08aedaed3086a8bc9b3a","order_source":"orderbook","orders_submitted":0,"presentation":{"amount":"1.27113313","amount_traded":"0","microtimestamp":"1787932601967000","price":"78669.97"},"previous_record_hash":"312da06c634cb4e4288b8a7485565b57ef6c415b59232231e502fa47706bab3b","profit_assessment":null,"record_hash":"97544a8ec504dc99e78e297ede97d39da7ebcdead1a80922e11ead30f1e17999","recorded_unix_us":1787932602009616,"recorded_utc":"2026-08-28T15:56:42.009616Z","schema_version":"nrrf810.exchange_authored_interactive_closure.v1","source_chain_continuous":true,"source_event":"order_created","source_event_id":"00065a1d-7f9f-6198-0000-000100000020","source_event_id_unique":true,"source_pre_event_id":"00065a1d-7f9f-4258-0000-000103000020","translation":"UNFOLD_TO_INF","unfold_event_id":null,"zero_hair":false}
{"channel":"live_orders_btcusd","interaction_index":499,"natural_form":{"channel":"live_orders_btcusd","order_id":"2044303881474048","order_subtype":5,"order_type":1},"natural_form_sha256":"f4d45c87d6bdbca0f812d914341a8b4d957349f09300c3abf9523874eb8977a5","order_source":"orderbook","orders_submitted":0,"presentation":{"amount":"0.06310787","amount_traded":"0","microtimestamp":"1787932601970000","price":"78522.55"},"previous_record_hash":"97544a8ec504dc99e78e297ede97d39da7ebcdead1a80922e11ead30f1e17999","profit_assessment":null,"record_hash":"030278a871ffd797a8ccbd2ca350e893b1d9d00639053b217ea55a469d37de54","recorded_unix_us":1787932602009709,"recorded_utc":"2026-08-28T15:56:42.009709Z","schema_version":"nrrf810.exchange_authored_interactive_closure.v1","source_chain_continuous":true,"source_event":"order_created","source_event_id":"00065a1d-7f9f-6d50-0000-000101000020","source_event_id_unique":true,"source_pre_event_id":"00065a1d-7f9f-6198-0000-000100000020","translation":"UNFOLD_TO_INF","unfold_event_id":null,"zero_hair":false}
{"channel":"live_orders_btcusd","interaction_index":500,"natural_form":{"channel":"live_orders_btcusd","order_id":"2044303881474048","order_subtype":5,"order_type":1},"natural_form_sha256":"f4d45c87d6bdbca0f812d914341a8b4d957349f09300c3abf9523874eb8977a5","order_source":"orderbook","orders_submitted":0,"presentation":{"amount":"0.06310787","amount_traded":"0","microtimestamp":"1787932601970000","price":"78522.55"},"previous_record_hash":"030278a871ffd797a8ccbd2ca350e893b1d9d00639053b217ea55a469d37de54","profit_assessment":null,"record_hash":"fae3ee43b7c84ccc710622f7110b6f2e2525abc563ad60f3f768f99d2ae87ec3","recorded_unix_us":1787932602009801,"recorded_utc":"2026-08-28T15:56:42.009801Z","schema_version":"nrrf810.exchange_authored_interactive_closure.v1","source_chain_continuous":true,"source_event":"order_deleted","source_event_id":"00065a1d-7f9f-6d50-0001-000102000020","source_event_id_unique":true,"source_pre_event_id":"00065a1d-7f9f-6d50-0000-000101000020","translation":"FOLD_RETURN_TO_ZERO","unfold_event_id":"00065a1d-7f9f-6d50-0000-000101000020","zero_hair":true}
{"channel":"live_orders_ethusd","interaction_index":501,"natural_form":{"channel":"live_orders_ethusd","order_id":"2044303881359362","order_subtype":5,"order_type":1},"natural_form_sha256":"9fbe4ea1b300f0fd2a8974812db1b3fb0d91fb7e3ebfeecf0d43ee0de5a01a30","order_source":"orderbook","orders_submitted":0,"presentation":{"amount":"5.000000","amount_traded":"0","microtimestamp":"1787932601970000","price":"2481.52"},"previous_record_hash":"fae3ee43b7c84ccc710622f7110b6f2e2525abc563ad60f3f768f99d2ae87ec3","profit_assessment":null,"record_hash":"f13c275acd48d3934709def2e8522062c22a64c63ebbf3664bafc608dd0b5f70","recorded_unix_us":1787932602009930,"recorded_utc":"2026-08-28T15:56:42.009930Z","schema_version":"nrrf810.exchange_authored_interactive_closure.v1","source_chain_continuous":true,"source_event":"order_deleted","source_event_id":"00065a1d-7f9f-6d50-0000-001202000020","source_event_id_unique":true,"source_pre_event_id":"00065a1d-7f9f-5db0-0000-001201000020","translation":"FOLD_RETURN_TO_ZERO","unfold_event_id":"00065a1d-7f9e-fff0-0001-001203000020","zero_hair":true}
{"channel":"live_orders_ethusd","interaction_index":502,"natural_form":{"channel":"live_orders_ethusd","order_id":"2044303881359361","order_subtype":5,"order_type":1},"natural_form_sha256":"f656b42d8cb2b85d767df30cf1d186e9d8e30a81fa1d685e5c45a2f19b644ea8","order_source":"orderbook","orders_submitted":0,"presentation":{"amount":"5.000000","amount_traded":"0","microtimestamp":"1787932601970000","price":"2481.77"},"previous_record_hash":"f13c275acd48d3934709def2e8522062c22a64c63ebbf3664bafc608dd0b5f70","profit_assessment":null,"record_hash":"6efda71b4c716cb9695143ba7a7afe83bdd14be9da2421d33d255b8bf171a2c0","recorded_unix_us":1787932602009958,"recorded_utc":"2026-08-28T15:56:42.009958Z","schema_version":"nrrf810.exchange_authored_interactive_closure.v1","source_chain_continuous":true,"source_event":"order_deleted","source_event_id":"00065a1d-7f9f-6d50-0001-001203000020","source_event_id_unique":true,"source_pre_event_id":"00065a1d-7f9f-6d50-0000-001202000020","translation":"FOLD_RETURN_TO_ZERO","unfold_event_id":"00065a1d-7f9e-fff0-0000-001202000020","zero_hair":true}
{"channel":"live_orders_btcusd","interaction_index":503,"natural_form":{"channel":"live_orders_btcusd","order_id":"2044303881490433","order_subtype":5,"order_type":1},"natural_form_sha256":"3888cd2532ee44e6632d7e7fcad168565f2ce3eb5e8664ce319b00faecc6a15e","order_source":"orderbook","orders_submitted":0,"presentation":{"amount":"0.10000000","amount_traded":"0","microtimestamp":"1787932601974000","price":"78522.62"},"previous_record_hash":"6efda71b4c716cb9695143ba7a7afe83bdd14be9da2421d33d255b8bf171a2c0","profit_assessment":null,"record_hash":"a8a35f4965649b9ef6d5bd9da30389ee550250379e71e133bcf2dd4654a8ce85","recorded_unix_us":1787932602010127,"recorded_utc":"2026-08-28T15:56:42.010127Z","schema_version":"nrrf810.exchange_authored_interactive_closure.v1","source_chain_continuous":true,"source_event":"order_created","source_event_id":"00065a1d-7f9f-7cf0-0000-000103000020","source_event_id_unique":true,"source_pre_event_id":"00065a1d-7f9f-6d50-0001-000102000020","translation":"UNFOLD_TO_INF","unfold_event_id":null,"zero_hair":false}
{"channel":"live_orders_btcusd","interaction_index":504,"natural_form":{"channel":"live_orders_btcusd","order_id":"2044303881490433","order_subtype":5,"order_type":1},"natural_form_sha256":"3888cd2532ee44e6632d7e7fcad168565f2ce3eb5e8664ce319b00faecc6a15e","order_source":"orderbook","orders_submitted":0,"presentation":{"amount":"0.10000000","amount_traded":"0","microtimestamp":"1787932601974000","price":"78522.62"},"previous_record_hash":"a8a35f4965649b9ef6d5bd9da30389ee550250379e71e133bcf2dd4654a8ce85","profit_assessment":null,"record_hash":"f69d4a42d0d8c7160a2cef5db812467d48337978f7360419a568384fb7c92200","recorded_unix_us":1787932602010155,"recorded_utc":"2026-08-28T15:56:42.010155Z","schema_version":"nrrf810.exchange_authored_interactive_closure.v1","source_chain_continuous":true,"source_event":"order_deleted","source_event_id":"00065a1d-7f9f-7cf0-0001-000100000020","source_event_id_unique":true,"source_pre_event_id":"00065a1d-7f9f-7cf0-0000-000103000020","translation":"FOLD_RETURN_TO_ZERO","unfold_event_id":"00065a1d-7f9f-7cf0-0000-000103000020","zero_hair":true}
{"channel":"live_orders_btcusd","interaction_index":505,"natural_form":{"channel":"live_orders_btcusd","order_id":"2044303881490434","order_subtype":5,"order_type":1},"natural_form_sha256":"774bddae96b9cc9ce41d2f79b088ac80df6b7bd16536e254a97c487909ba5589","order_source":"orderbook","orders_submitted":0,"presentation":{"amount":"0.10000000","amount_traded":"0","microtimestamp":"1787932601974000","price":"78522.63"},"previous_record_hash":"f69d4a42d0d8c7160a2cef5db812467d48337978f7360419a568384fb7c92200","profit_assessment":null,"record_hash":"9be8917f54525581e2425d56c8e57983fce843ceb742d04bd5bde7a3482ae7e6","recorded_unix_us":1787932602010179,"recorded_utc":"2026-08-28T15:56:42.010179Z","schema_version":"nrrf810.exchange_authored_interactive_closure.v1","source_chain_continuous":true,"source_event":"order_created","source_event_id":"00065a1d-7f9f-7cf0-0002-000101000020","source_event_id_unique":true,"source_pre_event_id":"00065a1d-7f9f-7cf0-0001-000100000020","translation":"UNFOLD_TO_INF","unfold_event_id":null,"zero_hair":false}
{"channel":"live_orders_btcusd","interaction_index":506,"natural_form":{"channel":"live_orders_btcusd","order_id":"2044303881490434","order_subtype":5,"order_type":1},"natural_form_sha256":"774bddae96b9cc9ce41d2f79b088ac80df6b7bd16536e254a97c487909ba5589","order_source":"orderbook","orders_submitted":0,"presentation":{"amount":"0.10000000","amount_traded":"0","microtimestamp":"1787932601974000","price":"78522.63"},"previous_record_hash":"9be8917f54525581e2425d56c8e57983fce843ceb742d04bd5bde7a3482ae7e6","profit_assessment":null,"record_hash":"5a25b2e55199b37f22569d0f400e066e35ed357307fea40451741f4dae9c3b09","recorded_unix_us":1787932602010202,"recorded_utc":"2026-08-28T15:56:42.010202Z","schema_version":"nrrf810.exchange_authored_interactive_closure.v1","source_chain_continuous":true,"source_event":"order_deleted","source_event_id":"00065a1d-7f9f-7cf0-0003-000102000020","source_event_id_unique":true,"source_pre_event_id":"00065a1d-7f9f-7cf0-0002-000101000020","translation":"FOLD_RETURN_TO_ZERO","unfold_event_id":"00065a1d-7f9f-7cf0-0002-000101000020","zero_hair":true}
{"channel":"live_orders_btcusd","interaction_index":507,"natural_form":{"channel":"live_orders_btcusd","order_id":"2044303881023494","order_subtype":5,"order_type":0},"natural_form_sha256":"f5342056f98d60f7b6915a9975d75ace5eedd32d98cbb91871b42279d54381e1","order_source":"orderbook","orders_submitted":0,"presentation":{"amount":"0.50943466","amount_traded":"0","microtimestamp":"1787932601980000","price":"78480.62"},"previous_record_hash":"5a25b2e55199b37f22569d0f400e066e35ed357307fea40451741f4dae9c3b09","profit_assessment":null,"record_hash":"05b561a5ee67f7640f1d83c16e48a7c60752d6787a1db703ce70fc7f4babb4d7","recorded_unix_us":1787932602022224,"recorded_utc":"2026-08-28T15:56:42.022224Z","schema_version":"nrrf810.exchange_authored_interactive_closure.v1","source_chain_continuous":true,"source_event":"order_deleted","source_event_id":"00065a1d-7f9f-9460-0000-000103000020","source_event_id_unique":true,"source_pre_event_id":"00065a1d-7f9f-7cf0-0003-000102000020","translation":"FOLD_RETURN_TO_ZERO","unfold_event_id":"00065a1d-7f9d-bfa0-0001-000100000020","zero_hair":true}
{"channel":"live_orders_ethbtc","interaction_index":508,"natural_form":{"channel":"live_orders_ethbtc","order_id":"2044303881531399","order_subtype":5,"order_type":1},"natural_form_sha256":"ed4f7ea7c2cc9468d3344c7d970bed8b43da43b46727ad564672bac5a91dedf2","order_source":"orderbook","orders_submitted":0,"presentation":{"amount":"0.60448710","amount_traded":"0","microtimestamp":"1787932601985000","price":"0.03160362"},"previous_record_hash":"05b561a5ee67f7640f1d83c16e48a7c60752d6787a1db703ce70fc7f4babb4d7","profit_assessment":null,"record_hash":"0d4a381f331f97b270e587e1d9cd8e782ef081c5ca6396b8058b25d229995362","recorded_unix_us":1787932602022538,"recorded_utc":"2026-08-28T15:56:42.022538Z","schema_version":"nrrf810.exchange_authored_interactive_closure.v1","source_chain_continuous":true,"source_event":"order_created","source_event_id":"00065a1d-7f9f-a7e8-0000-001102000020","source_event_id_unique":true,"source_pre_event_id":"00065a1d-7f9f-5db0-0000-001101000020","translation":"UNFOLD_TO_INF","unfold_event_id":null,"zero_hair":false}
{"channel":"live_orders_ethbtc","interaction_index":509,"natural_form":{"channel":"live_orders_ethbtc","order_id":"2044303881543680","order_subtype":5,"order_type":1},"natural_form_sha256":"f1fa93a33e654422c0b6bdd323e5786702af4d2fa5cdd1f62951866b9aac0e1a","order_source":"orderbook","orders_submitted":0,"presentation":{"amount":"1.00736500","amount_traded":"0","microtimestamp":"1787932601987000","price":"0.03160719"},"previous_record_hash":"0d4a381f331f97b270e587e1d9cd8e782ef081c5ca6396b8058b25d229995362","profit_assessment":null,"record_hash":"c87162cf32bca1d897a26dc9715cffcc5436798ad0dd3a0493fe3a32c65078ec","recorded_unix_us":1787932602022682,"recorded_utc":"2026-08-28T15:56:42.022682Z","schema_version":"nrrf810.exchange_authored_interactive_closure.v1","source_chain_continuous":true,"source_event":"order_created","source_event_id":"00065a1d-7f9f-afb8-0000-001103000020","source_event_id_unique":true,"source_pre_event_id":"00065a1d-7f9f-a7e8-0000-001102000020","translation":"UNFOLD_TO_INF","unfold_event_id":null,"zero_hair":false}
{"channel":"live_orders_btcusd","interaction_index":510,"natural_form":{"channel":"live_orders_btcusd","order_id":"2044303881543684","order_subtype":5,"order_type":0},"natural_form_sha256":"164196f82261a758757ca703577db1c80c1be889d95398b6c92cf431df410c9e","order_source":"orderbook","orders_submitted":0,"presentation":{"amount":"0.00140266","amount_traded":"0","microtimestamp":"1787932601988000","price":"70667.93"},"previous_record_hash":"c87162cf32bca1d897a26dc9715cffcc5436798ad0dd3a0493fe3a32c65078ec","profit_assessment":null,"record_hash":"00c025ceb211be48bd991a43a88e9257d799a0a56f3d10dcd9977ecb01836619","recorded_unix_us":1787932602022717,"recorded_utc":"2026-08-28T15:56:42.022717Z","schema_version":"nrrf810.exchange_authored_interactive_closure.v1","source_chain_continuous":true,"source_event":"order_created","source_event_id":"00065a1d-7f9f-b3a0-0000-000100000020","source_event_id_unique":true,"source_pre_event_id":"00065a1d-7f9f-9460-0000-000103000020","translation":"UNFOLD_TO_INF","unfold_event_id":null,"zero_hair":false}
{"channel":"live_orders_ethbtc","interaction_index":511,"natural_form":{"channel":"live_orders_ethbtc","order_id":"2044303881547776","order_subtype":5,"order_type":1},"natural_form_sha256":"cb32e055813a9c6e8a7ff7c9d07ae240edc60d44fb5e161127d7365df67b0b75","order_source":"orderbook","orders_submitted":0,"presentation":{"amount":"2.01406611","amount_traded":"0","microtimestamp":"1787932601988000","price":"0.03161760"},"previous_record_hash":"00c025ceb211be48bd991a43a88e9257d799a0a56f3d10dcd9977ecb01836619","profit_assessment":null,"record_hash":"b3862dab3635d5a9e60e42af62e77045c634a02377e0a02fb132b91de08ec6a9","recorded_unix_us":1787932602022883,"recorded_utc":"2026-08-28T15:56:42.022883Z","schema_version":"nrrf810.exchange_authored_interactive_closure.v1","source_chain_continuous":true,"source_event":"order_created","source_event_id":"00065a1d-7f9f-b3a0-0000-001100000020","source_event_id_unique":true,"source_pre_event_id":"00065a1d-7f9f-afb8-0000-001103000020","translation":"UNFOLD_TO_INF","unfold_event_id":null,"zero_hair":false}
{"channel":"live_orders_ethusd","interaction_index":512,"natural_form":{"channel":"live_orders_ethusd","order_id":"2044303880880129","order_subtype":5,"order_type":0},"natural_form_sha256":"86c88665626c214b5ecbabfcbf667136adf02f699d4b81d9f7daabfcdeb418e3","order_source":"orderbook","orders_submitted":0,"presentation":{"amount":"8.000000","amount_traded":"0","microtimestamp":"1787932601990000","price":"2478.96"},"previous_record_hash":"b3862dab3635d5a9e60e42af62e77045c634a02377e0a02fb132b91de08ec6a9","profit_assessment":null,"record_hash":"b624a5e4b97d8c731919f8e76ae401c50a92676138997336f04540a1793a1c13","recorded_unix_us":1787932602036253,"recorded_utc":"2026-08-28T15:56:42.036253Z","schema_version":"nrrf810.exchange_authored_interactive_closure.v1","source_chain_continuous":true,"source_event":"order_deleted","source_event_id":"00065a1d-7f9f-bb70-0000-001200000020","source_event_id_unique":true,"source_pre_event_id":"00065a1d-7f9f-6d50-0001-001203000020","translation":"FOLD_RETURN_TO_ZERO","unfold_event_id":"00065a1d-7f9d-36e8-0000-001201000020","zero_hair":true}
{"channel":"live_orders_ethusd","interaction_index":513,"natural_form":{"channel":"live_orders_ethusd","order_id":"2044303880704004","order_subtype":5,"order_type":0},"natural_form_sha256":"4458886dd9443b555fdfac4bd3644e01bb4925950877db8692c88767a8f2fce0","order_source":"orderbook","orders_submitted":0,"presentation":{"amount":"5.000000","amount_traded":"0","microtimestamp":"1787932601990000","price":"2479.95"},"previous_record_hash":"b624a5e4b97d8c731919f8e76ae401c50a92676138997336f04540a1793a1c13","profit_assessment":null,"record_hash":"e4ea82ea5b804bbcd560dd6641707841adead0bdc616f87d74ac3a181becc202","recorded_unix_us":1787932602036331,"recorded_utc":"2026-08-28T15:56:42.036331Z","schema_version":"nrrf810.exchange_authored_interactive_closure.v1","source_chain_continuous":true,"source_event":"order_deleted","source_event_id":"00065a1d-7f9f-bb70-0001-001201000020","source_event_id_unique":true,"source_pre_event_id":"00065a1d-7f9f-bb70-0000-001200000020","translation":"FOLD_RETURN_TO_ZERO","unfold_event_id":"00065a1d-7f9c-8ef0-0002-001203000020","zero_hair":true}
{"channel":"live_orders_ethusd","interaction_index":514,"natural_form":{"channel":"live_orders_ethusd","order_id":"2044303880716294","order_subtype":5,"order_type":0},"natural_form_sha256":"f875c707cc24f9d6ad3fbcc080f448a02717164dcc1f2dba5026c9de8bb1453d","order_source":"orderbook","orders_submitted":0,"presentation":{"amount":"6.000000","amount_traded":"0","microtimestamp":"1787932601990000","price":"2479.70"},"previous_record_hash":"e4ea82ea5b804bbcd560dd6641707841adead0bdc616f87d74ac3a181becc202","profit_assessment":null,"record_hash":"fbaed0df349d6fb81f78c1834c684876141f630c22d1ea0829ade95db19d5f1c","recorded_unix_us":1787932602036421,"recorded_utc":"2026-08-28T15:56:42.036421Z","schema_version":"nrrf810.exchange_authored_interactive_closure.v1","source_chain_continuous":true,"source_event":"order_deleted","source_event_id":"00065a1d-7f9f-bb70-0002-001202000020","source_event_id_unique":true,"source_pre_event_id":"00065a1d-7f9f-bb70-0001-001201000020","translation":"FOLD_RETURN_TO_ZERO","unfold_event_id":"00065a1d-7f9c-9e90-0000-001201000020","zero_hair":true}
{"channel":"live_orders_ethbtc","interaction_index":515,"natural_form":{"channel":"live_orders_ethbtc","order_id":"2044303881560074","order_subtype":5,"order_type":1},"natural_form_sha256":"a5410b368bd5913408c9756dd7789278053739c9b18730216b555b6123071af2","order_source":"orderbook","orders_submitted":0,"presentation":{"amount":"4.02232075","amount_traded":"0","microtimestamp":"1787932601991000","price":"0.03165997"},"previous_record_hash":"fbaed0df349d6fb81f78c1834c684876141f630c22d1ea0829ade95db19d5f1c","profit_assessment":null,"record_hash":"ceec392caee18c2c72054e102e3722758654e1687b537192ba6dded1a2a8d2c8","recorded_unix_us":1787932602036491,"recorded_utc":"2026-08-28T15:56:42.036491Z","schema_version":"nrrf810.exchange_authored_interactive_closure.v1","source_chain_continuous":true,"source_event":"order_created","source_event_id":"00065a1d-7f9f-bf58-0000-001101000020","source_event_id_unique":true,"source_pre_event_id":"00065a1d-7f9f-b3a0-0000-001100000020","translation":"UNFOLD_TO_INF","unfold_event_id":null,"zero_hair":false}
{"channel":"live_orders_btcusd","interaction_index":516,"natural_form":{"channel":"live_orders_btcusd","order_id":"2044303881564169","order_subtype":5,"order_type":0},"natural_form_sha256":"044ff45f8e129c252deea41eb7e867e70b93b1eea24deb82fec381d6b00b857e","order_source":"orderbook","orders_submitted":0,"presentation":{"amount":"0.50943161","amount_traded":"0","microtimestamp":"1787932601993000","price":"78481.52"},"previous_record_hash":"ceec392caee18c2c72054e102e3722758654e1687b537192ba6dded1a2a8d2c8","profit_assessment":null,"record_hash":"102848c0b29b21c32d6b33167296b74f7621ee4c82fa98d2b644a73fbe040443","recorded_unix_us":1787932602036617,"recorded_utc":"2026-08-28T15:56:42.036617Z","schema_version":"nrrf810.exchange_authored_interactive_closure.v1","source_chain_continuous":true,"source_event":"order_created","source_event_id":"00065a1d-7f9f-c728-0000-000101000020","source_event_id_unique":true,"source_pre_event_id":"00065a1d-7f9f-b3a0-0000-000100000020","translation":"UNFOLD_TO_INF","unfold_event_id":null,"zero_hair":false}
{"channel":"live_orders_ethbtc","interaction_index":517,"natural_form":{"channel":"live_orders_ethbtc","order_id":"2044303859556354","order_subtype":5,"order_type":0},"natural_form_sha256":"c96c873489fbc5eabea6db2bd5b459803c03e18c130dadcca440027367a72f76","order_source":"orderbook","orders_submitted":0,"presentation":{"amount":"0.03720000","amount_traded":"0","microtimestamp":"1787932601995000","price":"0.03155239"},"previous_record_hash":"102848c0b29b21c32d6b33167296b74f7621ee4c82fa98d2b644a73fbe040443","profit_assessment":null,"record_hash":"39dd1ef7b96ce079d925af82bd0100d934bf18c19f37c2dff889b48eea54e63d","recorded_unix_us":1787932602036669,"recorded_utc":"2026-08-28T15:56:42.036669Z","schema_version":"nrrf810.exchange_authored_interactive_closure.v1","source_chain_continuous":true,"source_event":"order_deleted","source_event_id":"00065a1d-7f9f-cef8-0000-001102000020","source_event_id_unique":true,"source_pre_event_id":"00065a1d-7f9f-bf58-0000-001101000020","translation":"PARTIAL_PRIOR_UNFOLD","unfold_event_id":null,"zero_hair":false}
{"channel":"live_orders_ethbtc","interaction_index":518,"natural_form":{"channel":"live_orders_ethbtc","order_id":"2044303859507202","order_subtype":5,"order_type":1},"natural_form_sha256":"fdcdd2ddc680b09d4979b1737d5756a77a2b82e0a6c16707b284839441dad81c","order_source":"orderbook","orders_submitted":0,"presentation":{"amount":"0.03720000","amount_traded":"0","microtimestamp":"1787932601995000","price":"0.03164078"},"previous_record_hash":"39dd1ef7b96ce079d925af82bd0100d934bf18c19f37c2dff889b48eea54e63d","profit_assessment":null,"record_hash":"73d41ea7e492e06faf038f740fb416896c376605ab71753ecb3c51a88f95a81d","recorded_unix_us":1787932602036765,"recorded_utc":"2026-08-28T15:56:42.036765Z","schema_version":"nrrf810.exchange_authored_interactive_closure.v1","source_chain_continuous":true,"source_event":"order_deleted","source_event_id":"00065a1d-7f9f-cef8-0001-001103000020","source_event_id_unique":true,"source_pre_event_id":"00065a1d-7f9f-cef8-0000-001102000020","translation":"PARTIAL_PRIOR_UNFOLD","unfold_event_id":null,"zero_hair":false}
{"channel":"live_orders_btcusd","interaction_index":519,"natural_form":{"channel":"live_orders_btcusd","order_id":"2044303881605126","order_subtype":5,"order_type":1},"natural_form_sha256":"eb3c1a78ed9764be219e9370743d27883caf84251e49baaf97b3e16a23e0a877","order_source":"orderbook","orders_submitted":0,"presentation":{"amount":"0.06310787","amount_traded":"0","microtimestamp":"1787932602003000","price":"78521.25"},"previous_record_hash":"73d41ea7e492e06faf038f740fb416896c376605ab71753ecb3c51a88f95a81d","profit_assessment":null,"record_hash":"39b4fba213adba6ab912343d6687e034bffd94ea2da0e54f0913fb3daa1c5548","recorded_unix_us":1787932602036905,"recorded_utc":"2026-08-28T15:56:42.036905Z","schema_version":"nrrf810.exchange_authored_interactive_closure.v1","source_chain_continuous":true,"source_event":"order_created","source_event_id":"00065a1d-7f9f-ee38-0000-000102000020","source_event_id_unique":true,"source_pre_event_id":"00065a1d-7f9f-c728-0000-000101000020","translation":"UNFOLD_TO_INF","unfold_event_id":null,"zero_hair":false}
{"channel":"live_orders_btcusd","interaction_index":520,"natural_form":{"channel":"live_orders_btcusd","order_id":"2044303881605126","order_subtype":5,"order_type":1},"natural_form_sha256":"eb3c1a78ed9764be219e9370743d27883caf84251e49baaf97b3e16a23e0a877","order_source":"orderbook","orders_submitted":0,"presentation":{"amount":"0.06310787","amount_traded":"0","microtimestamp":"1787932602003000","price":"78521.25"},"previous_record_hash":"39b4fba213adba6ab912343d6687e034bffd94ea2da0e54f0913fb3daa1c5548","profit_assessment":null,"record_hash":"123095abace662e221fc9355851bab73e62e1eb847fbf800caeff5c3c22e389b","recorded_unix_us":1787932602036940,"recorded_utc":"2026-08-28T15:56:42.036940Z","schema_version":"nrrf810.exchange_authored_interactive_closure.v1","source_chain_continuous":true,"source_event":"order_deleted","source_event_id":"00065a1d-7f9f-ee38-0001-000103000020","source_event_id_unique":true,"source_pre_event_id":"00065a1d-7f9f-ee38-0000-000102000020","translation":"FOLD_RETURN_TO_ZERO","unfold_event_id":"00065a1d-7f9f-ee38-0000-000102000020","zero_hair":true}
{"channel":"live_orders_btcusd","interaction_index":521,"natural_form":{"channel":"live_orders_btcusd","order_id":"2044303881613312","order_subtype":5,"order_type":1},"natural_form_sha256":"c4d79c14127bc805a2861fda577985c4fc9d506dbf9ad82f0eddece93ec9bece","order_source":"orderbook","orders_submitted":0,"presentation":{"amount":"0.10000000","amount_traded":"0","microtimestamp":"1787932602004000","price":"78522.62"},"previous_record_hash":"123095abace662e221fc9355851bab73e62e1eb847fbf800caeff5c3c22e389b","profit_assessment":null,"record_hash":"2babc89488dac5f736bc988ba7417e060d64a596cb2f314f2ec22205e1e67577","recorded_unix_us":1787932602037057,"recorded_utc":"2026-08-28T15:56:42.037057Z","schema_version":"nrrf810.exchange_authored_interactive_closure.v1","source_chain_continuous":true,"source_event":"order_created","source_event_id":"00065a1d-7f9f-f220-0000-000100000020","source_event_id_unique":true,"source_pre_event_id":"00065a1d-7f9f-ee38-0001-000103000020","translation":"UNFOLD_TO_INF","unfold_event_id":null,"zero_hair":false}
{"channel":"live_orders_btcusd","interaction_index":522,"natural_form":{"channel":"live_orders_btcusd","order_id":"2044303881613312","order_subtype":5,"order_type":1},"natural_form_sha256":"c4d79c14127bc805a2861fda577985c4fc9d506dbf9ad82f0eddece93ec9bece","order_source":"orderbook","orders_submitted":0,"presentation":{"amount":"0.10000000","amount_traded":"0","microtimestamp":"1787932602004000","price":"78522.62"},"previous_record_hash":"2babc89488dac5f736bc988ba7417e060d64a596cb2f314f2ec22205e1e67577","profit_assessment":null,"record_hash":"33549edf8837f3b5dc1ffc59f5cb18d4c1068cf45b408e0f01ccaa673aaccf95","recorded_unix_us":1787932602037087,"recorded_utc":"2026-08-28T15:56:42.037087Z","schema_version":"nrrf810.exchange_authored_interactive_closure.v1","source_chain_continuous":true,"source_event":"order_deleted","source_event_id":"00065a1d-7f9f-f220-0001-000101000020","source_event_id_unique":true,"source_pre_event_id":"00065a1d-7f9f-f220-0000-000100000020","translation":"FOLD_RETURN_TO_ZERO","unfold_event_id":"00065a1d-7f9f-f220-0000-000100000020","zero_hair":true}
{"channel":"live_orders_btcusd","interaction_index":523,"natural_form":{"channel":"live_orders_btcusd","order_id":"2044303881613313","order_subtype":5,"order_type":1},"natural_form_sha256":"082985cf5e9a295081b2c0641ddda053d062e3a23b8c0c64d08028fd95c302d6","order_source":"orderbook","orders_submitted":0,"presentation":{"amount":"0.10000000","amount_traded":"0","microtimestamp":"1787932602004000","price":"78522.63"},"previous_record_hash":"33549edf8837f3b5dc1ffc59f5cb18d4c1068cf45b408e0f01ccaa673aaccf95","profit_assessment":null,"record_hash":"bc38beefd8a6c8c4fa322c11ee17221df40e2c6c32fdf59c909b01051c1c6d8b","recorded_unix_us":1787932602049610,"recorded_utc":"2026-08-28T15:56:42.049610Z","schema_version":"nrrf810.exchange_authored_interactive_closure.v1","source_chain_continuous":true,"source_event":"order_created","source_event_id":"00065a1d-7f9f-f220-0002-000102000020","source_event_id_unique":true,"source_pre_event_id":"00065a1d-7f9f-f220-0001-000101000020","translation":"UNFOLD_TO_INF","unfold_event_id":null,"zero_hair":false}
{"channel":"live_orders_btcusd","interaction_index":524,"natural_form":{"channel":"live_orders_btcusd","order_id":"2044303881613313","order_subtype":5,"order_type":1},"natural_form_sha256":"082985cf5e9a295081b2c0641ddda053d062e3a23b8c0c64d08028fd95c302d6","order_source":"orderbook","orders_submitted":0,"presentation":{"amount":"0.10000000","amount_traded":"0","microtimestamp":"1787932602004000","price":"78522.63"},"previous_record_hash":"bc38beefd8a6c8c4fa322c11ee17221df40e2c6c32fdf59c909b01051c1c6d8b","profit_assessment":null,"record_hash":"0e1f8a6b3e305299d93ee5f4b44807c507efc53fc696b922e95c57e99db714f4","recorded_unix_us":1787932602049638,"recorded_utc":"2026-08-28T15:56:42.049638Z","schema_version":"nrrf810.exchange_authored_interactive_closure.v1","source_chain_continuous":true,"source_event":"order_deleted","source_event_id":"00065a1d-7f9f-f220-0003-000103000020","source_event_id_unique":true,"source_pre_event_id":"00065a1d-7f9f-f220-0002-000102000020","translation":"FOLD_RETURN_TO_ZERO","unfold_event_id":"00065a1d-7f9f-f220-0002-000102000020","zero_hair":true}
{"channel":"live_orders_btcusd","interaction_index":525,"natural_form":{"channel":"live_orders_btcusd","order_id":"2044303881191426","order_subtype":5,"order_type":0},"natural_form_sha256":"d0aacac317399e5afbd6b5206d888ebb855d30bc785dbc4b66a39fa0407fa443","order_source":"orderbook","orders_submitted":0,"presentation":{"amount":"0.19103753","amount_traded":"0","microtimestamp":"1787932602021000","price":"78485.11"},"previous_record_hash":"0e1f8a6b3e305299d93ee5f4b44807c507efc53fc696b922e95c57e99db714f4","profit_assessment":null,"record_hash":"c19f6e0623e7896b9bc7c23e70119e0d5e84531063665d489955c5589821ac9d","recorded_unix_us":1787932602064426,"recorded_utc":"2026-08-28T15:56:42.064426Z","schema_version":"nrrf810.exchange_authored_interactive_closure.v1","source_chain_continuous":true,"source_event":"order_deleted","source_event_id":"00065a1d-7fa0-3488-0000-000100000020","source_event_id_unique":true,"source_pre_event_id":"00065a1d-7f9f-f220-0003-000103000020","translation":"FOLD_RETURN_TO_ZERO","unfold_event_id":"00065a1d-7f9e-5fc8-0000-000101000020","zero_hair":true}
{"channel":"live_orders_btcusd","interaction_index":526,"natural_form":{"channel":"live_orders_btcusd","order_id":"2044303881428997","order_subtype":5,"order_type":0},"natural_form_sha256":"d8f893affbe1c79a34057124a008c5ef4201d720f2fe23183db16064b3b43ae2","order_source":"orderbook","orders_submitted":0,"presentation":{"amount":"0.63679897","amount_traded":"0","microtimestamp":"1787932602022000","price":"78483.23"},"previous_record_hash":"c19f6e0623e7896b9bc7c23e70119e0d5e84531063665d489955c5589821ac9d","profit_assessment":null,"record_hash":"9b40cf374d41b14d2119d186471f05a11c531971c9926822e083533b6475fdaa","recorded_unix_us":1787932602064455,"recorded_utc":"2026-08-28T15:56:42.064455Z","schema_version":"nrrf810.exchange_authored_interactive_closure.v1","source_chain_continuous":true,"source_event":"order_deleted","source_event_id":"00065a1d-7fa0-3870-0000-000101000020","source_event_id_unique":true,"source_pre_event_id":"00065a1d-7fa0-3488-0000-000100000020","translation":"FOLD_RETURN_TO_ZERO","unfold_event_id":"00065a1d-7f9f-4258-0000-000103000020","zero_hair":true}
{"channel":"live_orders_btcusd","interaction_index":527,"natural_form":{"channel":"live_orders_btcusd","order_id":"2044303881564169","order_subtype":5,"order_type":0},"natural_form_sha256":"044ff45f8e129c252deea41eb7e867e70b93b1eea24deb82fec381d6b00b857e","order_source":"orderbook","orders_submitted":0,"presentation":{"amount":"0.50943161","amount_traded":"0","microtimestamp":"1787932602022000","price":"78481.52"},"previous_record_hash":"9b40cf374d41b14d2119d186471f05a11c531971c9926822e083533b6475fdaa","profit_assessment":null,"record_hash":"629f888a7d7f57dad890ffb4e4e011660ba71b6e6bdac29c1309a30a314b0f98","recorded_unix_us":1787932602064542,"recorded_utc":"2026-08-28T15:56:42.064542Z","schema_version":"nrrf810.exchange_authored_interactive_closure.v1","source_chain_continuous":true,"source_event":"order_deleted","source_event_id":"00065a1d-7fa0-3870-0001-000102000020","source_event_id_unique":true,"source_pre_event_id":"00065a1d-7fa0-3870-0000-000101000020","translation":"FOLD_RETURN_TO_ZERO","unfold_event_id":"00065a1d-7f9f-c728-0000-000101000020","zero_hair":true}
{"channel":"live_orders_btcusd","interaction_index":528,"natural_form":{"channel":"live_orders_btcusd","order_id":"2044303881175053","order_subtype":5,"order_type":0},"natural_form_sha256":"35dc680f1a7505a1eaba930b8ff910d4ea9b40dcd543c386d29d48fdfa2cf5b5","order_source":"orderbook","orders_submitted":0,"presentation":{"amount":"0.06368031","amount_traded":"0","microtimestamp":"1787932602023000","price":"78517.20"},"previous_record_hash":"629f888a7d7f57dad890ffb4e4e011660ba71b6e6bdac29c1309a30a314b0f98","profit_assessment":null,"record_hash":"48c1b8768f886ff873e2f53063cc7ca1ac82b5e177d99a3dbc63d1ef8b20401f","recorded_unix_us":1787932602064645,"recorded_utc":"2026-08-28T15:56:42.064645Z","schema_version":"nrrf810.exchange_authored_interactive_closure.v1","source_chain_continuous":true,"source_event":"order_deleted","source_event_id":"00065a1d-7fa0-3c58-0000-000103000020","source_event_id_unique":true,"source_pre_event_id":"00065a1d-7fa0-3870-0001-000102000020","translation":"FOLD_RETURN_TO_ZERO","unfold_event_id":"00065a1d-7f9e-5410-0000-000100000020","zero_hair":true}
{"channel":"live_orders_btcusd","interaction_index":529,"natural_form":{"channel":"live_orders_btcusd","order_id":"2044303876300813","order_subtype":5,"order_type":1},"natural_form_sha256":"674203cbf2c5c229a97aa3ea9c400dbad7d66476a4e35e4cd5f4fb502859dc7b","order_source":"orderbook","orders_submitted":0,"presentation":{"amount":"0.50938943","amount_traded":"0","microtimestamp":"1787932602027000","price":"78522.64"},"previous_record_hash":"48c1b8768f886ff873e2f53063cc7ca1ac82b5e177d99a3dbc63d1ef8b20401f","profit_assessment":null,"record_hash":"e70a061c5f00f93ad24309540e04c0efb85198fce8c6160d2656b4d7a4b00540","recorded_unix_us":1787932602066514,"recorded_utc":"2026-08-28T15:56:42.066514Z","schema_version":"nrrf810.exchange_authored_interactive_closure.v1","source_chain_continuous":true,"source_event":"order_deleted","source_event_id":"00065a1d-7fa0-4bf8-0000-000100000020","source_event_id_unique":true,"source_pre_event_id":"00065a1d-7fa0-3c58-0000-000103000020","translation":"PARTIAL_PRIOR_UNFOLD","unfold_event_id":null,"zero_hair":false}
{"channel":"live_orders_btcusd","interaction_index":530,"natural_form":{"channel":"live_orders_btcusd","order_id":"2044303852109824","order_subtype":5,"order_type":1},"natural_form_sha256":"2d2b89af734f0f574c94e75730aac5008f1e93be02c2bd81d45d8a2b6add64ac","order_source":"orderbook","orders_submitted":0,"presentation":{"amount":"0.19101517","amount_traded":"0","microtimestamp":"1787932602028000","price":"78522.64"},"previous_record_hash":"e70a061c5f00f93ad24309540e04c0efb85198fce8c6160d2656b4d7a4b00540","profit_assessment":null,"record_hash":"2f5cad7a60e5d0f55e0e58857b63deffe122eec24ed740a135f3c72aa2e238f2","recorded_unix_us":1787932602066680,"recorded_utc":"2026-08-28T15:56:42.066680Z","schema_version":"nrrf810.exchange_authored_interactive_closure.v1","source_chain_continuous":true,"source_event":"order_deleted","source_event_id":"00065a1d-7fa0-4fe0-0000-000101000020","source_event_id_unique":true,"source_pre_event_id":"00065a1d-7fa0-4bf8-0000-000100000020","translation":"PARTIAL_PRIOR_UNFOLD","unfold_event_id":null,"zero_hair":false}
{"channel":"live_orders_btcusd","interaction_index":531,"natural_form":{"channel":"live_orders_btcusd","order_id":"2044303876247591","order_subtype":5,"order_type":1},"natural_form_sha256":"608cd3e122af84c3e0dd77430fd4ac482cc5ccac2e567cc2cc721ed6ba848516","order_source":"orderbook","orders_submitted":0,"presentation":{"amount":"0.63673110","amount_traded":"0","microtimestamp":"1787932602029000","price":"78522.64"},"previous_record_hash":"2f5cad7a60e5d0f55e0e58857b63deffe122eec24ed740a135f3c72aa2e238f2","profit_assessment":null,"record_hash":"806488946c32fb893e7b559cda3b80cfa1270c7993570823264fdb4f001da1f2","recorded_unix_us":1787932602066721,"recorded_utc":"2026-08-28T15:56:42.066721Z","schema_version":"nrrf810.exchange_authored_interactive_closure.v1","source_chain_continuous":true,"source_event":"order_deleted","source_event_id":"00065a1d-7fa0-53c8-0000-000102000020","source_event_id_unique":true,"source_pre_event_id":"00065a1d-7fa0-4fe0-0000-000101000020","translation":"PARTIAL_PRIOR_UNFOLD","unfold_event_id":null,"zero_hair":false}
{"channel":"live_orders_btcusd","interaction_index":532,"natural_form":{"channel":"live_orders_btcusd","order_id":"2044303881736194","order_subtype":5,"order_type":1},"natural_form_sha256":"e13a3360fb9be761ae6312a9dfbbe9991d2483848a39dc6c791e6eabc0a1907c","order_source":"orderbook","orders_submitted":0,"presentation":{"amount":"0.10000000","amount_traded":"0","microtimestamp":"1787932602034000","price":"78522.62"},"previous_record_hash":"806488946c32fb893e7b559cda3b80cfa1270c7993570823264fdb4f001da1f2","profit_assessment":null,"record_hash":"fb86e8dbde063639c781bddbe6f19dcdbd8215ca39b5449626fa5a53629efd3a","recorded_unix_us":1787932602087168,"recorded_utc":"2026-08-28T15:56:42.087168Z","schema_version":"nrrf810.exchange_authored_interactive_closure.v1","source_chain_continuous":true,"source_event":"order_created","source_event_id":"00065a1d-7fa0-6750-0000-000103000020","source_event_id_unique":true,"source_pre_event_id":"00065a1d-7fa0-53c8-0000-000102000020","translation":"UNFOLD_TO_INF","unfold_event_id":null,"zero_hair":false}
{"channel":"live_orders_btcusd","interaction_index":533,"natural_form":{"channel":"live_orders_btcusd","order_id":"2044303881736194","order_subtype":5,"order_type":1},"natural_form_sha256":"e13a3360fb9be761ae6312a9dfbbe9991d2483848a39dc6c791e6eabc0a1907c","order_source":"orderbook","orders_submitted":0,"presentation":{"amount":"0.10000000","amount_traded":"0","microtimestamp":"1787932602034000","price":"78522.62"},"previous_record_hash":"fb86e8dbde063639c781bddbe6f19dcdbd8215ca39b5449626fa5a53629efd3a","profit_assessment":null,"record_hash":"bc1b9ff727722b5cccb6b10d7edb4448057a668ede41716be92cd8fd78f92bd9","recorded_unix_us":1787932602087204,"recorded_utc":"2026-08-28T15:56:42.087204Z","schema_version":"nrrf810.exchange_authored_interactive_closure.v1","source_chain_continuous":true,"source_event":"order_deleted","source_event_id":"00065a1d-7fa0-6750-0001-000100000020","source_event_id_unique":true,"source_pre_event_id":"00065a1d-7fa0-6750-0000-000103000020","translation":"FOLD_RETURN_TO_ZERO","unfold_event_id":"00065a1d-7fa0-6750-0000-000103000020","zero_hair":true}
{"channel":"live_orders_btcusd","interaction_index":534,"natural_form":{"channel":"live_orders_btcusd","order_id":"2044303881736196","order_subtype":5,"order_type":0},"natural_form_sha256":"d998d70ac8d631346a8daafd2e01440f2aa7b88322968bba044dba8f295b44db","order_source":"orderbook","orders_submitted":0,"presentation":{"amount":"0.19103754","amount_traded":"0","microtimestamp":"1787932602035000","price":"78486.13"},"previous_record_hash":"bc1b9ff727722b5cccb6b10d7edb4448057a668ede41716be92cd8fd78f92bd9","profit_assessment":null,"record_hash":"7d3a6a891c382c15e2659a2af8708c05e14d01b87484249cee742e5223161d83","recorded_unix_us":1787932602087226,"recorded_utc":"2026-08-28T15:56:42.087226Z","schema_version":"nrrf810.exchange_authored_interactive_closure.v1","source_chain_continuous":true,"source_event":"order_created","source_event_id":"00065a1d-7fa0-6b38-0000-000101000020","source_event_id_unique":true,"source_pre_event_id":"00065a1d-7fa0-6750-0001-000100000020","translation":"UNFOLD_TO_INF","unfold_event_id":null,"zero_hair":false}
{"channel":"live_orders_btcusd","interaction_index":535,"natural_form":{"channel":"live_orders_btcusd","order_id":"2044303881744388","order_subtype":5,"order_type":0},"natural_form_sha256":"9ee051d1c08811c24f613ae8b43108ccaaa1ad9bc8768d709e895d8aea20eab6","order_source":"orderbook","orders_submitted":0,"presentation":{"amount":"0.50943344","amount_traded":"0","microtimestamp":"1787932602036000","price":"78482.20"},"previous_record_hash":"7d3a6a891c382c15e2659a2af8708c05e14d01b87484249cee742e5223161d83","profit_assessment":null,"record_hash":"556e381326d7a602e29307debf84ec88fa46a8b1ffc996f7bd1f94a83c789a02","recorded_unix_us":1787932602087341,"recorded_utc":"2026-08-28T15:56:42.087341Z","schema_version":"nrrf810.exchange_authored_interactive_closure.v1","source_chain_continuous":true,"source_event":"order_created","source_event_id":"00065a1d-7fa0-6f20-0000-000102000020","source_event_id_unique":true,"source_pre_event_id":"00065a1d-7fa0-6b38-0000-000101000020","translation":"UNFOLD_TO_INF","unfold_event_id":null,"zero_hair":false}
{"channel":"live_orders_btcusd","interaction_index":536,"natural_form":{"channel":"live_orders_btcusd","order_id":"2044303881744391","order_subtype":5,"order_type":0},"natural_form_sha256":"fbc841d4291ddf8d1bfab0283445a2361df1abad0115666974324e9b1e2b8a23","order_source":"orderbook","orders_submitted":0,"presentation":{"amount":"0.63679180","amount_traded":"0","microtimestamp":"1787932602036000","price":"78484.17"},"previous_record_hash":"556e381326d7a602e29307debf84ec88fa46a8b1ffc996f7bd1f94a83c789a02","profit_assessment":null,"record_hash":"5a11a2988924fd69de89208c8d51746f7d7fe2a13b32ee07100b23d8d60be218","recorded_unix_us":1787932602087371,"recorded_utc":"2026-08-28T15:56:42.087371Z","schema_version":"nrrf810.exchange_authored_interactive_closure.v1","source_chain_continuous":true,"source_event":"order_created","source_event_id":"00065a1d-7fa0-6f20-0001-000103000020","source_event_id_unique":true,"source_pre_event_id":"00065a1d-7fa0-6f20-0000-000102000020","translation":"UNFOLD_TO_INF","unfold_event_id":null,"zero_hair":false}
{"channel":"live_orders_ethusd","interaction_index":537,"natural_form":{"channel":"live_orders_ethusd","order_id":"2044303880777729","order_subtype":5,"order_type":0},"natural_form_sha256":"4a2c52856f11340efc5f26bcf411f140625f88112db9786f56da127c923d8074","order_source":"orderbook","orders_submitted":0,"presentation":{"amount":"0.403101","amount_traded":"0","microtimestamp":"1787932602038000","price":"2479.80"},"previous_record_hash":"5a11a2988924fd69de89208c8d51746f7d7fe2a13b32ee07100b23d8d60be218","profit_assessment":null,"record_hash":"ee8055c5b44755c4b041f1303549deb36aca873bf34c8e1bf3393eb9a921fcdb","recorded_unix_us":1787932602087495,"recorded_utc":"2026-08-28T15:56:42.087495Z","schema_version":"nrrf810.exchange_authored_interactive_closure.v1","source_chain_continuous":true,"source_event":"order_deleted","source_event_id":"00065a1d-7fa0-76f0-0000-001203000020","source_event_id_unique":true,"source_pre_event_id":"00065a1d-7f9f-bb70-0002-001202000020","translation":"FOLD_RETURN_TO_ZERO","unfold_event_id":"00065a1d-7f9c-d540-0000-001201000020","zero_hair":true}
{"channel":"live_orders_ethbtc","interaction_index":538,"natural_form":{"channel":"live_orders_ethbtc","order_id":"2044303881756676","order_subtype":5,"order_type":1},"natural_form_sha256":"29ef9504b7548dfbd7fbd5aa95559422f6b739b26fe5de961b3fe04114ba0cd7","order_source":"orderbook","orders_submitted":0,"presentation":{"amount":"0.03720000","amount_traded":"0","microtimestamp":"1787932602040000","price":"0.03164077"},"previous_record_hash":"ee8055c5b44755c4b041f1303549deb36aca873bf34c8e1bf3393eb9a921fcdb","profit_assessment":null,"record_hash":"e16d3c58bb7fe25dd5cb4af00f31c9f4eb7ee3599bb28798ceacba4f6a9745d6","recorded_unix_us":1787932602087520,"recorded_utc":"2026-08-28T15:56:42.087520Z","schema_version":"nrrf810.exchange_authored_interactive_closure.v1","source_chain_continuous":true,"source_event":"order_created","source_event_id":"00065a1d-7fa0-7ec0-0000-001100000020","source_event_id_unique":true,"source_pre_event_id":"00065a1d-7f9f-cef8-0001-001103000020","translation":"UNFOLD_TO_INF","unfold_event_id":null,"zero_hair":false}
{"channel":"live_orders_ethbtc","interaction_index":539,"natural_form":{"channel":"live_orders_ethbtc","order_id":"2044303881768960","order_subtype":5,"order_type":1},"natural_form_sha256":"0567498f546575dcb1815214c1eec193dbf009c088880b541b6e68518bd0ca0a","order_source":"orderbook","orders_submitted":0,"presentation":{"amount":"3.02055629","amount_traded":"0","microtimestamp":"1787932602042000","price":"0.03162186"},"previous_record_hash":"e16d3c58bb7fe25dd5cb4af00f31c9f4eb7ee3599bb28798ceacba4f6a9745d6","profit_assessment":null,"record_hash":"9ca479394642aa8dbd8fd753448c37b6825ac4c8c5e09dd87f4a7b5ab0bfebf2","recorded_unix_us":1787932602087596,"recorded_utc":"2026-08-28T15:56:42.087596Z","schema_version":"nrrf810.exchange_authored_interactive_closure.v1","source_chain_continuous":true,"source_event":"order_created","source_event_id":"00065a1d-7fa0-8690-0000-001101000020","source_event_id_unique":true,"source_pre_event_id":"00065a1d-7fa0-7ec0-0000-001100000020","translation":"UNFOLD_TO_INF","unfold_event_id":null,"zero_hair":false}
{"channel":"live_orders_ethbtc","interaction_index":540,"natural_form":{"channel":"live_orders_ethbtc","order_id":"2044303881768963","order_subtype":5,"order_type":1},"natural_form_sha256":"35293baebd102492b6fcd786a8baa2a1fb99feb417f62ca30374b5f9e761dcd5","order_source":"orderbook","orders_submitted":0,"presentation":{"amount":"1.56076612","amount_traded":"0","microtimestamp":"1787932602042000","price":"0.03317746"},"previous_record_hash":"9ca479394642aa8dbd8fd753448c37b6825ac4c8c5e09dd87f4a7b5ab0bfebf2","profit_assessment":null,"record_hash":"2d6f85d323d461cb37e85d62c181332afa30e138964d0e34efb80f42ecba92a1","recorded_unix_us":1787932602087672,"recorded_utc":"2026-08-28T15:56:42.087672Z","schema_version":"nrrf810.exchange_authored_interactive_closure.v1","source_chain_continuous":true,"source_event":"order_created","source_event_id":"00065a1d-7fa0-8690-0001-001102000020","source_event_id_unique":true,"source_pre_event_id":"00065a1d-7fa0-8690-0000-001101000020","translation":"UNFOLD_TO_INF","unfold_event_id":null,"zero_hair":false}
{"channel":"live_orders_ethbtc","interaction_index":541,"natural_form":{"channel":"live_orders_ethbtc","order_id":"2044303881768966","order_subtype":5,"order_type":0},"natural_form_sha256":"504bffdafb03463859bd9d6d7e7430d096f826a7b129d9de07056ad7cbb0a95f","order_source":"orderbook","orders_submitted":0,"presentation":{"amount":"0.60475617","amount_traded":"0","microtimestamp":"1787932602043000","price":"0.03158982"},"previous_record_hash":"2d6f85d323d461cb37e85d62c181332afa30e138964d0e34efb80f42ecba92a1","profit_assessment":null,"record_hash":"2a8b6e032232dcee390def9a68b5e8fd881536902993d1d9a7253e5540359fe7","recorded_unix_us":1787932602087832,"recorded_utc":"2026-08-28T15:56:42.087832Z","schema_version":"nrrf810.exchange_authored_interactive_closure.v1","source_chain_continuous":true,"source_event":"order_created","source_event_id":"00065a1d-7fa0-8a78-0000-001103000020","source_event_id_unique":true,"source_pre_event_id":"00065a1d-7fa0-8690-0001-001102000020","translation":"UNFOLD_TO_INF","unfold_event_id":null,"zero_hair":false}
{"channel":"live_orders_ethbtc","interaction_index":542,"natural_form":{"channel":"live_orders_ethbtc","order_id":"2044303881773058","order_subtype":5,"order_type":0},"natural_form_sha256":"f04c16aad04bcfe62b9d16224dcd3645fb70a7f6cf8c25060d2f0259976a2f70","order_source":"orderbook","orders_submitted":0,"presentation":{"amount":"1.00801353","amount_traded":"0","microtimestamp":"1787932602043000","price":"0.03158534"},"previous_record_hash":"2a8b6e032232dcee390def9a68b5e8fd881536902993d1d9a7253e5540359fe7","profit_assessment":null,"record_hash":"7bb0e5234521849aa8806a4fad927732c9e9766ac13de59eb0d5ef3ebc1cab0b","recorded_unix_us":1787932602087857,"recorded_utc":"2026-08-28T15:56:42.087857Z","schema_version":"nrrf810.exchange_authored_interactive_closure.v1","source_chain_continuous":true,"source_event":"order_created","source_event_id":"00065a1d-7fa0-8a78-0001-001100000020","source_event_id_unique":true,"source_pre_event_id":"00065a1d-7fa0-8a78-0000-001103000020","translation":"UNFOLD_TO_INF","unfold_event_id":null,"zero_hair":false}
{"channel":"live_orders_ethbtc","interaction_index":543,"natural_form":{"channel":"live_orders_ethbtc","order_id":"2044303881773063","order_subtype":5,"order_type":0},"natural_form_sha256":"6d30619b688f6a64834f5ab92d0785eb7349ec2e25adecf77adecc18c4365b94","order_source":"orderbook","orders_submitted":0,"presentation":{"amount":"2.01629689","amount_traded":"0","microtimestamp":"1787932602043000","price":"0.03157941"},"previous_record_hash":"7bb0e5234521849aa8806a4fad927732c9e9766ac13de59eb0d5ef3ebc1cab0b","profit_assessment":null,"record_hash":"8f3516bbee2ea8b438d1a32a162e10431d5ab539357ad819b35104e6b738fc78","recorded_unix_us":1787932602087878,"recorded_utc":"2026-08-28T15:56:42.087878Z","schema_version":"nrrf810.exchange_authored_interactive_closure.v1","source_chain_continuous":true,"source_event":"order_created","source_event_id":"00065a1d-7fa0-8a78-0002-001101000020","source_event_id_unique":true,"source_pre_event_id":"00065a1d-7fa0-8a78-0001-001100000020","translation":"UNFOLD_TO_INF","unfold_event_id":null,"zero_hair":false}
{"channel":"live_orders_btcusd","interaction_index":544,"natural_form":{"channel":"live_orders_btcusd","order_id":"2044303881773064","order_subtype":5,"order_type":1},"natural_form_sha256":"556a1444924964c367dbcbc133d76cb46a4fdc2e6afeab817808968cd8214881","order_source":"orderbook","orders_submitted":0,"presentation":{"amount":"0.06310787","amount_traded":"0","microtimestamp":"1787932602044000","price":"78522.11"},"previous_record_hash":"8f3516bbee2ea8b438d1a32a162e10431d5ab539357ad819b35104e6b738fc78","profit_assessment":null,"record_hash":"b9792acabab849684af4004af680bfd1447c65baf753b080fd3da9397131c5c3","recorded_unix_us":1787932602087897,"recorded_utc":"2026-08-28T15:56:42.087897Z","schema_version":"nrrf810.exchange_authored_interactive_closure.v1","source_chain_continuous":true,"source_event":"order_created","source_event_id":"00065a1d-7fa0-8e60-0000-000100000020","source_event_id_unique":true,"source_pre_event_id":"00065a1d-7fa0-6f20-0001-000103000020","translation":"UNFOLD_TO_INF","unfold_event_id":null,"zero_hair":false}
{"channel":"live_orders_btcusd","interaction_index":545,"natural_form":{"channel":"live_orders_btcusd","order_id":"2044303881773064","order_subtype":5,"order_type":1},"natural_form_sha256":"556a1444924964c367dbcbc133d76cb46a4fdc2e6afeab817808968cd8214881","order_source":"orderbook","orders_submitted":0,"presentation":{"amount":"0.06310787","amount_traded":"0","microtimestamp":"1787932602044000","price":"78522.11"},"previous_record_hash":"b9792acabab849684af4004af680bfd1447c65baf753b080fd3da9397131c5c3","profit_assessment":null,"record_hash":"9fc9d092b603484bc3cdb24a49825408899ac0728265723562745c728f13fb0f","recorded_unix_us":1787932602088014,"recorded_utc":"2026-08-28T15:56:42.088014Z","schema_version":"nrrf810.exchange_authored_interactive_closure.v1","source_chain_continuous":true,"source_event":"order_deleted","source_event_id":"00065a1d-7fa0-8e60-0001-000101000020","source_event_id_unique":true,"source_pre_event_id":"00065a1d-7fa0-8e60-0000-000100000020","translation":"FOLD_RETURN_TO_ZERO","unfold_event_id":"00065a1d-7fa0-8e60-0000-000100000020","zero_hair":true}
{"channel":"live_orders_ethbtc","interaction_index":546,"natural_form":{"channel":"live_orders_ethbtc","order_id":"2044303881777153","order_subtype":5,"order_type":0},"natural_form_sha256":"c286a5d44fe1315b9aa97f64ef881b5ed01848e4d506a61dbcc6d4316b6b8510","order_source":"orderbook","orders_submitted":0,"presentation":{"amount":"3.02537254","amount_traded":"0","microtimestamp":"1787932602044000","price":"0.03156999"},"previous_record_hash":"9fc9d092b603484bc3cdb24a49825408899ac0728265723562745c728f13fb0f","profit_assessment":null,"record_hash":"503f5f3e0548cff272d4f86c4870e1fa9ab682a7eb2af8bfbbb36a96e0e99a06","recorded_unix_us":1787932602088037,"recorded_utc":"2026-08-28T15:56:42.088037Z","schema_version":"nrrf810.exchange_authored_interactive_closure.v1","source_chain_continuous":true,"source_event":"order_created","source_event_id":"00065a1d-7fa0-8e60-0000-001102000020","source_event_id_unique":true,"source_pre_event_id":"00065a1d-7fa0-8a78-0002-001101000020","translation":"UNFOLD_TO_INF","unfold_event_id":null,"zero_hair":false}
{"channel":"live_orders_ethbtc","interaction_index":547,"natural_form":{"channel":"live_orders_ethbtc","order_id":"2044303881785349","order_subtype":5,"order_type":0},"natural_form_sha256":"9bbe6ee2927b5db5005105feee7c970f6e67a5e43e9bcc4bbd37a14e1cc42d22","order_source":"orderbook","orders_submitted":0,"presentation":{"amount":"4.03662068","amount_traded":"0","microtimestamp":"1787932602047000","price":"0.03154857"},"previous_record_hash":"503f5f3e0548cff272d4f86c4870e1fa9ab682a7eb2af8bfbbb36a96e0e99a06","profit_assessment":null,"record_hash":"c33c1dde1a094b922f99a3b4d2110f48a6ed4f6ee677524987404697ef96f723","recorded_unix_us":1787932602088108,"recorded_utc":"2026-08-28T15:56:42.088108Z","schema_version":"nrrf810.exchange_authored_interactive_closure.v1","source_chain_continuous":true,"source_event":"order_created","source_event_id":"00065a1d-7fa0-9a18-0000-001103000020","source_event_id_unique":true,"source_pre_event_id":"00065a1d-7fa0-8e60-0000-001102000020","translation":"UNFOLD_TO_INF","unfold_event_id":null,"zero_hair":false}
{"channel":"live_orders_ethusd","interaction_index":548,"natural_form":{"channel":"live_orders_ethusd","order_id":"2044303881793543","order_subtype":5,"order_type":0},"natural_form_sha256":"bc389985d9f9731445a9faf7d9a5b05135ac6f4ca732ebf096ec130e782171fd","order_source":"orderbook","orders_submitted":0,"presentation":{"amount":"0.403090","amount_traded":"0","microtimestamp":"1787932602048000","price":"2480.01"},"previous_record_hash":"c33c1dde1a094b922f99a3b4d2110f48a6ed4f6ee677524987404697ef96f723","profit_assessment":null,"record_hash":"a586ed093af169b777d6502a225e7e90fd8c97a6f8f20d7c24eb2edbe8d5b310","recorded_unix_us":1787932602088185,"recorded_utc":"2026-08-28T15:56:42.088185Z","schema_version":"nrrf810.exchange_authored_interactive_closure.v1","source_chain_continuous":true,"source_event":"order_created","source_event_id":"00065a1d-7fa0-9e00-0000-001200000020","source_event_id_unique":true,"source_pre_event_id":"00065a1d-7fa0-76f0-0000-001203000020","translation":"UNFOLD_TO_INF","unfold_event_id":null,"zero_hair":false}
{"channel":"live_orders_btcusd","interaction_index":549,"natural_form":{"channel":"live_orders_btcusd","order_id":"2044303881793550","order_subtype":5,"order_type":1},"natural_form_sha256":"0c47dc420c797936491a6a7b3444f7559a3a07e5219b89bb604a534e3c9d0b0e","order_source":"orderbook","orders_submitted":0,"presentation":{"amount":"0.10000000","amount_traded":"0","microtimestamp":"1787932602049000","price":"78522.63"},"previous_record_hash":"a586ed093af169b777d6502a225e7e90fd8c97a6f8f20d7c24eb2edbe8d5b310","profit_assessment":null,"record_hash":"5dad8771965e13e504059bd8911eb755ac3629a6516f22270263d6f62b094ff7","recorded_unix_us":1787932602097418,"recorded_utc":"2026-08-28T15:56:42.097418Z","schema_version":"nrrf810.exchange_authored_interactive_closure.v1","source_chain_continuous":true,"source_event":"order_created","source_event_id":"00065a1d-7fa0-a1e8-0000-000102000020","source_event_id_unique":true,"source_pre_event_id":"00065a1d-7fa0-8e60-0001-000101000020","translation":"UNFOLD_TO_INF","unfold_event_id":null,"zero_hair":false}
{"channel":"live_orders_btcusd","interaction_index":550,"natural_form":{"channel":"live_orders_btcusd","order_id":"2044303881793550","order_subtype":5,"order_type":1},"natural_form_sha256":"0c47dc420c797936491a6a7b3444f7559a3a07e5219b89bb604a534e3c9d0b0e","order_source":"orderbook","orders_submitted":0,"presentation":{"amount":"0.10000000","amount_traded":"0","microtimestamp":"1787932602049000","price":"78522.63"},"previous_record_hash":"5dad8771965e13e504059bd8911eb755ac3629a6516f22270263d6f62b094ff7","profit_assessment":null,"record_hash":"fc7c48766fef303bfb83a76b115224c3a9941f2247f942184fa68311f6ec4b6c","recorded_unix_us":1787932602097446,"recorded_utc":"2026-08-28T15:56:42.097446Z","schema_version":"nrrf810.exchange_authored_interactive_closure.v1","source_chain_continuous":true,"source_event":"order_deleted","source_event_id":"00065a1d-7fa0-a1e8-0001-000103000020","source_event_id_unique":true,"source_pre_event_id":"00065a1d-7fa0-a1e8-0000-000102000020","translation":"FOLD_RETURN_TO_ZERO","unfold_event_id":"00065a1d-7fa0-a1e8-0000-000102000020","zero_hair":true}
{"channel":"live_orders_btcusd","interaction_index":551,"natural_form":{"channel":"live_orders_btcusd","order_id":"2044303881543684","order_subtype":5,"order_type":0},"natural_form_sha256":"164196f82261a758757ca703577db1c80c1be889d95398b6c92cf431df410c9e","order_source":"orderbook","orders_submitted":0,"presentation":{"amount":"0.00140266","amount_traded":"0","microtimestamp":"1787932602054000","price":"70667.93"},"previous_record_hash":"fc7c48766fef303bfb83a76b115224c3a9941f2247f942184fa68311f6ec4b6c","profit_assessment":null,"record_hash":"48cf221a7bca8b38233888237316ca366a74e2a1b79e56b7112b45240afbb442","recorded_unix_us":1787932602097591,"recorded_utc":"2026-08-28T15:56:42.097591Z","schema_version":"nrrf810.exchange_authored_interactive_closure.v1","source_chain_continuous":true,"source_event":"order_deleted","source_event_id":"00065a1d-7fa0-b570-0000-000100000020","source_event_id_unique":true,"source_pre_event_id":"00065a1d-7fa0-a1e8-0001-000103000020","translation":"FOLD_RETURN_TO_ZERO","unfold_event_id":"00065a1d-7f9f-b3a0-0000-000100000020","zero_hair":true}
{"channel":"live_orders_ethusd","interaction_index":552,"natural_form":{"channel":"live_orders_ethusd","order_id":"2044303881830404","order_subtype":5,"order_type":0},"natural_form_sha256":"e5b6b3fb3f1ed7aa37318593413a27ca64e6550ad6295fda668d383ad1f5c37d","order_source":"orderbook","orders_submitted":0,"presentation":{"amount":"3.000000","amount_traded":"0","microtimestamp":"1787932602058000","price":"2479.81"},"previous_record_hash":"48cf221a7bca8b38233888237316ca366a74e2a1b79e56b7112b45240afbb442","profit_assessment":null,"record_hash":"7f2b954428104406a443a2783edd29bf82d2364ce5981548e0d05c4430d31dd8","recorded_unix_us":1787932602097622,"recorded_utc":"2026-08-28T15:56:42.097622Z","schema_version":"nrrf810.exchange_authored_interactive_closure.v1","source_chain_continuous":true,"source_event":"order_created","source_event_id":"00065a1d-7fa0-c510-0000-001201000020","source_event_id_unique":true,"source_pre_event_id":"00065a1d-7fa0-9e00-0000-001200000020","translation":"UNFOLD_TO_INF","unfold_event_id":null,"zero_hair":false}
{"channel":"live_orders_ethusd","interaction_index":553,"natural_form":{"channel":"live_orders_ethusd","order_id":"2044303881838592","order_subtype":5,"order_type":0},"natural_form_sha256":"5e7b8f90f47e5cc4f4ddf1a37605fa72efc3bcd5c099395a4f05e32e9024d807","order_source":"orderbook","orders_submitted":0,"presentation":{"amount":"3.000000","amount_traded":"0","microtimestamp":"1787932602059000","price":"2479.81"},"previous_record_hash":"7f2b954428104406a443a2783edd29bf82d2364ce5981548e0d05c4430d31dd8","profit_assessment":null,"record_hash":"c12367911f16a60d003b40e53624d01ac0def687f96b6016677fd1c749e5fff3","recorded_unix_us":1787932602097746,"recorded_utc":"2026-08-28T15:56:42.097746Z","schema_version":"nrrf810.exchange_authored_interactive_closure.v1","source_chain_continuous":true,"source_event":"order_created","source_event_id":"00065a1d-7fa0-c8f8-0000-001202000020","source_event_id_unique":true,"source_pre_event_id":"00065a1d-7fa0-c510-0000-001201000020","translation":"UNFOLD_TO_INF","unfold_event_id":null,"zero_hair":false}
{"channel":"live_orders_ethusd","interaction_index":554,"natural_form":{"channel":"live_orders_ethusd","order_id":"2044303881842690","order_subtype":5,"order_type":0},"natural_form_sha256":"a6ab64de046176a9d4bd76fb28dd7bad52ad81d3392e66044ea8f5b8455a1c34","order_source":"orderbook","orders_submitted":0,"presentation":{"amount":"5.000000","amount_traded":"0","microtimestamp":"1787932602060000","price":"2480.06"},"previous_record_hash":"c12367911f16a60d003b40e53624d01ac0def687f96b6016677fd1c749e5fff3","profit_assessment":null,"record_hash":"f902c75ab24cc1d242ab4b31d3ba45e728d6f04eb268b77bea5fb428db1ccfd3","recorded_unix_us":1787932602097776,"recorded_utc":"2026-08-28T15:56:42.097776Z","schema_version":"nrrf810.exchange_authored_interactive_closure.v1","source_chain_continuous":true,"source_event":"order_created","source_event_id":"00065a1d-7fa0-cce0-0000-001203000020","source_event_id_unique":true,"source_pre_event_id":"00065a1d-7fa0-c8f8-0000-001202000020","translation":"UNFOLD_TO_INF","unfold_event_id":null,"zero_hair":false}
{"channel":"live_orders_ethusd","interaction_index":555,"natural_form":{"channel":"live_orders_ethusd","order_id":"2044303881244675","order_subtype":5,"order_type":0},"natural_form_sha256":"3cc74411f7ee47b287eb241a2212021bba7c41950b2785af33ee56a382a902d7","order_source":"orderbook","orders_submitted":0,"presentation":{"amount":"0.043457","amount_traded":"0","microtimestamp":"1787932602063000","price":"2480.73"},"previous_record_hash":"f902c75ab24cc1d242ab4b31d3ba45e728d6f04eb268b77bea5fb428db1ccfd3","profit_assessment":null,"record_hash":"514868da3f61328ca83488eea661a2565aa49ede24f96966e790ed70f3adf260","recorded_unix_us":1787932602097906,"recorded_utc":"2026-08-28T15:56:42.097906Z","schema_version":"nrrf810.exchange_authored_interactive_closure.v1","source_chain_continuous":true,"source_event":"order_deleted","source_event_id":"00065a1d-7fa0-d898-0000-001200000020","source_event_id_unique":true,"source_pre_event_id":"00065a1d-7fa0-cce0-0000-001203000020","translation":"FOLD_RETURN_TO_ZERO","unfold_event_id":"00065a1d-7f9e-9290-0001-001201000020","zero_hair":true}
{"channel":"live_orders_ethusd","interaction_index":556,"natural_form":{"channel":"live_orders_ethusd","order_id":"2044303881850882","order_subtype":5,"order_type":1},"natural_form_sha256":"09f66d7f7b1142b6861ec2977d14ad4b56b35338fed0aa8527ac5ddaf4321e1b","order_source":"orderbook","orders_submitted":0,"presentation":{"amount":"2.015283","amount_traded":"0","microtimestamp":"1787932602063000","price":"2481.51"},"previous_record_hash":"514868da3f61328ca83488eea661a2565aa49ede24f96966e790ed70f3adf260","profit_assessment":null,"record_hash":"6dc31a691e7f878f39d0afdaad87d2e14394e0d14cdd1026f5670c34a5e0c175","recorded_unix_us":1787932602097943,"recorded_utc":"2026-08-28T15:56:42.097943Z","schema_version":"nrrf810.exchange_authored_interactive_closure.v1","source_chain_continuous":true,"source_event":"order_created","source_event_id":"00065a1d-7fa0-d898-0001-001201000020","source_event_id_unique":true,"source_pre_event_id":"00065a1d-7fa0-d898-0000-001200000020","translation":"UNFOLD_TO_INF","unfold_event_id":null,"zero_hair":false}
{"channel":"live_orders_ethbtc","interaction_index":557,"natural_form":{"channel":"live_orders_ethbtc","order_id":"2044303881854976","order_subtype":5,"order_type":1},"natural_form_sha256":"0f85b5e762944e3428d86e032d56f7968c6a093bab3f1d41754f322ed174978b","order_source":"orderbook","orders_submitted":0,"presentation":{"amount":"2.01528391","amount_traded":"0","microtimestamp":"1787932602063000","price":"0.03163293"},"previous_record_hash":"6dc31a691e7f878f39d0afdaad87d2e14394e0d14cdd1026f5670c34a5e0c175","profit_assessment":null,"record_hash":"768d68d2ba171d46e3b6e053da9990c4eb4cc09f8cd688d484671ba10e5405ce","recorded_unix_us":1787932602098046,"recorded_utc":"2026-08-28T15:56:42.098046Z","schema_version":"nrrf810.exchange_authored_interactive_closure.v1","source_chain_continuous":true,"source_event":"order_created","source_event_id":"00065a1d-7fa0-d898-0000-001100000020","source_event_id_unique":true,"source_pre_event_id":"00065a1d-7fa0-9a18-0000-001103000020","translation":"UNFOLD_TO_INF","unfold_event_id":null,"zero_hair":false}
{"channel":"live_orders_ethusd","interaction_index":558,"natural_form":{"channel":"live_orders_ethusd","order_id":"2044303880785925","order_subtype":5,"order_type":1},"natural_form_sha256":"24567b42ae1f751fe8f49c09e531849c342d5ed84c85cdec1eb88db351f58ee4","order_source":"orderbook","orders_submitted":0,"presentation":{"amount":"0.044018","amount_traded":"0","microtimestamp":"1787932602063000","price":"2480.82"},"previous_record_hash":"768d68d2ba171d46e3b6e053da9990c4eb4cc09f8cd688d484671ba10e5405ce","profit_assessment":null,"record_hash":"7cea35ad0b7dcefb9fdb657c490bb04105158a4b4ad219bbc5e281f982cef90b","recorded_unix_us":1787932602098147,"recorded_utc":"2026-08-28T15:56:42.098147Z","schema_version":"nrrf810.exchange_authored_interactive_closure.v1","source_chain_continuous":true,"source_event":"order_deleted","source_event_id":"00065a1d-7fa0-d898-0002-001202000020","source_event_id_unique":true,"source_pre_event_id":"00065a1d-7fa0-d898-0001-001201000020","translation":"FOLD_RETURN_TO_ZERO","unfold_event_id":"00065a1d-7f9c-e0f8-0000-001202000020","zero_hair":true}
{"channel":"live_orders_btcusd","interaction_index":559,"natural_form":{"channel":"live_orders_btcusd","order_id":"2044303881863168","order_subtype":5,"order_type":0},"natural_form_sha256":"ee8297b5006d8c9a50534f4b2c5c5856e30a45a1409278f3e3102303a5a00d9c","order_source":"orderbook","orders_submitted":0,"presentation":{"amount":"0.00140266","amount_traded":"0","microtimestamp":"1787932602065000","price":"70666.76"},"previous_record_hash":"7cea35ad0b7dcefb9fdb657c490bb04105158a4b4ad219bbc5e281f982cef90b","profit_assessment":null,"record_hash":"f468524bf8be61d35cc177ec9715409b1527b34e1e39b4a4acecd0921fffb73d","recorded_unix_us":1787932602117247,"recorded_utc":"2026-08-28T15:56:42.117247Z","schema_version":"nrrf810.exchange_authored_interactive_closure.v1","source_chain_continuous":true,"source_event":"order_created","source_event_id":"00065a1d-7fa0-e068-0000-000101000020","source_event_id_unique":true,"source_pre_event_id":"00065a1d-7fa0-b570-0000-000100000020","translation":"UNFOLD_TO_INF","unfold_event_id":null,"zero_hair":false}
{"channel":"live_orders_ethusd","interaction_index":560,"natural_form":{"channel":"live_orders_ethusd","order_id":"2044303881867264","order_subtype":5,"order_type":0},"natural_form_sha256":"7219ec5ffbb6d66e876726509272d9924dd20e0e840824c71c707ae28c2ef525","order_source":"orderbook","orders_submitted":0,"presentation":{"amount":"2.000000","amount_traded":"0","microtimestamp":"1787932602066000","price":"2479.07"},"previous_record_hash":"f468524bf8be61d35cc177ec9715409b1527b34e1e39b4a4acecd0921fffb73d","profit_assessment":null,"record_hash":"d50a36c38c8db0ce50782461276450612d9fffbd46e34dc6cdb6b83bfb5769a9","recorded_unix_us":1787932602117437,"recorded_utc":"2026-08-28T15:56:42.117437Z","schema_version":"nrrf810.exchange_authored_interactive_closure.v1","source_chain_continuous":true,"source_event":"order_created","source_event_id":"00065a1d-7fa0-e450-0000-001203000020","source_event_id_unique":true,"source_pre_event_id":"00065a1d-7fa0-d898-0002-001202000020","translation":"UNFOLD_TO_INF","unfold_event_id":null,"zero_hair":false}
{"channel":"live_orders_btcusd","interaction_index":561,"natural_form":{"channel":"live_orders_btcusd","order_id":"2044303881904133","order_subtype":5,"order_type":1},"natural_form_sha256":"4fd9b4c685b7b508162acedffbcb58589fb473a8358ff4fee4c43a0bafdd4636","order_source":"orderbook","orders_submitted":0,"presentation":{"amount":"0.10000000","amount_traded":"0","microtimestamp":"1787932602076000","price":"78522.62"},"previous_record_hash":"d50a36c38c8db0ce50782461276450612d9fffbd46e34dc6cdb6b83bfb5769a9","profit_assessment":null,"record_hash":"42174140c582a9ed422c55ae1a51b3841a54c017c83d034ac1e20bc48c99cdfd","recorded_unix_us":1787932602117580,"recorded_utc":"2026-08-28T15:56:42.117580Z","schema_version":"nrrf810.exchange_authored_interactive_closure.v1","source_chain_continuous":true,"source_event":"order_created","source_event_id":"00065a1d-7fa1-0b60-0000-000102000020","source_event_id_unique":true,"source_pre_event_id":"00065a1d-7fa0-e068-0000-000101000020","translation":"UNFOLD_TO_INF","unfold_event_id":null,"zero_hair":false}
{"channel":"live_orders_btcusd","interaction_index":562,"natural_form":{"channel":"live_orders_btcusd","order_id":"2044303881904133","order_subtype":5,"order_type":1},"natural_form_sha256":"4fd9b4c685b7b508162acedffbcb58589fb473a8358ff4fee4c43a0bafdd4636","order_source":"orderbook","orders_submitted":0,"presentation":{"amount":"0.10000000","amount_traded":"0","microtimestamp":"1787932602076000","price":"78522.62"},"previous_record_hash":"42174140c582a9ed422c55ae1a51b3841a54c017c83d034ac1e20bc48c99cdfd","profit_assessment":null,"record_hash":"6ce5618f77aada7c7c47b10608bc50e1a4bafabecfb378d6635017ccd38b5191","recorded_unix_us":1787932602117614,"recorded_utc":"2026-08-28T15:56:42.117614Z","schema_version":"nrrf810.exchange_authored_interactive_closure.v1","source_chain_continuous":true,"source_event":"order_deleted","source_event_id":"00065a1d-7fa1-0b60-0001-000103000020","source_event_id_unique":true,"source_pre_event_id":"00065a1d-7fa1-0b60-0000-000102000020","translation":"FOLD_RETURN_TO_ZERO","unfold_event_id":"00065a1d-7fa1-0b60-0000-000102000020","zero_hair":true}
{"channel":"live_orders_btcusd","interaction_index":563,"natural_form":{"channel":"live_orders_btcusd","order_id":"2044303881908224","order_subtype":5,"order_type":1},"natural_form_sha256":"6238821f8b7fe78f78a7fde202ed63c86217b20938214dd42880c4da051849da","order_source":"orderbook","orders_submitted":0,"presentation":{"amount":"0.06310787","amount_traded":"0","microtimestamp":"1787932602076000","price":"78521.55"},"previous_record_hash":"6ce5618f77aada7c7c47b10608bc50e1a4bafabecfb378d6635017ccd38b5191","profit_assessment":null,"record_hash":"3c4921d1eaf3323f508bc5871915ffd86cd5478091d0d416a27cad64cc379e43","recorded_unix_us":1787932602117701,"recorded_utc":"2026-08-28T15:56:42.117701Z","schema_version":"nrrf810.exchange_authored_interactive_closure.v1","source_chain_continuous":true,"source_event":"order_created","source_event_id":"00065a1d-7fa1-0b60-0002-000100000020","source_event_id_unique":true,"source_pre_event_id":"00065a1d-7fa1-0b60-0001-000103000020","translation":"UNFOLD_TO_INF","unfold_event_id":null,"zero_hair":false}
{"channel":"live_orders_btcusd","interaction_index":564,"natural_form":{"channel":"live_orders_btcusd","order_id":"2044303881908224","order_subtype":5,"order_type":1},"natural_form_sha256":"6238821f8b7fe78f78a7fde202ed63c86217b20938214dd42880c4da051849da","order_source":"orderbook","orders_submitted":0,"presentation":{"amount":"0.06310787","amount_traded":"0","microtimestamp":"1787932602076000","price":"78521.55"},"previous_record_hash":"3c4921d1eaf3323f508bc5871915ffd86cd5478091d0d416a27cad64cc379e43","profit_assessment":null,"record_hash":"39ad5b45324e767d1c39ef2f2aeea871a11112c6a3d2827031543a3f880d9939","recorded_unix_us":1787932602117863,"recorded_utc":"2026-08-28T15:56:42.117863Z","schema_version":"nrrf810.exchange_authored_interactive_closure.v1","source_chain_continuous":true,"source_event":"order_deleted","source_event_id":"00065a1d-7fa1-0b60-0003-000101000020","source_event_id_unique":true,"source_pre_event_id":"00065a1d-7fa1-0b60-0002-000100000020","translation":"FOLD_RETURN_TO_ZERO","unfold_event_id":"00065a1d-7fa1-0b60-0002-000100000020","zero_hair":true}
