{"channel":"live_orders_btcusd","interaction_index":0,"natural_form":{"channel":"live_orders_btcusd","order_id":"2044303878127633","order_subtype":5,"order_type":1},"natural_form_sha256":"2748b1908d48990d8e13458623b9002d81af8abc17566f1f419b81a136b6d980","order_source":"orderbook","orders_submitted":0,"presentation":{"amount":"0.10000000","amount_traded":"0","microtimestamp":"1787932601154000","price":"78523.32"},"previous_record_hash":"b52db62a3b7a1fc70a332a09dc668ac529a81d1113fa4b606a23e62026014dc1","profit_assessment":null,"record_hash":"010d49f647252b0eb7966cd26acddcc85e6287ef955af6e6a2ec10d0a93295e4","recorded_unix_us":1787932601208155,"recorded_utc":"2026-08-28T15:56:41.208155Z","schema_version":"nrrf810.exchange_authored_interactive_closure.v1","source_chain_continuous":true,"source_event":"order_created","source_event_id":"00065a1d-7f92-f9d0-0000-000100000020","source_event_id_unique":true,"source_pre_event_id":"00065a1d-7f92-de78-0000-000103000020","translation":"UNFOLD_TO_INF","unfold_event_id":null,"zero_hair":false}
{"channel":"live_orders_ethbtc","interaction_index":1,"natural_form":{"channel":"live_orders_ethbtc","order_id":"2044303848652817","order_subtype":5,"order_type":1},"natural_form_sha256":"9575bb6e5e9adc33fe67810be87cb3a26d286d39ee700eb89a993feaf4667d7c","order_source":"orderbook","orders_submitted":0,"presentation":{"amount":"4.23144408","amount_traded":"0","microtimestamp":"1787932601154000","price":"0.03161039"},"previous_record_hash":"010d49f647252b0eb7966cd26acddcc85e6287ef955af6e6a2ec10d0a93295e4","profit_assessment":null,"record_hash":"9ae815e27de521942b1a2c0e2ea0a1ff8490814871d7f251b56eb169a835fab8","recorded_unix_us":1787932601208293,"recorded_utc":"2026-08-28T15:56:41.208293Z","schema_version":"nrrf810.exchange_authored_interactive_closure.v1","source_chain_continuous":true,"source_event":"order_deleted","source_event_id":"00065a1d-7f92-f9d0-0000-001102000020","source_event_id_unique":true,"source_pre_event_id":"00065a1d-7f92-9058-0000-001101000020","translation":"PARTIAL_PRIOR_UNFOLD","unfold_event_id":null,"zero_hair":false}
{"channel":"live_orders_btcusd","interaction_index":2,"natural_form":{"channel":"live_orders_btcusd","order_id":"2044303877451783","order_subtype":5,"order_type":0},"natural_form_sha256":"890fc7348d55eefa65d9cf5cd596f9c28bf87f80d8e6323be098956e656c7c73","order_source":"orderbook","orders_submitted":0,"presentation":{"amount":"0.19103952","amount_traded":"0","microtimestamp":"1787932601156000","price":"78479.69"},"previous_record_hash":"9ae815e27de521942b1a2c0e2ea0a1ff8490814871d7f251b56eb169a835fab8","profit_assessment":null,"record_hash":"7ca4ff0e924dabc562132ec71b762d299e6f09f97505dc10fffb970eebceac37","recorded_unix_us":1787932601208411,"recorded_utc":"2026-08-28T15:56:41.208411Z","schema_version":"nrrf810.exchange_authored_interactive_closure.v1","source_chain_continuous":true,"source_event":"order_deleted","source_event_id":"00065a1d-7f93-01a0-0000-000101000020","source_event_id_unique":true,"source_pre_event_id":"00065a1d-7f92-f9d0-0000-000100000020","translation":"PARTIAL_PRIOR_UNFOLD","unfold_event_id":null,"zero_hair":false}
{"channel":"live_orders_btcusd","interaction_index":3,"natural_form":{"channel":"live_orders_btcusd","order_id":"2044303878144010","order_subtype":5,"order_type":1},"natural_form_sha256":"7de4357cd589c4bce05c929a6c649b8b5a4e15f1517254b60dbbe5c8ac54a880","order_source":"orderbook","orders_submitted":0,"presentation":{"amount":"0.10000000","amount_traded":"0","microtimestamp":"1787932601158000","price":"78522.62"},"previous_record_hash":"7ca4ff0e924dabc562132ec71b762d299e6f09f97505dc10fffb970eebceac37","profit_assessment":null,"record_hash":"fccc5d8a323bf9f25c3a83b5b36b01fdadc789b9f486cfb8b10ed19264767d4c","recorded_unix_us":1787932601208546,"recorded_utc":"2026-08-28T15:56:41.208546Z","schema_version":"nrrf810.exchange_authored_interactive_closure.v1","source_chain_continuous":true,"source_event":"order_created","source_event_id":"00065a1d-7f93-0970-0000-000102000020","source_event_id_unique":true,"source_pre_event_id":"00065a1d-7f93-01a0-0000-000101000020","translation":"UNFOLD_TO_INF","unfold_event_id":null,"zero_hair":false}
{"channel":"live_orders_btcusd","interaction_index":4,"natural_form":{"channel":"live_orders_btcusd","order_id":"2044303878144010","order_subtype":5,"order_type":1},"natural_form_sha256":"7de4357cd589c4bce05c929a6c649b8b5a4e15f1517254b60dbbe5c8ac54a880","order_source":"orderbook","orders_submitted":0,"presentation":{"amount":"0.10000000","amount_traded":"0","microtimestamp":"1787932601158000","price":"78522.62"},"previous_record_hash":"fccc5d8a323bf9f25c3a83b5b36b01fdadc789b9f486cfb8b10ed19264767d4c","profit_assessment":null,"record_hash":"e6768a7867cf4a98cdd20dc5c66356598e54bd0b821a7cee71486f48221738ff","recorded_unix_us":1787932601208580,"recorded_utc":"2026-08-28T15:56:41.208580Z","schema_version":"nrrf810.exchange_authored_interactive_closure.v1","source_chain_continuous":true,"source_event":"order_deleted","source_event_id":"00065a1d-7f93-0970-0001-000103000020","source_event_id_unique":true,"source_pre_event_id":"00065a1d-7f93-0970-0000-000102000020","translation":"FOLD_RETURN_TO_ZERO","unfold_event_id":"00065a1d-7f93-0970-0000-000102000020","zero_hair":true}
{"channel":"live_orders_ethusd","interaction_index":5,"natural_form":{"channel":"live_orders_ethusd","order_id":"2044303878144016","order_subtype":5,"order_type":0},"natural_form_sha256":"8a7c9c9132750bac2d8f0048e1e7a396a07122c5c2ecf0d3fc4d01f50012d7c2","order_source":"orderbook","orders_submitted":0,"presentation":{"amount":"6.044921","amount_traded":"0","microtimestamp":"1787932601158000","price":"2480.00"},"previous_record_hash":"e6768a7867cf4a98cdd20dc5c66356598e54bd0b821a7cee71486f48221738ff","profit_assessment":null,"record_hash":"403e84010596174e12e56688d94b284d78afaefd83711f2731434c482d3e13f4","recorded_unix_us":1787932601208673,"recorded_utc":"2026-08-28T15:56:41.208673Z","schema_version":"nrrf810.exchange_authored_interactive_closure.v1","source_chain_continuous":true,"source_event":"order_created","source_event_id":"00065a1d-7f93-0970-0000-001200000020","source_event_id_unique":true,"source_pre_event_id":"00065a1d-7f92-f200-0000-001203000020","translation":"UNFOLD_TO_INF","unfold_event_id":null,"zero_hair":false}
{"channel":"live_orders_ethusd","interaction_index":6,"natural_form":{"channel":"live_orders_ethusd","order_id":"2044303878152198","order_subtype":5,"order_type":1},"natural_form_sha256":"0ab1412869eece2ba656c5437ec33561eacc8b4d5a16cbf1aa94b7615137aa01","order_source":"orderbook","orders_submitted":0,"presentation":{"amount":"6.044921","amount_traded":"0","microtimestamp":"1787932601159000","price":"2481.75"},"previous_record_hash":"403e84010596174e12e56688d94b284d78afaefd83711f2731434c482d3e13f4","profit_assessment":null,"record_hash":"31707c88aae13d1ed97520f7f986393d3be2912dab1907d640909686d4ae5086","recorded_unix_us":1787932601208785,"recorded_utc":"2026-08-28T15:56:41.208785Z","schema_version":"nrrf810.exchange_authored_interactive_closure.v1","source_chain_continuous":true,"source_event":"order_created","source_event_id":"00065a1d-7f93-0d58-0000-001201000020","source_event_id_unique":true,"source_pre_event_id":"00065a1d-7f93-0970-0000-001200000020","translation":"UNFOLD_TO_INF","unfold_event_id":null,"zero_hair":false}
{"channel":"live_orders_btcusd","interaction_index":7,"natural_form":{"channel":"live_orders_btcusd","order_id":"2044303878176779","order_subtype":5,"order_type":0},"natural_form_sha256":"eca86c4d8ac91c40bc9b8fb4555822808b62d89a87af2fc337e347721fa3682b","order_source":"orderbook","orders_submitted":0,"presentation":{"amount":"0.19104140","amount_traded":"0","microtimestamp":"1787932601166000","price":"78481.58"},"previous_record_hash":"31707c88aae13d1ed97520f7f986393d3be2912dab1907d640909686d4ae5086","profit_assessment":null,"record_hash":"2bdcbd982113d341f0fcdb0d07fe078495af028e4bfd8ab94d175f86ad6c2015","recorded_unix_us":1787932601208855,"recorded_utc":"2026-08-28T15:56:41.208855Z","schema_version":"nrrf810.exchange_authored_interactive_closure.v1","source_chain_continuous":true,"source_event":"order_created","source_event_id":"00065a1d-7f93-28b0-0000-000100000020","source_event_id_unique":true,"source_pre_event_id":"00065a1d-7f93-0970-0001-000103000020","translation":"UNFOLD_TO_INF","unfold_event_id":null,"zero_hair":false}
{"channel":"live_orders_ethusd","interaction_index":8,"natural_form":{"channel":"live_orders_ethusd","order_id":"2044303878205450","order_subtype":5,"order_type":0},"natural_form_sha256":"17c790ad367ddcdb58f20ff33928d54813b26628abc98fb67e3f09a3e4bc2b13","order_source":"orderbook","orders_submitted":0,"presentation":{"amount":"4.034894","amount_traded":"0","microtimestamp":"1787932601173000","price":"2478.37"},"previous_record_hash":"2bdcbd982113d341f0fcdb0d07fe078495af028e4bfd8ab94d175f86ad6c2015","profit_assessment":null,"record_hash":"72b9f5abad0ea1c3a58cfb47650bd56ddcc99850b0f12035b18ef76b80b8de2c","recorded_unix_us":1787932601208945,"recorded_utc":"2026-08-28T15:56:41.208945Z","schema_version":"nrrf810.exchange_authored_interactive_closure.v1","source_chain_continuous":true,"source_event":"order_created","source_event_id":"00065a1d-7f93-4408-0000-001202000020","source_event_id_unique":true,"source_pre_event_id":"00065a1d-7f93-0d58-0000-001201000020","translation":"UNFOLD_TO_INF","unfold_event_id":null,"zero_hair":false}
{"channel":"live_orders_ethusd","interaction_index":9,"natural_form":{"channel":"live_orders_ethusd","order_id":"2044303878213635","order_subtype":5,"order_type":0},"natural_form_sha256":"17635897d7e09886bb7125a3ab26144c31fc8151c0ca82129ede6bb2ece40520","order_source":"orderbook","orders_submitted":0,"presentation":{"amount":"20.235437","amount_traded":"0","microtimestamp":"1787932601174000","price":"2470.91"},"previous_record_hash":"72b9f5abad0ea1c3a58cfb47650bd56ddcc99850b0f12035b18ef76b80b8de2c","profit_assessment":null,"record_hash":"696f8fe07910c2e4cbe45e41d4140a38c0035a554a749f76b1093fed4fe7394d","recorded_unix_us":1787932601317771,"recorded_utc":"2026-08-28T15:56:41.317771Z","schema_version":"nrrf810.exchange_authored_interactive_closure.v1","source_chain_continuous":true,"source_event":"order_created","source_event_id":"00065a1d-7f93-47f0-0000-001203000020","source_event_id_unique":true,"source_pre_event_id":"00065a1d-7f93-4408-0000-001202000020","translation":"UNFOLD_TO_INF","unfold_event_id":null,"zero_hair":false}
{"channel":"live_orders_btcusd","interaction_index":10,"natural_form":{"channel":"live_orders_btcusd","order_id":"2044303878217731","order_subtype":5,"order_type":1},"natural_form_sha256":"87149fe3db402e35effa116bc3d39a74eec2c817c39b6719c820078cf16315e4","order_source":"orderbook","orders_submitted":0,"presentation":{"amount":"0.10000000","amount_traded":"0","microtimestamp":"1787932601175000","price":"78522.63"},"previous_record_hash":"696f8fe07910c2e4cbe45e41d4140a38c0035a554a749f76b1093fed4fe7394d","profit_assessment":null,"record_hash":"d4fe4593dd2c3738a5aed8e7f9248ec35f20fba8f4042f58961a1d4f9e12802d","recorded_unix_us":1787932601317990,"recorded_utc":"2026-08-28T15:56:41.317990Z","schema_version":"nrrf810.exchange_authored_interactive_closure.v1","source_chain_continuous":true,"source_event":"order_created","source_event_id":"00065a1d-7f93-4bd8-0000-000101000020","source_event_id_unique":true,"source_pre_event_id":"00065a1d-7f93-28b0-0000-000100000020","translation":"UNFOLD_TO_INF","unfold_event_id":null,"zero_hair":false}
{"channel":"live_orders_btcusd","interaction_index":11,"natural_form":{"channel":"live_orders_btcusd","order_id":"2044303878217731","order_subtype":5,"order_type":1},"natural_form_sha256":"87149fe3db402e35effa116bc3d39a74eec2c817c39b6719c820078cf16315e4","order_source":"orderbook","orders_submitted":0,"presentation":{"amount":"0.10000000","amount_traded":"0","microtimestamp":"1787932601175000","price":"78522.63"},"previous_record_hash":"d4fe4593dd2c3738a5aed8e7f9248ec35f20fba8f4042f58961a1d4f9e12802d","profit_assessment":null,"record_hash":"b73be8a1783263af161a2f004cdab70f5ee2d7fec3cb28ca8504f3b58e7109a7","recorded_unix_us":1787932601318490,"recorded_utc":"2026-08-28T15:56:41.318490Z","schema_version":"nrrf810.exchange_authored_interactive_closure.v1","source_chain_continuous":true,"source_event":"order_deleted","source_event_id":"00065a1d-7f93-4bd8-0001-000102000020","source_event_id_unique":true,"source_pre_event_id":"00065a1d-7f93-4bd8-0000-000101000020","translation":"FOLD_RETURN_TO_ZERO","unfold_event_id":"00065a1d-7f93-4bd8-0000-000101000020","zero_hair":true}
{"channel":"live_orders_btcusd","interaction_index":12,"natural_form":{"channel":"live_orders_btcusd","order_id":"2044303878225930","order_subtype":5,"order_type":0},"natural_form_sha256":"69c1c4c067a22c44faed60799a391f4aec47c7efe57fe141106edbe7643e4cd0","order_source":"orderbook","orders_submitted":0,"presentation":{"amount":"0.50000000","amount_traded":"0","microtimestamp":"1787932601178000","price":"78507.73"},"previous_record_hash":"b73be8a1783263af161a2f004cdab70f5ee2d7fec3cb28ca8504f3b58e7109a7","profit_assessment":null,"record_hash":"9bfb7a70fb421c778d441bad51e039c9150225351432d0f52b1a907642dbc02b","recorded_unix_us":1787932601318538,"recorded_utc":"2026-08-28T15:56:41.318538Z","schema_version":"nrrf810.exchange_authored_interactive_closure.v1","source_chain_continuous":true,"source_event":"order_created","source_event_id":"00065a1d-7f93-5790-0000-000103000020","source_event_id_unique":true,"source_pre_event_id":"00065a1d-7f93-4bd8-0001-000102000020","translation":"UNFOLD_TO_INF","unfold_event_id":null,"zero_hair":false}
{"channel":"live_orders_btcusd","interaction_index":13,"natural_form":{"channel":"live_orders_btcusd","order_id":"2044303878234112","order_subtype":5,"order_type":0},"natural_form_sha256":"c6ecaaf26fb3bff6a369d809be72f3809163bbc5f60d86298b44f17e46475150","order_source":"orderbook","orders_submitted":0,"presentation":{"amount":"0.25000000","amount_traded":"0","microtimestamp":"1787932601179000","price":"78511.65"},"previous_record_hash":"9bfb7a70fb421c778d441bad51e039c9150225351432d0f52b1a907642dbc02b","profit_assessment":null,"record_hash":"7327ac192b1ab7aadc8ee390162a875d8007afca2a22792cd94fc0d63428841e","recorded_unix_us":1787932601318567,"recorded_utc":"2026-08-28T15:56:41.318567Z","schema_version":"nrrf810.exchange_authored_interactive_closure.v1","source_chain_continuous":true,"source_event":"order_created","source_event_id":"00065a1d-7f93-5b78-0000-000100000020","source_event_id_unique":true,"source_pre_event_id":"00065a1d-7f93-5790-0000-000103000020","translation":"UNFOLD_TO_INF","unfold_event_id":null,"zero_hair":false}
{"channel":"live_orders_btcusd","interaction_index":14,"natural_form":{"channel":"live_orders_btcusd","order_id":"2044303877533697","order_subtype":5,"order_type":0},"natural_form_sha256":"bf335535de7b35d4a26d0e600d27a9047fca77b5cad1f70afa09c2b3e52d6fe9","order_source":"orderbook","orders_submitted":0,"presentation":{"amount":"0.63679819","amount_traded":"0","microtimestamp":"1787932601179000","price":"78477.98"},"previous_record_hash":"7327ac192b1ab7aadc8ee390162a875d8007afca2a22792cd94fc0d63428841e","profit_assessment":null,"record_hash":"944924931575961e8234b301770f0bbd6a525b7ddd5cd8c6f2906fdc866ab601","recorded_unix_us":1787932601318592,"recorded_utc":"2026-08-28T15:56:41.318592Z","schema_version":"nrrf810.exchange_authored_interactive_closure.v1","source_chain_continuous":true,"source_event":"order_deleted","source_event_id":"00065a1d-7f93-5b78-0001-000101000020","source_event_id_unique":true,"source_pre_event_id":"00065a1d-7f93-5b78-0000-000100000020","translation":"PARTIAL_PRIOR_UNFOLD","unfold_event_id":null,"zero_hair":false}
{"channel":"live_orders_btcusd","interaction_index":15,"natural_form":{"channel":"live_orders_btcusd","order_id":"2044303877595137","order_subtype":5,"order_type":0},"natural_form_sha256":"888b7ab1c99016d95c8af55c9e6fd38fe5bbc01f3549d9c38dae65ce684965be","order_source":"orderbook","orders_submitted":0,"presentation":{"amount":"0.50943865","amount_traded":"0","microtimestamp":"1787932601180000","price":"78476.17"},"previous_record_hash":"944924931575961e8234b301770f0bbd6a525b7ddd5cd8c6f2906fdc866ab601","profit_assessment":null,"record_hash":"7d60a94dbc3453a738a0d5f11ddf9c2b4c501e38a27a605d13a40cae24323dee","recorded_unix_us":1787932601318618,"recorded_utc":"2026-08-28T15:56:41.318618Z","schema_version":"nrrf810.exchange_authored_interactive_closure.v1","source_chain_continuous":true,"source_event":"order_deleted","source_event_id":"00065a1d-7f93-5f60-0000-000102000020","source_event_id_unique":true,"source_pre_event_id":"00065a1d-7f93-5b78-0001-000101000020","translation":"PARTIAL_PRIOR_UNFOLD","unfold_event_id":null,"zero_hair":false}
{"channel":"live_orders_ethusd","interaction_index":16,"natural_form":{"channel":"live_orders_ethusd","order_id":"2044303878246406","order_subtype":5,"order_type":1},"natural_form_sha256":"cdd01c75bebe5242621802a88aa166c7f0240efd94ccb81b50ceae1c56d963e9","order_source":"orderbook","orders_submitted":0,"presentation":{"amount":"6.000000","amount_traded":"0","microtimestamp":"1787932601183000","price":"2482.48"},"previous_record_hash":"7d60a94dbc3453a738a0d5f11ddf9c2b4c501e38a27a605d13a40cae24323dee","profit_assessment":null,"record_hash":"c6650b392f3ade41aded16e0e3b93341043ea195bd7b9f1d6dd50438305a126a","recorded_unix_us":1787932601318720,"recorded_utc":"2026-08-28T15:56:41.318720Z","schema_version":"nrrf810.exchange_authored_interactive_closure.v1","source_chain_continuous":true,"source_event":"order_created","source_event_id":"00065a1d-7f93-6b18-0000-001200000020","source_event_id_unique":true,"source_pre_event_id":"00065a1d-7f93-47f0-0000-001203000020","translation":"UNFOLD_TO_INF","unfold_event_id":null,"zero_hair":false}
{"channel":"live_orders_btcusd","interaction_index":17,"natural_form":{"channel":"live_orders_btcusd","order_id":"2044303878266885","order_subtype":5,"order_type":0},"natural_form_sha256":"ed56c945037d78672ab73a13f6b1bd020776a683839cce24cd89c024649b2916","order_source":"orderbook","orders_submitted":0,"presentation":{"amount":"0.00140266","amount_traded":"0","microtimestamp":"1787932601187000","price":"70670.37"},"previous_record_hash":"c6650b392f3ade41aded16e0e3b93341043ea195bd7b9f1d6dd50438305a126a","profit_assessment":null,"record_hash":"bbeeddc4efee555d84950f940c6d15d504416439a0c85764d9b07df16a829975","recorded_unix_us":1787932601319094,"recorded_utc":"2026-08-28T15:56:41.319094Z","schema_version":"nrrf810.exchange_authored_interactive_closure.v1","source_chain_continuous":true,"source_event":"order_created","source_event_id":"00065a1d-7f93-7ab8-0000-000103000020","source_event_id_unique":true,"source_pre_event_id":"00065a1d-7f93-5f60-0000-000102000020","translation":"UNFOLD_TO_INF","unfold_event_id":null,"zero_hair":false}
{"channel":"live_orders_btcusd","interaction_index":18,"natural_form":{"channel":"live_orders_btcusd","order_id":"2044303878279172","order_subtype":5,"order_type":0},"natural_form_sha256":"6d706412054707e096890d565cd6ef6247f285cc955adfbf8f645f4b1058641f","order_source":"orderbook","orders_submitted":0,"presentation":{"amount":"0.63679790","amount_traded":"0","microtimestamp":"1787932601190000","price":"78480.38"},"previous_record_hash":"bbeeddc4efee555d84950f940c6d15d504416439a0c85764d9b07df16a829975","profit_assessment":null,"record_hash":"276f5789e2ba06fbf0cee84f518535bba85e47a074b80bd7f7e56908c8bd646c","recorded_unix_us":1787932601319133,"recorded_utc":"2026-08-28T15:56:41.319133Z","schema_version":"nrrf810.exchange_authored_interactive_closure.v1","source_chain_continuous":true,"source_event":"order_created","source_event_id":"00065a1d-7f93-8670-0000-000100000020","source_event_id_unique":true,"source_pre_event_id":"00065a1d-7f93-7ab8-0000-000103000020","translation":"UNFOLD_TO_INF","unfold_event_id":null,"zero_hair":false}
{"channel":"live_orders_btcusd","interaction_index":19,"natural_form":{"channel":"live_orders_btcusd","order_id":"2044303878283264","order_subtype":5,"order_type":0},"natural_form_sha256":"f7e06971054d5f66b74303984b3e58b2e75f7c2955003d188da8e71a501d36d1","order_source":"orderbook","orders_submitted":0,"presentation":{"amount":"0.50943832","amount_traded":"0","microtimestamp":"1787932601191000","price":"78478.42"},"previous_record_hash":"276f5789e2ba06fbf0cee84f518535bba85e47a074b80bd7f7e56908c8bd646c","profit_assessment":null,"record_hash":"982e34c2b2a39f77ab0ec5d4beaa61a8fe601c3a9687dd148607990d8a68d72b","recorded_unix_us":1787932601319159,"recorded_utc":"2026-08-28T15:56:41.319159Z","schema_version":"nrrf810.exchange_authored_interactive_closure.v1","source_chain_continuous":true,"source_event":"order_created","source_event_id":"00065a1d-7f93-8a58-0000-000101000020","source_event_id_unique":true,"source_pre_event_id":"00065a1d-7f93-8670-0000-000100000020","translation":"UNFOLD_TO_INF","unfold_event_id":null,"zero_hair":false}
{"channel":"live_orders_btcusd","interaction_index":20,"natural_form":{"channel":"live_orders_btcusd","order_id":"2044303876714497","order_subtype":5,"order_type":1},"natural_form_sha256":"8dc4115acffc02d49f06e4e09be0cf521ce00b3e81164f9ebcc379b49b720f7a","order_source":"orderbook","orders_submitted":0,"presentation":{"amount":"0.10000000","amount_traded":"0","microtimestamp":"1787932601191000","price":"78523.51"},"previous_record_hash":"982e34c2b2a39f77ab0ec5d4beaa61a8fe601c3a9687dd148607990d8a68d72b","profit_assessment":null,"record_hash":"770b9dd70b3d201ca1a72c7d5d64f58b86d5d207a4d563a0ffa94a88e4cd637c","recorded_unix_us":1787932601319186,"recorded_utc":"2026-08-28T15:56:41.319186Z","schema_version":"nrrf810.exchange_authored_interactive_closure.v1","source_chain_continuous":true,"source_event":"order_deleted","source_event_id":"00065a1d-7f93-8a58-0001-000102000020","source_event_id_unique":true,"source_pre_event_id":"00065a1d-7f93-8a58-0000-000101000020","translation":"PARTIAL_PRIOR_UNFOLD","unfold_event_id":null,"zero_hair":false}
{"channel":"live_orders_btcusd","interaction_index":21,"natural_form":{"channel":"live_orders_btcusd","order_id":"2044303878283276","order_subtype":5,"order_type":1},"natural_form_sha256":"a7294b797a08053db0c63277cd4d9ad0f706ac65a010f3257cf646a5850639d9","order_source":"orderbook","orders_submitted":0,"presentation":{"amount":"0.10000000","amount_traded":"0","microtimestamp":"1787932601192000","price":"78522.62"},"previous_record_hash":"770b9dd70b3d201ca1a72c7d5d64f58b86d5d207a4d563a0ffa94a88e4cd637c","profit_assessment":null,"record_hash":"af45a86edb5b4f5d7108febb453d428de118d577f868c2cc347f9dcadf6fa2e5","recorded_unix_us":1787932601319211,"recorded_utc":"2026-08-28T15:56:41.319211Z","schema_version":"nrrf810.exchange_authored_interactive_closure.v1","source_chain_continuous":true,"source_event":"order_created","source_event_id":"00065a1d-7f93-8e40-0000-000103000020","source_event_id_unique":true,"source_pre_event_id":"00065a1d-7f93-8a58-0001-000102000020","translation":"UNFOLD_TO_INF","unfold_event_id":null,"zero_hair":false}
{"channel":"live_orders_btcusd","interaction_index":22,"natural_form":{"channel":"live_orders_btcusd","order_id":"2044303878283276","order_subtype":5,"order_type":1},"natural_form_sha256":"a7294b797a08053db0c63277cd4d9ad0f706ac65a010f3257cf646a5850639d9","order_source":"orderbook","orders_submitted":0,"presentation":{"amount":"0.10000000","amount_traded":"0","microtimestamp":"1787932601192000","price":"78522.62"},"previous_record_hash":"af45a86edb5b4f5d7108febb453d428de118d577f868c2cc347f9dcadf6fa2e5","profit_assessment":null,"record_hash":"5207fc8acf496661ff2c43c7dd77709341e1eacf45ff502dd765cfc95438128a","recorded_unix_us":1787932601319237,"recorded_utc":"2026-08-28T15:56:41.319237Z","schema_version":"nrrf810.exchange_authored_interactive_closure.v1","source_chain_continuous":true,"source_event":"order_deleted","source_event_id":"00065a1d-7f93-8e40-0001-000100000020","source_event_id_unique":true,"source_pre_event_id":"00065a1d-7f93-8e40-0000-000103000020","translation":"FOLD_RETURN_TO_ZERO","unfold_event_id":"00065a1d-7f93-8e40-0000-000103000020","zero_hair":true}
{"channel":"live_orders_ethusd","interaction_index":23,"natural_form":{"channel":"live_orders_ethusd","order_id":"2044303878287371","order_subtype":5,"order_type":0},"natural_form_sha256":"0afdda0e1d600148324cb5b1221c22f7ef4c64f50dc1752741fa3a1b0d3bb2d1","order_source":"orderbook","orders_submitted":0,"presentation":{"amount":"10.090138","amount_traded":"0","microtimestamp":"1787932601193000","price":"2477.66"},"previous_record_hash":"5207fc8acf496661ff2c43c7dd77709341e1eacf45ff502dd765cfc95438128a","profit_assessment":null,"record_hash":"601d02ec334c8807b69b70ced1bf76700e231704cf4f1372588317ab4addc951","recorded_unix_us":1787932601319262,"recorded_utc":"2026-08-28T15:56:41.319262Z","schema_version":"nrrf810.exchange_authored_interactive_closure.v1","source_chain_continuous":true,"source_event":"order_created","source_event_id":"00065a1d-7f93-9228-0000-001201000020","source_event_id_unique":true,"source_pre_event_id":"00065a1d-7f93-6b18-0000-001200000020","translation":"UNFOLD_TO_INF","unfold_event_id":null,"zero_hair":false}
{"channel":"live_orders_btcusd","interaction_index":24,"natural_form":{"channel":"live_orders_btcusd","order_id":"2044303878291459","order_subtype":5,"order_type":1},"natural_form_sha256":"9f534bf63c29802d8377806862b393a3bd27a349a4ac768932641d6b59dd16b9","order_source":"orderbook","orders_submitted":0,"presentation":{"amount":"0.10000000","amount_traded":"0","microtimestamp":"1787932601193000","price":"78523.24"},"previous_record_hash":"601d02ec334c8807b69b70ced1bf76700e231704cf4f1372588317ab4addc951","profit_assessment":null,"record_hash":"10ee9495de77516080be6aad67a119a6752551b1fc4be28d9267a91f60f714da","recorded_unix_us":1787932601319350,"recorded_utc":"2026-08-28T15:56:41.319350Z","schema_version":"nrrf810.exchange_authored_interactive_closure.v1","source_chain_continuous":true,"source_event":"order_created","source_event_id":"00065a1d-7f93-9228-0000-000101000020","source_event_id_unique":true,"source_pre_event_id":"00065a1d-7f93-8e40-0001-000100000020","translation":"UNFOLD_TO_INF","unfold_event_id":null,"zero_hair":false}
{"channel":"live_orders_ethusd","interaction_index":25,"natural_form":{"channel":"live_orders_ethusd","order_id":"2044303878291460","order_subtype":5,"order_type":0},"natural_form_sha256":"b0d9dd036dc012db61a60df3d210831661e5dc4bc9ae33816650887c3a81a420","order_source":"orderbook","orders_submitted":0,"presentation":{"amount":"10.095101","amount_traded":"0","microtimestamp":"1787932601193000","price":"2476.44"},"previous_record_hash":"10ee9495de77516080be6aad67a119a6752551b1fc4be28d9267a91f60f714da","profit_assessment":null,"record_hash":"117f5e5d10a0f357304504eeac14abd5aa6d00e068a91128d97c3a50fb870356","recorded_unix_us":1787932601319476,"recorded_utc":"2026-08-28T15:56:41.319476Z","schema_version":"nrrf810.exchange_authored_interactive_closure.v1","source_chain_continuous":true,"source_event":"order_created","source_event_id":"00065a1d-7f93-9228-0001-001202000020","source_event_id_unique":true,"source_pre_event_id":"00065a1d-7f93-9228-0000-001201000020","translation":"UNFOLD_TO_INF","unfold_event_id":null,"zero_hair":false}
{"channel":"live_orders_ethusd","interaction_index":26,"natural_form":{"channel":"live_orders_ethusd","order_id":"2044303878291467","order_subtype":5,"order_type":0},"natural_form_sha256":"08a6430ec2dcf149e52808e6112b03d3ceceb00b8837cca59e634250c8de61a7","order_source":"orderbook","orders_submitted":0,"presentation":{"amount":"40.650432","amount_traded":"0","microtimestamp":"1787932601194000","price":"2459.99"},"previous_record_hash":"117f5e5d10a0f357304504eeac14abd5aa6d00e068a91128d97c3a50fb870356","profit_assessment":null,"record_hash":"a38ef259edb2897ff9260430bec1bd993b9e96f3708aca27008a1a44b2955a47","recorded_unix_us":1787932601319523,"recorded_utc":"2026-08-28T15:56:41.319523Z","schema_version":"nrrf810.exchange_authored_interactive_closure.v1","source_chain_continuous":true,"source_event":"order_created","source_event_id":"00065a1d-7f93-9610-0000-001203000020","source_event_id_unique":true,"source_pre_event_id":"00065a1d-7f93-9228-0001-001202000020","translation":"UNFOLD_TO_INF","unfold_event_id":null,"zero_hair":false}
{"channel":"live_orders_ethusd","interaction_index":27,"natural_form":{"channel":"live_orders_ethusd","order_id":"2044303878295552","order_subtype":5,"order_type":0},"natural_form_sha256":"c9ae39924c2d431a723ed23a4f27d60d7e619e094b4f40dbf8f507454b6dd6d4","order_source":"orderbook","orders_submitted":0,"presentation":{"amount":"4.033601","amount_traded":"0","microtimestamp":"1787932601194000","price":"2479.17"},"previous_record_hash":"a38ef259edb2897ff9260430bec1bd993b9e96f3708aca27008a1a44b2955a47","profit_assessment":null,"record_hash":"22bf9650ba757c5cf10285dcd7dc2d37927025c8616da851977c7fcfd589fced","recorded_unix_us":1787932601319611,"recorded_utc":"2026-08-28T15:56:41.319611Z","schema_version":"nrrf810.exchange_authored_interactive_closure.v1","source_chain_continuous":true,"source_event":"order_created","source_event_id":"00065a1d-7f93-9610-0001-001200000020","source_event_id_unique":true,"source_pre_event_id":"00065a1d-7f93-9610-0000-001203000020","translation":"UNFOLD_TO_INF","unfold_event_id":null,"zero_hair":false}
{"channel":"live_orders_ethusd","interaction_index":28,"natural_form":{"channel":"live_orders_ethusd","order_id":"2044303878295553","order_subtype":5,"order_type":0},"natural_form_sha256":"c73d6dc8867fa3d3f3ea8779f6845e9fcc692f165d59ab5816847d80270cd94e","order_source":"orderbook","orders_submitted":0,"presentation":{"amount":"20.204386","amount_traded":"0","microtimestamp":"1787932601194000","price":"2474.71"},"previous_record_hash":"22bf9650ba757c5cf10285dcd7dc2d37927025c8616da851977c7fcfd589fced","profit_assessment":null,"record_hash":"de08b7862cb3adf3a0f3523426c645fe7aedba1e6943117bbcbf9de96319ed57","recorded_unix_us":1787932601319895,"recorded_utc":"2026-08-28T15:56:41.319895Z","schema_version":"nrrf810.exchange_authored_interactive_closure.v1","source_chain_continuous":true,"source_event":"order_created","source_event_id":"00065a1d-7f93-9610-0002-001201000020","source_event_id_unique":true,"source_pre_event_id":"00065a1d-7f93-9610-0001-001200000020","translation":"UNFOLD_TO_INF","unfold_event_id":null,"zero_hair":false}
{"channel":"live_orders_ethusd","interaction_index":29,"natural_form":{"channel":"live_orders_ethusd","order_id":"2044303878295557","order_subtype":5,"order_type":0},"natural_form_sha256":"46b6d772704f836767f3b509a793fd0415533135cd5e8684ccb2ce206f6f1648","order_source":"orderbook","orders_submitted":0,"presentation":{"amount":"40.528033","amount_traded":"0","microtimestamp":"1787932601194000","price":"2467.42"},"previous_record_hash":"de08b7862cb3adf3a0f3523426c645fe7aedba1e6943117bbcbf9de96319ed57","profit_assessment":null,"record_hash":"85aeb9fce8315e7c1ba330fc4aec952948429d2782c8cf634f6214b9d3f8d5fc","recorded_unix_us":1787932601319929,"recorded_utc":"2026-08-28T15:56:41.319929Z","schema_version":"nrrf810.exchange_authored_interactive_closure.v1","source_chain_continuous":true,"source_event":"order_created","source_event_id":"00065a1d-7f93-9610-0003-001202000020","source_event_id_unique":true,"source_pre_event_id":"00065a1d-7f93-9610-0002-001201000020","translation":"UNFOLD_TO_INF","unfold_event_id":null,"zero_hair":false}
{"channel":"live_orders_btcusd","interaction_index":30,"natural_form":{"channel":"live_orders_btcusd","order_id":"2044303877603330","order_subtype":5,"order_type":0},"natural_form_sha256":"30906fc3adcb643bf0fcd545d958e8fa5d806b6aec7b940ed9bf88e195b8f9ae","order_source":"orderbook","orders_submitted":0,"presentation":{"amount":"0.00140266","amount_traded":"0","microtimestamp":"1787932601199000","price":"70670.37"},"previous_record_hash":"85aeb9fce8315e7c1ba330fc4aec952948429d2782c8cf634f6214b9d3f8d5fc","profit_assessment":null,"record_hash":"a6adf33f4ee50b3186c5a2a2c0271b4a2d779f1e16c0f2925e0f99cee881e927","recorded_unix_us":1787932601319954,"recorded_utc":"2026-08-28T15:56:41.319954Z","schema_version":"nrrf810.exchange_authored_interactive_closure.v1","source_chain_continuous":true,"source_event":"order_deleted","source_event_id":"00065a1d-7f93-a998-0000-000102000020","source_event_id_unique":true,"source_pre_event_id":"00065a1d-7f93-9228-0000-000101000020","translation":"PARTIAL_PRIOR_UNFOLD","unfold_event_id":null,"zero_hair":false}
{"channel":"live_orders_btcusd","interaction_index":31,"natural_form":{"channel":"live_orders_btcusd","order_id":"2044303837663234","order_subtype":0,"order_type":1},"natural_form_sha256":"4b084499908bc215b61c1f3a9daca107d850a42b10d7e9a4621b11d9b826dad6","order_source":"orderbook","orders_submitted":0,"presentation":{"amount":"0.00025000","amount_traded":"0","microtimestamp":"1787932601202000","price":"78588.00"},"previous_record_hash":"a6adf33f4ee50b3186c5a2a2c0271b4a2d779f1e16c0f2925e0f99cee881e927","profit_assessment":null,"record_hash":"fd3eff1cfc76ca73c4118610c50730b665e9684220604c2e8dda926c755705ee","recorded_unix_us":1787932601319978,"recorded_utc":"2026-08-28T15:56:41.319978Z","schema_version":"nrrf810.exchange_authored_interactive_closure.v1","source_chain_continuous":true,"source_event":"order_deleted","source_event_id":"00065a1d-7f93-b550-0000-000103000020","source_event_id_unique":true,"source_pre_event_id":"00065a1d-7f93-a998-0000-000102000020","translation":"PARTIAL_PRIOR_UNFOLD","unfold_event_id":null,"zero_hair":false}
{"channel":"live_orders_btcusd","interaction_index":32,"natural_form":{"channel":"live_orders_btcusd","order_id":"2044303878336525","order_subtype":5,"order_type":1},"natural_form_sha256":"0f424e1be0d993e6291960109319a7727ebf6c16803ff103cccd46fbe878a329","order_source":"orderbook","orders_submitted":0,"presentation":{"amount":"0.10000000","amount_traded":"0","microtimestamp":"1787932601205000","price":"78522.63"},"previous_record_hash":"fd3eff1cfc76ca73c4118610c50730b665e9684220604c2e8dda926c755705ee","profit_assessment":null,"record_hash":"07909b441a79d6f63d0d2c7c8afcc4b167eb2471feef7105e3fb78b663674625","recorded_unix_us":1787932601320059,"recorded_utc":"2026-08-28T15:56:41.320059Z","schema_version":"nrrf810.exchange_authored_interactive_closure.v1","source_chain_continuous":true,"source_event":"order_created","source_event_id":"00065a1d-7f93-c108-0000-000100000020","source_event_id_unique":true,"source_pre_event_id":"00065a1d-7f93-b550-0000-000103000020","translation":"UNFOLD_TO_INF","unfold_event_id":null,"zero_hair":false}
{"channel":"live_orders_btcusd","interaction_index":33,"natural_form":{"channel":"live_orders_btcusd","order_id":"2044303878336525","order_subtype":5,"order_type":1},"natural_form_sha256":"0f424e1be0d993e6291960109319a7727ebf6c16803ff103cccd46fbe878a329","order_source":"orderbook","orders_submitted":0,"presentation":{"amount":"0.10000000","amount_traded":"0","microtimestamp":"1787932601205000","price":"78522.63"},"previous_record_hash":"07909b441a79d6f63d0d2c7c8afcc4b167eb2471feef7105e3fb78b663674625","profit_assessment":null,"record_hash":"047e311ba023678d45cbde11f7f3e5760ddf007876b9e8fb1ec8862a1ce095ea","recorded_unix_us":1787932601320150,"recorded_utc":"2026-08-28T15:56:41.320150Z","schema_version":"nrrf810.exchange_authored_interactive_closure.v1","source_chain_continuous":true,"source_event":"order_deleted","source_event_id":"00065a1d-7f93-c108-0001-000101000020","source_event_id_unique":true,"source_pre_event_id":"00065a1d-7f93-c108-0000-000100000020","translation":"FOLD_RETURN_TO_ZERO","unfold_event_id":"00065a1d-7f93-c108-0000-000100000020","zero_hair":true}
{"channel":"live_orders_ethusd","interaction_index":34,"natural_form":{"channel":"live_orders_ethusd","order_id":"2044303878365186","order_subtype":5,"order_type":0},"natural_form_sha256":"d0494a0e3a2cffb427791294f7ab9243f47d2eac735bb400f8e1885aef04b206","order_source":"orderbook","orders_submitted":0,"presentation":{"amount":"12.096906","amount_traded":"0","microtimestamp":"1787932601211000","price":"2479.97"},"previous_record_hash":"047e311ba023678d45cbde11f7f3e5760ddf007876b9e8fb1ec8862a1ce095ea","profit_assessment":null,"record_hash":"9641c96fa09541f1974fe44b9130db3fab9762745a92c51ad2c894bb20f8192c","recorded_unix_us":1787932601320360,"recorded_utc":"2026-08-28T15:56:41.320360Z","schema_version":"nrrf810.exchange_authored_interactive_closure.v1","source_chain_continuous":true,"source_event":"order_created","source_event_id":"00065a1d-7f93-d878-0000-001203000020","source_event_id_unique":true,"source_pre_event_id":"00065a1d-7f93-9610-0003-001202000020","translation":"UNFOLD_TO_INF","unfold_event_id":null,"zero_hair":false}
{"channel":"live_orders_ethusd","interaction_index":35,"natural_form":{"channel":"live_orders_ethusd","order_id":"2044303878365189","order_subtype":5,"order_type":0},"natural_form_sha256":"22ab3c3af390adaff0bde43c6886c3dedb978ae06713969be8a01b78871b1780","order_source":"orderbook","orders_submitted":0,"presentation":{"amount":"12.098474","amount_traded":"0","microtimestamp":"1787932601211000","price":"2479.65"},"previous_record_hash":"9641c96fa09541f1974fe44b9130db3fab9762745a92c51ad2c894bb20f8192c","profit_assessment":null,"record_hash":"464ca2f2a98f1d9e921cef9f61e39ce5c51254cdb98486ab94a4fb6409d0762f","recorded_unix_us":1787932601320760,"recorded_utc":"2026-08-28T15:56:41.320760Z","schema_version":"nrrf810.exchange_authored_interactive_closure.v1","source_chain_continuous":true,"source_event":"order_created","source_event_id":"00065a1d-7f93-d878-0001-001200000020","source_event_id_unique":true,"source_pre_event_id":"00065a1d-7f93-d878-0000-001203000020","translation":"UNFOLD_TO_INF","unfold_event_id":null,"zero_hair":false}
{"channel":"live_orders_btcusd","interaction_index":36,"natural_form":{"channel":"live_orders_btcusd","order_id":"2044303878418442","order_subtype":5,"order_type":0},"natural_form_sha256":"7e53b6d324b50e21c1df8a55c0bde12df8e6525f078cd6f34b568ea3fb0e8a0a","order_source":"orderbook","orders_submitted":0,"presentation":{"amount":"0.12000000","amount_traded":"0","microtimestamp":"1787932601225000","price":"78507.07"},"previous_record_hash":"464ca2f2a98f1d9e921cef9f61e39ce5c51254cdb98486ab94a4fb6409d0762f","profit_assessment":null,"record_hash":"1579a264b0bb91436b34ffa2b48c3ab32ea4f7f72c30ca1ff320ab339f3046c2","recorded_unix_us":1787932601320856,"recorded_utc":"2026-08-28T15:56:41.320856Z","schema_version":"nrrf810.exchange_authored_interactive_closure.v1","source_chain_continuous":true,"source_event":"order_created","source_event_id":"00065a1d-7f94-0f28-0000-000102000020","source_event_id_unique":true,"source_pre_event_id":"00065a1d-7f93-c108-0001-000101000020","translation":"UNFOLD_TO_INF","unfold_event_id":null,"zero_hair":false}
{"channel":"live_orders_btcusd","interaction_index":37,"natural_form":{"channel":"live_orders_btcusd","order_id":"2044303878463488","order_subtype":5,"order_type":1},"natural_form_sha256":"a7b92b718b4b9181982d5c6052a4fc6e14cbc60065b244c5bdd9689ecefd7f68","order_source":"orderbook","orders_submitted":0,"presentation":{"amount":"0.10000000","amount_traded":"0","microtimestamp":"1787932601235000","price":"78523.14"},"previous_record_hash":"1579a264b0bb91436b34ffa2b48c3ab32ea4f7f72c30ca1ff320ab339f3046c2","profit_assessment":null,"record_hash":"0ad22d5a383c8074c7fd6935d149c1e8799c3327eda5214db5092e85f004bb1c","recorded_unix_us":1787932601320968,"recorded_utc":"2026-08-28T15:56:41.320968Z","schema_version":"nrrf810.exchange_authored_interactive_closure.v1","source_chain_continuous":true,"source_event":"order_created","source_event_id":"00065a1d-7f94-3638-0000-000103000020","source_event_id_unique":true,"source_pre_event_id":"00065a1d-7f94-0f28-0000-000102000020","translation":"UNFOLD_TO_INF","unfold_event_id":null,"zero_hair":false}
{"channel":"live_orders_btcusd","interaction_index":38,"natural_form":{"channel":"live_orders_btcusd","order_id":"2044303878463489","order_subtype":5,"order_type":1},"natural_form_sha256":"42759e5f68523835148e3788ca785fb78de0f24acac36050feacfa0ae080214e","order_source":"orderbook","orders_submitted":0,"presentation":{"amount":"0.10000000","amount_traded":"0","microtimestamp":"1787932601235000","price":"78522.62"},"previous_record_hash":"0ad22d5a383c8074c7fd6935d149c1e8799c3327eda5214db5092e85f004bb1c","profit_assessment":null,"record_hash":"9810e56bcfbfcc935a1436c14b1e6bb98cc645049b861d0468b34f35daff17d0","recorded_unix_us":1787932601321134,"recorded_utc":"2026-08-28T15:56:41.321134Z","schema_version":"nrrf810.exchange_authored_interactive_closure.v1","source_chain_continuous":true,"source_event":"order_created","source_event_id":"00065a1d-7f94-3638-0001-000100000020","source_event_id_unique":true,"source_pre_event_id":"00065a1d-7f94-3638-0000-000103000020","translation":"UNFOLD_TO_INF","unfold_event_id":null,"zero_hair":false}
{"channel":"live_orders_btcusd","interaction_index":39,"natural_form":{"channel":"live_orders_btcusd","order_id":"2044303878463489","order_subtype":5,"order_type":1},"natural_form_sha256":"42759e5f68523835148e3788ca785fb78de0f24acac36050feacfa0ae080214e","order_source":"orderbook","orders_submitted":0,"presentation":{"amount":"0.10000000","amount_traded":"0","microtimestamp":"1787932601235000","price":"78522.62"},"previous_record_hash":"9810e56bcfbfcc935a1436c14b1e6bb98cc645049b861d0468b34f35daff17d0","profit_assessment":null,"record_hash":"0cb5cce4b25b086cd429fbc68c5fc4910c73bf121df211d2da7c73f0063c5018","recorded_unix_us":1787932601321330,"recorded_utc":"2026-08-28T15:56:41.321330Z","schema_version":"nrrf810.exchange_authored_interactive_closure.v1","source_chain_continuous":true,"source_event":"order_deleted","source_event_id":"00065a1d-7f94-3638-0002-000101000020","source_event_id_unique":true,"source_pre_event_id":"00065a1d-7f94-3638-0001-000100000020","translation":"FOLD_RETURN_TO_ZERO","unfold_event_id":"00065a1d-7f94-3638-0001-000100000020","zero_hair":true}
{"channel":"live_orders_btcusd","interaction_index":40,"natural_form":{"channel":"live_orders_btcusd","order_id":"2044303878471682","order_subtype":5,"order_type":1},"natural_form_sha256":"971008170e6028b420437249cc39c51a1bd10f417fddb4797fed36d5ef944161","order_source":"orderbook","orders_submitted":0,"presentation":{"amount":"0.10000000","amount_traded":"0","microtimestamp":"1787932601237000","price":"78522.63"},"previous_record_hash":"0cb5cce4b25b086cd429fbc68c5fc4910c73bf121df211d2da7c73f0063c5018","profit_assessment":null,"record_hash":"e841a1b4cde62b32051643e7d16f54218bba9a80a5b5046d717517936689e1a4","recorded_unix_us":1787932601321491,"recorded_utc":"2026-08-28T15:56:41.321491Z","schema_version":"nrrf810.exchange_authored_interactive_closure.v1","source_chain_continuous":true,"source_event":"order_created","source_event_id":"00065a1d-7f94-3e08-0000-000102000020","source_event_id_unique":true,"source_pre_event_id":"00065a1d-7f94-3638-0002-000101000020","translation":"UNFOLD_TO_INF","unfold_event_id":null,"zero_hair":false}
{"channel":"live_orders_btcusd","interaction_index":41,"natural_form":{"channel":"live_orders_btcusd","order_id":"2044303878471682","order_subtype":5,"order_type":1},"natural_form_sha256":"971008170e6028b420437249cc39c51a1bd10f417fddb4797fed36d5ef944161","order_source":"orderbook","orders_submitted":0,"presentation":{"amount":"0.10000000","amount_traded":"0","microtimestamp":"1787932601237000","price":"78522.63"},"previous_record_hash":"e841a1b4cde62b32051643e7d16f54218bba9a80a5b5046d717517936689e1a4","profit_assessment":null,"record_hash":"014ae4b670d8df84d78b7ec344324462312e62a8e2c9cbbe2e3ad2b3f2619cf6","recorded_unix_us":1787932601321539,"recorded_utc":"2026-08-28T15:56:41.321539Z","schema_version":"nrrf810.exchange_authored_interactive_closure.v1","source_chain_continuous":true,"source_event":"order_deleted","source_event_id":"00065a1d-7f94-3e08-0001-000103000020","source_event_id_unique":true,"source_pre_event_id":"00065a1d-7f94-3e08-0000-000102000020","translation":"FOLD_RETURN_TO_ZERO","unfold_event_id":"00065a1d-7f94-3e08-0000-000102000020","zero_hair":true}
{"channel":"live_orders_btcusd","interaction_index":42,"natural_form":{"channel":"live_orders_btcusd","order_id":"2044303878488064","order_subtype":4,"order_type":1},"natural_form_sha256":"8b524b6fca6e36863fd62d4461d3bf94390abf87f883b37c48e2f149749937c1","order_source":"orderbook","orders_submitted":0,"presentation":{"amount":"0.00006244","amount_traded":"0","microtimestamp":"1787932601241000","price":"80878.00"},"previous_record_hash":"014ae4b670d8df84d78b7ec344324462312e62a8e2c9cbbe2e3ad2b3f2619cf6","profit_assessment":null,"record_hash":"de928cc4f97c226329eab658209a976a1a6522e5ee2bf9ecf7526dafad5e56e4","recorded_unix_us":1787932601321696,"recorded_utc":"2026-08-28T15:56:41.321696Z","schema_version":"nrrf810.exchange_authored_interactive_closure.v1","source_chain_continuous":true,"source_event":"order_created","source_event_id":"00065a1d-7f94-4da8-0000-000100000020","source_event_id_unique":true,"source_pre_event_id":"00065a1d-7f94-3e08-0001-000103000020","translation":"UNFOLD_TO_INF","unfold_event_id":null,"zero_hair":false}
{"channel":"live_orders_btcusd","interaction_index":43,"natural_form":{"channel":"live_orders_btcusd","order_id":"2044303878488064","order_subtype":4,"order_type":1},"natural_form_sha256":"8b524b6fca6e36863fd62d4461d3bf94390abf87f883b37c48e2f149749937c1","order_source":"orderbook","orders_submitted":0,"presentation":{"amount":"0.00006244","amount_traded":"0","microtimestamp":"1787932601241000","price":"80878.00"},"previous_record_hash":"de928cc4f97c226329eab658209a976a1a6522e5ee2bf9ecf7526dafad5e56e4","profit_assessment":null,"record_hash":"f5638cff7a048df38fedb38e7a9c3fc8478ac9226bcb53765e09485350be6a20","recorded_unix_us":1787932601321732,"recorded_utc":"2026-08-28T15:56:41.321732Z","schema_version":"nrrf810.exchange_authored_interactive_closure.v1","source_chain_continuous":true,"source_event":"order_deleted","source_event_id":"00065a1d-7f94-4da8-0001-000101000020","source_event_id_unique":true,"source_pre_event_id":"00065a1d-7f94-4da8-0000-000100000020","translation":"FOLD_RETURN_TO_ZERO","unfold_event_id":"00065a1d-7f94-4da8-0000-000100000020","zero_hair":true}
{"channel":"live_orders_btcusd","interaction_index":44,"natural_form":{"channel":"live_orders_btcusd","order_id":"2044303876886533","order_subtype":5,"order_type":1},"natural_form_sha256":"a7e6403851c935cd67181a10573281532092591d099b7f458bb5ae7bfcb985e6","order_source":"orderbook","orders_submitted":0,"presentation":{"amount":"0.10000000","amount_traded":"0","microtimestamp":"1787932601252000","price":"78523.46"},"previous_record_hash":"f5638cff7a048df38fedb38e7a9c3fc8478ac9226bcb53765e09485350be6a20","profit_assessment":null,"record_hash":"cfbb5a18cb66d11aec2bd23a44ee09e5fc62967d6ee3858cd561aa72d741121a","recorded_unix_us":1787932601321834,"recorded_utc":"2026-08-28T15:56:41.321834Z","schema_version":"nrrf810.exchange_authored_interactive_closure.v1","source_chain_continuous":true,"source_event":"order_deleted","source_event_id":"00065a1d-7f94-78a0-0000-000102000020","source_event_id_unique":true,"source_pre_event_id":"00065a1d-7f94-4da8-0001-000101000020","translation":"PARTIAL_PRIOR_UNFOLD","unfold_event_id":null,"zero_hair":false}
{"channel":"live_orders_ethusd","interaction_index":45,"natural_form":{"channel":"live_orders_ethusd","order_id":"2044303878000647","order_subtype":5,"order_type":0},"natural_form_sha256":"b5cb53193c09db26192dd55d29adb2792ebf7dbfc56158d66d20f049f1283eb1","order_source":"orderbook","orders_submitted":0,"presentation":{"amount":"0.468499","amount_traded":"0","microtimestamp":"1787932601266000","price":"2479.80"},"previous_record_hash":"cfbb5a18cb66d11aec2bd23a44ee09e5fc62967d6ee3858cd561aa72d741121a","profit_assessment":null,"record_hash":"cab3aa43925c6a0e6828decc002d2b3355dd855424abb4d7d8f54c2d22971932","recorded_unix_us":1787932601321944,"recorded_utc":"2026-08-28T15:56:41.321944Z","schema_version":"nrrf810.exchange_authored_interactive_closure.v1","source_chain_continuous":true,"source_event":"order_deleted","source_event_id":"00065a1d-7f94-af50-0000-001201000020","source_event_id_unique":true,"source_pre_event_id":"00065a1d-7f93-d878-0001-001200000020","translation":"PARTIAL_PRIOR_UNFOLD","unfold_event_id":null,"zero_hair":false}
{"channel":"live_orders_ethusd","interaction_index":46,"natural_form":{"channel":"live_orders_ethusd","order_id":"2044303877074948","order_subtype":5,"order_type":0},"natural_form_sha256":"e92884ab910a7c35bde548bb17a87d9bdceb040ff2e2b79054b717d5002c5d65","order_source":"orderbook","orders_submitted":0,"presentation":{"amount":"0.403104","amount_traded":"0","microtimestamp":"1787932601266000","price":"2479.50"},"previous_record_hash":"cab3aa43925c6a0e6828decc002d2b3355dd855424abb4d7d8f54c2d22971932","profit_assessment":null,"record_hash":"57234071efb2614096a86b85c8338001a7f02d9f31a7c253c48900d6dba05ed8","recorded_unix_us":1787932601322077,"recorded_utc":"2026-08-28T15:56:41.322077Z","schema_version":"nrrf810.exchange_authored_interactive_closure.v1","source_chain_continuous":true,"source_event":"order_deleted","source_event_id":"00065a1d-7f94-af50-0001-001202000020","source_event_id_unique":true,"source_pre_event_id":"00065a1d-7f94-af50-0000-001201000020","translation":"PARTIAL_PRIOR_UNFOLD","unfold_event_id":null,"zero_hair":false}
{"channel":"live_orders_btcusd","interaction_index":47,"natural_form":{"channel":"live_orders_btcusd","order_id":"2044303878176779","order_subtype":5,"order_type":0},"natural_form_sha256":"eca86c4d8ac91c40bc9b8fb4555822808b62d89a87af2fc337e347721fa3682b","order_source":"orderbook","orders_submitted":0,"presentation":{"amount":"0.19104140","amount_traded":"0","microtimestamp":"1787932601266000","price":"78481.58"},"previous_record_hash":"57234071efb2614096a86b85c8338001a7f02d9f31a7c253c48900d6dba05ed8","profit_assessment":null,"record_hash":"a722ca9659f0ab84fb8e0b557762a885056bd5e93fcc740feb3036f748546472","recorded_unix_us":1787932601322112,"recorded_utc":"2026-08-28T15:56:41.322112Z","schema_version":"nrrf810.exchange_authored_interactive_closure.v1","source_chain_continuous":true,"source_event":"order_deleted","source_event_id":"00065a1d-7f94-af50-0000-000103000020","source_event_id_unique":true,"source_pre_event_id":"00065a1d-7f94-78a0-0000-000102000020","translation":"FOLD_RETURN_TO_ZERO","unfold_event_id":"00065a1d-7f93-28b0-0000-000100000020","zero_hair":true}
{"channel":"live_orders_btcusd","interaction_index":48,"natural_form":{"channel":"live_orders_btcusd","order_id":"2044303878602752","order_subtype":5,"order_type":1},"natural_form_sha256":"0739090ff6d0b95384718fb551bc764355ac16a584bf50234775a5ba73e4cded","order_source":"orderbook","orders_submitted":0,"presentation":{"amount":"0.10000000","amount_traded":"0","microtimestamp":"1787932601269000","price":"78522.62"},"previous_record_hash":"a722ca9659f0ab84fb8e0b557762a885056bd5e93fcc740feb3036f748546472","profit_assessment":null,"record_hash":"1385b168fa8b19f20876f53b9f4e4da0784cf05a474b52dc82bf70048e84c0ce","recorded_unix_us":1787932601322212,"recorded_utc":"2026-08-28T15:56:41.322212Z","schema_version":"nrrf810.exchange_authored_interactive_closure.v1","source_chain_continuous":true,"source_event":"order_created","source_event_id":"00065a1d-7f94-bb08-0000-000100000020","source_event_id_unique":true,"source_pre_event_id":"00065a1d-7f94-af50-0000-000103000020","translation":"UNFOLD_TO_INF","unfold_event_id":null,"zero_hair":false}
{"channel":"live_orders_btcusd","interaction_index":49,"natural_form":{"channel":"live_orders_btcusd","order_id":"2044303878602752","order_subtype":5,"order_type":1},"natural_form_sha256":"0739090ff6d0b95384718fb551bc764355ac16a584bf50234775a5ba73e4cded","order_source":"orderbook","orders_submitted":0,"presentation":{"amount":"0.10000000","amount_traded":"0","microtimestamp":"1787932601269000","price":"78522.62"},"previous_record_hash":"1385b168fa8b19f20876f53b9f4e4da0784cf05a474b52dc82bf70048e84c0ce","profit_assessment":null,"record_hash":"ee862fcb3a70582858f05bd8e0f650d6a50d2cf8d5a07bdb22b4bd08baaaef9c","recorded_unix_us":1787932601322312,"recorded_utc":"2026-08-28T15:56:41.322312Z","schema_version":"nrrf810.exchange_authored_interactive_closure.v1","source_chain_continuous":true,"source_event":"order_deleted","source_event_id":"00065a1d-7f94-bb08-0001-000101000020","source_event_id_unique":true,"source_pre_event_id":"00065a1d-7f94-bb08-0000-000100000020","translation":"FOLD_RETURN_TO_ZERO","unfold_event_id":"00065a1d-7f94-bb08-0000-000100000020","zero_hair":true}
{"channel":"live_orders_btcusd","interaction_index":50,"natural_form":{"channel":"live_orders_btcusd","order_id":"2044303878602766","order_subtype":5,"order_type":0},"natural_form_sha256":"38686e9776951fa1f86e67b4657597fb595e4b5a05c511aa70a1772b800697b7","order_source":"orderbook","orders_submitted":0,"presentation":{"amount":"0.00140266","amount_traded":"0","microtimestamp":"1787932601270000","price":"70670.37"},"previous_record_hash":"ee862fcb3a70582858f05bd8e0f650d6a50d2cf8d5a07bdb22b4bd08baaaef9c","profit_assessment":null,"record_hash":"e442e4196745aadc041cc663351971a8fc2c68567f1ffd4806510ae0258784b0","recorded_unix_us":1787932601322437,"recorded_utc":"2026-08-28T15:56:41.322437Z","schema_version":"nrrf810.exchange_authored_interactive_closure.v1","source_chain_continuous":true,"source_event":"order_created","source_event_id":"00065a1d-7f94-bef0-0000-000102000020","source_event_id_unique":true,"source_pre_event_id":"00065a1d-7f94-bb08-0001-000101000020","translation":"UNFOLD_TO_INF","unfold_event_id":null,"zero_hair":false}
{"channel":"live_orders_btcusd","interaction_index":51,"natural_form":{"channel":"live_orders_btcusd","order_id":"2044303878606856","order_subtype":5,"order_type":1},"natural_form_sha256":"a798f6aa25dc6f76091521930974ac752e2e8fbdb7f736bc602e694d32a8bd18","order_source":"orderbook","orders_submitted":0,"presentation":{"amount":"0.10000000","amount_traded":"0","microtimestamp":"1787932601271000","price":"78522.63"},"previous_record_hash":"e442e4196745aadc041cc663351971a8fc2c68567f1ffd4806510ae0258784b0","profit_assessment":null,"record_hash":"e739812000e6012662440e46e3990d5fa82320712d617c8efdb1adc4b88ac6bb","recorded_unix_us":1787932601322461,"recorded_utc":"2026-08-28T15:56:41.322461Z","schema_version":"nrrf810.exchange_authored_interactive_closure.v1","source_chain_continuous":true,"source_event":"order_created","source_event_id":"00065a1d-7f94-c2d8-0000-000103000020","source_event_id_unique":true,"source_pre_event_id":"00065a1d-7f94-bef0-0000-000102000020","translation":"UNFOLD_TO_INF","unfold_event_id":null,"zero_hair":false}
{"channel":"live_orders_btcusd","interaction_index":52,"natural_form":{"channel":"live_orders_btcusd","order_id":"2044303878606856","order_subtype":5,"order_type":1},"natural_form_sha256":"a798f6aa25dc6f76091521930974ac752e2e8fbdb7f736bc602e694d32a8bd18","order_source":"orderbook","orders_submitted":0,"presentation":{"amount":"0.10000000","amount_traded":"0","microtimestamp":"1787932601271000","price":"78522.63"},"previous_record_hash":"e739812000e6012662440e46e3990d5fa82320712d617c8efdb1adc4b88ac6bb","profit_assessment":null,"record_hash":"d7ec1b2cbadfd9974b610e99c2e98e015b6f591477366206c811ba025b208fe1","recorded_unix_us":1787932601322539,"recorded_utc":"2026-08-28T15:56:41.322539Z","schema_version":"nrrf810.exchange_authored_interactive_closure.v1","source_chain_continuous":true,"source_event":"order_deleted","source_event_id":"00065a1d-7f94-c2d8-0001-000100000020","source_event_id_unique":true,"source_pre_event_id":"00065a1d-7f94-c2d8-0000-000103000020","translation":"FOLD_RETURN_TO_ZERO","unfold_event_id":"00065a1d-7f94-c2d8-0000-000103000020","zero_hair":true}
{"channel":"live_orders_btcusd","interaction_index":53,"natural_form":{"channel":"live_orders_btcusd","order_id":"2044303878619144","order_subtype":5,"order_type":1},"natural_form_sha256":"d718b44ec7b9088860a4cc5e2923281df126925715093c10cf91104232f2fca0","order_source":"orderbook","orders_submitted":0,"presentation":{"amount":"0.10000000","amount_traded":"0","microtimestamp":"1787932601274000","price":"78523.05"},"previous_record_hash":"d7ec1b2cbadfd9974b610e99c2e98e015b6f591477366206c811ba025b208fe1","profit_assessment":null,"record_hash":"38c83a10a1b9059d34a1090dd79182df3bdd60467751d3aa99885fafeae8df3b","recorded_unix_us":1787932601322654,"recorded_utc":"2026-08-28T15:56:41.322654Z","schema_version":"nrrf810.exchange_authored_interactive_closure.v1","source_chain_continuous":true,"source_event":"order_created","source_event_id":"00065a1d-7f94-ce90-0000-000101000020","source_event_id_unique":true,"source_pre_event_id":"00065a1d-7f94-c2d8-0001-000100000020","translation":"UNFOLD_TO_INF","unfold_event_id":null,"zero_hair":false}
{"channel":"live_orders_btcusd","interaction_index":54,"natural_form":{"channel":"live_orders_btcusd","order_id":"2044303878631428","order_subtype":5,"order_type":0},"natural_form_sha256":"adc4786058f6cabbb6f19277b52f8c3f5981af7676a2b1056c4b9266fd3aa608","order_source":"orderbook","orders_submitted":0,"presentation":{"amount":"0.19103753","amount_traded":"0","microtimestamp":"1787932601276000","price":"78483.49"},"previous_record_hash":"38c83a10a1b9059d34a1090dd79182df3bdd60467751d3aa99885fafeae8df3b","profit_assessment":null,"record_hash":"fe7b95934307e88a2a8e471ed6b6348875c930836bdaf00c08dce196ca1ba4e9","recorded_unix_us":1787932601334778,"recorded_utc":"2026-08-28T15:56:41.334778Z","schema_version":"nrrf810.exchange_authored_interactive_closure.v1","source_chain_continuous":true,"source_event":"order_created","source_event_id":"00065a1d-7f94-d660-0000-000102000020","source_event_id_unique":true,"source_pre_event_id":"00065a1d-7f94-ce90-0000-000101000020","translation":"UNFOLD_TO_INF","unfold_event_id":null,"zero_hair":false}
{"channel":"live_orders_ethusd","interaction_index":55,"natural_form":{"channel":"live_orders_ethusd","order_id":"2044303878631432","order_subtype":5,"order_type":0},"natural_form_sha256":"bdf635465c32766347c03f4034afe58a30d12a1e25f52cba507c73a468a0371f","order_source":"orderbook","orders_submitted":0,"presentation":{"amount":"0.262273","amount_traded":"0","microtimestamp":"1787932601277000","price":"2480.01"},"previous_record_hash":"fe7b95934307e88a2a8e471ed6b6348875c930836bdaf00c08dce196ca1ba4e9","profit_assessment":null,"record_hash":"2bc33dbe19cada5f288184e09a5a8423a6440936eb1dbafb4910f4c718807346","recorded_unix_us":1787932601334850,"recorded_utc":"2026-08-28T15:56:41.334850Z","schema_version":"nrrf810.exchange_authored_interactive_closure.v1","source_chain_continuous":true,"source_event":"order_created","source_event_id":"00065a1d-7f94-da48-0000-001203000020","source_event_id_unique":true,"source_pre_event_id":"00065a1d-7f94-af50-0001-001202000020","translation":"UNFOLD_TO_INF","unfold_event_id":null,"zero_hair":false}
{"channel":"live_orders_ethbtc","interaction_index":56,"natural_form":{"channel":"live_orders_ethbtc","order_id":"2044303878643712","order_subtype":5,"order_type":0},"natural_form_sha256":"515ebcfcf54f4ceed892079a7bca9a35b84a85f4eb9841379ece809e863a9d99","order_source":"orderbook","orders_submitted":0,"presentation":{"amount":"1.65847856","amount_traded":"0","microtimestamp":"1787932601279000","price":"0.03020012"},"previous_record_hash":"2bc33dbe19cada5f288184e09a5a8423a6440936eb1dbafb4910f4c718807346","profit_assessment":null,"record_hash":"082ffa21d99dc701ffd5bc19cf4d2f860fc421d7d46b5400d69e11149b6be24e","recorded_unix_us":1787932601334982,"recorded_utc":"2026-08-28T15:56:41.334982Z","schema_version":"nrrf810.exchange_authored_interactive_closure.v1","source_chain_continuous":true,"source_event":"order_created","source_event_id":"00065a1d-7f94-e218-0000-001103000020","source_event_id_unique":true,"source_pre_event_id":"00065a1d-7f92-f9d0-0000-001102000020","translation":"UNFOLD_TO_INF","unfold_event_id":null,"zero_hair":false}
{"channel":"live_orders_btcusd","interaction_index":57,"natural_form":{"channel":"live_orders_btcusd","order_id":"2044303877955592","order_subtype":5,"order_type":0},"natural_form_sha256":"2b97723837d0ce542afd1bc949e4b475b266bd5a322b1da4ce60b5f25126841b","order_source":"orderbook","orders_submitted":0,"presentation":{"amount":"0.00140266","amount_traded":"0","microtimestamp":"1787932601283000","price":"70670.37"},"previous_record_hash":"082ffa21d99dc701ffd5bc19cf4d2f860fc421d7d46b5400d69e11149b6be24e","profit_assessment":null,"record_hash":"82c43b1239b4bbe7b18d8f37632e0bbcb6aeb264ea9e5dac80b68b6ab8bade75","recorded_unix_us":1787932601335105,"recorded_utc":"2026-08-28T15:56:41.335105Z","schema_version":"nrrf810.exchange_authored_interactive_closure.v1","source_chain_continuous":true,"source_event":"order_deleted","source_event_id":"00065a1d-7f94-f1b8-0000-000103000020","source_event_id_unique":true,"source_pre_event_id":"00065a1d-7f94-d660-0000-000102000020","translation":"PARTIAL_PRIOR_UNFOLD","unfold_event_id":null,"zero_hair":false}
{"channel":"live_orders_ethusd","interaction_index":58,"natural_form":{"channel":"live_orders_ethusd","order_id":"2044303878639616","order_subtype":5,"order_type":0},"natural_form_sha256":"e5f39627d875fecdf000de8ec5db3bcc2b236c965845b56676a562585d2044ed","order_source":"orderbook","orders_submitted":0,"presentation":{"amount":"0.403103","amount_traded":"0","microtimestamp":"1787932601283000","price":"2479.78"},"previous_record_hash":"82c43b1239b4bbe7b18d8f37632e0bbcb6aeb264ea9e5dac80b68b6ab8bade75","profit_assessment":null,"record_hash":"1a10055668f4a12e1b267764586f3d7d9d18933d6a4bf84ddbc53b382e321fca","recorded_unix_us":1787932601335145,"recorded_utc":"2026-08-28T15:56:41.335145Z","schema_version":"nrrf810.exchange_authored_interactive_closure.v1","source_chain_continuous":true,"source_event":"order_created","source_event_id":"00065a1d-7f94-f1b8-0000-001200000020","source_event_id_unique":true,"source_pre_event_id":"00065a1d-7f94-da48-0000-001203000020","translation":"UNFOLD_TO_INF","unfold_event_id":null,"zero_hair":false}
{"channel":"live_orders_ethusd","interaction_index":59,"natural_form":{"channel":"live_orders_ethusd","order_id":"2044303878008837","order_subtype":5,"order_type":0},"natural_form_sha256":"58dd633aafccb0455ed1c8e4587cbeef74d64635c1e7500311e6a72a37a799e8","order_source":"orderbook","orders_submitted":0,"presentation":{"amount":"0.403103","amount_traded":"0","microtimestamp":"1787932601283000","price":"2480.25"},"previous_record_hash":"1a10055668f4a12e1b267764586f3d7d9d18933d6a4bf84ddbc53b382e321fca","profit_assessment":null,"record_hash":"0d618972a0e8054ab14c3120dd8fe46bb46ad2f692dad6ec7edbf8679cbb4dcb","recorded_unix_us":1787932601335223,"recorded_utc":"2026-08-28T15:56:41.335223Z","schema_version":"nrrf810.exchange_authored_interactive_closure.v1","source_chain_continuous":true,"source_event":"order_deleted","source_event_id":"00065a1d-7f94-f1b8-0001-001201000020","source_event_id_unique":true,"source_pre_event_id":"00065a1d-7f94-f1b8-0000-001200000020","translation":"PARTIAL_PRIOR_UNFOLD","unfold_event_id":null,"zero_hair":false}
{"channel":"live_orders_btcusd","interaction_index":60,"natural_form":{"channel":"live_orders_btcusd","order_id":"2044303878660115","order_subtype":0,"order_type":1},"natural_form_sha256":"b2860e3dd26a03acec5e08806e66efbe0f34b4a822e15306ab84a2500ab4fe1f","order_source":"orderbook","orders_submitted":0,"presentation":{"amount":"0.00025000","amount_traded":"0","microtimestamp":"1787932601284000","price":"78587.00"},"previous_record_hash":"0d618972a0e8054ab14c3120dd8fe46bb46ad2f692dad6ec7edbf8679cbb4dcb","profit_assessment":null,"record_hash":"10aa2c9468fea5699cd7b05602604d9029b8c430afe0409648d3c4bccbb1ca09","recorded_unix_us":1787932601335291,"recorded_utc":"2026-08-28T15:56:41.335291Z","schema_version":"nrrf810.exchange_authored_interactive_closure.v1","source_chain_continuous":true,"source_event":"order_created","source_event_id":"00065a1d-7f94-f5a0-0000-000100000020","source_event_id_unique":true,"source_pre_event_id":"00065a1d-7f94-f1b8-0000-000103000020","translation":"UNFOLD_TO_INF","unfold_event_id":null,"zero_hair":false}
{"channel":"live_orders_ethusd","interaction_index":61,"natural_form":{"channel":"live_orders_ethusd","order_id":"2044303878639616","order_subtype":5,"order_type":0},"natural_form_sha256":"e5f39627d875fecdf000de8ec5db3bcc2b236c965845b56676a562585d2044ed","order_source":"orderbook","orders_submitted":0,"presentation":{"amount":"0.403103","amount_traded":"0","microtimestamp":"1787932601287000","price":"2479.78"},"previous_record_hash":"10aa2c9468fea5699cd7b05602604d9029b8c430afe0409648d3c4bccbb1ca09","profit_assessment":null,"record_hash":"f9d387d535ec63b576d5a7dfade89045dafe6223df1beeed1fa56c1fc76a8e02","recorded_unix_us":1787932601335359,"recorded_utc":"2026-08-28T15:56:41.335359Z","schema_version":"nrrf810.exchange_authored_interactive_closure.v1","source_chain_continuous":true,"source_event":"order_deleted","source_event_id":"00065a1d-7f95-0158-0000-001202000020","source_event_id_unique":true,"source_pre_event_id":"00065a1d-7f94-f1b8-0001-001201000020","translation":"FOLD_RETURN_TO_ZERO","unfold_event_id":"00065a1d-7f94-f1b8-0000-001200000020","zero_hair":true}
{"channel":"live_orders_ethusd","interaction_index":62,"natural_form":{"channel":"live_orders_ethusd","order_id":"2044303878676498","order_subtype":5,"order_type":0},"natural_form_sha256":"e98ea90332a3e7a183bcc208b066c6aaa6493847a2e00008d80b8bb3081def77","order_source":"orderbook","orders_submitted":0,"presentation":{"amount":"0.403104","amount_traded":"0","microtimestamp":"1787932601288000","price":"2479.50"},"previous_record_hash":"f9d387d535ec63b576d5a7dfade89045dafe6223df1beeed1fa56c1fc76a8e02","profit_assessment":null,"record_hash":"bb8d1b6dd991dcf93fef824e780fe25e845680367027eb990f5b083b9ef01d38","recorded_unix_us":1787932601335425,"recorded_utc":"2026-08-28T15:56:41.335425Z","schema_version":"nrrf810.exchange_authored_interactive_closure.v1","source_chain_continuous":true,"source_event":"order_created","source_event_id":"00065a1d-7f95-0540-0000-001203000020","source_event_id_unique":true,"source_pre_event_id":"00065a1d-7f95-0158-0000-001202000020","translation":"UNFOLD_TO_INF","unfold_event_id":null,"zero_hair":false}
{"channel":"live_orders_btcusd","interaction_index":63,"natural_form":{"channel":"live_orders_btcusd","order_id":"2044303878680580","order_subtype":5,"order_type":1},"natural_form_sha256":"05299797305c5d594904df4eada772f62ceef22eb97195167278eb985cc013e6","order_source":"orderbook","orders_submitted":0,"presentation":{"amount":"0.00254665","amount_traded":"0","microtimestamp":"1787932601288000","price":"78534.59"},"previous_record_hash":"bb8d1b6dd991dcf93fef824e780fe25e845680367027eb990f5b083b9ef01d38","profit_assessment":null,"record_hash":"df5d2582616ebbe85cce7925f14effff784ac496225ca92dbf3b19ac160c5a9f","recorded_unix_us":1787932601335490,"recorded_utc":"2026-08-28T15:56:41.335490Z","schema_version":"nrrf810.exchange_authored_interactive_closure.v1","source_chain_continuous":true,"source_event":"order_created","source_event_id":"00065a1d-7f95-0540-0000-000101000020","source_event_id_unique":true,"source_pre_event_id":"00065a1d-7f94-f5a0-0000-000100000020","translation":"UNFOLD_TO_INF","unfold_event_id":null,"zero_hair":false}
{"channel":"live_orders_ethusd","interaction_index":64,"natural_form":{"channel":"live_orders_ethusd","order_id":"2044303878684678","order_subtype":5,"order_type":0},"natural_form_sha256":"13c442beb84de690b9a3f4fb7feeae37f9303f7430728d56c550ec61cdbc8140","order_source":"orderbook","orders_submitted":0,"presentation":{"amount":"0.403103","amount_traded":"0","microtimestamp":"1787932601289000","price":"2480.01"},"previous_record_hash":"df5d2582616ebbe85cce7925f14effff784ac496225ca92dbf3b19ac160c5a9f","profit_assessment":null,"record_hash":"f9a78a266746230a186fac4f7272f31f8f15117794c948b96abd09915f73bba3","recorded_unix_us":1787932601335555,"recorded_utc":"2026-08-28T15:56:41.335555Z","schema_version":"nrrf810.exchange_authored_interactive_closure.v1","source_chain_continuous":true,"source_event":"order_created","source_event_id":"00065a1d-7f95-0928-0000-001200000020","source_event_id_unique":true,"source_pre_event_id":"00065a1d-7f95-0540-0000-001203000020","translation":"UNFOLD_TO_INF","unfold_event_id":null,"zero_hair":false}
{"channel":"live_orders_btcusd","interaction_index":65,"natural_form":{"channel":"live_orders_btcusd","order_id":"2044303877971968","order_subtype":5,"order_type":1},"natural_form_sha256":"b14a7c782fa40a4600a298793b033bff13072b51830dc2f1b9af745a503c1b7c","order_source":"orderbook","orders_submitted":0,"presentation":{"amount":"0.10000000","amount_traded":"0","microtimestamp":"1787932601297000","price":"78523.45"},"previous_record_hash":"f9a78a266746230a186fac4f7272f31f8f15117794c948b96abd09915f73bba3","profit_assessment":null,"record_hash":"8c3b99a8b1a04df484f57f3d5741ab1419558b2b48df13fe27196ea322ab91a8","recorded_unix_us":1787932601335622,"recorded_utc":"2026-08-28T15:56:41.335622Z","schema_version":"nrrf810.exchange_authored_interactive_closure.v1","source_chain_continuous":true,"source_event":"order_deleted","source_event_id":"00065a1d-7f95-2868-0000-000102000020","source_event_id_unique":true,"source_pre_event_id":"00065a1d-7f95-0540-0000-000101000020","translation":"PARTIAL_PRIOR_UNFOLD","unfold_event_id":null,"zero_hair":false}
{"channel":"live_orders_btcusd","interaction_index":66,"natural_form":{"channel":"live_orders_btcusd","order_id":"2044303878725651","order_subtype":5,"order_type":0},"natural_form_sha256":"74066d9252197cb501989873a45204a3a3bc052a4ce95021a6389008f2e59313","order_source":"orderbook","orders_submitted":0,"presentation":{"amount":"0.00254770","amount_traded":"0","microtimestamp":"1787932601300000","price":"78502.27"},"previous_record_hash":"8c3b99a8b1a04df484f57f3d5741ab1419558b2b48df13fe27196ea322ab91a8","profit_assessment":null,"record_hash":"f5f2b8a587c7012d861e9579b3020c5551c1b3848495ee75a5e1d477ab4dca04","recorded_unix_us":1787932601344563,"recorded_utc":"2026-08-28T15:56:41.344563Z","schema_version":"nrrf810.exchange_authored_interactive_closure.v1","source_chain_continuous":true,"source_event":"order_created","source_event_id":"00065a1d-7f95-3420-0000-000103000020","source_event_id_unique":true,"source_pre_event_id":"00065a1d-7f95-2868-0000-000102000020","translation":"UNFOLD_TO_INF","unfold_event_id":null,"zero_hair":false}
{"channel":"live_orders_btcusd","interaction_index":67,"natural_form":{"channel":"live_orders_btcusd","order_id":"2044303877378048","order_subtype":5,"order_type":1},"natural_form_sha256":"a8c6d8a0657a6b63ef49472264209ea6ac6c4cf81bb3f069b2be6a01aa801b56","order_source":"orderbook","orders_submitted":0,"presentation":{"amount":"0.06367563","amount_traded":"0","microtimestamp":"1787932601310000","price":"78522.98"},"previous_record_hash":"f5f2b8a587c7012d861e9579b3020c5551c1b3848495ee75a5e1d477ab4dca04","profit_assessment":null,"record_hash":"12f0a5663ed538f011c4bd752ee277d80117c8677e704aa27ee3fa47438a4553","recorded_unix_us":1787932601345739,"recorded_utc":"2026-08-28T15:56:41.345739Z","schema_version":"nrrf810.exchange_authored_interactive_closure.v1","source_chain_continuous":true,"source_event":"order_deleted","source_event_id":"00065a1d-7f95-5b30-0000-000100000020","source_event_id_unique":true,"source_pre_event_id":"00065a1d-7f95-3420-0000-000103000020","translation":"PARTIAL_PRIOR_UNFOLD","unfold_event_id":null,"zero_hair":false}
{"channel":"live_orders_btcusd","interaction_index":68,"natural_form":{"channel":"live_orders_btcusd","order_id":"2044303877513221","order_subtype":5,"order_type":1},"natural_form_sha256":"e6c1b021112393f8d79100e83cc7406788344ce3992af4f04d4c2ddec90683ed","order_source":"orderbook","orders_submitted":0,"presentation":{"amount":"0.06367384","amount_traded":"0","microtimestamp":"1787932601311000","price":"78525.19"},"previous_record_hash":"12f0a5663ed538f011c4bd752ee277d80117c8677e704aa27ee3fa47438a4553","profit_assessment":null,"record_hash":"6c8cd9a40d21e327455d5c07492bc4e4b28995bc498e0bfa19c605da4e66981b","recorded_unix_us":1787932601345763,"recorded_utc":"2026-08-28T15:56:41.345763Z","schema_version":"nrrf810.exchange_authored_interactive_closure.v1","source_chain_continuous":true,"source_event":"order_deleted","source_event_id":"00065a1d-7f95-5f18-0000-000101000020","source_event_id_unique":true,"source_pre_event_id":"00065a1d-7f95-5b30-0000-000100000020","translation":"PARTIAL_PRIOR_UNFOLD","unfold_event_id":null,"zero_hair":false}
{"channel":"live_orders_btcusd","interaction_index":69,"natural_form":{"channel":"live_orders_btcusd","order_id":"2044303877513222","order_subtype":5,"order_type":1},"natural_form_sha256":"e5c6cecca9b22f72dc854a96d37dec842b4a1fa571d10330df6e93f1fa229037","order_source":"orderbook","orders_submitted":0,"presentation":{"amount":"0.25467128","amount_traded":"0","microtimestamp":"1787932601311000","price":"78532.61"},"previous_record_hash":"6c8cd9a40d21e327455d5c07492bc4e4b28995bc498e0bfa19c605da4e66981b","profit_assessment":null,"record_hash":"ec09a207d7e915b4b35002a4c1a317a2e54bd3d98ddd4346b23093ce5e94a4d8","recorded_unix_us":1787932601345847,"recorded_utc":"2026-08-28T15:56:41.345847Z","schema_version":"nrrf810.exchange_authored_interactive_closure.v1","source_chain_continuous":true,"source_event":"order_deleted","source_event_id":"00065a1d-7f95-5f18-0001-000102000020","source_event_id_unique":true,"source_pre_event_id":"00065a1d-7f95-5f18-0000-000101000020","translation":"PARTIAL_PRIOR_UNFOLD","unfold_event_id":null,"zero_hair":false}
{"channel":"live_orders_btcusd","interaction_index":70,"natural_form":{"channel":"live_orders_btcusd","order_id":"2044303877517313","order_subtype":5,"order_type":1},"natural_form_sha256":"91d760674922c1a444253779efe4b5f6394fb1bb652546615addaef55ee754a6","order_source":"orderbook","orders_submitted":0,"presentation":{"amount":"0.25466146","amount_traded":"0","microtimestamp":"1787932601311000","price":"78535.64"},"previous_record_hash":"ec09a207d7e915b4b35002a4c1a317a2e54bd3d98ddd4346b23093ce5e94a4d8","profit_assessment":null,"record_hash":"9afe7bdf6a147e107cac05435208da662641db1cfd9f80f15c1d572ef52b37ee","recorded_unix_us":1787932601345961,"recorded_utc":"2026-08-28T15:56:41.345961Z","schema_version":"nrrf810.exchange_authored_interactive_closure.v1","source_chain_continuous":true,"source_event":"order_deleted","source_event_id":"00065a1d-7f95-5f18-0002-000103000020","source_event_id_unique":true,"source_pre_event_id":"00065a1d-7f95-5f18-0001-000102000020","translation":"PARTIAL_PRIOR_UNFOLD","unfold_event_id":null,"zero_hair":false}
{"channel":"live_orders_btcusd","interaction_index":71,"natural_form":{"channel":"live_orders_btcusd","order_id":"2044303877517320","order_subtype":5,"order_type":1},"natural_form_sha256":"def5e5375b10b859117d6e9b7078e98b01e7d85a5960fb4c00e89a0c7b2944d9","order_source":"orderbook","orders_submitted":0,"presentation":{"amount":"1.27209222","amount_traded":"0","microtimestamp":"1787932601312000","price":"78610.66"},"previous_record_hash":"9afe7bdf6a147e107cac05435208da662641db1cfd9f80f15c1d572ef52b37ee","profit_assessment":null,"record_hash":"7dadd5aa0269fbd2162e7867c5ea7c4a59b6d7fbf45f2751af8677c85fdbe2d0","recorded_unix_us":1787932601345984,"recorded_utc":"2026-08-28T15:56:41.345984Z","schema_version":"nrrf810.exchange_authored_interactive_closure.v1","source_chain_continuous":true,"source_event":"order_deleted","source_event_id":"00065a1d-7f95-6300-0000-000100000020","source_event_id_unique":true,"source_pre_event_id":"00065a1d-7f95-5f18-0002-000103000020","translation":"PARTIAL_PRIOR_UNFOLD","unfold_event_id":null,"zero_hair":false}
{"channel":"live_orders_btcusd","interaction_index":72,"natural_form":{"channel":"live_orders_btcusd","order_id":"2044303878774791","order_subtype":5,"order_type":1},"natural_form_sha256":"9ae6d227b55bb0d7ae5f251cda721ad406deb5010a29046e81ac1c9c434ea966","order_source":"orderbook","orders_submitted":0,"presentation":{"amount":"0.10000000","amount_traded":"0","microtimestamp":"1787932601312000","price":"78522.62"},"previous_record_hash":"7dadd5aa0269fbd2162e7867c5ea7c4a59b6d7fbf45f2751af8677c85fdbe2d0","profit_assessment":null,"record_hash":"7568e4b3ff7c65c41e9cc57d401a1de5eb33d225e3a78b8750a31a016ff45e2c","recorded_unix_us":1787932601420717,"recorded_utc":"2026-08-28T15:56:41.420717Z","schema_version":"nrrf810.exchange_authored_interactive_closure.v1","source_chain_continuous":true,"source_event":"order_created","source_event_id":"00065a1d-7f95-6300-0001-000101000020","source_event_id_unique":true,"source_pre_event_id":"00065a1d-7f95-6300-0000-000100000020","translation":"UNFOLD_TO_INF","unfold_event_id":null,"zero_hair":false}
{"channel":"live_orders_btcusd","interaction_index":73,"natural_form":{"channel":"live_orders_btcusd","order_id":"2044303878774791","order_subtype":5,"order_type":1},"natural_form_sha256":"9ae6d227b55bb0d7ae5f251cda721ad406deb5010a29046e81ac1c9c434ea966","order_source":"orderbook","orders_submitted":0,"presentation":{"amount":"0.10000000","amount_traded":"0","microtimestamp":"1787932601312000","price":"78522.62"},"previous_record_hash":"7568e4b3ff7c65c41e9cc57d401a1de5eb33d225e3a78b8750a31a016ff45e2c","profit_assessment":null,"record_hash":"e95969b200ff011e86dfc5216ee4e77589ce62081638fb22193356fe9666e20b","recorded_unix_us":1787932601420776,"recorded_utc":"2026-08-28T15:56:41.420776Z","schema_version":"nrrf810.exchange_authored_interactive_closure.v1","source_chain_continuous":true,"source_event":"order_deleted","source_event_id":"00065a1d-7f95-6300-0002-000102000020","source_event_id_unique":true,"source_pre_event_id":"00065a1d-7f95-6300-0001-000101000020","translation":"FOLD_RETURN_TO_ZERO","unfold_event_id":"00065a1d-7f95-6300-0001-000101000020","zero_hair":true}
{"channel":"live_orders_btcusd","interaction_index":74,"natural_form":{"channel":"live_orders_btcusd","order_id":"2044303877521409","order_subtype":5,"order_type":1},"natural_form_sha256":"cf2b2b4597fafa7493de99b118e9fcf43ef29aa103b432cdb095198e8d6fde48","order_source":"orderbook","orders_submitted":0,"presentation":{"amount":"12.70451953","amount_traded":"0","microtimestamp":"1787932601312000","price":"78712.15"},"previous_record_hash":"e95969b200ff011e86dfc5216ee4e77589ce62081638fb22193356fe9666e20b","profit_assessment":null,"record_hash":"45e915a85e94c86ff8cd6d9c724134e0184f6932ef5e318341cee19064020a37","recorded_unix_us":1787932601420925,"recorded_utc":"2026-08-28T15:56:41.420925Z","schema_version":"nrrf810.exchange_authored_interactive_closure.v1","source_chain_continuous":true,"source_event":"order_deleted","source_event_id":"00065a1d-7f95-6300-0003-000103000020","source_event_id_unique":true,"source_pre_event_id":"00065a1d-7f95-6300-0002-000102000020","translation":"PARTIAL_PRIOR_UNFOLD","unfold_event_id":null,"zero_hair":false}
{"channel":"live_orders_btcusd","interaction_index":75,"natural_form":{"channel":"live_orders_btcusd","order_id":"2044303877521413","order_subtype":5,"order_type":1},"natural_form_sha256":"827c3b7dac8b576dbf79fe55f3ffb8bdbfee8cd4d2c916a48a5c1afa9707a650","order_source":"orderbook","orders_submitted":0,"presentation":{"amount":"1.26840120","amount_traded":"0","microtimestamp":"1787932601312000","price":"78839.41"},"previous_record_hash":"45e915a85e94c86ff8cd6d9c724134e0184f6932ef5e318341cee19064020a37","profit_assessment":null,"record_hash":"76bb2cf452d8d711ebcebd0f2e2b63deff3cc406c5e14a6b01cb23869f7dbddd","recorded_unix_us":1787932601420952,"recorded_utc":"2026-08-28T15:56:41.420952Z","schema_version":"nrrf810.exchange_authored_interactive_closure.v1","source_chain_continuous":true,"source_event":"order_deleted","source_event_id":"00065a1d-7f95-6300-0004-000100000020","source_event_id_unique":true,"source_pre_event_id":"00065a1d-7f95-6300-0003-000103000020","translation":"PARTIAL_PRIOR_UNFOLD","unfold_event_id":null,"zero_hair":false}
{"channel":"live_orders_btcusd","interaction_index":76,"natural_form":{"channel":"live_orders_btcusd","order_id":"2044303877525504","order_subtype":5,"order_type":1},"natural_form_sha256":"2fedda178938c8fad23c106f93bf3989cfbd9b1107887a94fadf14c84351b13f","order_source":"orderbook","orders_submitted":0,"presentation":{"amount":"1.26970017","amount_traded":"0","microtimestamp":"1787932601312000","price":"78758.76"},"previous_record_hash":"76bb2cf452d8d711ebcebd0f2e2b63deff3cc406c5e14a6b01cb23869f7dbddd","profit_assessment":null,"record_hash":"4745b7603a2b0b9346a4d0a331a17bc3e36f7a175d37b2667a9cec53a7468432","recorded_unix_us":1787932601421057,"recorded_utc":"2026-08-28T15:56:41.421057Z","schema_version":"nrrf810.exchange_authored_interactive_closure.v1","source_chain_continuous":true,"source_event":"order_deleted","source_event_id":"00065a1d-7f95-6300-0005-000101000020","source_event_id_unique":true,"source_pre_event_id":"00065a1d-7f95-6300-0004-000100000020","translation":"PARTIAL_PRIOR_UNFOLD","unfold_event_id":null,"zero_hair":false}
{"channel":"live_orders_btcusd","interaction_index":77,"natural_form":{"channel":"live_orders_btcusd","order_id":"2044303877648389","order_subtype":5,"order_type":1},"natural_form_sha256":"9db355592884394204ec14aeed66c012be54b090d86cad9c18a001a3142751d8","order_source":"orderbook","orders_submitted":0,"presentation":{"amount":"1.26842789","amount_traded":"0","microtimestamp":"1787932601313000","price":"78837.75"},"previous_record_hash":"4745b7603a2b0b9346a4d0a331a17bc3e36f7a175d37b2667a9cec53a7468432","profit_assessment":null,"record_hash":"93d55bd4cd531979c5d8ecbd0d45eaa27aeb13311415c68f8b44ad16086be114","recorded_unix_us":1787932601421168,"recorded_utc":"2026-08-28T15:56:41.421168Z","schema_version":"nrrf810.exchange_authored_interactive_closure.v1","source_chain_continuous":true,"source_event":"order_deleted","source_event_id":"00065a1d-7f95-66e8-0000-000102000020","source_event_id_unique":true,"source_pre_event_id":"00065a1d-7f95-6300-0005-000101000020","translation":"PARTIAL_PRIOR_UNFOLD","unfold_event_id":null,"zero_hair":false}
{"channel":"live_orders_btcusd","interaction_index":78,"natural_form":{"channel":"live_orders_btcusd","order_id":"2044303877660694","order_subtype":5,"order_type":1},"natural_form_sha256":"b86fd088dcae426924190b8412ecf83fa9c55b49fcc8456ed18035c8bacf1198","order_source":"orderbook","orders_submitted":0,"presentation":{"amount":"1.27177200","amount_traded":"0","microtimestamp":"1787932601313000","price":"78630.45"},"previous_record_hash":"93d55bd4cd531979c5d8ecbd0d45eaa27aeb13311415c68f8b44ad16086be114","profit_assessment":null,"record_hash":"f13a93bcd1a7aca47d81caeb7a11ec566316ad466704b9e75e9127fd81c18c7f","recorded_unix_us":1787932601421296,"recorded_utc":"2026-08-28T15:56:41.421296Z","schema_version":"nrrf810.exchange_authored_interactive_closure.v1","source_chain_continuous":true,"source_event":"order_deleted","source_event_id":"00065a1d-7f95-66e8-0001-000103000020","source_event_id_unique":true,"source_pre_event_id":"00065a1d-7f95-66e8-0000-000102000020","translation":"PARTIAL_PRIOR_UNFOLD","unfold_event_id":null,"zero_hair":false}
{"channel":"live_orders_btcusd","interaction_index":79,"natural_form":{"channel":"live_orders_btcusd","order_id":"2044303877681159","order_subtype":5,"order_type":0},"natural_form_sha256":"d43c38357611bdb766d2775fd81937455cf408a2cafe0f0e6d9541d3b34f33b4","order_source":"orderbook","orders_submitted":0,"presentation":{"amount":"0.06368334","amount_traded":"0","microtimestamp":"1787932601313000","price":"78513.46"},"previous_record_hash":"f13a93bcd1a7aca47d81caeb7a11ec566316ad466704b9e75e9127fd81c18c7f","profit_assessment":null,"record_hash":"fa6f0454d3ac820c4238b0a426008772551f4fdd54791b7a02c4601e004a3952","recorded_unix_us":1787932601421345,"recorded_utc":"2026-08-28T15:56:41.421345Z","schema_version":"nrrf810.exchange_authored_interactive_closure.v1","source_chain_continuous":true,"source_event":"order_deleted","source_event_id":"00065a1d-7f95-66e8-0002-000100000020","source_event_id_unique":true,"source_pre_event_id":"00065a1d-7f95-66e8-0001-000103000020","translation":"PARTIAL_PRIOR_UNFOLD","unfold_event_id":null,"zero_hair":false}
{"channel":"live_orders_btcusd","interaction_index":80,"natural_form":{"channel":"live_orders_btcusd","order_id":"2044303877685248","order_subtype":5,"order_type":0},"natural_form_sha256":"2d6c68cb4374c32631bec7aabcedf9e5b61d511383cd288d318bc598544db700","order_source":"orderbook","orders_submitted":0,"presentation":{"amount":"0.25478772","amount_traded":"0","microtimestamp":"1787932601314000","price":"78496.71"},"previous_record_hash":"fa6f0454d3ac820c4238b0a426008772551f4fdd54791b7a02c4601e004a3952","profit_assessment":null,"record_hash":"decfa3710b1d148021a19ead8ec7ba79cbd9d83f2bc8bda3881c81d108ab819d","recorded_unix_us":1787932601421467,"recorded_utc":"2026-08-28T15:56:41.421467Z","schema_version":"nrrf810.exchange_authored_interactive_closure.v1","source_chain_continuous":true,"source_event":"order_deleted","source_event_id":"00065a1d-7f95-6ad0-0000-000101000020","source_event_id_unique":true,"source_pre_event_id":"00065a1d-7f95-66e8-0002-000100000020","translation":"PARTIAL_PRIOR_UNFOLD","unfold_event_id":null,"zero_hair":false}
{"channel":"live_orders_btcusd","interaction_index":81,"natural_form":{"channel":"live_orders_btcusd","order_id":"2044303878787072","order_subtype":5,"order_type":1},"natural_form_sha256":"343f52c2f9cd8e2162fcce716216783ff4c1d510851ef81e056a83211f05d855","order_source":"orderbook","orders_submitted":0,"presentation":{"amount":"0.10000000","amount_traded":"0","microtimestamp":"1787932601314000","price":"78522.63"},"previous_record_hash":"decfa3710b1d148021a19ead8ec7ba79cbd9d83f2bc8bda3881c81d108ab819d","profit_assessment":null,"record_hash":"3007ab9a0f7cbcacd8f962606d6cb8f64046d08c07d520a133e6b28dd6ce4cbd","recorded_unix_us":1787932601421501,"recorded_utc":"2026-08-28T15:56:41.421501Z","schema_version":"nrrf810.exchange_authored_interactive_closure.v1","source_chain_continuous":true,"source_event":"order_created","source_event_id":"00065a1d-7f95-6ad0-0001-000102000020","source_event_id_unique":true,"source_pre_event_id":"00065a1d-7f95-6ad0-0000-000101000020","translation":"UNFOLD_TO_INF","unfold_event_id":null,"zero_hair":false}
{"channel":"live_orders_btcusd","interaction_index":82,"natural_form":{"channel":"live_orders_btcusd","order_id":"2044303878787072","order_subtype":5,"order_type":1},"natural_form_sha256":"343f52c2f9cd8e2162fcce716216783ff4c1d510851ef81e056a83211f05d855","order_source":"orderbook","orders_submitted":0,"presentation":{"amount":"0.10000000","amount_traded":"0","microtimestamp":"1787932601314000","price":"78522.63"},"previous_record_hash":"3007ab9a0f7cbcacd8f962606d6cb8f64046d08c07d520a133e6b28dd6ce4cbd","profit_assessment":null,"record_hash":"b1d7f2e7cc7207b99288db15ed8034f16831367847aedd5be774f2c8fafa5562","recorded_unix_us":1787932601421640,"recorded_utc":"2026-08-28T15:56:41.421640Z","schema_version":"nrrf810.exchange_authored_interactive_closure.v1","source_chain_continuous":true,"source_event":"order_deleted","source_event_id":"00065a1d-7f95-6ad0-0002-000103000020","source_event_id_unique":true,"source_pre_event_id":"00065a1d-7f95-6ad0-0001-000102000020","translation":"FOLD_RETURN_TO_ZERO","unfold_event_id":"00065a1d-7f95-6ad0-0001-000102000020","zero_hair":true}
{"channel":"live_orders_btcusd","interaction_index":83,"natural_form":{"channel":"live_orders_btcusd","order_id":"2044303877689348","order_subtype":5,"order_type":0},"natural_form_sha256":"c10a52e2a60177e5a03cc6e872640df0e50b7239a9ff9ea730eec9ac18e45b53","order_source":"orderbook","orders_submitted":0,"presentation":{"amount":"1.27567513","amount_traded":"0","microtimestamp":"1787932601314000","price":"78389.86"},"previous_record_hash":"b1d7f2e7cc7207b99288db15ed8034f16831367847aedd5be774f2c8fafa5562","profit_assessment":null,"record_hash":"18660251565e48bbb9afd358b582805336ac9ebc6eb51d4d3d13fea9bf9a310b","recorded_unix_us":1787932601421671,"recorded_utc":"2026-08-28T15:56:41.421671Z","schema_version":"nrrf810.exchange_authored_interactive_closure.v1","source_chain_continuous":true,"source_event":"order_deleted","source_event_id":"00065a1d-7f95-6ad0-0003-000100000020","source_event_id_unique":true,"source_pre_event_id":"00065a1d-7f95-6ad0-0002-000103000020","translation":"PARTIAL_PRIOR_UNFOLD","unfold_event_id":null,"zero_hair":false}
{"channel":"live_orders_btcusd","interaction_index":84,"natural_form":{"channel":"live_orders_btcusd","order_id":"2044303878787076","order_subtype":5,"order_type":1},"natural_form_sha256":"aa5e79dc637159620275c970c0e0d207dd540c5941d5ad68677104553561ff86","order_source":"orderbook","orders_submitted":0,"presentation":{"amount":"0.10000000","amount_traded":"0","microtimestamp":"1787932601314000","price":"78523.00"},"previous_record_hash":"18660251565e48bbb9afd358b582805336ac9ebc6eb51d4d3d13fea9bf9a310b","profit_assessment":null,"record_hash":"d8da8bdae84ce7c03362b7c2299e1793b32b9d51ace4627a6f82ba5279d1e910","recorded_unix_us":1787932601421694,"recorded_utc":"2026-08-28T15:56:41.421694Z","schema_version":"nrrf810.exchange_authored_interactive_closure.v1","source_chain_continuous":true,"source_event":"order_created","source_event_id":"00065a1d-7f95-6ad0-0004-000101000020","source_event_id_unique":true,"source_pre_event_id":"00065a1d-7f95-6ad0-0003-000100000020","translation":"UNFOLD_TO_INF","unfold_event_id":null,"zero_hair":false}
{"channel":"live_orders_btcusd","interaction_index":85,"natural_form":{"channel":"live_orders_btcusd","order_id":"2044303877689349","order_subtype":5,"order_type":0},"natural_form_sha256":"9e624c0cc9c186d5d1f2db63b1ead2542b37ce2ede5875e5e317f5ff6cb05057","order_source":"orderbook","orders_submitted":0,"presentation":{"amount":"1.27541152","amount_traded":"0","microtimestamp":"1787932601314000","price":"78406.06"},"previous_record_hash":"d8da8bdae84ce7c03362b7c2299e1793b32b9d51ace4627a6f82ba5279d1e910","profit_assessment":null,"record_hash":"3996ce6f92e7096d21fc93fafa2fa02d44a45b3fb11badefbad5fc31c644101e","recorded_unix_us":1787932601421775,"recorded_utc":"2026-08-28T15:56:41.421775Z","schema_version":"nrrf810.exchange_authored_interactive_closure.v1","source_chain_continuous":true,"source_event":"order_deleted","source_event_id":"00065a1d-7f95-6ad0-0005-000102000020","source_event_id_unique":true,"source_pre_event_id":"00065a1d-7f95-6ad0-0004-000101000020","translation":"PARTIAL_PRIOR_UNFOLD","unfold_event_id":null,"zero_hair":false}
{"channel":"live_orders_btcusd","interaction_index":86,"natural_form":{"channel":"live_orders_btcusd","order_id":"2044303877693441","order_subtype":5,"order_type":0},"natural_form_sha256":"c3ec6f88c3bde5dc122a454fe1e2c96c210e57b3f95b7195b6c014eca751bcf6","order_source":"orderbook","orders_submitted":0,"presentation":{"amount":"1.27507828","amount_traded":"0","microtimestamp":"1787932601315000","price":"78426.55"},"previous_record_hash":"3996ce6f92e7096d21fc93fafa2fa02d44a45b3fb11badefbad5fc31c644101e","profit_assessment":null,"record_hash":"976bca930bd2740c6ad8b7db9a67aeb119911ed78932a1ed45dd545d519b9b93","recorded_unix_us":1787932601421882,"recorded_utc":"2026-08-28T15:56:41.421882Z","schema_version":"nrrf810.exchange_authored_interactive_closure.v1","source_chain_continuous":true,"source_event":"order_deleted","source_event_id":"00065a1d-7f95-6eb8-0000-000103000020","source_event_id_unique":true,"source_pre_event_id":"00065a1d-7f95-6ad0-0005-000102000020","translation":"PARTIAL_PRIOR_UNFOLD","unfold_event_id":null,"zero_hair":false}
{"channel":"live_orders_btcusd","interaction_index":87,"natural_form":{"channel":"live_orders_btcusd","order_id":"2044303877742596","order_subtype":5,"order_type":0},"natural_form_sha256":"fc6dd4a1596c9f3f2f5f038af6018a778853997a6f48dcf94fd1dfc7eb084fe5","order_source":"orderbook","orders_submitted":0,"presentation":{"amount":"12.76418733","amount_traded":"0","microtimestamp":"1787932601315000","price":"78344.19"},"previous_record_hash":"976bca930bd2740c6ad8b7db9a67aeb119911ed78932a1ed45dd545d519b9b93","profit_assessment":null,"record_hash":"1995b6d0f61f760c658a4c0fc80bc7033c2e0971aa7215087a7dd7b68247e5d8","recorded_unix_us":1787932601421907,"recorded_utc":"2026-08-28T15:56:41.421907Z","schema_version":"nrrf810.exchange_authored_interactive_closure.v1","source_chain_continuous":true,"source_event":"order_deleted","source_event_id":"00065a1d-7f95-6eb8-0001-000100000020","source_event_id_unique":true,"source_pre_event_id":"00065a1d-7f95-6eb8-0000-000103000020","translation":"PARTIAL_PRIOR_UNFOLD","unfold_event_id":null,"zero_hair":false}
{"channel":"live_orders_btcusd","interaction_index":88,"natural_form":{"channel":"live_orders_btcusd","order_id":"2044303877795854","order_subtype":5,"order_type":0},"natural_form_sha256":"5aca37277f10ee97c9ce9cb1ac706f7f6ec9ce2050eb3871cb2b3c615a91d02d","order_source":"orderbook","orders_submitted":0,"presentation":{"amount":"1.27757154","amount_traded":"0","microtimestamp":"1787932601315000","price":"78273.50"},"previous_record_hash":"1995b6d0f61f760c658a4c0fc80bc7033c2e0971aa7215087a7dd7b68247e5d8","profit_assessment":null,"record_hash":"802a2cdc09a739d72508c22548b2eab6abe7691ec2ba1cf050824f43d88c1c75","recorded_unix_us":1787932601421988,"recorded_utc":"2026-08-28T15:56:41.421988Z","schema_version":"nrrf810.exchange_authored_interactive_closure.v1","source_chain_continuous":true,"source_event":"order_deleted","source_event_id":"00065a1d-7f95-6eb8-0002-000101000020","source_event_id_unique":true,"source_pre_event_id":"00065a1d-7f95-6eb8-0001-000100000020","translation":"PARTIAL_PRIOR_UNFOLD","unfold_event_id":null,"zero_hair":false}
{"channel":"live_orders_btcusd","interaction_index":89,"natural_form":{"channel":"live_orders_btcusd","order_id":"2044303877918729","order_subtype":5,"order_type":1},"natural_form_sha256":"17fe4b80fa912f3306b5b7e1e5d0817bb04c259d92a4962cb3381b0258773eba","order_source":"orderbook","orders_submitted":0,"presentation":{"amount":"1.27145262","amount_traded":"0","microtimestamp":"1787932601316000","price":"78650.20"},"previous_record_hash":"802a2cdc09a739d72508c22548b2eab6abe7691ec2ba1cf050824f43d88c1c75","profit_assessment":null,"record_hash":"07755d6fca4c703f1a2d5406f39241defb7781d201cd3a2af08f061552e37b59","recorded_unix_us":1787932601422097,"recorded_utc":"2026-08-28T15:56:41.422097Z","schema_version":"nrrf810.exchange_authored_interactive_closure.v1","source_chain_continuous":true,"source_event":"order_deleted","source_event_id":"00065a1d-7f95-72a0-0000-000102000020","source_event_id_unique":true,"source_pre_event_id":"00065a1d-7f95-6eb8-0002-000101000020","translation":"PARTIAL_PRIOR_UNFOLD","unfold_event_id":null,"zero_hair":false}
{"channel":"live_orders_btcusd","interaction_index":90,"natural_form":{"channel":"live_orders_btcusd","order_id":"2044303877935115","order_subtype":5,"order_type":0},"natural_form_sha256":"2e2e2486ec385e2b0edc2294f2de69c21ea071e7c35d94bc5186edab4cd61c74","order_source":"orderbook","orders_submitted":0,"presentation":{"amount":"1.27604867","amount_traded":"0","microtimestamp":"1787932601316000","price":"78366.91"},"previous_record_hash":"07755d6fca4c703f1a2d5406f39241defb7781d201cd3a2af08f061552e37b59","profit_assessment":null,"record_hash":"b141cac1096030df051565d441a3b5a09e0bd6dd95a4f9ae06e15a15ef5fed42","recorded_unix_us":1787932601422124,"recorded_utc":"2026-08-28T15:56:41.422124Z","schema_version":"nrrf810.exchange_authored_interactive_closure.v1","source_chain_continuous":true,"source_event":"order_deleted","source_event_id":"00065a1d-7f95-72a0-0001-000103000020","source_event_id_unique":true,"source_pre_event_id":"00065a1d-7f95-72a0-0000-000102000020","translation":"PARTIAL_PRIOR_UNFOLD","unfold_event_id":null,"zero_hair":false}
{"channel":"live_orders_btcusd","interaction_index":91,"natural_form":{"channel":"live_orders_btcusd","order_id":"2044303877939204","order_subtype":5,"order_type":0},"natural_form_sha256":"aeb1314fb35653b9ae13cd7b59c55c4bc0270ee9836ae0e107a941007f061eec","order_source":"orderbook","orders_submitted":0,"presentation":{"amount":"1.27817952","amount_traded":"0","microtimestamp":"1787932601316000","price":"78236.27"},"previous_record_hash":"b141cac1096030df051565d441a3b5a09e0bd6dd95a4f9ae06e15a15ef5fed42","profit_assessment":null,"record_hash":"3ce8ead78214bec1a020d3ddef6bc6f39b34ceef0dde63e912eb36ab53715331","recorded_unix_us":1787932601422198,"recorded_utc":"2026-08-28T15:56:41.422198Z","schema_version":"nrrf810.exchange_authored_interactive_closure.v1","source_chain_continuous":true,"source_event":"order_deleted","source_event_id":"00065a1d-7f95-72a0-0002-000100000020","source_event_id_unique":true,"source_pre_event_id":"00065a1d-7f95-72a0-0001-000103000020","translation":"PARTIAL_PRIOR_UNFOLD","unfold_event_id":null,"zero_hair":false}
{"channel":"live_orders_ethbtc","interaction_index":92,"natural_form":{"channel":"live_orders_ethbtc","order_id":"2044303878811654","order_subtype":5,"order_type":1},"natural_form_sha256":"102ddd71a43f3d7e3a6669375399c86a3ec5e02a7d32f9bfacdbb86366495057","order_source":"orderbook","orders_submitted":0,"presentation":{"amount":"2.01528391","amount_traded":"0","microtimestamp":"1787932601320000","price":"0.03160301"},"previous_record_hash":"3ce8ead78214bec1a020d3ddef6bc6f39b34ceef0dde63e912eb36ab53715331","profit_assessment":null,"record_hash":"97f08bb2d17d104f77df60407e89a693aa02f22e13a12eb06649644ce3096535","recorded_unix_us":1787932601422343,"recorded_utc":"2026-08-28T15:56:41.422343Z","schema_version":"nrrf810.exchange_authored_interactive_closure.v1","source_chain_continuous":true,"source_event":"order_created","source_event_id":"00065a1d-7f95-8240-0000-001100000020","source_event_id_unique":true,"source_pre_event_id":"00065a1d-7f94-e218-0000-001103000020","translation":"UNFOLD_TO_INF","unfold_event_id":null,"zero_hair":false}
{"channel":"live_orders_ethbtc","interaction_index":93,"natural_form":{"channel":"live_orders_ethbtc","order_id":"2044303877382144","order_subtype":5,"order_type":1},"natural_form_sha256":"cc97a368664a324f72ae81920b94166226ce2ac7ee25186bed3ffd5b0545de90","order_source":"orderbook","orders_submitted":0,"presentation":{"amount":"4.02232075","amount_traded":"0","microtimestamp":"1787932601328000","price":"0.03165997"},"previous_record_hash":"97f08bb2d17d104f77df60407e89a693aa02f22e13a12eb06649644ce3096535","profit_assessment":null,"record_hash":"5f5ecacdce286cc44e02e5fc439fa5aeb7cc9efc4ad4c62600ad333eb441fee8","recorded_unix_us":1787932601422369,"recorded_utc":"2026-08-28T15:56:41.422369Z","schema_version":"nrrf810.exchange_authored_interactive_closure.v1","source_chain_continuous":true,"source_event":"order_deleted","source_event_id":"00065a1d-7f95-a180-0000-001101000020","source_event_id_unique":true,"source_pre_event_id":"00065a1d-7f95-8240-0000-001100000020","translation":"PARTIAL_PRIOR_UNFOLD","unfold_event_id":null,"zero_hair":false}
{"channel":"live_orders_ethbtc","interaction_index":94,"natural_form":{"channel":"live_orders_ethbtc","order_id":"2044303877517317","order_subtype":5,"order_type":1},"natural_form_sha256":"272976ffa03d682c538db3b3788fdfabd2f051cf480eda83b7747ec3bc7ee67c","order_source":"orderbook","orders_submitted":0,"presentation":{"amount":"0.60446465","amount_traded":"0","microtimestamp":"1787932601329000","price":"0.03160302"},"previous_record_hash":"5f5ecacdce286cc44e02e5fc439fa5aeb7cc9efc4ad4c62600ad333eb441fee8","profit_assessment":null,"record_hash":"e1099350cb369944e08ebe8ec2a8de09405f3a19fff5277743e3049a4f07712a","recorded_unix_us":1787932601422465,"recorded_utc":"2026-08-28T15:56:41.422465Z","schema_version":"nrrf810.exchange_authored_interactive_closure.v1","source_chain_continuous":true,"source_event":"order_deleted","source_event_id":"00065a1d-7f95-a568-0000-001102000020","source_event_id_unique":true,"source_pre_event_id":"00065a1d-7f95-a180-0000-001101000020","translation":"PARTIAL_PRIOR_UNFOLD","unfold_event_id":null,"zero_hair":false}
{"channel":"live_orders_ethbtc","interaction_index":95,"natural_form":{"channel":"live_orders_ethbtc","order_id":"2044303877525505","order_subtype":5,"order_type":1},"natural_form_sha256":"b5591730c0d6e9dca6c229639446db2a826f223a35170eec17226a3dde8e7207","order_source":"orderbook","orders_submitted":0,"presentation":{"amount":"3.02055629","amount_traded":"0","microtimestamp":"1787932601329000","price":"0.03162186"},"previous_record_hash":"e1099350cb369944e08ebe8ec2a8de09405f3a19fff5277743e3049a4f07712a","profit_assessment":null,"record_hash":"94fdf0d948bccdcbd13ef314234773bd7f2d4d3c4b055544440240f168eb314a","recorded_unix_us":1787932601422694,"recorded_utc":"2026-08-28T15:56:41.422694Z","schema_version":"nrrf810.exchange_authored_interactive_closure.v1","source_chain_continuous":true,"source_event":"order_deleted","source_event_id":"00065a1d-7f95-a568-0001-001103000020","source_event_id_unique":true,"source_pre_event_id":"00065a1d-7f95-a568-0000-001102000020","translation":"PARTIAL_PRIOR_UNFOLD","unfold_event_id":null,"zero_hair":false}
{"channel":"live_orders_ethbtc","interaction_index":96,"natural_form":{"channel":"live_orders_ethbtc","order_id":"2044303877525506","order_subtype":5,"order_type":1},"natural_form_sha256":"1119805653e9df22975ebced8d1d18007cd8e83fb493a1c13491b00cdb8a03d0","order_source":"orderbook","orders_submitted":0,"presentation":{"amount":"2.01386943","amount_traded":"0","microtimestamp":"1787932601329000","price":"0.03161840"},"previous_record_hash":"94fdf0d948bccdcbd13ef314234773bd7f2d4d3c4b055544440240f168eb314a","profit_assessment":null,"record_hash":"bd1abdc0bd70827744098d256846403acb87ce837212f9389b2829aa2a95af6a","recorded_unix_us":1787932601422720,"recorded_utc":"2026-08-28T15:56:41.422720Z","schema_version":"nrrf810.exchange_authored_interactive_closure.v1","source_chain_continuous":true,"source_event":"order_deleted","source_event_id":"00065a1d-7f95-a568-0002-001100000020","source_event_id_unique":true,"source_pre_event_id":"00065a1d-7f95-a568-0001-001103000020","translation":"PARTIAL_PRIOR_UNFOLD","unfold_event_id":null,"zero_hair":false}
{"channel":"live_orders_ethbtc","interaction_index":97,"natural_form":{"channel":"live_orders_ethbtc","order_id":"2044303877529603","order_subtype":5,"order_type":0},"natural_form_sha256":"ed7e05f8a77cfbe4eae9cc8fa9161516ad080be2da56033d2bc7ac1a36d76ac4","order_source":"orderbook","orders_submitted":0,"presentation":{"amount":"0.60481990","amount_traded":"0","microtimestamp":"1787932601330000","price":"0.03158573"},"previous_record_hash":"bd1abdc0bd70827744098d256846403acb87ce837212f9389b2829aa2a95af6a","profit_assessment":null,"record_hash":"13214a9131052c7b287b567ef407504a8358552eaa868a669e329cfd216a996b","recorded_unix_us":1787932601422741,"recorded_utc":"2026-08-28T15:56:41.422741Z","schema_version":"nrrf810.exchange_authored_interactive_closure.v1","source_chain_continuous":true,"source_event":"order_deleted","source_event_id":"00065a1d-7f95-a950-0000-001101000020","source_event_id_unique":true,"source_pre_event_id":"00065a1d-7f95-a568-0002-001100000020","translation":"PARTIAL_PRIOR_UNFOLD","unfold_event_id":null,"zero_hair":false}
{"channel":"live_orders_ethbtc","interaction_index":98,"natural_form":{"channel":"live_orders_ethbtc","order_id":"2044303877533698","order_subtype":5,"order_type":0},"natural_form_sha256":"9a9e3844cfc20182c7fb0ce8b941b8b9e79e3c45cf8f19876a5ee98250ce62b1","order_source":"orderbook","orders_submitted":0,"presentation":{"amount":"1.00801353","amount_traded":"0","microtimestamp":"1787932601330000","price":"0.03158534"},"previous_record_hash":"13214a9131052c7b287b567ef407504a8358552eaa868a669e329cfd216a996b","profit_assessment":null,"record_hash":"628daa61fafb41bbcb56c6265f65b81c885b7be8d631b88b21624a79393026f4","recorded_unix_us":1787932601422849,"recorded_utc":"2026-08-28T15:56:41.422849Z","schema_version":"nrrf810.exchange_authored_interactive_closure.v1","source_chain_continuous":true,"source_event":"order_deleted","source_event_id":"00065a1d-7f95-a950-0001-001102000020","source_event_id_unique":true,"source_pre_event_id":"00065a1d-7f95-a950-0000-001101000020","translation":"PARTIAL_PRIOR_UNFOLD","unfold_event_id":null,"zero_hair":false}
{"channel":"live_orders_ethbtc","interaction_index":99,"natural_form":{"channel":"live_orders_ethbtc","order_id":"2044303877533699","order_subtype":5,"order_type":1},"natural_form_sha256":"052946a3bb048329700ccb3b5bca396fcfd0655c0fe99d873be2a3babe73e57f","order_source":"orderbook","orders_submitted":0,"presentation":{"amount":"1.00740464","amount_traded":"0","microtimestamp":"1787932601330000","price":"0.03160452"},"previous_record_hash":"628daa61fafb41bbcb56c6265f65b81c885b7be8d631b88b21624a79393026f4","profit_assessment":null,"record_hash":"9a68c135e5ed9d865646ad1f26d5a9f2c13fb3816315bf89284af4aed042d1af","recorded_unix_us":1787932601422884,"recorded_utc":"2026-08-28T15:56:41.422884Z","schema_version":"nrrf810.exchange_authored_interactive_closure.v1","source_chain_continuous":true,"source_event":"order_deleted","source_event_id":"00065a1d-7f95-a950-0002-001103000020","source_event_id_unique":true,"source_pre_event_id":"00065a1d-7f95-a950-0001-001102000020","translation":"PARTIAL_PRIOR_UNFOLD","unfold_event_id":null,"zero_hair":false}
{"channel":"live_orders_ethbtc","interaction_index":100,"natural_form":{"channel":"live_orders_ethbtc","order_id":"2044303877537801","order_subtype":5,"order_type":0},"natural_form_sha256":"f33f83eba09805d78f1b939f7ca1827069ae2181622f092c89812e056dfa791f","order_source":"orderbook","orders_submitted":0,"presentation":{"amount":"2.01629689","amount_traded":"0","microtimestamp":"1787932601331000","price":"0.03157941"},"previous_record_hash":"9a68c135e5ed9d865646ad1f26d5a9f2c13fb3816315bf89284af4aed042d1af","profit_assessment":null,"record_hash":"70bfd27f76f9d9c9682ec2150c79a500c002ac1419c910ae9e15f11fd4d5e338","recorded_unix_us":1787932601422999,"recorded_utc":"2026-08-28T15:56:41.422999Z","schema_version":"nrrf810.exchange_authored_interactive_closure.v1","source_chain_continuous":true,"source_event":"order_deleted","source_event_id":"00065a1d-7f95-ad38-0000-001100000020","source_event_id_unique":true,"source_pre_event_id":"00065a1d-7f95-a950-0002-001103000020","translation":"PARTIAL_PRIOR_UNFOLD","unfold_event_id":null,"zero_hair":false}
{"channel":"live_orders_ethbtc","interaction_index":101,"natural_form":{"channel":"live_orders_ethbtc","order_id":"2044303877537803","order_subtype":5,"order_type":0},"natural_form_sha256":"780e9e89730a9e295b77cced3a7f3e8c836ca7f8d3b5b2d404d83b92a225be4f","order_source":"orderbook","orders_submitted":0,"presentation":{"amount":"4.03662068","amount_traded":"0","microtimestamp":"1787932601331000","price":"0.03154857"},"previous_record_hash":"70bfd27f76f9d9c9682ec2150c79a500c002ac1419c910ae9e15f11fd4d5e338","profit_assessment":null,"record_hash":"1b10f517c666901efe24dd49a564605978a361a828e9d34551e6d5a6561e2800","recorded_unix_us":1787932601423024,"recorded_utc":"2026-08-28T15:56:41.423024Z","schema_version":"nrrf810.exchange_authored_interactive_closure.v1","source_chain_continuous":true,"source_event":"order_deleted","source_event_id":"00065a1d-7f95-ad38-0001-001101000020","source_event_id_unique":true,"source_pre_event_id":"00065a1d-7f95-ad38-0000-001100000020","translation":"PARTIAL_PRIOR_UNFOLD","unfold_event_id":null,"zero_hair":false}
{"channel":"live_orders_ethbtc","interaction_index":102,"natural_form":{"channel":"live_orders_ethbtc","order_id":"2044303877537806","order_subtype":5,"order_type":0},"natural_form_sha256":"77ed01ad0e6db7a57ba4488418d5ddff4a88faa4db5635e8cc1044ab74f0eebd","order_source":"orderbook","orders_submitted":0,"presentation":{"amount":"3.02537254","amount_traded":"0","microtimestamp":"1787932601331000","price":"0.03156999"},"previous_record_hash":"1b10f517c666901efe24dd49a564605978a361a828e9d34551e6d5a6561e2800","profit_assessment":null,"record_hash":"0c474552013ddb625671fd03940ebb9bf0962b871f9727f62f95582c388d04d6","recorded_unix_us":1787932601423141,"recorded_utc":"2026-08-28T15:56:41.423141Z","schema_version":"nrrf810.exchange_authored_interactive_closure.v1","source_chain_continuous":true,"source_event":"order_deleted","source_event_id":"00065a1d-7f95-ad38-0002-001102000020","source_event_id_unique":true,"source_pre_event_id":"00065a1d-7f95-ad38-0001-001101000020","translation":"PARTIAL_PRIOR_UNFOLD","unfold_event_id":null,"zero_hair":false}
{"channel":"live_orders_btcusd","interaction_index":103,"natural_form":{"channel":"live_orders_btcusd","order_id":"2044303878901771","order_subtype":5,"order_type":1},"natural_form_sha256":"c85a3302c27d0a216f3448b30980a3c10767c8a60c787eb6d585584c361e3056","order_source":"orderbook","orders_submitted":0,"presentation":{"amount":"0.10000000","amount_traded":"0","microtimestamp":"1787932601343000","price":"78522.62"},"previous_record_hash":"0c474552013ddb625671fd03940ebb9bf0962b871f9727f62f95582c388d04d6","profit_assessment":null,"record_hash":"74e8fa2ab939f8f640e4a4d3fd9f946a76c553cfe5b0c1b5c91eb5ae7cfcdb09","recorded_unix_us":1787932601423218,"recorded_utc":"2026-08-28T15:56:41.423218Z","schema_version":"nrrf810.exchange_authored_interactive_closure.v1","source_chain_continuous":true,"source_event":"order_created","source_event_id":"00065a1d-7f95-dc18-0000-000101000020","source_event_id_unique":true,"source_pre_event_id":"00065a1d-7f95-72a0-0002-000100000020","translation":"UNFOLD_TO_INF","unfold_event_id":null,"zero_hair":false}
{"channel":"live_orders_btcusd","interaction_index":104,"natural_form":{"channel":"live_orders_btcusd","order_id":"2044303878901771","order_subtype":5,"order_type":1},"natural_form_sha256":"c85a3302c27d0a216f3448b30980a3c10767c8a60c787eb6d585584c361e3056","order_source":"orderbook","orders_submitted":0,"presentation":{"amount":"0.10000000","amount_traded":"0","microtimestamp":"1787932601343000","price":"78522.62"},"previous_record_hash":"74e8fa2ab939f8f640e4a4d3fd9f946a76c553cfe5b0c1b5c91eb5ae7cfcdb09","profit_assessment":null,"record_hash":"b5b6d40c2fb20ef0d2bf88d1a6bef3166b7fabb9da2a545782ae98c07ae0468e","recorded_unix_us":1787932601423288,"recorded_utc":"2026-08-28T15:56:41.423288Z","schema_version":"nrrf810.exchange_authored_interactive_closure.v1","source_chain_continuous":true,"source_event":"order_deleted","source_event_id":"00065a1d-7f95-dc18-0001-000102000020","source_event_id_unique":true,"source_pre_event_id":"00065a1d-7f95-dc18-0000-000101000020","translation":"FOLD_RETURN_TO_ZERO","unfold_event_id":"00065a1d-7f95-dc18-0000-000101000020","zero_hair":true}
{"channel":"live_orders_btcusd","interaction_index":105,"natural_form":{"channel":"live_orders_btcusd","order_id":"2044303878922240","order_subtype":5,"order_type":0},"natural_form_sha256":"ba3e9acf397e4359c70372f89d42f94e99e2a3d71b0068b5f1d3a603ed8b8987","order_source":"orderbook","orders_submitted":0,"presentation":{"amount":"0.00140266","amount_traded":"0","microtimestamp":"1787932601347000","price":"70670.37"},"previous_record_hash":"b5b6d40c2fb20ef0d2bf88d1a6bef3166b7fabb9da2a545782ae98c07ae0468e","profit_assessment":null,"record_hash":"e43b79b5c8ee5d32745f106c019accf3c97ff0a9d4caf95b222ad03f4d67be70","recorded_unix_us":1787932601423414,"recorded_utc":"2026-08-28T15:56:41.423414Z","schema_version":"nrrf810.exchange_authored_interactive_closure.v1","source_chain_continuous":true,"source_event":"order_created","source_event_id":"00065a1d-7f95-ebb8-0000-000103000020","source_event_id_unique":true,"source_pre_event_id":"00065a1d-7f95-dc18-0001-000102000020","translation":"UNFOLD_TO_INF","unfold_event_id":null,"zero_hair":false}
{"channel":"live_orders_btcusd","interaction_index":106,"natural_form":{"channel":"live_orders_btcusd","order_id":"2044303878266885","order_subtype":5,"order_type":0},"natural_form_sha256":"ed56c945037d78672ab73a13f6b1bd020776a683839cce24cd89c024649b2916","order_source":"orderbook","orders_submitted":0,"presentation":{"amount":"0.00140266","amount_traded":"0","microtimestamp":"1787932601359000","price":"70670.37"},"previous_record_hash":"e43b79b5c8ee5d32745f106c019accf3c97ff0a9d4caf95b222ad03f4d67be70","profit_assessment":null,"record_hash":"212facfee8300a721594f822e515a2d5398c16d089128481f8383867fe4f7e35","recorded_unix_us":1787932601423445,"recorded_utc":"2026-08-28T15:56:41.423445Z","schema_version":"nrrf810.exchange_authored_interactive_closure.v1","source_chain_continuous":true,"source_event":"order_deleted","source_event_id":"00065a1d-7f96-1a98-0000-000100000020","source_event_id_unique":true,"source_pre_event_id":"00065a1d-7f95-ebb8-0000-000103000020","translation":"FOLD_RETURN_TO_ZERO","unfold_event_id":"00065a1d-7f93-7ab8-0000-000103000020","zero_hair":true}
{"channel":"live_orders_btcusd","interaction_index":107,"natural_form":{"channel":"live_orders_btcusd","order_id":"2044303878127633","order_subtype":5,"order_type":1},"natural_form_sha256":"2748b1908d48990d8e13458623b9002d81af8abc17566f1f419b81a136b6d980","order_source":"orderbook","orders_submitted":0,"presentation":{"amount":"0.10000000","amount_traded":"0","microtimestamp":"1787932601363000","price":"78523.32"},"previous_record_hash":"212facfee8300a721594f822e515a2d5398c16d089128481f8383867fe4f7e35","profit_assessment":null,"record_hash":"d19e3c4fd0d0c2b9ac40b8da5b141a7c878e9821e5cb04f374b0a925fb21a5d4","recorded_unix_us":1787932601423540,"recorded_utc":"2026-08-28T15:56:41.423540Z","schema_version":"nrrf810.exchange_authored_interactive_closure.v1","source_chain_continuous":true,"source_event":"order_deleted","source_event_id":"00065a1d-7f96-2a38-0000-000101000020","source_event_id_unique":true,"source_pre_event_id":"00065a1d-7f96-1a98-0000-000100000020","translation":"FOLD_RETURN_TO_ZERO","unfold_event_id":"00065a1d-7f92-f9d0-0000-000100000020","zero_hair":true}
{"channel":"live_orders_btcusd","interaction_index":108,"natural_form":{"channel":"live_orders_btcusd","order_id":"2044303879000072","order_subtype":5,"order_type":1},"natural_form_sha256":"755ac35d9838e65535ff80647699ad50ee15d39a53075794bef24a5bd8dfbd4f","order_source":"orderbook","orders_submitted":0,"presentation":{"amount":"0.10000000","amount_traded":"0","microtimestamp":"1787932601366000","price":"78522.63"},"previous_record_hash":"d19e3c4fd0d0c2b9ac40b8da5b141a7c878e9821e5cb04f374b0a925fb21a5d4","profit_assessment":null,"record_hash":"02fe4272f70f76889d46c64fc6d166c17bb9fbdbae2280d41801de8f7f153d33","recorded_unix_us":1787932601423675,"recorded_utc":"2026-08-28T15:56:41.423675Z","schema_version":"nrrf810.exchange_authored_interactive_closure.v1","source_chain_continuous":true,"source_event":"order_created","source_event_id":"00065a1d-7f96-35f0-0000-000102000020","source_event_id_unique":true,"source_pre_event_id":"00065a1d-7f96-2a38-0000-000101000020","translation":"UNFOLD_TO_INF","unfold_event_id":null,"zero_hair":false}
{"channel":"live_orders_btcusd","interaction_index":109,"natural_form":{"channel":"live_orders_btcusd","order_id":"2044303879000072","order_subtype":5,"order_type":1},"natural_form_sha256":"755ac35d9838e65535ff80647699ad50ee15d39a53075794bef24a5bd8dfbd4f","order_source":"orderbook","orders_submitted":0,"presentation":{"amount":"0.10000000","amount_traded":"0","microtimestamp":"1787932601366000","price":"78522.63"},"previous_record_hash":"02fe4272f70f76889d46c64fc6d166c17bb9fbdbae2280d41801de8f7f153d33","profit_assessment":null,"record_hash":"cb1c43b39e6025323d99fbe474f64a0b9ddec86c2cef47c472d9364f05dd279d","recorded_unix_us":1787932601423697,"recorded_utc":"2026-08-28T15:56:41.423697Z","schema_version":"nrrf810.exchange_authored_interactive_closure.v1","source_chain_continuous":true,"source_event":"order_deleted","source_event_id":"00065a1d-7f96-35f0-0001-000103000020","source_event_id_unique":true,"source_pre_event_id":"00065a1d-7f96-35f0-0000-000102000020","translation":"FOLD_RETURN_TO_ZERO","unfold_event_id":"00065a1d-7f96-35f0-0000-000102000020","zero_hair":true}
{"channel":"live_orders_ethusd","interaction_index":110,"natural_form":{"channel":"live_orders_ethusd","order_id":"2044303879004165","order_subtype":5,"order_type":0},"natural_form_sha256":"6c7ce6b078455690095181b15b1ac6ade197846398809c0372deaefc8b6afafe","order_source":"orderbook","orders_submitted":0,"presentation":{"amount":"1.184652","amount_traded":"0","microtimestamp":"1787932601367000","price":"2480.14"},"previous_record_hash":"cb1c43b39e6025323d99fbe474f64a0b9ddec86c2cef47c472d9364f05dd279d","profit_assessment":null,"record_hash":"ba09d694e3635272d1fa9f620e9beb300ff49a72422e63e1a49779ad40e74350","recorded_unix_us":1787932601423716,"recorded_utc":"2026-08-28T15:56:41.423716Z","schema_version":"nrrf810.exchange_authored_interactive_closure.v1","source_chain_continuous":true,"source_event":"order_created","source_event_id":"00065a1d-7f96-39d8-0000-001201000020","source_event_id_unique":true,"source_pre_event_id":"00065a1d-7f95-0928-0000-001200000020","translation":"UNFOLD_TO_INF","unfold_event_id":null,"zero_hair":false}
{"channel":"live_orders_btcusd","interaction_index":111,"natural_form":{"channel":"live_orders_btcusd","order_id":"2044303879032836","order_subtype":5,"order_type":1},"natural_form_sha256":"ec9d7ed7acafe113bfa0dfea88546bd2982104170fd077260e4d00ee281fe238","order_source":"orderbook","orders_submitted":0,"presentation":{"amount":"0.10000000","amount_traded":"0","microtimestamp":"1787932601374000","price":"78522.79"},"previous_record_hash":"ba09d694e3635272d1fa9f620e9beb300ff49a72422e63e1a49779ad40e74350","profit_assessment":null,"record_hash":"f0973f3541fc04f6695d86a2df5a0e0800451f6c6d3c49827b11431dd703da79","recorded_unix_us":1787932601423795,"recorded_utc":"2026-08-28T15:56:41.423795Z","schema_version":"nrrf810.exchange_authored_interactive_closure.v1","source_chain_continuous":true,"source_event":"order_created","source_event_id":"00065a1d-7f96-5530-0000-000100000020","source_event_id_unique":true,"source_pre_event_id":"00065a1d-7f96-35f0-0001-000103000020","translation":"UNFOLD_TO_INF","unfold_event_id":null,"zero_hair":false}
{"channel":"live_orders_btcusd","interaction_index":112,"natural_form":{"channel":"live_orders_btcusd","order_id":"2044303879061513","order_subtype":5,"order_type":1},"natural_form_sha256":"d20527458d5681847843a79087b860a2695fc2b29157e56d4e36abf8fca0f294","order_source":"orderbook","orders_submitted":0,"presentation":{"amount":"0.10000000","amount_traded":"0","microtimestamp":"1787932601382000","price":"78522.62"},"previous_record_hash":"f0973f3541fc04f6695d86a2df5a0e0800451f6c6d3c49827b11431dd703da79","profit_assessment":null,"record_hash":"0aa3f57d19e50766bede6dbfa493e3ce55a7496e9b35ebb9b2cc2dd1be308c72","recorded_unix_us":1787932601423901,"recorded_utc":"2026-08-28T15:56:41.423901Z","schema_version":"nrrf810.exchange_authored_interactive_closure.v1","source_chain_continuous":true,"source_event":"order_created","source_event_id":"00065a1d-7f96-7470-0000-000101000020","source_event_id_unique":true,"source_pre_event_id":"00065a1d-7f96-5530-0000-000100000020","translation":"UNFOLD_TO_INF","unfold_event_id":null,"zero_hair":false}
{"channel":"live_orders_btcusd","interaction_index":113,"natural_form":{"channel":"live_orders_btcusd","order_id":"2044303879061513","order_subtype":5,"order_type":1},"natural_form_sha256":"d20527458d5681847843a79087b860a2695fc2b29157e56d4e36abf8fca0f294","order_source":"orderbook","orders_submitted":0,"presentation":{"amount":"0.10000000","amount_traded":"0","microtimestamp":"1787932601382000","price":"78522.62"},"previous_record_hash":"0aa3f57d19e50766bede6dbfa493e3ce55a7496e9b35ebb9b2cc2dd1be308c72","profit_assessment":null,"record_hash":"17e56419c97f99931153b72edcaa70742d3e726ecbe679ad7afc054344abcc4d","recorded_unix_us":1787932601423927,"recorded_utc":"2026-08-28T15:56:41.423927Z","schema_version":"nrrf810.exchange_authored_interactive_closure.v1","source_chain_continuous":true,"source_event":"order_deleted","source_event_id":"00065a1d-7f96-7470-0001-000102000020","source_event_id_unique":true,"source_pre_event_id":"00065a1d-7f96-7470-0000-000101000020","translation":"FOLD_RETURN_TO_ZERO","unfold_event_id":"00065a1d-7f96-7470-0000-000101000020","zero_hair":true}
{"channel":"live_orders_ethbtc","interaction_index":114,"natural_form":{"channel":"live_orders_ethbtc","order_id":"2044303879073795","order_subtype":5,"order_type":1},"natural_form_sha256":"2cd3ba6ea67ac5b5e19d37dcc590f76804268b65e1db3f2caff9a2ce8c770ef4","order_source":"orderbook","orders_submitted":0,"presentation":{"amount":"0.60450317","amount_traded":"0","microtimestamp":"1787932601384000","price":"0.03160300"},"previous_record_hash":"17e56419c97f99931153b72edcaa70742d3e726ecbe679ad7afc054344abcc4d","profit_assessment":null,"record_hash":"510e67e1a36b63aa15050072a41823580a3e8eb7c615a1a4f2555f49d1f0171e","recorded_unix_us":1787932601424063,"recorded_utc":"2026-08-28T15:56:41.424063Z","schema_version":"nrrf810.exchange_authored_interactive_closure.v1","source_chain_continuous":true,"source_event":"order_created","source_event_id":"00065a1d-7f96-7c40-0000-001103000020","source_event_id_unique":true,"source_pre_event_id":"00065a1d-7f95-ad38-0002-001102000020","translation":"UNFOLD_TO_INF","unfold_event_id":null,"zero_hair":false}
{"channel":"live_orders_ethbtc","interaction_index":115,"natural_form":{"channel":"live_orders_ethbtc","order_id":"2044303879073800","order_subtype":5,"order_type":1},"natural_form_sha256":"165f4f8704a07837f48a2e4fd6c1f2bfd7936a9ff10a30b76998179d112a3a91","order_source":"orderbook","orders_submitted":0,"presentation":{"amount":"4.02232075","amount_traded":"0","microtimestamp":"1787932601385000","price":"0.03165997"},"previous_record_hash":"510e67e1a36b63aa15050072a41823580a3e8eb7c615a1a4f2555f49d1f0171e","profit_assessment":null,"record_hash":"e3465388c3a2bf03d29e527afc40f787428d6125f9d85a2f2e049e7c6fe8925e","recorded_unix_us":1787932601424091,"recorded_utc":"2026-08-28T15:56:41.424091Z","schema_version":"nrrf810.exchange_authored_interactive_closure.v1","source_chain_continuous":true,"source_event":"order_created","source_event_id":"00065a1d-7f96-8028-0000-001100000020","source_event_id_unique":true,"source_pre_event_id":"00065a1d-7f96-7c40-0000-001103000020","translation":"UNFOLD_TO_INF","unfold_event_id":null,"zero_hair":false}
{"channel":"live_orders_btcusd","interaction_index":116,"natural_form":{"channel":"live_orders_btcusd","order_id":"2044303878291459","order_subtype":5,"order_type":1},"natural_form_sha256":"9f534bf63c29802d8377806862b393a3bd27a349a4ac768932641d6b59dd16b9","order_source":"orderbook","orders_submitted":0,"presentation":{"amount":"0.10000000","amount_traded":"0","microtimestamp":"1787932601393000","price":"78523.24"},"previous_record_hash":"e3465388c3a2bf03d29e527afc40f787428d6125f9d85a2f2e049e7c6fe8925e","profit_assessment":null,"record_hash":"033af40a448a9d54a1049e5efd3c2ac965cf54611706265bd7e1f56ea35ac43f","recorded_unix_us":1787932601428314,"recorded_utc":"2026-08-28T15:56:41.428314Z","schema_version":"nrrf810.exchange_authored_interactive_closure.v1","source_chain_continuous":true,"source_event":"order_deleted","source_event_id":"00065a1d-7f96-9f68-0000-000103000020","source_event_id_unique":true,"source_pre_event_id":"00065a1d-7f96-7470-0001-000102000020","translation":"FOLD_RETURN_TO_ZERO","unfold_event_id":"00065a1d-7f93-9228-0000-000101000020","zero_hair":true}
{"channel":"live_orders_btcusd","interaction_index":117,"natural_form":{"channel":"live_orders_btcusd","order_id":"2044303879139328","order_subtype":5,"order_type":1},"natural_form_sha256":"c9adf170d35d2f75ae7172be9c9708740db6947dd2f0aef5f356cc9ea76b73e6","order_source":"orderbook","orders_submitted":0,"presentation":{"amount":"0.10000000","amount_traded":"0","microtimestamp":"1787932601400000","price":"78522.63"},"previous_record_hash":"033af40a448a9d54a1049e5efd3c2ac965cf54611706265bd7e1f56ea35ac43f","profit_assessment":null,"record_hash":"831c81f5a70ac997b8b4b40c48ba28010c2af19146baf66eecb0a151cfd09eeb","recorded_unix_us":1787932601441154,"recorded_utc":"2026-08-28T15:56:41.441154Z","schema_version":"nrrf810.exchange_authored_interactive_closure.v1","source_chain_continuous":true,"source_event":"order_created","source_event_id":"00065a1d-7f96-bac0-0000-000100000020","source_event_id_unique":true,"source_pre_event_id":"00065a1d-7f96-9f68-0000-000103000020","translation":"UNFOLD_TO_INF","unfold_event_id":null,"zero_hair":false}
{"channel":"live_orders_btcusd","interaction_index":118,"natural_form":{"channel":"live_orders_btcusd","order_id":"2044303879139328","order_subtype":5,"order_type":1},"natural_form_sha256":"c9adf170d35d2f75ae7172be9c9708740db6947dd2f0aef5f356cc9ea76b73e6","order_source":"orderbook","orders_submitted":0,"presentation":{"amount":"0.10000000","amount_traded":"0","microtimestamp":"1787932601400000","price":"78522.63"},"previous_record_hash":"831c81f5a70ac997b8b4b40c48ba28010c2af19146baf66eecb0a151cfd09eeb","profit_assessment":null,"record_hash":"cd2d73c17b221e5725f7af73d0c4dcb1e43ec591b00b92c79f0a2c1415176799","recorded_unix_us":1787932601441253,"recorded_utc":"2026-08-28T15:56:41.441253Z","schema_version":"nrrf810.exchange_authored_interactive_closure.v1","source_chain_continuous":true,"source_event":"order_deleted","source_event_id":"00065a1d-7f96-bac0-0001-000101000020","source_event_id_unique":true,"source_pre_event_id":"00065a1d-7f96-bac0-0000-000100000020","translation":"FOLD_RETURN_TO_ZERO","unfold_event_id":"00065a1d-7f96-bac0-0000-000100000020","zero_hair":true}
{"channel":"live_orders_ethbtc","interaction_index":119,"natural_form":{"channel":"live_orders_ethbtc","order_id":"2044303879147520","order_subtype":5,"order_type":1},"natural_form_sha256":"d9b8a3dcc939b920db32efa022f920f77aeea84331270a656ef8b8a5b87e470b","order_source":"orderbook","orders_submitted":0,"presentation":{"amount":"2.01386943","amount_traded":"0","microtimestamp":"1787932601403000","price":"0.03161840"},"previous_record_hash":"cd2d73c17b221e5725f7af73d0c4dcb1e43ec591b00b92c79f0a2c1415176799","profit_assessment":null,"record_hash":"7368e8ae0d1e0876aa65a4290a7d52057c336edb05e25355f563868610844667","recorded_unix_us":1787932601442281,"recorded_utc":"2026-08-28T15:56:41.442281Z","schema_version":"nrrf810.exchange_authored_interactive_closure.v1","source_chain_continuous":true,"source_event":"order_created","source_event_id":"00065a1d-7f96-c678-0000-001101000020","source_event_id_unique":true,"source_pre_event_id":"00065a1d-7f96-8028-0000-001100000020","translation":"UNFOLD_TO_INF","unfold_event_id":null,"zero_hair":false}
{"channel":"live_orders_ethbtc","interaction_index":120,"natural_form":{"channel":"live_orders_ethbtc","order_id":"2044303879155717","order_subtype":5,"order_type":1},"natural_form_sha256":"2502a0f483f223556f8a518f941bdb2ba482d1105dd977c32bab676efe054b4c","order_source":"orderbook","orders_submitted":0,"presentation":{"amount":"1.00740464","amount_traded":"0","microtimestamp":"1787932601404000","price":"0.03160452"},"previous_record_hash":"7368e8ae0d1e0876aa65a4290a7d52057c336edb05e25355f563868610844667","profit_assessment":null,"record_hash":"c9fbcaa6d6abd58e18584415bac3f9092ab8dbf916ac9873e4e43c93517ee658","recorded_unix_us":1787932601442347,"recorded_utc":"2026-08-28T15:56:41.442347Z","schema_version":"nrrf810.exchange_authored_interactive_closure.v1","source_chain_continuous":true,"source_event":"order_created","source_event_id":"00065a1d-7f96-ca60-0000-001102000020","source_event_id_unique":true,"source_pre_event_id":"00065a1d-7f96-c678-0000-001101000020","translation":"UNFOLD_TO_INF","unfold_event_id":null,"zero_hair":false}
{"channel":"live_orders_ethbtc","interaction_index":121,"natural_form":{"channel":"live_orders_ethbtc","order_id":"2044303879163906","order_subtype":5,"order_type":1},"natural_form_sha256":"abffb0ecbed071c5e8a4912659916075dbd8257930f93473f2bc48a98789a33d","order_source":"orderbook","orders_submitted":0,"presentation":{"amount":"3.02055629","amount_traded":"0","microtimestamp":"1787932601406000","price":"0.03162186"},"previous_record_hash":"c9fbcaa6d6abd58e18584415bac3f9092ab8dbf916ac9873e4e43c93517ee658","profit_assessment":null,"record_hash":"f87f2f32e14985fdea63086ce32703ca26ae40a870e9ca57d47132647dfd9f75","recorded_unix_us":1787932601442415,"recorded_utc":"2026-08-28T15:56:41.442415Z","schema_version":"nrrf810.exchange_authored_interactive_closure.v1","source_chain_continuous":true,"source_event":"order_created","source_event_id":"00065a1d-7f96-d230-0000-001103000020","source_event_id_unique":true,"source_pre_event_id":"00065a1d-7f96-ca60-0000-001102000020","translation":"UNFOLD_TO_INF","unfold_event_id":null,"zero_hair":false}
{"channel":"live_orders_ethbtc","interaction_index":122,"natural_form":{"channel":"live_orders_ethbtc","order_id":"2044303879176196","order_subtype":5,"order_type":0},"natural_form_sha256":"48825783a9ae2d02d93f38d1110f2549d91cb149918ab7b0cbc1a836d133dc27","order_source":"orderbook","orders_submitted":0,"presentation":{"amount":"1.00801353","amount_traded":"0","microtimestamp":"1787932601409000","price":"0.03158534"},"previous_record_hash":"f87f2f32e14985fdea63086ce32703ca26ae40a870e9ca57d47132647dfd9f75","profit_assessment":null,"record_hash":"3ade8d534c88c6eebea26454dbb6a1c624f77e0c5bbf35dc298a91899504cb11","recorded_unix_us":1787932601442469,"recorded_utc":"2026-08-28T15:56:41.442469Z","schema_version":"nrrf810.exchange_authored_interactive_closure.v1","source_chain_continuous":true,"source_event":"order_created","source_event_id":"00065a1d-7f96-dde8-0000-001100000020","source_event_id_unique":true,"source_pre_event_id":"00065a1d-7f96-d230-0000-001103000020","translation":"UNFOLD_TO_INF","unfold_event_id":null,"zero_hair":false}
{"channel":"live_orders_ethbtc","interaction_index":123,"natural_form":{"channel":"live_orders_ethbtc","order_id":"2044303879176203","order_subtype":5,"order_type":0},"natural_form_sha256":"bbf2bfb8bfd93ed3eea20bf34393738d18813251452933e567c8a7e76aebe6e5","order_source":"orderbook","orders_submitted":0,"presentation":{"amount":"2.01629689","amount_traded":"0","microtimestamp":"1787932601410000","price":"0.03157941"},"previous_record_hash":"3ade8d534c88c6eebea26454dbb6a1c624f77e0c5bbf35dc298a91899504cb11","profit_assessment":null,"record_hash":"cef15dd5766ab6e22f742c95121ed280b6d842d9ed6052ab1adc21c337a0fb7f","recorded_unix_us":1787932601443889,"recorded_utc":"2026-08-28T15:56:41.443889Z","schema_version":"nrrf810.exchange_authored_interactive_closure.v1","source_chain_continuous":true,"source_event":"order_created","source_event_id":"00065a1d-7f96-e1d0-0000-001101000020","source_event_id_unique":true,"source_pre_event_id":"00065a1d-7f96-dde8-0000-001100000020","translation":"UNFOLD_TO_INF","unfold_event_id":null,"zero_hair":false}
{"channel":"live_orders_ethbtc","interaction_index":124,"natural_form":{"channel":"live_orders_ethbtc","order_id":"2044303879180296","order_subtype":5,"order_type":0},"natural_form_sha256":"b502354ad56b0985f11ff50454ad9b95303c954f937a3aa7073cb83f1eca5cb2","order_source":"orderbook","orders_submitted":0,"presentation":{"amount":"0.60481990","amount_traded":"0","microtimestamp":"1787932601411000","price":"0.03158573"},"previous_record_hash":"cef15dd5766ab6e22f742c95121ed280b6d842d9ed6052ab1adc21c337a0fb7f","profit_assessment":null,"record_hash":"37d9d755e96e42ab1e7efa1e1c48fc331999a4a1d5fab13739be6c9516af0b37","recorded_unix_us":1787932601443905,"recorded_utc":"2026-08-28T15:56:41.443905Z","schema_version":"nrrf810.exchange_authored_interactive_closure.v1","source_chain_continuous":true,"source_event":"order_created","source_event_id":"00065a1d-7f96-e5b8-0000-001102000020","source_event_id_unique":true,"source_pre_event_id":"00065a1d-7f96-e1d0-0000-001101000020","translation":"UNFOLD_TO_INF","unfold_event_id":null,"zero_hair":false}
{"channel":"live_orders_ethbtc","interaction_index":125,"natural_form":{"channel":"live_orders_ethbtc","order_id":"2044303879184384","order_subtype":5,"order_type":0},"natural_form_sha256":"3e81e6e5c42dc17974b26a44d710b73041530cc0ef0d3efa665c4016090aeccd","order_source":"orderbook","orders_submitted":0,"presentation":{"amount":"3.02537254","amount_traded":"0","microtimestamp":"1787932601411000","price":"0.03156999"},"previous_record_hash":"37d9d755e96e42ab1e7efa1e1c48fc331999a4a1d5fab13739be6c9516af0b37","profit_assessment":null,"record_hash":"81023fd45da5540fbbd5a0a8144f4075a696a5911276e3353ba7f4c4b995ff60","recorded_unix_us":1787932601443918,"recorded_utc":"2026-08-28T15:56:41.443918Z","schema_version":"nrrf810.exchange_authored_interactive_closure.v1","source_chain_continuous":true,"source_event":"order_created","source_event_id":"00065a1d-7f96-e5b8-0001-001103000020","source_event_id_unique":true,"source_pre_event_id":"00065a1d-7f96-e5b8-0000-001102000020","translation":"UNFOLD_TO_INF","unfold_event_id":null,"zero_hair":false}
{"channel":"live_orders_ethbtc","interaction_index":126,"natural_form":{"channel":"live_orders_ethbtc","order_id":"2044303879180296","order_subtype":5,"order_type":0},"natural_form_sha256":"b502354ad56b0985f11ff50454ad9b95303c954f937a3aa7073cb83f1eca5cb2","order_source":"orderbook","orders_submitted":0,"presentation":{"amount":"0.60481990","amount_traded":"0","microtimestamp":"1787932601411000","price":"0.03158573"},"previous_record_hash":"81023fd45da5540fbbd5a0a8144f4075a696a5911276e3353ba7f4c4b995ff60","profit_assessment":null,"record_hash":"0cfc40c6f4387df85abb99c5b90bd93725c117a68f8efc3191b71c058912928c","recorded_unix_us":1787932601443995,"recorded_utc":"2026-08-28T15:56:41.443995Z","schema_version":"nrrf810.exchange_authored_interactive_closure.v1","source_chain_continuous":true,"source_event":"order_deleted","source_event_id":"00065a1d-7f96-e5b8-0002-001100000020","source_event_id_unique":true,"source_pre_event_id":"00065a1d-7f96-e5b8-0001-001103000020","translation":"FOLD_RETURN_TO_ZERO","unfold_event_id":"00065a1d-7f96-e5b8-0000-001102000020","zero_hair":true}
{"channel":"live_orders_btcusd","interaction_index":127,"natural_form":{"channel":"live_orders_btcusd","order_id":"2044303879184389","order_subtype":5,"order_type":1},"natural_form_sha256":"c32ae464887f8870f52536d441683faefcda3aec65730a270b66504b82b71b38","order_source":"orderbook","orders_submitted":0,"presentation":{"amount":"0.10000000","amount_traded":"0","microtimestamp":"1787932601412000","price":"78522.74"},"previous_record_hash":"0cfc40c6f4387df85abb99c5b90bd93725c117a68f8efc3191b71c058912928c","profit_assessment":null,"record_hash":"50b0fd25f91e3a3e7cdd0c69dc5f413d7646ac91cc0143fac48f0e07ccb3f316","recorded_unix_us":1787932601444055,"recorded_utc":"2026-08-28T15:56:41.444055Z","schema_version":"nrrf810.exchange_authored_interactive_closure.v1","source_chain_continuous":true,"source_event":"order_created","source_event_id":"00065a1d-7f96-e9a0-0000-000102000020","source_event_id_unique":true,"source_pre_event_id":"00065a1d-7f96-bac0-0001-000101000020","translation":"UNFOLD_TO_INF","unfold_event_id":null,"zero_hair":false}
{"channel":"live_orders_btcusd","interaction_index":128,"natural_form":{"channel":"live_orders_btcusd","order_id":"2044303879188480","order_subtype":5,"order_type":1},"natural_form_sha256":"9b96b0954f675cdf4f47ce2e0ee324b8fa1f0052f82d7994fc7741a3b5f4535a","order_source":"orderbook","orders_submitted":0,"presentation":{"amount":"0.10000000","amount_traded":"0","microtimestamp":"1787932601412000","price":"78522.62"},"previous_record_hash":"50b0fd25f91e3a3e7cdd0c69dc5f413d7646ac91cc0143fac48f0e07ccb3f316","profit_assessment":null,"record_hash":"1556392996c09467772e09958227080d051fccf76523799b4ef810af1b006be5","recorded_unix_us":1787932601444069,"recorded_utc":"2026-08-28T15:56:41.444069Z","schema_version":"nrrf810.exchange_authored_interactive_closure.v1","source_chain_continuous":true,"source_event":"order_created","source_event_id":"00065a1d-7f96-e9a0-0001-000103000020","source_event_id_unique":true,"source_pre_event_id":"00065a1d-7f96-e9a0-0000-000102000020","translation":"UNFOLD_TO_INF","unfold_event_id":null,"zero_hair":false}
{"channel":"live_orders_btcusd","interaction_index":129,"natural_form":{"channel":"live_orders_btcusd","order_id":"2044303879188480","order_subtype":5,"order_type":1},"natural_form_sha256":"9b96b0954f675cdf4f47ce2e0ee324b8fa1f0052f82d7994fc7741a3b5f4535a","order_source":"orderbook","orders_submitted":0,"presentation":{"amount":"0.10000000","amount_traded":"0","microtimestamp":"1787932601412000","price":"78522.62"},"previous_record_hash":"1556392996c09467772e09958227080d051fccf76523799b4ef810af1b006be5","profit_assessment":null,"record_hash":"51b4118bb1f8af594af70fc5c231ca26535d315411c38dca76f70060e99ba674","recorded_unix_us":1787932601444081,"recorded_utc":"2026-08-28T15:56:41.444081Z","schema_version":"nrrf810.exchange_authored_interactive_closure.v1","source_chain_continuous":true,"source_event":"order_deleted","source_event_id":"00065a1d-7f96-e9a0-0002-000100000020","source_event_id_unique":true,"source_pre_event_id":"00065a1d-7f96-e9a0-0001-000103000020","translation":"FOLD_RETURN_TO_ZERO","unfold_event_id":"00065a1d-7f96-e9a0-0001-000103000020","zero_hair":true}
{"channel":"live_orders_btcusd","interaction_index":130,"natural_form":{"channel":"live_orders_btcusd","order_id":"2044303878463488","order_subtype":5,"order_type":1},"natural_form_sha256":"a7b92b718b4b9181982d5c6052a4fc6e14cbc60065b244c5bdd9689ecefd7f68","order_source":"orderbook","orders_submitted":0,"presentation":{"amount":"0.10000000","amount_traded":"0","microtimestamp":"1787932601413000","price":"78523.14"},"previous_record_hash":"51b4118bb1f8af594af70fc5c231ca26535d315411c38dca76f70060e99ba674","profit_assessment":null,"record_hash":"61e69bceb8870c6f47baf039ab442be00b1577ac9c006be8c7bab550185a84d4","recorded_unix_us":1787932601455701,"recorded_utc":"2026-08-28T15:56:41.455701Z","schema_version":"nrrf810.exchange_authored_interactive_closure.v1","source_chain_continuous":true,"source_event":"order_deleted","source_event_id":"00065a1d-7f96-ed88-0000-000101000020","source_event_id_unique":true,"source_pre_event_id":"00065a1d-7f96-e9a0-0002-000100000020","translation":"FOLD_RETURN_TO_ZERO","unfold_event_id":"00065a1d-7f94-3638-0000-000103000020","zero_hair":true}
{"channel":"live_orders_ethbtc","interaction_index":131,"natural_form":{"channel":"live_orders_ethbtc","order_id":"2044303879233536","order_subtype":5,"order_type":0},"natural_form_sha256":"21a9144de3ec4f03c11559e0277c2665cb96b08f66cb7a143e916f07cf24cc2a","order_source":"orderbook","orders_submitted":0,"presentation":{"amount":"4.03662068","amount_traded":"0","microtimestamp":"1787932601423000","price":"0.03154857"},"previous_record_hash":"61e69bceb8870c6f47baf039ab442be00b1577ac9c006be8c7bab550185a84d4","profit_assessment":null,"record_hash":"6793353eb3c5801ff4273302bb7c41d4d2fdc0a5f8c292ff587a320818c761e3","recorded_unix_us":1787932601457679,"recorded_utc":"2026-08-28T15:56:41.457679Z","schema_version":"nrrf810.exchange_authored_interactive_closure.v1","source_chain_continuous":true,"source_event":"order_created","source_event_id":"00065a1d-7f97-1498-0000-001101000020","source_event_id_unique":true,"source_pre_event_id":"00065a1d-7f96-e5b8-0002-001100000020","translation":"UNFOLD_TO_INF","unfold_event_id":null,"zero_hair":false}
{"channel":"live_orders_btcusd","interaction_index":132,"natural_form":{"channel":"live_orders_btcusd","order_id":"2044303879241730","order_subtype":5,"order_type":1},"natural_form_sha256":"af69d7049695141aa724513145f886aa02707e40dc3af73a6f5236f75a44c32a","order_source":"orderbook","orders_submitted":0,"presentation":{"amount":"0.06367563","amount_traded":"0","microtimestamp":"1787932601425000","price":"78522.98"},"previous_record_hash":"6793353eb3c5801ff4273302bb7c41d4d2fdc0a5f8c292ff587a320818c761e3","profit_assessment":null,"record_hash":"fde0877d4d1516dd866f067a9e7f00d5f253021960eda4c4d1c6b1e123e71e9e","recorded_unix_us":1787932601457759,"recorded_utc":"2026-08-28T15:56:41.457759Z","schema_version":"nrrf810.exchange_authored_interactive_closure.v1","source_chain_continuous":true,"source_event":"order_created","source_event_id":"00065a1d-7f97-1c68-0000-000102000020","source_event_id_unique":true,"source_pre_event_id":"00065a1d-7f96-ed88-0000-000101000020","translation":"UNFOLD_TO_INF","unfold_event_id":null,"zero_hair":false}
{"channel":"live_orders_btcusd","interaction_index":133,"natural_form":{"channel":"live_orders_btcusd","order_id":"2044303879249922","order_subtype":5,"order_type":0},"natural_form_sha256":"ec461b943e4cb0cbcaecde5c5ac870abba356d82b9584c51412b404b524fdba5","order_source":"orderbook","orders_submitted":0,"presentation":{"amount":"0.00140266","amount_traded":"0","microtimestamp":"1787932601428000","price":"70670.37"},"previous_record_hash":"fde0877d4d1516dd866f067a9e7f00d5f253021960eda4c4d1c6b1e123e71e9e","profit_assessment":null,"record_hash":"bb389d6d453a1c201881397785998e00f4256fb432c541dc7cbf5e06ad6bbc93","recorded_unix_us":1787932601457773,"recorded_utc":"2026-08-28T15:56:41.457773Z","schema_version":"nrrf810.exchange_authored_interactive_closure.v1","source_chain_continuous":true,"source_event":"order_created","source_event_id":"00065a1d-7f97-2820-0000-000103000020","source_event_id_unique":true,"source_pre_event_id":"00065a1d-7f97-1c68-0000-000102000020","translation":"UNFOLD_TO_INF","unfold_event_id":null,"zero_hair":false}
{"channel":"live_orders_btcusd","interaction_index":134,"natural_form":{"channel":"live_orders_btcusd","order_id":"2044303878602766","order_subtype":5,"order_type":0},"natural_form_sha256":"38686e9776951fa1f86e67b4657597fb595e4b5a05c511aa70a1772b800697b7","order_source":"orderbook","orders_submitted":0,"presentation":{"amount":"0.00140266","amount_traded":"0","microtimestamp":"1787932601438000","price":"70670.37"},"previous_record_hash":"bb389d6d453a1c201881397785998e00f4256fb432c541dc7cbf5e06ad6bbc93","profit_assessment":null,"record_hash":"0074d49f9db16528ae59b99dd82ddb66aa8538bfb0f836f34ba0e18e46e78ae1","recorded_unix_us":1787932601482247,"recorded_utc":"2026-08-28T15:56:41.482247Z","schema_version":"nrrf810.exchange_authored_interactive_closure.v1","source_chain_continuous":true,"source_event":"order_deleted","source_event_id":"00065a1d-7f97-4f30-0000-000100000020","source_event_id_unique":true,"source_pre_event_id":"00065a1d-7f97-2820-0000-000103000020","translation":"FOLD_RETURN_TO_ZERO","unfold_event_id":"00065a1d-7f94-bef0-0000-000102000020","zero_hair":true}
{"channel":"live_orders_btcusd","interaction_index":135,"natural_form":{"channel":"live_orders_btcusd","order_id":"2044303879303170","order_subtype":5,"order_type":1},"natural_form_sha256":"b89d707a74a0c459ff3ea76895249c32fea7bb59a287988dd5faeaf1aee00f68","order_source":"orderbook","orders_submitted":0,"presentation":{"amount":"0.10000000","amount_traded":"0","microtimestamp":"1787932601440000","price":"78522.63"},"previous_record_hash":"0074d49f9db16528ae59b99dd82ddb66aa8538bfb0f836f34ba0e18e46e78ae1","profit_assessment":null,"record_hash":"b163931fc8ff0e2737281e7d33b83d411fb5847980c1824b686b4eaf49ec0147","recorded_unix_us":1787932601482436,"recorded_utc":"2026-08-28T15:56:41.482436Z","schema_version":"nrrf810.exchange_authored_interactive_closure.v1","source_chain_continuous":true,"source_event":"order_created","source_event_id":"00065a1d-7f97-5700-0000-000101000020","source_event_id_unique":true,"source_pre_event_id":"00065a1d-7f97-4f30-0000-000100000020","translation":"UNFOLD_TO_INF","unfold_event_id":null,"zero_hair":false}
{"channel":"live_orders_btcusd","interaction_index":136,"natural_form":{"channel":"live_orders_btcusd","order_id":"2044303879303170","order_subtype":5,"order_type":1},"natural_form_sha256":"b89d707a74a0c459ff3ea76895249c32fea7bb59a287988dd5faeaf1aee00f68","order_source":"orderbook","orders_submitted":0,"presentation":{"amount":"0.10000000","amount_traded":"0","microtimestamp":"1787932601440000","price":"78522.63"},"previous_record_hash":"b163931fc8ff0e2737281e7d33b83d411fb5847980c1824b686b4eaf49ec0147","profit_assessment":null,"record_hash":"8d89fe7572734169237d6fcfd2b91245337782ee66236548e7e45ceb85e3222c","recorded_unix_us":1787932601482472,"recorded_utc":"2026-08-28T15:56:41.482472Z","schema_version":"nrrf810.exchange_authored_interactive_closure.v1","source_chain_continuous":true,"source_event":"order_deleted","source_event_id":"00065a1d-7f97-5700-0001-000102000020","source_event_id_unique":true,"source_pre_event_id":"00065a1d-7f97-5700-0000-000101000020","translation":"FOLD_RETURN_TO_ZERO","unfold_event_id":"00065a1d-7f97-5700-0000-000101000020","zero_hair":true}
{"channel":"live_orders_btcusd","interaction_index":137,"natural_form":{"channel":"live_orders_btcusd","order_id":"2044303879307268","order_subtype":5,"order_type":1},"natural_form_sha256":"b9afc72ec64dc0a184e838cef54822a68a6dc8055f7b944da066ee0c85f6bed3","order_source":"orderbook","orders_submitted":0,"presentation":{"amount":"0.10000000","amount_traded":"0","microtimestamp":"1787932601442000","price":"78522.62"},"previous_record_hash":"8d89fe7572734169237d6fcfd2b91245337782ee66236548e7e45ceb85e3222c","profit_assessment":null,"record_hash":"2973affb96b24db110f98c8f87eeb80c0d606706addbcc020944cba1419767e9","recorded_unix_us":1787932601482493,"recorded_utc":"2026-08-28T15:56:41.482493Z","schema_version":"nrrf810.exchange_authored_interactive_closure.v1","source_chain_continuous":true,"source_event":"order_created","source_event_id":"00065a1d-7f97-5ed0-0000-000103000020","source_event_id_unique":true,"source_pre_event_id":"00065a1d-7f97-5700-0001-000102000020","translation":"UNFOLD_TO_INF","unfold_event_id":null,"zero_hair":false}
{"channel":"live_orders_btcusd","interaction_index":138,"natural_form":{"channel":"live_orders_btcusd","order_id":"2044303879307268","order_subtype":5,"order_type":1},"natural_form_sha256":"b9afc72ec64dc0a184e838cef54822a68a6dc8055f7b944da066ee0c85f6bed3","order_source":"orderbook","orders_submitted":0,"presentation":{"amount":"0.10000000","amount_traded":"0","microtimestamp":"1787932601442000","price":"78522.62"},"previous_record_hash":"2973affb96b24db110f98c8f87eeb80c0d606706addbcc020944cba1419767e9","profit_assessment":null,"record_hash":"477245bed8415df4191f61dc1a0d98a7138b9ea1ddb1b2b3297029630b83210f","recorded_unix_us":1787932601482509,"recorded_utc":"2026-08-28T15:56:41.482509Z","schema_version":"nrrf810.exchange_authored_interactive_closure.v1","source_chain_continuous":true,"source_event":"order_deleted","source_event_id":"00065a1d-7f97-5ed0-0001-000100000020","source_event_id_unique":true,"source_pre_event_id":"00065a1d-7f97-5ed0-0000-000103000020","translation":"FOLD_RETURN_TO_ZERO","unfold_event_id":"00065a1d-7f97-5ed0-0000-000103000020","zero_hair":true}
{"channel":"live_orders_ethusd","interaction_index":139,"natural_form":{"channel":"live_orders_ethusd","order_id":"2044303876800512","order_subtype":5,"order_type":1},"natural_form_sha256":"4907d508c03add025beee9e3094e4717087f68e855720ebe2086d7c3bc6c363b","order_source":"orderbook","orders_submitted":0,"presentation":{"amount":"1.732162","amount_traded":"0","microtimestamp":"1787932601447000","price":"2481.02"},"previous_record_hash":"477245bed8415df4191f61dc1a0d98a7138b9ea1ddb1b2b3297029630b83210f","profit_assessment":null,"record_hash":"4a0c2365575d49fde1e871e6a73fbaaa152ee1528d63aeaebde4fffc62e14e57","recorded_unix_us":1787932601485048,"recorded_utc":"2026-08-28T15:56:41.485048Z","schema_version":"nrrf810.exchange_authored_interactive_closure.v1","source_chain_continuous":true,"source_event":"order_deleted","source_event_id":"00065a1d-7f97-7258-0000-001202000020","source_event_id_unique":true,"source_pre_event_id":"00065a1d-7f96-39d8-0000-001201000020","translation":"PARTIAL_PRIOR_UNFOLD","unfold_event_id":null,"zero_hair":false}
{"channel":"live_orders_ethusd","interaction_index":140,"natural_form":{"channel":"live_orders_ethusd","order_id":"2044303879327745","order_subtype":5,"order_type":1},"natural_form_sha256":"635a0604ce4e0660296c32ac8a46593d96cc55b91c0af004e7dd6b01d7e85063","order_source":"orderbook","orders_submitted":0,"presentation":{"amount":"1.732162","amount_traded":"0","microtimestamp":"1787932601447000","price":"2481.02"},"previous_record_hash":"4a0c2365575d49fde1e871e6a73fbaaa152ee1528d63aeaebde4fffc62e14e57","profit_assessment":null,"record_hash":"fde6bd2dffabf15ae2c64bce59db4b71296be0c9803bf3192e20d9148d246c36","recorded_unix_us":1787932601485073,"recorded_utc":"2026-08-28T15:56:41.485073Z","schema_version":"nrrf810.exchange_authored_interactive_closure.v1","source_chain_continuous":true,"source_event":"order_created","source_event_id":"00065a1d-7f97-7258-0001-001203000020","source_event_id_unique":true,"source_pre_event_id":"00065a1d-7f97-7258-0000-001202000020","translation":"UNFOLD_TO_INF","unfold_event_id":null,"zero_hair":false}
{"channel":"live_orders_btcusd","interaction_index":141,"natural_form":{"channel":"live_orders_btcusd","order_id":"2044303879331844","order_subtype":5,"order_type":1},"natural_form_sha256":"fe23d4ba7ccb1ad354aced06d6e211e930ba6cfbc75d8357d751d399979af648","order_source":"orderbook","orders_submitted":0,"presentation":{"amount":"0.06367384","amount_traded":"0","microtimestamp":"1787932601447000","price":"78525.19"},"previous_record_hash":"fde6bd2dffabf15ae2c64bce59db4b71296be0c9803bf3192e20d9148d246c36","profit_assessment":null,"record_hash":"51c24938479da8256b665266cac8c974336563608cc929f90a1bb0a7b81863cf","recorded_unix_us":1787932601485089,"recorded_utc":"2026-08-28T15:56:41.485089Z","schema_version":"nrrf810.exchange_authored_interactive_closure.v1","source_chain_continuous":true,"source_event":"order_created","source_event_id":"00065a1d-7f97-7258-0000-000101000020","source_event_id_unique":true,"source_pre_event_id":"00065a1d-7f97-5ed0-0001-000100000020","translation":"UNFOLD_TO_INF","unfold_event_id":null,"zero_hair":false}
{"channel":"live_orders_btcusd","interaction_index":142,"natural_form":{"channel":"live_orders_btcusd","order_id":"2044303879331849","order_subtype":5,"order_type":1},"natural_form_sha256":"d72be876c85d9d795e6188bf8c5232848e217e7781792d69beceb321a39f92e0","order_source":"orderbook","orders_submitted":0,"presentation":{"amount":"0.25467128","amount_traded":"0","microtimestamp":"1787932601448000","price":"78532.61"},"previous_record_hash":"51c24938479da8256b665266cac8c974336563608cc929f90a1bb0a7b81863cf","profit_assessment":null,"record_hash":"57f877e994a6d39665ba8edc80210fb34d50d3f6261bb134658950fe2bf5396f","recorded_unix_us":1787932601485170,"recorded_utc":"2026-08-28T15:56:41.485170Z","schema_version":"nrrf810.exchange_authored_interactive_closure.v1","source_chain_continuous":true,"source_event":"order_created","source_event_id":"00065a1d-7f97-7640-0000-000102000020","source_event_id_unique":true,"source_pre_event_id":"00065a1d-7f97-7258-0000-000101000020","translation":"UNFOLD_TO_INF","unfold_event_id":null,"zero_hair":false}
{"channel":"live_orders_btcusd","interaction_index":143,"natural_form":{"channel":"live_orders_btcusd","order_id":"2044303879335936","order_subtype":5,"order_type":1},"natural_form_sha256":"71b2fb5d1acee2ee116d5df16738c22a6a81e8b0e3c8bb65fb8f4725d24ddc18","order_source":"orderbook","orders_submitted":0,"presentation":{"amount":"0.25466146","amount_traded":"0","microtimestamp":"1787932601448000","price":"78535.64"},"previous_record_hash":"57f877e994a6d39665ba8edc80210fb34d50d3f6261bb134658950fe2bf5396f","profit_assessment":null,"record_hash":"bec083d7e1dbd1c594257f6106d56d839d4c51913280df5f22e9dd305523c8d0","recorded_unix_us":1787932601485262,"recorded_utc":"2026-08-28T15:56:41.485262Z","schema_version":"nrrf810.exchange_authored_interactive_closure.v1","source_chain_continuous":true,"source_event":"order_created","source_event_id":"00065a1d-7f97-7640-0001-000103000020","source_event_id_unique":true,"source_pre_event_id":"00065a1d-7f97-7640-0000-000102000020","translation":"UNFOLD_TO_INF","unfold_event_id":null,"zero_hair":false}
{"channel":"live_orders_btcusd","interaction_index":144,"natural_form":{"channel":"live_orders_btcusd","order_id":"2044303879340046","order_subtype":5,"order_type":1},"natural_form_sha256":"6ff070f89d23e86278e796c005dc8c7c1e700f4ba32fa0d6ce03393ea7238cff","order_source":"orderbook","orders_submitted":0,"presentation":{"amount":"12.70451953","amount_traded":"0","microtimestamp":"1787932601450000","price":"78712.15"},"previous_record_hash":"bec083d7e1dbd1c594257f6106d56d839d4c51913280df5f22e9dd305523c8d0","profit_assessment":null,"record_hash":"b857fb407efa126851abc83bffaf7c902e88c9558427793a916886f08df1cdb9","recorded_unix_us":1787932601485332,"recorded_utc":"2026-08-28T15:56:41.485332Z","schema_version":"nrrf810.exchange_authored_interactive_closure.v1","source_chain_continuous":true,"source_event":"order_created","source_event_id":"00065a1d-7f97-7e10-0000-000100000020","source_event_id_unique":true,"source_pre_event_id":"00065a1d-7f97-7640-0001-000103000020","translation":"UNFOLD_TO_INF","unfold_event_id":null,"zero_hair":false}
{"channel":"live_orders_btcusd","interaction_index":145,"natural_form":{"channel":"live_orders_btcusd","order_id":"2044303879340045","order_subtype":5,"order_type":1},"natural_form_sha256":"f9d09e58822611588bc4de63fec5b66e68f4b3861d702003bbf1f84d7fd5fe9f","order_source":"orderbook","orders_submitted":0,"presentation":{"amount":"1.27209222","amount_traded":"0","microtimestamp":"1787932601450000","price":"78610.66"},"previous_record_hash":"b857fb407efa126851abc83bffaf7c902e88c9558427793a916886f08df1cdb9","profit_assessment":null,"record_hash":"7163af5eaafaa36f49e40a72e56433b0f56c921a44004f1ee120877cd80dc5f4","recorded_unix_us":1787932601485354,"recorded_utc":"2026-08-28T15:56:41.485354Z","schema_version":"nrrf810.exchange_authored_interactive_closure.v1","source_chain_continuous":true,"source_event":"order_created","source_event_id":"00065a1d-7f97-7e10-0001-000101000020","source_event_id_unique":true,"source_pre_event_id":"00065a1d-7f97-7e10-0000-000100000020","translation":"UNFOLD_TO_INF","unfold_event_id":null,"zero_hair":false}
{"channel":"live_orders_btcusd","interaction_index":146,"natural_form":{"channel":"live_orders_btcusd","order_id":"2044303879344135","order_subtype":4,"order_type":1},"natural_form_sha256":"662ed3d0cf75ce608a2b572f37f6fb72758e81c2ac8b265907b002f03017c374","order_source":"orderbook","orders_submitted":0,"presentation":{"amount":"0.00006244","amount_traded":"0","microtimestamp":"1787932601450000","price":"80878.00"},"previous_record_hash":"7163af5eaafaa36f49e40a72e56433b0f56c921a44004f1ee120877cd80dc5f4","profit_assessment":null,"record_hash":"7dc97ff9430a52a2032b18e5a8a0b12d9bcb8c4cd6674bde401e7b38302ca74b","recorded_unix_us":1787932601485370,"recorded_utc":"2026-08-28T15:56:41.485370Z","schema_version":"nrrf810.exchange_authored_interactive_closure.v1","source_chain_continuous":true,"source_event":"order_created","source_event_id":"00065a1d-7f97-7e10-0002-000102000020","source_event_id_unique":true,"source_pre_event_id":"00065a1d-7f97-7e10-0001-000101000020","translation":"UNFOLD_TO_INF","unfold_event_id":null,"zero_hair":false}
{"channel":"live_orders_btcusd","interaction_index":147,"natural_form":{"channel":"live_orders_btcusd","order_id":"2044303879344135","order_subtype":4,"order_type":1},"natural_form_sha256":"662ed3d0cf75ce608a2b572f37f6fb72758e81c2ac8b265907b002f03017c374","order_source":"orderbook","orders_submitted":0,"presentation":{"amount":"0.00006244","amount_traded":"0","microtimestamp":"1787932601450000","price":"80878.00"},"previous_record_hash":"7dc97ff9430a52a2032b18e5a8a0b12d9bcb8c4cd6674bde401e7b38302ca74b","profit_assessment":null,"record_hash":"b9768ff59258198f1334e8b808080c0ced99c9ca8ff75b3c6715c15b61883646","recorded_unix_us":1787932601485456,"recorded_utc":"2026-08-28T15:56:41.485456Z","schema_version":"nrrf810.exchange_authored_interactive_closure.v1","source_chain_continuous":true,"source_event":"order_deleted","source_event_id":"00065a1d-7f97-7e10-0003-000103000020","source_event_id_unique":true,"source_pre_event_id":"00065a1d-7f97-7e10-0002-000102000020","translation":"FOLD_RETURN_TO_ZERO","unfold_event_id":"00065a1d-7f97-7e10-0002-000102000020","zero_hair":true}
{"channel":"live_orders_btcusd","interaction_index":148,"natural_form":{"channel":"live_orders_btcusd","order_id":"2044303879352320","order_subtype":5,"order_type":1},"natural_form_sha256":"79ca6e9d65bbb1f223266644ec14c5cadafd6777f437e4c75ca0f7ab69bb666c","order_source":"orderbook","orders_submitted":0,"presentation":{"amount":"1.26970017","amount_traded":"0","microtimestamp":"1787932601452000","price":"78758.76"},"previous_record_hash":"b9768ff59258198f1334e8b808080c0ced99c9ca8ff75b3c6715c15b61883646","profit_assessment":null,"record_hash":"92a74beccc21f132139d801056bd2bf90735482c5a2e6d0ddd80f2b0bb860566","recorded_unix_us":1787932601485474,"recorded_utc":"2026-08-28T15:56:41.485474Z","schema_version":"nrrf810.exchange_authored_interactive_closure.v1","source_chain_continuous":true,"source_event":"order_created","source_event_id":"00065a1d-7f97-85e0-0000-000100000020","source_event_id_unique":true,"source_pre_event_id":"00065a1d-7f97-7e10-0003-000103000020","translation":"UNFOLD_TO_INF","unfold_event_id":null,"zero_hair":false}
{"channel":"live_orders_btcusd","interaction_index":149,"natural_form":{"channel":"live_orders_btcusd","order_id":"2044303879352323","order_subtype":5,"order_type":0},"natural_form_sha256":"62638184565c19c96625d905454a91fcb379a73f7f78746e04ee0902d0c1ff27","order_source":"orderbook","orders_submitted":0,"presentation":{"amount":"0.67500000","amount_traded":"0","microtimestamp":"1787932601453000","price":"78487.36"},"previous_record_hash":"92a74beccc21f132139d801056bd2bf90735482c5a2e6d0ddd80f2b0bb860566","profit_assessment":null,"record_hash":"9923c8c0e648f7c2ec5f113cf9d577adf314e085ee93d5264234bbf4997f345a","recorded_unix_us":1787932601485546,"recorded_utc":"2026-08-28T15:56:41.485546Z","schema_version":"nrrf810.exchange_authored_interactive_closure.v1","source_chain_continuous":true,"source_event":"order_created","source_event_id":"00065a1d-7f97-89c8-0000-000101000020","source_event_id_unique":true,"source_pre_event_id":"00065a1d-7f97-85e0-0000-000100000020","translation":"UNFOLD_TO_INF","unfold_event_id":null,"zero_hair":false}
{"channel":"live_orders_btcusd","interaction_index":150,"natural_form":{"channel":"live_orders_btcusd","order_id":"2044303879356416","order_subtype":5,"order_type":1},"natural_form_sha256":"2687321c37d14fa88fa3224a39d3528944ef9aaf5f7e4fb6986e917bfe48b4ea","order_source":"orderbook","orders_submitted":0,"presentation":{"amount":"1.26840120","amount_traded":"0","microtimestamp":"1787932601453000","price":"78839.41"},"previous_record_hash":"9923c8c0e648f7c2ec5f113cf9d577adf314e085ee93d5264234bbf4997f345a","profit_assessment":null,"record_hash":"a0c19f5c646008fe7df06b41a8312feeffdb0eca37e86de76f6d9d033f2996f4","recorded_unix_us":1787932601485567,"recorded_utc":"2026-08-28T15:56:41.485567Z","schema_version":"nrrf810.exchange_authored_interactive_closure.v1","source_chain_continuous":true,"source_event":"order_created","source_event_id":"00065a1d-7f97-89c8-0001-000102000020","source_event_id_unique":true,"source_pre_event_id":"00065a1d-7f97-89c8-0000-000101000020","translation":"UNFOLD_TO_INF","unfold_event_id":null,"zero_hair":false}
{"channel":"live_orders_btcusd","interaction_index":151,"natural_form":{"channel":"live_orders_btcusd","order_id":"2044303879360514","order_subtype":4,"order_type":1},"natural_form_sha256":"227e121610f8f1c606ec94f58e051270b630b06558b32ad25904a682c6cc6b77","order_source":"orderbook","orders_submitted":0,"presentation":{"amount":"0.01500079","amount_traded":"0","microtimestamp":"1787932601454000","price":"78486.44"},"previous_record_hash":"a0c19f5c646008fe7df06b41a8312feeffdb0eca37e86de76f6d9d033f2996f4","profit_assessment":null,"record_hash":"003b931aac335dbd02fea886fbfd87acbee83c5d0dbe07629855579f31ed9619","recorded_unix_us":1787932601485702,"recorded_utc":"2026-08-28T15:56:41.485702Z","schema_version":"nrrf810.exchange_authored_interactive_closure.v1","source_chain_continuous":true,"source_event":"order_created","source_event_id":"00065a1d-7f97-8db0-0000-000103000020","source_event_id_unique":true,"source_pre_event_id":"00065a1d-7f97-89c8-0001-000102000020","translation":"UNFOLD_TO_INF","unfold_event_id":null,"zero_hair":false}
{"channel":"live_orders_btcusd","interaction_index":152,"natural_form":{"channel":"live_orders_btcusd","order_id":"2044303879360514","order_subtype":4,"order_type":1},"natural_form_sha256":"227e121610f8f1c606ec94f58e051270b630b06558b32ad25904a682c6cc6b77","order_source":"orderbook","orders_submitted":0,"presentation":{"amount":"0","amount_traded":"0.01500079","microtimestamp":"1787932601454000","price":"78522.63"},"previous_record_hash":"003b931aac335dbd02fea886fbfd87acbee83c5d0dbe07629855579f31ed9619","profit_assessment":null,"record_hash":"b61882f060b90cabc5544d2ac93efc42f484ce8edd945964852634d9a0b15de3","recorded_unix_us":1787932601485718,"recorded_utc":"2026-08-28T15:56:41.485718Z","schema_version":"nrrf810.exchange_authored_interactive_closure.v1","source_chain_continuous":true,"source_event":"order_deleted","source_event_id":"00065a1d-7f97-8db0-0001-000100000020","source_event_id_unique":true,"source_pre_event_id":"00065a1d-7f97-8db0-0000-000103000020","translation":"FOLD_RETURN_TO_ZERO","unfold_event_id":"00065a1d-7f97-8db0-0000-000103000020","zero_hair":true}
{"channel":"live_orders_btcusd","interaction_index":153,"natural_form":{"channel":"live_orders_btcusd","order_id":"2044303819288576","order_subtype":5,"order_type":0},"natural_form_sha256":"b51e0d9ee88623fe1518775a4ba92dfe00068c9e09d56b98689f2ebeed123750","order_source":"orderbook","orders_submitted":0,"presentation":{"amount":"0.06013098","amount_traded":"0.01500079","microtimestamp":"1787932601454000","price":"78522.63"},"previous_record_hash":"b61882f060b90cabc5544d2ac93efc42f484ce8edd945964852634d9a0b15de3","profit_assessment":null,"record_hash":"6e32d506b6c2f1dbcf5d62aa49de8375013c8f9ab0f4397130e3410265c60b0f","recorded_unix_us":1787932601485732,"recorded_utc":"2026-08-28T15:56:41.485732Z","schema_version":"nrrf810.exchange_authored_interactive_closure.v1","source_chain_continuous":true,"source_event":"order_changed","source_event_id":"00065a1d-7f97-8db0-0002-000101000020","source_event_id_unique":true,"source_pre_event_id":"00065a1d-7f97-8db0-0001-000100000020","translation":"PARTIAL_PRIOR_UNFOLD","unfold_event_id":null,"zero_hair":false}
{"channel":"live_orders_btcusd","interaction_index":154,"natural_form":{"channel":"live_orders_btcusd","order_id":"2044303879360515","order_subtype":5,"order_type":1},"natural_form_sha256":"6da3ace946672bea5eff23e092952155a4dbb9974bbf78ea02fab821ab4ddb3e","order_source":"orderbook","orders_submitted":0,"presentation":{"amount":"0.10000000","amount_traded":"0","microtimestamp":"1787932601454000","price":"78522.64"},"previous_record_hash":"6e32d506b6c2f1dbcf5d62aa49de8375013c8f9ab0f4397130e3410265c60b0f","profit_assessment":null,"record_hash":"c31bab90ced0f7032c70bf2705ee72af62eddc3638c5739041fcd68df6e189cd","recorded_unix_us":1787932601485746,"recorded_utc":"2026-08-28T15:56:41.485746Z","schema_version":"nrrf810.exchange_authored_interactive_closure.v1","source_chain_continuous":true,"source_event":"order_created","source_event_id":"00065a1d-7f97-8db0-0003-000102000020","source_event_id_unique":true,"source_pre_event_id":"00065a1d-7f97-8db0-0002-000101000020","translation":"UNFOLD_TO_INF","unfold_event_id":null,"zero_hair":false}
{"channel":"live_orders_btcusd","interaction_index":155,"natural_form":{"channel":"live_orders_btcusd","order_id":"2044303879360520","order_subtype":5,"order_type":0},"natural_form_sha256":"093c474d972995c8f753bf025a2a472acd22d718c406ebec90eb813e7ad7b3e7","order_source":"orderbook","orders_submitted":0,"presentation":{"amount":"0.06368219","amount_traded":"0","microtimestamp":"1787932601454000","price":"78514.87"},"previous_record_hash":"c31bab90ced0f7032c70bf2705ee72af62eddc3638c5739041fcd68df6e189cd","profit_assessment":null,"record_hash":"b1abc76a106d2a1804e2ea2204b14fb3c526e7c6a08d4df3d7894e5d3712a02c","recorded_unix_us":1787932601485759,"recorded_utc":"2026-08-28T15:56:41.485759Z","schema_version":"nrrf810.exchange_authored_interactive_closure.v1","source_chain_continuous":true,"source_event":"order_created","source_event_id":"00065a1d-7f97-8db0-0004-000103000020","source_event_id_unique":true,"source_pre_event_id":"00065a1d-7f97-8db0-0003-000102000020","translation":"UNFOLD_TO_INF","unfold_event_id":null,"zero_hair":false}
{"channel":"live_orders_btcusd","interaction_index":156,"natural_form":{"channel":"live_orders_btcusd","order_id":"2044303879360522","order_subtype":5,"order_type":0},"natural_form_sha256":"cd1c86be8baf49cab239b2192012cb36449ea86cdbd6c8715d1a936a3637acef","order_source":"orderbook","orders_submitted":0,"presentation":{"amount":"0.25476924","amount_traded":"0","microtimestamp":"1787932601455000","price":"78502.41"},"previous_record_hash":"b1abc76a106d2a1804e2ea2204b14fb3c526e7c6a08d4df3d7894e5d3712a02c","profit_assessment":null,"record_hash":"ebd3451a83f86b70a0effbdb8a2ee9bc8bbc4a8959a7a5de6888a4f07e555374","recorded_unix_us":1787932601485882,"recorded_utc":"2026-08-28T15:56:41.485882Z","schema_version":"nrrf810.exchange_authored_interactive_closure.v1","source_chain_continuous":true,"source_event":"order_created","source_event_id":"00065a1d-7f97-9198-0000-000100000020","source_event_id_unique":true,"source_pre_event_id":"00065a1d-7f97-8db0-0004-000103000020","translation":"UNFOLD_TO_INF","unfold_event_id":null,"zero_hair":false}
{"channel":"live_orders_btcusd","interaction_index":157,"natural_form":{"channel":"live_orders_btcusd","order_id":"2044303879364609","order_subtype":5,"order_type":0},"natural_form_sha256":"6fe8430574062210accbfb351e82c369bc35b11b26c9d4036cb7de4c1af8b639","order_source":"orderbook","orders_submitted":0,"presentation":{"amount":"0.25478772","amount_traded":"0","microtimestamp":"1787932601455000","price":"78496.71"},"previous_record_hash":"ebd3451a83f86b70a0effbdb8a2ee9bc8bbc4a8959a7a5de6888a4f07e555374","profit_assessment":null,"record_hash":"a6e9a9280018318026ea565317780cbb2e5cee62eadc7e650d20a05a1360d0e3","recorded_unix_us":1787932601485898,"recorded_utc":"2026-08-28T15:56:41.485898Z","schema_version":"nrrf810.exchange_authored_interactive_closure.v1","source_chain_continuous":true,"source_event":"order_created","source_event_id":"00065a1d-7f97-9198-0001-000101000020","source_event_id_unique":true,"source_pre_event_id":"00065a1d-7f97-9198-0000-000100000020","translation":"UNFOLD_TO_INF","unfold_event_id":null,"zero_hair":false}
{"channel":"live_orders_btcusd","interaction_index":158,"natural_form":{"channel":"live_orders_btcusd","order_id":"2044303879368706","order_subtype":5,"order_type":0},"natural_form_sha256":"bf12bf516e3729bb374cc370454310911955074ccc548185b67508bab7fca92c","order_source":"orderbook","orders_submitted":0,"presentation":{"amount":"1.27507828","amount_traded":"0","microtimestamp":"1787932601456000","price":"78426.55"},"previous_record_hash":"a6e9a9280018318026ea565317780cbb2e5cee62eadc7e650d20a05a1360d0e3","profit_assessment":null,"record_hash":"06a760a0c178b84c273eb26c042d16c55c0f8aab21539279b5bb09421ea6cd4b","recorded_unix_us":1787932601502634,"recorded_utc":"2026-08-28T15:56:41.502634Z","schema_version":"nrrf810.exchange_authored_interactive_closure.v1","source_chain_continuous":true,"source_event":"order_created","source_event_id":"00065a1d-7f97-9580-0000-000102000020","source_event_id_unique":true,"source_pre_event_id":"00065a1d-7f97-9198-0001-000101000020","translation":"UNFOLD_TO_INF","unfold_event_id":null,"zero_hair":false}
{"channel":"live_orders_btcusd","interaction_index":159,"natural_form":{"channel":"live_orders_btcusd","order_id":"2044303879360515","order_subtype":5,"order_type":1},"natural_form_sha256":"6da3ace946672bea5eff23e092952155a4dbb9974bbf78ea02fab821ab4ddb3e","order_source":"orderbook","orders_submitted":0,"presentation":{"amount":"0.10000000","amount_traded":"0","microtimestamp":"1787932601457000","price":"78522.64"},"previous_record_hash":"06a760a0c178b84c273eb26c042d16c55c0f8aab21539279b5bb09421ea6cd4b","profit_assessment":null,"record_hash":"1f86dc329232498abbe253758951a19701ab4b6b5eafdabc339222e8b0eb3ed1","recorded_unix_us":1787932601502694,"recorded_utc":"2026-08-28T15:56:41.502694Z","schema_version":"nrrf810.exchange_authored_interactive_closure.v1","source_chain_continuous":true,"source_event":"order_deleted","source_event_id":"00065a1d-7f97-9968-0000-000103000020","source_event_id_unique":true,"source_pre_event_id":"00065a1d-7f97-9580-0000-000102000020","translation":"FOLD_RETURN_TO_ZERO","unfold_event_id":"00065a1d-7f97-8db0-0003-000102000020","zero_hair":true}
{"channel":"live_orders_btcusd","interaction_index":160,"natural_form":{"channel":"live_orders_btcusd","order_id":"2044303879372801","order_subtype":5,"order_type":0},"natural_form_sha256":"c93e5d3ea3f9380e3eb45363e2eb28874986ca39dc0f8aba7b82d106668d4dcf","order_source":"orderbook","orders_submitted":0,"presentation":{"amount":"1.27541152","amount_traded":"0","microtimestamp":"1787932601457000","price":"78406.06"},"previous_record_hash":"1f86dc329232498abbe253758951a19701ab4b6b5eafdabc339222e8b0eb3ed1","profit_assessment":null,"record_hash":"e652763995c0d3d097bd962a9c4fbc0db22c735c396715a136625820e11711c6","recorded_unix_us":1787932601502770,"recorded_utc":"2026-08-28T15:56:41.502770Z","schema_version":"nrrf810.exchange_authored_interactive_closure.v1","source_chain_continuous":true,"source_event":"order_created","source_event_id":"00065a1d-7f97-9968-0001-000100000020","source_event_id_unique":true,"source_pre_event_id":"00065a1d-7f97-9968-0000-000103000020","translation":"UNFOLD_TO_INF","unfold_event_id":null,"zero_hair":false}
{"channel":"live_orders_btcusd","interaction_index":161,"natural_form":{"channel":"live_orders_btcusd","order_id":"2044303879376898","order_subtype":5,"order_type":0},"natural_form_sha256":"d94b9bf5f8b399a0e2ed508c7717d75066d2f74e02ae4ac588a749cbf31b2044","order_source":"orderbook","orders_submitted":0,"presentation":{"amount":"1.27567513","amount_traded":"0","microtimestamp":"1787932601458000","price":"78389.86"},"previous_record_hash":"e652763995c0d3d097bd962a9c4fbc0db22c735c396715a136625820e11711c6","profit_assessment":null,"record_hash":"b67c1385239297fd3beb34eeda5554620307a3a8965f845f6327f2da7eb22f4d","recorded_unix_us":1787932601502788,"recorded_utc":"2026-08-28T15:56:41.502788Z","schema_version":"nrrf810.exchange_authored_interactive_closure.v1","source_chain_continuous":true,"source_event":"order_created","source_event_id":"00065a1d-7f97-9d50-0000-000101000020","source_event_id_unique":true,"source_pre_event_id":"00065a1d-7f97-9968-0001-000100000020","translation":"UNFOLD_TO_INF","unfold_event_id":null,"zero_hair":false}
{"channel":"live_orders_btcusd","interaction_index":162,"natural_form":{"channel":"live_orders_btcusd","order_id":"2044303879376897","order_subtype":5,"order_type":0},"natural_form_sha256":"bcd838997f01375306bc2fdfd20c28312f5ce8173e4aa81704c5ec9081d99d36","order_source":"orderbook","orders_submitted":0,"presentation":{"amount":"12.76418733","amount_traded":"0","microtimestamp":"1787932601458000","price":"78344.19"},"previous_record_hash":"b67c1385239297fd3beb34eeda5554620307a3a8965f845f6327f2da7eb22f4d","profit_assessment":null,"record_hash":"0de411f51bb300293db5404e379a660b870e4edd02f4300e3d7623255c280e32","recorded_unix_us":1787932601502883,"recorded_utc":"2026-08-28T15:56:41.502883Z","schema_version":"nrrf810.exchange_authored_interactive_closure.v1","source_chain_continuous":true,"source_event":"order_created","source_event_id":"00065a1d-7f97-9d50-0001-000102000020","source_event_id_unique":true,"source_pre_event_id":"00065a1d-7f97-9d50-0000-000101000020","translation":"UNFOLD_TO_INF","unfold_event_id":null,"zero_hair":false}
{"channel":"live_orders_btcusd","interaction_index":163,"natural_form":{"channel":"live_orders_btcusd","order_id":"2044303879380996","order_subtype":5,"order_type":0},"natural_form_sha256":"d8d23bd7444f3a523cfc7d57b23d31cdb662c41641a684994393c451261da38b","order_source":"orderbook","orders_submitted":0,"presentation":{"amount":"1.27757154","amount_traded":"0","microtimestamp":"1787932601459000","price":"78273.50"},"previous_record_hash":"0de411f51bb300293db5404e379a660b870e4edd02f4300e3d7623255c280e32","profit_assessment":null,"record_hash":"9b5943104093e9e354dd94fa6659efdeae45620aae4d2aafa88cbd8e92eed0e3","recorded_unix_us":1787932601502901,"recorded_utc":"2026-08-28T15:56:41.502901Z","schema_version":"nrrf810.exchange_authored_interactive_closure.v1","source_chain_continuous":true,"source_event":"order_created","source_event_id":"00065a1d-7f97-a138-0000-000103000020","source_event_id_unique":true,"source_pre_event_id":"00065a1d-7f97-9d50-0001-000102000020","translation":"UNFOLD_TO_INF","unfold_event_id":null,"zero_hair":false}
{"channel":"live_orders_btcusd","interaction_index":164,"natural_form":{"channel":"live_orders_btcusd","order_id":"2044303879421954","order_subtype":5,"order_type":1},"natural_form_sha256":"7d4f3bdae3e01a6e80c3c29cbefac59e3daa3a668eb21ac01d006ae1a7c3e1a2","order_source":"orderbook","orders_submitted":0,"presentation":{"amount":"0.10000000","amount_traded":"0","microtimestamp":"1787932601470000","price":"78522.63"},"previous_record_hash":"9b5943104093e9e354dd94fa6659efdeae45620aae4d2aafa88cbd8e92eed0e3","profit_assessment":null,"record_hash":"893ae2652a97b7e7fedcb67b368e6c482806fbfb9a87eb24adc8aeaa88f0df1d","recorded_unix_us":1787932601502973,"recorded_utc":"2026-08-28T15:56:41.502973Z","schema_version":"nrrf810.exchange_authored_interactive_closure.v1","source_chain_continuous":true,"source_event":"order_created","source_event_id":"00065a1d-7f97-cc30-0000-000100000020","source_event_id_unique":true,"source_pre_event_id":"00065a1d-7f97-a138-0000-000103000020","translation":"UNFOLD_TO_INF","unfold_event_id":null,"zero_hair":false}
{"channel":"live_orders_btcusd","interaction_index":165,"natural_form":{"channel":"live_orders_btcusd","order_id":"2044303879421954","order_subtype":5,"order_type":1},"natural_form_sha256":"7d4f3bdae3e01a6e80c3c29cbefac59e3daa3a668eb21ac01d006ae1a7c3e1a2","order_source":"orderbook","orders_submitted":0,"presentation":{"amount":"0.10000000","amount_traded":"0","microtimestamp":"1787932601470000","price":"78522.63"},"previous_record_hash":"893ae2652a97b7e7fedcb67b368e6c482806fbfb9a87eb24adc8aeaa88f0df1d","profit_assessment":null,"record_hash":"8b36624d4aca439efd5897a4149c9699bb7b185105439693da9099616262bca9","recorded_unix_us":1787932601502989,"recorded_utc":"2026-08-28T15:56:41.502989Z","schema_version":"nrrf810.exchange_authored_interactive_closure.v1","source_chain_continuous":true,"source_event":"order_deleted","source_event_id":"00065a1d-7f97-cc30-0001-000101000020","source_event_id_unique":true,"source_pre_event_id":"00065a1d-7f97-cc30-0000-000100000020","translation":"FOLD_RETURN_TO_ZERO","unfold_event_id":"00065a1d-7f97-cc30-0000-000100000020","zero_hair":true}
{"channel":"live_orders_btcusd","interaction_index":166,"natural_form":{"channel":"live_orders_btcusd","order_id":"2044303879430144","order_subtype":5,"order_type":1},"natural_form_sha256":"6829720528d1cb8fcec938603271ddcfa8934f9d65227d8072ca327385e17b1a","order_source":"orderbook","orders_submitted":0,"presentation":{"amount":"0.10000000","amount_traded":"0","microtimestamp":"1787932601471000","price":"78522.62"},"previous_record_hash":"8b36624d4aca439efd5897a4149c9699bb7b185105439693da9099616262bca9","profit_assessment":null,"record_hash":"cb6aab6fb83c5931a834e7dfb4d5f41d9c4bde8e32704b8150a095910225cda2","recorded_unix_us":1787932601530974,"recorded_utc":"2026-08-28T15:56:41.530974Z","schema_version":"nrrf810.exchange_authored_interactive_closure.v1","source_chain_continuous":true,"source_event":"order_created","source_event_id":"00065a1d-7f97-d018-0000-000102000020","source_event_id_unique":true,"source_pre_event_id":"00065a1d-7f97-cc30-0001-000101000020","translation":"UNFOLD_TO_INF","unfold_event_id":null,"zero_hair":false}
{"channel":"live_orders_btcusd","interaction_index":167,"natural_form":{"channel":"live_orders_btcusd","order_id":"2044303879430144","order_subtype":5,"order_type":1},"natural_form_sha256":"6829720528d1cb8fcec938603271ddcfa8934f9d65227d8072ca327385e17b1a","order_source":"orderbook","orders_submitted":0,"presentation":{"amount":"0.10000000","amount_traded":"0","microtimestamp":"1787932601471000","price":"78522.62"},"previous_record_hash":"cb6aab6fb83c5931a834e7dfb4d5f41d9c4bde8e32704b8150a095910225cda2","profit_assessment":null,"record_hash":"35f2c4effdf870c16990aef3cb33c9307b34d7cb43bf3c4750abc9a5a4f5fc1c","recorded_unix_us":1787932601531005,"recorded_utc":"2026-08-28T15:56:41.531005Z","schema_version":"nrrf810.exchange_authored_interactive_closure.v1","source_chain_continuous":true,"source_event":"order_deleted","source_event_id":"00065a1d-7f97-d018-0001-000103000020","source_event_id_unique":true,"source_pre_event_id":"00065a1d-7f97-d018-0000-000102000020","translation":"FOLD_RETURN_TO_ZERO","unfold_event_id":"00065a1d-7f97-d018-0000-000102000020","zero_hair":true}
{"channel":"live_orders_btcusd","interaction_index":168,"natural_form":{"channel":"live_orders_btcusd","order_id":"2044303859847170","order_subtype":0,"order_type":1},"natural_form_sha256":"fd4797f09c2768b90a4de0009747082731741b613563b33b678f1053e7a0ee70","order_source":"orderbook","orders_submitted":0,"presentation":{"amount":"0.06310787","amount_traded":"0","microtimestamp":"1787932601476000","price":"78555.58"},"previous_record_hash":"35f2c4effdf870c16990aef3cb33c9307b34d7cb43bf3c4750abc9a5a4f5fc1c","profit_assessment":null,"record_hash":"d867f75283f7ca4b681671517c84919035c66ea8418f4bf6b978f9c7b40b5f6b","recorded_unix_us":1787932601531102,"recorded_utc":"2026-08-28T15:56:41.531102Z","schema_version":"nrrf810.exchange_authored_interactive_closure.v1","source_chain_continuous":true,"source_event":"order_deleted","source_event_id":"00065a1d-7f97-e3a0-0000-000100000020","source_event_id_unique":true,"source_pre_event_id":"00065a1d-7f97-d018-0001-000103000020","translation":"PARTIAL_PRIOR_UNFOLD","unfold_event_id":null,"zero_hair":false}
{"channel":"live_orders_btcusd","interaction_index":169,"natural_form":{"channel":"live_orders_btcusd","order_id":"2044303878922240","order_subtype":5,"order_type":0},"natural_form_sha256":"ba3e9acf397e4359c70372f89d42f94e99e2a3d71b0068b5f1d3a603ed8b8987","order_source":"orderbook","orders_submitted":0,"presentation":{"amount":"0.00140266","amount_traded":"0","microtimestamp":"1787932601476000","price":"70670.37"},"previous_record_hash":"d867f75283f7ca4b681671517c84919035c66ea8418f4bf6b978f9c7b40b5f6b","profit_assessment":null,"record_hash":"d71b71ace22ee65b388e7a5d8386ab4b8de7faedbb02832337bffaf17ba358ad","recorded_unix_us":1787932601531187,"recorded_utc":"2026-08-28T15:56:41.531187Z","schema_version":"nrrf810.exchange_authored_interactive_closure.v1","source_chain_continuous":true,"source_event":"order_deleted","source_event_id":"00065a1d-7f97-e3a0-0001-000101000020","source_event_id_unique":true,"source_pre_event_id":"00065a1d-7f97-e3a0-0000-000100000020","translation":"FOLD_RETURN_TO_ZERO","unfold_event_id":"00065a1d-7f95-ebb8-0000-000103000020","zero_hair":true}
{"channel":"live_orders_btcusd","interaction_index":170,"natural_form":{"channel":"live_orders_btcusd","order_id":"2044303879450628","order_subtype":5,"order_type":1},"natural_form_sha256":"58bdba9d939f5924bf94eaa427d988d2af2363b8f8085cc73e988f8c525114f8","order_source":"orderbook","orders_submitted":0,"presentation":{"amount":"1.26842789","amount_traded":"0","microtimestamp":"1787932601476000","price":"78837.75"},"previous_record_hash":"d71b71ace22ee65b388e7a5d8386ab4b8de7faedbb02832337bffaf17ba358ad","profit_assessment":null,"record_hash":"50f67b4a9558af08317a475da0e83a1a69e198043829d81b40dd5ae9ab0ac118","recorded_unix_us":1787932601531310,"recorded_utc":"2026-08-28T15:56:41.531310Z","schema_version":"nrrf810.exchange_authored_interactive_closure.v1","source_chain_continuous":true,"source_event":"order_created","source_event_id":"00065a1d-7f97-e3a0-0002-000102000020","source_event_id_unique":true,"source_pre_event_id":"00065a1d-7f97-e3a0-0001-000101000020","translation":"UNFOLD_TO_INF","unfold_event_id":null,"zero_hair":false}
{"channel":"live_orders_btcusd","interaction_index":171,"natural_form":{"channel":"live_orders_btcusd","order_id":"2044303879249922","order_subtype":5,"order_type":0},"natural_form_sha256":"ec461b943e4cb0cbcaecde5c5ac870abba356d82b9584c51412b404b524fdba5","order_source":"orderbook","orders_submitted":0,"presentation":{"amount":"0.00140266","amount_traded":"0","microtimestamp":"1787932601476000","price":"70670.37"},"previous_record_hash":"50f67b4a9558af08317a475da0e83a1a69e198043829d81b40dd5ae9ab0ac118","profit_assessment":null,"record_hash":"478a84c6a35cbb894b106d901932e21c247c9aaa2ae8eeba5c680184e8e9e8be","recorded_unix_us":1787932601531335,"recorded_utc":"2026-08-28T15:56:41.531335Z","schema_version":"nrrf810.exchange_authored_interactive_closure.v1","source_chain_continuous":true,"source_event":"order_deleted","source_event_id":"00065a1d-7f97-e3a0-0003-000103000020","source_event_id_unique":true,"source_pre_event_id":"00065a1d-7f97-e3a0-0002-000102000020","translation":"FOLD_RETURN_TO_ZERO","unfold_event_id":"00065a1d-7f97-2820-0000-000103000020","zero_hair":true}
{"channel":"live_orders_btcusd","interaction_index":172,"natural_form":{"channel":"live_orders_btcusd","order_id":"2044303879450629","order_subtype":5,"order_type":1},"natural_form_sha256":"7f371b9acdd49bfad77846356d9fcffa22434a87098a29767216b0dab13b9819","order_source":"orderbook","orders_submitted":0,"presentation":{"amount":"1.27177200","amount_traded":"0","microtimestamp":"1787932601476000","price":"78630.45"},"previous_record_hash":"478a84c6a35cbb894b106d901932e21c247c9aaa2ae8eeba5c680184e8e9e8be","profit_assessment":null,"record_hash":"846d5e028eb4538548a49d7ec20c9910c76e4e0dc34b2d335693052fd31fefc9","recorded_unix_us":1787932601531467,"recorded_utc":"2026-08-28T15:56:41.531467Z","schema_version":"nrrf810.exchange_authored_interactive_closure.v1","source_chain_continuous":true,"source_event":"order_created","source_event_id":"00065a1d-7f97-e3a0-0004-000100000020","source_event_id_unique":true,"source_pre_event_id":"00065a1d-7f97-e3a0-0003-000103000020","translation":"UNFOLD_TO_INF","unfold_event_id":null,"zero_hair":false}
{"channel":"live_orders_btcusd","interaction_index":173,"natural_form":{"channel":"live_orders_btcusd","order_id":"2044303879458820","order_subtype":5,"order_type":0},"natural_form_sha256":"27fd4d7d82025ef63988d6dc4f7f2f85c8488f167dc1653bbe55b04539cd65e2","order_source":"orderbook","orders_submitted":0,"presentation":{"amount":"0.06368334","amount_traded":"0","microtimestamp":"1787932601479000","price":"78513.46"},"previous_record_hash":"846d5e028eb4538548a49d7ec20c9910c76e4e0dc34b2d335693052fd31fefc9","profit_assessment":null,"record_hash":"6010e2969daa2898d6036eaf2038a897d574fc0899063b4e21e666db1efb8232","recorded_unix_us":1787932601531494,"recorded_utc":"2026-08-28T15:56:41.531494Z","schema_version":"nrrf810.exchange_authored_interactive_closure.v1","source_chain_continuous":true,"source_event":"order_created","source_event_id":"00065a1d-7f97-ef58-0000-000101000020","source_event_id_unique":true,"source_pre_event_id":"00065a1d-7f97-e3a0-0004-000100000020","translation":"UNFOLD_TO_INF","unfold_event_id":null,"zero_hair":false}
{"channel":"live_orders_btcusd","interaction_index":174,"natural_form":{"channel":"live_orders_btcusd","order_id":"2044303879467021","order_subtype":5,"order_type":0},"natural_form_sha256":"3160722b0632f38e0f1fc18f96d4fa7c115c4fe059ab31f9b3bc1dadbd3e77ea","order_source":"orderbook","orders_submitted":0,"presentation":{"amount":"1.27604867","amount_traded":"0","microtimestamp":"1787932601481000","price":"78366.91"},"previous_record_hash":"6010e2969daa2898d6036eaf2038a897d574fc0899063b4e21e666db1efb8232","profit_assessment":null,"record_hash":"8b680de07a1bf34a439dc7f7ba53a42cbd646335d08e03e83dfc789f9f5938d9","recorded_unix_us":1787932601531599,"recorded_utc":"2026-08-28T15:56:41.531599Z","schema_version":"nrrf810.exchange_authored_interactive_closure.v1","source_chain_continuous":true,"source_event":"order_created","source_event_id":"00065a1d-7f97-f728-0000-000102000020","source_event_id_unique":true,"source_pre_event_id":"00065a1d-7f97-ef58-0000-000101000020","translation":"UNFOLD_TO_INF","unfold_event_id":null,"zero_hair":false}
{"channel":"live_orders_btcusd","interaction_index":175,"natural_form":{"channel":"live_orders_btcusd","order_id":"2044303879475200","order_subtype":5,"order_type":0},"natural_form_sha256":"e56b245f5328f053017abda68217223c6de00ca44f296918a86ccfc7d317acf8","order_source":"orderbook","orders_submitted":0,"presentation":{"amount":"1.27817952","amount_traded":"0","microtimestamp":"1787932601482000","price":"78236.27"},"previous_record_hash":"8b680de07a1bf34a439dc7f7ba53a42cbd646335d08e03e83dfc789f9f5938d9","profit_assessment":null,"record_hash":"4a35f7289876ba2d24baf9a68211fe3a895d34652c8733df5a283bbd03a92208","recorded_unix_us":1787932601531622,"recorded_utc":"2026-08-28T15:56:41.531622Z","schema_version":"nrrf810.exchange_authored_interactive_closure.v1","source_chain_continuous":true,"source_event":"order_created","source_event_id":"00065a1d-7f97-fb10-0000-000103000020","source_event_id_unique":true,"source_pre_event_id":"00065a1d-7f97-f728-0000-000102000020","translation":"UNFOLD_TO_INF","unfold_event_id":null,"zero_hair":false}
{"channel":"live_orders_btcusd","interaction_index":176,"natural_form":{"channel":"live_orders_btcusd","order_id":"2044303879184389","order_subtype":5,"order_type":1},"natural_form_sha256":"c32ae464887f8870f52536d441683faefcda3aec65730a270b66504b82b71b38","order_source":"orderbook","orders_submitted":0,"presentation":{"amount":"0.10000000","amount_traded":"0","microtimestamp":"1787932601484000","price":"78522.74"},"previous_record_hash":"4a35f7289876ba2d24baf9a68211fe3a895d34652c8733df5a283bbd03a92208","profit_assessment":null,"record_hash":"97625d401c17660aa8e8262b109b13bfa0a821a1e016c3cf0c842cdc0189a0d6","recorded_unix_us":1787932601531694,"recorded_utc":"2026-08-28T15:56:41.531694Z","schema_version":"nrrf810.exchange_authored_interactive_closure.v1","source_chain_continuous":true,"source_event":"order_deleted","source_event_id":"00065a1d-7f98-02e0-0000-000100000020","source_event_id_unique":true,"source_pre_event_id":"00065a1d-7f97-fb10-0000-000103000020","translation":"FOLD_RETURN_TO_ZERO","unfold_event_id":"00065a1d-7f96-e9a0-0000-000102000020","zero_hair":true}
{"channel":"live_orders_btcusd","interaction_index":177,"natural_form":{"channel":"live_orders_btcusd","order_id":"2044303879032836","order_subtype":5,"order_type":1},"natural_form_sha256":"ec9d7ed7acafe113bfa0dfea88546bd2982104170fd077260e4d00ee281fe238","order_source":"orderbook","orders_submitted":0,"presentation":{"amount":"0.10000000","amount_traded":"0","microtimestamp":"1787932601485000","price":"78522.79"},"previous_record_hash":"97625d401c17660aa8e8262b109b13bfa0a821a1e016c3cf0c842cdc0189a0d6","profit_assessment":null,"record_hash":"ea9ba2364fe8547d09f978ef4d1e9008998a55a1af466847d78230aabdfe1340","recorded_unix_us":1787932601531770,"recorded_utc":"2026-08-28T15:56:41.531770Z","schema_version":"nrrf810.exchange_authored_interactive_closure.v1","source_chain_continuous":true,"source_event":"order_deleted","source_event_id":"00065a1d-7f98-06c8-0000-000101000020","source_event_id_unique":true,"source_pre_event_id":"00065a1d-7f98-02e0-0000-000100000020","translation":"FOLD_RETURN_TO_ZERO","unfold_event_id":"00065a1d-7f96-5530-0000-000100000020","zero_hair":true}
{"channel":"live_orders_btcusd","interaction_index":178,"natural_form":{"channel":"live_orders_btcusd","order_id":"2044303878787076","order_subtype":5,"order_type":1},"natural_form_sha256":"aa5e79dc637159620275c970c0e0d207dd540c5941d5ad68677104553561ff86","order_source":"orderbook","orders_submitted":0,"presentation":{"amount":"0.10000000","amount_traded":"0","microtimestamp":"1787932601485000","price":"78523.00"},"previous_record_hash":"ea9ba2364fe8547d09f978ef4d1e9008998a55a1af466847d78230aabdfe1340","profit_assessment":null,"record_hash":"1f204ab6227d5ed337f0864fe83a4cba9916449b2b6927c003d51e2d6ad368ba","recorded_unix_us":1787932601531843,"recorded_utc":"2026-08-28T15:56:41.531843Z","schema_version":"nrrf810.exchange_authored_interactive_closure.v1","source_chain_continuous":true,"source_event":"order_deleted","source_event_id":"00065a1d-7f98-06c8-0001-000102000020","source_event_id_unique":true,"source_pre_event_id":"00065a1d-7f98-06c8-0000-000101000020","translation":"FOLD_RETURN_TO_ZERO","unfold_event_id":"00065a1d-7f95-6ad0-0004-000101000020","zero_hair":true}
{"channel":"live_orders_btcusd","interaction_index":179,"natural_form":{"channel":"live_orders_btcusd","order_id":"2044303878619144","order_subtype":5,"order_type":1},"natural_form_sha256":"d718b44ec7b9088860a4cc5e2923281df126925715093c10cf91104232f2fca0","order_source":"orderbook","orders_submitted":0,"presentation":{"amount":"0.10000000","amount_traded":"0","microtimestamp":"1787932601486000","price":"78523.05"},"previous_record_hash":"1f204ab6227d5ed337f0864fe83a4cba9916449b2b6927c003d51e2d6ad368ba","profit_assessment":null,"record_hash":"cbae6de145a0b668925429c74c3b75518db166ee9406af2b19bd8efc1fe0487f","recorded_unix_us":1787932601567797,"recorded_utc":"2026-08-28T15:56:41.567797Z","schema_version":"nrrf810.exchange_authored_interactive_closure.v1","source_chain_continuous":true,"source_event":"order_deleted","source_event_id":"00065a1d-7f98-0ab0-0000-000103000020","source_event_id_unique":true,"source_pre_event_id":"00065a1d-7f98-06c8-0001-000102000020","translation":"FOLD_RETURN_TO_ZERO","unfold_event_id":"00065a1d-7f94-ce90-0000-000101000020","zero_hair":true}
{"channel":"live_orders_btcusd","interaction_index":180,"natural_form":{"channel":"live_orders_btcusd","order_id":"2044303879491587","order_subtype":5,"order_type":1},"natural_form_sha256":"880eb613d69dbe9fd807805ec074893f532f4d3fc05f80ff5b48edf509803343","order_source":"orderbook","orders_submitted":0,"presentation":{"amount":"0.06310787","amount_traded":"0","microtimestamp":"1787932601487000","price":"78520.83"},"previous_record_hash":"cbae6de145a0b668925429c74c3b75518db166ee9406af2b19bd8efc1fe0487f","profit_assessment":null,"record_hash":"acd02780a5f71336cfd18130010fa4d86a9c0d11205969c3abc010bf49c3efb3","recorded_unix_us":1787932601567980,"recorded_utc":"2026-08-28T15:56:41.567980Z","schema_version":"nrrf810.exchange_authored_interactive_closure.v1","source_chain_continuous":true,"source_event":"order_created","source_event_id":"00065a1d-7f98-0e98-0000-000100000020","source_event_id_unique":true,"source_pre_event_id":"00065a1d-7f98-0ab0-0000-000103000020","translation":"UNFOLD_TO_INF","unfold_event_id":null,"zero_hair":false}
{"channel":"live_orders_btcusd","interaction_index":181,"natural_form":{"channel":"live_orders_btcusd","order_id":"2044303879491587","order_subtype":5,"order_type":1},"natural_form_sha256":"880eb613d69dbe9fd807805ec074893f532f4d3fc05f80ff5b48edf509803343","order_source":"orderbook","orders_submitted":0,"presentation":{"amount":"0.06310787","amount_traded":"0","microtimestamp":"1787932601487000","price":"78520.83"},"previous_record_hash":"acd02780a5f71336cfd18130010fa4d86a9c0d11205969c3abc010bf49c3efb3","profit_assessment":null,"record_hash":"7f8e6cb5376b986a9d0ca44854a1211cf101bddcc760bcf8f4d5ebd06f9cac4b","recorded_unix_us":1787932601568134,"recorded_utc":"2026-08-28T15:56:41.568134Z","schema_version":"nrrf810.exchange_authored_interactive_closure.v1","source_chain_continuous":true,"source_event":"order_deleted","source_event_id":"00065a1d-7f98-0e98-0001-000101000020","source_event_id_unique":true,"source_pre_event_id":"00065a1d-7f98-0e98-0000-000100000020","translation":"FOLD_RETURN_TO_ZERO","unfold_event_id":"00065a1d-7f98-0e98-0000-000100000020","zero_hair":true}
{"channel":"live_orders_btcusd","interaction_index":182,"natural_form":{"channel":"live_orders_btcusd","order_id":"2044303879360520","order_subtype":5,"order_type":0},"natural_form_sha256":"093c474d972995c8f753bf025a2a472acd22d718c406ebec90eb813e7ad7b3e7","order_source":"orderbook","orders_submitted":0,"presentation":{"amount":"0.06368219","amount_traded":"0","microtimestamp":"1787932601491000","price":"78514.87"},"previous_record_hash":"7f8e6cb5376b986a9d0ca44854a1211cf101bddcc760bcf8f4d5ebd06f9cac4b","profit_assessment":null,"record_hash":"d526b6053edd825ced6295280dba988d8525493ca408e5fdcaf8a330138a8a48","recorded_unix_us":1787932601568253,"recorded_utc":"2026-08-28T15:56:41.568253Z","schema_version":"nrrf810.exchange_authored_interactive_closure.v1","source_chain_continuous":true,"source_event":"order_deleted","source_event_id":"00065a1d-7f98-1e38-0000-000102000020","source_event_id_unique":true,"source_pre_event_id":"00065a1d-7f98-0e98-0001-000101000020","translation":"FOLD_RETURN_TO_ZERO","unfold_event_id":"00065a1d-7f97-8db0-0004-000103000020","zero_hair":true}
{"channel":"live_orders_btcusd","interaction_index":183,"natural_form":{"channel":"live_orders_btcusd","order_id":"2044303879516162","order_subtype":5,"order_type":1},"natural_form_sha256":"4181a21d9cc0da37252d41534857671c3fa1eed407b1018323dbece17d3653bc","order_source":"orderbook","orders_submitted":0,"presentation":{"amount":"0.10000000","amount_traded":"0","microtimestamp":"1787932601492000","price":"78522.64"},"previous_record_hash":"d526b6053edd825ced6295280dba988d8525493ca408e5fdcaf8a330138a8a48","profit_assessment":null,"record_hash":"28339c14e67c9504d5a6db0a08692ce104da738dcdc5260a58d0cb8a7e9f15d9","recorded_unix_us":1787932601568366,"recorded_utc":"2026-08-28T15:56:41.568366Z","schema_version":"nrrf810.exchange_authored_interactive_closure.v1","source_chain_continuous":true,"source_event":"order_created","source_event_id":"00065a1d-7f98-2220-0000-000103000020","source_event_id_unique":true,"source_pre_event_id":"00065a1d-7f98-1e38-0000-000102000020","translation":"UNFOLD_TO_INF","unfold_event_id":null,"zero_hair":false}
{"channel":"live_orders_btcusd","interaction_index":184,"natural_form":{"channel":"live_orders_btcusd","order_id":"2044303879516162","order_subtype":5,"order_type":1},"natural_form_sha256":"4181a21d9cc0da37252d41534857671c3fa1eed407b1018323dbece17d3653bc","order_source":"orderbook","orders_submitted":0,"presentation":{"amount":"0.10000000","amount_traded":"0","microtimestamp":"1787932601495000","price":"78522.64"},"previous_record_hash":"28339c14e67c9504d5a6db0a08692ce104da738dcdc5260a58d0cb8a7e9f15d9","profit_assessment":null,"record_hash":"bf1385e3480ab1568f7ba64b985111e626754b2869d4f357ce6ad01b598fb495","recorded_unix_us":1787932601568460,"recorded_utc":"2026-08-28T15:56:41.568460Z","schema_version":"nrrf810.exchange_authored_interactive_closure.v1","source_chain_continuous":true,"source_event":"order_deleted","source_event_id":"00065a1d-7f98-2dd8-0000-000100000020","source_event_id_unique":true,"source_pre_event_id":"00065a1d-7f98-2220-0000-000103000020","translation":"FOLD_RETURN_TO_ZERO","unfold_event_id":"00065a1d-7f98-2220-0000-000103000020","zero_hair":true}
{"channel":"live_orders_ethusd","interaction_index":185,"natural_form":{"channel":"live_orders_ethusd","order_id":"2044303878676498","order_subtype":5,"order_type":0},"natural_form_sha256":"e98ea90332a3e7a183bcc208b066c6aaa6493847a2e00008d80b8bb3081def77","order_source":"orderbook","orders_submitted":0,"presentation":{"amount":"0.403104","amount_traded":"0","microtimestamp":"1787932601496000","price":"2479.50"},"previous_record_hash":"bf1385e3480ab1568f7ba64b985111e626754b2869d4f357ce6ad01b598fb495","profit_assessment":null,"record_hash":"b82864af8c9f1cd9d833ba746b236e923ac0f837ada24f0c143e71d1e765a640","recorded_unix_us":1787932601568556,"recorded_utc":"2026-08-28T15:56:41.568556Z","schema_version":"nrrf810.exchange_authored_interactive_closure.v1","source_chain_continuous":true,"source_event":"order_deleted","source_event_id":"00065a1d-7f98-31c0-0000-001200000020","source_event_id_unique":true,"source_pre_event_id":"00065a1d-7f97-7258-0001-001203000020","translation":"FOLD_RETURN_TO_ZERO","unfold_event_id":"00065a1d-7f95-0540-0000-001203000020","zero_hair":true}
{"channel":"live_orders_btcusd","interaction_index":186,"natural_form":{"channel":"live_orders_btcusd","order_id":"2044303879536647","order_subtype":5,"order_type":1},"natural_form_sha256":"4ec4a2ba7e9d349fea635a19cdbcb6df78512c01d70d0b90facb4786d03fd206","order_source":"orderbook","orders_submitted":0,"presentation":{"amount":"1.27145262","amount_traded":"0","microtimestamp":"1787932601497000","price":"78650.20"},"previous_record_hash":"b82864af8c9f1cd9d833ba746b236e923ac0f837ada24f0c143e71d1e765a640","profit_assessment":null,"record_hash":"0d09c488161f4b60a6a39c353a907967d837124f761aaed8e3ea4d470e9d7f0d","recorded_unix_us":1787932601568664,"recorded_utc":"2026-08-28T15:56:41.568664Z","schema_version":"nrrf810.exchange_authored_interactive_closure.v1","source_chain_continuous":true,"source_event":"order_created","source_event_id":"00065a1d-7f98-35a8-0000-000101000020","source_event_id_unique":true,"source_pre_event_id":"00065a1d-7f98-2dd8-0000-000100000020","translation":"UNFOLD_TO_INF","unfold_event_id":null,"zero_hair":false}
{"channel":"live_orders_btcusd","interaction_index":187,"natural_form":{"channel":"live_orders_btcusd","order_id":"2044303879540737","order_subtype":5,"order_type":0},"natural_form_sha256":"b86039ddf39e57ef83903a13a2c44f9d4db9c64d1c06cef684b9848a73d9e62d","order_source":"orderbook","orders_submitted":0,"presentation":{"amount":"1.27888333","amount_traded":"0","microtimestamp":"1787932601498000","price":"78193.21"},"previous_record_hash":"0d09c488161f4b60a6a39c353a907967d837124f761aaed8e3ea4d470e9d7f0d","profit_assessment":null,"record_hash":"6ecbee2a638860527883314789d921ec942b2024c483a57e16ad9e532ecac495","recorded_unix_us":1787932601568849,"recorded_utc":"2026-08-28T15:56:41.568849Z","schema_version":"nrrf810.exchange_authored_interactive_closure.v1","source_chain_continuous":true,"source_event":"order_created","source_event_id":"00065a1d-7f98-3990-0000-000102000020","source_event_id_unique":true,"source_pre_event_id":"00065a1d-7f98-35a8-0000-000101000020","translation":"UNFOLD_TO_INF","unfold_event_id":null,"zero_hair":false}
{"channel":"live_orders_ethusd","interaction_index":188,"natural_form":{"channel":"live_orders_ethusd","order_id":"2044303878205450","order_subtype":5,"order_type":0},"natural_form_sha256":"17c790ad367ddcdb58f20ff33928d54813b26628abc98fb67e3f09a3e4bc2b13","order_source":"orderbook","orders_submitted":0,"presentation":{"amount":"4.034894","amount_traded":"0","microtimestamp":"1787932601500000","price":"2478.37"},"previous_record_hash":"6ecbee2a638860527883314789d921ec942b2024c483a57e16ad9e532ecac495","profit_assessment":null,"record_hash":"0488e7a9fa9e8df1ab08297ae1bbcd9836327eb51b109a91c36712e88e661ffb","recorded_unix_us":1787932601568881,"recorded_utc":"2026-08-28T15:56:41.568881Z","schema_version":"nrrf810.exchange_authored_interactive_closure.v1","source_chain_continuous":true,"source_event":"order_deleted","source_event_id":"00065a1d-7f98-4160-0000-001201000020","source_event_id_unique":true,"source_pre_event_id":"00065a1d-7f98-31c0-0000-001200000020","translation":"FOLD_RETURN_TO_ZERO","unfold_event_id":"00065a1d-7f93-4408-0000-001202000020","zero_hair":true}
