{"channel":"live_orders_ethusd","interaction_index":565,"natural_form":{"channel":"live_orders_ethusd","order_id":"2044303881039878","order_subtype":5,"order_type":0},"natural_form_sha256":"1b83b7d784302e5a55557cca610bd8c8bc6534fb15b052b8adb62aa7a5723213","order_source":"orderbook","orders_submitted":0,"presentation":{"amount":"0.527206","amount_traded":"0","microtimestamp":"1787932602079000","price":"2480.02"},"previous_record_hash":"39ad5b45324e767d1c39ef2f2aeea871a11112c6a3d2827031543a3f880d9939","profit_assessment":null,"record_hash":"20ccc44316df7b86e55846c5d04ad2a7783a194377a9c9210bd43614c6fcb96d","recorded_unix_us":1787932602125285,"recorded_utc":"2026-08-28T15:56:42.125285Z","schema_version":"nrrf810.exchange_authored_interactive_closure.v1","source_chain_continuous":true,"source_event":"order_deleted","source_event_id":"00065a1d-7fa1-1718-0000-001200000020","source_event_id_unique":true,"source_pre_event_id":"00065a1d-7fa0-e450-0000-001203000020","translation":"FOLD_RETURN_TO_ZERO","unfold_event_id":"00065a1d-7f9d-cf40-0001-001202000020","zero_hair":true}
{"channel":"live_orders_btcusd","interaction_index":566,"natural_form":{"channel":"live_orders_btcusd","order_id":"2044303881940995","order_subtype":5,"order_type":1},"natural_form_sha256":"f046d336c597f05617d2c28e70f7bdb4da2fe5d8f9121e71ccaec66da9fedc70","order_source":"orderbook","orders_submitted":0,"presentation":{"amount":"0.50943420","amount_traded":"0","microtimestamp":"1787932602085000","price":"78522.64"},"previous_record_hash":"20ccc44316df7b86e55846c5d04ad2a7783a194377a9c9210bd43614c6fcb96d","profit_assessment":null,"record_hash":"e3233aeda09bd49f09b0fdf33137ea29022fa763a309771239c2e71fb6584160","recorded_unix_us":1787932602125404,"recorded_utc":"2026-08-28T15:56:42.125404Z","schema_version":"nrrf810.exchange_authored_interactive_closure.v1","source_chain_continuous":true,"source_event":"order_created","source_event_id":"00065a1d-7fa1-2e88-0000-000102000020","source_event_id_unique":true,"source_pre_event_id":"00065a1d-7fa1-0b60-0003-000101000020","translation":"UNFOLD_TO_INF","unfold_event_id":null,"zero_hair":false}
{"channel":"live_orders_ethusd","interaction_index":567,"natural_form":{"channel":"live_orders_ethusd","order_id":"2044303881940997","order_subtype":5,"order_type":0},"natural_form_sha256":"2c596c39bbcd67c9eaf724b69544ef10770d8a0a577c83d3b54cdf73a79ef3f5","order_source":"orderbook","orders_submitted":0,"presentation":{"amount":"0.042508","amount_traded":"0","microtimestamp":"1787932602085000","price":"2480.80"},"previous_record_hash":"e3233aeda09bd49f09b0fdf33137ea29022fa763a309771239c2e71fb6584160","profit_assessment":null,"record_hash":"8435dca61835dfc8584ef3a2b40926af2483eeaafa258744fb98af1fbd2d2483","recorded_unix_us":1787932602125572,"recorded_utc":"2026-08-28T15:56:42.125572Z","schema_version":"nrrf810.exchange_authored_interactive_closure.v1","source_chain_continuous":true,"source_event":"order_created","source_event_id":"00065a1d-7fa1-2e88-0000-001201000020","source_event_id_unique":true,"source_pre_event_id":"00065a1d-7fa1-1718-0000-001200000020","translation":"UNFOLD_TO_INF","unfold_event_id":null,"zero_hair":false}
{"channel":"live_orders_btcusd","interaction_index":568,"natural_form":{"channel":"live_orders_btcusd","order_id":"2044303881940996","order_subtype":5,"order_type":1},"natural_form_sha256":"10e65859503ef331d4f87de021395f45df6dbdfe7293c180a3660615112a9636","order_source":"orderbook","orders_submitted":0,"presentation":{"amount":"0.06367384","amount_traded":"0","microtimestamp":"1787932602085000","price":"78525.19"},"previous_record_hash":"8435dca61835dfc8584ef3a2b40926af2483eeaafa258744fb98af1fbd2d2483","profit_assessment":null,"record_hash":"f4db9391f114adf724ce1a58bafae62a0e11d0976c752c4e0d1b329507c55ad2","recorded_unix_us":1787932602125607,"recorded_utc":"2026-08-28T15:56:42.125607Z","schema_version":"nrrf810.exchange_authored_interactive_closure.v1","source_chain_continuous":true,"source_event":"order_created","source_event_id":"00065a1d-7fa1-2e88-0001-000103000020","source_event_id_unique":true,"source_pre_event_id":"00065a1d-7fa1-2e88-0000-000102000020","translation":"UNFOLD_TO_INF","unfold_event_id":null,"zero_hair":false}
{"channel":"live_orders_ethusd","interaction_index":569,"natural_form":{"channel":"live_orders_ethusd","order_id":"2044303881945090","order_subtype":5,"order_type":1},"natural_form_sha256":"b12054c37442433535f54533f94bb28d6bb73f217fde7a20f8b0595eebe0035e","order_source":"orderbook","orders_submitted":0,"presentation":{"amount":"0.043646","amount_traded":"0","microtimestamp":"1787932602085000","price":"2480.89"},"previous_record_hash":"f4db9391f114adf724ce1a58bafae62a0e11d0976c752c4e0d1b329507c55ad2","profit_assessment":null,"record_hash":"eee92b956f3d6a7f05f572dc1f70e36c54cc2dafcb8dd723fe6dfc8f855a839d","recorded_unix_us":1787932602125631,"recorded_utc":"2026-08-28T15:56:42.125631Z","schema_version":"nrrf810.exchange_authored_interactive_closure.v1","source_chain_continuous":true,"source_event":"order_created","source_event_id":"00065a1d-7fa1-2e88-0001-001202000020","source_event_id_unique":true,"source_pre_event_id":"00065a1d-7fa1-2e88-0000-001201000020","translation":"UNFOLD_TO_INF","unfold_event_id":null,"zero_hair":false}
{"channel":"live_orders_btcusd","interaction_index":570,"natural_form":{"channel":"live_orders_btcusd","order_id":"2044303881945092","order_subtype":5,"order_type":1},"natural_form_sha256":"7ef1f4e260f7564290a36fe630833f0663f6f1d5c13c595a37c13b88550bdb29","order_source":"orderbook","orders_submitted":0,"presentation":{"amount":"0.06367563","amount_traded":"0","microtimestamp":"1787932602085000","price":"78522.98"},"previous_record_hash":"eee92b956f3d6a7f05f572dc1f70e36c54cc2dafcb8dd723fe6dfc8f855a839d","profit_assessment":null,"record_hash":"fd2d43163dddcb9980a3ce9b3e58fd1cfde58e7f23bb3cdf23853fe81b1b1fb2","recorded_unix_us":1787932602125707,"recorded_utc":"2026-08-28T15:56:42.125707Z","schema_version":"nrrf810.exchange_authored_interactive_closure.v1","source_chain_continuous":true,"source_event":"order_created","source_event_id":"00065a1d-7fa1-2e88-0002-000100000020","source_event_id_unique":true,"source_pre_event_id":"00065a1d-7fa1-2e88-0001-000103000020","translation":"UNFOLD_TO_INF","unfold_event_id":null,"zero_hair":false}
{"channel":"live_orders_btcusd","interaction_index":571,"natural_form":{"channel":"live_orders_btcusd","order_id":"2044303881949184","order_subtype":5,"order_type":1},"natural_form_sha256":"68e7940f5de657c0280ae7edbb723bab9c0416896b369550b233d00d56bf5705","order_source":"orderbook","orders_submitted":0,"presentation":{"amount":"0.63679275","amount_traded":"0","microtimestamp":"1787932602086000","price":"78522.64"},"previous_record_hash":"fd2d43163dddcb9980a3ce9b3e58fd1cfde58e7f23bb3cdf23853fe81b1b1fb2","profit_assessment":null,"record_hash":"07f8583935fbb521ccbab6e7e6b4670627bb1853fa1307666c6bb02603b2770a","recorded_unix_us":1787932602125790,"recorded_utc":"2026-08-28T15:56:42.125790Z","schema_version":"nrrf810.exchange_authored_interactive_closure.v1","source_chain_continuous":true,"source_event":"order_created","source_event_id":"00065a1d-7fa1-3270-0000-000101000020","source_event_id_unique":true,"source_pre_event_id":"00065a1d-7fa1-2e88-0002-000100000020","translation":"UNFOLD_TO_INF","unfold_event_id":null,"zero_hair":false}
{"channel":"live_orders_btcusd","interaction_index":572,"natural_form":{"channel":"live_orders_btcusd","order_id":"2044303881949185","order_subtype":5,"order_type":1},"natural_form_sha256":"77d0192a58408566da9101902b08fe479c21d81fc3a46023c4dda0eabad7433f","order_source":"orderbook","orders_submitted":0,"presentation":{"amount":"0.19103782","amount_traded":"0","microtimestamp":"1787932602086000","price":"78522.64"},"previous_record_hash":"07f8583935fbb521ccbab6e7e6b4670627bb1853fa1307666c6bb02603b2770a","profit_assessment":null,"record_hash":"14bf4a1f26c97d0026556fd75c2d5807cc2b5b2d5c2eec0c183b007094bb3b09","recorded_unix_us":1787932602125862,"recorded_utc":"2026-08-28T15:56:42.125862Z","schema_version":"nrrf810.exchange_authored_interactive_closure.v1","source_chain_continuous":true,"source_event":"order_created","source_event_id":"00065a1d-7fa1-3270-0001-000102000020","source_event_id_unique":true,"source_pre_event_id":"00065a1d-7fa1-3270-0000-000101000020","translation":"UNFOLD_TO_INF","unfold_event_id":null,"zero_hair":false}
{"channel":"live_orders_ethusd","interaction_index":573,"natural_form":{"channel":"live_orders_ethusd","order_id":"2044303880323082","order_subtype":5,"order_type":0},"natural_form_sha256":"2b1e2289aacfef003a1bf281276a3ed953d64ba467b8e43710d05aecfd41de76","order_source":"orderbook","orders_submitted":0,"presentation":{"amount":"0.403104","amount_traded":"0","microtimestamp":"1787932602086000","price":"2480.15"},"previous_record_hash":"14bf4a1f26c97d0026556fd75c2d5807cc2b5b2d5c2eec0c183b007094bb3b09","profit_assessment":null,"record_hash":"ee33f8b76acfd5e380259a8c8d0243926548fc9c31b3b46f7ba17d07e131c2cc","recorded_unix_us":1787932602125931,"recorded_utc":"2026-08-28T15:56:42.125931Z","schema_version":"nrrf810.exchange_authored_interactive_closure.v1","source_chain_continuous":true,"source_event":"order_deleted","source_event_id":"00065a1d-7fa1-3270-0000-001203000020","source_event_id_unique":true,"source_pre_event_id":"00065a1d-7fa1-2e88-0001-001202000020","translation":"FOLD_RETURN_TO_ZERO","unfold_event_id":"00065a1d-7f9b-2790-0000-001202000020","zero_hair":true}
{"channel":"live_orders_btcusd","interaction_index":574,"natural_form":{"channel":"live_orders_btcusd","order_id":"2044303881949188","order_subtype":5,"order_type":1},"natural_form_sha256":"6403093feec85ad017aa4e9d09579e489676a96e00c4d339bdab52af87b7069b","order_source":"orderbook","orders_submitted":0,"presentation":{"amount":"0.25467128","amount_traded":"0","microtimestamp":"1787932602087000","price":"78532.61"},"previous_record_hash":"ee33f8b76acfd5e380259a8c8d0243926548fc9c31b3b46f7ba17d07e131c2cc","profit_assessment":null,"record_hash":"4ca352cc0894af3d9ad814f2a352f4ed2972a21b1056c06ab84944f367d74c6d","recorded_unix_us":1787932602126002,"recorded_utc":"2026-08-28T15:56:42.126002Z","schema_version":"nrrf810.exchange_authored_interactive_closure.v1","source_chain_continuous":true,"source_event":"order_created","source_event_id":"00065a1d-7fa1-3658-0000-000103000020","source_event_id_unique":true,"source_pre_event_id":"00065a1d-7fa1-3270-0001-000102000020","translation":"UNFOLD_TO_INF","unfold_event_id":null,"zero_hair":false}
{"channel":"live_orders_btcusd","interaction_index":575,"natural_form":{"channel":"live_orders_btcusd","order_id":"2044303881957376","order_subtype":5,"order_type":1},"natural_form_sha256":"4ccae53c099a18ef58d5daa41ee19784a3e59f6108396ed022a8ca526b58f689","order_source":"orderbook","orders_submitted":0,"presentation":{"amount":"0.25466146","amount_traded":"0","microtimestamp":"1787932602088000","price":"78535.64"},"previous_record_hash":"4ca352cc0894af3d9ad814f2a352f4ed2972a21b1056c06ab84944f367d74c6d","profit_assessment":null,"record_hash":"2ab26a884b225052ed6b4365d5c806bdce19c654f83d0cf467dfe475ff746542","recorded_unix_us":1787932602126070,"recorded_utc":"2026-08-28T15:56:42.126070Z","schema_version":"nrrf810.exchange_authored_interactive_closure.v1","source_chain_continuous":true,"source_event":"order_created","source_event_id":"00065a1d-7fa1-3a40-0000-000100000020","source_event_id_unique":true,"source_pre_event_id":"00065a1d-7fa1-3658-0000-000103000020","translation":"UNFOLD_TO_INF","unfold_event_id":null,"zero_hair":false}
{"channel":"live_orders_btcusd","interaction_index":576,"natural_form":{"channel":"live_orders_btcusd","order_id":"2044303881957380","order_subtype":5,"order_type":1},"natural_form_sha256":"c0d260d1da948f3da0719ab58e4be8c35308090fd8c57fbb97e066c388a73155","order_source":"orderbook","orders_submitted":0,"presentation":{"amount":"1.26970017","amount_traded":"0","microtimestamp":"1787932602089000","price":"78758.76"},"previous_record_hash":"2ab26a884b225052ed6b4365d5c806bdce19c654f83d0cf467dfe475ff746542","profit_assessment":null,"record_hash":"88e279cb0aa8d0a821137f91d3a90753388783900f38614601aa6ea49978bb9e","recorded_unix_us":1787932602126219,"recorded_utc":"2026-08-28T15:56:42.126219Z","schema_version":"nrrf810.exchange_authored_interactive_closure.v1","source_chain_continuous":true,"source_event":"order_created","source_event_id":"00065a1d-7fa1-3e28-0000-000101000020","source_event_id_unique":true,"source_pre_event_id":"00065a1d-7fa1-3a40-0000-000100000020","translation":"UNFOLD_TO_INF","unfold_event_id":null,"zero_hair":false}
{"channel":"live_orders_btcusd","interaction_index":577,"natural_form":{"channel":"live_orders_btcusd","order_id":"2044303881957382","order_subtype":5,"order_type":1},"natural_form_sha256":"8309fc81cadfe2b51c3726ebc4a43155fa3444b115e17a9d06342499d01146b1","order_source":"orderbook","orders_submitted":0,"presentation":{"amount":"1.27209222","amount_traded":"0","microtimestamp":"1787932602089000","price":"78610.66"},"previous_record_hash":"88e279cb0aa8d0a821137f91d3a90753388783900f38614601aa6ea49978bb9e","profit_assessment":null,"record_hash":"46912e94eb1dca393df2dfa5d954b1afeddc53394f2142fede626e7e0d937c5d","recorded_unix_us":1787932602126244,"recorded_utc":"2026-08-28T15:56:42.126244Z","schema_version":"nrrf810.exchange_authored_interactive_closure.v1","source_chain_continuous":true,"source_event":"order_created","source_event_id":"00065a1d-7fa1-3e28-0001-000102000020","source_event_id_unique":true,"source_pre_event_id":"00065a1d-7fa1-3e28-0000-000101000020","translation":"UNFOLD_TO_INF","unfold_event_id":null,"zero_hair":false}
{"channel":"live_orders_ethusd","interaction_index":578,"natural_form":{"channel":"live_orders_ethusd","order_id":"2044303881961472","order_subtype":5,"order_type":0},"natural_form_sha256":"502af49deefae0b5dec155d92a47be578075e2eeef550522c8789db3509b111c","order_source":"orderbook","orders_submitted":0,"presentation":{"amount":"0.562275","amount_traded":"0","microtimestamp":"1787932602089000","price":"2480.16"},"previous_record_hash":"46912e94eb1dca393df2dfa5d954b1afeddc53394f2142fede626e7e0d937c5d","profit_assessment":null,"record_hash":"ea50b80e65d0c589d6be7dd099b8203ff3736c03aa2170615da73d6cbd575feb","recorded_unix_us":1787932602126266,"recorded_utc":"2026-08-28T15:56:42.126266Z","schema_version":"nrrf810.exchange_authored_interactive_closure.v1","source_chain_continuous":true,"source_event":"order_created","source_event_id":"00065a1d-7fa1-3e28-0000-001200000020","source_event_id_unique":true,"source_pre_event_id":"00065a1d-7fa1-3270-0000-001203000020","translation":"UNFOLD_TO_INF","unfold_event_id":null,"zero_hair":false}
{"channel":"live_orders_btcusd","interaction_index":579,"natural_form":{"channel":"live_orders_btcusd","order_id":"2044303881961473","order_subtype":5,"order_type":1},"natural_form_sha256":"61af4c113ea6941fec36a4b9f23ca32d645f14e8a640a33fe8f5257d4da507c4","order_source":"orderbook","orders_submitted":0,"presentation":{"amount":"12.70451953","amount_traded":"0","microtimestamp":"1787932602089000","price":"78712.15"},"previous_record_hash":"ea50b80e65d0c589d6be7dd099b8203ff3736c03aa2170615da73d6cbd575feb","profit_assessment":null,"record_hash":"c2db4d6b6bc31af828e6d915806b018d0592d4cc5d3f8bd8c5dc2a5b504ae1a2","recorded_unix_us":1787932602126290,"recorded_utc":"2026-08-28T15:56:42.126290Z","schema_version":"nrrf810.exchange_authored_interactive_closure.v1","source_chain_continuous":true,"source_event":"order_created","source_event_id":"00065a1d-7fa1-3e28-0002-000103000020","source_event_id_unique":true,"source_pre_event_id":"00065a1d-7fa1-3e28-0001-000102000020","translation":"UNFOLD_TO_INF","unfold_event_id":null,"zero_hair":false}
{"channel":"live_orders_btcusd","interaction_index":580,"natural_form":{"channel":"live_orders_btcusd","order_id":"2044303881965574","order_subtype":5,"order_type":1},"natural_form_sha256":"cbb4ae9fcc7c6826d9379a6612506bb00ad0039df142b1feb7bb3110e62115e6","order_source":"orderbook","orders_submitted":0,"presentation":{"amount":"0.10000000","amount_traded":"0","microtimestamp":"1787932602091000","price":"78522.63"},"previous_record_hash":"c2db4d6b6bc31af828e6d915806b018d0592d4cc5d3f8bd8c5dc2a5b504ae1a2","profit_assessment":null,"record_hash":"3a29817a018b13e8358246aaccb136ccc2b276fb79144762957acf23fdbc696c","recorded_unix_us":1787932602126383,"recorded_utc":"2026-08-28T15:56:42.126383Z","schema_version":"nrrf810.exchange_authored_interactive_closure.v1","source_chain_continuous":true,"source_event":"order_created","source_event_id":"00065a1d-7fa1-45f8-0000-000100000020","source_event_id_unique":true,"source_pre_event_id":"00065a1d-7fa1-3e28-0002-000103000020","translation":"UNFOLD_TO_INF","unfold_event_id":null,"zero_hair":false}
{"channel":"live_orders_btcusd","interaction_index":581,"natural_form":{"channel":"live_orders_btcusd","order_id":"2044303881965574","order_subtype":5,"order_type":1},"natural_form_sha256":"cbb4ae9fcc7c6826d9379a6612506bb00ad0039df142b1feb7bb3110e62115e6","order_source":"orderbook","orders_submitted":0,"presentation":{"amount":"0.10000000","amount_traded":"0","microtimestamp":"1787932602091000","price":"78522.63"},"previous_record_hash":"3a29817a018b13e8358246aaccb136ccc2b276fb79144762957acf23fdbc696c","profit_assessment":null,"record_hash":"20adba620959bbfcfd3cc1b13a29284e9ffd93bf8d64ab43b77423673ea85d35","recorded_unix_us":1787932602126406,"recorded_utc":"2026-08-28T15:56:42.126406Z","schema_version":"nrrf810.exchange_authored_interactive_closure.v1","source_chain_continuous":true,"source_event":"order_deleted","source_event_id":"00065a1d-7fa1-45f8-0001-000101000020","source_event_id_unique":true,"source_pre_event_id":"00065a1d-7fa1-45f8-0000-000100000020","translation":"FOLD_RETURN_TO_ZERO","unfold_event_id":"00065a1d-7fa1-45f8-0000-000100000020","zero_hair":true}
{"channel":"live_orders_ethusd","interaction_index":582,"natural_form":{"channel":"live_orders_ethusd","order_id":"2044303881973764","order_subtype":5,"order_type":0},"natural_form_sha256":"47c417f3a09cd69c27a0e9aa8fe47ae315c4181f6fbd19ee52fab223c83b85cd","order_source":"orderbook","orders_submitted":0,"presentation":{"amount":"0.403088","amount_traded":"0","microtimestamp":"1787932602092000","price":"2480.10"},"previous_record_hash":"20adba620959bbfcfd3cc1b13a29284e9ffd93bf8d64ab43b77423673ea85d35","profit_assessment":null,"record_hash":"4a759dedf500390e8aec39596fcae1ade197527b63e65fc825037afaf6bb24e4","recorded_unix_us":1787932602154101,"recorded_utc":"2026-08-28T15:56:42.154101Z","schema_version":"nrrf810.exchange_authored_interactive_closure.v1","source_chain_continuous":true,"source_event":"order_created","source_event_id":"00065a1d-7fa1-49e0-0000-001201000020","source_event_id_unique":true,"source_pre_event_id":"00065a1d-7fa1-3e28-0000-001200000020","translation":"UNFOLD_TO_INF","unfold_event_id":null,"zero_hair":false}
{"channel":"live_orders_btcusd","interaction_index":583,"natural_form":{"channel":"live_orders_btcusd","order_id":"2044303881973767","order_subtype":5,"order_type":1},"natural_form_sha256":"9649295e8ef102e65ea791b3e395be03291368d33f3d701061d72828dd987b9b","order_source":"orderbook","orders_submitted":0,"presentation":{"amount":"1.26840120","amount_traded":"0","microtimestamp":"1787932602093000","price":"78839.41"},"previous_record_hash":"4a759dedf500390e8aec39596fcae1ade197527b63e65fc825037afaf6bb24e4","profit_assessment":null,"record_hash":"ab6a0122aa4e612243ee3d8da0a591d5ffc81b85a7b83d4ad43c30e145763458","recorded_unix_us":1787932602154477,"recorded_utc":"2026-08-28T15:56:42.154477Z","schema_version":"nrrf810.exchange_authored_interactive_closure.v1","source_chain_continuous":true,"source_event":"order_created","source_event_id":"00065a1d-7fa1-4dc8-0000-000102000020","source_event_id_unique":true,"source_pre_event_id":"00065a1d-7fa1-45f8-0001-000101000020","translation":"UNFOLD_TO_INF","unfold_event_id":null,"zero_hair":false}
{"channel":"live_orders_btcusd","interaction_index":584,"natural_form":{"channel":"live_orders_btcusd","order_id":"2044303881736196","order_subtype":5,"order_type":0},"natural_form_sha256":"d998d70ac8d631346a8daafd2e01440f2aa7b88322968bba044dba8f295b44db","order_source":"orderbook","orders_submitted":0,"presentation":{"amount":"0.19103754","amount_traded":"0","microtimestamp":"1787932602094000","price":"78486.13"},"previous_record_hash":"ab6a0122aa4e612243ee3d8da0a591d5ffc81b85a7b83d4ad43c30e145763458","profit_assessment":null,"record_hash":"0254153644f3a11b0fd82ef36d9675fc4033082b2591e3fdbce959136f978fef","recorded_unix_us":1787932602154541,"recorded_utc":"2026-08-28T15:56:42.154541Z","schema_version":"nrrf810.exchange_authored_interactive_closure.v1","source_chain_continuous":true,"source_event":"order_deleted","source_event_id":"00065a1d-7fa1-51b0-0000-000103000020","source_event_id_unique":true,"source_pre_event_id":"00065a1d-7fa1-4dc8-0000-000102000020","translation":"FOLD_RETURN_TO_ZERO","unfold_event_id":"00065a1d-7fa0-6b38-0000-000101000020","zero_hair":true}
{"channel":"live_orders_btcusd","interaction_index":585,"natural_form":{"channel":"live_orders_btcusd","order_id":"2044303881744391","order_subtype":5,"order_type":0},"natural_form_sha256":"fbc841d4291ddf8d1bfab0283445a2361df1abad0115666974324e9b1e2b8a23","order_source":"orderbook","orders_submitted":0,"presentation":{"amount":"0.63679180","amount_traded":"0","microtimestamp":"1787932602094000","price":"78484.17"},"previous_record_hash":"0254153644f3a11b0fd82ef36d9675fc4033082b2591e3fdbce959136f978fef","profit_assessment":null,"record_hash":"bcf4907f361ce04af38de06ec862f5d4a32f975f131f29418434465962960701","recorded_unix_us":1787932602154700,"recorded_utc":"2026-08-28T15:56:42.154700Z","schema_version":"nrrf810.exchange_authored_interactive_closure.v1","source_chain_continuous":true,"source_event":"order_deleted","source_event_id":"00065a1d-7fa1-51b0-0001-000100000020","source_event_id_unique":true,"source_pre_event_id":"00065a1d-7fa1-51b0-0000-000103000020","translation":"FOLD_RETURN_TO_ZERO","unfold_event_id":"00065a1d-7fa0-6f20-0001-000103000020","zero_hair":true}
{"channel":"live_orders_btcusd","interaction_index":586,"natural_form":{"channel":"live_orders_btcusd","order_id":"2044303881744388","order_subtype":5,"order_type":0},"natural_form_sha256":"9ee051d1c08811c24f613ae8b43108ccaaa1ad9bc8768d709e895d8aea20eab6","order_source":"orderbook","orders_submitted":0,"presentation":{"amount":"0.50943344","amount_traded":"0","microtimestamp":"1787932602095000","price":"78482.20"},"previous_record_hash":"bcf4907f361ce04af38de06ec862f5d4a32f975f131f29418434465962960701","profit_assessment":null,"record_hash":"f74d83d75f156fac6feddcc8dd472fa89acd2d3689edb2f2f3df3b6293fc3403","recorded_unix_us":1787932602154738,"recorded_utc":"2026-08-28T15:56:42.154738Z","schema_version":"nrrf810.exchange_authored_interactive_closure.v1","source_chain_continuous":true,"source_event":"order_deleted","source_event_id":"00065a1d-7fa1-5598-0000-000101000020","source_event_id_unique":true,"source_pre_event_id":"00065a1d-7fa1-51b0-0001-000100000020","translation":"FOLD_RETURN_TO_ZERO","unfold_event_id":"00065a1d-7fa0-6f20-0000-000102000020","zero_hair":true}
{"channel":"live_orders_btcusd","interaction_index":587,"natural_form":{"channel":"live_orders_btcusd","order_id":"2044303881986050","order_subtype":5,"order_type":0},"natural_form_sha256":"c547d44ab1a88d86d718054ee7346f2d1a484ba5b4c970e7f300e6b3c0b1679c","order_source":"orderbook","orders_submitted":0,"presentation":{"amount":"0.06367953","amount_traded":"0","microtimestamp":"1787932602095000","price":"78518.15"},"previous_record_hash":"f74d83d75f156fac6feddcc8dd472fa89acd2d3689edb2f2f3df3b6293fc3403","profit_assessment":null,"record_hash":"786d72f0179dc4eec289582050440b0f31ef79faa109ae7cdcb633dcabbae6e6","recorded_unix_us":1787932602154766,"recorded_utc":"2026-08-28T15:56:42.154766Z","schema_version":"nrrf810.exchange_authored_interactive_closure.v1","source_chain_continuous":true,"source_event":"order_created","source_event_id":"00065a1d-7fa1-5598-0001-000102000020","source_event_id_unique":true,"source_pre_event_id":"00065a1d-7fa1-5598-0000-000101000020","translation":"UNFOLD_TO_INF","unfold_event_id":null,"zero_hair":false}
{"channel":"live_orders_btcusd","interaction_index":588,"natural_form":{"channel":"live_orders_btcusd","order_id":"2044303881986057","order_subtype":5,"order_type":0},"natural_form_sha256":"2f332f1405122ce0fa8db088b97bed57b28587c5ddc62219b41c7a97bcd9254f","order_source":"orderbook","orders_submitted":0,"presentation":{"amount":"0.25476924","amount_traded":"0","microtimestamp":"1787932602095000","price":"78502.41"},"previous_record_hash":"786d72f0179dc4eec289582050440b0f31ef79faa109ae7cdcb633dcabbae6e6","profit_assessment":null,"record_hash":"b35040a00f9a8d3c560cd573bae1f3df6372447e1232b76cff4eab9bd10ed970","recorded_unix_us":1787932602154897,"recorded_utc":"2026-08-28T15:56:42.154897Z","schema_version":"nrrf810.exchange_authored_interactive_closure.v1","source_chain_continuous":true,"source_event":"order_created","source_event_id":"00065a1d-7fa1-5598-0002-000103000020","source_event_id_unique":true,"source_pre_event_id":"00065a1d-7fa1-5598-0001-000102000020","translation":"UNFOLD_TO_INF","unfold_event_id":null,"zero_hair":false}
{"channel":"live_orders_btcusd","interaction_index":589,"natural_form":{"channel":"live_orders_btcusd","order_id":"2044303881990146","order_subtype":5,"order_type":0},"natural_form_sha256":"2610f4fee02e36d953729b5589ba33048952c23aa9055eadbeecfc77761cea0e","order_source":"orderbook","orders_submitted":0,"presentation":{"amount":"0.25478772","amount_traded":"0","microtimestamp":"1787932602096000","price":"78496.71"},"previous_record_hash":"b35040a00f9a8d3c560cd573bae1f3df6372447e1232b76cff4eab9bd10ed970","profit_assessment":null,"record_hash":"c6cb8cce4486a70286116a9ce0431f55b0d74de9962771afdb9bb38ad3876662","recorded_unix_us":1787932602155058,"recorded_utc":"2026-08-28T15:56:42.155058Z","schema_version":"nrrf810.exchange_authored_interactive_closure.v1","source_chain_continuous":true,"source_event":"order_created","source_event_id":"00065a1d-7fa1-5980-0000-000100000020","source_event_id_unique":true,"source_pre_event_id":"00065a1d-7fa1-5598-0002-000103000020","translation":"UNFOLD_TO_INF","unfold_event_id":null,"zero_hair":false}
{"channel":"live_orders_btcusd","interaction_index":590,"natural_form":{"channel":"live_orders_btcusd","order_id":"2044303882002434","order_subtype":5,"order_type":0},"natural_form_sha256":"0aba38903703856ee95da3d52ea0e1b91b1150341e6a6c0992df06148975e9fe","order_source":"orderbook","orders_submitted":0,"presentation":{"amount":"1.27507828","amount_traded":"0","microtimestamp":"1787932602099000","price":"78426.55"},"previous_record_hash":"c6cb8cce4486a70286116a9ce0431f55b0d74de9962771afdb9bb38ad3876662","profit_assessment":null,"record_hash":"51f53aeab6c7f157b79b5603b8a58a05c4a50638e0d482b5e023a980ad7aa9e8","recorded_unix_us":1787932602155233,"recorded_utc":"2026-08-28T15:56:42.155233Z","schema_version":"nrrf810.exchange_authored_interactive_closure.v1","source_chain_continuous":true,"source_event":"order_created","source_event_id":"00065a1d-7fa1-6538-0000-000101000020","source_event_id_unique":true,"source_pre_event_id":"00065a1d-7fa1-5980-0000-000100000020","translation":"UNFOLD_TO_INF","unfold_event_id":null,"zero_hair":false}
{"channel":"live_orders_ethusd","interaction_index":591,"natural_form":{"channel":"live_orders_ethusd","order_id":"2044303881961472","order_subtype":5,"order_type":0},"natural_form_sha256":"502af49deefae0b5dec155d92a47be578075e2eeef550522c8789db3509b111c","order_source":"orderbook","orders_submitted":0,"presentation":{"amount":"0.562275","amount_traded":"0","microtimestamp":"1787932602100000","price":"2480.16"},"previous_record_hash":"51f53aeab6c7f157b79b5603b8a58a05c4a50638e0d482b5e023a980ad7aa9e8","profit_assessment":null,"record_hash":"013abf60222b5f1d5fb80a4d125e9f1e97b5e3f951825e4b0916a183e19e0502","recorded_unix_us":1787932602155289,"recorded_utc":"2026-08-28T15:56:42.155289Z","schema_version":"nrrf810.exchange_authored_interactive_closure.v1","source_chain_continuous":true,"source_event":"order_deleted","source_event_id":"00065a1d-7fa1-6920-0000-001202000020","source_event_id_unique":true,"source_pre_event_id":"00065a1d-7fa1-49e0-0000-001201000020","translation":"FOLD_RETURN_TO_ZERO","unfold_event_id":"00065a1d-7fa1-3e28-0000-001200000020","zero_hair":true}
{"channel":"live_orders_btcusd","interaction_index":592,"natural_form":{"channel":"live_orders_btcusd","order_id":"2044303882014723","order_subtype":5,"order_type":0},"natural_form_sha256":"68bbdf263bf5a587d528ddc0f579e00e6b090686b2aac278f54c5e8d30d60d76","order_source":"orderbook","orders_submitted":0,"presentation":{"amount":"1.27541152","amount_traded":"0","microtimestamp":"1787932602102000","price":"78406.06"},"previous_record_hash":"013abf60222b5f1d5fb80a4d125e9f1e97b5e3f951825e4b0916a183e19e0502","profit_assessment":null,"record_hash":"ac786708a283716d614261d38bfe61a9921fadc22b38a40c26e23afcf73d047c","recorded_unix_us":1787932602155435,"recorded_utc":"2026-08-28T15:56:42.155435Z","schema_version":"nrrf810.exchange_authored_interactive_closure.v1","source_chain_continuous":true,"source_event":"order_created","source_event_id":"00065a1d-7fa1-70f0-0000-000102000020","source_event_id_unique":true,"source_pre_event_id":"00065a1d-7fa1-6538-0000-000101000020","translation":"UNFOLD_TO_INF","unfold_event_id":null,"zero_hair":false}
{"channel":"live_orders_btcusd","interaction_index":593,"natural_form":{"channel":"live_orders_btcusd","order_id":"2044303882014724","order_subtype":5,"order_type":0},"natural_form_sha256":"9f835f356cc755e2171b3654ddeb84b7575fbde992582357a06361e7e8b223ac","order_source":"orderbook","orders_submitted":0,"presentation":{"amount":"12.76418733","amount_traded":"0","microtimestamp":"1787932602103000","price":"78344.19"},"previous_record_hash":"ac786708a283716d614261d38bfe61a9921fadc22b38a40c26e23afcf73d047c","profit_assessment":null,"record_hash":"54cbe7e5c4649d00a28a4d64aa4d88d861f344082eaf7fbc7529e0575eedfdad","recorded_unix_us":1787932602155471,"recorded_utc":"2026-08-28T15:56:42.155471Z","schema_version":"nrrf810.exchange_authored_interactive_closure.v1","source_chain_continuous":true,"source_event":"order_created","source_event_id":"00065a1d-7fa1-74d8-0000-000103000020","source_event_id_unique":true,"source_pre_event_id":"00065a1d-7fa1-70f0-0000-000102000020","translation":"UNFOLD_TO_INF","unfold_event_id":null,"zero_hair":false}
{"channel":"live_orders_btcusd","interaction_index":594,"natural_form":{"channel":"live_orders_btcusd","order_id":"2044303882018821","order_subtype":5,"order_type":0},"natural_form_sha256":"e9dc1c4435ca8e132bf716b76856a415190f60519f1f5ee68b31dfb014dbd68c","order_source":"orderbook","orders_submitted":0,"presentation":{"amount":"1.27567513","amount_traded":"0","microtimestamp":"1787932602104000","price":"78389.86"},"previous_record_hash":"54cbe7e5c4649d00a28a4d64aa4d88d861f344082eaf7fbc7529e0575eedfdad","profit_assessment":null,"record_hash":"dd534758f1184aa38035b050cb7de15c6545deffd2db55142c5f5749b07353e4","recorded_unix_us":1787932602155566,"recorded_utc":"2026-08-28T15:56:42.155566Z","schema_version":"nrrf810.exchange_authored_interactive_closure.v1","source_chain_continuous":true,"source_event":"order_created","source_event_id":"00065a1d-7fa1-78c0-0000-000100000020","source_event_id_unique":true,"source_pre_event_id":"00065a1d-7fa1-74d8-0000-000103000020","translation":"UNFOLD_TO_INF","unfold_event_id":null,"zero_hair":false}
{"channel":"live_orders_btcusd","interaction_index":595,"natural_form":{"channel":"live_orders_btcusd","order_id":"2044303882027014","order_subtype":5,"order_type":1},"natural_form_sha256":"9c75a6b6a9e050c80242b192cdb7111f689b27a7e86ecaf2fd6883d5abd207b6","order_source":"orderbook","orders_submitted":0,"presentation":{"amount":"0.06310787","amount_traded":"0","microtimestamp":"1787932602106000","price":"78520.73"},"previous_record_hash":"dd534758f1184aa38035b050cb7de15c6545deffd2db55142c5f5749b07353e4","profit_assessment":null,"record_hash":"224f0a66ed2b15b914fed1fffaa40852cd5d8f8a4ad393474ef3c69fd0f025ae","recorded_unix_us":1787932602155675,"recorded_utc":"2026-08-28T15:56:42.155675Z","schema_version":"nrrf810.exchange_authored_interactive_closure.v1","source_chain_continuous":true,"source_event":"order_created","source_event_id":"00065a1d-7fa1-8090-0000-000101000020","source_event_id_unique":true,"source_pre_event_id":"00065a1d-7fa1-78c0-0000-000100000020","translation":"UNFOLD_TO_INF","unfold_event_id":null,"zero_hair":false}
{"channel":"live_orders_btcusd","interaction_index":596,"natural_form":{"channel":"live_orders_btcusd","order_id":"2044303882027014","order_subtype":5,"order_type":1},"natural_form_sha256":"9c75a6b6a9e050c80242b192cdb7111f689b27a7e86ecaf2fd6883d5abd207b6","order_source":"orderbook","orders_submitted":0,"presentation":{"amount":"0.06310787","amount_traded":"0","microtimestamp":"1787932602106000","price":"78520.73"},"previous_record_hash":"224f0a66ed2b15b914fed1fffaa40852cd5d8f8a4ad393474ef3c69fd0f025ae","profit_assessment":null,"record_hash":"66f32359bb224db347f9ad5e78e7a1f94887095c13ce381b79c568d346afad2f","recorded_unix_us":1787932602155762,"recorded_utc":"2026-08-28T15:56:42.155762Z","schema_version":"nrrf810.exchange_authored_interactive_closure.v1","source_chain_continuous":true,"source_event":"order_deleted","source_event_id":"00065a1d-7fa1-8090-0001-000102000020","source_event_id_unique":true,"source_pre_event_id":"00065a1d-7fa1-8090-0000-000101000020","translation":"FOLD_RETURN_TO_ZERO","unfold_event_id":"00065a1d-7fa1-8090-0000-000101000020","zero_hair":true}
{"channel":"live_orders_btcusd","interaction_index":597,"natural_form":{"channel":"live_orders_btcusd","order_id":"2044303882031107","order_subtype":5,"order_type":0},"natural_form_sha256":"5e4c7260fa9f01b2d48def704f1128e4ee0103ba9579781f4340af1cfbe8c882","order_source":"orderbook","orders_submitted":0,"presentation":{"amount":"0.19104003","amount_traded":"0","microtimestamp":"1787932602107000","price":"78485.62"},"previous_record_hash":"66f32359bb224db347f9ad5e78e7a1f94887095c13ce381b79c568d346afad2f","profit_assessment":null,"record_hash":"3d07099083b01c6d1586faa75e8d25837d0731aba0c1a533f1af173f5746e8c0","recorded_unix_us":1787932602155854,"recorded_utc":"2026-08-28T15:56:42.155854Z","schema_version":"nrrf810.exchange_authored_interactive_closure.v1","source_chain_continuous":true,"source_event":"order_created","source_event_id":"00065a1d-7fa1-8478-0000-000103000020","source_event_id_unique":true,"source_pre_event_id":"00065a1d-7fa1-8090-0001-000102000020","translation":"UNFOLD_TO_INF","unfold_event_id":null,"zero_hair":false}
{"channel":"live_orders_ethusd","interaction_index":598,"natural_form":{"channel":"live_orders_ethusd","order_id":"2044303881793543","order_subtype":5,"order_type":0},"natural_form_sha256":"bc389985d9f9731445a9faf7d9a5b05135ac6f4ca732ebf096ec130e782171fd","order_source":"orderbook","orders_submitted":0,"presentation":{"amount":"0.403090","amount_traded":"0","microtimestamp":"1787932602107000","price":"2480.01"},"previous_record_hash":"3d07099083b01c6d1586faa75e8d25837d0731aba0c1a533f1af173f5746e8c0","profit_assessment":null,"record_hash":"3f665aa7aec1316f6c6f803dca39d016be8f0695e8a10c11b681cff2a0067fdf","recorded_unix_us":1787932602155968,"recorded_utc":"2026-08-28T15:56:42.155968Z","schema_version":"nrrf810.exchange_authored_interactive_closure.v1","source_chain_continuous":true,"source_event":"order_deleted","source_event_id":"00065a1d-7fa1-8478-0000-001203000020","source_event_id_unique":true,"source_pre_event_id":"00065a1d-7fa1-6920-0000-001202000020","translation":"FOLD_RETURN_TO_ZERO","unfold_event_id":"00065a1d-7fa0-9e00-0000-001200000020","zero_hair":true}
{"channel":"live_orders_btcusd","interaction_index":599,"natural_form":{"channel":"live_orders_btcusd","order_id":"2044303882035207","order_subtype":5,"order_type":0},"natural_form_sha256":"6e66bff44df61439df6115460f7b61d767c60d6f4c7e258729bd776f9179ceb4","order_source":"orderbook","orders_submitted":0,"presentation":{"amount":"1.27757154","amount_traded":"0","microtimestamp":"1787932602107000","price":"78273.50"},"previous_record_hash":"3f665aa7aec1316f6c6f803dca39d016be8f0695e8a10c11b681cff2a0067fdf","profit_assessment":null,"record_hash":"d6e3803333cba489c5915170e3ee9aa04d1c404c87eadfe66709adaf8a5db7d2","recorded_unix_us":1787932602155999,"recorded_utc":"2026-08-28T15:56:42.155999Z","schema_version":"nrrf810.exchange_authored_interactive_closure.v1","source_chain_continuous":true,"source_event":"order_created","source_event_id":"00065a1d-7fa1-8478-0001-000100000020","source_event_id_unique":true,"source_pre_event_id":"00065a1d-7fa1-8478-0000-000103000020","translation":"UNFOLD_TO_INF","unfold_event_id":null,"zero_hair":false}
{"channel":"live_orders_btcusd","interaction_index":600,"natural_form":{"channel":"live_orders_btcusd","order_id":"2044303882035211","order_subtype":5,"order_type":1},"natural_form_sha256":"537f8877337e8c0767fe0518cb1910875f8f034d4c7c933812b324eed6941729","order_source":"orderbook","orders_submitted":0,"presentation":{"amount":"0.10000000","amount_traded":"0","microtimestamp":"1787932602108000","price":"78522.62"},"previous_record_hash":"d6e3803333cba489c5915170e3ee9aa04d1c404c87eadfe66709adaf8a5db7d2","profit_assessment":null,"record_hash":"b4676836d294464fc6ebd8bb3bff4322640cd0f816de717ba5836404ab6a8acc","recorded_unix_us":1787932602156114,"recorded_utc":"2026-08-28T15:56:42.156114Z","schema_version":"nrrf810.exchange_authored_interactive_closure.v1","source_chain_continuous":true,"source_event":"order_created","source_event_id":"00065a1d-7fa1-8860-0000-000101000020","source_event_id_unique":true,"source_pre_event_id":"00065a1d-7fa1-8478-0001-000100000020","translation":"UNFOLD_TO_INF","unfold_event_id":null,"zero_hair":false}
{"channel":"live_orders_btcusd","interaction_index":601,"natural_form":{"channel":"live_orders_btcusd","order_id":"2044303882035211","order_subtype":5,"order_type":1},"natural_form_sha256":"537f8877337e8c0767fe0518cb1910875f8f034d4c7c933812b324eed6941729","order_source":"orderbook","orders_submitted":0,"presentation":{"amount":"0.10000000","amount_traded":"0","microtimestamp":"1787932602108000","price":"78522.62"},"previous_record_hash":"b4676836d294464fc6ebd8bb3bff4322640cd0f816de717ba5836404ab6a8acc","profit_assessment":null,"record_hash":"a9a1b8f984bf0ff82f1d210252ec6cbf28102f5ae969c3d721595fcea12b1292","recorded_unix_us":1787932602156143,"recorded_utc":"2026-08-28T15:56:42.156143Z","schema_version":"nrrf810.exchange_authored_interactive_closure.v1","source_chain_continuous":true,"source_event":"order_deleted","source_event_id":"00065a1d-7fa1-8860-0001-000102000020","source_event_id_unique":true,"source_pre_event_id":"00065a1d-7fa1-8860-0000-000101000020","translation":"FOLD_RETURN_TO_ZERO","unfold_event_id":"00065a1d-7fa1-8860-0000-000101000020","zero_hair":true}
{"channel":"live_orders_btcusd","interaction_index":602,"natural_form":{"channel":"live_orders_btcusd","order_id":"2044303882039300","order_subtype":5,"order_type":0},"natural_form_sha256":"0fd3b2688f12c46cee724a57e30bb42e3d39559f54630faaae61d40eb34e0ae5","order_source":"orderbook","orders_submitted":0,"presentation":{"amount":"0.63680011","amount_traded":"0","microtimestamp":"1787932602108000","price":"78483.66"},"previous_record_hash":"a9a1b8f984bf0ff82f1d210252ec6cbf28102f5ae969c3d721595fcea12b1292","profit_assessment":null,"record_hash":"0978bdb66ef55d5fd88074076a467b8f37b72842570080adc82f6f3284ffd731","recorded_unix_us":1787932602156221,"recorded_utc":"2026-08-28T15:56:42.156221Z","schema_version":"nrrf810.exchange_authored_interactive_closure.v1","source_chain_continuous":true,"source_event":"order_created","source_event_id":"00065a1d-7fa1-8860-0002-000103000020","source_event_id_unique":true,"source_pre_event_id":"00065a1d-7fa1-8860-0001-000102000020","translation":"UNFOLD_TO_INF","unfold_event_id":null,"zero_hair":false}
{"channel":"live_orders_btcusd","interaction_index":603,"natural_form":{"channel":"live_orders_btcusd","order_id":"2044303882039302","order_subtype":5,"order_type":0},"natural_form_sha256":"2547021919789e4dcb3bb2a460e4094fd281aa4010a83d440726757d9ff103c8","order_source":"orderbook","orders_submitted":0,"presentation":{"amount":"0.50944009","amount_traded":"0","microtimestamp":"1787932602109000","price":"78481.69"},"previous_record_hash":"0978bdb66ef55d5fd88074076a467b8f37b72842570080adc82f6f3284ffd731","profit_assessment":null,"record_hash":"56e89352fb1644cb4522fae7d5b906f8abafdc422ebf2c25237924edf62136d9","recorded_unix_us":1787932602156302,"recorded_utc":"2026-08-28T15:56:42.156302Z","schema_version":"nrrf810.exchange_authored_interactive_closure.v1","source_chain_continuous":true,"source_event":"order_created","source_event_id":"00065a1d-7fa1-8c48-0000-000100000020","source_event_id_unique":true,"source_pre_event_id":"00065a1d-7fa1-8860-0002-000103000020","translation":"UNFOLD_TO_INF","unfold_event_id":null,"zero_hair":false}
{"channel":"live_orders_ethusd","interaction_index":604,"natural_form":{"channel":"live_orders_ethusd","order_id":"2044303882043392","order_subtype":5,"order_type":0},"natural_form_sha256":"ae3a23a4d263c0e8089e8b93f81a0e79a0b88f2af3bb174436675fd520e11623","order_source":"orderbook","orders_submitted":0,"presentation":{"amount":"0.546944","amount_traded":"0","microtimestamp":"1787932602109000","price":"2480.10"},"previous_record_hash":"56e89352fb1644cb4522fae7d5b906f8abafdc422ebf2c25237924edf62136d9","profit_assessment":null,"record_hash":"1fd7bf95787fb81cb79558a3a744edd23556e5ff0c2ac1db81e3415538d96b29","recorded_unix_us":1787932602156380,"recorded_utc":"2026-08-28T15:56:42.156380Z","schema_version":"nrrf810.exchange_authored_interactive_closure.v1","source_chain_continuous":true,"source_event":"order_created","source_event_id":"00065a1d-7fa1-8c48-0000-001200000020","source_event_id_unique":true,"source_pre_event_id":"00065a1d-7fa1-8478-0000-001203000020","translation":"UNFOLD_TO_INF","unfold_event_id":null,"zero_hair":false}
{"channel":"live_orders_ethusd","interaction_index":605,"natural_form":{"channel":"live_orders_ethusd","order_id":"2044303882072069","order_subtype":5,"order_type":0},"natural_form_sha256":"2d10115c771acfa6588ef9dafcd33d45f338303dcbec66c0dc3f9f18c7dfbe56","order_source":"orderbook","orders_submitted":0,"presentation":{"amount":"0.403091","amount_traded":"0","microtimestamp":"1787932602116000","price":"2479.96"},"previous_record_hash":"1fd7bf95787fb81cb79558a3a744edd23556e5ff0c2ac1db81e3415538d96b29","profit_assessment":null,"record_hash":"73ba8614ca1e53c9a1f19d858776505559534eca27b6ca1e146703bd88f9456b","recorded_unix_us":1787932602156465,"recorded_utc":"2026-08-28T15:56:42.156465Z","schema_version":"nrrf810.exchange_authored_interactive_closure.v1","source_chain_continuous":true,"source_event":"order_created","source_event_id":"00065a1d-7fa1-a7a0-0000-001201000020","source_event_id_unique":true,"source_pre_event_id":"00065a1d-7fa1-8c48-0000-001200000020","translation":"UNFOLD_TO_INF","unfold_event_id":null,"zero_hair":false}
{"channel":"live_orders_ethbtc","interaction_index":606,"natural_form":{"channel":"live_orders_ethbtc","order_id":"2044303882088448","order_subtype":5,"order_type":1},"natural_form_sha256":"49f67cdc3f2503712d4b78850f8a9e9332aed40251d6f607eceee0ae10a8a8b8","order_source":"orderbook","orders_submitted":0,"presentation":{"amount":"0.03720000","amount_traded":"0","microtimestamp":"1787932602120000","price":"0.03162890"},"previous_record_hash":"73ba8614ca1e53c9a1f19d858776505559534eca27b6ca1e146703bd88f9456b","profit_assessment":null,"record_hash":"0eb88a7f86c322f16cfead61a87bccee5df1566ae1d14fb3a36e68cd16c1a870","recorded_unix_us":1787932602156590,"recorded_utc":"2026-08-28T15:56:42.156590Z","schema_version":"nrrf810.exchange_authored_interactive_closure.v1","source_chain_continuous":true,"source_event":"order_created","source_event_id":"00065a1d-7fa1-b740-0000-001101000020","source_event_id_unique":true,"source_pre_event_id":"00065a1d-7fa0-d898-0000-001100000020","translation":"UNFOLD_TO_INF","unfold_event_id":null,"zero_hair":false}
{"channel":"live_orders_ethusd","interaction_index":607,"natural_form":{"channel":"live_orders_ethusd","order_id":"2044303882043392","order_subtype":5,"order_type":0},"natural_form_sha256":"ae3a23a4d263c0e8089e8b93f81a0e79a0b88f2af3bb174436675fd520e11623","order_source":"orderbook","orders_submitted":0,"presentation":{"amount":"0.546944","amount_traded":"0","microtimestamp":"1787932602121000","price":"2480.10"},"previous_record_hash":"0eb88a7f86c322f16cfead61a87bccee5df1566ae1d14fb3a36e68cd16c1a870","profit_assessment":null,"record_hash":"96658818c08127d6b2d567dd0dbc2be97059123c07e6c149b7eb5cbfbb206ab2","recorded_unix_us":1787932602163356,"recorded_utc":"2026-08-28T15:56:42.163356Z","schema_version":"nrrf810.exchange_authored_interactive_closure.v1","source_chain_continuous":true,"source_event":"order_deleted","source_event_id":"00065a1d-7fa1-bb28-0000-001202000020","source_event_id_unique":true,"source_pre_event_id":"00065a1d-7fa1-a7a0-0000-001201000020","translation":"FOLD_RETURN_TO_ZERO","unfold_event_id":"00065a1d-7fa1-8c48-0000-001200000020","zero_hair":true}
{"channel":"live_orders_btcusd","interaction_index":608,"natural_form":{"channel":"live_orders_btcusd","order_id":"2044303882096644","order_subtype":5,"order_type":1},"natural_form_sha256":"5d22077be44ef014b9295ed0a015fbcd67c790075fc6d19d98a2cf856573036d","order_source":"orderbook","orders_submitted":0,"presentation":{"amount":"1.27177200","amount_traded":"0","microtimestamp":"1787932602123000","price":"78630.45"},"previous_record_hash":"96658818c08127d6b2d567dd0dbc2be97059123c07e6c149b7eb5cbfbb206ab2","profit_assessment":null,"record_hash":"3478cc118975e8f60c3db114a9d6610d86f084dc6e4042146d0452d6e232a967","recorded_unix_us":1787932602163491,"recorded_utc":"2026-08-28T15:56:42.163491Z","schema_version":"nrrf810.exchange_authored_interactive_closure.v1","source_chain_continuous":true,"source_event":"order_created","source_event_id":"00065a1d-7fa1-c2f8-0000-000101000020","source_event_id_unique":true,"source_pre_event_id":"00065a1d-7fa1-8c48-0000-000100000020","translation":"UNFOLD_TO_INF","unfold_event_id":null,"zero_hair":false}
{"channel":"live_orders_btcusd","interaction_index":609,"natural_form":{"channel":"live_orders_btcusd","order_id":"2044303882104836","order_subtype":5,"order_type":1},"natural_form_sha256":"cbe9064087ac3549f7edb93f1f541e72155ac337093a0e78f32db027c9ed6dc0","order_source":"orderbook","orders_submitted":0,"presentation":{"amount":"0.10000000","amount_traded":"0","microtimestamp":"1787932602124000","price":"78522.63"},"previous_record_hash":"3478cc118975e8f60c3db114a9d6610d86f084dc6e4042146d0452d6e232a967","profit_assessment":null,"record_hash":"b72d960d355bf0e677cff9715402754924c48b2d42f8626c40cfbd6db3cb5e49","recorded_unix_us":1787932602167112,"recorded_utc":"2026-08-28T15:56:42.167112Z","schema_version":"nrrf810.exchange_authored_interactive_closure.v1","source_chain_continuous":true,"source_event":"order_created","source_event_id":"00065a1d-7fa1-c6e0-0000-000102000020","source_event_id_unique":true,"source_pre_event_id":"00065a1d-7fa1-c2f8-0000-000101000020","translation":"UNFOLD_TO_INF","unfold_event_id":null,"zero_hair":false}
{"channel":"live_orders_btcusd","interaction_index":610,"natural_form":{"channel":"live_orders_btcusd","order_id":"2044303882104836","order_subtype":5,"order_type":1},"natural_form_sha256":"cbe9064087ac3549f7edb93f1f541e72155ac337093a0e78f32db027c9ed6dc0","order_source":"orderbook","orders_submitted":0,"presentation":{"amount":"0.10000000","amount_traded":"0","microtimestamp":"1787932602124000","price":"78522.63"},"previous_record_hash":"b72d960d355bf0e677cff9715402754924c48b2d42f8626c40cfbd6db3cb5e49","profit_assessment":null,"record_hash":"0c90f404e897ec6bab413b969eec7e97d9b33953e68701a339391fd3d5cc0de3","recorded_unix_us":1787932602167311,"recorded_utc":"2026-08-28T15:56:42.167311Z","schema_version":"nrrf810.exchange_authored_interactive_closure.v1","source_chain_continuous":true,"source_event":"order_deleted","source_event_id":"00065a1d-7fa1-c6e0-0001-000103000020","source_event_id_unique":true,"source_pre_event_id":"00065a1d-7fa1-c6e0-0000-000102000020","translation":"FOLD_RETURN_TO_ZERO","unfold_event_id":"00065a1d-7fa1-c6e0-0000-000102000020","zero_hair":true}
{"channel":"live_orders_btcusd","interaction_index":611,"natural_form":{"channel":"live_orders_btcusd","order_id":"2044303882104841","order_subtype":5,"order_type":0},"natural_form_sha256":"6e28dd2b5311182d4fded92cb2b8132604649a74e8e3071be198f0970b4f9fa7","order_source":"orderbook","orders_submitted":0,"presentation":{"amount":"1.27604867","amount_traded":"0","microtimestamp":"1787932602125000","price":"78366.91"},"previous_record_hash":"0c90f404e897ec6bab413b969eec7e97d9b33953e68701a339391fd3d5cc0de3","profit_assessment":null,"record_hash":"e252f0c43026b2b2baed3c7f9f8c78c3ef51ead58fbcb4b4c44fe675b55c005a","recorded_unix_us":1787932602167374,"recorded_utc":"2026-08-28T15:56:42.167374Z","schema_version":"nrrf810.exchange_authored_interactive_closure.v1","source_chain_continuous":true,"source_event":"order_created","source_event_id":"00065a1d-7fa1-cac8-0000-000100000020","source_event_id_unique":true,"source_pre_event_id":"00065a1d-7fa1-c6e0-0001-000103000020","translation":"UNFOLD_TO_INF","unfold_event_id":null,"zero_hair":false}
{"channel":"live_orders_btcusd","interaction_index":612,"natural_form":{"channel":"live_orders_btcusd","order_id":"2044303882108933","order_subtype":5,"order_type":1},"natural_form_sha256":"afea37422e778d6590df4b009d5aad1080b9b71e2846588536fc18f213f2b24f","order_source":"orderbook","orders_submitted":0,"presentation":{"amount":"1.26842789","amount_traded":"0","microtimestamp":"1787932602125000","price":"78837.75"},"previous_record_hash":"e252f0c43026b2b2baed3c7f9f8c78c3ef51ead58fbcb4b4c44fe675b55c005a","profit_assessment":null,"record_hash":"dbdf6d738497be38ee20da82380a9972f3d4f0d04344c6b2eedc45b657879c19","recorded_unix_us":1787932602173645,"recorded_utc":"2026-08-28T15:56:42.173645Z","schema_version":"nrrf810.exchange_authored_interactive_closure.v1","source_chain_continuous":true,"source_event":"order_created","source_event_id":"00065a1d-7fa1-cac8-0001-000101000020","source_event_id_unique":true,"source_pre_event_id":"00065a1d-7fa1-cac8-0000-000100000020","translation":"UNFOLD_TO_INF","unfold_event_id":null,"zero_hair":false}
{"channel":"live_orders_btcusd","interaction_index":613,"natural_form":{"channel":"live_orders_btcusd","order_id":"2044303881863168","order_subtype":5,"order_type":0},"natural_form_sha256":"ee8297b5006d8c9a50534f4b2c5c5856e30a45a1409278f3e3102303a5a00d9c","order_source":"orderbook","orders_submitted":0,"presentation":{"amount":"0.00140266","amount_traded":"0","microtimestamp":"1787932602126000","price":"70666.76"},"previous_record_hash":"dbdf6d738497be38ee20da82380a9972f3d4f0d04344c6b2eedc45b657879c19","profit_assessment":null,"record_hash":"4048b5bff5a7ef426bd141c4f9de257545bfe87f4b7f646cf63ef3fa79f7fb17","recorded_unix_us":1787932602173721,"recorded_utc":"2026-08-28T15:56:42.173721Z","schema_version":"nrrf810.exchange_authored_interactive_closure.v1","source_chain_continuous":true,"source_event":"order_deleted","source_event_id":"00065a1d-7fa1-ceb0-0000-000102000020","source_event_id_unique":true,"source_pre_event_id":"00065a1d-7fa1-cac8-0001-000101000020","translation":"FOLD_RETURN_TO_ZERO","unfold_event_id":"00065a1d-7fa0-e068-0000-000101000020","zero_hair":true}
{"channel":"live_orders_btcusd","interaction_index":614,"natural_form":{"channel":"live_orders_btcusd","order_id":"2044303882113034","order_subtype":5,"order_type":0},"natural_form_sha256":"97e7cfec0547f3be34c957b190ce25886aa58141ea3e57d2688358e76f126520","order_source":"orderbook","orders_submitted":0,"presentation":{"amount":"0.06368171","amount_traded":"0","microtimestamp":"1787932602127000","price":"78515.46"},"previous_record_hash":"4048b5bff5a7ef426bd141c4f9de257545bfe87f4b7f646cf63ef3fa79f7fb17","profit_assessment":null,"record_hash":"c3ade46024a72158ec533e392f00b78a53d48230940f3a00e0888132c771dfdc","recorded_unix_us":1787932602173837,"recorded_utc":"2026-08-28T15:56:42.173837Z","schema_version":"nrrf810.exchange_authored_interactive_closure.v1","source_chain_continuous":true,"source_event":"order_created","source_event_id":"00065a1d-7fa1-d298-0000-000103000020","source_event_id_unique":true,"source_pre_event_id":"00065a1d-7fa1-ceb0-0000-000102000020","translation":"UNFOLD_TO_INF","unfold_event_id":null,"zero_hair":false}
{"channel":"live_orders_btcusd","interaction_index":615,"natural_form":{"channel":"live_orders_btcusd","order_id":"2044303882117122","order_subtype":5,"order_type":0},"natural_form_sha256":"503e79041937b17ba90ab3e6c8fc00d5c0cfadf3b643abfcb1f146055a34eef4","order_source":"orderbook","orders_submitted":0,"presentation":{"amount":"1.27817952","amount_traded":"0","microtimestamp":"1787932602127000","price":"78236.27"},"previous_record_hash":"c3ade46024a72158ec533e392f00b78a53d48230940f3a00e0888132c771dfdc","profit_assessment":null,"record_hash":"058062328ee5cb48e0a6e4acc8bb6a136883f4894cf11a3dea956704b610666b","recorded_unix_us":1787932602173959,"recorded_utc":"2026-08-28T15:56:42.173959Z","schema_version":"nrrf810.exchange_authored_interactive_closure.v1","source_chain_continuous":true,"source_event":"order_created","source_event_id":"00065a1d-7fa1-d298-0001-000100000020","source_event_id_unique":true,"source_pre_event_id":"00065a1d-7fa1-d298-0000-000103000020","translation":"UNFOLD_TO_INF","unfold_event_id":null,"zero_hair":false}
{"channel":"live_orders_ethusd","interaction_index":616,"natural_form":{"channel":"live_orders_ethusd","order_id":"2044303882133515","order_subtype":5,"order_type":0},"natural_form_sha256":"2dc54b6b1e1e8fa8cab17e3c6c4206ddd7ecf82c97622e7c4aceee9428138f01","order_source":"orderbook","orders_submitted":0,"presentation":{"amount":"0.481961","amount_traded":"0","microtimestamp":"1787932602132000","price":"2480.02"},"previous_record_hash":"058062328ee5cb48e0a6e4acc8bb6a136883f4894cf11a3dea956704b610666b","profit_assessment":null,"record_hash":"a795927fbd6f6ae7d8d0980ac4148855f8e77a37308ff2a755b96d9e48004b30","recorded_unix_us":1787932602174082,"recorded_utc":"2026-08-28T15:56:42.174082Z","schema_version":"nrrf810.exchange_authored_interactive_closure.v1","source_chain_continuous":true,"source_event":"order_created","source_event_id":"00065a1d-7fa1-e620-0000-001203000020","source_event_id_unique":true,"source_pre_event_id":"00065a1d-7fa1-bb28-0000-001202000020","translation":"UNFOLD_TO_INF","unfold_event_id":null,"zero_hair":false}
{"channel":"live_orders_btcusd","interaction_index":617,"natural_form":{"channel":"live_orders_btcusd","order_id":"2044303882149893","order_subtype":5,"order_type":1},"natural_form_sha256":"5e120fb784381988b94dbbfced52a60a6445283802367181d46c0f85a6907b84","order_source":"orderbook","orders_submitted":0,"presentation":{"amount":"0.06310787","amount_traded":"0","microtimestamp":"1787932602136000","price":"78522.06"},"previous_record_hash":"a795927fbd6f6ae7d8d0980ac4148855f8e77a37308ff2a755b96d9e48004b30","profit_assessment":null,"record_hash":"be1b495364d3859b055614c8e087cd5fd7a2d5a73f63c8f5f659bbd9cd135de5","recorded_unix_us":1787932602179333,"recorded_utc":"2026-08-28T15:56:42.179333Z","schema_version":"nrrf810.exchange_authored_interactive_closure.v1","source_chain_continuous":true,"source_event":"order_created","source_event_id":"00065a1d-7fa1-f5c0-0000-000101000020","source_event_id_unique":true,"source_pre_event_id":"00065a1d-7fa1-d298-0001-000100000020","translation":"UNFOLD_TO_INF","unfold_event_id":null,"zero_hair":false}
{"channel":"live_orders_btcusd","interaction_index":618,"natural_form":{"channel":"live_orders_btcusd","order_id":"2044303882149893","order_subtype":5,"order_type":1},"natural_form_sha256":"5e120fb784381988b94dbbfced52a60a6445283802367181d46c0f85a6907b84","order_source":"orderbook","orders_submitted":0,"presentation":{"amount":"0.06310787","amount_traded":"0","microtimestamp":"1787932602136000","price":"78522.06"},"previous_record_hash":"be1b495364d3859b055614c8e087cd5fd7a2d5a73f63c8f5f659bbd9cd135de5","profit_assessment":null,"record_hash":"5a6b518157532c1a7857a572f44dea71002a5c21bdbf2babc46405824830f2e8","recorded_unix_us":1787932602179404,"recorded_utc":"2026-08-28T15:56:42.179404Z","schema_version":"nrrf810.exchange_authored_interactive_closure.v1","source_chain_continuous":true,"source_event":"order_deleted","source_event_id":"00065a1d-7fa1-f5c0-0001-000102000020","source_event_id_unique":true,"source_pre_event_id":"00065a1d-7fa1-f5c0-0000-000101000020","translation":"FOLD_RETURN_TO_ZERO","unfold_event_id":"00065a1d-7fa1-f5c0-0000-000101000020","zero_hair":true}
{"channel":"live_orders_ethusd","interaction_index":619,"natural_form":{"channel":"live_orders_ethusd","order_id":"2044303877349390","order_subtype":5,"order_type":1},"natural_form_sha256":"0bcf2456f20297ba1de8274557fdb861b56e80c9e1c6fa12c9c452cb42be4703","order_source":"orderbook","orders_submitted":0,"presentation":{"amount":"1.000000","amount_traded":"0","microtimestamp":"1787932602141000","price":"2480.82"},"previous_record_hash":"5a6b518157532c1a7857a572f44dea71002a5c21bdbf2babc46405824830f2e8","profit_assessment":null,"record_hash":"e8477005d17a996c297c27b027265cb7d8c4c49ddffa4c4658bd09a607c24fc2","recorded_unix_us":1787932602179564,"recorded_utc":"2026-08-28T15:56:42.179564Z","schema_version":"nrrf810.exchange_authored_interactive_closure.v1","source_chain_continuous":true,"source_event":"order_deleted","source_event_id":"00065a1d-7fa2-0948-0000-001200000020","source_event_id_unique":true,"source_pre_event_id":"00065a1d-7fa1-e620-0000-001203000020","translation":"PARTIAL_PRIOR_UNFOLD","unfold_event_id":null,"zero_hair":false}
{"channel":"live_orders_btcusd","interaction_index":620,"natural_form":{"channel":"live_orders_btcusd","order_id":"2044303882178560","order_subtype":5,"order_type":1},"natural_form_sha256":"6e151f0077bae4cca911079b390ac47e1c670caf9cd808f6d5587a30d20334c1","order_source":"orderbook","orders_submitted":0,"presentation":{"amount":"1.27145262","amount_traded":"0","microtimestamp":"1787932602142000","price":"78650.20"},"previous_record_hash":"e8477005d17a996c297c27b027265cb7d8c4c49ddffa4c4658bd09a607c24fc2","profit_assessment":null,"record_hash":"f62b62dd31b42f0ec958b1b61c18b1a024e8bea02c61ea47f1fd7d5f896d8cd5","recorded_unix_us":1787932602179604,"recorded_utc":"2026-08-28T15:56:42.179604Z","schema_version":"nrrf810.exchange_authored_interactive_closure.v1","source_chain_continuous":true,"source_event":"order_created","source_event_id":"00065a1d-7fa2-0d30-0000-000103000020","source_event_id_unique":true,"source_pre_event_id":"00065a1d-7fa1-f5c0-0001-000102000020","translation":"UNFOLD_TO_INF","unfold_event_id":null,"zero_hair":false}
{"channel":"live_orders_btcusd","interaction_index":621,"natural_form":{"channel":"live_orders_btcusd","order_id":"2044303882186762","order_subtype":5,"order_type":0},"natural_form_sha256":"d7a4708931494fb7e275f9f5d40755582de7e886c2434a4eaa040e47c7ddbb06","order_source":"orderbook","orders_submitted":0,"presentation":{"amount":"1.27888333","amount_traded":"0","microtimestamp":"1787932602144000","price":"78193.21"},"previous_record_hash":"f62b62dd31b42f0ec958b1b61c18b1a024e8bea02c61ea47f1fd7d5f896d8cd5","profit_assessment":null,"record_hash":"4a8612b357f6c07a9e4cd3c33da815514d1461db28fd962a971a2ba669fde9dd","recorded_unix_us":1787932602179728,"recorded_utc":"2026-08-28T15:56:42.179728Z","schema_version":"nrrf810.exchange_authored_interactive_closure.v1","source_chain_continuous":true,"source_event":"order_created","source_event_id":"00065a1d-7fa2-1500-0000-000100000020","source_event_id_unique":true,"source_pre_event_id":"00065a1d-7fa2-0d30-0000-000103000020","translation":"UNFOLD_TO_INF","unfold_event_id":null,"zero_hair":false}
{"channel":"live_orders_btcusd","interaction_index":622,"natural_form":{"channel":"live_orders_btcusd","order_id":"2044303882190850","order_subtype":5,"order_type":0},"natural_form_sha256":"b480493d01210377a3fffc3bc6e93089d19e756170d95f16c03106ae2c2b4d9f","order_source":"orderbook","orders_submitted":0,"presentation":{"amount":"0.00140266","amount_traded":"0","microtimestamp":"1787932602145000","price":"70668.36"},"previous_record_hash":"4a8612b357f6c07a9e4cd3c33da815514d1461db28fd962a971a2ba669fde9dd","profit_assessment":null,"record_hash":"2deeb6cf68fb94a3379447f7d2e37386b48d1150fd9f41f6a0783505632d5e84","recorded_unix_us":1787932602179859,"recorded_utc":"2026-08-28T15:56:42.179859Z","schema_version":"nrrf810.exchange_authored_interactive_closure.v1","source_chain_continuous":true,"source_event":"order_created","source_event_id":"00065a1d-7fa2-18e8-0000-000101000020","source_event_id_unique":true,"source_pre_event_id":"00065a1d-7fa2-1500-0000-000100000020","translation":"UNFOLD_TO_INF","unfold_event_id":null,"zero_hair":false}
{"channel":"live_orders_ethusd","interaction_index":623,"natural_form":{"channel":"live_orders_ethusd","order_id":"2044303881252867","order_subtype":5,"order_type":1},"natural_form_sha256":"11f7659d1d62ad535b4c446e0bcf664f3d9248f2b06f6e98f74d81e232000660","order_source":"orderbook","orders_submitted":0,"presentation":{"amount":"12.087961","amount_traded":"0","microtimestamp":"1787932602146000","price":"2481.81"},"previous_record_hash":"2deeb6cf68fb94a3379447f7d2e37386b48d1150fd9f41f6a0783505632d5e84","profit_assessment":null,"record_hash":"b83d4c930eb2097a43fc8e9c1e30317ea2d3bdac2ddf1b754409bd1930be5fd7","recorded_unix_us":1787932602180058,"recorded_utc":"2026-08-28T15:56:42.180058Z","schema_version":"nrrf810.exchange_authored_interactive_closure.v1","source_chain_continuous":true,"source_event":"order_deleted","source_event_id":"00065a1d-7fa2-1cd0-0000-001201000020","source_event_id_unique":true,"source_pre_event_id":"00065a1d-7fa2-0948-0000-001200000020","translation":"FOLD_RETURN_TO_ZERO","unfold_event_id":"00065a1d-7f9e-9a60-0000-001203000020","zero_hair":true}
{"channel":"live_orders_ethusd","interaction_index":624,"natural_form":{"channel":"live_orders_ethusd","order_id":"2044303881302021","order_subtype":5,"order_type":0},"natural_form_sha256":"dbb7455894a90e33c66f709fa260ffb01200295cc4f712ab171e0fc12c582f81","order_source":"orderbook","orders_submitted":0,"presentation":{"amount":"12.096046","amount_traded":"0","microtimestamp":"1787932602147000","price":"2480.14"},"previous_record_hash":"b83d4c930eb2097a43fc8e9c1e30317ea2d3bdac2ddf1b754409bd1930be5fd7","profit_assessment":null,"record_hash":"891f52d6d495fd5598017155a2dbdf9670e380c6efee0397b6f65dd9e347ba68","recorded_unix_us":1787932602180094,"recorded_utc":"2026-08-28T15:56:42.180094Z","schema_version":"nrrf810.exchange_authored_interactive_closure.v1","source_chain_continuous":true,"source_event":"order_deleted","source_event_id":"00065a1d-7fa2-20b8-0000-001202000020","source_event_id_unique":true,"source_pre_event_id":"00065a1d-7fa2-1cd0-0000-001201000020","translation":"FOLD_RETURN_TO_ZERO","unfold_event_id":"00065a1d-7f9e-cd28-0000-001201000020","zero_hair":true}
{"channel":"live_orders_btcusd","interaction_index":625,"natural_form":{"channel":"live_orders_btcusd","order_id":"2044303882199041","order_subtype":5,"order_type":1},"natural_form_sha256":"367349b379cd7327e83b4cf36d2c1bce7b913212e96f7c532cbc70f348865167","order_source":"orderbook","orders_submitted":0,"presentation":{"amount":"0.10000000","amount_traded":"0","microtimestamp":"1787932602148000","price":"78522.62"},"previous_record_hash":"891f52d6d495fd5598017155a2dbdf9670e380c6efee0397b6f65dd9e347ba68","profit_assessment":null,"record_hash":"e1b853eb8214c8a441cea32275c4a9befbea76886775fc4d7992ba6e237c7e28","recorded_unix_us":1787932602180124,"recorded_utc":"2026-08-28T15:56:42.180124Z","schema_version":"nrrf810.exchange_authored_interactive_closure.v1","source_chain_continuous":true,"source_event":"order_created","source_event_id":"00065a1d-7fa2-24a0-0000-000102000020","source_event_id_unique":true,"source_pre_event_id":"00065a1d-7fa2-18e8-0000-000101000020","translation":"UNFOLD_TO_INF","unfold_event_id":null,"zero_hair":false}
{"channel":"live_orders_btcusd","interaction_index":626,"natural_form":{"channel":"live_orders_btcusd","order_id":"2044303882199041","order_subtype":5,"order_type":1},"natural_form_sha256":"367349b379cd7327e83b4cf36d2c1bce7b913212e96f7c532cbc70f348865167","order_source":"orderbook","orders_submitted":0,"presentation":{"amount":"0.10000000","amount_traded":"0","microtimestamp":"1787932602148000","price":"78522.62"},"previous_record_hash":"e1b853eb8214c8a441cea32275c4a9befbea76886775fc4d7992ba6e237c7e28","profit_assessment":null,"record_hash":"f0dcadcf629f7d1f78ed7b8130dc4b3050ada69b68379eb9da3cac30c0e5dbfd","recorded_unix_us":1787932602180319,"recorded_utc":"2026-08-28T15:56:42.180319Z","schema_version":"nrrf810.exchange_authored_interactive_closure.v1","source_chain_continuous":true,"source_event":"order_deleted","source_event_id":"00065a1d-7fa2-24a0-0001-000103000020","source_event_id_unique":true,"source_pre_event_id":"00065a1d-7fa2-24a0-0000-000102000020","translation":"FOLD_RETURN_TO_ZERO","unfold_event_id":"00065a1d-7fa2-24a0-0000-000102000020","zero_hair":true}
{"channel":"live_orders_ethusd","interaction_index":627,"natural_form":{"channel":"live_orders_ethusd","order_id":"2044303882133515","order_subtype":5,"order_type":0},"natural_form_sha256":"2dc54b6b1e1e8fa8cab17e3c6c4206ddd7ecf82c97622e7c4aceee9428138f01","order_source":"orderbook","orders_submitted":0,"presentation":{"amount":"0.481961","amount_traded":"0","microtimestamp":"1787932602148000","price":"2480.02"},"previous_record_hash":"f0dcadcf629f7d1f78ed7b8130dc4b3050ada69b68379eb9da3cac30c0e5dbfd","profit_assessment":null,"record_hash":"04d3abe7b4d93a4153860e018516a704d96023e01db8bbf2c22251bc474decc8","recorded_unix_us":1787932602180376,"recorded_utc":"2026-08-28T15:56:42.180376Z","schema_version":"nrrf810.exchange_authored_interactive_closure.v1","source_chain_continuous":true,"source_event":"order_deleted","source_event_id":"00065a1d-7fa2-24a0-0000-001203000020","source_event_id_unique":true,"source_pre_event_id":"00065a1d-7fa2-20b8-0000-001202000020","translation":"FOLD_RETURN_TO_ZERO","unfold_event_id":"00065a1d-7fa1-e620-0000-001203000020","zero_hair":true}
{"channel":"live_orders_ethusd","interaction_index":628,"natural_form":{"channel":"live_orders_ethusd","order_id":"2044303882072069","order_subtype":5,"order_type":0},"natural_form_sha256":"2d10115c771acfa6588ef9dafcd33d45f338303dcbec66c0dc3f9f18c7dfbe56","order_source":"orderbook","orders_submitted":0,"presentation":{"amount":"0.403091","amount_traded":"0","microtimestamp":"1787932602149000","price":"2479.96"},"previous_record_hash":"04d3abe7b4d93a4153860e018516a704d96023e01db8bbf2c22251bc474decc8","profit_assessment":null,"record_hash":"1655110ee13bd383f502efc1a64a98bf1ef7f74bcdbd3747242f5e4b2332e08a","recorded_unix_us":1787932602180412,"recorded_utc":"2026-08-28T15:56:42.180412Z","schema_version":"nrrf810.exchange_authored_interactive_closure.v1","source_chain_continuous":true,"source_event":"order_deleted","source_event_id":"00065a1d-7fa2-2888-0000-001200000020","source_event_id_unique":true,"source_pre_event_id":"00065a1d-7fa2-24a0-0000-001203000020","translation":"FOLD_RETURN_TO_ZERO","unfold_event_id":"00065a1d-7fa1-a7a0-0000-001201000020","zero_hair":true}
{"channel":"live_orders_ethusd","interaction_index":629,"natural_form":{"channel":"live_orders_ethusd","order_id":"2044303882223618","order_subtype":5,"order_type":0},"natural_form_sha256":"7eca4700e0dc0b57e0e2b84992c3f9886e204534d6c9315c8d864f55b5a730eb","order_source":"orderbook","orders_submitted":0,"presentation":{"amount":"0.080642","amount_traded":"0","microtimestamp":"1787932602154000","price":"2480.10"},"previous_record_hash":"1655110ee13bd383f502efc1a64a98bf1ef7f74bcdbd3747242f5e4b2332e08a","profit_assessment":null,"record_hash":"1f7b3605a9056eaf123e60ade6377b27be8f5942d4cc27da1701eb50a53ebf82","recorded_unix_us":1787932602196525,"recorded_utc":"2026-08-28T15:56:42.196525Z","schema_version":"nrrf810.exchange_authored_interactive_closure.v1","source_chain_continuous":true,"source_event":"order_created","source_event_id":"00065a1d-7fa2-3c10-0000-001201000020","source_event_id_unique":true,"source_pre_event_id":"00065a1d-7fa2-2888-0000-001200000020","translation":"UNFOLD_TO_INF","unfold_event_id":null,"zero_hair":false}
{"channel":"live_orders_ethusd","interaction_index":630,"natural_form":{"channel":"live_orders_ethusd","order_id":"2044303881240580","order_subtype":5,"order_type":1},"natural_form_sha256":"161a666f1f1c458cbdf5652c8a619ddae5a83b3591af0556b0af22de46c48ae9","order_source":"orderbook","orders_submitted":0,"presentation":{"amount":"12.086599","amount_traded":"0","microtimestamp":"1787932602155000","price":"2482.09"},"previous_record_hash":"1f7b3605a9056eaf123e60ade6377b27be8f5942d4cc27da1701eb50a53ebf82","profit_assessment":null,"record_hash":"9a9243000a3b1e1edb46eceb53dd9a1980edfca9fc4de8993738be7a72ffbe1f","recorded_unix_us":1787932602196770,"recorded_utc":"2026-08-28T15:56:42.196770Z","schema_version":"nrrf810.exchange_authored_interactive_closure.v1","source_chain_continuous":true,"source_event":"order_deleted","source_event_id":"00065a1d-7fa2-3ff8-0000-001202000020","source_event_id_unique":true,"source_pre_event_id":"00065a1d-7fa2-3c10-0000-001201000020","translation":"FOLD_RETURN_TO_ZERO","unfold_event_id":"00065a1d-7f9e-8ea8-0000-001203000020","zero_hair":true}
{"channel":"live_orders_ethusd","interaction_index":631,"natural_form":{"channel":"live_orders_ethusd","order_id":"2044303876526081","order_subtype":5,"order_type":0},"natural_form_sha256":"f638bca750049e8d84a07ee997187d439088660446c432adde9acc1713da1697","order_source":"orderbook","orders_submitted":0,"presentation":{"amount":"2.542775","amount_traded":"0","microtimestamp":"1787932602155000","price":"2455.46"},"previous_record_hash":"9a9243000a3b1e1edb46eceb53dd9a1980edfca9fc4de8993738be7a72ffbe1f","profit_assessment":null,"record_hash":"a6d2cc005b945e5699f150a9b61e04b4f09fec9290e09e789c949d8e2bd5b2e8","recorded_unix_us":1787932602196975,"recorded_utc":"2026-08-28T15:56:42.196975Z","schema_version":"nrrf810.exchange_authored_interactive_closure.v1","source_chain_continuous":true,"source_event":"order_deleted","source_event_id":"00065a1d-7fa2-3ff8-0001-001203000020","source_event_id_unique":true,"source_pre_event_id":"00065a1d-7fa2-3ff8-0000-001202000020","translation":"PARTIAL_PRIOR_UNFOLD","unfold_event_id":null,"zero_hair":false}
{"channel":"live_orders_ethusd","interaction_index":632,"natural_form":{"channel":"live_orders_ethusd","order_id":"2044303881117697","order_subtype":5,"order_type":0},"natural_form_sha256":"424dfb6be312d3114d56b90e0d53fea9741232d26e410697a2020fe852f1c421","order_source":"orderbook","orders_submitted":0,"presentation":{"amount":"4.034214","amount_traded":"0","microtimestamp":"1787932602156000","price":"2478.79"},"previous_record_hash":"a6d2cc005b945e5699f150a9b61e04b4f09fec9290e09e789c949d8e2bd5b2e8","profit_assessment":null,"record_hash":"838cd5dc1956f275e7e2add6711b838d98238abc4d570bc29dffe7a6d047ebaa","recorded_unix_us":1787932602197023,"recorded_utc":"2026-08-28T15:56:42.197023Z","schema_version":"nrrf810.exchange_authored_interactive_closure.v1","source_chain_continuous":true,"source_event":"order_deleted","source_event_id":"00065a1d-7fa2-43e0-0000-001200000020","source_event_id_unique":true,"source_pre_event_id":"00065a1d-7fa2-3ff8-0001-001203000020","translation":"FOLD_RETURN_TO_ZERO","unfold_event_id":"00065a1d-7f9e-1978-0000-001200000020","zero_hair":true}
{"channel":"live_orders_ethusd","interaction_index":633,"natural_form":{"channel":"live_orders_ethusd","order_id":"2044303881322500","order_subtype":5,"order_type":0},"natural_form_sha256":"cb2142d2b4a280a3a20d76f6edb5f3838eee64eba6bb41be356cf666036ced73","order_source":"orderbook","orders_submitted":0,"presentation":{"amount":"12.097180","amount_traded":"0","microtimestamp":"1787932602159000","price":"2479.91"},"previous_record_hash":"838cd5dc1956f275e7e2add6711b838d98238abc4d570bc29dffe7a6d047ebaa","profit_assessment":null,"record_hash":"3510a4cb52871641512949c7c744a6a161141adcbb0082f10f0f617152ee85ef","recorded_unix_us":1787932602197187,"recorded_utc":"2026-08-28T15:56:42.197187Z","schema_version":"nrrf810.exchange_authored_interactive_closure.v1","source_chain_continuous":true,"source_event":"order_deleted","source_event_id":"00065a1d-7fa2-4f98-0000-001201000020","source_event_id_unique":true,"source_pre_event_id":"00065a1d-7fa2-43e0-0000-001200000020","translation":"FOLD_RETURN_TO_ZERO","unfold_event_id":"00065a1d-7f9e-dcc8-0000-001203000020","zero_hair":true}
{"channel":"live_orders_ethusd","interaction_index":634,"natural_form":{"channel":"live_orders_ethusd","order_id":"2044303882248198","order_subtype":5,"order_type":0},"natural_form_sha256":"8cb0bc795fab4414f8484a8f82582cfa660ff8756378480437814b3c550ddc31","order_source":"orderbook","orders_submitted":0,"presentation":{"amount":"0.524518","amount_traded":"0","microtimestamp":"1787932602160000","price":"2480.10"},"previous_record_hash":"3510a4cb52871641512949c7c744a6a161141adcbb0082f10f0f617152ee85ef","profit_assessment":null,"record_hash":"d4ddf8ded0b355fd1e4d8c0c19f1fcaaf970da7257e107f871d137a17949f708","recorded_unix_us":1787932602197338,"recorded_utc":"2026-08-28T15:56:42.197338Z","schema_version":"nrrf810.exchange_authored_interactive_closure.v1","source_chain_continuous":true,"source_event":"order_created","source_event_id":"00065a1d-7fa2-5380-0000-001202000020","source_event_id_unique":true,"source_pre_event_id":"00065a1d-7fa2-4f98-0000-001201000020","translation":"UNFOLD_TO_INF","unfold_event_id":null,"zero_hair":false}
{"channel":"live_orders_ethusd","interaction_index":635,"natural_form":{"channel":"live_orders_ethusd","order_id":"2044303882252297","order_subtype":5,"order_type":0},"natural_form_sha256":"fb471071cfdb230e4cf84a4e8fcc9496d87d36be0ac2075283e0668828c9341d","order_source":"orderbook","orders_submitted":0,"presentation":{"amount":"0.403088","amount_traded":"0","microtimestamp":"1787932602161000","price":"2480.02"},"previous_record_hash":"d4ddf8ded0b355fd1e4d8c0c19f1fcaaf970da7257e107f871d137a17949f708","profit_assessment":null,"record_hash":"d6d639a2141160a06daa58fa4764e43dce1ca85955b7c8d028ca04d3d5fc9631","recorded_unix_us":1787932602197466,"recorded_utc":"2026-08-28T15:56:42.197466Z","schema_version":"nrrf810.exchange_authored_interactive_closure.v1","source_chain_continuous":true,"source_event":"order_created","source_event_id":"00065a1d-7fa2-5768-0000-001203000020","source_event_id_unique":true,"source_pre_event_id":"00065a1d-7fa2-5380-0000-001202000020","translation":"UNFOLD_TO_INF","unfold_event_id":null,"zero_hair":false}
{"channel":"live_orders_btcusd","interaction_index":636,"natural_form":{"channel":"live_orders_btcusd","order_id":"2044303882256389","order_subtype":5,"order_type":1},"natural_form_sha256":"6ba655296aa9959c95d2821647cd167c8bb709b692524f82402ac8fdfd1d2214","order_source":"orderbook","orders_submitted":0,"presentation":{"amount":"0.10000000","amount_traded":"0","microtimestamp":"1787932602162000","price":"78522.63"},"previous_record_hash":"d6d639a2141160a06daa58fa4764e43dce1ca85955b7c8d028ca04d3d5fc9631","profit_assessment":null,"record_hash":"953651fe998416a543a6c6a3a9b744d32f0a5570be257295fc4077e4d0d83f53","recorded_unix_us":1787932602197589,"recorded_utc":"2026-08-28T15:56:42.197589Z","schema_version":"nrrf810.exchange_authored_interactive_closure.v1","source_chain_continuous":true,"source_event":"order_created","source_event_id":"00065a1d-7fa2-5b50-0000-000100000020","source_event_id_unique":true,"source_pre_event_id":"00065a1d-7fa2-24a0-0001-000103000020","translation":"UNFOLD_TO_INF","unfold_event_id":null,"zero_hair":false}
{"channel":"live_orders_btcusd","interaction_index":637,"natural_form":{"channel":"live_orders_btcusd","order_id":"2044303882256389","order_subtype":5,"order_type":1},"natural_form_sha256":"6ba655296aa9959c95d2821647cd167c8bb709b692524f82402ac8fdfd1d2214","order_source":"orderbook","orders_submitted":0,"presentation":{"amount":"0.10000000","amount_traded":"0","microtimestamp":"1787932602162000","price":"78522.63"},"previous_record_hash":"953651fe998416a543a6c6a3a9b744d32f0a5570be257295fc4077e4d0d83f53","profit_assessment":null,"record_hash":"dec07287a3b57b56744a89378b6c3c9340017d7a39e09fa69c7d1ff2de11c527","recorded_unix_us":1787932602197770,"recorded_utc":"2026-08-28T15:56:42.197770Z","schema_version":"nrrf810.exchange_authored_interactive_closure.v1","source_chain_continuous":true,"source_event":"order_deleted","source_event_id":"00065a1d-7fa2-5b50-0001-000101000020","source_event_id_unique":true,"source_pre_event_id":"00065a1d-7fa2-5b50-0000-000100000020","translation":"FOLD_RETURN_TO_ZERO","unfold_event_id":"00065a1d-7fa2-5b50-0000-000100000020","zero_hair":true}
{"channel":"live_orders_ethusd","interaction_index":638,"natural_form":{"channel":"live_orders_ethusd","order_id":"2044303882248198","order_subtype":5,"order_type":0},"natural_form_sha256":"8cb0bc795fab4414f8484a8f82582cfa660ff8756378480437814b3c550ddc31","order_source":"orderbook","orders_submitted":0,"presentation":{"amount":"0.524518","amount_traded":"0","microtimestamp":"1787932602163000","price":"2480.10"},"previous_record_hash":"dec07287a3b57b56744a89378b6c3c9340017d7a39e09fa69c7d1ff2de11c527","profit_assessment":null,"record_hash":"02368a44ef3daff014c888bb1b7e5d872e1dff0efca2c88d514813aa9ac1113b","recorded_unix_us":1787932602207105,"recorded_utc":"2026-08-28T15:56:42.207105Z","schema_version":"nrrf810.exchange_authored_interactive_closure.v1","source_chain_continuous":true,"source_event":"order_deleted","source_event_id":"00065a1d-7fa2-5f38-0000-001200000020","source_event_id_unique":true,"source_pre_event_id":"00065a1d-7fa2-5768-0000-001203000020","translation":"FOLD_RETURN_TO_ZERO","unfold_event_id":"00065a1d-7fa2-5380-0000-001202000020","zero_hair":true}
{"channel":"live_orders_ethusd","interaction_index":639,"natural_form":{"channel":"live_orders_ethusd","order_id":"2044303882268672","order_subtype":5,"order_type":0},"natural_form_sha256":"5143b5825235a46273fcf89e0d0c2224d1ce7b694021b8b4d6f5e6a456514d13","order_source":"orderbook","orders_submitted":0,"presentation":{"amount":"0.595025","amount_traded":"0","microtimestamp":"1787932602164000","price":"2480.16"},"previous_record_hash":"02368a44ef3daff014c888bb1b7e5d872e1dff0efca2c88d514813aa9ac1113b","profit_assessment":null,"record_hash":"0e867eee5a4831908c7bca8e04e23f2b0c157e14487765eaa7ef34aa645036cd","recorded_unix_us":1787932602207346,"recorded_utc":"2026-08-28T15:56:42.207346Z","schema_version":"nrrf810.exchange_authored_interactive_closure.v1","source_chain_continuous":true,"source_event":"order_created","source_event_id":"00065a1d-7fa2-6320-0000-001201000020","source_event_id_unique":true,"source_pre_event_id":"00065a1d-7fa2-5f38-0000-001200000020","translation":"UNFOLD_TO_INF","unfold_event_id":null,"zero_hair":false}
{"channel":"live_orders_btcusd","interaction_index":640,"natural_form":{"channel":"live_orders_btcusd","order_id":"2044303882305543","order_subtype":5,"order_type":1},"natural_form_sha256":"64e48c7b264a2d8b98fb97071f72b9454bc1b02196b86eea26230c4f4793a2f7","order_source":"orderbook","orders_submitted":0,"presentation":{"amount":"0.06310787","amount_traded":"0","microtimestamp":"1787932602174000","price":"78521.64"},"previous_record_hash":"0e867eee5a4831908c7bca8e04e23f2b0c157e14487765eaa7ef34aa645036cd","profit_assessment":null,"record_hash":"e6adce52c78056a1d3f08ac2a67fc8c4a6b0ee379d23f7abf6d0d98e7100b489","recorded_unix_us":1787932602207494,"recorded_utc":"2026-08-28T15:56:42.207494Z","schema_version":"nrrf810.exchange_authored_interactive_closure.v1","source_chain_continuous":true,"source_event":"order_created","source_event_id":"00065a1d-7fa2-8a30-0000-000102000020","source_event_id_unique":true,"source_pre_event_id":"00065a1d-7fa2-5b50-0001-000101000020","translation":"UNFOLD_TO_INF","unfold_event_id":null,"zero_hair":false}
{"channel":"live_orders_btcusd","interaction_index":641,"natural_form":{"channel":"live_orders_btcusd","order_id":"2044303882305543","order_subtype":5,"order_type":1},"natural_form_sha256":"64e48c7b264a2d8b98fb97071f72b9454bc1b02196b86eea26230c4f4793a2f7","order_source":"orderbook","orders_submitted":0,"presentation":{"amount":"0.06310787","amount_traded":"0","microtimestamp":"1787932602174000","price":"78521.64"},"previous_record_hash":"e6adce52c78056a1d3f08ac2a67fc8c4a6b0ee379d23f7abf6d0d98e7100b489","profit_assessment":null,"record_hash":"0330ae41fc9829705166fb67c7eac4094ecf17ef89c47a4da2a2dfe88fac33e5","recorded_unix_us":1787932602207618,"recorded_utc":"2026-08-28T15:56:42.207618Z","schema_version":"nrrf810.exchange_authored_interactive_closure.v1","source_chain_continuous":true,"source_event":"order_deleted","source_event_id":"00065a1d-7fa2-8a30-0001-000103000020","source_event_id_unique":true,"source_pre_event_id":"00065a1d-7fa2-8a30-0000-000102000020","translation":"FOLD_RETURN_TO_ZERO","unfold_event_id":"00065a1d-7fa2-8a30-0000-000102000020","zero_hair":true}
{"channel":"live_orders_btcusd","interaction_index":642,"natural_form":{"channel":"live_orders_btcusd","order_id":"2044303882321931","order_subtype":5,"order_type":1},"natural_form_sha256":"82781083f22328a0f41576c60e86194c98195c3f5775e9c5b2e4df671f34901c","order_source":"orderbook","orders_submitted":0,"presentation":{"amount":"0.10000000","amount_traded":"0","microtimestamp":"1787932602178000","price":"78522.62"},"previous_record_hash":"0330ae41fc9829705166fb67c7eac4094ecf17ef89c47a4da2a2dfe88fac33e5","profit_assessment":null,"record_hash":"3016a9d088376d530af4c700a8830839576c9dec1f6f7e084a20203052446abf","recorded_unix_us":1787932602224124,"recorded_utc":"2026-08-28T15:56:42.224124Z","schema_version":"nrrf810.exchange_authored_interactive_closure.v1","source_chain_continuous":true,"source_event":"order_created","source_event_id":"00065a1d-7fa2-99d0-0000-000100000020","source_event_id_unique":true,"source_pre_event_id":"00065a1d-7fa2-8a30-0001-000103000020","translation":"UNFOLD_TO_INF","unfold_event_id":null,"zero_hair":false}
{"channel":"live_orders_btcusd","interaction_index":643,"natural_form":{"channel":"live_orders_btcusd","order_id":"2044303882321931","order_subtype":5,"order_type":1},"natural_form_sha256":"82781083f22328a0f41576c60e86194c98195c3f5775e9c5b2e4df671f34901c","order_source":"orderbook","orders_submitted":0,"presentation":{"amount":"0.10000000","amount_traded":"0","microtimestamp":"1787932602178000","price":"78522.62"},"previous_record_hash":"3016a9d088376d530af4c700a8830839576c9dec1f6f7e084a20203052446abf","profit_assessment":null,"record_hash":"c76d4bd8d0453dfbfa89aaf82d2db487c3d53f75c54f3f15de51e7fe33065888","recorded_unix_us":1787932602224354,"recorded_utc":"2026-08-28T15:56:42.224354Z","schema_version":"nrrf810.exchange_authored_interactive_closure.v1","source_chain_continuous":true,"source_event":"order_deleted","source_event_id":"00065a1d-7fa2-99d0-0001-000101000020","source_event_id_unique":true,"source_pre_event_id":"00065a1d-7fa2-99d0-0000-000100000020","translation":"FOLD_RETURN_TO_ZERO","unfold_event_id":"00065a1d-7fa2-99d0-0000-000100000020","zero_hair":true}
{"channel":"live_orders_ethbtc","interaction_index":644,"natural_form":{"channel":"live_orders_ethbtc","order_id":"2044303881854976","order_subtype":5,"order_type":1},"natural_form_sha256":"0f85b5e762944e3428d86e032d56f7968c6a093bab3f1d41754f322ed174978b","order_source":"orderbook","orders_submitted":0,"presentation":{"amount":"2.01528391","amount_traded":"0","microtimestamp":"1787932602183000","price":"0.03163293"},"previous_record_hash":"c76d4bd8d0453dfbfa89aaf82d2db487c3d53f75c54f3f15de51e7fe33065888","profit_assessment":null,"record_hash":"e96fffeb3c06b9dc4ca265bc41b01c440c6a91fd5200e0898103bfffe3979b10","recorded_unix_us":1787932602224569,"recorded_utc":"2026-08-28T15:56:42.224569Z","schema_version":"nrrf810.exchange_authored_interactive_closure.v1","source_chain_continuous":true,"source_event":"order_deleted","source_event_id":"00065a1d-7fa2-ad58-0000-001102000020","source_event_id_unique":true,"source_pre_event_id":"00065a1d-7fa1-b740-0000-001101000020","translation":"FOLD_RETURN_TO_ZERO","unfold_event_id":"00065a1d-7fa0-d898-0000-001100000020","zero_hair":true}
{"channel":"live_orders_btcusd","interaction_index":645,"natural_form":{"channel":"live_orders_btcusd","order_id":"2044303882371072","order_subtype":5,"order_type":1},"natural_form_sha256":"ac6207c51e9c2f4e4734745d576a2b41ab650da00bbe1429724a801cc4d78719","order_source":"orderbook","orders_submitted":0,"presentation":{"amount":"0.10000000","amount_traded":"0","microtimestamp":"1787932602189000","price":"78522.63"},"previous_record_hash":"e96fffeb3c06b9dc4ca265bc41b01c440c6a91fd5200e0898103bfffe3979b10","profit_assessment":null,"record_hash":"526795ff3001f021f22d88de24e9fbbb0e3331337e2b853fc917941492b03a22","recorded_unix_us":1787932602236443,"recorded_utc":"2026-08-28T15:56:42.236443Z","schema_version":"nrrf810.exchange_authored_interactive_closure.v1","source_chain_continuous":true,"source_event":"order_created","source_event_id":"00065a1d-7fa2-c4c8-0000-000102000020","source_event_id_unique":true,"source_pre_event_id":"00065a1d-7fa2-99d0-0001-000101000020","translation":"UNFOLD_TO_INF","unfold_event_id":null,"zero_hair":false}
{"channel":"live_orders_btcusd","interaction_index":646,"natural_form":{"channel":"live_orders_btcusd","order_id":"2044303882371072","order_subtype":5,"order_type":1},"natural_form_sha256":"ac6207c51e9c2f4e4734745d576a2b41ab650da00bbe1429724a801cc4d78719","order_source":"orderbook","orders_submitted":0,"presentation":{"amount":"0.10000000","amount_traded":"0","microtimestamp":"1787932602189000","price":"78522.63"},"previous_record_hash":"526795ff3001f021f22d88de24e9fbbb0e3331337e2b853fc917941492b03a22","profit_assessment":null,"record_hash":"acf5270de7d13092bdd6f17c5fb387ca520912815170b5504b1a23baf5465008","recorded_unix_us":1787932602236723,"recorded_utc":"2026-08-28T15:56:42.236723Z","schema_version":"nrrf810.exchange_authored_interactive_closure.v1","source_chain_continuous":true,"source_event":"order_deleted","source_event_id":"00065a1d-7fa2-c4c8-0001-000103000020","source_event_id_unique":true,"source_pre_event_id":"00065a1d-7fa2-c4c8-0000-000102000020","translation":"FOLD_RETURN_TO_ZERO","unfold_event_id":"00065a1d-7fa2-c4c8-0000-000102000020","zero_hair":true}
{"channel":"live_orders_ethusd","interaction_index":647,"natural_form":{"channel":"live_orders_ethusd","order_id":"2044303880622094","order_subtype":5,"order_type":0},"natural_form_sha256":"e378abf8043b93b9d81d74329e7428d48f63bd0b4169973e043efe38a3da3ee8","order_source":"orderbook","orders_submitted":0,"presentation":{"amount":"4.034022","amount_traded":"0","microtimestamp":"1787932602192000","price":"2478.91"},"previous_record_hash":"acf5270de7d13092bdd6f17c5fb387ca520912815170b5504b1a23baf5465008","profit_assessment":null,"record_hash":"3238efa6929cfe8441c5199fa2fa163fcc94f390900eaf1d326ee29299a0e006","recorded_unix_us":1787932602236909,"recorded_utc":"2026-08-28T15:56:42.236909Z","schema_version":"nrrf810.exchange_authored_interactive_closure.v1","source_chain_continuous":true,"source_event":"order_deleted","source_event_id":"00065a1d-7fa2-d080-0000-001202000020","source_event_id_unique":true,"source_pre_event_id":"00065a1d-7fa2-6320-0000-001201000020","translation":"FOLD_RETURN_TO_ZERO","unfold_event_id":"00065a1d-7f9c-44b8-0001-001200000020","zero_hair":true}
{"channel":"live_orders_ethusd","interaction_index":648,"natural_form":{"channel":"live_orders_ethusd","order_id":"2044303882383360","order_subtype":5,"order_type":1},"natural_form_sha256":"557b6bd06da0e7c435e8be1d68e169ba6008b2050043bc81b009708c28e36833","order_source":"orderbook","orders_submitted":0,"presentation":{"amount":"5.000000","amount_traded":"0","microtimestamp":"1787932602192000","price":"2481.70"},"previous_record_hash":"3238efa6929cfe8441c5199fa2fa163fcc94f390900eaf1d326ee29299a0e006","profit_assessment":null,"record_hash":"6c79880b181234cd2fbbe056bec54743a6c2d0d0e76aeb8767e981a8e77f576d","recorded_unix_us":1787932602237168,"recorded_utc":"2026-08-28T15:56:42.237168Z","schema_version":"nrrf810.exchange_authored_interactive_closure.v1","source_chain_continuous":true,"source_event":"order_created","source_event_id":"00065a1d-7fa2-d080-0001-001203000020","source_event_id_unique":true,"source_pre_event_id":"00065a1d-7fa2-d080-0000-001202000020","translation":"UNFOLD_TO_INF","unfold_event_id":null,"zero_hair":false}
{"channel":"live_orders_ethusd","interaction_index":649,"natural_form":{"channel":"live_orders_ethusd","order_id":"2044303880728576","order_subtype":5,"order_type":1},"natural_form_sha256":"70169ba87056285c91118d507920bdfb8410e9a9d633a811d8d7481e31f48b8c","order_source":"orderbook","orders_submitted":0,"presentation":{"amount":"10.057184","amount_traded":"0","microtimestamp":"1787932602192000","price":"2485.79"},"previous_record_hash":"6c79880b181234cd2fbbe056bec54743a6c2d0d0e76aeb8767e981a8e77f576d","profit_assessment":null,"record_hash":"af902bed9765855cec4309c85ab4daada44e573ea0cedc5efde524ba023c6b02","recorded_unix_us":1787932602237221,"recorded_utc":"2026-08-28T15:56:42.237221Z","schema_version":"nrrf810.exchange_authored_interactive_closure.v1","source_chain_continuous":true,"source_event":"order_deleted","source_event_id":"00065a1d-7fa2-d080-0002-001200000020","source_event_id_unique":true,"source_pre_event_id":"00065a1d-7fa2-d080-0001-001203000020","translation":"FOLD_RETURN_TO_ZERO","unfold_event_id":"00065a1d-7f9c-a660-0000-001203000020","zero_hair":true}
{"channel":"live_orders_ethusd","interaction_index":650,"natural_form":{"channel":"live_orders_ethusd","order_id":"2044303880728580","order_subtype":5,"order_type":1},"natural_form_sha256":"cfe76a8daf3b16b06c46c0de38dd4562474c8beed479c2662c0732b9ebe5d684","order_source":"orderbook","orders_submitted":0,"presentation":{"amount":"10.065070","amount_traded":"0","microtimestamp":"1787932602192000","price":"2483.84"},"previous_record_hash":"af902bed9765855cec4309c85ab4daada44e573ea0cedc5efde524ba023c6b02","profit_assessment":null,"record_hash":"3af353dbfff7f8e5580965b3f933e48bdda97bb6ac1f16046e9a49e9167bae51","recorded_unix_us":1787932602237274,"recorded_utc":"2026-08-28T15:56:42.237274Z","schema_version":"nrrf810.exchange_authored_interactive_closure.v1","source_chain_continuous":true,"source_event":"order_deleted","source_event_id":"00065a1d-7fa2-d080-0003-001201000020","source_event_id_unique":true,"source_pre_event_id":"00065a1d-7fa2-d080-0002-001200000020","translation":"FOLD_RETURN_TO_ZERO","unfold_event_id":"00065a1d-7f9c-aa48-0000-001200000020","zero_hair":true}
{"channel":"live_orders_ethusd","interaction_index":651,"natural_form":{"channel":"live_orders_ethusd","order_id":"2044303880728581","order_subtype":5,"order_type":1},"natural_form_sha256":"7900d392b9e9a89fdfcda86c730071f194e24ea07efbb7a0bbd16096dadba4d9","order_source":"orderbook","orders_submitted":0,"presentation":{"amount":"20.097242","amount_traded":"0","microtimestamp":"1787932602193000","price":"2487.91"},"previous_record_hash":"3af353dbfff7f8e5580965b3f933e48bdda97bb6ac1f16046e9a49e9167bae51","profit_assessment":null,"record_hash":"cac17dc8e8d2c2bae70426ea88a0a5fea3213e52bfbd8de9fbd93d1a6bcf98ad","recorded_unix_us":1787932602237311,"recorded_utc":"2026-08-28T15:56:42.237311Z","schema_version":"nrrf810.exchange_authored_interactive_closure.v1","source_chain_continuous":true,"source_event":"order_deleted","source_event_id":"00065a1d-7fa2-d468-0000-001202000020","source_event_id_unique":true,"source_pre_event_id":"00065a1d-7fa2-d080-0003-001201000020","translation":"FOLD_RETURN_TO_ZERO","unfold_event_id":"00065a1d-7f9c-aa48-0001-001201000020","zero_hair":true}
{"channel":"live_orders_ethusd","interaction_index":652,"natural_form":{"channel":"live_orders_ethusd","order_id":"2044303880732678","order_subtype":5,"order_type":1},"natural_form_sha256":"156934d00a20142a8337942bf031212ac508d883774aed9ca91a0ef74b408a62","order_source":"orderbook","orders_submitted":0,"presentation":{"amount":"20.088574","amount_traded":"0","microtimestamp":"1787932602193000","price":"2488.98"},"previous_record_hash":"cac17dc8e8d2c2bae70426ea88a0a5fea3213e52bfbd8de9fbd93d1a6bcf98ad","profit_assessment":null,"record_hash":"83c0e345515d4867bbb022955b379440ab262507882608fa0c8400f2533eb67f","recorded_unix_us":1787932602237437,"recorded_utc":"2026-08-28T15:56:42.237437Z","schema_version":"nrrf810.exchange_authored_interactive_closure.v1","source_chain_continuous":true,"source_event":"order_deleted","source_event_id":"00065a1d-7fa2-d468-0001-001203000020","source_event_id_unique":true,"source_pre_event_id":"00065a1d-7fa2-d468-0000-001202000020","translation":"FOLD_RETURN_TO_ZERO","unfold_event_id":"00065a1d-7f9c-aa48-0002-001202000020","zero_hair":true}
{"channel":"live_orders_ethusd","interaction_index":653,"natural_form":{"channel":"live_orders_ethusd","order_id":"2044303880736780","order_subtype":5,"order_type":1},"natural_form_sha256":"95deb7c22b424eee170a30984e8aeb816a7b253437d7e662d44f2f9e9206dfec","order_source":"orderbook","orders_submitted":0,"presentation":{"amount":"39.969006","amount_traded":"0","microtimestamp":"1787932602193000","price":"2501.94"},"previous_record_hash":"83c0e345515d4867bbb022955b379440ab262507882608fa0c8400f2533eb67f","profit_assessment":null,"record_hash":"08170eba598d8d86a7efd7a4813b6dd3fc61135abcf4a250136f94b2c2c74fbd","recorded_unix_us":1787932602237589,"recorded_utc":"2026-08-28T15:56:42.237589Z","schema_version":"nrrf810.exchange_authored_interactive_closure.v1","source_chain_continuous":true,"source_event":"order_deleted","source_event_id":"00065a1d-7fa2-d468-0002-001200000020","source_event_id_unique":true,"source_pre_event_id":"00065a1d-7fa2-d468-0001-001203000020","translation":"FOLD_RETURN_TO_ZERO","unfold_event_id":"00065a1d-7f9c-b218-0001-001200000020","zero_hair":true}
{"channel":"live_orders_ethusd","interaction_index":654,"natural_form":{"channel":"live_orders_ethusd","order_id":"2044303880740872","order_subtype":5,"order_type":1},"natural_form_sha256":"aad563d3dfa91e35bc6394d0180921e8f6ab2af6ae8af6c8137abebab96029fd","order_source":"orderbook","orders_submitted":0,"presentation":{"amount":"40.092050","amount_traded":"0","microtimestamp":"1787932602194000","price":"2494.27"},"previous_record_hash":"08170eba598d8d86a7efd7a4813b6dd3fc61135abcf4a250136f94b2c2c74fbd","profit_assessment":null,"record_hash":"3b0726aea1dd186053bbed4b166b7a639de7ec7b7f060bcbdae3fea2fd6b0870","recorded_unix_us":1787932602237630,"recorded_utc":"2026-08-28T15:56:42.237630Z","schema_version":"nrrf810.exchange_authored_interactive_closure.v1","source_chain_continuous":true,"source_event":"order_deleted","source_event_id":"00065a1d-7fa2-d850-0000-001201000020","source_event_id_unique":true,"source_pre_event_id":"00065a1d-7fa2-d468-0002-001200000020","translation":"FOLD_RETURN_TO_ZERO","unfold_event_id":"00065a1d-7f9c-b600-0000-001201000020","zero_hair":true}
{"channel":"live_orders_ethusd","interaction_index":655,"natural_form":{"channel":"live_orders_ethusd","order_id":"2044303880753154","order_subtype":5,"order_type":0},"natural_form_sha256":"e56de15aebb8927c38ca1a8868066f521e3d0b574dee795edb483ec968a9a36a","order_source":"orderbook","orders_submitted":0,"presentation":{"amount":"10.095101","amount_traded":"0","microtimestamp":"1787932602194000","price":"2476.44"},"previous_record_hash":"3b0726aea1dd186053bbed4b166b7a639de7ec7b7f060bcbdae3fea2fd6b0870","profit_assessment":null,"record_hash":"060f0c5e1a95c625211ec70f2210ec34132a055814adc21c0330a1468c58f71f","recorded_unix_us":1787932602237741,"recorded_utc":"2026-08-28T15:56:42.237741Z","schema_version":"nrrf810.exchange_authored_interactive_closure.v1","source_chain_continuous":true,"source_event":"order_deleted","source_event_id":"00065a1d-7fa2-d850-0001-001202000020","source_event_id_unique":true,"source_pre_event_id":"00065a1d-7fa2-d850-0000-001201000020","translation":"FOLD_RETURN_TO_ZERO","unfold_event_id":"00065a1d-7f9c-bdd0-0000-001200000020","zero_hair":true}
{"channel":"live_orders_ethusd","interaction_index":656,"natural_form":{"channel":"live_orders_ethusd","order_id":"2044303880753156","order_subtype":5,"order_type":0},"natural_form_sha256":"e384fac2a1b1e23f43d3d2eeebcc2f4d6a358a3c76c53aaaf96f7660885ea5c4","order_source":"orderbook","orders_submitted":0,"presentation":{"amount":"4.033204","amount_traded":"0","microtimestamp":"1787932602194000","price":"2479.41"},"previous_record_hash":"060f0c5e1a95c625211ec70f2210ec34132a055814adc21c0330a1468c58f71f","profit_assessment":null,"record_hash":"d60a8e50b910f30cddc7b625a43fe2ad0094209c8c60bf3c6f6464bca6493603","recorded_unix_us":1787932602238067,"recorded_utc":"2026-08-28T15:56:42.238067Z","schema_version":"nrrf810.exchange_authored_interactive_closure.v1","source_chain_continuous":true,"source_event":"order_deleted","source_event_id":"00065a1d-7fa2-d850-0002-001203000020","source_event_id_unique":true,"source_pre_event_id":"00065a1d-7fa2-d850-0001-001202000020","translation":"FOLD_RETURN_TO_ZERO","unfold_event_id":"00065a1d-7f9c-bdd0-0001-001201000020","zero_hair":true}
{"channel":"live_orders_ethusd","interaction_index":657,"natural_form":{"channel":"live_orders_ethusd","order_id":"2044303880753159","order_subtype":5,"order_type":0},"natural_form_sha256":"f1331951cb83acbcc42797c9e10ab7092eaeba1418585f6c629f2762614bbf32","order_source":"orderbook","orders_submitted":0,"presentation":{"amount":"20.204386","amount_traded":"0","microtimestamp":"1787932602195000","price":"2474.71"},"previous_record_hash":"d60a8e50b910f30cddc7b625a43fe2ad0094209c8c60bf3c6f6464bca6493603","profit_assessment":null,"record_hash":"36e29d59d0b5373bcc89476bf9804ff5d3772537684dbf7176f13ade90bd5f69","recorded_unix_us":1787932602238104,"recorded_utc":"2026-08-28T15:56:42.238104Z","schema_version":"nrrf810.exchange_authored_interactive_closure.v1","source_chain_continuous":true,"source_event":"order_deleted","source_event_id":"00065a1d-7fa2-dc38-0000-001200000020","source_event_id_unique":true,"source_pre_event_id":"00065a1d-7fa2-d850-0002-001203000020","translation":"FOLD_RETURN_TO_ZERO","unfold_event_id":"00065a1d-7f9c-c1b8-0001-001203000020","zero_hair":true}
{"channel":"live_orders_ethusd","interaction_index":658,"natural_form":{"channel":"live_orders_ethusd","order_id":"2044303880753160","order_subtype":5,"order_type":0},"natural_form_sha256":"2e13a6bada2bcf44801adf1e1979d87fddc693a00c5aac2999aea3734728485a","order_source":"orderbook","orders_submitted":0,"presentation":{"amount":"10.090138","amount_traded":"0","microtimestamp":"1787932602195000","price":"2477.66"},"previous_record_hash":"36e29d59d0b5373bcc89476bf9804ff5d3772537684dbf7176f13ade90bd5f69","profit_assessment":null,"record_hash":"ba72067e564c87486a20c8107daa9e49309876b179cff6d4f709fa7fb8861e6d","recorded_unix_us":1787932602238165,"recorded_utc":"2026-08-28T15:56:42.238165Z","schema_version":"nrrf810.exchange_authored_interactive_closure.v1","source_chain_continuous":true,"source_event":"order_deleted","source_event_id":"00065a1d-7fa2-dc38-0001-001201000020","source_event_id_unique":true,"source_pre_event_id":"00065a1d-7fa2-dc38-0000-001200000020","translation":"FOLD_RETURN_TO_ZERO","unfold_event_id":"00065a1d-7f9c-c1b8-0000-001202000020","zero_hair":true}
{"channel":"live_orders_ethusd","interaction_index":659,"natural_form":{"channel":"live_orders_ethusd","order_id":"2044303880757250","order_subtype":5,"order_type":0},"natural_form_sha256":"cff8f30f6ce1e3a79be3fafb2a1fdf2dd393a3ae135e84b2626625dc821fccf9","order_source":"orderbook","orders_submitted":0,"presentation":{"amount":"4.033601","amount_traded":"0","microtimestamp":"1787932602195000","price":"2479.17"},"previous_record_hash":"ba72067e564c87486a20c8107daa9e49309876b179cff6d4f709fa7fb8861e6d","profit_assessment":null,"record_hash":"fc327ce03f8b3941a6b5278a61dbdaceb17a0f971db807765df16a406c0a7040","recorded_unix_us":1787932602238196,"recorded_utc":"2026-08-28T15:56:42.238196Z","schema_version":"nrrf810.exchange_authored_interactive_closure.v1","source_chain_continuous":true,"source_event":"order_deleted","source_event_id":"00065a1d-7fa2-dc38-0002-001202000020","source_event_id_unique":true,"source_pre_event_id":"00065a1d-7fa2-dc38-0001-001201000020","translation":"FOLD_RETURN_TO_ZERO","unfold_event_id":"00065a1d-7f9c-c1b8-0002-001200000020","zero_hair":true}
{"channel":"live_orders_ethusd","interaction_index":660,"natural_form":{"channel":"live_orders_ethusd","order_id":"2044303880814602","order_subtype":5,"order_type":0},"natural_form_sha256":"a3c727c6d4def29fd9f584b0b3770bb977795de697d6a19ece515015b37cf27d","order_source":"orderbook","orders_submitted":0,"presentation":{"amount":"40.528033","amount_traded":"0","microtimestamp":"1787932602196000","price":"2467.42"},"previous_record_hash":"fc327ce03f8b3941a6b5278a61dbdaceb17a0f971db807765df16a406c0a7040","profit_assessment":null,"record_hash":"303cbae15b46a6c1f03a96c8ee4bcd6c03b95ab1d0ef0439db0b845adc6d6607","recorded_unix_us":1787932602238547,"recorded_utc":"2026-08-28T15:56:42.238547Z","schema_version":"nrrf810.exchange_authored_interactive_closure.v1","source_chain_continuous":true,"source_event":"order_deleted","source_event_id":"00065a1d-7fa2-e020-0000-001203000020","source_event_id_unique":true,"source_pre_event_id":"00065a1d-7fa2-dc38-0002-001202000020","translation":"FOLD_RETURN_TO_ZERO","unfold_event_id":"00065a1d-7f9c-f868-0001-001200000020","zero_hair":true}
{"channel":"live_orders_ethusd","interaction_index":661,"natural_form":{"channel":"live_orders_ethusd","order_id":"2044303880880134","order_subtype":5,"order_type":0},"natural_form_sha256":"45db0ff7f684e17a0a7739b4700ae4f7133a516d30445dd0c2dcf1e23aaf00f0","order_source":"orderbook","orders_submitted":0,"presentation":{"amount":"40.650432","amount_traded":"0","microtimestamp":"1787932602196000","price":"2459.99"},"previous_record_hash":"303cbae15b46a6c1f03a96c8ee4bcd6c03b95ab1d0ef0439db0b845adc6d6607","profit_assessment":null,"record_hash":"4e7ad47a14c5e8373b71be0c5d69eb60ad1eae32be4c68506696101482112c5c","recorded_unix_us":1787932602238591,"recorded_utc":"2026-08-28T15:56:42.238591Z","schema_version":"nrrf810.exchange_authored_interactive_closure.v1","source_chain_continuous":true,"source_event":"order_deleted","source_event_id":"00065a1d-7fa2-e020-0001-001200000020","source_event_id_unique":true,"source_pre_event_id":"00065a1d-7fa2-e020-0000-001203000020","translation":"FOLD_RETURN_TO_ZERO","unfold_event_id":"00065a1d-7f9d-36e8-0001-001202000020","zero_hair":true}
{"channel":"live_orders_ethusd","interaction_index":662,"natural_form":{"channel":"live_orders_ethusd","order_id":"2044303881084943","order_subtype":5,"order_type":1},"natural_form_sha256":"9de452757b94cfce96c341390eaee6a333e1fa504f1552087e1d6200a2b7847e","order_source":"orderbook","orders_submitted":0,"presentation":{"amount":"4.028412","amount_traded":"0","microtimestamp":"1787932602196000","price":"2482.37"},"previous_record_hash":"4e7ad47a14c5e8373b71be0c5d69eb60ad1eae32be4c68506696101482112c5c","profit_assessment":null,"record_hash":"9963a3bb04ce0940afdca026b98861449c0bd19a9297d646f139f7ab89a04647","recorded_unix_us":1787932602238621,"recorded_utc":"2026-08-28T15:56:42.238621Z","schema_version":"nrrf810.exchange_authored_interactive_closure.v1","source_chain_continuous":true,"source_event":"order_deleted","source_event_id":"00065a1d-7fa2-e020-0002-001201000020","source_event_id_unique":true,"source_pre_event_id":"00065a1d-7fa2-e020-0001-001200000020","translation":"FOLD_RETURN_TO_ZERO","unfold_event_id":"00065a1d-7f9d-fe20-0000-001202000020","zero_hair":true}
{"channel":"live_orders_ethusd","interaction_index":663,"natural_form":{"channel":"live_orders_ethusd","order_id":"2044303881089031","order_subtype":5,"order_type":1},"natural_form_sha256":"7ffd01d535af99ec9911fcf4a15bbeb9039421d70e3c5a293beb9cb1756d5bae","order_source":"orderbook","orders_submitted":0,"presentation":{"amount":"4.027018","amount_traded":"0","microtimestamp":"1787932602197000","price":"2483.23"},"previous_record_hash":"9963a3bb04ce0940afdca026b98861449c0bd19a9297d646f139f7ab89a04647","profit_assessment":null,"record_hash":"9d830a0951c17d4296c0bb221239b103421fb381755701f9c9af00de13dcea08","recorded_unix_us":1787932602238649,"recorded_utc":"2026-08-28T15:56:42.238649Z","schema_version":"nrrf810.exchange_authored_interactive_closure.v1","source_chain_continuous":true,"source_event":"order_deleted","source_event_id":"00065a1d-7fa2-e408-0000-001202000020","source_event_id_unique":true,"source_pre_event_id":"00065a1d-7fa2-e020-0002-001201000020","translation":"FOLD_RETURN_TO_ZERO","unfold_event_id":"00065a1d-7f9d-fe20-0001-001203000020","zero_hair":true}
{"channel":"live_orders_ethusd","interaction_index":664,"natural_form":{"channel":"live_orders_ethusd","order_id":"2044303881105415","order_subtype":5,"order_type":1},"natural_form_sha256":"1dec016ed42f0f02cdb24b82fe334f3d4e609a202954d402c9325c7788346ccb","order_source":"orderbook","orders_submitted":0,"presentation":{"amount":"20.077182","amount_traded":"0","microtimestamp":"1787932602197000","price":"2490.39"},"previous_record_hash":"9d830a0951c17d4296c0bb221239b103421fb381755701f9c9af00de13dcea08","profit_assessment":null,"record_hash":"fac0c2a7c91942e4b983bb0d30a1e0a97922186a6e3c268435b6461c073295c9","recorded_unix_us":1787932602238838,"recorded_utc":"2026-08-28T15:56:42.238838Z","schema_version":"nrrf810.exchange_authored_interactive_closure.v1","source_chain_continuous":true,"source_event":"order_deleted","source_event_id":"00065a1d-7fa2-e408-0001-001203000020","source_event_id_unique":true,"source_pre_event_id":"00065a1d-7fa2-e408-0000-001202000020","translation":"FOLD_RETURN_TO_ZERO","unfold_event_id":"00065a1d-7f9e-11a8-0000-001202000020","zero_hair":true}
{"channel":"live_orders_ethusd","interaction_index":665,"natural_form":{"channel":"live_orders_ethusd","order_id":"2044303881113600","order_subtype":5,"order_type":1},"natural_form_sha256":"4adaf0a0dc70b9dba1716b25ea6d5082f186a5d57f2d539aadc1133617b19b76","order_source":"orderbook","orders_submitted":0,"presentation":{"amount":"10.062547","amount_traded":"0","microtimestamp":"1787932602197000","price":"2484.47"},"previous_record_hash":"fac0c2a7c91942e4b983bb0d30a1e0a97922186a6e3c268435b6461c073295c9","profit_assessment":null,"record_hash":"3fe1383814c19d69b223d3ddf387d401a2d588c1b91392b2f30b4adab7025dfd","recorded_unix_us":1787932602238873,"recorded_utc":"2026-08-28T15:56:42.238873Z","schema_version":"nrrf810.exchange_authored_interactive_closure.v1","source_chain_continuous":true,"source_event":"order_deleted","source_event_id":"00065a1d-7fa2-e408-0002-001200000020","source_event_id_unique":true,"source_pre_event_id":"00065a1d-7fa2-e408-0001-001203000020","translation":"FOLD_RETURN_TO_ZERO","unfold_event_id":"00065a1d-7f9e-1590-0000-001203000020","zero_hair":true}
{"channel":"live_orders_ethusd","interaction_index":666,"natural_form":{"channel":"live_orders_ethusd","order_id":"2044303881117701","order_subtype":5,"order_type":1},"natural_form_sha256":"ca632b75641aff51dbd96bb753bd84cd34cbc4d9255810c6585f58d560eefbdb","order_source":"orderbook","orders_submitted":0,"presentation":{"amount":"40.051178","amount_traded":"0","microtimestamp":"1787932602198000","price":"2496.81"},"previous_record_hash":"3fe1383814c19d69b223d3ddf387d401a2d588c1b91392b2f30b4adab7025dfd","profit_assessment":null,"record_hash":"fa84685e750e0c681628630b2482f50cd154599879faa3eb951835512c004c8f","recorded_unix_us":1787932602238901,"recorded_utc":"2026-08-28T15:56:42.238901Z","schema_version":"nrrf810.exchange_authored_interactive_closure.v1","source_chain_continuous":true,"source_event":"order_deleted","source_event_id":"00065a1d-7fa2-e7f0-0000-001201000020","source_event_id_unique":true,"source_pre_event_id":"00065a1d-7fa2-e408-0002-001200000020","translation":"FOLD_RETURN_TO_ZERO","unfold_event_id":"00065a1d-7f9e-1978-0001-001201000020","zero_hair":true}
{"channel":"live_orders_ethusd","interaction_index":667,"natural_form":{"channel":"live_orders_ethusd","order_id":"2044303881129985","order_subtype":5,"order_type":0},"natural_form_sha256":"9c8f0717fc5ec4cec07958a89ac7e70b2336ca50ed71278a88a4be0a2239ac77","order_source":"orderbook","orders_submitted":0,"presentation":{"amount":"20.215084","amount_traded":"0","microtimestamp":"1787932602198000","price":"2473.40"},"previous_record_hash":"fa84685e750e0c681628630b2482f50cd154599879faa3eb951835512c004c8f","profit_assessment":null,"record_hash":"13945d4de6b4b221df08c8f1c9061540e977b899dce29b72f763f727113188eb","recorded_unix_us":1787932602238929,"recorded_utc":"2026-08-28T15:56:42.238929Z","schema_version":"nrrf810.exchange_authored_interactive_closure.v1","source_chain_continuous":true,"source_event":"order_deleted","source_event_id":"00065a1d-7fa2-e7f0-0001-001202000020","source_event_id_unique":true,"source_pre_event_id":"00065a1d-7fa2-e7f0-0000-001201000020","translation":"FOLD_RETURN_TO_ZERO","unfold_event_id":"00065a1d-7f9e-2530-0000-001202000020","zero_hair":true}
{"channel":"live_orders_ethusd","interaction_index":668,"natural_form":{"channel":"live_orders_ethusd","order_id":"2044303881129986","order_subtype":5,"order_type":0},"natural_form_sha256":"12a5b218aa077bf84cb60fe0de0b7d6915f86c790ec57a4ff1e456e93df8ed0a","order_source":"orderbook","orders_submitted":0,"presentation":{"amount":"10.092689","amount_traded":"0","microtimestamp":"1787932602198000","price":"2477.04"},"previous_record_hash":"13945d4de6b4b221df08c8f1c9061540e977b899dce29b72f763f727113188eb","profit_assessment":null,"record_hash":"57dc91e38abdf1aaabd3f029c35e965ea82905e7971349c8ea3a58c9f3e823d8","recorded_unix_us":1787932602239031,"recorded_utc":"2026-08-28T15:56:42.239031Z","schema_version":"nrrf810.exchange_authored_interactive_closure.v1","source_chain_continuous":true,"source_event":"order_deleted","source_event_id":"00065a1d-7fa2-e7f0-0002-001203000020","source_event_id_unique":true,"source_pre_event_id":"00065a1d-7fa2-e7f0-0001-001202000020","translation":"FOLD_RETURN_TO_ZERO","unfold_event_id":"00065a1d-7f9e-2530-0001-001203000020","zero_hair":true}
{"channel":"live_orders_ethusd","interaction_index":669,"natural_form":{"channel":"live_orders_ethusd","order_id":"2044303881138178","order_subtype":5,"order_type":0},"natural_form_sha256":"58e0d0aba00dbd7e7e1d993d8356badd745867445df1760e1f0340ba3214c85b","order_source":"orderbook","orders_submitted":0,"presentation":{"amount":"40.568517","amount_traded":"0","microtimestamp":"1787932602199000","price":"2464.96"},"previous_record_hash":"57dc91e38abdf1aaabd3f029c35e965ea82905e7971349c8ea3a58c9f3e823d8","profit_assessment":null,"record_hash":"5c723f1a571c5555fd826bf46b1ba1d3d005cb32bea617edc694fa24719851a5","recorded_unix_us":1787932602239204,"recorded_utc":"2026-08-28T15:56:42.239204Z","schema_version":"nrrf810.exchange_authored_interactive_closure.v1","source_chain_continuous":true,"source_event":"order_deleted","source_event_id":"00065a1d-7fa2-ebd8-0000-001200000020","source_event_id_unique":true,"source_pre_event_id":"00065a1d-7fa2-e7f0-0002-001203000020","translation":"FOLD_RETURN_TO_ZERO","unfold_event_id":"00065a1d-7f9e-2d00-0000-001200000020","zero_hair":true}
{"channel":"live_orders_ethusd","interaction_index":670,"natural_form":{"channel":"live_orders_ethusd","order_id":"2044303881142283","order_subtype":5,"order_type":0},"natural_form_sha256":"4bb26b0d217dc279ce40f98a368d10c9dd0d7b775dbac86df1cd1fed4f4294ad","order_source":"orderbook","orders_submitted":0,"presentation":{"amount":"10.097738","amount_traded":"0","microtimestamp":"1787932602199000","price":"2475.80"},"previous_record_hash":"5c723f1a571c5555fd826bf46b1ba1d3d005cb32bea617edc694fa24719851a5","profit_assessment":null,"record_hash":"efa26416e12cf10d48e3b784e2e56f03be1e2b85cf523440c7d5e1e3e01ca3db","recorded_unix_us":1787932602239246,"recorded_utc":"2026-08-28T15:56:42.239246Z","schema_version":"nrrf810.exchange_authored_interactive_closure.v1","source_chain_continuous":true,"source_event":"order_deleted","source_event_id":"00065a1d-7fa2-ebd8-0001-001201000020","source_event_id_unique":true,"source_pre_event_id":"00065a1d-7fa2-ebd8-0000-001200000020","translation":"FOLD_RETURN_TO_ZERO","unfold_event_id":"00065a1d-7f9e-34d0-0000-001201000020","zero_hair":true}
{"channel":"live_orders_ethusd","interaction_index":671,"natural_form":{"channel":"live_orders_ethusd","order_id":"2044303881244674","order_subtype":5,"order_type":1},"natural_form_sha256":"c0eb005599c497e7f32e6e1a1e3e9b82772394e8874b781727aacfadf18937d6","order_source":"orderbook","orders_submitted":0,"presentation":{"amount":"4.028003","amount_traded":"0","microtimestamp":"1787932602200000","price":"2482.62"},"previous_record_hash":"efa26416e12cf10d48e3b784e2e56f03be1e2b85cf523440c7d5e1e3e01ca3db","profit_assessment":null,"record_hash":"b9e185f01a6b76341e0baa374e5561a17cee6adba5c6152d7f5038239a6fcdb1","recorded_unix_us":1787932602239522,"recorded_utc":"2026-08-28T15:56:42.239522Z","schema_version":"nrrf810.exchange_authored_interactive_closure.v1","source_chain_continuous":true,"source_event":"order_deleted","source_event_id":"00065a1d-7fa2-efc0-0000-001202000020","source_event_id_unique":true,"source_pre_event_id":"00065a1d-7fa2-ebd8-0001-001201000020","translation":"FOLD_RETURN_TO_ZERO","unfold_event_id":"00065a1d-7f9e-9290-0000-001200000020","zero_hair":true}
{"channel":"live_orders_ethusd","interaction_index":672,"natural_form":{"channel":"live_orders_ethusd","order_id":"2044303881244688","order_subtype":5,"order_type":1},"natural_form_sha256":"02658ad873068450f9d68e2b07499ffb58ff2764c6feb6a57dd66bab9318ff79","order_source":"orderbook","orders_submitted":0,"presentation":{"amount":"10.059779","amount_traded":"0","microtimestamp":"1787932602200000","price":"2485.15"},"previous_record_hash":"b9e185f01a6b76341e0baa374e5561a17cee6adba5c6152d7f5038239a6fcdb1","profit_assessment":null,"record_hash":"62d2942844b093a11b93e6840b4101450aa89d2f21fb48c5953492c732f27f13","recorded_unix_us":1787932602239569,"recorded_utc":"2026-08-28T15:56:42.239569Z","schema_version":"nrrf810.exchange_authored_interactive_closure.v1","source_chain_continuous":true,"source_event":"order_deleted","source_event_id":"00065a1d-7fa2-efc0-0001-001203000020","source_event_id_unique":true,"source_pre_event_id":"00065a1d-7fa2-efc0-0000-001202000020","translation":"FOLD_RETURN_TO_ZERO","unfold_event_id":"00065a1d-7f9e-9678-0000-001202000020","zero_hair":true}
{"channel":"live_orders_ethusd","interaction_index":673,"natural_form":{"channel":"live_orders_ethusd","order_id":"2044303881297922","order_subtype":5,"order_type":1},"natural_form_sha256":"928e9518853b286d68dcfaf51943e77580041a6ab63db4fa233ba965c5fa58ae","order_source":"orderbook","orders_submitted":0,"presentation":{"amount":"20.063885","amount_traded":"0","microtimestamp":"1787932602200000","price":"2492.04"},"previous_record_hash":"62d2942844b093a11b93e6840b4101450aa89d2f21fb48c5953492c732f27f13","profit_assessment":null,"record_hash":"1adf628b581a6d6b8cf5c0b5bb13a1f819b7b92d1c28c2eb71294c9655643269","recorded_unix_us":1787932602239712,"recorded_utc":"2026-08-28T15:56:42.239712Z","schema_version":"nrrf810.exchange_authored_interactive_closure.v1","source_chain_continuous":true,"source_event":"order_deleted","source_event_id":"00065a1d-7fa2-efc0-0002-001200000020","source_event_id_unique":true,"source_pre_event_id":"00065a1d-7fa2-efc0-0001-001203000020","translation":"FOLD_RETURN_TO_ZERO","unfold_event_id":"00065a1d-7f9e-c558-0000-001200000020","zero_hair":true}
{"channel":"live_orders_ethusd","interaction_index":674,"natural_form":{"channel":"live_orders_ethusd","order_id":"2044303881306112","order_subtype":5,"order_type":1},"natural_form_sha256":"f84e429699388a7502f88fdfe3f9104855c16a8e56a90eaf6d5f66a497edfc35","order_source":"orderbook","orders_submitted":0,"presentation":{"amount":"40.010118","amount_traded":"0","microtimestamp":"1787932602200000","price":"2499.37"},"previous_record_hash":"1adf628b581a6d6b8cf5c0b5bb13a1f819b7b92d1c28c2eb71294c9655643269","profit_assessment":null,"record_hash":"6de1f87b0f1bb8fc43cbeae1f7aa5e6e5e9b177014bf32c1b91ab704141201e5","recorded_unix_us":1787932602239749,"recorded_utc":"2026-08-28T15:56:42.239749Z","schema_version":"nrrf810.exchange_authored_interactive_closure.v1","source_chain_continuous":true,"source_event":"order_deleted","source_event_id":"00065a1d-7fa2-efc0-0003-001201000020","source_event_id_unique":true,"source_pre_event_id":"00065a1d-7fa2-efc0-0002-001200000020","translation":"FOLD_RETURN_TO_ZERO","unfold_event_id":"00065a1d-7f9e-cd28-0001-001202000020","zero_hair":true}
{"channel":"live_orders_ethusd","interaction_index":675,"natural_form":{"channel":"live_orders_ethusd","order_id":"2044303881347095","order_subtype":5,"order_type":0},"natural_form_sha256":"8900a8fc481300b28d1d89fa9387751bf643441ea59fe387c6e759ee8f8917e3","order_source":"orderbook","orders_submitted":0,"presentation":{"amount":"20.225289","amount_traded":"0","microtimestamp":"1787932602201000","price":"2472.15"},"previous_record_hash":"6de1f87b0f1bb8fc43cbeae1f7aa5e6e5e9b177014bf32c1b91ab704141201e5","profit_assessment":null,"record_hash":"0b8098b641fac7bad4e5368d4bfc85d5a4c2c7ca06a086318e5859731fa18b85","recorded_unix_us":1787932602239870,"recorded_utc":"2026-08-28T15:56:42.239870Z","schema_version":"nrrf810.exchange_authored_interactive_closure.v1","source_chain_continuous":true,"source_event":"order_deleted","source_event_id":"00065a1d-7fa2-f3a8-0000-001202000020","source_event_id_unique":true,"source_pre_event_id":"00065a1d-7fa2-efc0-0003-001201000020","translation":"FOLD_RETURN_TO_ZERO","unfold_event_id":"00065a1d-7f9e-f820-0000-001200000020","zero_hair":true}
{"channel":"live_orders_ethusd","interaction_index":676,"natural_form":{"channel":"live_orders_ethusd","order_id":"2044303881355264","order_subtype":5,"order_type":0},"natural_form_sha256":"6c9cc2408a5dadf899536fa4cad6a8a394e2e328b5cfde7469dad2a382d3fc31","order_source":"orderbook","orders_submitted":0,"presentation":{"amount":"40.609081","amount_traded":"0","microtimestamp":"1787932602201000","price":"2462.50"},"previous_record_hash":"0b8098b641fac7bad4e5368d4bfc85d5a4c2c7ca06a086318e5859731fa18b85","profit_assessment":null,"record_hash":"3b523962bcd7ad54563aa88b4e4121e9768f3c7f07b32d08a3b514aa1f0c0a13","recorded_unix_us":1787932602240073,"recorded_utc":"2026-08-28T15:56:42.240073Z","schema_version":"nrrf810.exchange_authored_interactive_closure.v1","source_chain_continuous":true,"source_event":"order_deleted","source_event_id":"00065a1d-7fa2-f3a8-0001-001203000020","source_event_id_unique":true,"source_pre_event_id":"00065a1d-7fa2-f3a8-0000-001202000020","translation":"FOLD_RETURN_TO_ZERO","unfold_event_id":"00065a1d-7f9e-fc08-0000-001201000020","zero_hair":true}
{"channel":"live_orders_ethusd","interaction_index":677,"natural_form":{"channel":"live_orders_ethusd","order_id":"2044303881441288","order_subtype":5,"order_type":1},"natural_form_sha256":"eae264c4f2a21a2e7e8f4b1273732cb05e714b91f0d7943fb21ca25d9a32a4cb","order_source":"orderbook","orders_submitted":0,"presentation":{"amount":"4.027586","amount_traded":"0","microtimestamp":"1787932602202000","price":"2482.88"},"previous_record_hash":"3b523962bcd7ad54563aa88b4e4121e9768f3c7f07b32d08a3b514aa1f0c0a13","profit_assessment":null,"record_hash":"04ceba080996eb8ddbaadd91adbd0699589f7bbfa7b7b659fefae4d45c345983","recorded_unix_us":1787932602240117,"recorded_utc":"2026-08-28T15:56:42.240117Z","schema_version":"nrrf810.exchange_authored_interactive_closure.v1","source_chain_continuous":true,"source_event":"order_deleted","source_event_id":"00065a1d-7fa2-f790-0000-001200000020","source_event_id_unique":true,"source_pre_event_id":"00065a1d-7fa2-f3a8-0001-001203000020","translation":"FOLD_RETURN_TO_ZERO","unfold_event_id":"00065a1d-7f9f-51f8-0000-001200000020","zero_hair":true}
{"channel":"live_orders_ethusd","interaction_index":678,"natural_form":{"channel":"live_orders_ethusd","order_id":"2044303881457666","order_subtype":5,"order_type":0},"natural_form_sha256":"704314872c59d6ee8c1d80a4914be9067fc753261341493ca99061a78dd2357d","order_source":"orderbook","orders_submitted":0,"presentation":{"amount":"20.235437","amount_traded":"0","microtimestamp":"1787932602202000","price":"2470.91"},"previous_record_hash":"04ceba080996eb8ddbaadd91adbd0699589f7bbfa7b7b659fefae4d45c345983","profit_assessment":null,"record_hash":"216e3c59ace8079320e46dd59254a3b6ab109524c2753df803205d9f054882d1","recorded_unix_us":1787932602240149,"recorded_utc":"2026-08-28T15:56:42.240149Z","schema_version":"nrrf810.exchange_authored_interactive_closure.v1","source_chain_continuous":true,"source_event":"order_deleted","source_event_id":"00065a1d-7fa2-f790-0001-001201000020","source_event_id_unique":true,"source_pre_event_id":"00065a1d-7fa2-f790-0000-001200000020","translation":"FOLD_RETURN_TO_ZERO","unfold_event_id":"00065a1d-7f9f-5db0-0000-001201000020","zero_hair":true}
{"channel":"live_orders_btcusd","interaction_index":679,"natural_form":{"channel":"live_orders_btcusd","order_id":"2044303882424331","order_subtype":5,"order_type":1},"natural_form_sha256":"8220f59aa7bc8cc47ad300a83ca536d269d179315d45a3fd6a2834441748edbc","order_source":"orderbook","orders_submitted":0,"presentation":{"amount":"0.06310787","amount_traded":"0","microtimestamp":"1787932602202000","price":"78521.10"},"previous_record_hash":"216e3c59ace8079320e46dd59254a3b6ab109524c2753df803205d9f054882d1","profit_assessment":null,"record_hash":"eb4779e8007fe9a631901286c020458adcd99bc643c36e11318efc4fe28b963f","recorded_unix_us":1787932602240247,"recorded_utc":"2026-08-28T15:56:42.240247Z","schema_version":"nrrf810.exchange_authored_interactive_closure.v1","source_chain_continuous":true,"source_event":"order_created","source_event_id":"00065a1d-7fa2-f790-0000-000100000020","source_event_id_unique":true,"source_pre_event_id":"00065a1d-7fa2-c4c8-0001-000103000020","translation":"UNFOLD_TO_INF","unfold_event_id":null,"zero_hair":false}
{"channel":"live_orders_btcusd","interaction_index":680,"natural_form":{"channel":"live_orders_btcusd","order_id":"2044303882424331","order_subtype":5,"order_type":1},"natural_form_sha256":"8220f59aa7bc8cc47ad300a83ca536d269d179315d45a3fd6a2834441748edbc","order_source":"orderbook","orders_submitted":0,"presentation":{"amount":"0.06310787","amount_traded":"0","microtimestamp":"1787932602202000","price":"78521.10"},"previous_record_hash":"eb4779e8007fe9a631901286c020458adcd99bc643c36e11318efc4fe28b963f","profit_assessment":null,"record_hash":"5272cab9f8b6ed02de4c3de0a385cb1b7adecb7abb122dc50675d84fc504820b","recorded_unix_us":1787932602240366,"recorded_utc":"2026-08-28T15:56:42.240366Z","schema_version":"nrrf810.exchange_authored_interactive_closure.v1","source_chain_continuous":true,"source_event":"order_deleted","source_event_id":"00065a1d-7fa2-f790-0001-000101000020","source_event_id_unique":true,"source_pre_event_id":"00065a1d-7fa2-f790-0000-000100000020","translation":"FOLD_RETURN_TO_ZERO","unfold_event_id":"00065a1d-7fa2-f790-0000-000100000020","zero_hair":true}
{"channel":"live_orders_ethusd","interaction_index":681,"natural_form":{"channel":"live_orders_ethusd","order_id":"2044303882252297","order_subtype":5,"order_type":0},"natural_form_sha256":"fb471071cfdb230e4cf84a4e8fcc9496d87d36be0ac2075283e0668828c9341d","order_source":"orderbook","orders_submitted":0,"presentation":{"amount":"0.403088","amount_traded":"0","microtimestamp":"1787932602213000","price":"2480.02"},"previous_record_hash":"5272cab9f8b6ed02de4c3de0a385cb1b7adecb7abb122dc50675d84fc504820b","profit_assessment":null,"record_hash":"9ccfe768d0ef185b2dda08b252aa7ea6b1a0bff51103259e28e36d0f713fba58","recorded_unix_us":1787932602249326,"recorded_utc":"2026-08-28T15:56:42.249326Z","schema_version":"nrrf810.exchange_authored_interactive_closure.v1","source_chain_continuous":true,"source_event":"order_deleted","source_event_id":"00065a1d-7fa3-2288-0000-001202000020","source_event_id_unique":true,"source_pre_event_id":"00065a1d-7fa2-f790-0001-001201000020","translation":"FOLD_RETURN_TO_ZERO","unfold_event_id":"00065a1d-7fa2-5768-0000-001203000020","zero_hair":true}
{"channel":"live_orders_btcusd","interaction_index":682,"natural_form":{"channel":"live_orders_btcusd","order_id":"2044303882489873","order_subtype":5,"order_type":1},"natural_form_sha256":"de01432f10e0ecbf79ed75841808cac1513ece72371d31867430a8125d5f8b71","order_source":"orderbook","orders_submitted":0,"presentation":{"amount":"0.10000000","amount_traded":"0","microtimestamp":"1787932602219000","price":"78522.62"},"previous_record_hash":"9ccfe768d0ef185b2dda08b252aa7ea6b1a0bff51103259e28e36d0f713fba58","profit_assessment":null,"record_hash":"2dccbff4c1c2106902ee7e39b96869b7e412ceda27cb92e002d6296536f7258e","recorded_unix_us":1787932602249550,"recorded_utc":"2026-08-28T15:56:42.249550Z","schema_version":"nrrf810.exchange_authored_interactive_closure.v1","source_chain_continuous":true,"source_event":"order_created","source_event_id":"00065a1d-7fa3-39f8-0000-000102000020","source_event_id_unique":true,"source_pre_event_id":"00065a1d-7fa2-f790-0001-000101000020","translation":"UNFOLD_TO_INF","unfold_event_id":null,"zero_hair":false}
{"channel":"live_orders_btcusd","interaction_index":683,"natural_form":{"channel":"live_orders_btcusd","order_id":"2044303882489873","order_subtype":5,"order_type":1},"natural_form_sha256":"de01432f10e0ecbf79ed75841808cac1513ece72371d31867430a8125d5f8b71","order_source":"orderbook","orders_submitted":0,"presentation":{"amount":"0.10000000","amount_traded":"0","microtimestamp":"1787932602219000","price":"78522.62"},"previous_record_hash":"2dccbff4c1c2106902ee7e39b96869b7e412ceda27cb92e002d6296536f7258e","profit_assessment":null,"record_hash":"cd1d74302c554191326533fc1a137814fcfd8e2f283722de1451551ceeb75545","recorded_unix_us":1787932602249600,"recorded_utc":"2026-08-28T15:56:42.249600Z","schema_version":"nrrf810.exchange_authored_interactive_closure.v1","source_chain_continuous":true,"source_event":"order_deleted","source_event_id":"00065a1d-7fa3-39f8-0001-000103000020","source_event_id_unique":true,"source_pre_event_id":"00065a1d-7fa3-39f8-0000-000102000020","translation":"FOLD_RETURN_TO_ZERO","unfold_event_id":"00065a1d-7fa3-39f8-0000-000102000020","zero_hair":true}
{"channel":"live_orders_ethusd","interaction_index":684,"natural_form":{"channel":"live_orders_ethusd","order_id":"2044303882510346","order_subtype":5,"order_type":0},"natural_form_sha256":"df47de35d108088c4cc7126220adcd86b8b7b2e81cf8571c0ffee81179c69645","order_source":"orderbook","orders_submitted":0,"presentation":{"amount":"0.403085","amount_traded":"0","microtimestamp":"1787932602224000","price":"2480.10"},"previous_record_hash":"cd1d74302c554191326533fc1a137814fcfd8e2f283722de1451551ceeb75545","profit_assessment":null,"record_hash":"10fee0545ff244ed28dd17d9d3b966f97b7613f8a9ede1d7e46f04c1edcbc93f","recorded_unix_us":1787932602265843,"recorded_utc":"2026-08-28T15:56:42.265843Z","schema_version":"nrrf810.exchange_authored_interactive_closure.v1","source_chain_continuous":true,"source_event":"order_created","source_event_id":"00065a1d-7fa3-4d80-0000-001203000020","source_event_id_unique":true,"source_pre_event_id":"00065a1d-7fa3-2288-0000-001202000020","translation":"UNFOLD_TO_INF","unfold_event_id":null,"zero_hair":false}
{"channel":"live_orders_ethusd","interaction_index":685,"natural_form":{"channel":"live_orders_ethusd","order_id":"2044303882510346","order_subtype":5,"order_type":0},"natural_form_sha256":"df47de35d108088c4cc7126220adcd86b8b7b2e81cf8571c0ffee81179c69645","order_source":"orderbook","orders_submitted":0,"presentation":{"amount":"0.403085","amount_traded":"0","microtimestamp":"1787932602227000","price":"2480.10"},"previous_record_hash":"10fee0545ff244ed28dd17d9d3b966f97b7613f8a9ede1d7e46f04c1edcbc93f","profit_assessment":null,"record_hash":"453208b8e98f927cc2e2018249e4b38a0bb3d9587089cb797f6d8ca7d658cd54","recorded_unix_us":1787932602266118,"recorded_utc":"2026-08-28T15:56:42.266118Z","schema_version":"nrrf810.exchange_authored_interactive_closure.v1","source_chain_continuous":true,"source_event":"order_deleted","source_event_id":"00065a1d-7fa3-5938-0000-001200000020","source_event_id_unique":true,"source_pre_event_id":"00065a1d-7fa3-4d80-0000-001203000020","translation":"FOLD_RETURN_TO_ZERO","unfold_event_id":"00065a1d-7fa3-4d80-0000-001203000020","zero_hair":true}
{"channel":"live_orders_btcusd","interaction_index":686,"natural_form":{"channel":"live_orders_btcusd","order_id":"2044303882530818","order_subtype":5,"order_type":0},"natural_form_sha256":"c25ab10cfadc36c456d1ee6fbfa85ad223d5b1ccdd1caf16442df0f8154fc454","order_source":"orderbook","orders_submitted":0,"presentation":{"amount":"0.00140266","amount_traded":"0","microtimestamp":"1787932602228000","price":"70668.36"},"previous_record_hash":"453208b8e98f927cc2e2018249e4b38a0bb3d9587089cb797f6d8ca7d658cd54","profit_assessment":null,"record_hash":"e11b37c6a7ac7df9068187790544f3e183388e32f548c02088d4654bb3bfc214","recorded_unix_us":1787932602266208,"recorded_utc":"2026-08-28T15:56:42.266208Z","schema_version":"nrrf810.exchange_authored_interactive_closure.v1","source_chain_continuous":true,"source_event":"order_created","source_event_id":"00065a1d-7fa3-5d20-0000-000100000020","source_event_id_unique":true,"source_pre_event_id":"00065a1d-7fa3-39f8-0001-000103000020","translation":"UNFOLD_TO_INF","unfold_event_id":null,"zero_hair":false}
{"channel":"live_orders_ethusd","interaction_index":687,"natural_form":{"channel":"live_orders_ethusd","order_id":"2044303882551300","order_subtype":5,"order_type":1},"natural_form_sha256":"52f4c4410a2b7b8e86cfd3a138057b51122bd1eb860e0b0a2f853351760ece28","order_source":"orderbook","orders_submitted":0,"presentation":{"amount":"0.275637","amount_traded":"0","microtimestamp":"1787932602233000","price":"2481.27"},"previous_record_hash":"e11b37c6a7ac7df9068187790544f3e183388e32f548c02088d4654bb3bfc214","profit_assessment":null,"record_hash":"1d81541ecff4b50a7a1a0e724b0a4330719fbc4099a0bedc29592c787f932a2b","recorded_unix_us":1787932602266498,"recorded_utc":"2026-08-28T15:56:42.266498Z","schema_version":"nrrf810.exchange_authored_interactive_closure.v1","source_chain_continuous":true,"source_event":"order_created","source_event_id":"00065a1d-7fa3-70a8-0000-001201000020","source_event_id_unique":true,"source_pre_event_id":"00065a1d-7fa3-5938-0000-001200000020","translation":"UNFOLD_TO_INF","unfold_event_id":null,"zero_hair":false}
{"channel":"live_orders_btcusd","interaction_index":688,"natural_form":{"channel":"live_orders_btcusd","order_id":"2044303882551307","order_subtype":5,"order_type":1},"natural_form_sha256":"bf4c83d7c45c238b11a177cbc1f7c33e8202ae3dcabdd9f45f979108b1dd783e","order_source":"orderbook","orders_submitted":0,"presentation":{"amount":"0.06310787","amount_traded":"0","microtimestamp":"1787932602234000","price":"78520.44"},"previous_record_hash":"1d81541ecff4b50a7a1a0e724b0a4330719fbc4099a0bedc29592c787f932a2b","profit_assessment":null,"record_hash":"0ff40565e6085e95890355df8b43fa1ee9178b43f4068c9e60df828995507aa4","recorded_unix_us":1787932602275298,"recorded_utc":"2026-08-28T15:56:42.275298Z","schema_version":"nrrf810.exchange_authored_interactive_closure.v1","source_chain_continuous":true,"source_event":"order_created","source_event_id":"00065a1d-7fa3-7490-0000-000101000020","source_event_id_unique":true,"source_pre_event_id":"00065a1d-7fa3-5d20-0000-000100000020","translation":"UNFOLD_TO_INF","unfold_event_id":null,"zero_hair":false}
{"channel":"live_orders_btcusd","interaction_index":689,"natural_form":{"channel":"live_orders_btcusd","order_id":"2044303882551307","order_subtype":5,"order_type":1},"natural_form_sha256":"bf4c83d7c45c238b11a177cbc1f7c33e8202ae3dcabdd9f45f979108b1dd783e","order_source":"orderbook","orders_submitted":0,"presentation":{"amount":"0.06310787","amount_traded":"0","microtimestamp":"1787932602234000","price":"78520.44"},"previous_record_hash":"0ff40565e6085e95890355df8b43fa1ee9178b43f4068c9e60df828995507aa4","profit_assessment":null,"record_hash":"307009c2b8bf24d78aab7fbfc39832e343a1580dc0633f337e69099a66aed2d0","recorded_unix_us":1787932602275492,"recorded_utc":"2026-08-28T15:56:42.275492Z","schema_version":"nrrf810.exchange_authored_interactive_closure.v1","source_chain_continuous":true,"source_event":"order_deleted","source_event_id":"00065a1d-7fa3-7490-0001-000102000020","source_event_id_unique":true,"source_pre_event_id":"00065a1d-7fa3-7490-0000-000101000020","translation":"FOLD_RETURN_TO_ZERO","unfold_event_id":"00065a1d-7fa3-7490-0000-000101000020","zero_hair":true}
{"channel":"live_orders_btcusd","interaction_index":690,"natural_form":{"channel":"live_orders_btcusd","order_id":"2044303882555395","order_subtype":5,"order_type":1},"natural_form_sha256":"3e807761b4e31d8f8674932cedc8ae9e7ba4146d7069c72cdf4e132ef914adc7","order_source":"orderbook","orders_submitted":0,"presentation":{"amount":"0.10000000","amount_traded":"0","microtimestamp":"1787932602234000","price":"78522.63"},"previous_record_hash":"307009c2b8bf24d78aab7fbfc39832e343a1580dc0633f337e69099a66aed2d0","profit_assessment":null,"record_hash":"98e7df9ee33e54f16a1f616d32a380dcfde6fef88dc34419918b13361a286285","recorded_unix_us":1787932602275654,"recorded_utc":"2026-08-28T15:56:42.275654Z","schema_version":"nrrf810.exchange_authored_interactive_closure.v1","source_chain_continuous":true,"source_event":"order_created","source_event_id":"00065a1d-7fa3-7490-0002-000103000020","source_event_id_unique":true,"source_pre_event_id":"00065a1d-7fa3-7490-0001-000102000020","translation":"UNFOLD_TO_INF","unfold_event_id":null,"zero_hair":false}
{"channel":"live_orders_btcusd","interaction_index":691,"natural_form":{"channel":"live_orders_btcusd","order_id":"2044303882555395","order_subtype":5,"order_type":1},"natural_form_sha256":"3e807761b4e31d8f8674932cedc8ae9e7ba4146d7069c72cdf4e132ef914adc7","order_source":"orderbook","orders_submitted":0,"presentation":{"amount":"0.10000000","amount_traded":"0","microtimestamp":"1787932602234000","price":"78522.63"},"previous_record_hash":"98e7df9ee33e54f16a1f616d32a380dcfde6fef88dc34419918b13361a286285","profit_assessment":null,"record_hash":"9e832c8bf2e732253e89ad1e4529b681de637c8f220f2841c0983ff85dcf31d3","recorded_unix_us":1787932602278504,"recorded_utc":"2026-08-28T15:56:42.278504Z","schema_version":"nrrf810.exchange_authored_interactive_closure.v1","source_chain_continuous":true,"source_event":"order_deleted","source_event_id":"00065a1d-7fa3-7490-0003-000100000020","source_event_id_unique":true,"source_pre_event_id":"00065a1d-7fa3-7490-0002-000103000020","translation":"FOLD_RETURN_TO_ZERO","unfold_event_id":"00065a1d-7fa3-7490-0002-000103000020","zero_hair":true}
{"channel":"live_orders_ethusd","interaction_index":692,"natural_form":{"channel":"live_orders_ethusd","order_id":"2044303882563594","order_subtype":5,"order_type":0},"natural_form_sha256":"060d5f7c4b1a51d32b3a161eb6db180f1058b07d0f83623c6b488ab75eda4429","order_source":"orderbook","orders_submitted":0,"presentation":{"amount":"0.403087","amount_traded":"0","microtimestamp":"1787932602237000","price":"2480.03"},"previous_record_hash":"9e832c8bf2e732253e89ad1e4529b681de637c8f220f2841c0983ff85dcf31d3","profit_assessment":null,"record_hash":"c6c64242a51d6b2627dbd1e2d70d401a797c5133be5c8038531e144b2702ad8b","recorded_unix_us":1787932602278567,"recorded_utc":"2026-08-28T15:56:42.278567Z","schema_version":"nrrf810.exchange_authored_interactive_closure.v1","source_chain_continuous":true,"source_event":"order_created","source_event_id":"00065a1d-7fa3-8048-0000-001202000020","source_event_id_unique":true,"source_pre_event_id":"00065a1d-7fa3-70a8-0000-001201000020","translation":"UNFOLD_TO_INF","unfold_event_id":null,"zero_hair":false}
{"channel":"live_orders_btcusd","interaction_index":693,"natural_form":{"channel":"live_orders_btcusd","order_id":"2044303882584076","order_subtype":4,"order_type":1},"natural_form_sha256":"f47dffc8f5990d6020478a148e53e5ff64ffa6f081e0fc1ffc17c7db00506b8c","order_source":"orderbook","orders_submitted":0,"presentation":{"amount":"0.00006244","amount_traded":"0","microtimestamp":"1787932602242000","price":"80878.00"},"previous_record_hash":"c6c64242a51d6b2627dbd1e2d70d401a797c5133be5c8038531e144b2702ad8b","profit_assessment":null,"record_hash":"df244b14030c37140194866e2756cb1962f47e1d592f89fac9aeb3cada15ce81","recorded_unix_us":1787932602278717,"recorded_utc":"2026-08-28T15:56:42.278717Z","schema_version":"nrrf810.exchange_authored_interactive_closure.v1","source_chain_continuous":true,"source_event":"order_created","source_event_id":"00065a1d-7fa3-93d0-0000-000101000020","source_event_id_unique":true,"source_pre_event_id":"00065a1d-7fa3-7490-0003-000100000020","translation":"UNFOLD_TO_INF","unfold_event_id":null,"zero_hair":false}
{"channel":"live_orders_btcusd","interaction_index":694,"natural_form":{"channel":"live_orders_btcusd","order_id":"2044303882584076","order_subtype":4,"order_type":1},"natural_form_sha256":"f47dffc8f5990d6020478a148e53e5ff64ffa6f081e0fc1ffc17c7db00506b8c","order_source":"orderbook","orders_submitted":0,"presentation":{"amount":"0.00006244","amount_traded":"0","microtimestamp":"1787932602242000","price":"80878.00"},"previous_record_hash":"df244b14030c37140194866e2756cb1962f47e1d592f89fac9aeb3cada15ce81","profit_assessment":null,"record_hash":"4e69b525567f3b5c7db8efa9b00d79ef6ede6515aabbb66c16c40cb1d6cd198c","recorded_unix_us":1787932602278753,"recorded_utc":"2026-08-28T15:56:42.278753Z","schema_version":"nrrf810.exchange_authored_interactive_closure.v1","source_chain_continuous":true,"source_event":"order_deleted","source_event_id":"00065a1d-7fa3-93d0-0001-000102000020","source_event_id_unique":true,"source_pre_event_id":"00065a1d-7fa3-93d0-0000-000101000020","translation":"FOLD_RETURN_TO_ZERO","unfold_event_id":"00065a1d-7fa3-93d0-0000-000101000020","zero_hair":true}
{"channel":"live_orders_ethbtc","interaction_index":695,"natural_form":{"channel":"live_orders_ethbtc","order_id":"2044303882604554","order_subtype":5,"order_type":1},"natural_form_sha256":"a2a126ffa2758196b057ac83644ddcc7d1e4881eb1d8575f71bef1f7085fb629","order_source":"orderbook","orders_submitted":0,"presentation":{"amount":"4.23144408","amount_traded":"0","microtimestamp":"1787932602247000","price":"0.03161011"},"previous_record_hash":"4e69b525567f3b5c7db8efa9b00d79ef6ede6515aabbb66c16c40cb1d6cd198c","profit_assessment":null,"record_hash":"1fa758ae9561f251cb83363123386b2984c990e6d151b240364fbc2a9ced553b","recorded_unix_us":1787932602278861,"recorded_utc":"2026-08-28T15:56:42.278861Z","schema_version":"nrrf810.exchange_authored_interactive_closure.v1","source_chain_continuous":true,"source_event":"order_created","source_event_id":"00065a1d-7fa3-a758-0000-001103000020","source_event_id_unique":true,"source_pre_event_id":"00065a1d-7fa2-ad58-0000-001102000020","translation":"UNFOLD_TO_INF","unfold_event_id":null,"zero_hair":false}
{"channel":"live_orders_ethusd","interaction_index":696,"natural_form":{"channel":"live_orders_ethusd","order_id":"2044303882563594","order_subtype":5,"order_type":0},"natural_form_sha256":"060d5f7c4b1a51d32b3a161eb6db180f1058b07d0f83623c6b488ab75eda4429","order_source":"orderbook","orders_submitted":0,"presentation":{"amount":"0.403087","amount_traded":"0","microtimestamp":"1787932602248000","price":"2480.03"},"previous_record_hash":"1fa758ae9561f251cb83363123386b2984c990e6d151b240364fbc2a9ced553b","profit_assessment":null,"record_hash":"a5895f5a4f59bf146fb7854061cfc81553eddae36e536500be8ebb0fbd4cad0b","recorded_unix_us":1787932602293906,"recorded_utc":"2026-08-28T15:56:42.293906Z","schema_version":"nrrf810.exchange_authored_interactive_closure.v1","source_chain_continuous":true,"source_event":"order_deleted","source_event_id":"00065a1d-7fa3-ab40-0000-001203000020","source_event_id_unique":true,"source_pre_event_id":"00065a1d-7fa3-8048-0000-001202000020","translation":"FOLD_RETURN_TO_ZERO","unfold_event_id":"00065a1d-7fa3-8048-0000-001202000020","zero_hair":true}
{"channel":"live_orders_ethusd","interaction_index":697,"natural_form":{"channel":"live_orders_ethusd","order_id":"2044303882612741","order_subtype":5,"order_type":0},"natural_form_sha256":"1b81b438cee95cfcbfb9ea41b2aa41021ce2027f36a80a9a28815a206d3e35a5","order_source":"orderbook","orders_submitted":0,"presentation":{"amount":"2.734871","amount_traded":"0","microtimestamp":"1787932602249000","price":"2480.21"},"previous_record_hash":"a5895f5a4f59bf146fb7854061cfc81553eddae36e536500be8ebb0fbd4cad0b","profit_assessment":null,"record_hash":"2b63f111084cd8703ec94437a5f1338fd465fcfab8cc1f038d44f100b8d91dcf","recorded_unix_us":1787932602294137,"recorded_utc":"2026-08-28T15:56:42.294137Z","schema_version":"nrrf810.exchange_authored_interactive_closure.v1","source_chain_continuous":true,"source_event":"order_created","source_event_id":"00065a1d-7fa3-af28-0000-001200000020","source_event_id_unique":true,"source_pre_event_id":"00065a1d-7fa3-ab40-0000-001203000020","translation":"UNFOLD_TO_INF","unfold_event_id":null,"zero_hair":false}
{"channel":"live_orders_btcusd","interaction_index":698,"natural_form":{"channel":"live_orders_btcusd","order_id":"2044303882625030","order_subtype":5,"order_type":1},"natural_form_sha256":"c6ca7b5441d72ea439d7263da3bfa59a4a3ef758925a86b59b5482cc5388fb7f","order_source":"orderbook","orders_submitted":0,"presentation":{"amount":"0.10000000","amount_traded":"0","microtimestamp":"1787932602251000","price":"78522.62"},"previous_record_hash":"2b63f111084cd8703ec94437a5f1338fd465fcfab8cc1f038d44f100b8d91dcf","profit_assessment":null,"record_hash":"d4f7cdb988b6ac7fe2e5b5080e8698d9973a9c08005f49aa1c5d9c89da6fd14c","recorded_unix_us":1787932602294292,"recorded_utc":"2026-08-28T15:56:42.294292Z","schema_version":"nrrf810.exchange_authored_interactive_closure.v1","source_chain_continuous":true,"source_event":"order_created","source_event_id":"00065a1d-7fa3-b6f8-0000-000103000020","source_event_id_unique":true,"source_pre_event_id":"00065a1d-7fa3-93d0-0001-000102000020","translation":"UNFOLD_TO_INF","unfold_event_id":null,"zero_hair":false}
{"channel":"live_orders_btcusd","interaction_index":699,"natural_form":{"channel":"live_orders_btcusd","order_id":"2044303882625030","order_subtype":5,"order_type":1},"natural_form_sha256":"c6ca7b5441d72ea439d7263da3bfa59a4a3ef758925a86b59b5482cc5388fb7f","order_source":"orderbook","orders_submitted":0,"presentation":{"amount":"0.10000000","amount_traded":"0","microtimestamp":"1787932602251000","price":"78522.62"},"previous_record_hash":"d4f7cdb988b6ac7fe2e5b5080e8698d9973a9c08005f49aa1c5d9c89da6fd14c","profit_assessment":null,"record_hash":"111a1516e6e00af512d6f68c294a585e1ef5940a70c64957800489c3a2c03af5","recorded_unix_us":1787932602294418,"recorded_utc":"2026-08-28T15:56:42.294418Z","schema_version":"nrrf810.exchange_authored_interactive_closure.v1","source_chain_continuous":true,"source_event":"order_deleted","source_event_id":"00065a1d-7fa3-b6f8-0001-000100000020","source_event_id_unique":true,"source_pre_event_id":"00065a1d-7fa3-b6f8-0000-000103000020","translation":"FOLD_RETURN_TO_ZERO","unfold_event_id":"00065a1d-7fa3-b6f8-0000-000103000020","zero_hair":true}
{"channel":"live_orders_ethusd","interaction_index":700,"natural_form":{"channel":"live_orders_ethusd","order_id":"2044303882661889","order_subtype":5,"order_type":0},"natural_form_sha256":"f8b338228c8b9f50f9f3890a5377bd9e6204e60f4b9218ce0602788eef844ccf","order_source":"orderbook","orders_submitted":0,"presentation":{"amount":"0.403086","amount_traded":"0","microtimestamp":"1787932602260000","price":"2480.10"},"previous_record_hash":"111a1516e6e00af512d6f68c294a585e1ef5940a70c64957800489c3a2c03af5","profit_assessment":null,"record_hash":"a2f0d4aa93fe3e489d6dacdf7851c0f8bee6e281c848a194e36b98e296247e48","recorded_unix_us":1787932602294566,"recorded_utc":"2026-08-28T15:56:42.294566Z","schema_version":"nrrf810.exchange_authored_interactive_closure.v1","source_chain_continuous":true,"source_event":"order_created","source_event_id":"00065a1d-7fa3-da20-0000-001201000020","source_event_id_unique":true,"source_pre_event_id":"00065a1d-7fa3-af28-0000-001200000020","translation":"UNFOLD_TO_INF","unfold_event_id":null,"zero_hair":false}
{"channel":"live_orders_ethusd","interaction_index":701,"natural_form":{"channel":"live_orders_ethusd","order_id":"2044303881973764","order_subtype":5,"order_type":0},"natural_form_sha256":"47c417f3a09cd69c27a0e9aa8fe47ae315c4181f6fbd19ee52fab223c83b85cd","order_source":"orderbook","orders_submitted":0,"presentation":{"amount":"0.403088","amount_traded":"0","microtimestamp":"1787932602261000","price":"2480.10"},"previous_record_hash":"a2f0d4aa93fe3e489d6dacdf7851c0f8bee6e281c848a194e36b98e296247e48","profit_assessment":null,"record_hash":"acd5f80ca4912e41a33d060de0e9f0dd202452af423c6d13537fc6d69b347f35","recorded_unix_us":1787932602306938,"recorded_utc":"2026-08-28T15:56:42.306938Z","schema_version":"nrrf810.exchange_authored_interactive_closure.v1","source_chain_continuous":true,"source_event":"order_deleted","source_event_id":"00065a1d-7fa3-de08-0000-001202000020","source_event_id_unique":true,"source_pre_event_id":"00065a1d-7fa3-da20-0000-001201000020","translation":"FOLD_RETURN_TO_ZERO","unfold_event_id":"00065a1d-7fa1-49e0-0000-001201000020","zero_hair":true}
{"channel":"live_orders_ethusd","interaction_index":702,"natural_form":{"channel":"live_orders_ethusd","order_id":"2044303882694659","order_subtype":5,"order_type":0},"natural_form_sha256":"b3e4a141bc59eaf1c3b1f65f0dc164d3e8394ae4212d0e9ab323da5ad600eb5d","order_source":"orderbook","orders_submitted":0,"presentation":{"amount":"0.403086","amount_traded":"0","microtimestamp":"1787932602268000","price":"2480.16"},"previous_record_hash":"acd5f80ca4912e41a33d060de0e9f0dd202452af423c6d13537fc6d69b347f35","profit_assessment":null,"record_hash":"bc754bf2cf6fec829f1c332a7a2803220b8f2bb52bad681d687c50eacd8b37c4","recorded_unix_us":1787932602307182,"recorded_utc":"2026-08-28T15:56:42.307182Z","schema_version":"nrrf810.exchange_authored_interactive_closure.v1","source_chain_continuous":true,"source_event":"order_created","source_event_id":"00065a1d-7fa3-f960-0000-001203000020","source_event_id_unique":true,"source_pre_event_id":"00065a1d-7fa3-de08-0000-001202000020","translation":"UNFOLD_TO_INF","unfold_event_id":null,"zero_hair":false}
{"channel":"live_orders_ethusd","interaction_index":703,"natural_form":{"channel":"live_orders_ethusd","order_id":"2044303874338819","order_subtype":0,"order_type":0},"natural_form_sha256":"45ccdc28654b3c46d85bd8dd32a66261cc77dcd404322c9b6ae22f94c5dad88e","order_source":"orderbook","orders_submitted":0,"presentation":{"amount":"0.042969","amount_traded":"0","microtimestamp":"1787932602272000","price":"2472.16"},"previous_record_hash":"bc754bf2cf6fec829f1c332a7a2803220b8f2bb52bad681d687c50eacd8b37c4","profit_assessment":null,"record_hash":"6d66cb3f1ca72bf7f51c4c29689c0a56852f22ce2d5cc6ca7557a235d26c6346","recorded_unix_us":1787932602307328,"recorded_utc":"2026-08-28T15:56:42.307328Z","schema_version":"nrrf810.exchange_authored_interactive_closure.v1","source_chain_continuous":true,"source_event":"order_deleted","source_event_id":"00065a1d-7fa4-0900-0000-001200000020","source_event_id_unique":true,"source_pre_event_id":"00065a1d-7fa3-f960-0000-001203000020","translation":"PARTIAL_PRIOR_UNFOLD","unfold_event_id":null,"zero_hair":false}
{"channel":"live_orders_ethusd","interaction_index":704,"natural_form":{"channel":"live_orders_ethusd","order_id":"2044303882711043","order_subtype":0,"order_type":0},"natural_form_sha256":"44b5c3346d1532432e342260dc3eb58d635bac10dce810dc0d5a8f6bb2f5fd47","order_source":"orderbook","orders_submitted":0,"presentation":{"amount":"0.042863","amount_traded":"0","microtimestamp":"1787932602272000","price":"2472.16"},"previous_record_hash":"6d66cb3f1ca72bf7f51c4c29689c0a56852f22ce2d5cc6ca7557a235d26c6346","profit_assessment":null,"record_hash":"0fe64d8296c8eb8081769ffc44a181c535ba5451d288eaa8064cae2b859e1165","recorded_unix_us":1787932602307478,"recorded_utc":"2026-08-28T15:56:42.307478Z","schema_version":"nrrf810.exchange_authored_interactive_closure.v1","source_chain_continuous":true,"source_event":"order_created","source_event_id":"00065a1d-7fa4-0900-0001-001201000020","source_event_id_unique":true,"source_pre_event_id":"00065a1d-7fa4-0900-0000-001200000020","translation":"UNFOLD_TO_INF","unfold_event_id":null,"zero_hair":false}
{"channel":"live_orders_ethusd","interaction_index":705,"natural_form":{"channel":"live_orders_ethusd","order_id":"2044303882383360","order_subtype":5,"order_type":1},"natural_form_sha256":"557b6bd06da0e7c435e8be1d68e169ba6008b2050043bc81b009708c28e36833","order_source":"orderbook","orders_submitted":0,"presentation":{"amount":"5.000000","amount_traded":"0","microtimestamp":"1787932602273000","price":"2481.70"},"previous_record_hash":"0fe64d8296c8eb8081769ffc44a181c535ba5451d288eaa8064cae2b859e1165","profit_assessment":null,"record_hash":"16f538f323980646a6c0ef422e42c5f3f7e4b7f05369f864190ee62d1d312fe1","recorded_unix_us":1787932602307625,"recorded_utc":"2026-08-28T15:56:42.307625Z","schema_version":"nrrf810.exchange_authored_interactive_closure.v1","source_chain_continuous":true,"source_event":"order_deleted","source_event_id":"00065a1d-7fa4-0ce8-0000-001202000020","source_event_id_unique":true,"source_pre_event_id":"00065a1d-7fa4-0900-0001-001201000020","translation":"FOLD_RETURN_TO_ZERO","unfold_event_id":"00065a1d-7fa2-d080-0001-001203000020","zero_hair":true}
{"channel":"live_orders_btcusd","interaction_index":706,"natural_form":{"channel":"live_orders_btcusd","order_id":"2044303882719235","order_subtype":5,"order_type":1},"natural_form_sha256":"3df5abd62d522d70bb0aa432b3a08136d96843f68275f149f4e977350f9f8a0c","order_source":"orderbook","orders_submitted":0,"presentation":{"amount":"0.06310787","amount_traded":"0","microtimestamp":"1787932602274000","price":"78520.86"},"previous_record_hash":"16f538f323980646a6c0ef422e42c5f3f7e4b7f05369f864190ee62d1d312fe1","profit_assessment":null,"record_hash":"e041d9a445d3ae9e8ce50e2df2c8aa5d78f373e0de829c9f2137b6298b617e6b","recorded_unix_us":1787932602307798,"recorded_utc":"2026-08-28T15:56:42.307798Z","schema_version":"nrrf810.exchange_authored_interactive_closure.v1","source_chain_continuous":true,"source_event":"order_created","source_event_id":"00065a1d-7fa4-10d0-0000-000101000020","source_event_id_unique":true,"source_pre_event_id":"00065a1d-7fa3-b6f8-0001-000100000020","translation":"UNFOLD_TO_INF","unfold_event_id":null,"zero_hair":false}
{"channel":"live_orders_btcusd","interaction_index":707,"natural_form":{"channel":"live_orders_btcusd","order_id":"2044303882719235","order_subtype":5,"order_type":1},"natural_form_sha256":"3df5abd62d522d70bb0aa432b3a08136d96843f68275f149f4e977350f9f8a0c","order_source":"orderbook","orders_submitted":0,"presentation":{"amount":"0.06310787","amount_traded":"0","microtimestamp":"1787932602274000","price":"78520.86"},"previous_record_hash":"e041d9a445d3ae9e8ce50e2df2c8aa5d78f373e0de829c9f2137b6298b617e6b","profit_assessment":null,"record_hash":"b6fd03a2c47ec415147b5899b7920677a1be1bc44d8520bd8fcc980267dfa86c","recorded_unix_us":1787932602307837,"recorded_utc":"2026-08-28T15:56:42.307837Z","schema_version":"nrrf810.exchange_authored_interactive_closure.v1","source_chain_continuous":true,"source_event":"order_deleted","source_event_id":"00065a1d-7fa4-10d0-0001-000102000020","source_event_id_unique":true,"source_pre_event_id":"00065a1d-7fa4-10d0-0000-000101000020","translation":"FOLD_RETURN_TO_ZERO","unfold_event_id":"00065a1d-7fa4-10d0-0000-000101000020","zero_hair":true}
{"channel":"live_orders_btcusd","interaction_index":708,"natural_form":{"channel":"live_orders_btcusd","order_id":"2044303882719244","order_subtype":5,"order_type":1},"natural_form_sha256":"30cfb52b837649a495589f42774e3a411621ef6936bf5cfbaea2a6fc2867844f","order_source":"orderbook","orders_submitted":0,"presentation":{"amount":"0.10000000","amount_traded":"0","microtimestamp":"1787932602275000","price":"78522.63"},"previous_record_hash":"b6fd03a2c47ec415147b5899b7920677a1be1bc44d8520bd8fcc980267dfa86c","profit_assessment":null,"record_hash":"6c98173c9b15dc2e05d7067ba83fc4c0a109bc4000173b9eb9af0431142a3b8e","recorded_unix_us":1787932602308038,"recorded_utc":"2026-08-28T15:56:42.308038Z","schema_version":"nrrf810.exchange_authored_interactive_closure.v1","source_chain_continuous":true,"source_event":"order_created","source_event_id":"00065a1d-7fa4-14b8-0000-000103000020","source_event_id_unique":true,"source_pre_event_id":"00065a1d-7fa4-10d0-0001-000102000020","translation":"UNFOLD_TO_INF","unfold_event_id":null,"zero_hair":false}
{"channel":"live_orders_btcusd","interaction_index":709,"natural_form":{"channel":"live_orders_btcusd","order_id":"2044303882719244","order_subtype":5,"order_type":1},"natural_form_sha256":"30cfb52b837649a495589f42774e3a411621ef6936bf5cfbaea2a6fc2867844f","order_source":"orderbook","orders_submitted":0,"presentation":{"amount":"0.10000000","amount_traded":"0","microtimestamp":"1787932602275000","price":"78522.63"},"previous_record_hash":"6c98173c9b15dc2e05d7067ba83fc4c0a109bc4000173b9eb9af0431142a3b8e","profit_assessment":null,"record_hash":"678e9e946f126fd347c5de9197ea3e6a2ebb0d2ed33f179a96b40f6998baeafb","recorded_unix_us":1787932602308164,"recorded_utc":"2026-08-28T15:56:42.308164Z","schema_version":"nrrf810.exchange_authored_interactive_closure.v1","source_chain_continuous":true,"source_event":"order_deleted","source_event_id":"00065a1d-7fa4-14b8-0001-000100000020","source_event_id_unique":true,"source_pre_event_id":"00065a1d-7fa4-14b8-0000-000103000020","translation":"FOLD_RETURN_TO_ZERO","unfold_event_id":"00065a1d-7fa4-14b8-0000-000103000020","zero_hair":true}
{"channel":"live_orders_btcusd","interaction_index":710,"natural_form":{"channel":"live_orders_btcusd","order_id":"2044303882780684","order_subtype":5,"order_type":1},"natural_form_sha256":"5f54d3c8c585551aeb103a46032308f9356a87b02b84186d00bde508cfc89387","order_source":"orderbook","orders_submitted":0,"presentation":{"amount":"0.10000000","amount_traded":"0","microtimestamp":"1787932602290000","price":"78522.62"},"previous_record_hash":"678e9e946f126fd347c5de9197ea3e6a2ebb0d2ed33f179a96b40f6998baeafb","profit_assessment":null,"record_hash":"2b47fa470fdee7b7b899f5c023c973f39a165adafc34089f3deac87c24845c4f","recorded_unix_us":1787932602321277,"recorded_utc":"2026-08-28T15:56:42.321277Z","schema_version":"nrrf810.exchange_authored_interactive_closure.v1","source_chain_continuous":true,"source_event":"order_created","source_event_id":"00065a1d-7fa4-4f50-0000-000101000020","source_event_id_unique":true,"source_pre_event_id":"00065a1d-7fa4-14b8-0001-000100000020","translation":"UNFOLD_TO_INF","unfold_event_id":null,"zero_hair":false}
{"channel":"live_orders_btcusd","interaction_index":711,"natural_form":{"channel":"live_orders_btcusd","order_id":"2044303882780684","order_subtype":5,"order_type":1},"natural_form_sha256":"5f54d3c8c585551aeb103a46032308f9356a87b02b84186d00bde508cfc89387","order_source":"orderbook","orders_submitted":0,"presentation":{"amount":"0.10000000","amount_traded":"0","microtimestamp":"1787932602290000","price":"78522.62"},"previous_record_hash":"2b47fa470fdee7b7b899f5c023c973f39a165adafc34089f3deac87c24845c4f","profit_assessment":null,"record_hash":"20ce2e84be53761c063f9def736ed785644a46dc37c52c8af7fc0f0c677bdbc1","recorded_unix_us":1787932602321536,"recorded_utc":"2026-08-28T15:56:42.321536Z","schema_version":"nrrf810.exchange_authored_interactive_closure.v1","source_chain_continuous":true,"source_event":"order_deleted","source_event_id":"00065a1d-7fa4-4f50-0001-000102000020","source_event_id_unique":true,"source_pre_event_id":"00065a1d-7fa4-4f50-0000-000101000020","translation":"FOLD_RETURN_TO_ZERO","unfold_event_id":"00065a1d-7fa4-4f50-0000-000101000020","zero_hair":true}
{"channel":"live_orders_btcusd","interaction_index":712,"natural_form":{"channel":"live_orders_btcusd","order_id":"2044303881424900","order_subtype":5,"order_type":0},"natural_form_sha256":"26906b328e17dd42c7f79d4942d2103d0183f4e118ff38780636884eb7800173","order_source":"orderbook","orders_submitted":0,"presentation":{"amount":"0.26750492","amount_traded":"0","microtimestamp":"1787932602290000","price":"78486.82"},"previous_record_hash":"20ce2e84be53761c063f9def736ed785644a46dc37c52c8af7fc0f0c677bdbc1","profit_assessment":null,"record_hash":"054b79b04475c1bca54a98114d3c008afc972afab8652acdb4e6a962121eb426","recorded_unix_us":1787932602333317,"recorded_utc":"2026-08-28T15:56:42.333317Z","schema_version":"nrrf810.exchange_authored_interactive_closure.v1","source_chain_continuous":true,"source_event":"order_deleted","source_event_id":"00065a1d-7fa4-4f50-0002-000103000020","source_event_id_unique":true,"source_pre_event_id":"00065a1d-7fa4-4f50-0001-000102000020","translation":"FOLD_RETURN_TO_ZERO","unfold_event_id":"00065a1d-7f9f-3e70-0001-000102000020","zero_hair":true}
{"channel":"live_orders_btcusd","interaction_index":713,"natural_form":{"channel":"live_orders_btcusd","order_id":"2044303882784773","order_subtype":5,"order_type":0},"natural_form_sha256":"c22fccd3f3e199243b458ecc6414d5046413fd4191beef9bf7e0d7d56c1635ef","order_source":"orderbook","orders_submitted":0,"presentation":{"amount":"0.26750492","amount_traded":"0","microtimestamp":"1787932602290000","price":"78486.82"},"previous_record_hash":"054b79b04475c1bca54a98114d3c008afc972afab8652acdb4e6a962121eb426","profit_assessment":null,"record_hash":"911d0ddff3c681596823e12af3d31c64995d4a3a513e46a2e53c4d6fbb734263","recorded_unix_us":1787932602333434,"recorded_utc":"2026-08-28T15:56:42.333434Z","schema_version":"nrrf810.exchange_authored_interactive_closure.v1","source_chain_continuous":true,"source_event":"order_created","source_event_id":"00065a1d-7fa4-4f50-0003-000100000020","source_event_id_unique":true,"source_pre_event_id":"00065a1d-7fa4-4f50-0002-000103000020","translation":"UNFOLD_TO_INF","unfold_event_id":null,"zero_hair":false}
{"channel":"live_orders_btcusd","interaction_index":714,"natural_form":{"channel":"live_orders_btcusd","order_id":"2044303882833933","order_subtype":5,"order_type":1},"natural_form_sha256":"138dfe062927232e417e6df9d6a27b9081485512e534b3a753203e7aee680def","order_source":"orderbook","orders_submitted":0,"presentation":{"amount":"0.06310787","amount_traded":"0","microtimestamp":"1787932602303000","price":"78520.39"},"previous_record_hash":"911d0ddff3c681596823e12af3d31c64995d4a3a513e46a2e53c4d6fbb734263","profit_assessment":null,"record_hash":"407f034ac0aa76f796aa67a365b7e23a14105f31805f71036c42b6d6fcc8b098","recorded_unix_us":1787932602335146,"recorded_utc":"2026-08-28T15:56:42.335146Z","schema_version":"nrrf810.exchange_authored_interactive_closure.v1","source_chain_continuous":true,"source_event":"order_created","source_event_id":"00065a1d-7fa4-8218-0000-000101000020","source_event_id_unique":true,"source_pre_event_id":"00065a1d-7fa4-4f50-0003-000100000020","translation":"UNFOLD_TO_INF","unfold_event_id":null,"zero_hair":false}
{"channel":"live_orders_btcusd","interaction_index":715,"natural_form":{"channel":"live_orders_btcusd","order_id":"2044303882833933","order_subtype":5,"order_type":1},"natural_form_sha256":"138dfe062927232e417e6df9d6a27b9081485512e534b3a753203e7aee680def","order_source":"orderbook","orders_submitted":0,"presentation":{"amount":"0.06310787","amount_traded":"0","microtimestamp":"1787932602303000","price":"78520.39"},"previous_record_hash":"407f034ac0aa76f796aa67a365b7e23a14105f31805f71036c42b6d6fcc8b098","profit_assessment":null,"record_hash":"3f6c30f22ae305bf42727a9c4174eb5fbc303063ccaefcaba6d836dc01b92313","recorded_unix_us":1787932602335240,"recorded_utc":"2026-08-28T15:56:42.335240Z","schema_version":"nrrf810.exchange_authored_interactive_closure.v1","source_chain_continuous":true,"source_event":"order_deleted","source_event_id":"00065a1d-7fa4-8218-0001-000102000020","source_event_id_unique":true,"source_pre_event_id":"00065a1d-7fa4-8218-0000-000101000020","translation":"FOLD_RETURN_TO_ZERO","unfold_event_id":"00065a1d-7fa4-8218-0000-000101000020","zero_hair":true}
{"channel":"live_orders_btcusd","interaction_index":716,"natural_form":{"channel":"live_orders_btcusd","order_id":"2044303882842112","order_subtype":5,"order_type":1},"natural_form_sha256":"c6a3ae4445286f3bf86fdd09eaf7ef12082bc2b84c94b6d2d27772a34a5fae3a","order_source":"orderbook","orders_submitted":0,"presentation":{"amount":"0.10000000","amount_traded":"0","microtimestamp":"1787932602304000","price":"78522.63"},"previous_record_hash":"3f6c30f22ae305bf42727a9c4174eb5fbc303063ccaefcaba6d836dc01b92313","profit_assessment":null,"record_hash":"3bb8a00e785bbf35aeed2c046d3b14aac6527d910de698327fcd0bb46774ed50","recorded_unix_us":1787932602350611,"recorded_utc":"2026-08-28T15:56:42.350611Z","schema_version":"nrrf810.exchange_authored_interactive_closure.v1","source_chain_continuous":true,"source_event":"order_created","source_event_id":"00065a1d-7fa4-8600-0000-000103000020","source_event_id_unique":true,"source_pre_event_id":"00065a1d-7fa4-8218-0001-000102000020","translation":"UNFOLD_TO_INF","unfold_event_id":null,"zero_hair":false}
{"channel":"live_orders_btcusd","interaction_index":717,"natural_form":{"channel":"live_orders_btcusd","order_id":"2044303882842112","order_subtype":5,"order_type":1},"natural_form_sha256":"c6a3ae4445286f3bf86fdd09eaf7ef12082bc2b84c94b6d2d27772a34a5fae3a","order_source":"orderbook","orders_submitted":0,"presentation":{"amount":"0.10000000","amount_traded":"0","microtimestamp":"1787932602304000","price":"78522.63"},"previous_record_hash":"3bb8a00e785bbf35aeed2c046d3b14aac6527d910de698327fcd0bb46774ed50","profit_assessment":null,"record_hash":"3bd1ab1506763752e0d09abce2e104a1dc8985004d7acc02da4cba9bbefe9fdf","recorded_unix_us":1787932602350817,"recorded_utc":"2026-08-28T15:56:42.350817Z","schema_version":"nrrf810.exchange_authored_interactive_closure.v1","source_chain_continuous":true,"source_event":"order_deleted","source_event_id":"00065a1d-7fa4-8600-0001-000100000020","source_event_id_unique":true,"source_pre_event_id":"00065a1d-7fa4-8600-0000-000103000020","translation":"FOLD_RETURN_TO_ZERO","unfold_event_id":"00065a1d-7fa4-8600-0000-000103000020","zero_hair":true}
{"channel":"live_orders_btcusd","interaction_index":718,"natural_form":{"channel":"live_orders_btcusd","order_id":"2044303882031107","order_subtype":5,"order_type":0},"natural_form_sha256":"5e4c7260fa9f01b2d48def704f1128e4ee0103ba9579781f4340af1cfbe8c882","order_source":"orderbook","orders_submitted":0,"presentation":{"amount":"0.19104003","amount_traded":"0","microtimestamp":"1787932602305000","price":"78485.62"},"previous_record_hash":"3bd1ab1506763752e0d09abce2e104a1dc8985004d7acc02da4cba9bbefe9fdf","profit_assessment":null,"record_hash":"4a8aaa67e3bac73e0b5ca811ba72bf80122384e94a686ddb2d86421455a1790a","recorded_unix_us":1787932602350971,"recorded_utc":"2026-08-28T15:56:42.350971Z","schema_version":"nrrf810.exchange_authored_interactive_closure.v1","source_chain_continuous":true,"source_event":"order_deleted","source_event_id":"00065a1d-7fa4-89e8-0000-000101000020","source_event_id_unique":true,"source_pre_event_id":"00065a1d-7fa4-8600-0001-000100000020","translation":"FOLD_RETURN_TO_ZERO","unfold_event_id":"00065a1d-7fa1-8478-0000-000103000020","zero_hair":true}
{"channel":"live_orders_btcusd","interaction_index":719,"natural_form":{"channel":"live_orders_btcusd","order_id":"2044303882039300","order_subtype":5,"order_type":0},"natural_form_sha256":"0fd3b2688f12c46cee724a57e30bb42e3d39559f54630faaae61d40eb34e0ae5","order_source":"orderbook","orders_submitted":0,"presentation":{"amount":"0.63680011","amount_traded":"0","microtimestamp":"1787932602305000","price":"78483.66"},"previous_record_hash":"4a8aaa67e3bac73e0b5ca811ba72bf80122384e94a686ddb2d86421455a1790a","profit_assessment":null,"record_hash":"0ebb7e5c6d30bbbf4b4f48b8a6c5b5b787ad2234a33c3b755e509ad29e48664c","recorded_unix_us":1787932602351099,"recorded_utc":"2026-08-28T15:56:42.351099Z","schema_version":"nrrf810.exchange_authored_interactive_closure.v1","source_chain_continuous":true,"source_event":"order_deleted","source_event_id":"00065a1d-7fa4-89e8-0001-000102000020","source_event_id_unique":true,"source_pre_event_id":"00065a1d-7fa4-89e8-0000-000101000020","translation":"FOLD_RETURN_TO_ZERO","unfold_event_id":"00065a1d-7fa1-8860-0002-000103000020","zero_hair":true}
{"channel":"live_orders_btcusd","interaction_index":720,"natural_form":{"channel":"live_orders_btcusd","order_id":"2044303882039302","order_subtype":5,"order_type":0},"natural_form_sha256":"2547021919789e4dcb3bb2a460e4094fd281aa4010a83d440726757d9ff103c8","order_source":"orderbook","orders_submitted":0,"presentation":{"amount":"0.50944009","amount_traded":"0","microtimestamp":"1787932602306000","price":"78481.69"},"previous_record_hash":"0ebb7e5c6d30bbbf4b4f48b8a6c5b5b787ad2234a33c3b755e509ad29e48664c","profit_assessment":null,"record_hash":"56c7d9a3ec06f9f1346f4676d4b5ba10bae855992f3d07c00967d06b107b1991","recorded_unix_us":1787932602351222,"recorded_utc":"2026-08-28T15:56:42.351222Z","schema_version":"nrrf810.exchange_authored_interactive_closure.v1","source_chain_continuous":true,"source_event":"order_deleted","source_event_id":"00065a1d-7fa4-8dd0-0000-000103000020","source_event_id_unique":true,"source_pre_event_id":"00065a1d-7fa4-89e8-0001-000102000020","translation":"FOLD_RETURN_TO_ZERO","unfold_event_id":"00065a1d-7fa1-8c48-0000-000100000020","zero_hair":true}
{"channel":"live_orders_btcusd","interaction_index":721,"natural_form":{"channel":"live_orders_btcusd","order_id":"2044303882854404","order_subtype":5,"order_type":0},"natural_form_sha256":"867c716673c3e64dbab179a8f5572680b0803755568cbd5545beeac015449c46","order_source":"orderbook","orders_submitted":0,"presentation":{"amount":"0.00140266","amount_traded":"0","microtimestamp":"1787932602307000","price":"70668.36"},"previous_record_hash":"56c7d9a3ec06f9f1346f4676d4b5ba10bae855992f3d07c00967d06b107b1991","profit_assessment":null,"record_hash":"f9c95f2d0819cfd5fcf7378e0ea3e1bad6155d8f0af29ebe275f91d42799452c","recorded_unix_us":1787932602351461,"recorded_utc":"2026-08-28T15:56:42.351461Z","schema_version":"nrrf810.exchange_authored_interactive_closure.v1","source_chain_continuous":true,"source_event":"order_created","source_event_id":"00065a1d-7fa4-91b8-0000-000100000020","source_event_id_unique":true,"source_pre_event_id":"00065a1d-7fa4-8dd0-0000-000103000020","translation":"UNFOLD_TO_INF","unfold_event_id":null,"zero_hair":false}
{"channel":"live_orders_ethusd","interaction_index":722,"natural_form":{"channel":"live_orders_ethusd","order_id":"2044303882661889","order_subtype":5,"order_type":0},"natural_form_sha256":"f8b338228c8b9f50f9f3890a5377bd9e6204e60f4b9218ce0602788eef844ccf","order_source":"orderbook","orders_submitted":0,"presentation":{"amount":"0.403086","amount_traded":"0","microtimestamp":"1787932602309000","price":"2480.10"},"previous_record_hash":"f9c95f2d0819cfd5fcf7378e0ea3e1bad6155d8f0af29ebe275f91d42799452c","profit_assessment":null,"record_hash":"868c82e3e0c12dcf0da098125a6b23f8bacb978dea5eab091636ea1b37475d81","recorded_unix_us":1787932602351562,"recorded_utc":"2026-08-28T15:56:42.351562Z","schema_version":"nrrf810.exchange_authored_interactive_closure.v1","source_chain_continuous":true,"source_event":"order_deleted","source_event_id":"00065a1d-7fa4-9988-0000-001203000020","source_event_id_unique":true,"source_pre_event_id":"00065a1d-7fa4-0ce8-0000-001202000020","translation":"FOLD_RETURN_TO_ZERO","unfold_event_id":"00065a1d-7fa3-da20-0000-001201000020","zero_hair":true}
{"channel":"live_orders_btcusd","interaction_index":723,"natural_form":{"channel":"live_orders_btcusd","order_id":"2044303882887181","order_subtype":5,"order_type":0},"natural_form_sha256":"4c92c813b470fdf1dcaa431fe4a741aac20cb23234834718128d0bdfc113cb95","order_source":"orderbook","orders_submitted":0,"presentation":{"amount":"0.19103770","amount_traded":"0","microtimestamp":"1787932602316000","price":"78485.00"},"previous_record_hash":"868c82e3e0c12dcf0da098125a6b23f8bacb978dea5eab091636ea1b37475d81","profit_assessment":null,"record_hash":"98b48e3954694fd581d31b06eb22568c4c0da1824ff82d5dc71c48de6040112a","recorded_unix_us":1787932602351838,"recorded_utc":"2026-08-28T15:56:42.351838Z","schema_version":"nrrf810.exchange_authored_interactive_closure.v1","source_chain_continuous":true,"source_event":"order_created","source_event_id":"00065a1d-7fa4-b4e0-0000-000101000020","source_event_id_unique":true,"source_pre_event_id":"00065a1d-7fa4-91b8-0000-000100000020","translation":"UNFOLD_TO_INF","unfold_event_id":null,"zero_hair":false}
{"channel":"live_orders_ethusd","interaction_index":724,"natural_form":{"channel":"live_orders_ethusd","order_id":"2044303882899463","order_subtype":5,"order_type":0},"natural_form_sha256":"a67b1a2993780de4b1782b9b07754e69dc1170862318f14ddca5441153471254","order_source":"orderbook","orders_submitted":0,"presentation":{"amount":"0.403089","amount_traded":"0","microtimestamp":"1787932602318000","price":"2480.07"},"previous_record_hash":"98b48e3954694fd581d31b06eb22568c4c0da1824ff82d5dc71c48de6040112a","profit_assessment":null,"record_hash":"6e6d2a3eaf90d819c0aea66b9b87311b76ea2113ce1139c491bc103f15cf2bf8","recorded_unix_us":1787932602351951,"recorded_utc":"2026-08-28T15:56:42.351951Z","schema_version":"nrrf810.exchange_authored_interactive_closure.v1","source_chain_continuous":true,"source_event":"order_created","source_event_id":"00065a1d-7fa4-bcb0-0000-001200000020","source_event_id_unique":true,"source_pre_event_id":"00065a1d-7fa4-9988-0000-001203000020","translation":"UNFOLD_TO_INF","unfold_event_id":null,"zero_hair":false}
{"channel":"live_orders_btcusd","interaction_index":725,"natural_form":{"channel":"live_orders_btcusd","order_id":"2044303882190850","order_subtype":5,"order_type":0},"natural_form_sha256":"b480493d01210377a3fffc3bc6e93089d19e756170d95f16c03106ae2c2b4d9f","order_source":"orderbook","orders_submitted":0,"presentation":{"amount":"0.00140266","amount_traded":"0","microtimestamp":"1787932602318000","price":"70668.36"},"previous_record_hash":"6e6d2a3eaf90d819c0aea66b9b87311b76ea2113ce1139c491bc103f15cf2bf8","profit_assessment":null,"record_hash":"2c99ab341796bdf61364d748b8117f84aabb2a98849c80b0f9069d8c5a8ae06c","recorded_unix_us":1787932602351997,"recorded_utc":"2026-08-28T15:56:42.351997Z","schema_version":"nrrf810.exchange_authored_interactive_closure.v1","source_chain_continuous":true,"source_event":"order_deleted","source_event_id":"00065a1d-7fa4-bcb0-0000-000102000020","source_event_id_unique":true,"source_pre_event_id":"00065a1d-7fa4-b4e0-0000-000101000020","translation":"FOLD_RETURN_TO_ZERO","unfold_event_id":"00065a1d-7fa2-18e8-0000-000101000020","zero_hair":true}
{"channel":"live_orders_btcusd","interaction_index":726,"natural_form":{"channel":"live_orders_btcusd","order_id":"2044303882911744","order_subtype":5,"order_type":0},"natural_form_sha256":"b179cc7864ae29ebba748a16bd0656bc69c3ca4a16c7295070bb70a2c47c5deb","order_source":"orderbook","orders_submitted":0,"presentation":{"amount":"0.63679235","amount_traded":"0","microtimestamp":"1787932602321000","price":"78483.04"},"previous_record_hash":"2c99ab341796bdf61364d748b8117f84aabb2a98849c80b0f9069d8c5a8ae06c","profit_assessment":null,"record_hash":"42af6bc41a0e9db19dab7edb187867dcabe0ca2dc9db2d0e3940b0ffbff8f5fd","recorded_unix_us":1787932602362524,"recorded_utc":"2026-08-28T15:56:42.362524Z","schema_version":"nrrf810.exchange_authored_interactive_closure.v1","source_chain_continuous":true,"source_event":"order_created","source_event_id":"00065a1d-7fa4-c868-0000-000103000020","source_event_id_unique":true,"source_pre_event_id":"00065a1d-7fa4-bcb0-0000-000102000020","translation":"UNFOLD_TO_INF","unfold_event_id":null,"zero_hair":false}
{"channel":"live_orders_btcusd","interaction_index":727,"natural_form":{"channel":"live_orders_btcusd","order_id":"2044303882911754","order_subtype":5,"order_type":0},"natural_form_sha256":"d8ac403f564cdbe90417c832301ac39fb9027829ca70f9133639857529175088","order_source":"orderbook","orders_submitted":0,"presentation":{"amount":"0.50943388","amount_traded":"0","microtimestamp":"1787932602321000","price":"78481.08"},"previous_record_hash":"42af6bc41a0e9db19dab7edb187867dcabe0ca2dc9db2d0e3940b0ffbff8f5fd","profit_assessment":null,"record_hash":"8a64c211a781d45a4857f00d106b816ea7d5d97c06d1cd2e1bab909c062c7b7f","recorded_unix_us":1787932602362735,"recorded_utc":"2026-08-28T15:56:42.362735Z","schema_version":"nrrf810.exchange_authored_interactive_closure.v1","source_chain_continuous":true,"source_event":"order_created","source_event_id":"00065a1d-7fa4-c868-0001-000100000020","source_event_id_unique":true,"source_pre_event_id":"00065a1d-7fa4-c868-0000-000103000020","translation":"UNFOLD_TO_INF","unfold_event_id":null,"zero_hair":false}
{"channel":"live_orders_btcusd","interaction_index":728,"natural_form":{"channel":"live_orders_btcusd","order_id":"2044303882915840","order_subtype":5,"order_type":1},"natural_form_sha256":"fd0d60775254763aa73439c5172cc256aaacdc23b039e388cda7ab23e3fe3985","order_source":"orderbook","orders_submitted":0,"presentation":{"amount":"0.10000000","amount_traded":"0","microtimestamp":"1787932602322000","price":"78522.62"},"previous_record_hash":"8a64c211a781d45a4857f00d106b816ea7d5d97c06d1cd2e1bab909c062c7b7f","profit_assessment":null,"record_hash":"366ed507e85c00961d6804bca355d86290ff633b97a2bf0e308e4206801f435c","recorded_unix_us":1787932602362928,"recorded_utc":"2026-08-28T15:56:42.362928Z","schema_version":"nrrf810.exchange_authored_interactive_closure.v1","source_chain_continuous":true,"source_event":"order_created","source_event_id":"00065a1d-7fa4-cc50-0000-000101000020","source_event_id_unique":true,"source_pre_event_id":"00065a1d-7fa4-c868-0001-000100000020","translation":"UNFOLD_TO_INF","unfold_event_id":null,"zero_hair":false}
{"channel":"live_orders_btcusd","interaction_index":729,"natural_form":{"channel":"live_orders_btcusd","order_id":"2044303882915840","order_subtype":5,"order_type":1},"natural_form_sha256":"fd0d60775254763aa73439c5172cc256aaacdc23b039e388cda7ab23e3fe3985","order_source":"orderbook","orders_submitted":0,"presentation":{"amount":"0.10000000","amount_traded":"0","microtimestamp":"1787932602322000","price":"78522.62"},"previous_record_hash":"366ed507e85c00961d6804bca355d86290ff633b97a2bf0e308e4206801f435c","profit_assessment":null,"record_hash":"98e0fa3ba806e6bf139e27943922a694ca5dc273e0b16b4b79b72cebd5d6ad07","recorded_unix_us":1787932602363119,"recorded_utc":"2026-08-28T15:56:42.363119Z","schema_version":"nrrf810.exchange_authored_interactive_closure.v1","source_chain_continuous":true,"source_event":"order_deleted","source_event_id":"00065a1d-7fa4-cc50-0001-000102000020","source_event_id_unique":true,"source_pre_event_id":"00065a1d-7fa4-cc50-0000-000101000020","translation":"FOLD_RETURN_TO_ZERO","unfold_event_id":"00065a1d-7fa4-cc50-0000-000101000020","zero_hair":true}
{"channel":"live_orders_btcusd","interaction_index":730,"natural_form":{"channel":"live_orders_btcusd","order_id":"2044303880990722","order_subtype":0,"order_type":1},"natural_form_sha256":"336b8d1243068b5e077b0b08d4e53ab5d62c6142fad466c78c315662e4074c4b","order_source":"orderbook","orders_submitted":0,"presentation":{"amount":"0.06310787","amount_traded":"0","microtimestamp":"1787932602323000","price":"78549.20"},"previous_record_hash":"98e0fa3ba806e6bf139e27943922a694ca5dc273e0b16b4b79b72cebd5d6ad07","profit_assessment":null,"record_hash":"406433efd54f43b70ea4e418d8f024f98eb4a8d9cfde674ca285681aa7e0cb95","recorded_unix_us":1787932602363241,"recorded_utc":"2026-08-28T15:56:42.363241Z","schema_version":"nrrf810.exchange_authored_interactive_closure.v1","source_chain_continuous":true,"source_event":"order_deleted","source_event_id":"00065a1d-7fa4-d038-0000-000103000020","source_event_id_unique":true,"source_pre_event_id":"00065a1d-7fa4-cc50-0001-000102000020","translation":"FOLD_RETURN_TO_ZERO","unfold_event_id":"00065a1d-7f9d-a060-0000-000102000020","zero_hair":true}
{"channel":"live_orders_btcusd","interaction_index":731,"natural_form":{"channel":"live_orders_btcusd","order_id":"2044303882956805","order_subtype":5,"order_type":1},"natural_form_sha256":"cddf8f1eceaedaa3a36634ef9a2bc53b7b148da6161bb33fe96adb71ff6e41ef","order_source":"orderbook","orders_submitted":0,"presentation":{"amount":"0.06310787","amount_traded":"0","microtimestamp":"1787932602332000","price":"78520.12"},"previous_record_hash":"406433efd54f43b70ea4e418d8f024f98eb4a8d9cfde674ca285681aa7e0cb95","profit_assessment":null,"record_hash":"a580fb8f48f9bd3601d0e55023f5f0a129a0621fd7ab5cd2cbab167176bfc0bd","recorded_unix_us":1787932602365320,"recorded_utc":"2026-08-28T15:56:42.365320Z","schema_version":"nrrf810.exchange_authored_interactive_closure.v1","source_chain_continuous":true,"source_event":"order_created","source_event_id":"00065a1d-7fa4-f360-0000-000100000020","source_event_id_unique":true,"source_pre_event_id":"00065a1d-7fa4-d038-0000-000103000020","translation":"UNFOLD_TO_INF","unfold_event_id":null,"zero_hair":false}
{"channel":"live_orders_btcusd","interaction_index":732,"natural_form":{"channel":"live_orders_btcusd","order_id":"2044303882956805","order_subtype":5,"order_type":1},"natural_form_sha256":"cddf8f1eceaedaa3a36634ef9a2bc53b7b148da6161bb33fe96adb71ff6e41ef","order_source":"orderbook","orders_submitted":0,"presentation":{"amount":"0.06310787","amount_traded":"0","microtimestamp":"1787932602332000","price":"78520.12"},"previous_record_hash":"a580fb8f48f9bd3601d0e55023f5f0a129a0621fd7ab5cd2cbab167176bfc0bd","profit_assessment":null,"record_hash":"f5bba0ec73072fcaa456c954e4a4bd0a5ab8aa85e1c319ac0f9016c51356eae6","recorded_unix_us":1787932602365460,"recorded_utc":"2026-08-28T15:56:42.365460Z","schema_version":"nrrf810.exchange_authored_interactive_closure.v1","source_chain_continuous":true,"source_event":"order_deleted","source_event_id":"00065a1d-7fa4-f360-0001-000101000020","source_event_id_unique":true,"source_pre_event_id":"00065a1d-7fa4-f360-0000-000100000020","translation":"FOLD_RETURN_TO_ZERO","unfold_event_id":"00065a1d-7fa4-f360-0000-000100000020","zero_hair":true}
{"channel":"live_orders_btcusd","interaction_index":733,"natural_form":{"channel":"live_orders_btcusd","order_id":"2044303882964992","order_subtype":5,"order_type":1},"natural_form_sha256":"e966b01ffe955ab9eb133af79c70db3786b19d2b70bafa7eebb686478f1a66be","order_source":"orderbook","orders_submitted":0,"presentation":{"amount":"0.06310787","amount_traded":"0","microtimestamp":"1787932602334000","price":"78522.48"},"previous_record_hash":"f5bba0ec73072fcaa456c954e4a4bd0a5ab8aa85e1c319ac0f9016c51356eae6","profit_assessment":null,"record_hash":"3457dd0f8e57d6316dbc91b2ae66ca3c607b63a580b5736bf2d2f6fbd17b7e57","recorded_unix_us":1787932602375232,"recorded_utc":"2026-08-28T15:56:42.375232Z","schema_version":"nrrf810.exchange_authored_interactive_closure.v1","source_chain_continuous":true,"source_event":"order_created","source_event_id":"00065a1d-7fa4-fb30-0000-000102000020","source_event_id_unique":true,"source_pre_event_id":"00065a1d-7fa4-f360-0001-000101000020","translation":"UNFOLD_TO_INF","unfold_event_id":null,"zero_hair":false}
{"channel":"live_orders_btcusd","interaction_index":734,"natural_form":{"channel":"live_orders_btcusd","order_id":"2044303882964992","order_subtype":5,"order_type":1},"natural_form_sha256":"e966b01ffe955ab9eb133af79c70db3786b19d2b70bafa7eebb686478f1a66be","order_source":"orderbook","orders_submitted":0,"presentation":{"amount":"0.06310787","amount_traded":"0","microtimestamp":"1787932602334000","price":"78522.48"},"previous_record_hash":"3457dd0f8e57d6316dbc91b2ae66ca3c607b63a580b5736bf2d2f6fbd17b7e57","profit_assessment":null,"record_hash":"70a03bc478ef399262e594c1387fb33a813253a855fbf535ee00a9c8d2251195","recorded_unix_us":1787932602375766,"recorded_utc":"2026-08-28T15:56:42.375766Z","schema_version":"nrrf810.exchange_authored_interactive_closure.v1","source_chain_continuous":true,"source_event":"order_deleted","source_event_id":"00065a1d-7fa4-fb30-0001-000103000020","source_event_id_unique":true,"source_pre_event_id":"00065a1d-7fa4-fb30-0000-000102000020","translation":"FOLD_RETURN_TO_ZERO","unfold_event_id":"00065a1d-7fa4-fb30-0000-000102000020","zero_hair":true}
{"channel":"live_orders_btcusd","interaction_index":735,"natural_form":{"channel":"live_orders_btcusd","order_id":"2044303877599234","order_subtype":5,"order_type":1},"natural_form_sha256":"4ebf7278509d4106656848d62e2d47c4fe58e5383f45edc019e27209b2ce9373","order_source":"orderbook","orders_submitted":0,"presentation":{"amount":"0.12000000","amount_traded":"0","microtimestamp":"1787932602339000","price":"78541.00"},"previous_record_hash":"70a03bc478ef399262e594c1387fb33a813253a855fbf535ee00a9c8d2251195","profit_assessment":null,"record_hash":"a3251614800c7cf3991ba1a581b76896a7cc547e7f968282b548ff256eac5d29","recorded_unix_us":1787932602376099,"recorded_utc":"2026-08-28T15:56:42.376099Z","schema_version":"nrrf810.exchange_authored_interactive_closure.v1","source_chain_continuous":true,"source_event":"order_deleted","source_event_id":"00065a1d-7fa5-0eb8-0000-000100000020","source_event_id_unique":true,"source_pre_event_id":"00065a1d-7fa4-fb30-0001-000103000020","translation":"PARTIAL_PRIOR_UNFOLD","unfold_event_id":null,"zero_hair":false}
{"channel":"live_orders_btcusd","interaction_index":736,"natural_form":{"channel":"live_orders_btcusd","order_id":"2044303883022336","order_subtype":5,"order_type":1},"natural_form_sha256":"b3d918eeee1028dc2d69f5afec4a8c3fa868e8c0a739a309f1c4da5dbd715ce1","order_source":"orderbook","orders_submitted":0,"presentation":{"amount":"0.10000000","amount_traded":"0","microtimestamp":"1787932602348000","price":"78522.63"},"previous_record_hash":"a3251614800c7cf3991ba1a581b76896a7cc547e7f968282b548ff256eac5d29","profit_assessment":null,"record_hash":"82d48dca9626e9c39795e5277924aeb1028bf7f077ab4aff6acd878fbdac0020","recorded_unix_us":1787932602388826,"recorded_utc":"2026-08-28T15:56:42.388826Z","schema_version":"nrrf810.exchange_authored_interactive_closure.v1","source_chain_continuous":true,"source_event":"order_created","source_event_id":"00065a1d-7fa5-31e0-0000-000101000020","source_event_id_unique":true,"source_pre_event_id":"00065a1d-7fa5-0eb8-0000-000100000020","translation":"UNFOLD_TO_INF","unfold_event_id":null,"zero_hair":false}
{"channel":"live_orders_btcusd","interaction_index":737,"natural_form":{"channel":"live_orders_btcusd","order_id":"2044303883022336","order_subtype":5,"order_type":1},"natural_form_sha256":"b3d918eeee1028dc2d69f5afec4a8c3fa868e8c0a739a309f1c4da5dbd715ce1","order_source":"orderbook","orders_submitted":0,"presentation":{"amount":"0.10000000","amount_traded":"0","microtimestamp":"1787932602348000","price":"78522.63"},"previous_record_hash":"82d48dca9626e9c39795e5277924aeb1028bf7f077ab4aff6acd878fbdac0020","profit_assessment":null,"record_hash":"f6ed57afd94d83ab696f7b514bcb754c16346a9c733b3a07fe38b2582096ab00","recorded_unix_us":1787932602389013,"recorded_utc":"2026-08-28T15:56:42.389013Z","schema_version":"nrrf810.exchange_authored_interactive_closure.v1","source_chain_continuous":true,"source_event":"order_deleted","source_event_id":"00065a1d-7fa5-31e0-0001-000102000020","source_event_id_unique":true,"source_pre_event_id":"00065a1d-7fa5-31e0-0000-000101000020","translation":"FOLD_RETURN_TO_ZERO","unfold_event_id":"00065a1d-7fa5-31e0-0000-000101000020","zero_hair":true}
{"channel":"live_orders_ethusd","interaction_index":738,"natural_form":{"channel":"live_orders_ethusd","order_id":"2044303883046920","order_subtype":5,"order_type":1},"natural_form_sha256":"6a7b2d98313660ca37cbd96ebf65a458cdfdbe1fcc9f9fee729bab50cbf95bbd","order_source":"orderbook","orders_submitted":0,"presentation":{"amount":"5.206947","amount_traded":"0","microtimestamp":"1787932602355000","price":"2482.05"},"previous_record_hash":"f6ed57afd94d83ab696f7b514bcb754c16346a9c733b3a07fe38b2582096ab00","profit_assessment":null,"record_hash":"a2753669a9e7c833125335a18c4b71f3edc279e07126f4a9ee7fbb0218d685ad","recorded_unix_us":1787932602392650,"recorded_utc":"2026-08-28T15:56:42.392650Z","schema_version":"nrrf810.exchange_authored_interactive_closure.v1","source_chain_continuous":true,"source_event":"order_created","source_event_id":"00065a1d-7fa5-4d38-0000-001201000020","source_event_id_unique":true,"source_pre_event_id":"00065a1d-7fa4-bcb0-0000-001200000020","translation":"UNFOLD_TO_INF","unfold_event_id":null,"zero_hair":false}
{"channel":"live_orders_btcusd","interaction_index":739,"natural_form":{"channel":"live_orders_btcusd","order_id":"2044303883079685","order_subtype":5,"order_type":1},"natural_form_sha256":"859d3321e8674b6be6820282159041464f50791984b0d2d56d769d049292d8da","order_source":"orderbook","orders_submitted":0,"presentation":{"amount":"0.10000000","amount_traded":"0","microtimestamp":"1787932602362000","price":"78522.62"},"previous_record_hash":"a2753669a9e7c833125335a18c4b71f3edc279e07126f4a9ee7fbb0218d685ad","profit_assessment":null,"record_hash":"d13ee80409d105ebd04cdc2a7ee2118cb2892464cb4c958ccfbeb86672d5cb62","recorded_unix_us":1787932602407682,"recorded_utc":"2026-08-28T15:56:42.407682Z","schema_version":"nrrf810.exchange_authored_interactive_closure.v1","source_chain_continuous":true,"source_event":"order_created","source_event_id":"00065a1d-7fa5-6890-0000-000103000020","source_event_id_unique":true,"source_pre_event_id":"00065a1d-7fa5-31e0-0001-000102000020","translation":"UNFOLD_TO_INF","unfold_event_id":null,"zero_hair":false}
{"channel":"live_orders_btcusd","interaction_index":740,"natural_form":{"channel":"live_orders_btcusd","order_id":"2044303883079685","order_subtype":5,"order_type":1},"natural_form_sha256":"859d3321e8674b6be6820282159041464f50791984b0d2d56d769d049292d8da","order_source":"orderbook","orders_submitted":0,"presentation":{"amount":"0.10000000","amount_traded":"0","microtimestamp":"1787932602362000","price":"78522.62"},"previous_record_hash":"d13ee80409d105ebd04cdc2a7ee2118cb2892464cb4c958ccfbeb86672d5cb62","profit_assessment":null,"record_hash":"886d94cf978d23cbfbd103588d5d547e21e44c9549129bcf830f2f636e295f28","recorded_unix_us":1787932602407771,"recorded_utc":"2026-08-28T15:56:42.407771Z","schema_version":"nrrf810.exchange_authored_interactive_closure.v1","source_chain_continuous":true,"source_event":"order_deleted","source_event_id":"00065a1d-7fa5-6890-0001-000100000020","source_event_id_unique":true,"source_pre_event_id":"00065a1d-7fa5-6890-0000-000103000020","translation":"FOLD_RETURN_TO_ZERO","unfold_event_id":"00065a1d-7fa5-6890-0000-000103000020","zero_hair":true}
{"channel":"live_orders_btcusd","interaction_index":741,"natural_form":{"channel":"live_orders_btcusd","order_id":"2044303881457676","order_subtype":5,"order_type":1},"natural_form_sha256":"eb2baf841588485f7549dae5d8592fc10c8ae00403fa08aedaed3086a8bc9b3a","order_source":"orderbook","orders_submitted":0,"presentation":{"amount":"1.27113313","amount_traded":"0","microtimestamp":"1787932602365000","price":"78669.97"},"previous_record_hash":"886d94cf978d23cbfbd103588d5d547e21e44c9549129bcf830f2f636e295f28","profit_assessment":null,"record_hash":"c458d8458cf69559090f84c940975d41cc994c44c007704fa118dc559c103365","recorded_unix_us":1787932602407871,"recorded_utc":"2026-08-28T15:56:42.407871Z","schema_version":"nrrf810.exchange_authored_interactive_closure.v1","source_chain_continuous":true,"source_event":"order_deleted","source_event_id":"00065a1d-7fa5-7448-0000-000101000020","source_event_id_unique":true,"source_pre_event_id":"00065a1d-7fa5-6890-0001-000100000020","translation":"FOLD_RETURN_TO_ZERO","unfold_event_id":"00065a1d-7f9f-6198-0000-000100000020","zero_hair":true}
{"channel":"live_orders_btcusd","interaction_index":742,"natural_form":{"channel":"live_orders_btcusd","order_id":"2044303881940996","order_subtype":5,"order_type":1},"natural_form_sha256":"10e65859503ef331d4f87de021395f45df6dbdfe7293c180a3660615112a9636","order_source":"orderbook","orders_submitted":0,"presentation":{"amount":"0.06367384","amount_traded":"0","microtimestamp":"1787932602365000","price":"78525.19"},"previous_record_hash":"c458d8458cf69559090f84c940975d41cc994c44c007704fa118dc559c103365","profit_assessment":null,"record_hash":"4a8c417295190cf539dc2aec499317e43c49e6b166451f16bb577842df147488","recorded_unix_us":1787932602407985,"recorded_utc":"2026-08-28T15:56:42.407985Z","schema_version":"nrrf810.exchange_authored_interactive_closure.v1","source_chain_continuous":true,"source_event":"order_deleted","source_event_id":"00065a1d-7fa5-7448-0001-000102000020","source_event_id_unique":true,"source_pre_event_id":"00065a1d-7fa5-7448-0000-000101000020","translation":"FOLD_RETURN_TO_ZERO","unfold_event_id":"00065a1d-7fa1-2e88-0001-000103000020","zero_hair":true}
{"channel":"live_orders_btcusd","interaction_index":743,"natural_form":{"channel":"live_orders_btcusd","order_id":"2044303881945092","order_subtype":5,"order_type":1},"natural_form_sha256":"7ef1f4e260f7564290a36fe630833f0663f6f1d5c13c595a37c13b88550bdb29","order_source":"orderbook","orders_submitted":0,"presentation":{"amount":"0.06367563","amount_traded":"0","microtimestamp":"1787932602366000","price":"78522.98"},"previous_record_hash":"4a8c417295190cf539dc2aec499317e43c49e6b166451f16bb577842df147488","profit_assessment":null,"record_hash":"92a0242f24e9b8dafd7bd3e483f22dae454871f055e77dd12fb7741b0ebca437","recorded_unix_us":1787932602408010,"recorded_utc":"2026-08-28T15:56:42.408010Z","schema_version":"nrrf810.exchange_authored_interactive_closure.v1","source_chain_continuous":true,"source_event":"order_deleted","source_event_id":"00065a1d-7fa5-7830-0000-000103000020","source_event_id_unique":true,"source_pre_event_id":"00065a1d-7fa5-7448-0001-000102000020","translation":"FOLD_RETURN_TO_ZERO","unfold_event_id":"00065a1d-7fa1-2e88-0002-000100000020","zero_hair":true}
{"channel":"live_orders_btcusd","interaction_index":744,"natural_form":{"channel":"live_orders_btcusd","order_id":"2044303881949188","order_subtype":5,"order_type":1},"natural_form_sha256":"6403093feec85ad017aa4e9d09579e489676a96e00c4d339bdab52af87b7069b","order_source":"orderbook","orders_submitted":0,"presentation":{"amount":"0.25467128","amount_traded":"0","microtimestamp":"1787932602366000","price":"78532.61"},"previous_record_hash":"92a0242f24e9b8dafd7bd3e483f22dae454871f055e77dd12fb7741b0ebca437","profit_assessment":null,"record_hash":"7d6a3499383264c704d01230a6dedc943186c31026a4806ffc9a31bfa1614b47","recorded_unix_us":1787932602408129,"recorded_utc":"2026-08-28T15:56:42.408129Z","schema_version":"nrrf810.exchange_authored_interactive_closure.v1","source_chain_continuous":true,"source_event":"order_deleted","source_event_id":"00065a1d-7fa5-7830-0001-000100000020","source_event_id_unique":true,"source_pre_event_id":"00065a1d-7fa5-7830-0000-000103000020","translation":"FOLD_RETURN_TO_ZERO","unfold_event_id":"00065a1d-7fa1-3658-0000-000103000020","zero_hair":true}
{"channel":"live_orders_btcusd","interaction_index":745,"natural_form":{"channel":"live_orders_btcusd","order_id":"2044303881957376","order_subtype":5,"order_type":1},"natural_form_sha256":"4ccae53c099a18ef58d5daa41ee19784a3e59f6108396ed022a8ca526b58f689","order_source":"orderbook","orders_submitted":0,"presentation":{"amount":"0.25466146","amount_traded":"0","microtimestamp":"1787932602367000","price":"78535.64"},"previous_record_hash":"7d6a3499383264c704d01230a6dedc943186c31026a4806ffc9a31bfa1614b47","profit_assessment":null,"record_hash":"da9ee3d06ab66c51a036b925f97a2308402f0a5c2f8814c9299799f59d3b1a18","recorded_unix_us":1787932602408201,"recorded_utc":"2026-08-28T15:56:42.408201Z","schema_version":"nrrf810.exchange_authored_interactive_closure.v1","source_chain_continuous":true,"source_event":"order_deleted","source_event_id":"00065a1d-7fa5-7c18-0000-000101000020","source_event_id_unique":true,"source_pre_event_id":"00065a1d-7fa5-7830-0001-000100000020","translation":"FOLD_RETURN_TO_ZERO","unfold_event_id":"00065a1d-7fa1-3a40-0000-000100000020","zero_hair":true}
{"channel":"live_orders_btcusd","interaction_index":746,"natural_form":{"channel":"live_orders_btcusd","order_id":"2044303881957380","order_subtype":5,"order_type":1},"natural_form_sha256":"c0d260d1da948f3da0719ab58e4be8c35308090fd8c57fbb97e066c388a73155","order_source":"orderbook","orders_submitted":0,"presentation":{"amount":"1.26970017","amount_traded":"0","microtimestamp":"1787932602367000","price":"78758.76"},"previous_record_hash":"da9ee3d06ab66c51a036b925f97a2308402f0a5c2f8814c9299799f59d3b1a18","profit_assessment":null,"record_hash":"53a41d944fce08e88d6b3aedd5fa210576437616293ec18c201a583f65972316","recorded_unix_us":1787932602408224,"recorded_utc":"2026-08-28T15:56:42.408224Z","schema_version":"nrrf810.exchange_authored_interactive_closure.v1","source_chain_continuous":true,"source_event":"order_deleted","source_event_id":"00065a1d-7fa5-7c18-0001-000102000020","source_event_id_unique":true,"source_pre_event_id":"00065a1d-7fa5-7c18-0000-000101000020","translation":"FOLD_RETURN_TO_ZERO","unfold_event_id":"00065a1d-7fa1-3e28-0000-000101000020","zero_hair":true}
{"channel":"live_orders_btcusd","interaction_index":747,"natural_form":{"channel":"live_orders_btcusd","order_id":"2044303881957382","order_subtype":5,"order_type":1},"natural_form_sha256":"8309fc81cadfe2b51c3726ebc4a43155fa3444b115e17a9d06342499d01146b1","order_source":"orderbook","orders_submitted":0,"presentation":{"amount":"1.27209222","amount_traded":"0","microtimestamp":"1787932602367000","price":"78610.66"},"previous_record_hash":"53a41d944fce08e88d6b3aedd5fa210576437616293ec18c201a583f65972316","profit_assessment":null,"record_hash":"a03615062bc102d3d6c65c458859fb3010d759930d10727d1cb0c7994ef85ea0","recorded_unix_us":1787932602408344,"recorded_utc":"2026-08-28T15:56:42.408344Z","schema_version":"nrrf810.exchange_authored_interactive_closure.v1","source_chain_continuous":true,"source_event":"order_deleted","source_event_id":"00065a1d-7fa5-7c18-0002-000103000020","source_event_id_unique":true,"source_pre_event_id":"00065a1d-7fa5-7c18-0001-000102000020","translation":"FOLD_RETURN_TO_ZERO","unfold_event_id":"00065a1d-7fa1-3e28-0001-000102000020","zero_hair":true}
{"channel":"live_orders_btcusd","interaction_index":748,"natural_form":{"channel":"live_orders_btcusd","order_id":"2044303881961473","order_subtype":5,"order_type":1},"natural_form_sha256":"61af4c113ea6941fec36a4b9f23ca32d645f14e8a640a33fe8f5257d4da507c4","order_source":"orderbook","orders_submitted":0,"presentation":{"amount":"12.70451953","amount_traded":"0","microtimestamp":"1787932602368000","price":"78712.15"},"previous_record_hash":"a03615062bc102d3d6c65c458859fb3010d759930d10727d1cb0c7994ef85ea0","profit_assessment":null,"record_hash":"f84bdea8d2744c27113e5a3a3b07bffab4a3de2d5dbcf7becd04551eed8ad9ae","recorded_unix_us":1787932602408405,"recorded_utc":"2026-08-28T15:56:42.408405Z","schema_version":"nrrf810.exchange_authored_interactive_closure.v1","source_chain_continuous":true,"source_event":"order_deleted","source_event_id":"00065a1d-7fa5-8000-0000-000100000020","source_event_id_unique":true,"source_pre_event_id":"00065a1d-7fa5-7c18-0002-000103000020","translation":"FOLD_RETURN_TO_ZERO","unfold_event_id":"00065a1d-7fa1-3e28-0002-000103000020","zero_hair":true}
{"channel":"live_orders_btcusd","interaction_index":749,"natural_form":{"channel":"live_orders_btcusd","order_id":"2044303881973767","order_subtype":5,"order_type":1},"natural_form_sha256":"9649295e8ef102e65ea791b3e395be03291368d33f3d701061d72828dd987b9b","order_source":"orderbook","orders_submitted":0,"presentation":{"amount":"1.26840120","amount_traded":"0","microtimestamp":"1787932602368000","price":"78839.41"},"previous_record_hash":"f84bdea8d2744c27113e5a3a3b07bffab4a3de2d5dbcf7becd04551eed8ad9ae","profit_assessment":null,"record_hash":"fbe4c4aa643e1f9e7ec04dd7deeef1dfe8b581f18be8c6a0d99d524efa3062a6","recorded_unix_us":1787932602408429,"recorded_utc":"2026-08-28T15:56:42.408429Z","schema_version":"nrrf810.exchange_authored_interactive_closure.v1","source_chain_continuous":true,"source_event":"order_deleted","source_event_id":"00065a1d-7fa5-8000-0001-000101000020","source_event_id_unique":true,"source_pre_event_id":"00065a1d-7fa5-8000-0000-000100000020","translation":"FOLD_RETURN_TO_ZERO","unfold_event_id":"00065a1d-7fa1-4dc8-0000-000102000020","zero_hair":true}
{"channel":"live_orders_btcusd","interaction_index":750,"natural_form":{"channel":"live_orders_btcusd","order_id":"2044303881986050","order_subtype":5,"order_type":0},"natural_form_sha256":"c547d44ab1a88d86d718054ee7346f2d1a484ba5b4c970e7f300e6b3c0b1679c","order_source":"orderbook","orders_submitted":0,"presentation":{"amount":"0.06367953","amount_traded":"0","microtimestamp":"1787932602368000","price":"78518.15"},"previous_record_hash":"fbe4c4aa643e1f9e7ec04dd7deeef1dfe8b581f18be8c6a0d99d524efa3062a6","profit_assessment":null,"record_hash":"935b6f2052955a31598e4f158b0573794593ec3323a114c57ac77d6336a34625","recorded_unix_us":1787932602408555,"recorded_utc":"2026-08-28T15:56:42.408555Z","schema_version":"nrrf810.exchange_authored_interactive_closure.v1","source_chain_continuous":true,"source_event":"order_deleted","source_event_id":"00065a1d-7fa5-8000-0002-000102000020","source_event_id_unique":true,"source_pre_event_id":"00065a1d-7fa5-8000-0001-000101000020","translation":"FOLD_RETURN_TO_ZERO","unfold_event_id":"00065a1d-7fa1-5598-0001-000102000020","zero_hair":true}
{"channel":"live_orders_ethusd","interaction_index":751,"natural_form":{"channel":"live_orders_ethusd","order_id":"2044303878094874","order_subtype":5,"order_type":0},"natural_form_sha256":"64bf261a701604e50d7cc26dfdfd73028b9baa8de513ded06ba6cca881d10e76","order_source":"orderbook","orders_submitted":0,"presentation":{"amount":"4.838915","amount_traded":"0","microtimestamp":"1787932602369000","price":"2480.07"},"previous_record_hash":"935b6f2052955a31598e4f158b0573794593ec3323a114c57ac77d6336a34625","profit_assessment":null,"record_hash":"863f537fb6f0f0d454e0e0a3cbcced00e9b1ccbfe385bd5e4a5926bcd2dc7b73","recorded_unix_us":1787932602408584,"recorded_utc":"2026-08-28T15:56:42.408584Z","schema_version":"nrrf810.exchange_authored_interactive_closure.v1","source_chain_continuous":true,"source_event":"order_deleted","source_event_id":"00065a1d-7fa5-83e8-0000-001202000020","source_event_id_unique":true,"source_pre_event_id":"00065a1d-7fa5-4d38-0000-001201000020","translation":"PARTIAL_PRIOR_UNFOLD","unfold_event_id":null,"zero_hair":false}
