{"message":"{\"data\":{\"id\":2044303884533760,\"id_str\":\"2044303884533760\",\"order_type\":0,\"order_subtype\":5,\"datetime\":\"1787932603\",\"microtimestamp\":\"1787932602718000\",\"amount\":0.63679443,\"amount_str\":\"0.63679443\",\"amount_traded\":\"0\",\"amount_at_create\":\"0.63679443\",\"price\":78484.05,\"price_str\":\"78484.05\",\"is_liquidation\":false},\"channel\":\"live_orders_btcusd\",\"event\":\"order_created\",\"event_id\":\"00065a1d-7faa-d730-0000-000103000020\",\"pre_event_id\":\"00065a1d-7faa-c3a8-0001-000102000020\",\"order_source\":\"orderbook\"}","recorded_unix_us":1787932602790205}
{"message":"{\"data\":{\"id\":2044303884541952,\"id_str\":\"2044303884541952\",\"order_type\":1,\"order_subtype\":5,\"datetime\":\"1787932603\",\"microtimestamp\":\"1787932602719000\",\"amount\":0.1,\"amount_str\":\"0.10000000\",\"amount_traded\":\"0\",\"amount_at_create\":\"0.10000000\",\"price\":78522.62,\"price_str\":\"78522.62\",\"is_liquidation\":false},\"channel\":\"live_orders_btcusd\",\"event\":\"order_created\",\"event_id\":\"00065a1d-7faa-db18-0000-000100000020\",\"pre_event_id\":\"00065a1d-7faa-d730-0000-000103000020\",\"order_source\":\"orderbook\"}","recorded_unix_us":1787932602790376}
{"message":"{\"data\":{\"id\":2044303884541952,\"id_str\":\"2044303884541952\",\"order_type\":1,\"order_subtype\":5,\"datetime\":\"1787932603\",\"microtimestamp\":\"1787932602719000\",\"amount\":0.1,\"amount_str\":\"0.10000000\",\"amount_traded\":\"0\",\"amount_at_create\":\"0.10000000\",\"price\":78522.62,\"price_str\":\"78522.62\",\"is_liquidation\":false},\"channel\":\"live_orders_btcusd\",\"event\":\"order_deleted\",\"event_id\":\"00065a1d-7faa-db18-0001-000101000020\",\"pre_event_id\":\"00065a1d-7faa-db18-0000-000100000020\",\"order_source\":\"orderbook\"}","recorded_unix_us":1787932602790395}
{"message":"{\"data\":{\"id\":2044303884546048,\"id_str\":\"2044303884546048\",\"order_type\":0,\"order_subtype\":5,\"datetime\":\"1787932603\",\"microtimestamp\":\"1787932602720000\",\"amount\":0.12,\"amount_str\":\"0.12000000\",\"amount_traded\":\"0\",\"amount_at_create\":\"0.12000000\",\"price\":78509.2,\"price_str\":\"78509.20\",\"is_liquidation\":false},\"channel\":\"live_orders_btcusd\",\"event\":\"order_created\",\"event_id\":\"00065a1d-7faa-df00-0000-000102000020\",\"pre_event_id\":\"00065a1d-7faa-db18-0001-000101000020\",\"order_source\":\"orderbook\"}","recorded_unix_us":1787932602790413}
{"message":"{\"data\":{\"id\":2044303883722752,\"id_str\":\"2044303883722752\",\"order_type\":0,\"order_subtype\":5,\"datetime\":\"1787932603\",\"microtimestamp\":\"1787932602722000\",\"amount\":0.12,\"amount_str\":\"0.12000000\",\"amount_traded\":\"0\",\"amount_at_create\":\"0.12000000\",\"price\":78508.87,\"price_str\":\"78508.87\",\"is_liquidation\":false},\"channel\":\"live_orders_btcusd\",\"event\":\"order_deleted\",\"event_id\":\"00065a1d-7faa-e6d0-0000-000103000020\",\"pre_event_id\":\"00065a1d-7faa-df00-0000-000102000020\",\"order_source\":\"orderbook\"}","recorded_unix_us":1787932602790429}
{"message":"{\"data\":{\"id\":2044303884500993,\"id_str\":\"2044303884500993\",\"order_type\":0,\"order_subtype\":5,\"datetime\":\"1787932603\",\"microtimestamp\":\"1787932602725000\",\"amount\":0.435648,\"amount_str\":\"0.435648\",\"amount_traded\":\"0\",\"amount_at_create\":\"0.435648\",\"price\":2480.11,\"price_str\":\"2480.11\",\"is_liquidation\":false},\"channel\":\"live_orders_ethusd\",\"event\":\"order_deleted\",\"event_id\":\"00065a1d-7faa-f288-0000-001200000020\",\"pre_event_id\":\"00065a1d-7faa-b7f0-0000-001203000020\",\"order_source\":\"orderbook\"}","recorded_unix_us":1787932602790505}
{"message":"{\"data\":{\"id\":2044303884574720,\"id_str\":\"2044303884574720\",\"order_type\":1,\"order_subtype\":5,\"datetime\":\"1787932603\",\"microtimestamp\":\"1787932602727000\",\"amount\":0.1,\"amount_str\":\"0.10000000\",\"amount_traded\":\"0\",\"amount_at_create\":\"0.10000000\",\"price\":78522.63,\"price_str\":\"78522.63\",\"is_liquidation\":false},\"channel\":\"live_orders_btcusd\",\"event\":\"order_created\",\"event_id\":\"00065a1d-7faa-fa58-0000-000100000020\",\"pre_event_id\":\"00065a1d-7faa-e6d0-0000-000103000020\",\"order_source\":\"orderbook\"}","recorded_unix_us":1787932602790598}
{"message":"{\"data\":{\"id\":2044303884574720,\"id_str\":\"2044303884574720\",\"order_type\":1,\"order_subtype\":5,\"datetime\":\"1787932603\",\"microtimestamp\":\"1787932602727000\",\"amount\":0.1,\"amount_str\":\"0.10000000\",\"amount_traded\":\"0\",\"amount_at_create\":\"0.10000000\",\"price\":78522.63,\"price_str\":\"78522.63\",\"is_liquidation\":false},\"channel\":\"live_orders_btcusd\",\"event\":\"order_deleted\",\"event_id\":\"00065a1d-7faa-fa58-0001-000101000020\",\"pre_event_id\":\"00065a1d-7faa-fa58-0000-000100000020\",\"order_source\":\"orderbook\"}","recorded_unix_us":1787932602790618}
{"message":"{\"data\":{\"id\":2044303884611584,\"id_str\":\"2044303884611584\",\"order_type\":0,\"order_subtype\":5,\"datetime\":\"1787932603\",\"microtimestamp\":\"1787932602736000\",\"amount\":0.535391,\"amount_str\":\"0.535391\",\"amount_traded\":\"0\",\"amount_at_create\":\"0.535391\",\"price\":2480.17,\"price_str\":\"2480.17\",\"is_liquidation\":false},\"channel\":\"live_orders_ethusd\",\"event\":\"order_created\",\"event_id\":\"00065a1d-7fab-1d80-0000-001201000020\",\"pre_event_id\":\"00065a1d-7faa-f288-0000-001200000020\",\"order_source\":\"orderbook\"}","recorded_unix_us":1787932602790682}
{"message":"{\"data\":{\"id\":2044303884611586,\"id_str\":\"2044303884611586\",\"order_type\":1,\"order_subtype\":5,\"datetime\":\"1787932603\",\"microtimestamp\":\"1787932602736000\",\"amount\":0.06310787,\"amount_str\":\"0.06310787\",\"amount_traded\":\"0\",\"amount_at_create\":\"0.06310787\",\"price\":78520.1,\"price_str\":\"78520.10\",\"is_liquidation\":false},\"channel\":\"live_orders_btcusd\",\"event\":\"order_created\",\"event_id\":\"00065a1d-7fab-1d80-0000-000102000020\",\"pre_event_id\":\"00065a1d-7faa-fa58-0001-000101000020\",\"order_source\":\"orderbook\"}","recorded_unix_us":1787932602790759}
{"message":"{\"data\":{\"id\":2044303884611586,\"id_str\":\"2044303884611586\",\"order_type\":1,\"order_subtype\":5,\"datetime\":\"1787932603\",\"microtimestamp\":\"1787932602736000\",\"amount\":0.06310787,\"amount_str\":\"0.06310787\",\"amount_traded\":\"0\",\"amount_at_create\":\"0.06310787\",\"price\":78520.1,\"price_str\":\"78520.10\",\"is_liquidation\":false},\"channel\":\"live_orders_btcusd\",\"event\":\"order_deleted\",\"event_id\":\"00065a1d-7fab-1d80-0001-000103000020\",\"pre_event_id\":\"00065a1d-7fab-1d80-0000-000102000020\",\"order_source\":\"orderbook\"}","recorded_unix_us":1787932602790849}
{"message":"{\"data\":{\"id\":2044303884636160,\"id_str\":\"2044303884636160\",\"order_type\":1,\"order_subtype\":5,\"datetime\":\"1787932603\",\"microtimestamp\":\"1787932602743000\",\"amount\":0.06310787,\"amount_str\":\"0.06310787\",\"amount_traded\":\"0\",\"amount_at_create\":\"0.06310787\",\"price\":78522.46,\"price_str\":\"78522.46\",\"is_liquidation\":false},\"channel\":\"live_orders_btcusd\",\"event\":\"order_created\",\"event_id\":\"00065a1d-7fab-38d8-0000-000100000020\",\"pre_event_id\":\"00065a1d-7fab-1d80-0001-000103000020\",\"order_source\":\"orderbook\"}","recorded_unix_us":1787932602790903}
{"message":"{\"data\":{\"id\":2044303884636160,\"id_str\":\"2044303884636160\",\"order_type\":1,\"order_subtype\":5,\"datetime\":\"1787932603\",\"microtimestamp\":\"1787932602743000\",\"amount\":0.06310787,\"amount_str\":\"0.06310787\",\"amount_traded\":\"0\",\"amount_at_create\":\"0.06310787\",\"price\":78522.46,\"price_str\":\"78522.46\",\"is_liquidation\":false},\"channel\":\"live_orders_btcusd\",\"event\":\"order_deleted\",\"event_id\":\"00065a1d-7fab-38d8-0001-000101000020\",\"pre_event_id\":\"00065a1d-7fab-38d8-0000-000100000020\",\"order_source\":\"orderbook\"}","recorded_unix_us":1787932602790923}
{"message":"{\"data\":{\"id\":2044303884693505,\"id_str\":\"2044303884693505\",\"order_type\":1,\"order_subtype\":5,\"datetime\":\"1787932603\",\"microtimestamp\":\"1787932602757000\",\"amount\":0.1,\"amount_str\":\"0.10000000\",\"amount_traded\":\"0\",\"amount_at_create\":\"0.10000000\",\"price\":78522.63,\"price_str\":\"78522.63\",\"is_liquidation\":false},\"channel\":\"live_orders_btcusd\",\"event\":\"order_created\",\"event_id\":\"00065a1d-7fab-6f88-0000-000102000020\",\"pre_event_id\":\"00065a1d-7fab-38d8-0001-000101000020\",\"order_source\":\"orderbook\"}","recorded_unix_us":1787932602791002}
{"message":"{\"data\":{\"id\":2044303884693505,\"id_str\":\"2044303884693505\",\"order_type\":1,\"order_subtype\":5,\"datetime\":\"1787932603\",\"microtimestamp\":\"1787932602757000\",\"amount\":0.1,\"amount_str\":\"0.10000000\",\"amount_traded\":\"0\",\"amount_at_create\":\"0.10000000\",\"price\":78522.63,\"price_str\":\"78522.63\",\"is_liquidation\":false},\"channel\":\"live_orders_btcusd\",\"event\":\"order_deleted\",\"event_id\":\"00065a1d-7fab-6f88-0001-000103000020\",\"pre_event_id\":\"00065a1d-7fab-6f88-0000-000102000020\",\"order_source\":\"orderbook\"}","recorded_unix_us":1787932602791021}
{"message":"{\"data\":{\"id\":2044303884713984,\"id_str\":\"2044303884713984\",\"order_type\":1,\"order_subtype\":5,\"datetime\":\"1787932603\",\"microtimestamp\":\"1787932602762000\",\"amount\":0.1,\"amount_str\":\"0.10000000\",\"amount_traded\":\"0\",\"amount_at_create\":\"0.10000000\",\"price\":78522.62,\"price_str\":\"78522.62\",\"is_liquidation\":false},\"channel\":\"live_orders_btcusd\",\"event\":\"order_created\",\"event_id\":\"00065a1d-7fab-8310-0000-000100000020\",\"pre_event_id\":\"00065a1d-7fab-6f88-0001-000103000020\",\"order_source\":\"orderbook\"}","recorded_unix_us":1787932602799341}
{"message":"{\"data\":{\"id\":2044303884713984,\"id_str\":\"2044303884713984\",\"order_type\":1,\"order_subtype\":5,\"datetime\":\"1787932603\",\"microtimestamp\":\"1787932602762000\",\"amount\":0.1,\"amount_str\":\"0.10000000\",\"amount_traded\":\"0\",\"amount_at_create\":\"0.10000000\",\"price\":78522.62,\"price_str\":\"78522.62\",\"is_liquidation\":false},\"channel\":\"live_orders_btcusd\",\"event\":\"order_deleted\",\"event_id\":\"00065a1d-7fab-8310-0001-000101000020\",\"pre_event_id\":\"00065a1d-7fab-8310-0000-000100000020\",\"order_source\":\"orderbook\"}","recorded_unix_us":1787932602799427}
{"message":"{\"data\":{\"id\":2044303884746753,\"id_str\":\"2044303884746753\",\"order_type\":1,\"order_subtype\":5,\"datetime\":\"1787932603\",\"microtimestamp\":\"1787932602770000\",\"amount\":0.06310787,\"amount_str\":\"0.06310787\",\"amount_traded\":\"0\",\"amount_at_create\":\"0.06310787\",\"price\":78522.58,\"price_str\":\"78522.58\",\"is_liquidation\":false},\"channel\":\"live_orders_btcusd\",\"event\":\"order_created\",\"event_id\":\"00065a1d-7fab-a250-0000-000102000020\",\"pre_event_id\":\"00065a1d-7fab-8310-0001-000101000020\",\"order_source\":\"orderbook\"}","recorded_unix_us":1787932602799480}
{"message":"{\"data\":{\"id\":2044303884746753,\"id_str\":\"2044303884746753\",\"order_type\":1,\"order_subtype\":5,\"datetime\":\"1787932603\",\"microtimestamp\":\"1787932602770000\",\"amount\":0.06310787,\"amount_str\":\"0.06310787\",\"amount_traded\":\"0\",\"amount_at_create\":\"0.06310787\",\"price\":78522.58,\"price_str\":\"78522.58\",\"is_liquidation\":false},\"channel\":\"live_orders_btcusd\",\"event\":\"order_deleted\",\"event_id\":\"00065a1d-7fab-a250-0001-000103000020\",\"pre_event_id\":\"00065a1d-7fab-a250-0000-000102000020\",\"order_source\":\"orderbook\"}","recorded_unix_us":1787932602799508}
{"message":"{\"data\":{\"id\":2044303884750848,\"id_str\":\"2044303884750848\",\"order_type\":1,\"order_subtype\":5,\"datetime\":\"1787932603\",\"microtimestamp\":\"1787932602770000\",\"amount\":0.06310787,\"amount_str\":\"0.06310787\",\"amount_traded\":\"0\",\"amount_at_create\":\"0.06310787\",\"price\":78520.22,\"price_str\":\"78520.22\",\"is_liquidation\":false},\"channel\":\"live_orders_btcusd\",\"event\":\"order_created\",\"event_id\":\"00065a1d-7fab-a250-0002-000100000020\",\"pre_event_id\":\"00065a1d-7fab-a250-0001-000103000020\",\"order_source\":\"orderbook\"}","recorded_unix_us":1787932602799586}
{"message":"{\"data\":{\"id\":2044303884750848,\"id_str\":\"2044303884750848\",\"order_type\":1,\"order_subtype\":5,\"datetime\":\"1787932603\",\"microtimestamp\":\"1787932602770000\",\"amount\":0.06310787,\"amount_str\":\"0.06310787\",\"amount_traded\":\"0\",\"amount_at_create\":\"0.06310787\",\"price\":78520.22,\"price_str\":\"78520.22\",\"is_liquidation\":false},\"channel\":\"live_orders_btcusd\",\"event\":\"order_deleted\",\"event_id\":\"00065a1d-7fab-a250-0003-000101000020\",\"pre_event_id\":\"00065a1d-7fab-a250-0002-000100000020\",\"order_source\":\"orderbook\"}","recorded_unix_us":1787932602799604}
{"message":"{\"data\":{\"id\":2044303884812288,\"id_str\":\"2044303884812288\",\"order_type\":1,\"order_subtype\":5,\"datetime\":\"1787932603\",\"microtimestamp\":\"1787932602785000\",\"amount\":0.1,\"amount_str\":\"0.10000000\",\"amount_traded\":\"0\",\"amount_at_create\":\"0.10000000\",\"price\":78522.63,\"price_str\":\"78522.63\",\"is_liquidation\":false},\"channel\":\"live_orders_btcusd\",\"event\":\"order_created\",\"event_id\":\"00065a1d-7fab-dce8-0000-000102000020\",\"pre_event_id\":\"00065a1d-7fab-a250-0003-000101000020\",\"order_source\":\"orderbook\"}","recorded_unix_us":1787932602839098}
{"message":"{\"data\":{\"id\":2044303884812288,\"id_str\":\"2044303884812288\",\"order_type\":1,\"order_subtype\":5,\"datetime\":\"1787932603\",\"microtimestamp\":\"1787932602785000\",\"amount\":0.1,\"amount_str\":\"0.10000000\",\"amount_traded\":\"0\",\"amount_at_create\":\"0.10000000\",\"price\":78522.63,\"price_str\":\"78522.63\",\"is_liquidation\":false},\"channel\":\"live_orders_btcusd\",\"event\":\"order_deleted\",\"event_id\":\"00065a1d-7fab-dce8-0001-000103000020\",\"pre_event_id\":\"00065a1d-7fab-dce8-0000-000102000020\",\"order_source\":\"orderbook\"}","recorded_unix_us":1787932602839148}
{"message":"{\"data\":{\"id\":2044303884812293,\"id_str\":\"2044303884812293\",\"order_type\":0,\"order_subtype\":5,\"datetime\":\"1787932603\",\"microtimestamp\":\"1787932602785000\",\"amount\":0.00140266,\"amount_str\":\"0.00140266\",\"amount_traded\":\"0\",\"amount_at_create\":\"0.00140266\",\"price\":70668.36,\"price_str\":\"70668.36\",\"is_liquidation\":false},\"channel\":\"live_orders_btcusd\",\"event\":\"order_created\",\"event_id\":\"00065a1d-7fab-dce8-0002-000100000020\",\"pre_event_id\":\"00065a1d-7fab-dce8-0001-000103000020\",\"order_source\":\"orderbook\"}","recorded_unix_us":1787932602839175}
{"message":"{\"data\":{\"id\":2044303883984900,\"id_str\":\"2044303883984900\",\"order_type\":1,\"order_subtype\":5,\"datetime\":\"1787932603\",\"microtimestamp\":\"1787932602788000\",\"amount\":12.087822,\"amount_str\":\"12.087822\",\"amount_traded\":\"0\",\"amount_at_create\":\"12.087822\",\"price\":2481.84,\"price_str\":\"2481.84\",\"is_liquidation\":false},\"channel\":\"live_orders_ethusd\",\"event\":\"order_deleted\",\"event_id\":\"00065a1d-7fab-e8a0-0000-001202000020\",\"pre_event_id\":\"00065a1d-7fab-1d80-0000-001201000020\",\"order_source\":\"orderbook\"}","recorded_unix_us":1787932602839285}
{"message":"{\"data\":{\"id\":2044303883988997,\"id_str\":\"2044303883988997\",\"order_type\":1,\"order_subtype\":5,\"datetime\":\"1787932603\",\"microtimestamp\":\"1787932602789000\",\"amount\":12.086444,\"amount_str\":\"12.086444\",\"amount_traded\":\"0\",\"amount_at_create\":\"12.086444\",\"price\":2482.12,\"price_str\":\"2482.12\",\"is_liquidation\":false},\"channel\":\"live_orders_ethusd\",\"event\":\"order_deleted\",\"event_id\":\"00065a1d-7fab-ec88-0000-001203000020\",\"pre_event_id\":\"00065a1d-7fab-e8a0-0000-001202000020\",\"order_source\":\"orderbook\"}","recorded_unix_us":1787932602839384}
{"message":"{\"data\":{\"id\":2044303884001280,\"id_str\":\"2044303884001280\",\"order_type\":1,\"order_subtype\":5,\"datetime\":\"1787932603\",\"microtimestamp\":\"1787932602789000\",\"amount\":4.028412,\"amount_str\":\"4.028412\",\"amount_traded\":\"0\",\"amount_at_create\":\"4.028412\",\"price\":2482.37,\"price_str\":\"2482.37\",\"is_liquidation\":false},\"channel\":\"live_orders_ethusd\",\"event\":\"order_deleted\",\"event_id\":\"00065a1d-7fab-ec88-0001-001200000020\",\"pre_event_id\":\"00065a1d-7fab-ec88-0000-001203000020\",\"order_source\":\"orderbook\"}","recorded_unix_us":1787932602839515}
{"message":"{\"data\":{\"id\":2044303884005376,\"id_str\":\"2044303884005376\",\"order_type\":1,\"order_subtype\":5,\"datetime\":\"1787932603\",\"microtimestamp\":\"1787932602789000\",\"amount\":4.027018,\"amount_str\":\"4.027018\",\"amount_traded\":\"0\",\"amount_at_create\":\"4.027018\",\"price\":2483.23,\"price_str\":\"2483.23\",\"is_liquidation\":false},\"channel\":\"live_orders_ethusd\",\"event\":\"order_deleted\",\"event_id\":\"00065a1d-7fab-ec88-0002-001201000020\",\"pre_event_id\":\"00065a1d-7fab-ec88-0001-001200000020\",\"order_source\":\"orderbook\"}","recorded_unix_us":1787932602839545}
{"message":"{\"data\":{\"id\":2044303884009473,\"id_str\":\"2044303884009473\",\"order_type\":1,\"order_subtype\":5,\"datetime\":\"1787932603\",\"microtimestamp\":\"1787932602790000\",\"amount\":10.06507,\"amount_str\":\"10.065070\",\"amount_traded\":\"0\",\"amount_at_create\":\"10.065070\",\"price\":2483.84,\"price_str\":\"2483.84\",\"is_liquidation\":false},\"channel\":\"live_orders_ethusd\",\"event\":\"order_deleted\",\"event_id\":\"00065a1d-7fab-f070-0000-001202000020\",\"pre_event_id\":\"00065a1d-7fab-ec88-0002-001201000020\",\"order_source\":\"orderbook\"}","recorded_unix_us":1787932602839669}
{"message":"{\"data\":{\"id\":2044303882911754,\"id_str\":\"2044303882911754\",\"order_type\":0,\"order_subtype\":5,\"datetime\":\"1787932603\",\"microtimestamp\":\"1787932602790000\",\"amount\":0.50943388,\"amount_str\":\"0.50943388\",\"amount_traded\":\"0\",\"amount_at_create\":\"0.50943388\",\"price\":78481.08,\"price_str\":\"78481.08\",\"is_liquidation\":false},\"channel\":\"live_orders_btcusd\",\"event\":\"order_deleted\",\"event_id\":\"00065a1d-7fab-f070-0000-000101000020\",\"pre_event_id\":\"00065a1d-7fab-dce8-0002-000100000020\",\"order_source\":\"orderbook\"}","recorded_unix_us":1787932602839735}
{"message":"{\"data\":{\"id\":2044303884009474,\"id_str\":\"2044303884009474\",\"order_type\":1,\"order_subtype\":5,\"datetime\":\"1787932603\",\"microtimestamp\":\"1787932602790000\",\"amount\":10.057184,\"amount_str\":\"10.057184\",\"amount_traded\":\"0\",\"amount_at_create\":\"10.057184\",\"price\":2485.79,\"price_str\":\"2485.79\",\"is_liquidation\":false},\"channel\":\"live_orders_ethusd\",\"event\":\"order_deleted\",\"event_id\":\"00065a1d-7fab-f070-0001-001203000020\",\"pre_event_id\":\"00065a1d-7fab-f070-0000-001202000020\",\"order_source\":\"orderbook\"}","recorded_unix_us":1787932602839760}
{"message":"{\"data\":{\"id\":2044303884013568,\"id_str\":\"2044303884013568\",\"order_type\":1,\"order_subtype\":5,\"datetime\":\"1787932603\",\"microtimestamp\":\"1787932602790000\",\"amount\":20.088574,\"amount_str\":\"20.088574\",\"amount_traded\":\"0\",\"amount_at_create\":\"20.088574\",\"price\":2488.98,\"price_str\":\"2488.98\",\"is_liquidation\":false},\"channel\":\"live_orders_ethusd\",\"event\":\"order_deleted\",\"event_id\":\"00065a1d-7fab-f070-0002-001200000020\",\"pre_event_id\":\"00065a1d-7fab-f070-0001-001203000020\",\"order_source\":\"orderbook\"}","recorded_unix_us":1787932602839835}
{"message":"{\"data\":{\"id\":2044303884017666,\"id_str\":\"2044303884017666\",\"order_type\":1,\"order_subtype\":5,\"datetime\":\"1787932603\",\"microtimestamp\":\"1787932602791000\",\"amount\":20.097242,\"amount_str\":\"20.097242\",\"amount_traded\":\"0\",\"amount_at_create\":\"20.097242\",\"price\":2487.91,\"price_str\":\"2487.91\",\"is_liquidation\":false},\"channel\":\"live_orders_ethusd\",\"event\":\"order_deleted\",\"event_id\":\"00065a1d-7fab-f458-0000-001201000020\",\"pre_event_id\":\"00065a1d-7fab-f070-0002-001200000020\",\"order_source\":\"orderbook\"}","recorded_unix_us":1787932602840280}
{"message":"{\"data\":{\"id\":2044303884025861,\"id_str\":\"2044303884025861\",\"order_type\":1,\"order_subtype\":5,\"datetime\":\"1787932603\",\"microtimestamp\":\"1787932602791000\",\"amount\":40.09205,\"amount_str\":\"40.092050\",\"amount_traded\":\"0\",\"amount_at_create\":\"40.092050\",\"price\":2494.27,\"price_str\":\"2494.27\",\"is_liquidation\":false},\"channel\":\"live_orders_ethusd\",\"event\":\"order_deleted\",\"event_id\":\"00065a1d-7fab-f458-0001-001202000020\",\"pre_event_id\":\"00065a1d-7fab-f458-0000-001201000020\",\"order_source\":\"orderbook\"}","recorded_unix_us":1787932602840303}
{"message":"{\"data\":{\"id\":2044303884025862,\"id_str\":\"2044303884025862\",\"order_type\":1,\"order_subtype\":5,\"datetime\":\"1787932603\",\"microtimestamp\":\"1787932602791000\",\"amount\":39.969006,\"amount_str\":\"39.969006\",\"amount_traded\":\"0\",\"amount_at_create\":\"39.969006\",\"price\":2501.94,\"price_str\":\"2501.94\",\"is_liquidation\":false},\"channel\":\"live_orders_ethusd\",\"event\":\"order_deleted\",\"event_id\":\"00065a1d-7fab-f458-0002-001203000020\",\"pre_event_id\":\"00065a1d-7fab-f458-0001-001202000020\",\"order_source\":\"orderbook\"}","recorded_unix_us":1787932602840323}
{"message":"{\"data\":{\"id\":2044303843934214,\"id_str\":\"2044303843934214\",\"order_type\":1,\"order_subtype\":5,\"datetime\":\"1787932603\",\"microtimestamp\":\"1787932602794000\",\"amount\":14.02,\"amount_str\":\"14.020000\",\"amount_traded\":\"0\",\"amount_at_create\":\"14.020000\",\"price\":2482.44,\"price_str\":\"2482.44\",\"is_liquidation\":false},\"channel\":\"live_orders_ethusd\",\"event\":\"order_deleted\",\"event_id\":\"00065a1d-7fac-0010-0000-001200000020\",\"pre_event_id\":\"00065a1d-7fab-f458-0002-001203000020\",\"order_source\":\"orderbook\"}","recorded_unix_us":1787932602840443}
{"message":"{\"data\":{\"id\":2044303884857350,\"id_str\":\"2044303884857350\",\"order_type\":1,\"order_subtype\":5,\"datetime\":\"1787932603\",\"microtimestamp\":\"1787932602796000\",\"amount\":0.06310787,\"amount_str\":\"0.06310787\",\"amount_traded\":\"0\",\"amount_at_create\":\"0.06310787\",\"price\":78522.58,\"price_str\":\"78522.58\",\"is_liquidation\":false},\"channel\":\"live_orders_btcusd\",\"event\":\"order_created\",\"event_id\":\"00065a1d-7fac-07e0-0000-000102000020\",\"pre_event_id\":\"00065a1d-7fab-f070-0000-000101000020\",\"order_source\":\"orderbook\"}","recorded_unix_us":1787932602840467}
{"message":"{\"data\":{\"id\":2044303884857350,\"id_str\":\"2044303884857350\",\"order_type\":1,\"order_subtype\":5,\"datetime\":\"1787932603\",\"microtimestamp\":\"1787932602796000\",\"amount\":0.06310787,\"amount_str\":\"0.06310787\",\"amount_traded\":\"0\",\"amount_at_create\":\"0.06310787\",\"price\":78522.58,\"price_str\":\"78522.58\",\"is_liquidation\":false},\"channel\":\"live_orders_btcusd\",\"event\":\"order_deleted\",\"event_id\":\"00065a1d-7fac-07e0-0001-000103000020\",\"pre_event_id\":\"00065a1d-7fac-07e0-0000-000102000020\",\"order_source\":\"orderbook\"}","recorded_unix_us":1787932602840562}
{"message":"{\"data\":{\"id\":2044303884857352,\"id_str\":\"2044303884857352\",\"order_type\":1,\"order_subtype\":5,\"datetime\":\"1787932603\",\"microtimestamp\":\"1787932602797000\",\"amount\":0.1,\"amount_str\":\"0.10000000\",\"amount_traded\":\"0\",\"amount_at_create\":\"0.10000000\",\"price\":78522.62,\"price_str\":\"78522.62\",\"is_liquidation\":false},\"channel\":\"live_orders_btcusd\",\"event\":\"order_created\",\"event_id\":\"00065a1d-7fac-0bc8-0000-000100000020\",\"pre_event_id\":\"00065a1d-7fac-07e0-0001-000103000020\",\"order_source\":\"orderbook\"}","recorded_unix_us":1787932602840586}
{"message":"{\"data\":{\"id\":2044303884857352,\"id_str\":\"2044303884857352\",\"order_type\":1,\"order_subtype\":5,\"datetime\":\"1787932603\",\"microtimestamp\":\"1787932602797000\",\"amount\":0.1,\"amount_str\":\"0.10000000\",\"amount_traded\":\"0\",\"amount_at_create\":\"0.10000000\",\"price\":78522.62,\"price_str\":\"78522.62\",\"is_liquidation\":false},\"channel\":\"live_orders_btcusd\",\"event\":\"order_deleted\",\"event_id\":\"00065a1d-7fac-0bc8-0001-000101000020\",\"pre_event_id\":\"00065a1d-7fac-0bc8-0000-000100000020\",\"order_source\":\"orderbook\"}","recorded_unix_us":1787932602840682}
{"message":"{\"data\":{\"id\":2044303884861445,\"id_str\":\"2044303884861445\",\"order_type\":1,\"order_subtype\":5,\"datetime\":\"1787932603\",\"microtimestamp\":\"1787932602797000\",\"amount\":0.06310787,\"amount_str\":\"0.06310787\",\"amount_traded\":\"0\",\"amount_at_create\":\"0.06310787\",\"price\":78520.14,\"price_str\":\"78520.14\",\"is_liquidation\":false},\"channel\":\"live_orders_btcusd\",\"event\":\"order_created\",\"event_id\":\"00065a1d-7fac-0bc8-0002-000102000020\",\"pre_event_id\":\"00065a1d-7fac-0bc8-0001-000101000020\",\"order_source\":\"orderbook\"}","recorded_unix_us":1787932602840705}
{"message":"{\"data\":{\"id\":2044303884861445,\"id_str\":\"2044303884861445\",\"order_type\":1,\"order_subtype\":5,\"datetime\":\"1787932603\",\"microtimestamp\":\"1787932602797000\",\"amount\":0.06310787,\"amount_str\":\"0.06310787\",\"amount_traded\":\"0\",\"amount_at_create\":\"0.06310787\",\"price\":78520.14,\"price_str\":\"78520.14\",\"is_liquidation\":false},\"channel\":\"live_orders_btcusd\",\"event\":\"order_deleted\",\"event_id\":\"00065a1d-7fac-0bc8-0003-000103000020\",\"pre_event_id\":\"00065a1d-7fac-0bc8-0002-000102000020\",\"order_source\":\"orderbook\"}","recorded_unix_us":1787932602840822}
{"message":"{\"data\":{\"id\":2044303884865544,\"id_str\":\"2044303884865544\",\"order_type\":0,\"order_subtype\":5,\"datetime\":\"1787932603\",\"microtimestamp\":\"1787932602799000\",\"amount\":0.50943342,\"amount_str\":\"0.50943342\",\"amount_traded\":\"0\",\"amount_at_create\":\"0.50943342\",\"price\":78482.12,\"price_str\":\"78482.12\",\"is_liquidation\":false},\"channel\":\"live_orders_btcusd\",\"event\":\"order_created\",\"event_id\":\"00065a1d-7fac-1398-0000-000100000020\",\"pre_event_id\":\"00065a1d-7fac-0bc8-0003-000103000020\",\"order_source\":\"orderbook\"}","recorded_unix_us":1787932602840885}
{"message":"{\"data\":{\"id\":2044303884173314,\"id_str\":\"2044303884173314\",\"order_type\":0,\"order_subtype\":5,\"datetime\":\"1787932603\",\"microtimestamp\":\"1787932602799000\",\"amount\":0.00140266,\"amount_str\":\"0.00140266\",\"amount_traded\":\"0\",\"amount_at_create\":\"0.00140266\",\"price\":70668.36,\"price_str\":\"70668.36\",\"is_liquidation\":false},\"channel\":\"live_orders_btcusd\",\"event\":\"order_deleted\",\"event_id\":\"00065a1d-7fac-1398-0001-000101000020\",\"pre_event_id\":\"00065a1d-7fac-1398-0000-000100000020\",\"order_source\":\"orderbook\"}","recorded_unix_us":1787932602840907}
{"message":"{\"data\":{\"id\":2044303884468224,\"id_str\":\"2044303884468224\",\"order_type\":1,\"order_subtype\":5,\"datetime\":\"1787932603\",\"microtimestamp\":\"1787932602801000\",\"amount\":5,\"amount_str\":\"5.000000\",\"amount_traded\":\"0\",\"amount_at_create\":\"5.000000\",\"price\":2481.63,\"price_str\":\"2481.63\",\"is_liquidation\":false},\"channel\":\"live_orders_ethusd\",\"event\":\"order_deleted\",\"event_id\":\"00065a1d-7fac-1b68-0000-001201000020\",\"pre_event_id\":\"00065a1d-7fac-0010-0000-001200000020\",\"order_source\":\"orderbook\"}","recorded_unix_us":1787932602863198}
{"message":"{\"data\":{\"id\":2044303884042241,\"id_str\":\"2044303884042241\",\"order_type\":0,\"order_subtype\":5,\"datetime\":\"1787932603\",\"microtimestamp\":\"1787932602807000\",\"amount\":12.095621,\"amount_str\":\"12.095621\",\"amount_traded\":\"0\",\"amount_at_create\":\"12.095621\",\"price\":2480.23,\"price_str\":\"2480.23\",\"is_liquidation\":false},\"channel\":\"live_orders_ethusd\",\"event\":\"order_deleted\",\"event_id\":\"00065a1d-7fac-32d8-0000-001202000020\",\"pre_event_id\":\"00065a1d-7fac-1b68-0000-001201000020\",\"order_source\":\"orderbook\"}","recorded_unix_us":1787932602863605}
{"message":"{\"data\":{\"id\":2044303884050432,\"id_str\":\"2044303884050432\",\"order_type\":0,\"order_subtype\":5,\"datetime\":\"1787932603\",\"microtimestamp\":\"1787932602808000\",\"amount\":12.096984,\"amount_str\":\"12.096984\",\"amount_traded\":\"0\",\"amount_at_create\":\"12.096984\",\"price\":2479.95,\"price_str\":\"2479.95\",\"is_liquidation\":false},\"channel\":\"live_orders_ethusd\",\"event\":\"order_deleted\",\"event_id\":\"00065a1d-7fac-36c0-0000-001203000020\",\"pre_event_id\":\"00065a1d-7fac-32d8-0000-001202000020\",\"order_source\":\"orderbook\"}","recorded_unix_us":1787932602863674}
{"message":"{\"data\":{\"id\":2044303884050433,\"id_str\":\"2044303884050433\",\"order_type\":0,\"order_subtype\":5,\"datetime\":\"1787932603\",\"microtimestamp\":\"1787932602808000\",\"amount\":4.032745,\"amount_str\":\"4.032745\",\"amount_traded\":\"0\",\"amount_at_create\":\"4.032745\",\"price\":2479.7,\"price_str\":\"2479.70\",\"is_liquidation\":false},\"channel\":\"live_orders_ethusd\",\"event\":\"order_deleted\",\"event_id\":\"00065a1d-7fac-36c0-0001-001200000020\",\"pre_event_id\":\"00065a1d-7fac-36c0-0000-001203000020\",\"order_source\":\"orderbook\"}","recorded_unix_us":1787932602863746}
{"message":"{\"data\":{\"id\":2044303884066817,\"id_str\":\"2044303884066817\",\"order_type\":0,\"order_subtype\":5,\"datetime\":\"1787932603\",\"microtimestamp\":\"1787932602808000\",\"amount\":4.033601,\"amount_str\":\"4.033601\",\"amount_traded\":\"0\",\"amount_at_create\":\"4.033601\",\"price\":2479.17,\"price_str\":\"2479.17\",\"is_liquidation\":false},\"channel\":\"live_orders_ethusd\",\"event\":\"order_deleted\",\"event_id\":\"00065a1d-7fac-36c0-0002-001201000020\",\"pre_event_id\":\"00065a1d-7fac-36c0-0001-001200000020\",\"order_source\":\"orderbook\"}","recorded_unix_us":1787932602863860}
{"message":"{\"data\":{\"id\":2044303884079105,\"id_str\":\"2044303884079105\",\"order_type\":0,\"order_subtype\":5,\"datetime\":\"1787932603\",\"microtimestamp\":\"1787932602809000\",\"amount\":10.090138,\"amount_str\":\"10.090138\",\"amount_traded\":\"0\",\"amount_at_create\":\"10.090138\",\"price\":2477.66,\"price_str\":\"2477.66\",\"is_liquidation\":false},\"channel\":\"live_orders_ethusd\",\"event\":\"order_deleted\",\"event_id\":\"00065a1d-7fac-3aa8-0000-001202000020\",\"pre_event_id\":\"00065a1d-7fac-36c0-0002-001201000020\",\"order_source\":\"orderbook\"}","recorded_unix_us":1787932602863963}
{"message":"{\"data\":{\"id\":2044303884091394,\"id_str\":\"2044303884091394\",\"order_type\":0,\"order_subtype\":5,\"datetime\":\"1787932603\",\"microtimestamp\":\"1787932602809000\",\"amount\":10.095101,\"amount_str\":\"10.095101\",\"amount_traded\":\"0\",\"amount_at_create\":\"10.095101\",\"price\":2476.44,\"price_str\":\"2476.44\",\"is_liquidation\":false},\"channel\":\"live_orders_ethusd\",\"event\":\"order_deleted\",\"event_id\":\"00065a1d-7fac-3aa8-0001-001203000020\",\"pre_event_id\":\"00065a1d-7fac-3aa8-0000-001202000020\",\"order_source\":\"orderbook\"}","recorded_unix_us":1787932602989967}
{"message":"{\"data\":{\"id\":2044303884095493,\"id_str\":\"2044303884095493\",\"order_type\":0,\"order_subtype\":5,\"datetime\":\"1787932603\",\"microtimestamp\":\"1787932602809000\",\"amount\":20.204386,\"amount_str\":\"20.204386\",\"amount_traded\":\"0\",\"amount_at_create\":\"20.204386\",\"price\":2474.71,\"price_str\":\"2474.71\",\"is_liquidation\":false},\"channel\":\"live_orders_ethusd\",\"event\":\"order_deleted\",\"event_id\":\"00065a1d-7fac-3aa8-0002-001200000020\",\"pre_event_id\":\"00065a1d-7fac-3aa8-0001-001203000020\",\"order_source\":\"orderbook\"}","recorded_unix_us":1787932602990119}
{"message":"{\"data\":{\"id\":2044303884099584,\"id_str\":\"2044303884099584\",\"order_type\":0,\"order_subtype\":5,\"datetime\":\"1787932603\",\"microtimestamp\":\"1787932602810000\",\"amount\":40.528033,\"amount_str\":\"40.528033\",\"amount_traded\":\"0\",\"amount_at_create\":\"40.528033\",\"price\":2467.42,\"price_str\":\"2467.42\",\"is_liquidation\":false},\"channel\":\"live_orders_ethusd\",\"event\":\"order_deleted\",\"event_id\":\"00065a1d-7fac-3e90-0000-001201000020\",\"pre_event_id\":\"00065a1d-7fac-3aa8-0002-001200000020\",\"order_source\":\"orderbook\"}","recorded_unix_us":1787932602990159}
{"message":"{\"data\":{\"id\":2044303884099585,\"id_str\":\"2044303884099585\",\"order_type\":0,\"order_subtype\":5,\"datetime\":\"1787932603\",\"microtimestamp\":\"1787932602810000\",\"amount\":40.650432,\"amount_str\":\"40.650432\",\"amount_traded\":\"0\",\"amount_at_create\":\"40.650432\",\"price\":2459.99,\"price_str\":\"2459.99\",\"is_liquidation\":false},\"channel\":\"live_orders_ethusd\",\"event\":\"order_deleted\",\"event_id\":\"00065a1d-7fac-3e90-0001-001202000020\",\"pre_event_id\":\"00065a1d-7fac-3e90-0000-001201000020\",\"order_source\":\"orderbook\"}","recorded_unix_us":1787932602990219}
{"message":"{\"data\":{\"id\":2044303884173315,\"id_str\":\"2044303884173315\",\"order_type\":1,\"order_subtype\":5,\"datetime\":\"1787932603\",\"microtimestamp\":\"1787932602810000\",\"amount\":4.028003,\"amount_str\":\"4.028003\",\"amount_traded\":\"0\",\"amount_at_create\":\"4.028003\",\"price\":2482.62,\"price_str\":\"2482.62\",\"is_liquidation\":false},\"channel\":\"live_orders_ethusd\",\"event\":\"order_deleted\",\"event_id\":\"00065a1d-7fac-3e90-0002-001203000020\",\"pre_event_id\":\"00065a1d-7fac-3e90-0001-001202000020\",\"order_source\":\"orderbook\"}","recorded_unix_us":1787932602990260}
{"message":"{\"data\":{\"id\":2044303884189696,\"id_str\":\"2044303884189696\",\"order_type\":0,\"order_subtype\":5,\"datetime\":\"1787932603\",\"microtimestamp\":\"1787932602811000\",\"amount\":20.215084,\"amount_str\":\"20.215084\",\"amount_traded\":\"0\",\"amount_at_create\":\"20.215084\",\"price\":2473.4,\"price_str\":\"2473.40\",\"is_liquidation\":false},\"channel\":\"live_orders_ethusd\",\"event\":\"order_deleted\",\"event_id\":\"00065a1d-7fac-4278-0000-001200000020\",\"pre_event_id\":\"00065a1d-7fac-3e90-0002-001203000020\",\"order_source\":\"orderbook\"}","recorded_unix_us":1787932602990293}
{"message":"{\"data\":{\"id\":2044303884189698,\"id_str\":\"2044303884189698\",\"order_type\":1,\"order_subtype\":5,\"datetime\":\"1787932603\",\"microtimestamp\":\"1787932602811000\",\"amount\":10.062547,\"amount_str\":\"10.062547\",\"amount_traded\":\"0\",\"amount_at_create\":\"10.062547\",\"price\":2484.47,\"price_str\":\"2484.47\",\"is_liquidation\":false},\"channel\":\"live_orders_ethusd\",\"event\":\"order_deleted\",\"event_id\":\"00065a1d-7fac-4278-0001-001201000020\",\"pre_event_id\":\"00065a1d-7fac-4278-0000-001200000020\",\"order_source\":\"orderbook\"}","recorded_unix_us":1787932602990585}
{"message":"{\"data\":{\"id\":2044303884189700,\"id_str\":\"2044303884189700\",\"order_type\":1,\"order_subtype\":5,\"datetime\":\"1787932603\",\"microtimestamp\":\"1787932602811000\",\"amount\":40.051178,\"amount_str\":\"40.051178\",\"amount_traded\":\"0\",\"amount_at_create\":\"40.051178\",\"price\":2496.81,\"price_str\":\"2496.81\",\"is_liquidation\":false},\"channel\":\"live_orders_ethusd\",\"event\":\"order_deleted\",\"event_id\":\"00065a1d-7fac-4278-0002-001202000020\",\"pre_event_id\":\"00065a1d-7fac-4278-0001-001201000020\",\"order_source\":\"orderbook\"}","recorded_unix_us":1787932602990652}
{"message":"{\"data\":{\"id\":2044303884189702,\"id_str\":\"2044303884189702\",\"order_type\":1,\"order_subtype\":5,\"datetime\":\"1787932603\",\"microtimestamp\":\"1787932602812000\",\"amount\":20.077182,\"amount_str\":\"20.077182\",\"amount_traded\":\"0\",\"amount_at_create\":\"20.077182\",\"price\":2490.39,\"price_str\":\"2490.39\",\"is_liquidation\":false},\"channel\":\"live_orders_ethusd\",\"event\":\"order_deleted\",\"event_id\":\"00065a1d-7fac-4660-0000-001203000020\",\"pre_event_id\":\"00065a1d-7fac-4278-0002-001202000020\",\"order_source\":\"orderbook\"}","recorded_unix_us":1787932602990687}
{"message":"{\"data\":{\"id\":2044303884189703,\"id_str\":\"2044303884189703\",\"order_type\":0,\"order_subtype\":5,\"datetime\":\"1787932603\",\"microtimestamp\":\"1787932602812000\",\"amount\":4.033204,\"amount_str\":\"4.033204\",\"amount_traded\":\"0\",\"amount_at_create\":\"4.033204\",\"price\":2479.41,\"price_str\":\"2479.41\",\"is_liquidation\":false},\"channel\":\"live_orders_ethusd\",\"event\":\"order_deleted\",\"event_id\":\"00065a1d-7fac-4660-0001-001200000020\",\"pre_event_id\":\"00065a1d-7fac-4660-0000-001203000020\",\"order_source\":\"orderbook\"}","recorded_unix_us":1787932602990897}
{"message":"{\"data\":{\"id\":2044303884193792,\"id_str\":\"2044303884193792\",\"order_type\":0,\"order_subtype\":5,\"datetime\":\"1787932603\",\"microtimestamp\":\"1787932602812000\",\"amount\":10.092689,\"amount_str\":\"10.092689\",\"amount_traded\":\"0\",\"amount_at_create\":\"10.092689\",\"price\":2477.04,\"price_str\":\"2477.04\",\"is_liquidation\":false},\"channel\":\"live_orders_ethusd\",\"event\":\"order_deleted\",\"event_id\":\"00065a1d-7fac-4660-0002-001201000020\",\"pre_event_id\":\"00065a1d-7fac-4660-0001-001200000020\",\"order_source\":\"orderbook\"}","recorded_unix_us":1787932602990951}
{"message":"{\"data\":{\"id\":2044303884193795,\"id_str\":\"2044303884193795\",\"order_type\":0,\"order_subtype\":5,\"datetime\":\"1787932603\",\"microtimestamp\":\"1787932602813000\",\"amount\":4.034022,\"amount_str\":\"4.034022\",\"amount_traded\":\"0\",\"amount_at_create\":\"4.034022\",\"price\":2478.91,\"price_str\":\"2478.91\",\"is_liquidation\":false},\"channel\":\"live_orders_ethusd\",\"event\":\"order_deleted\",\"event_id\":\"00065a1d-7fac-4a48-0000-001202000020\",\"pre_event_id\":\"00065a1d-7fac-4660-0002-001201000020\",\"order_source\":\"orderbook\"}","recorded_unix_us":1787932602990987}
{"message":"{\"data\":{\"id\":2044303884193801,\"id_str\":\"2044303884193801\",\"order_type\":0,\"order_subtype\":5,\"datetime\":\"1787932603\",\"microtimestamp\":\"1787932602813000\",\"amount\":10.097738,\"amount_str\":\"10.097738\",\"amount_traded\":\"0\",\"amount_at_create\":\"10.097738\",\"price\":2475.8,\"price_str\":\"2475.80\",\"is_liquidation\":false},\"channel\":\"live_orders_ethusd\",\"event\":\"order_deleted\",\"event_id\":\"00065a1d-7fac-4a48-0001-001203000020\",\"pre_event_id\":\"00065a1d-7fac-4a48-0000-001202000020\",\"order_source\":\"orderbook\"}","recorded_unix_us":1787932602991178}
{"message":"{\"data\":{\"id\":2044303884201985,\"id_str\":\"2044303884201985\",\"order_type\":0,\"order_subtype\":5,\"datetime\":\"1787932603\",\"microtimestamp\":\"1787932602813000\",\"amount\":40.568517,\"amount_str\":\"40.568517\",\"amount_traded\":\"0\",\"amount_at_create\":\"40.568517\",\"price\":2464.96,\"price_str\":\"2464.96\",\"is_liquidation\":false},\"channel\":\"live_orders_ethusd\",\"event\":\"order_deleted\",\"event_id\":\"00065a1d-7fac-4a48-0002-001200000020\",\"pre_event_id\":\"00065a1d-7fac-4a48-0001-001203000020\",\"order_source\":\"orderbook\"}","recorded_unix_us":1787932602991234}
{"message":"{\"data\":{\"id\":2044303884279808,\"id_str\":\"2044303884279808\",\"order_type\":1,\"order_subtype\":5,\"datetime\":\"1787932603\",\"microtimestamp\":\"1787932602813000\",\"amount\":10.059779,\"amount_str\":\"10.059779\",\"amount_traded\":\"0\",\"amount_at_create\":\"10.059779\",\"price\":2485.15,\"price_str\":\"2485.15\",\"is_liquidation\":false},\"channel\":\"live_orders_ethusd\",\"event\":\"order_deleted\",\"event_id\":\"00065a1d-7fac-4a48-0003-001201000020\",\"pre_event_id\":\"00065a1d-7fac-4a48-0002-001200000020\",\"order_source\":\"orderbook\"}","recorded_unix_us":1787932602991270}
{"message":"{\"data\":{\"id\":2044303884283904,\"id_str\":\"2044303884283904\",\"order_type\":1,\"order_subtype\":5,\"datetime\":\"1787932603\",\"microtimestamp\":\"1787932602814000\",\"amount\":4.027586,\"amount_str\":\"4.027586\",\"amount_traded\":\"0\",\"amount_at_create\":\"4.027586\",\"price\":2482.88,\"price_str\":\"2482.88\",\"is_liquidation\":false},\"channel\":\"live_orders_ethusd\",\"event\":\"order_deleted\",\"event_id\":\"00065a1d-7fac-4e30-0000-001202000020\",\"pre_event_id\":\"00065a1d-7fac-4a48-0003-001201000020\",\"order_source\":\"orderbook\"}","recorded_unix_us":1787932602991437}
{"message":"{\"data\":{\"id\":2044303884283905,\"id_str\":\"2044303884283905\",\"order_type\":0,\"order_subtype\":5,\"datetime\":\"1787932603\",\"microtimestamp\":\"1787932602814000\",\"amount\":20.225289,\"amount_str\":\"20.225289\",\"amount_traded\":\"0\",\"amount_at_create\":\"20.225289\",\"price\":2472.15,\"price_str\":\"2472.15\",\"is_liquidation\":false},\"channel\":\"live_orders_ethusd\",\"event\":\"order_deleted\",\"event_id\":\"00065a1d-7fac-4e30-0001-001203000020\",\"pre_event_id\":\"00065a1d-7fac-4e30-0000-001202000020\",\"order_source\":\"orderbook\"}","recorded_unix_us":1787932602991477}
{"message":"{\"data\":{\"id\":2044303884288000,\"id_str\":\"2044303884288000\",\"order_type\":1,\"order_subtype\":5,\"datetime\":\"1787932603\",\"microtimestamp\":\"1787932602814000\",\"amount\":40.010118,\"amount_str\":\"40.010118\",\"amount_traded\":\"0\",\"amount_at_create\":\"40.010118\",\"price\":2499.37,\"price_str\":\"2499.37\",\"is_liquidation\":false},\"channel\":\"live_orders_ethusd\",\"event\":\"order_deleted\",\"event_id\":\"00065a1d-7fac-4e30-0002-001200000020\",\"pre_event_id\":\"00065a1d-7fac-4e30-0001-001203000020\",\"order_source\":\"orderbook\"}","recorded_unix_us":1787932602991587}
{"message":"{\"data\":{\"id\":2044303884292097,\"id_str\":\"2044303884292097\",\"order_type\":1,\"order_subtype\":5,\"datetime\":\"1787932603\",\"microtimestamp\":\"1787932602815000\",\"amount\":20.063885,\"amount_str\":\"20.063885\",\"amount_traded\":\"0\",\"amount_at_create\":\"20.063885\",\"price\":2492.04,\"price_str\":\"2492.04\",\"is_liquidation\":false},\"channel\":\"live_orders_ethusd\",\"event\":\"order_deleted\",\"event_id\":\"00065a1d-7fac-5218-0000-001201000020\",\"pre_event_id\":\"00065a1d-7fac-4e30-0002-001200000020\",\"order_source\":\"orderbook\"}","recorded_unix_us":1787932602991738}
{"message":"{\"data\":{\"id\":2044303884292101,\"id_str\":\"2044303884292101\",\"order_type\":0,\"order_subtype\":5,\"datetime\":\"1787932603\",\"microtimestamp\":\"1787932602815000\",\"amount\":40.609081,\"amount_str\":\"40.609081\",\"amount_traded\":\"0\",\"amount_at_create\":\"40.609081\",\"price\":2462.5,\"price_str\":\"2462.50\",\"is_liquidation\":false},\"channel\":\"live_orders_ethusd\",\"event\":\"order_deleted\",\"event_id\":\"00065a1d-7fac-5218-0001-001202000020\",\"pre_event_id\":\"00065a1d-7fac-5218-0000-001201000020\",\"order_source\":\"orderbook\"}","recorded_unix_us":1787932602991775}
{"message":"{\"data\":{\"id\":2044303884935174,\"id_str\":\"2044303884935174\",\"order_type\":0,\"order_subtype\":5,\"datetime\":\"1787932603\",\"microtimestamp\":\"1787932602815000\",\"amount\":6,\"amount_str\":\"6.000000\",\"amount_traded\":\"0\",\"amount_at_create\":\"6.000000\",\"price\":2479.07,\"price_str\":\"2479.07\",\"is_liquidation\":false},\"channel\":\"live_orders_ethusd\",\"event\":\"order_created\",\"event_id\":\"00065a1d-7fac-5218-0002-001203000020\",\"pre_event_id\":\"00065a1d-7fac-5218-0001-001202000020\",\"order_source\":\"orderbook\"}","recorded_unix_us":1787932602991927}
{"message":"{\"data\":{\"id\":2044303884357634,\"id_str\":\"2044303884357634\",\"order_type\":0,\"order_subtype\":5,\"datetime\":\"1787932603\",\"microtimestamp\":\"1787932602815000\",\"amount\":20.235437,\"amount_str\":\"20.235437\",\"amount_traded\":\"0\",\"amount_at_create\":\"20.235437\",\"price\":2470.91,\"price_str\":\"2470.91\",\"is_liquidation\":false},\"channel\":\"live_orders_ethusd\",\"event\":\"order_deleted\",\"event_id\":\"00065a1d-7fac-5218-0003-001200000020\",\"pre_event_id\":\"00065a1d-7fac-5218-0002-001203000020\",\"order_source\":\"orderbook\"}","recorded_unix_us":1787932602991966}
{"message":"{\"data\":{\"id\":2044303884984323,\"id_str\":\"2044303884984323\",\"order_type\":1,\"order_subtype\":5,\"datetime\":\"1787932603\",\"microtimestamp\":\"1787932602827000\",\"amount\":0.1,\"amount_str\":\"0.10000000\",\"amount_traded\":\"0\",\"amount_at_create\":\"0.10000000\",\"price\":78522.63,\"price_str\":\"78522.63\",\"is_liquidation\":false},\"channel\":\"live_orders_btcusd\",\"event\":\"order_created\",\"event_id\":\"00065a1d-7fac-80f8-0000-000102000020\",\"pre_event_id\":\"00065a1d-7fac-1398-0001-000101000020\",\"order_source\":\"orderbook\"}","recorded_unix_us":1787932602992116}
{"message":"{\"data\":{\"id\":2044303884984323,\"id_str\":\"2044303884984323\",\"order_type\":1,\"order_subtype\":5,\"datetime\":\"1787932603\",\"microtimestamp\":\"1787932602827000\",\"amount\":0.1,\"amount_str\":\"0.10000000\",\"amount_traded\":\"0\",\"amount_at_create\":\"0.10000000\",\"price\":78522.63,\"price_str\":\"78522.63\",\"is_liquidation\":false},\"channel\":\"live_orders_btcusd\",\"event\":\"order_deleted\",\"event_id\":\"00065a1d-7fac-80f8-0001-000103000020\",\"pre_event_id\":\"00065a1d-7fac-80f8-0000-000102000020\",\"order_source\":\"orderbook\"}","recorded_unix_us":1787932602992150}
{"message":"{\"data\":{\"id\":2044303884992515,\"id_str\":\"2044303884992515\",\"order_type\":1,\"order_subtype\":5,\"datetime\":\"1787932603\",\"microtimestamp\":\"1787932602829000\",\"amount\":0.06310787,\"amount_str\":\"0.06310787\",\"amount_traded\":\"0\",\"amount_at_create\":\"0.06310787\",\"price\":78522.5,\"price_str\":\"78522.50\",\"is_liquidation\":false},\"channel\":\"live_orders_btcusd\",\"event\":\"order_created\",\"event_id\":\"00065a1d-7fac-88c8-0000-000100000020\",\"pre_event_id\":\"00065a1d-7fac-80f8-0001-000103000020\",\"order_source\":\"orderbook\"}","recorded_unix_us":1787932602992250}
{"message":"{\"data\":{\"id\":2044303884992515,\"id_str\":\"2044303884992515\",\"order_type\":1,\"order_subtype\":5,\"datetime\":\"1787932603\",\"microtimestamp\":\"1787932602829000\",\"amount\":0.06310787,\"amount_str\":\"0.06310787\",\"amount_traded\":\"0\",\"amount_at_create\":\"0.06310787\",\"price\":78522.5,\"price_str\":\"78522.50\",\"is_liquidation\":false},\"channel\":\"live_orders_btcusd\",\"event\":\"order_deleted\",\"event_id\":\"00065a1d-7fac-88c8-0001-000101000020\",\"pre_event_id\":\"00065a1d-7fac-88c8-0000-000100000020\",\"order_source\":\"orderbook\"}","recorded_unix_us":1787932602992358}
{"message":"{\"data\":{\"id\":2044303884996617,\"id_str\":\"2044303884996617\",\"order_type\":1,\"order_subtype\":5,\"datetime\":\"1787932603\",\"microtimestamp\":\"1787932602831000\",\"amount\":0.1,\"amount_str\":\"0.10000000\",\"amount_traded\":\"0\",\"amount_at_create\":\"0.10000000\",\"price\":78522.62,\"price_str\":\"78522.62\",\"is_liquidation\":false},\"channel\":\"live_orders_btcusd\",\"event\":\"order_created\",\"event_id\":\"00065a1d-7fac-9098-0000-000102000020\",\"pre_event_id\":\"00065a1d-7fac-88c8-0001-000101000020\",\"order_source\":\"orderbook\"}","recorded_unix_us":1787932602992497}
{"message":"{\"data\":{\"id\":2044303884996617,\"id_str\":\"2044303884996617\",\"order_type\":1,\"order_subtype\":5,\"datetime\":\"1787932603\",\"microtimestamp\":\"1787932602831000\",\"amount\":0.1,\"amount_str\":\"0.10000000\",\"amount_traded\":\"0\",\"amount_at_create\":\"0.10000000\",\"price\":78522.62,\"price_str\":\"78522.62\",\"is_liquidation\":false},\"channel\":\"live_orders_btcusd\",\"event\":\"order_deleted\",\"event_id\":\"00065a1d-7fac-9098-0001-000103000020\",\"pre_event_id\":\"00065a1d-7fac-9098-0000-000102000020\",\"order_source\":\"orderbook\"}","recorded_unix_us":1787932602992528}
{"message":"{\"data\":{\"id\":2044303885000705,\"id_str\":\"2044303885000705\",\"order_type\":1,\"order_subtype\":5,\"datetime\":\"1787932603\",\"microtimestamp\":\"1787932602831000\",\"amount\":12.087822,\"amount_str\":\"12.087822\",\"amount_traded\":\"0\",\"amount_at_create\":\"12.087822\",\"price\":2481.84,\"price_str\":\"2481.84\",\"is_liquidation\":false},\"channel\":\"live_orders_ethusd\",\"event\":\"order_created\",\"event_id\":\"00065a1d-7fac-9098-0000-001201000020\",\"pre_event_id\":\"00065a1d-7fac-5218-0003-001200000020\",\"order_source\":\"orderbook\"}","recorded_unix_us":1787932602992619}
{"message":"{\"data\":{\"id\":2044303885045769,\"id_str\":\"2044303885045769\",\"order_type\":1,\"order_subtype\":5,\"datetime\":\"1787932603\",\"microtimestamp\":\"1787932602843000\",\"amount\":5,\"amount_str\":\"5.000000\",\"amount_traded\":\"0\",\"amount_at_create\":\"5.000000\",\"price\":2481.72,\"price_str\":\"2481.72\",\"is_liquidation\":false},\"channel\":\"live_orders_ethusd\",\"event\":\"order_created\",\"event_id\":\"00065a1d-7fac-bf78-0000-001202000020\",\"pre_event_id\":\"00065a1d-7fac-9098-0000-001201000020\",\"order_source\":\"orderbook\"}","recorded_unix_us":1787932602992709}
{"message":"{\"data\":{\"id\":2044303885049861,\"id_str\":\"2044303885049861\",\"order_type\":1,\"order_subtype\":5,\"datetime\":\"1787932603\",\"microtimestamp\":\"1787932602844000\",\"amount\":1,\"amount_str\":\"1.000000\",\"amount_traded\":\"0\",\"amount_at_create\":\"1.000000\",\"price\":2482.72,\"price_str\":\"2482.72\",\"is_liquidation\":false},\"channel\":\"live_orders_ethusd\",\"event\":\"order_created\",\"event_id\":\"00065a1d-7fac-c360-0000-001203000020\",\"pre_event_id\":\"00065a1d-7fac-bf78-0000-001202000020\",\"order_source\":\"orderbook\"}","recorded_unix_us":1787932602992796}
{"message":"{\"data\":{\"id\":2044303885062150,\"id_str\":\"2044303885062150\",\"order_type\":1,\"order_subtype\":5,\"datetime\":\"1787932603\",\"microtimestamp\":\"1787932602846000\",\"amount\":5,\"amount_str\":\"5.000000\",\"amount_traded\":\"0\",\"amount_at_create\":\"5.000000\",\"price\":2481.97,\"price_str\":\"2481.97\",\"is_liquidation\":false},\"channel\":\"live_orders_ethusd\",\"event\":\"order_created\",\"event_id\":\"00065a1d-7fac-cb30-0000-001200000020\",\"pre_event_id\":\"00065a1d-7fac-c360-0000-001203000020\",\"order_source\":\"orderbook\"}","recorded_unix_us":1787932602992882}
{"message":"{\"data\":{\"id\":2044303885070339,\"id_str\":\"2044303885070339\",\"order_type\":1,\"order_subtype\":5,\"datetime\":\"1787932603\",\"microtimestamp\":\"1787932602848000\",\"amount\":4.028412,\"amount_str\":\"4.028412\",\"amount_traded\":\"0\",\"amount_at_create\":\"4.028412\",\"price\":2482.37,\"price_str\":\"2482.37\",\"is_liquidation\":false},\"channel\":\"live_orders_ethusd\",\"event\":\"order_created\",\"event_id\":\"00065a1d-7fac-d300-0000-001201000020\",\"pre_event_id\":\"00065a1d-7fac-cb30-0000-001200000020\",\"order_source\":\"orderbook\"}","recorded_unix_us":1787932602993033}
{"message":"{\"data\":{\"id\":2044303885070340,\"id_str\":\"2044303885070340\",\"order_type\":1,\"order_subtype\":5,\"datetime\":\"1787932603\",\"microtimestamp\":\"1787932602848000\",\"amount\":12.086444,\"amount_str\":\"12.086444\",\"amount_traded\":\"0\",\"amount_at_create\":\"12.086444\",\"price\":2482.12,\"price_str\":\"2482.12\",\"is_liquidation\":false},\"channel\":\"live_orders_ethusd\",\"event\":\"order_created\",\"event_id\":\"00065a1d-7fac-d300-0001-001202000020\",\"pre_event_id\":\"00065a1d-7fac-d300-0000-001201000020\",\"order_source\":\"orderbook\"}","recorded_unix_us":1787932602993063}
{"message":"{\"data\":{\"id\":2044303885070341,\"id_str\":\"2044303885070341\",\"order_type\":1,\"order_subtype\":5,\"datetime\":\"1787932603\",\"microtimestamp\":\"1787932602848000\",\"amount\":10.06507,\"amount_str\":\"10.065070\",\"amount_traded\":\"0\",\"amount_at_create\":\"10.065070\",\"price\":2483.84,\"price_str\":\"2483.84\",\"is_liquidation\":false},\"channel\":\"live_orders_ethusd\",\"event\":\"order_created\",\"event_id\":\"00065a1d-7fac-d300-0002-001203000020\",\"pre_event_id\":\"00065a1d-7fac-d300-0001-001202000020\",\"order_source\":\"orderbook\"}","recorded_unix_us":1787932602993088}
{"message":"{\"data\":{\"id\":2044303885070349,\"id_str\":\"2044303885070349\",\"order_type\":1,\"order_subtype\":5,\"datetime\":\"1787932603\",\"microtimestamp\":\"1787932602849000\",\"amount\":4.027018,\"amount_str\":\"4.027018\",\"amount_traded\":\"0\",\"amount_at_create\":\"4.027018\",\"price\":2483.23,\"price_str\":\"2483.23\",\"is_liquidation\":false},\"channel\":\"live_orders_ethusd\",\"event\":\"order_created\",\"event_id\":\"00065a1d-7fac-d6e8-0000-001200000020\",\"pre_event_id\":\"00065a1d-7fac-d300-0002-001203000020\",\"order_source\":\"orderbook\"}","recorded_unix_us":1787932602993172}
{"message":"{\"data\":{\"id\":2044303885074437,\"id_str\":\"2044303885074437\",\"order_type\":1,\"order_subtype\":5,\"datetime\":\"1787932603\",\"microtimestamp\":\"1787932602850000\",\"amount\":10.057184,\"amount_str\":\"10.057184\",\"amount_traded\":\"0\",\"amount_at_create\":\"10.057184\",\"price\":2485.79,\"price_str\":\"2485.79\",\"is_liquidation\":false},\"channel\":\"live_orders_ethusd\",\"event\":\"order_created\",\"event_id\":\"00065a1d-7fac-dad0-0000-001201000020\",\"pre_event_id\":\"00065a1d-7fac-d6e8-0000-001200000020\",\"order_source\":\"orderbook\"}","recorded_unix_us":1787932602993293}
{"message":"{\"data\":{\"id\":2044303885078531,\"id_str\":\"2044303885078531\",\"order_type\":1,\"order_subtype\":5,\"datetime\":\"1787932603\",\"microtimestamp\":\"1787932602850000\",\"amount\":20.097242,\"amount_str\":\"20.097242\",\"amount_traded\":\"0\",\"amount_at_create\":\"20.097242\",\"price\":2487.91,\"price_str\":\"2487.91\",\"is_liquidation\":false},\"channel\":\"live_orders_ethusd\",\"event\":\"order_created\",\"event_id\":\"00065a1d-7fac-dad0-0001-001202000020\",\"pre_event_id\":\"00065a1d-7fac-dad0-0000-001201000020\",\"order_source\":\"orderbook\"}","recorded_unix_us":1787932602993324}
{"message":"{\"data\":{\"id\":2044303885082627,\"id_str\":\"2044303885082627\",\"order_type\":1,\"order_subtype\":5,\"datetime\":\"1787932603\",\"microtimestamp\":\"1787932602851000\",\"amount\":40.09205,\"amount_str\":\"40.092050\",\"amount_traded\":\"0\",\"amount_at_create\":\"40.092050\",\"price\":2494.27,\"price_str\":\"2494.27\",\"is_liquidation\":false},\"channel\":\"live_orders_ethusd\",\"event\":\"order_created\",\"event_id\":\"00065a1d-7fac-deb8-0000-001203000020\",\"pre_event_id\":\"00065a1d-7fac-dad0-0001-001202000020\",\"order_source\":\"orderbook\"}","recorded_unix_us":1787932602993407}
{"message":"{\"data\":{\"id\":2044303885082633,\"id_str\":\"2044303885082633\",\"order_type\":1,\"order_subtype\":5,\"datetime\":\"1787932603\",\"microtimestamp\":\"1787932602852000\",\"amount\":39.969006,\"amount_str\":\"39.969006\",\"amount_traded\":\"0\",\"amount_at_create\":\"39.969006\",\"price\":2501.94,\"price_str\":\"2501.94\",\"is_liquidation\":false},\"channel\":\"live_orders_ethusd\",\"event\":\"order_created\",\"event_id\":\"00065a1d-7fac-e2a0-0000-001200000020\",\"pre_event_id\":\"00065a1d-7fac-deb8-0000-001203000020\",\"order_source\":\"orderbook\"}","recorded_unix_us":1787932602993601}
{"message":"{\"data\":{\"id\":2044303885086723,\"id_str\":\"2044303885086723\",\"order_type\":1,\"order_subtype\":5,\"datetime\":\"1787932603\",\"microtimestamp\":\"1787932602852000\",\"amount\":20.088574,\"amount_str\":\"20.088574\",\"amount_traded\":\"0\",\"amount_at_create\":\"20.088574\",\"price\":2488.98,\"price_str\":\"2488.98\",\"is_liquidation\":false},\"channel\":\"live_orders_ethusd\",\"event\":\"order_created\",\"event_id\":\"00065a1d-7fac-e2a0-0001-001201000020\",\"pre_event_id\":\"00065a1d-7fac-e2a0-0000-001200000020\",\"order_source\":\"orderbook\"}","recorded_unix_us":1787932602993631}
{"message":"{\"data\":{\"id\":2044303885144073,\"id_str\":\"2044303885144073\",\"order_type\":0,\"order_subtype\":5,\"datetime\":\"1787932603\",\"microtimestamp\":\"1787932602866000\",\"amount\":0.00140266,\"amount_str\":\"0.00140266\",\"amount_traded\":\"0\",\"amount_at_create\":\"0.00140266\",\"price\":70668.36,\"price_str\":\"70668.36\",\"is_liquidation\":false},\"channel\":\"live_orders_btcusd\",\"event\":\"order_created\",\"event_id\":\"00065a1d-7fad-1950-0000-000100000020\",\"pre_event_id\":\"00065a1d-7fac-9098-0001-000103000020\",\"order_source\":\"orderbook\"}","recorded_unix_us":1787932603026770}
{"message":"{\"data\":{\"id\":2044303884611584,\"id_str\":\"2044303884611584\",\"order_type\":0,\"order_subtype\":5,\"datetime\":\"1787932603\",\"microtimestamp\":\"1787932602872000\",\"amount\":0.535391,\"amount_str\":\"0.535391\",\"amount_traded\":\"0\",\"amount_at_create\":\"0.535391\",\"price\":2480.17,\"price_str\":\"2480.17\",\"is_liquidation\":false},\"channel\":\"live_orders_ethusd\",\"event\":\"order_deleted\",\"event_id\":\"00065a1d-7fad-30c0-0000-001202000020\",\"pre_event_id\":\"00065a1d-7fac-e2a0-0001-001201000020\",\"order_source\":\"orderbook\"}","recorded_unix_us":1787932603027153}
{"message":"{\"data\":{\"id\":2044303885185034,\"id_str\":\"2044303885185034\",\"order_type\":1,\"order_subtype\":5,\"datetime\":\"1787932603\",\"microtimestamp\":\"1787932602877000\",\"amount\":0.06310787,\"amount_str\":\"0.06310787\",\"amount_traded\":\"0\",\"amount_at_create\":\"0.06310787\",\"price\":78520.14,\"price_str\":\"78520.14\",\"is_liquidation\":false},\"channel\":\"live_orders_btcusd\",\"event\":\"order_created\",\"event_id\":\"00065a1d-7fad-4448-0000-000101000020\",\"pre_event_id\":\"00065a1d-7fad-1950-0000-000100000020\",\"order_source\":\"orderbook\"}","recorded_unix_us":1787932603027216}
{"message":"{\"data\":{\"id\":2044303885185034,\"id_str\":\"2044303885185034\",\"order_type\":1,\"order_subtype\":5,\"datetime\":\"1787932603\",\"microtimestamp\":\"1787932602877000\",\"amount\":0.06310787,\"amount_str\":\"0.06310787\",\"amount_traded\":\"0\",\"amount_at_create\":\"0.06310787\",\"price\":78520.14,\"price_str\":\"78520.14\",\"is_liquidation\":false},\"channel\":\"live_orders_btcusd\",\"event\":\"order_deleted\",\"event_id\":\"00065a1d-7fad-4448-0001-000102000020\",\"pre_event_id\":\"00065a1d-7fad-4448-0000-000101000020\",\"order_source\":\"orderbook\"}","recorded_unix_us":1787932603027322}
{"message":"{\"data\":{\"id\":2044303885185035,\"id_str\":\"2044303885185035\",\"order_type\":1,\"order_subtype\":5,\"datetime\":\"1787932603\",\"microtimestamp\":\"1787932602877000\",\"amount\":0.06310787,\"amount_str\":\"0.06310787\",\"amount_traded\":\"0\",\"amount_at_create\":\"0.06310787\",\"price\":78522.5,\"price_str\":\"78522.50\",\"is_liquidation\":false},\"channel\":\"live_orders_btcusd\",\"event\":\"order_created\",\"event_id\":\"00065a1d-7fad-4448-0002-000103000020\",\"pre_event_id\":\"00065a1d-7fad-4448-0001-000102000020\",\"order_source\":\"orderbook\"}","recorded_unix_us":1787932603027374}
{"message":"{\"data\":{\"id\":2044303885185035,\"id_str\":\"2044303885185035\",\"order_type\":1,\"order_subtype\":5,\"datetime\":\"1787932603\",\"microtimestamp\":\"1787932602877000\",\"amount\":0.06310787,\"amount_str\":\"0.06310787\",\"amount_traded\":\"0\",\"amount_at_create\":\"0.06310787\",\"price\":78522.5,\"price_str\":\"78522.50\",\"is_liquidation\":false},\"channel\":\"live_orders_btcusd\",\"event\":\"order_deleted\",\"event_id\":\"00065a1d-7fad-4448-0003-000100000020\",\"pre_event_id\":\"00065a1d-7fad-4448-0002-000103000020\",\"order_source\":\"orderbook\"}","recorded_unix_us":1787932603027480}
{"message":"{\"data\":{\"id\":2044303885193222,\"id_str\":\"2044303885193222\",\"order_type\":1,\"order_subtype\":5,\"datetime\":\"1787932603\",\"microtimestamp\":\"1787932602878000\",\"amount\":0.1,\"amount_str\":\"0.10000000\",\"amount_traded\":\"0\",\"amount_at_create\":\"0.10000000\",\"price\":78522.62,\"price_str\":\"78522.62\",\"is_liquidation\":false},\"channel\":\"live_orders_btcusd\",\"event\":\"order_created\",\"event_id\":\"00065a1d-7fad-4830-0000-000101000020\",\"pre_event_id\":\"00065a1d-7fad-4448-0003-000100000020\",\"order_source\":\"orderbook\"}","recorded_unix_us":1787932603027567}
{"message":"{\"data\":{\"id\":2044303885193222,\"id_str\":\"2044303885193222\",\"order_type\":1,\"order_subtype\":5,\"datetime\":\"1787932603\",\"microtimestamp\":\"1787932602878000\",\"amount\":0.1,\"amount_str\":\"0.10000000\",\"amount_traded\":\"0\",\"amount_at_create\":\"0.10000000\",\"price\":78522.62,\"price_str\":\"78522.62\",\"is_liquidation\":false},\"channel\":\"live_orders_btcusd\",\"event\":\"order_deleted\",\"event_id\":\"00065a1d-7fad-4830-0001-000102000020\",\"pre_event_id\":\"00065a1d-7fad-4830-0000-000101000020\",\"order_source\":\"orderbook\"}","recorded_unix_us":1787932603027649}
{"message":"{\"data\":{\"id\":2044303884492800,\"id_str\":\"2044303884492800\",\"order_type\":0,\"order_subtype\":5,\"datetime\":\"1787932603\",\"microtimestamp\":\"1787932602878000\",\"amount\":0.00140266,\"amount_str\":\"0.00140266\",\"amount_traded\":\"0\",\"amount_at_create\":\"0.00140266\",\"price\":70668.36,\"price_str\":\"70668.36\",\"is_liquidation\":false},\"channel\":\"live_orders_btcusd\",\"event\":\"order_deleted\",\"event_id\":\"00065a1d-7fad-4830-0002-000103000020\",\"pre_event_id\":\"00065a1d-7fad-4830-0001-000102000020\",\"order_source\":\"orderbook\"}","recorded_unix_us":1787932603027760}
{"message":"{\"data\":{\"id\":2044303885201413,\"id_str\":\"2044303885201413\",\"order_type\":0,\"order_subtype\":5,\"datetime\":\"1787932603\",\"microtimestamp\":\"1787932602881000\",\"amount\":0.444921,\"amount_str\":\"0.444921\",\"amount_traded\":\"0\",\"amount_at_create\":\"0.444921\",\"price\":2480.11,\"price_str\":\"2480.11\",\"is_liquidation\":false},\"channel\":\"live_orders_ethusd\",\"event\":\"order_created\",\"event_id\":\"00065a1d-7fad-53e8-0000-001203000020\",\"pre_event_id\":\"00065a1d-7fad-30c0-0000-001202000020\",\"order_source\":\"orderbook\"}","recorded_unix_us":1787932603027981}
{"message":"{\"data\":{\"id\":2044303885205506,\"id_str\":\"2044303885205506\",\"order_type\":1,\"order_subtype\":5,\"datetime\":\"1787932603\",\"microtimestamp\":\"1787932602881000\",\"amount\":0.1,\"amount_str\":\"0.10000000\",\"amount_traded\":\"0\",\"amount_at_create\":\"0.10000000\",\"price\":78522.63,\"price_str\":\"78522.63\",\"is_liquidation\":false},\"channel\":\"live_orders_btcusd\",\"event\":\"order_created\",\"event_id\":\"00065a1d-7fad-53e8-0000-000100000020\",\"pre_event_id\":\"00065a1d-7fad-4830-0002-000103000020\",\"order_source\":\"orderbook\"}","recorded_unix_us":1787932603028019}
{"message":"{\"data\":{\"id\":2044303885205506,\"id_str\":\"2044303885205506\",\"order_type\":1,\"order_subtype\":5,\"datetime\":\"1787932603\",\"microtimestamp\":\"1787932602881000\",\"amount\":0.1,\"amount_str\":\"0.10000000\",\"amount_traded\":\"0\",\"amount_at_create\":\"0.10000000\",\"price\":78522.63,\"price_str\":\"78522.63\",\"is_liquidation\":false},\"channel\":\"live_orders_btcusd\",\"event\":\"order_deleted\",\"event_id\":\"00065a1d-7fad-53e8-0001-000101000020\",\"pre_event_id\":\"00065a1d-7fad-53e8-0000-000100000020\",\"order_source\":\"orderbook\"}","recorded_unix_us":1787932603028047}
{"message":"{\"data\":{\"id\":2044303885209600,\"id_str\":\"2044303885209600\",\"order_type\":1,\"order_subtype\":5,\"datetime\":\"1787932603\",\"microtimestamp\":\"1787932602882000\",\"amount\":10.062547,\"amount_str\":\"10.062547\",\"amount_traded\":\"0\",\"amount_at_create\":\"10.062547\",\"price\":2484.47,\"price_str\":\"2484.47\",\"is_liquidation\":false},\"channel\":\"live_orders_ethusd\",\"event\":\"order_created\",\"event_id\":\"00065a1d-7fad-57d0-0000-001200000020\",\"pre_event_id\":\"00065a1d-7fad-53e8-0000-001203000020\",\"order_source\":\"orderbook\"}","recorded_unix_us":1787932603028163}
{"message":"{\"data\":{\"id\":2044303885209601,\"id_str\":\"2044303885209601\",\"order_type\":1,\"order_subtype\":5,\"datetime\":\"1787932603\",\"microtimestamp\":\"1787932602882000\",\"amount\":4.028003,\"amount_str\":\"4.028003\",\"amount_traded\":\"0\",\"amount_at_create\":\"4.028003\",\"price\":2482.62,\"price_str\":\"2482.62\",\"is_liquidation\":false},\"channel\":\"live_orders_ethusd\",\"event\":\"order_created\",\"event_id\":\"00065a1d-7fad-57d0-0001-001201000020\",\"pre_event_id\":\"00065a1d-7fad-57d0-0000-001200000020\",\"order_source\":\"orderbook\"}","recorded_unix_us":1787932603028288}
{"message":"{\"data\":{\"id\":2044303885209605,\"id_str\":\"2044303885209605\",\"order_type\":1,\"order_subtype\":5,\"datetime\":\"1787932603\",\"microtimestamp\":\"1787932602882000\",\"amount\":20.077182,\"amount_str\":\"20.077182\",\"amount_traded\":\"0\",\"amount_at_create\":\"20.077182\",\"price\":2490.39,\"price_str\":\"2490.39\",\"is_liquidation\":false},\"channel\":\"live_orders_ethusd\",\"event\":\"order_created\",\"event_id\":\"00065a1d-7fad-57d0-0002-001202000020\",\"pre_event_id\":\"00065a1d-7fad-57d0-0001-001201000020\",\"order_source\":\"orderbook\"}","recorded_unix_us":1787932603028321}
{"message":"{\"data\":{\"id\":2044303885209606,\"id_str\":\"2044303885209606\",\"order_type\":1,\"order_subtype\":5,\"datetime\":\"1787932603\",\"microtimestamp\":\"1787932602882000\",\"amount\":40.051178,\"amount_str\":\"40.051178\",\"amount_traded\":\"0\",\"amount_at_create\":\"40.051178\",\"price\":2496.81,\"price_str\":\"2496.81\",\"is_liquidation\":false},\"channel\":\"live_orders_ethusd\",\"event\":\"order_created\",\"event_id\":\"00065a1d-7fad-57d0-0003-001203000020\",\"pre_event_id\":\"00065a1d-7fad-57d0-0002-001202000020\",\"order_source\":\"orderbook\"}","recorded_unix_us":1787932603028426}
{"message":"{\"data\":{\"id\":2044303885213701,\"id_str\":\"2044303885213701\",\"order_type\":0,\"order_subtype\":5,\"datetime\":\"1787932603\",\"microtimestamp\":\"1787932602883000\",\"amount\":12.096984,\"amount_str\":\"12.096984\",\"amount_traded\":\"0\",\"amount_at_create\":\"12.096984\",\"price\":2479.95,\"price_str\":\"2479.95\",\"is_liquidation\":false},\"channel\":\"live_orders_ethusd\",\"event\":\"order_created\",\"event_id\":\"00065a1d-7fad-5bb8-0000-001200000020\",\"pre_event_id\":\"00065a1d-7fad-57d0-0003-001203000020\",\"order_source\":\"orderbook\"}","recorded_unix_us":1787932603028730}
{"message":"{\"data\":{\"id\":2044303885217799,\"id_str\":\"2044303885217799\",\"order_type\":0,\"order_subtype\":5,\"datetime\":\"1787932603\",\"microtimestamp\":\"1787932602885000\",\"amount\":12.095621,\"amount_str\":\"12.095621\",\"amount_traded\":\"0\",\"amount_at_create\":\"12.095621\",\"price\":2480.23,\"price_str\":\"2480.23\",\"is_liquidation\":false},\"channel\":\"live_orders_ethusd\",\"event\":\"order_created\",\"event_id\":\"00065a1d-7fad-6388-0000-001201000020\",\"pre_event_id\":\"00065a1d-7fad-5bb8-0000-001200000020\",\"order_source\":\"orderbook\"}","recorded_unix_us":1787932603028765}
{"message":"{\"data\":{\"id\":2044303885217804,\"id_str\":\"2044303885217804\",\"order_type\":0,\"order_subtype\":5,\"datetime\":\"1787932603\",\"microtimestamp\":\"1787932602885000\",\"amount\":4.032745,\"amount_str\":\"4.032745\",\"amount_traded\":\"0\",\"amount_at_create\":\"4.032745\",\"price\":2479.7,\"price_str\":\"2479.70\",\"is_liquidation\":false},\"channel\":\"live_orders_ethusd\",\"event\":\"order_created\",\"event_id\":\"00065a1d-7fad-6388-0001-001202000020\",\"pre_event_id\":\"00065a1d-7fad-6388-0000-001201000020\",\"order_source\":\"orderbook\"}","recorded_unix_us":1787932603028791}
{"message":"{\"data\":{\"id\":2044303885230091,\"id_str\":\"2044303885230091\",\"order_type\":0,\"order_subtype\":5,\"datetime\":\"1787932603\",\"microtimestamp\":\"1787932602888000\",\"amount\":10.090138,\"amount_str\":\"10.090138\",\"amount_traded\":\"0\",\"amount_at_create\":\"10.090138\",\"price\":2477.66,\"price_str\":\"2477.66\",\"is_liquidation\":false},\"channel\":\"live_orders_ethusd\",\"event\":\"order_created\",\"event_id\":\"00065a1d-7fad-6f40-0000-001203000020\",\"pre_event_id\":\"00065a1d-7fad-6388-0001-001202000020\",\"order_source\":\"orderbook\"}","recorded_unix_us":1787932603028818}
{"message":"{\"data\":{\"id\":2044303885234180,\"id_str\":\"2044303885234180\",\"order_type\":0,\"order_subtype\":5,\"datetime\":\"1787932603\",\"microtimestamp\":\"1787932602888000\",\"amount\":10.095101,\"amount_str\":\"10.095101\",\"amount_traded\":\"0\",\"amount_at_create\":\"10.095101\",\"price\":2476.44,\"price_str\":\"2476.44\",\"is_liquidation\":false},\"channel\":\"live_orders_ethusd\",\"event\":\"order_created\",\"event_id\":\"00065a1d-7fad-6f40-0001-001200000020\",\"pre_event_id\":\"00065a1d-7fad-6f40-0000-001203000020\",\"order_source\":\"orderbook\"}","recorded_unix_us":1787932603028846}
{"message":"{\"data\":{\"id\":2044303885234187,\"id_str\":\"2044303885234187\",\"order_type\":0,\"order_subtype\":5,\"datetime\":\"1787932603\",\"microtimestamp\":\"1787932602889000\",\"amount\":20.204386,\"amount_str\":\"20.204386\",\"amount_traded\":\"0\",\"amount_at_create\":\"20.204386\",\"price\":2474.71,\"price_str\":\"2474.71\",\"is_liquidation\":false},\"channel\":\"live_orders_ethusd\",\"event\":\"order_created\",\"event_id\":\"00065a1d-7fad-7328-0000-001201000020\",\"pre_event_id\":\"00065a1d-7fad-6f40-0001-001200000020\",\"order_source\":\"orderbook\"}","recorded_unix_us":1787932603028872}
{"message":"{\"data\":{\"id\":2044303885238272,\"id_str\":\"2044303885238272\",\"order_type\":0,\"order_subtype\":5,\"datetime\":\"1787932603\",\"microtimestamp\":\"1787932602889000\",\"amount\":4.033601,\"amount_str\":\"4.033601\",\"amount_traded\":\"0\",\"amount_at_create\":\"4.033601\",\"price\":2479.17,\"price_str\":\"2479.17\",\"is_liquidation\":false},\"channel\":\"live_orders_ethusd\",\"event\":\"order_created\",\"event_id\":\"00065a1d-7fad-7328-0001-001202000020\",\"pre_event_id\":\"00065a1d-7fad-7328-0000-001201000020\",\"order_source\":\"orderbook\"}","recorded_unix_us":1787932603028973}
{"message":"{\"data\":{\"id\":2044303885242368,\"id_str\":\"2044303885242368\",\"order_type\":0,\"order_subtype\":5,\"datetime\":\"1787932603\",\"microtimestamp\":\"1787932602890000\",\"amount\":40.528033,\"amount_str\":\"40.528033\",\"amount_traded\":\"0\",\"amount_at_create\":\"40.528033\",\"price\":2467.42,\"price_str\":\"2467.42\",\"is_liquidation\":false},\"channel\":\"live_orders_ethusd\",\"event\":\"order_created\",\"event_id\":\"00065a1d-7fad-7710-0000-001203000020\",\"pre_event_id\":\"00065a1d-7fad-7328-0001-001202000020\",\"order_source\":\"orderbook\"}","recorded_unix_us":1787932603029121}
{"message":"{\"data\":{\"id\":2044303885242372,\"id_str\":\"2044303885242372\",\"order_type\":0,\"order_subtype\":5,\"datetime\":\"1787932603\",\"microtimestamp\":\"1787932602890000\",\"amount\":40.650432,\"amount_str\":\"40.650432\",\"amount_traded\":\"0\",\"amount_at_create\":\"40.650432\",\"price\":2459.99,\"price_str\":\"2459.99\",\"is_liquidation\":false},\"channel\":\"live_orders_ethusd\",\"event\":\"order_created\",\"event_id\":\"00065a1d-7fad-7710-0001-001200000020\",\"pre_event_id\":\"00065a1d-7fad-7710-0000-001203000020\",\"order_source\":\"orderbook\"}","recorded_unix_us":1787932603029200}
{"message":"{\"data\":{\"id\":2044303885307908,\"id_str\":\"2044303885307908\",\"order_type\":1,\"order_subtype\":5,\"datetime\":\"1787932603\",\"microtimestamp\":\"1787932602906000\",\"amount\":0.06310787,\"amount_str\":\"0.06310787\",\"amount_traded\":\"0\",\"amount_at_create\":\"0.06310787\",\"price\":78519.95,\"price_str\":\"78519.95\",\"is_liquidation\":false},\"channel\":\"live_orders_btcusd\",\"event\":\"order_created\",\"event_id\":\"00065a1d-7fad-b590-0000-000102000020\",\"pre_event_id\":\"00065a1d-7fad-53e8-0001-000101000020\",\"order_source\":\"orderbook\"}","recorded_unix_us":1787932603029345}
{"message":"{\"data\":{\"id\":2044303885307908,\"id_str\":\"2044303885307908\",\"order_type\":1,\"order_subtype\":5,\"datetime\":\"1787932603\",\"microtimestamp\":\"1787932602906000\",\"amount\":0.06310787,\"amount_str\":\"0.06310787\",\"amount_traded\":\"0\",\"amount_at_create\":\"0.06310787\",\"price\":78519.95,\"price_str\":\"78519.95\",\"is_liquidation\":false},\"channel\":\"live_orders_btcusd\",\"event\":\"order_deleted\",\"event_id\":\"00065a1d-7fad-b590-0001-000103000020\",\"pre_event_id\":\"00065a1d-7fad-b590-0000-000102000020\",\"order_source\":\"orderbook\"}","recorded_unix_us":1787932603029383}
{"message":"{\"data\":{\"id\":2044303885307916,\"id_str\":\"2044303885307916\",\"order_type\":1,\"order_subtype\":5,\"datetime\":\"1787932603\",\"microtimestamp\":\"1787932602907000\",\"amount\":0.06310787,\"amount_str\":\"0.06310787\",\"amount_traded\":\"0\",\"amount_at_create\":\"0.06310787\",\"price\":78522.31,\"price_str\":\"78522.31\",\"is_liquidation\":false},\"channel\":\"live_orders_btcusd\",\"event\":\"order_created\",\"event_id\":\"00065a1d-7fad-b978-0000-000100000020\",\"pre_event_id\":\"00065a1d-7fad-b590-0001-000103000020\",\"order_source\":\"orderbook\"}","recorded_unix_us":1787932603029486}
{"message":"{\"data\":{\"id\":2044303885307916,\"id_str\":\"2044303885307916\",\"order_type\":1,\"order_subtype\":5,\"datetime\":\"1787932603\",\"microtimestamp\":\"1787932602907000\",\"amount\":0.06310787,\"amount_str\":\"0.06310787\",\"amount_traded\":\"0\",\"amount_at_create\":\"0.06310787\",\"price\":78522.31,\"price_str\":\"78522.31\",\"is_liquidation\":false},\"channel\":\"live_orders_btcusd\",\"event\":\"order_deleted\",\"event_id\":\"00065a1d-7fad-b978-0001-000101000020\",\"pre_event_id\":\"00065a1d-7fad-b978-0000-000100000020\",\"order_source\":\"orderbook\"}","recorded_unix_us":1787932603029595}
{"message":"{\"data\":{\"id\":2044303885312012,\"id_str\":\"2044303885312012\",\"order_type\":1,\"order_subtype\":5,\"datetime\":\"1787932603\",\"microtimestamp\":\"1787932602908000\",\"amount\":0.1,\"amount_str\":\"0.10000000\",\"amount_traded\":\"0\",\"amount_at_create\":\"0.10000000\",\"price\":78522.62,\"price_str\":\"78522.62\",\"is_liquidation\":false},\"channel\":\"live_orders_btcusd\",\"event\":\"order_created\",\"event_id\":\"00065a1d-7fad-bd60-0000-000102000020\",\"pre_event_id\":\"00065a1d-7fad-b978-0001-000101000020\",\"order_source\":\"orderbook\"}","recorded_unix_us":1787932603029725}
{"message":"{\"data\":{\"id\":2044303885312012,\"id_str\":\"2044303885312012\",\"order_type\":1,\"order_subtype\":5,\"datetime\":\"1787932603\",\"microtimestamp\":\"1787932602908000\",\"amount\":0.1,\"amount_str\":\"0.10000000\",\"amount_traded\":\"0\",\"amount_at_create\":\"0.10000000\",\"price\":78522.62,\"price_str\":\"78522.62\",\"is_liquidation\":false},\"channel\":\"live_orders_btcusd\",\"event\":\"order_deleted\",\"event_id\":\"00065a1d-7fad-bd60-0001-000103000020\",\"pre_event_id\":\"00065a1d-7fad-bd60-0000-000102000020\",\"order_source\":\"orderbook\"}","recorded_unix_us":1787932603029759}
{"message":"{\"data\":{\"id\":2044303885324299,\"id_str\":\"2044303885324299\",\"order_type\":1,\"order_subtype\":5,\"datetime\":\"1787932603\",\"microtimestamp\":\"1787932602911000\",\"amount\":4.027586,\"amount_str\":\"4.027586\",\"amount_traded\":\"0\",\"amount_at_create\":\"4.027586\",\"price\":2482.88,\"price_str\":\"2482.88\",\"is_liquidation\":false},\"channel\":\"live_orders_ethusd\",\"event\":\"order_created\",\"event_id\":\"00065a1d-7fad-c918-0000-001201000020\",\"pre_event_id\":\"00065a1d-7fad-7710-0001-001200000020\",\"order_source\":\"orderbook\"}","recorded_unix_us":1787932603029904}
{"message":"{\"data\":{\"id\":2044303885336585,\"id_str\":\"2044303885336585\",\"order_type\":1,\"order_subtype\":5,\"datetime\":\"1787932603\",\"microtimestamp\":\"1787932602913000\",\"amount\":10.059779,\"amount_str\":\"10.059779\",\"amount_traded\":\"0\",\"amount_at_create\":\"10.059779\",\"price\":2485.15,\"price_str\":\"2485.15\",\"is_liquidation\":false},\"channel\":\"live_orders_ethusd\",\"event\":\"order_created\",\"event_id\":\"00065a1d-7fad-d0e8-0000-001202000020\",\"pre_event_id\":\"00065a1d-7fad-c918-0000-001201000020\",\"order_source\":\"orderbook\"}","recorded_unix_us":1787932603030018}
{"message":"{\"data\":{\"id\":2044303885336593,\"id_str\":\"2044303885336593\",\"order_type\":1,\"order_subtype\":5,\"datetime\":\"1787932603\",\"microtimestamp\":\"1787932602914000\",\"amount\":40.010118,\"amount_str\":\"40.010118\",\"amount_traded\":\"0\",\"amount_at_create\":\"40.010118\",\"price\":2499.37,\"price_str\":\"2499.37\",\"is_liquidation\":false},\"channel\":\"live_orders_ethusd\",\"event\":\"order_created\",\"event_id\":\"00065a1d-7fad-d4d0-0000-001203000020\",\"pre_event_id\":\"00065a1d-7fad-d0e8-0000-001202000020\",\"order_source\":\"orderbook\"}","recorded_unix_us":1787932603030044}
{"message":"{\"data\":{\"id\":2044303885340675,\"id_str\":\"2044303885340675\",\"order_type\":1,\"order_subtype\":5,\"datetime\":\"1787932603\",\"microtimestamp\":\"1787932602914000\",\"amount\":20.063885,\"amount_str\":\"20.063885\",\"amount_traded\":\"0\",\"amount_at_create\":\"20.063885\",\"price\":2492.04,\"price_str\":\"2492.04\",\"is_liquidation\":false},\"channel\":\"live_orders_ethusd\",\"event\":\"order_created\",\"event_id\":\"00065a1d-7fad-d4d0-0001-001200000020\",\"pre_event_id\":\"00065a1d-7fad-d4d0-0000-001203000020\",\"order_source\":\"orderbook\"}","recorded_unix_us":1787932603030065}
{"message":"{\"data\":{\"id\":2044303885344777,\"id_str\":\"2044303885344777\",\"order_type\":0,\"order_subtype\":5,\"datetime\":\"1787932603\",\"microtimestamp\":\"1787932602916000\",\"amount\":4.034022,\"amount_str\":\"4.034022\",\"amount_traded\":\"0\",\"amount_at_create\":\"4.034022\",\"price\":2478.91,\"price_str\":\"2478.91\",\"is_liquidation\":false},\"channel\":\"live_orders_ethusd\",\"event\":\"order_created\",\"event_id\":\"00065a1d-7fad-dca0-0000-001201000020\",\"pre_event_id\":\"00065a1d-7fad-d4d0-0001-001200000020\",\"order_source\":\"orderbook\"}","recorded_unix_us":1787932603030167}
{"message":"{\"data\":{\"id\":2044303885348874,\"id_str\":\"2044303885348874\",\"order_type\":0,\"order_subtype\":5,\"datetime\":\"1787932603\",\"microtimestamp\":\"1787932602917000\",\"amount\":10.092689,\"amount_str\":\"10.092689\",\"amount_traded\":\"0\",\"amount_at_create\":\"10.092689\",\"price\":2477.04,\"price_str\":\"2477.04\",\"is_liquidation\":false},\"channel\":\"live_orders_ethusd\",\"event\":\"order_created\",\"event_id\":\"00065a1d-7fad-e088-0000-001202000020\",\"pre_event_id\":\"00065a1d-7fad-dca0-0000-001201000020\",\"order_source\":\"orderbook\"}","recorded_unix_us":1787932603030249}
{"message":"{\"data\":{\"id\":2044303885361152,\"id_str\":\"2044303885361152\",\"order_type\":0,\"order_subtype\":5,\"datetime\":\"1787932603\",\"microtimestamp\":\"1787932602919000\",\"amount\":10.097738,\"amount_str\":\"10.097738\",\"amount_traded\":\"0\",\"amount_at_create\":\"10.097738\",\"price\":2475.8,\"price_str\":\"2475.80\",\"is_liquidation\":false},\"channel\":\"live_orders_ethusd\",\"event\":\"order_created\",\"event_id\":\"00065a1d-7fad-e858-0000-001203000020\",\"pre_event_id\":\"00065a1d-7fad-e088-0000-001202000020\",\"order_source\":\"orderbook\"}","recorded_unix_us":1787932603030329}
{"message":"{\"data\":{\"id\":2044303885365251,\"id_str\":\"2044303885365251\",\"order_type\":0,\"order_subtype\":5,\"datetime\":\"1787932603\",\"microtimestamp\":\"1787932602920000\",\"amount\":4.033204,\"amount_str\":\"4.033204\",\"amount_traded\":\"0\",\"amount_at_create\":\"4.033204\",\"price\":2479.41,\"price_str\":\"2479.41\",\"is_liquidation\":false},\"channel\":\"live_orders_ethusd\",\"event\":\"order_created\",\"event_id\":\"00065a1d-7fad-ec40-0000-001200000020\",\"pre_event_id\":\"00065a1d-7fad-e858-0000-001203000020\",\"order_source\":\"orderbook\"}","recorded_unix_us":1787932603030403}
{"message":"{\"data\":{\"id\":2044303885373447,\"id_str\":\"2044303885373447\",\"order_type\":1,\"order_subtype\":5,\"datetime\":\"1787932603\",\"microtimestamp\":\"1787932602923000\",\"amount\":0.1,\"amount_str\":\"0.10000000\",\"amount_traded\":\"0\",\"amount_at_create\":\"0.10000000\",\"price\":78522.63,\"price_str\":\"78522.63\",\"is_liquidation\":false},\"channel\":\"live_orders_btcusd\",\"event\":\"order_created\",\"event_id\":\"00065a1d-7fad-f7f8-0000-000100000020\",\"pre_event_id\":\"00065a1d-7fad-bd60-0001-000103000020\",\"order_source\":\"orderbook\"}","recorded_unix_us":1787932603030533}
{"message":"{\"data\":{\"id\":2044303885373447,\"id_str\":\"2044303885373447\",\"order_type\":1,\"order_subtype\":5,\"datetime\":\"1787932603\",\"microtimestamp\":\"1787932602923000\",\"amount\":0.1,\"amount_str\":\"0.10000000\",\"amount_traded\":\"0\",\"amount_at_create\":\"0.10000000\",\"price\":78522.63,\"price_str\":\"78522.63\",\"is_liquidation\":false},\"channel\":\"live_orders_btcusd\",\"event\":\"order_deleted\",\"event_id\":\"00065a1d-7fad-f7f8-0001-000101000020\",\"pre_event_id\":\"00065a1d-7fad-f7f8-0000-000100000020\",\"order_source\":\"orderbook\"}","recorded_unix_us":1787932603030561}
{"message":"{\"data\":{\"id\":2044303885381632,\"id_str\":\"2044303885381632\",\"order_type\":0,\"order_subtype\":5,\"datetime\":\"1787932603\",\"microtimestamp\":\"1787932602924000\",\"amount\":40.568517,\"amount_str\":\"40.568517\",\"amount_traded\":\"0\",\"amount_at_create\":\"40.568517\",\"price\":2464.96,\"price_str\":\"2464.96\",\"is_liquidation\":false},\"channel\":\"live_orders_ethusd\",\"event\":\"order_created\",\"event_id\":\"00065a1d-7fad-fbe0-0000-001201000020\",\"pre_event_id\":\"00065a1d-7fad-ec40-0000-001200000020\",\"order_source\":\"orderbook\"}","recorded_unix_us":1787932603030621}
{"message":"{\"data\":{\"id\":2044303885385738,\"id_str\":\"2044303885385738\",\"order_type\":0,\"order_subtype\":5,\"datetime\":\"1787932603\",\"microtimestamp\":\"1787932602926000\",\"amount\":20.215084,\"amount_str\":\"20.215084\",\"amount_traded\":\"0\",\"amount_at_create\":\"20.215084\",\"price\":2473.4,\"price_str\":\"2473.40\",\"is_liquidation\":false},\"channel\":\"live_orders_ethusd\",\"event\":\"order_created\",\"event_id\":\"00065a1d-7fae-03b0-0000-001202000020\",\"pre_event_id\":\"00065a1d-7fad-fbe0-0000-001201000020\",\"order_source\":\"orderbook\"}","recorded_unix_us":1787932603030693}
{"message":"{\"data\":{\"id\":2044303808425991,\"id_str\":\"2044303808425991\",\"order_type\":0,\"order_subtype\":5,\"datetime\":\"1787932603\",\"microtimestamp\":\"1787932602929000\",\"amount\":3.076464,\"amount_str\":\"3.076464\",\"amount_traded\":\"0\",\"amount_at_create\":\"3.076464\",\"price\":2479.17,\"price_str\":\"2479.17\",\"is_liquidation\":false},\"channel\":\"live_orders_ethusd\",\"event\":\"order_deleted\",\"event_id\":\"00065a1d-7fae-0f68-0000-001203000020\",\"pre_event_id\":\"00065a1d-7fae-03b0-0000-001202000020\",\"order_source\":\"orderbook\"}","recorded_unix_us":1787932603030766}
{"message":"{\"data\":{\"id\":2044303885430788,\"id_str\":\"2044303885430788\",\"order_type\":1,\"order_subtype\":5,\"datetime\":\"1787932603\",\"microtimestamp\":\"1787932602936000\",\"amount\":0.1,\"amount_str\":\"0.10000000\",\"amount_traded\":\"0\",\"amount_at_create\":\"0.10000000\",\"price\":78522.62,\"price_str\":\"78522.62\",\"is_liquidation\":false},\"channel\":\"live_orders_btcusd\",\"event\":\"order_created\",\"event_id\":\"00065a1d-7fae-2ac0-0000-000102000020\",\"pre_event_id\":\"00065a1d-7fad-f7f8-0001-000101000020\",\"order_source\":\"orderbook\"}","recorded_unix_us":1787932603030853}
{"message":"{\"data\":{\"id\":2044303885430788,\"id_str\":\"2044303885430788\",\"order_type\":1,\"order_subtype\":5,\"datetime\":\"1787932603\",\"microtimestamp\":\"1787932602936000\",\"amount\":0.1,\"amount_str\":\"0.10000000\",\"amount_traded\":\"0\",\"amount_at_create\":\"0.10000000\",\"price\":78522.62,\"price_str\":\"78522.62\",\"is_liquidation\":false},\"channel\":\"live_orders_btcusd\",\"event\":\"order_deleted\",\"event_id\":\"00065a1d-7fae-2ac0-0001-000103000020\",\"pre_event_id\":\"00065a1d-7fae-2ac0-0000-000102000020\",\"order_source\":\"orderbook\"}","recorded_unix_us":1787932603030925}
{"message":"{\"data\":{\"id\":2044303885430815,\"id_str\":\"2044303885430815\",\"order_type\":1,\"order_subtype\":5,\"datetime\":\"1787932603\",\"microtimestamp\":\"1787932602937000\",\"amount\":0.06310787,\"amount_str\":\"0.06310787\",\"amount_traded\":\"0\",\"amount_at_create\":\"0.06310787\",\"price\":78522.38,\"price_str\":\"78522.38\",\"is_liquidation\":false},\"channel\":\"live_orders_btcusd\",\"event\":\"order_created\",\"event_id\":\"00065a1d-7fae-2ea8-0000-000100000020\",\"pre_event_id\":\"00065a1d-7fae-2ac0-0001-000103000020\",\"order_source\":\"orderbook\"}","recorded_unix_us":1787932603031006}
{"message":"{\"data\":{\"id\":2044303885430815,\"id_str\":\"2044303885430815\",\"order_type\":1,\"order_subtype\":5,\"datetime\":\"1787932603\",\"microtimestamp\":\"1787932602937000\",\"amount\":0.06310787,\"amount_str\":\"0.06310787\",\"amount_traded\":\"0\",\"amount_at_create\":\"0.06310787\",\"price\":78522.38,\"price_str\":\"78522.38\",\"is_liquidation\":false},\"channel\":\"live_orders_btcusd\",\"event\":\"order_deleted\",\"event_id\":\"00065a1d-7fae-2ea8-0001-000101000020\",\"pre_event_id\":\"00065a1d-7fae-2ea8-0000-000100000020\",\"order_source\":\"orderbook\"}","recorded_unix_us":1787932603031092}
{"message":"{\"data\":{\"id\":2044303885434894,\"id_str\":\"2044303885434894\",\"order_type\":1,\"order_subtype\":5,\"datetime\":\"1787932603\",\"microtimestamp\":\"1787932602937000\",\"amount\":0.06310787,\"amount_str\":\"0.06310787\",\"amount_traded\":\"0\",\"amount_at_create\":\"0.06310787\",\"price\":78520.02,\"price_str\":\"78520.02\",\"is_liquidation\":false},\"channel\":\"live_orders_btcusd\",\"event\":\"order_created\",\"event_id\":\"00065a1d-7fae-2ea8-0002-000102000020\",\"pre_event_id\":\"00065a1d-7fae-2ea8-0001-000101000020\",\"order_source\":\"orderbook\"}","recorded_unix_us":1787932603031165}
{"message":"{\"data\":{\"id\":2044303885434894,\"id_str\":\"2044303885434894\",\"order_type\":1,\"order_subtype\":5,\"datetime\":\"1787932603\",\"microtimestamp\":\"1787932602937000\",\"amount\":0.06310787,\"amount_str\":\"0.06310787\",\"amount_traded\":\"0\",\"amount_at_create\":\"0.06310787\",\"price\":78520.02,\"price_str\":\"78520.02\",\"is_liquidation\":false},\"channel\":\"live_orders_btcusd\",\"event\":\"order_deleted\",\"event_id\":\"00065a1d-7fae-2ea8-0003-000103000020\",\"pre_event_id\":\"00065a1d-7fae-2ea8-0002-000102000020\",\"order_source\":\"orderbook\"}","recorded_unix_us":1787932603031237}
{"message":"{\"data\":{\"id\":2044303883362316,\"id_str\":\"2044303883362316\",\"order_type\":1,\"order_subtype\":5,\"datetime\":\"1787932603\",\"microtimestamp\":\"1787932602938000\",\"amount\":1.27113313,\"amount_str\":\"1.27113313\",\"amount_traded\":\"0\",\"amount_at_create\":\"1.27113313\",\"price\":78669.97,\"price_str\":\"78669.97\",\"is_liquidation\":false},\"channel\":\"live_orders_btcusd\",\"event\":\"order_deleted\",\"event_id\":\"00065a1d-7fae-3290-0000-000100000020\",\"pre_event_id\":\"00065a1d-7fae-2ea8-0003-000103000020\",\"order_source\":\"orderbook\"}","recorded_unix_us":1787932603031307}
{"message":"{\"data\":{\"id\":2044303883714560,\"id_str\":\"2044303883714560\",\"order_type\":1,\"order_subtype\":5,\"datetime\":\"1787932603\",\"microtimestamp\":\"1787932602938000\",\"amount\":0.06367384,\"amount_str\":\"0.06367384\",\"amount_traded\":\"0\",\"amount_at_create\":\"0.06367384\",\"price\":78525.19,\"price_str\":\"78525.19\",\"is_liquidation\":false},\"channel\":\"live_orders_btcusd\",\"event\":\"order_deleted\",\"event_id\":\"00065a1d-7fae-3290-0001-000101000020\",\"pre_event_id\":\"00065a1d-7fae-3290-0000-000100000020\",\"order_source\":\"orderbook\"}","recorded_unix_us":1787932603031384}
{"message":"{\"data\":{\"id\":2044303883714561,\"id_str\":\"2044303883714561\",\"order_type\":1,\"order_subtype\":5,\"datetime\":\"1787932603\",\"microtimestamp\":\"1787932602939000\",\"amount\":0.06367563,\"amount_str\":\"0.06367563\",\"amount_traded\":\"0\",\"amount_at_create\":\"0.06367563\",\"price\":78522.98,\"price_str\":\"78522.98\",\"is_liquidation\":false},\"channel\":\"live_orders_btcusd\",\"event\":\"order_deleted\",\"event_id\":\"00065a1d-7fae-3678-0000-000102000020\",\"pre_event_id\":\"00065a1d-7fae-3290-0001-000101000020\",\"order_source\":\"orderbook\"}","recorded_unix_us":1787932603031466}
{"message":"{\"data\":{\"id\":2044303883739137,\"id_str\":\"2044303883739137\",\"order_type\":1,\"order_subtype\":5,\"datetime\":\"1787932603\",\"microtimestamp\":\"1787932602939000\",\"amount\":0.25467128,\"amount_str\":\"0.25467128\",\"amount_traded\":\"0\",\"amount_at_create\":\"0.25467128\",\"price\":78532.61,\"price_str\":\"78532.61\",\"is_liquidation\":false},\"channel\":\"live_orders_btcusd\",\"event\":\"order_deleted\",\"event_id\":\"00065a1d-7fae-3678-0001-000103000020\",\"pre_event_id\":\"00065a1d-7fae-3678-0000-000102000020\",\"order_source\":\"orderbook\"}","recorded_unix_us":1787932603031536}
{"message":"{\"data\":{\"id\":2044303883747328,\"id_str\":\"2044303883747328\",\"order_type\":1,\"order_subtype\":5,\"datetime\":\"1787932603\",\"microtimestamp\":\"1787932602939000\",\"amount\":1.27209222,\"amount_str\":\"1.27209222\",\"amount_traded\":\"0\",\"amount_at_create\":\"1.27209222\",\"price\":78610.66,\"price_str\":\"78610.66\",\"is_liquidation\":false},\"channel\":\"live_orders_btcusd\",\"event\":\"order_deleted\",\"event_id\":\"00065a1d-7fae-3678-0002-000100000020\",\"pre_event_id\":\"00065a1d-7fae-3678-0001-000103000020\",\"order_source\":\"orderbook\"}","recorded_unix_us":1787932603031610}
{"message":"{\"data\":{\"id\":2044303883747329,\"id_str\":\"2044303883747329\",\"order_type\":1,\"order_subtype\":5,\"datetime\":\"1787932603\",\"microtimestamp\":\"1787932602940000\",\"amount\":0.25466146,\"amount_str\":\"0.25466146\",\"amount_traded\":\"0\",\"amount_at_create\":\"0.25466146\",\"price\":78535.64,\"price_str\":\"78535.64\",\"is_liquidation\":false},\"channel\":\"live_orders_btcusd\",\"event\":\"order_deleted\",\"event_id\":\"00065a1d-7fae-3a60-0000-000101000020\",\"pre_event_id\":\"00065a1d-7fae-3678-0002-000100000020\",\"order_source\":\"orderbook\"}","recorded_unix_us":1787932603031679}
{"message":"{\"data\":{\"id\":2044303883751424,\"id_str\":\"2044303883751424\",\"order_type\":1,\"order_subtype\":5,\"datetime\":\"1787932603\",\"microtimestamp\":\"1787932602940000\",\"amount\":12.70451953,\"amount_str\":\"12.70451953\",\"amount_traded\":\"0\",\"amount_at_create\":\"12.70451953\",\"price\":78712.15,\"price_str\":\"78712.15\",\"is_liquidation\":false},\"channel\":\"live_orders_btcusd\",\"event\":\"order_deleted\",\"event_id\":\"00065a1d-7fae-3a60-0001-000102000020\",\"pre_event_id\":\"00065a1d-7fae-3a60-0000-000101000020\",\"order_source\":\"orderbook\"}","recorded_unix_us":1787932603031750}
{"message":"{\"data\":{\"id\":2044303883788289,\"id_str\":\"2044303883788289\",\"order_type\":1,\"order_subtype\":5,\"datetime\":\"1787932603\",\"microtimestamp\":\"1787932602940000\",\"amount\":1.26970017,\"amount_str\":\"1.26970017\",\"amount_traded\":\"0\",\"amount_at_create\":\"1.26970017\",\"price\":78758.76,\"price_str\":\"78758.76\",\"is_liquidation\":false},\"channel\":\"live_orders_btcusd\",\"event\":\"order_deleted\",\"event_id\":\"00065a1d-7fae-3a60-0002-000103000020\",\"pre_event_id\":\"00065a1d-7fae-3a60-0001-000102000020\",\"order_source\":\"orderbook\"}","recorded_unix_us":1787932603031937}
{"message":"{\"data\":{\"id\":2044303883808770,\"id_str\":\"2044303883808770\",\"order_type\":1,\"order_subtype\":5,\"datetime\":\"1787932603\",\"microtimestamp\":\"1787932602941000\",\"amount\":1.2684012,\"amount_str\":\"1.26840120\",\"amount_traded\":\"0\",\"amount_at_create\":\"1.26840120\",\"price\":78839.41,\"price_str\":\"78839.41\",\"is_liquidation\":false},\"channel\":\"live_orders_btcusd\",\"event\":\"order_deleted\",\"event_id\":\"00065a1d-7fae-3e48-0000-000100000020\",\"pre_event_id\":\"00065a1d-7fae-3a60-0002-000103000020\",\"order_source\":\"orderbook\"}","recorded_unix_us":1787932603031994}
{"message":"{\"data\":{\"id\":2044303883812868,\"id_str\":\"2044303883812868\",\"order_type\":0,\"order_subtype\":5,\"datetime\":\"1787932603\",\"microtimestamp\":\"1787932602941000\",\"amount\":0.06367953,\"amount_str\":\"0.06367953\",\"amount_traded\":\"0\",\"amount_at_create\":\"0.06367953\",\"price\":78518.15,\"price_str\":\"78518.15\",\"is_liquidation\":false},\"channel\":\"live_orders_btcusd\",\"event\":\"order_deleted\",\"event_id\":\"00065a1d-7fae-3e48-0001-000101000020\",\"pre_event_id\":\"00065a1d-7fae-3e48-0000-000100000020\",\"order_source\":\"orderbook\"}","recorded_unix_us":1787932603032124}
{"message":"{\"data\":{\"id\":2044303883866122,\"id_str\":\"2044303883866122\",\"order_type\":0,\"order_subtype\":5,\"datetime\":\"1787932603\",\"microtimestamp\":\"1787932602941000\",\"amount\":0.06368171,\"amount_str\":\"0.06368171\",\"amount_traded\":\"0\",\"amount_at_create\":\"0.06368171\",\"price\":78515.46,\"price_str\":\"78515.46\",\"is_liquidation\":false},\"channel\":\"live_orders_btcusd\",\"event\":\"order_deleted\",\"event_id\":\"00065a1d-7fae-3e48-0002-000102000020\",\"pre_event_id\":\"00065a1d-7fae-3e48-0001-000101000020\",\"order_source\":\"orderbook\"}","recorded_unix_us":1787932603032262}
{"message":"{\"data\":{\"id\":2044303883870209,\"id_str\":\"2044303883870209\",\"order_type\":0,\"order_subtype\":5,\"datetime\":\"1787932603\",\"microtimestamp\":\"1787932602942000\",\"amount\":0.25476924,\"amount_str\":\"0.25476924\",\"amount_traded\":\"0\",\"amount_at_create\":\"0.25476924\",\"price\":78502.41,\"price_str\":\"78502.41\",\"is_liquidation\":false},\"channel\":\"live_orders_btcusd\",\"event\":\"order_deleted\",\"event_id\":\"00065a1d-7fae-4230-0000-000103000020\",\"pre_event_id\":\"00065a1d-7fae-3e48-0002-000102000020\",\"order_source\":\"orderbook\"}","recorded_unix_us":1787932603032356}
{"message":"{\"data\":{\"id\":2044303883919360,\"id_str\":\"2044303883919360\",\"order_type\":0,\"order_subtype\":5,\"datetime\":\"1787932603\",\"microtimestamp\":\"1787932602942000\",\"amount\":0.25478772,\"amount_str\":\"0.25478772\",\"amount_traded\":\"0\",\"amount_at_create\":\"0.25478772\",\"price\":78496.71,\"price_str\":\"78496.71\",\"is_liquidation\":false},\"channel\":\"live_orders_btcusd\",\"event\":\"order_deleted\",\"event_id\":\"00065a1d-7fae-4230-0001-000100000020\",\"pre_event_id\":\"00065a1d-7fae-4230-0000-000103000020\",\"order_source\":\"orderbook\"}","recorded_unix_us":1787932603032456}
{"message":"{\"data\":{\"id\":2044303883927552,\"id_str\":\"2044303883927552\",\"order_type\":0,\"order_subtype\":5,\"datetime\":\"1787932603\",\"microtimestamp\":\"1787932602942000\",\"amount\":1.27507828,\"amount_str\":\"1.27507828\",\"amount_traded\":\"0\",\"amount_at_create\":\"1.27507828\",\"price\":78426.55,\"price_str\":\"78426.55\",\"is_liquidation\":false},\"channel\":\"live_orders_btcusd\",\"event\":\"order_deleted\",\"event_id\":\"00065a1d-7fae-4230-0002-000101000020\",\"pre_event_id\":\"00065a1d-7fae-4230-0001-000100000020\",\"order_source\":\"orderbook\"}","recorded_unix_us":1787932603032576}
{"message":"{\"data\":{\"id\":2044303883948035,\"id_str\":\"2044303883948035\",\"order_type\":0,\"order_subtype\":5,\"datetime\":\"1787932603\",\"microtimestamp\":\"1787932602943000\",\"amount\":1.27541152,\"amount_str\":\"1.27541152\",\"amount_traded\":\"0\",\"amount_at_create\":\"1.27541152\",\"price\":78406.06,\"price_str\":\"78406.06\",\"is_liquidation\":false},\"channel\":\"live_orders_btcusd\",\"event\":\"order_deleted\",\"event_id\":\"00065a1d-7fae-4618-0000-000102000020\",\"pre_event_id\":\"00065a1d-7fae-4230-0002-000101000020\",\"order_source\":\"orderbook\"}","recorded_unix_us":1787932603032650}
{"message":"{\"data\":{\"id\":2044303883952129,\"id_str\":\"2044303883952129\",\"order_type\":0,\"order_subtype\":5,\"datetime\":\"1787932603\",\"microtimestamp\":\"1787932602943000\",\"amount\":1.27567513,\"amount_str\":\"1.27567513\",\"amount_traded\":\"0\",\"amount_at_create\":\"1.27567513\",\"price\":78389.86,\"price_str\":\"78389.86\",\"is_liquidation\":false},\"channel\":\"live_orders_btcusd\",\"event\":\"order_deleted\",\"event_id\":\"00065a1d-7fae-4618-0001-000103000020\",\"pre_event_id\":\"00065a1d-7fae-4618-0000-000102000020\",\"order_source\":\"orderbook\"}","recorded_unix_us":1787932603032680}
{"message":"{\"data\":{\"id\":2044303883956229,\"id_str\":\"2044303883956229\",\"order_type\":0,\"order_subtype\":5,\"datetime\":\"1787932603\",\"microtimestamp\":\"1787932602943000\",\"amount\":12.76418733,\"amount_str\":\"12.76418733\",\"amount_traded\":\"0\",\"amount_at_create\":\"12.76418733\",\"price\":78344.19,\"price_str\":\"78344.19\",\"is_liquidation\":false},\"channel\":\"live_orders_btcusd\",\"event\":\"order_deleted\",\"event_id\":\"00065a1d-7fae-4618-0002-000100000020\",\"pre_event_id\":\"00065a1d-7fae-4618-0001-000103000020\",\"order_source\":\"orderbook\"}","recorded_unix_us":1787932603032781}
{"message":"{\"data\":{\"id\":2044303883968513,\"id_str\":\"2044303883968513\",\"order_type\":0,\"order_subtype\":5,\"datetime\":\"1787932603\",\"microtimestamp\":\"1787932602944000\",\"amount\":1.27757154,\"amount_str\":\"1.27757154\",\"amount_traded\":\"0\",\"amount_at_create\":\"1.27757154\",\"price\":78273.5,\"price_str\":\"78273.50\",\"is_liquidation\":false},\"channel\":\"live_orders_btcusd\",\"event\":\"order_deleted\",\"event_id\":\"00065a1d-7fae-4a00-0000-000101000020\",\"pre_event_id\":\"00065a1d-7fae-4618-0002-000100000020\",\"order_source\":\"orderbook\"}","recorded_unix_us":1787932603032809}
{"message":"{\"data\":{\"id\":2044303884046336,\"id_str\":\"2044303884046336\",\"order_type\":1,\"order_subtype\":5,\"datetime\":\"1787932603\",\"microtimestamp\":\"1787932602944000\",\"amount\":1.271772,\"amount_str\":\"1.27177200\",\"amount_traded\":\"0\",\"amount_at_create\":\"1.27177200\",\"price\":78630.45,\"price_str\":\"78630.45\",\"is_liquidation\":false},\"channel\":\"live_orders_btcusd\",\"event\":\"order_deleted\",\"event_id\":\"00065a1d-7fae-4a00-0001-000102000020\",\"pre_event_id\":\"00065a1d-7fae-4a00-0000-000101000020\",\"order_source\":\"orderbook\"}","recorded_unix_us":1787932603032941}
{"message":"{\"data\":{\"id\":2044303884054532,\"id_str\":\"2044303884054532\",\"order_type\":1,\"order_subtype\":5,\"datetime\":\"1787932603\",\"microtimestamp\":\"1787932602944000\",\"amount\":1.26842789,\"amount_str\":\"1.26842789\",\"amount_traded\":\"0\",\"amount_at_create\":\"1.26842789\",\"price\":78837.75,\"price_str\":\"78837.75\",\"is_liquidation\":false},\"channel\":\"live_orders_btcusd\",\"event\":\"order_deleted\",\"event_id\":\"00065a1d-7fae-4a00-0002-000103000020\",\"pre_event_id\":\"00065a1d-7fae-4a00-0001-000102000020\",\"order_source\":\"orderbook\"}","recorded_unix_us":1787932603033005}
{"message":"{\"data\":{\"id\":2044303885463555,\"id_str\":\"2044303885463555\",\"order_type\":0,\"order_subtype\":5,\"datetime\":\"1787932603\",\"microtimestamp\":\"1787932602944000\",\"amount\":20.225289,\"amount_str\":\"20.225289\",\"amount_traded\":\"0\",\"amount_at_create\":\"20.225289\",\"price\":2472.15,\"price_str\":\"2472.15\",\"is_liquidation\":false},\"channel\":\"live_orders_ethusd\",\"event\":\"order_created\",\"event_id\":\"00065a1d-7fae-4a00-0000-001200000020\",\"pre_event_id\":\"00065a1d-7fae-0f68-0000-001203000020\",\"order_source\":\"orderbook\"}","recorded_unix_us":1787932603033032}
{"message":"{\"data\":{\"id\":2044303884058625,\"id_str\":\"2044303884058625\",\"order_type\":0,\"order_subtype\":5,\"datetime\":\"1787932603\",\"microtimestamp\":\"1787932602944000\",\"amount\":1.27604867,\"amount_str\":\"1.27604867\",\"amount_traded\":\"0\",\"amount_at_create\":\"1.27604867\",\"price\":78366.91,\"price_str\":\"78366.91\",\"is_liquidation\":false},\"channel\":\"live_orders_btcusd\",\"event\":\"order_deleted\",\"event_id\":\"00065a1d-7fae-4a00-0003-000100000020\",\"pre_event_id\":\"00065a1d-7fae-4a00-0002-000103000020\",\"order_source\":\"orderbook\"}","recorded_unix_us":1787932603033155}
{"message":"{\"data\":{\"id\":2044303884066818,\"id_str\":\"2044303884066818\",\"order_type\":0,\"order_subtype\":5,\"datetime\":\"1787932603\",\"microtimestamp\":\"1787932602945000\",\"amount\":1.27817952,\"amount_str\":\"1.27817952\",\"amount_traded\":\"0\",\"amount_at_create\":\"1.27817952\",\"price\":78236.27,\"price_str\":\"78236.27\",\"is_liquidation\":false},\"channel\":\"live_orders_btcusd\",\"event\":\"order_deleted\",\"event_id\":\"00065a1d-7fae-4de8-0000-000101000020\",\"pre_event_id\":\"00065a1d-7fae-4a00-0003-000100000020\",\"order_source\":\"orderbook\"}","recorded_unix_us":1787932603033178}
{"message":"{\"data\":{\"id\":2044303885467651,\"id_str\":\"2044303885467651\",\"order_type\":0,\"order_subtype\":5,\"datetime\":\"1787932603\",\"microtimestamp\":\"1787932602945000\",\"amount\":0.00140266,\"amount_str\":\"0.00140266\",\"amount_traded\":\"0\",\"amount_at_create\":\"0.00140266\",\"price\":70668.36,\"price_str\":\"70668.36\",\"is_liquidation\":false},\"channel\":\"live_orders_btcusd\",\"event\":\"order_created\",\"event_id\":\"00065a1d-7fae-4de8-0001-000102000020\",\"pre_event_id\":\"00065a1d-7fae-4de8-0000-000101000020\",\"order_source\":\"orderbook\"}","recorded_unix_us":1787932603033198}
{"message":"{\"data\":{\"id\":2044303885467655,\"id_str\":\"2044303885467655\",\"order_type\":0,\"order_subtype\":5,\"datetime\":\"1787932603\",\"microtimestamp\":\"1787932602946000\",\"amount\":40.609081,\"amount_str\":\"40.609081\",\"amount_traded\":\"0\",\"amount_at_create\":\"40.609081\",\"price\":2462.5,\"price_str\":\"2462.50\",\"is_liquidation\":false},\"channel\":\"live_orders_ethusd\",\"event\":\"order_created\",\"event_id\":\"00065a1d-7fae-51d0-0000-001201000020\",\"pre_event_id\":\"00065a1d-7fae-4a00-0000-001200000020\",\"order_source\":\"orderbook\"}","recorded_unix_us":1787932603033316}
{"message":"{\"data\":{\"id\":2044303884034048,\"id_str\":\"2044303884034048\",\"order_type\":0,\"order_subtype\":5,\"datetime\":\"1787932603\",\"microtimestamp\":\"1787932602955000\",\"amount\":0.26750492,\"amount_str\":\"0.26750492\",\"amount_traded\":\"0\",\"amount_at_create\":\"0.26750492\",\"price\":78486.82,\"price_str\":\"78486.82\",\"is_liquidation\":false},\"channel\":\"live_orders_btcusd\",\"event\":\"order_deleted\",\"event_id\":\"00065a1d-7fae-74f8-0000-000103000020\",\"pre_event_id\":\"00065a1d-7fae-4de8-0001-000102000020\",\"order_source\":\"orderbook\"}","recorded_unix_us":1787932603033341}
{"message":"{\"data\":{\"id\":2044303885508611,\"id_str\":\"2044303885508611\",\"order_type\":0,\"order_subtype\":5,\"datetime\":\"1787932603\",\"microtimestamp\":\"1787932602955000\",\"amount\":0.26750492,\"amount_str\":\"0.26750492\",\"amount_traded\":\"0\",\"amount_at_create\":\"0.26750492\",\"price\":78486.82,\"price_str\":\"78486.82\",\"is_liquidation\":false},\"channel\":\"live_orders_btcusd\",\"event\":\"order_created\",\"event_id\":\"00065a1d-7fae-74f8-0001-000100000020\",\"pre_event_id\":\"00065a1d-7fae-74f8-0000-000103000020\",\"order_source\":\"orderbook\"}","recorded_unix_us":1787932603033460}
{"message":"{\"data\":{\"id\":2044303884173316,\"id_str\":\"2044303884173316\",\"order_type\":1,\"order_subtype\":5,\"datetime\":\"1787932603\",\"microtimestamp\":\"1787932602956000\",\"amount\":1.27145262,\"amount_str\":\"1.27145262\",\"amount_traded\":\"0\",\"amount_at_create\":\"1.27145262\",\"price\":78650.2,\"price_str\":\"78650.20\",\"is_liquidation\":false},\"channel\":\"live_orders_btcusd\",\"event\":\"order_deleted\",\"event_id\":\"00065a1d-7fae-78e0-0000-000101000020\",\"pre_event_id\":\"00065a1d-7fae-74f8-0001-000100000020\",\"order_source\":\"orderbook\"}","recorded_unix_us":1787932603033519}
{"message":"{\"data\":{\"id\":2044303885512708,\"id_str\":\"2044303885512708\",\"order_type\":1,\"order_subtype\":5,\"datetime\":\"1787932603\",\"microtimestamp\":\"1787932602957000\",\"amount\":5,\"amount_str\":\"5.000000\",\"amount_traded\":\"0\",\"amount_at_create\":\"5.000000\",\"price\":2482.72,\"price_str\":\"2482.72\",\"is_liquidation\":false},\"channel\":\"live_orders_ethusd\",\"event\":\"order_created\",\"event_id\":\"00065a1d-7fae-7cc8-0000-001202000020\",\"pre_event_id\":\"00065a1d-7fae-51d0-0000-001201000020\",\"order_source\":\"orderbook\"}","recorded_unix_us":1787932603033626}
{"message":"{\"data\":{\"id\":2044303884189704,\"id_str\":\"2044303884189704\",\"order_type\":0,\"order_subtype\":5,\"datetime\":\"1787932603\",\"microtimestamp\":\"1787932602957000\",\"amount\":1.27888333,\"amount_str\":\"1.27888333\",\"amount_traded\":\"0\",\"amount_at_create\":\"1.27888333\",\"price\":78193.21,\"price_str\":\"78193.21\",\"is_liquidation\":false},\"channel\":\"live_orders_btcusd\",\"event\":\"order_deleted\",\"event_id\":\"00065a1d-7fae-7cc8-0000-000102000020\",\"pre_event_id\":\"00065a1d-7fae-78e0-0000-000101000020\",\"order_source\":\"orderbook\"}","recorded_unix_us":1787932603033707}
{"message":"{\"data\":{\"id\":2044303885520900,\"id_str\":\"2044303885520900\",\"order_type\":1,\"order_subtype\":5,\"datetime\":\"1787932603\",\"microtimestamp\":\"1787932602958000\",\"amount\":0.1,\"amount_str\":\"0.10000000\",\"amount_traded\":\"0\",\"amount_at_create\":\"0.10000000\",\"price\":78522.63,\"price_str\":\"78522.63\",\"is_liquidation\":false},\"channel\":\"live_orders_btcusd\",\"event\":\"order_created\",\"event_id\":\"00065a1d-7fae-80b0-0000-000103000020\",\"pre_event_id\":\"00065a1d-7fae-7cc8-0000-000102000020\",\"order_source\":\"orderbook\"}","recorded_unix_us":1787932603033827}
{"message":"{\"data\":{\"id\":2044303885520900,\"id_str\":\"2044303885520900\",\"order_type\":1,\"order_subtype\":5,\"datetime\":\"1787932603\",\"microtimestamp\":\"1787932602958000\",\"amount\":0.1,\"amount_str\":\"0.10000000\",\"amount_traded\":\"0\",\"amount_at_create\":\"0.10000000\",\"price\":78522.63,\"price_str\":\"78522.63\",\"is_liquidation\":false},\"channel\":\"live_orders_btcusd\",\"event\":\"order_deleted\",\"event_id\":\"00065a1d-7fae-80b0-0001-000100000020\",\"pre_event_id\":\"00065a1d-7fae-80b0-0000-000103000020\",\"order_source\":\"orderbook\"}","recorded_unix_us":1787932603033893}
{"message":"{\"data\":{\"id\":2044303884812293,\"id_str\":\"2044303884812293\",\"order_type\":0,\"order_subtype\":5,\"datetime\":\"1787932603\",\"microtimestamp\":\"1787932602958000\",\"amount\":0.00140266,\"amount_str\":\"0.00140266\",\"amount_traded\":\"0\",\"amount_at_create\":\"0.00140266\",\"price\":70668.36,\"price_str\":\"70668.36\",\"is_liquidation\":false},\"channel\":\"live_orders_btcusd\",\"event\":\"order_deleted\",\"event_id\":\"00065a1d-7fae-80b0-0002-000101000020\",\"pre_event_id\":\"00065a1d-7fae-80b0-0001-000100000020\",\"order_source\":\"orderbook\"}","recorded_unix_us":1787932603033918}
{"message":"{\"data\":{\"id\":2044303883431937,\"id_str\":\"2044303883431937\",\"order_type\":1,\"order_subtype\":5,\"datetime\":\"1787932603\",\"microtimestamp\":\"1787932602966000\",\"amount\":0.6044871,\"amount_str\":\"0.60448710\",\"amount_traded\":\"0\",\"amount_at_create\":\"0.60448710\",\"price\":0.03160362,\"price_str\":\"0.03160362\",\"is_liquidation\":false},\"channel\":\"live_orders_ethbtc\",\"event\":\"order_deleted\",\"event_id\":\"00065a1d-7fae-9ff0-0000-001102000020\",\"pre_event_id\":\"00065a1d-7fa8-98f8-0000-001101000020\",\"order_source\":\"orderbook\"}","recorded_unix_us":1787932603033992}
{"message":"{\"data\":{\"id\":2044303883493384,\"id_str\":\"2044303883493384\",\"order_type\":1,\"order_subtype\":5,\"datetime\":\"1787932603\",\"microtimestamp\":\"1787932602967000\",\"amount\":1.007365,\"amount_str\":\"1.00736500\",\"amount_traded\":\"0\",\"amount_at_create\":\"1.00736500\",\"price\":0.03160719,\"price_str\":\"0.03160719\",\"is_liquidation\":false},\"channel\":\"live_orders_ethbtc\",\"event\":\"order_deleted\",\"event_id\":\"00065a1d-7fae-a3d8-0000-001103000020\",\"pre_event_id\":\"00065a1d-7fae-9ff0-0000-001102000020\",\"order_source\":\"orderbook\"}","recorded_unix_us":1787932603034115}
{"message":"{\"data\":{\"id\":2044303883497482,\"id_str\":\"2044303883497482\",\"order_type\":1,\"order_subtype\":5,\"datetime\":\"1787932603\",\"microtimestamp\":\"1787932602967000\",\"amount\":2.01406611,\"amount_str\":\"2.01406611\",\"amount_traded\":\"0\",\"amount_at_create\":\"2.01406611\",\"price\":0.0316176,\"price_str\":\"0.03161760\",\"is_liquidation\":false},\"channel\":\"live_orders_ethbtc\",\"event\":\"order_deleted\",\"event_id\":\"00065a1d-7fae-a3d8-0001-001100000020\",\"pre_event_id\":\"00065a1d-7fae-a3d8-0000-001103000020\",\"order_source\":\"orderbook\"}","recorded_unix_us":1787932603034138}
{"message":"{\"data\":{\"id\":2044303885557761,\"id_str\":\"2044303885557761\",\"order_type\":1,\"order_subtype\":5,\"datetime\":\"1787932603\",\"microtimestamp\":\"1787932602967000\",\"amount\":0.1,\"amount_str\":\"0.10000000\",\"amount_traded\":\"0\",\"amount_at_create\":\"0.10000000\",\"price\":78522.62,\"price_str\":\"78522.62\",\"is_liquidation\":false},\"channel\":\"live_orders_btcusd\",\"event\":\"order_created\",\"event_id\":\"00065a1d-7fae-a3d8-0000-000102000020\",\"pre_event_id\":\"00065a1d-7fae-80b0-0002-000101000020\",\"order_source\":\"orderbook\"}","recorded_unix_us":1787932603034252}
{"message":"{\"data\":{\"id\":2044303885557761,\"id_str\":\"2044303885557761\",\"order_type\":1,\"order_subtype\":5,\"datetime\":\"1787932603\",\"microtimestamp\":\"1787932602967000\",\"amount\":0.1,\"amount_str\":\"0.10000000\",\"amount_traded\":\"0\",\"amount_at_create\":\"0.10000000\",\"price\":78522.62,\"price_str\":\"78522.62\",\"is_liquidation\":false},\"channel\":\"live_orders_btcusd\",\"event\":\"order_deleted\",\"event_id\":\"00065a1d-7fae-a3d8-0001-000103000020\",\"pre_event_id\":\"00065a1d-7fae-a3d8-0000-000102000020\",\"order_source\":\"orderbook\"}","recorded_unix_us":1787932603034316}
{"message":"{\"data\":{\"id\":2044303883501576,\"id_str\":\"2044303883501576\",\"order_type\":1,\"order_subtype\":5,\"datetime\":\"1787932603\",\"microtimestamp\":\"1787932602967000\",\"amount\":3.02055629,\"amount_str\":\"3.02055629\",\"amount_traded\":\"0\",\"amount_at_create\":\"3.02055629\",\"price\":0.03162186,\"price_str\":\"0.03162186\",\"is_liquidation\":false},\"channel\":\"live_orders_ethbtc\",\"event\":\"order_deleted\",\"event_id\":\"00065a1d-7fae-a3d8-0002-001101000020\",\"pre_event_id\":\"00065a1d-7fae-a3d8-0001-001100000020\",\"order_source\":\"orderbook\"}","recorded_unix_us":1787932603034339}
{"message":"{\"data\":{\"id\":2044303885557764,\"id_str\":\"2044303885557764\",\"order_type\":1,\"order_subtype\":5,\"datetime\":\"1787932603\",\"microtimestamp\":\"1787932602967000\",\"amount\":0.06310787,\"amount_str\":\"0.06310787\",\"amount_traded\":\"0\",\"amount_at_create\":\"0.06310787\",\"price\":78522.38,\"price_str\":\"78522.38\",\"is_liquidation\":false},\"channel\":\"live_orders_btcusd\",\"event\":\"order_created\",\"event_id\":\"00065a1d-7fae-a3d8-0002-000100000020\",\"pre_event_id\":\"00065a1d-7fae-a3d8-0001-000103000020\",\"order_source\":\"orderbook\"}","recorded_unix_us":1787932603034422}
{"message":"{\"data\":{\"id\":2044303885557764,\"id_str\":\"2044303885557764\",\"order_type\":1,\"order_subtype\":5,\"datetime\":\"1787932603\",\"microtimestamp\":\"1787932602967000\",\"amount\":0.06310787,\"amount_str\":\"0.06310787\",\"amount_traded\":\"0\",\"amount_at_create\":\"0.06310787\",\"price\":78522.38,\"price_str\":\"78522.38\",\"is_liquidation\":false},\"channel\":\"live_orders_btcusd\",\"event\":\"order_deleted\",\"event_id\":\"00065a1d-7fae-a3d8-0003-000101000020\",\"pre_event_id\":\"00065a1d-7fae-a3d8-0002-000100000020\",\"order_source\":\"orderbook\"}","recorded_unix_us":1787932603034531}
{"message":"{\"data\":{\"id\":2044303883505675,\"id_str\":\"2044303883505675\",\"order_type\":0,\"order_subtype\":5,\"datetime\":\"1787932603\",\"microtimestamp\":\"1787932602968000\",\"amount\":0.60475617,\"amount_str\":\"0.60475617\",\"amount_traded\":\"0\",\"amount_at_create\":\"0.60475617\",\"price\":0.03158982,\"price_str\":\"0.03158982\",\"is_liquidation\":false},\"channel\":\"live_orders_ethbtc\",\"event\":\"order_deleted\",\"event_id\":\"00065a1d-7fae-a7c0-0000-001102000020\",\"pre_event_id\":\"00065a1d-7fae-a3d8-0002-001101000020\",\"order_source\":\"orderbook\"}","recorded_unix_us":1787932603034553}
{"message":"{\"data\":{\"id\":2044303883509763,\"id_str\":\"2044303883509763\",\"order_type\":0,\"order_subtype\":5,\"datetime\":\"1787932603\",\"microtimestamp\":\"1787932602968000\",\"amount\":1.00801353,\"amount_str\":\"1.00801353\",\"amount_traded\":\"0\",\"amount_at_create\":\"1.00801353\",\"price\":0.03158534,\"price_str\":\"0.03158534\",\"is_liquidation\":false},\"channel\":\"live_orders_ethbtc\",\"event\":\"order_deleted\",\"event_id\":\"00065a1d-7fae-a7c0-0001-001103000020\",\"pre_event_id\":\"00065a1d-7fae-a7c0-0000-001102000020\",\"order_source\":\"orderbook\"}","recorded_unix_us":1787932603034668}
{"message":"{\"data\":{\"id\":2044303883509765,\"id_str\":\"2044303883509765\",\"order_type\":1,\"order_subtype\":5,\"datetime\":\"1787932603\",\"microtimestamp\":\"1787932602968000\",\"amount\":4.02232075,\"amount_str\":\"4.02232075\",\"amount_traded\":\"0\",\"amount_at_create\":\"4.02232075\",\"price\":0.03165997,\"price_str\":\"0.03165997\",\"is_liquidation\":false},\"channel\":\"live_orders_ethbtc\",\"event\":\"order_deleted\",\"event_id\":\"00065a1d-7fae-a7c0-0002-001100000020\",\"pre_event_id\":\"00065a1d-7fae-a7c0-0001-001103000020\",\"order_source\":\"orderbook\"}","recorded_unix_us":1787932603034691}
{"message":"{\"data\":{\"id\":2044303883517953,\"id_str\":\"2044303883517953\",\"order_type\":0,\"order_subtype\":5,\"datetime\":\"1787932603\",\"microtimestamp\":\"1787932602969000\",\"amount\":2.01629689,\"amount_str\":\"2.01629689\",\"amount_traded\":\"0\",\"amount_at_create\":\"2.01629689\",\"price\":0.03157941,\"price_str\":\"0.03157941\",\"is_liquidation\":false},\"channel\":\"live_orders_ethbtc\",\"event\":\"order_deleted\",\"event_id\":\"00065a1d-7fae-aba8-0000-001101000020\",\"pre_event_id\":\"00065a1d-7fae-a7c0-0002-001100000020\",\"order_source\":\"orderbook\"}","recorded_unix_us":1787932603034807}
{"message":"{\"data\":{\"id\":2044303883517972,\"id_str\":\"2044303883517972\",\"order_type\":0,\"order_subtype\":5,\"datetime\":\"1787932603\",\"microtimestamp\":\"1787932602969000\",\"amount\":3.02537254,\"amount_str\":\"3.02537254\",\"amount_traded\":\"0\",\"amount_at_create\":\"3.02537254\",\"price\":0.03156999,\"price_str\":\"0.03156999\",\"is_liquidation\":false},\"channel\":\"live_orders_ethbtc\",\"event\":\"order_deleted\",\"event_id\":\"00065a1d-7fae-aba8-0001-001102000020\",\"pre_event_id\":\"00065a1d-7fae-aba8-0000-001101000020\",\"order_source\":\"orderbook\"}","recorded_unix_us":1787932603034830}
{"message":"{\"data\":{\"id\":2044303883522052,\"id_str\":\"2044303883522052\",\"order_type\":0,\"order_subtype\":5,\"datetime\":\"1787932603\",\"microtimestamp\":\"1787932602969000\",\"amount\":4.03662068,\"amount_str\":\"4.03662068\",\"amount_traded\":\"0\",\"amount_at_create\":\"4.03662068\",\"price\":0.03154857,\"price_str\":\"0.03154857\",\"is_liquidation\":false},\"channel\":\"live_orders_ethbtc\",\"event\":\"order_deleted\",\"event_id\":\"00065a1d-7fae-aba8-0002-001103000020\",\"pre_event_id\":\"00065a1d-7fae-aba8-0001-001102000020\",\"order_source\":\"orderbook\"}","recorded_unix_us":1787932603034957}
{"message":"{\"data\":{\"id\":2044303885144073,\"id_str\":\"2044303885144073\",\"order_type\":0,\"order_subtype\":5,\"datetime\":\"1787932603\",\"microtimestamp\":\"1787932602973000\",\"amount\":0.00140266,\"amount_str\":\"0.00140266\",\"amount_traded\":\"0\",\"amount_at_create\":\"0.00140266\",\"price\":70668.36,\"price_str\":\"70668.36\",\"is_liquidation\":false},\"channel\":\"live_orders_btcusd\",\"event\":\"order_deleted\",\"event_id\":\"00065a1d-7fae-bb48-0000-000102000020\",\"pre_event_id\":\"00065a1d-7fae-a3d8-0003-000101000020\",\"order_source\":\"orderbook\"}","recorded_unix_us":1787932603034984}
{"message":"{\"data\":{\"id\":2044303885467651,\"id_str\":\"2044303885467651\",\"order_type\":0,\"order_subtype\":5,\"datetime\":\"1787932603\",\"microtimestamp\":\"1787932602973000\",\"amount\":0.00140266,\"amount_str\":\"0.00140266\",\"amount_traded\":\"0\",\"amount_at_create\":\"0.00140266\",\"price\":70668.36,\"price_str\":\"70668.36\",\"is_liquidation\":false},\"channel\":\"live_orders_btcusd\",\"event\":\"order_deleted\",\"event_id\":\"00065a1d-7fae-bb48-0001-000103000020\",\"pre_event_id\":\"00065a1d-7fae-bb48-0000-000102000020\",\"order_source\":\"orderbook\"}","recorded_unix_us":1787932603035049}
{"message":"{\"data\":{\"id\":2044303807668230,\"id_str\":\"2044303807668230\",\"order_type\":1,\"order_subtype\":5,\"datetime\":\"1787932603\",\"microtimestamp\":\"1787932602975000\",\"amount\":0.0581,\"amount_str\":\"0.05810000\",\"amount_traded\":\"0\",\"amount_at_create\":\"0.05810000\",\"price\":78673.04,\"price_str\":\"78673.04\",\"is_liquidation\":false},\"channel\":\"live_orders_btcusd\",\"event\":\"order_deleted\",\"event_id\":\"00065a1d-7fae-c318-0000-000100000020\",\"pre_event_id\":\"00065a1d-7fae-bb48-0001-000103000020\",\"order_source\":\"orderbook\"}","recorded_unix_us":1787932603035148}
{"message":"{\"data\":{\"id\":2044303885668352,\"id_str\":\"2044303885668352\",\"order_type\":1,\"order_subtype\":5,\"datetime\":\"1787932603\",\"microtimestamp\":\"1787932602994000\",\"amount\":0.1,\"amount_str\":\"0.10000000\",\"amount_traded\":\"0\",\"amount_at_create\":\"0.10000000\",\"price\":78522.63,\"price_str\":\"78522.63\",\"is_liquidation\":false},\"channel\":\"live_orders_btcusd\",\"event\":\"order_created\",\"event_id\":\"00065a1d-7faf-0d50-0000-000101000020\",\"pre_event_id\":\"00065a1d-7fae-c318-0000-000100000020\",\"order_source\":\"orderbook\"}","recorded_unix_us":1787932603036046}
{"message":"{\"data\":{\"id\":2044303885668352,\"id_str\":\"2044303885668352\",\"order_type\":1,\"order_subtype\":5,\"datetime\":\"1787932603\",\"microtimestamp\":\"1787932602994000\",\"amount\":0.1,\"amount_str\":\"0.10000000\",\"amount_traded\":\"0\",\"amount_at_create\":\"0.10000000\",\"price\":78522.63,\"price_str\":\"78522.63\",\"is_liquidation\":false},\"channel\":\"live_orders_btcusd\",\"event\":\"order_deleted\",\"event_id\":\"00065a1d-7faf-0d50-0001-000102000020\",\"pre_event_id\":\"00065a1d-7faf-0d50-0000-000101000020\",\"order_source\":\"orderbook\"}","recorded_unix_us":1787932603036072}
{"message":"{\"data\":{\"id\":2044303883104262,\"id_str\":\"2044303883104262\",\"order_type\":0,\"order_subtype\":5,\"datetime\":\"1787932603\",\"microtimestamp\":\"1787932602997000\",\"amount\":4.837906,\"amount_str\":\"4.837906\",\"amount_traded\":\"0\",\"amount_at_create\":\"4.837906\",\"price\":2480.24,\"price_str\":\"2480.24\",\"is_liquidation\":false},\"channel\":\"live_orders_ethusd\",\"event\":\"order_deleted\",\"event_id\":\"00065a1d-7faf-1908-0000-001203000020\",\"pre_event_id\":\"00065a1d-7fae-7cc8-0000-001202000020\",\"order_source\":\"orderbook\"}","recorded_unix_us":1787932603042760}
{"message":"{\"data\":{\"id\":2044303885676549,\"id_str\":\"2044303885676549\",\"order_type\":0,\"order_subtype\":5,\"datetime\":\"1787932603\",\"microtimestamp\":\"1787932602997000\",\"amount\":4.837906,\"amount_str\":\"4.837906\",\"amount_traded\":\"0\",\"amount_at_create\":\"4.837906\",\"price\":2480.24,\"price_str\":\"2480.24\",\"is_liquidation\":false},\"channel\":\"live_orders_ethusd\",\"event\":\"order_created\",\"event_id\":\"00065a1d-7faf-1908-0001-001200000020\",\"pre_event_id\":\"00065a1d-7faf-1908-0000-001203000020\",\"order_source\":\"orderbook\"}","recorded_unix_us":1787932603042790}
{"message":"{\"data\":{\"id\":2044303885717504,\"id_str\":\"2044303885717504\",\"order_type\":1,\"order_subtype\":5,\"datetime\":\"1787932603\",\"microtimestamp\":\"1787932603006000\",\"amount\":0.06310787,\"amount_str\":\"0.06310787\",\"amount_traded\":\"0\",\"amount_at_create\":\"0.06310787\",\"price\":78520.09,\"price_str\":\"78520.09\",\"is_liquidation\":false},\"channel\":\"live_orders_btcusd\",\"event\":\"order_created\",\"event_id\":\"00065a1d-7faf-3c30-0000-000103000020\",\"pre_event_id\":\"00065a1d-7faf-0d50-0001-000102000020\",\"order_source\":\"orderbook\"}","recorded_unix_us":1787932603044865}
{"message":"{\"data\":{\"id\":2044303885717504,\"id_str\":\"2044303885717504\",\"order_type\":1,\"order_subtype\":5,\"datetime\":\"1787932603\",\"microtimestamp\":\"1787932603006000\",\"amount\":0.06310787,\"amount_str\":\"0.06310787\",\"amount_traded\":\"0\",\"amount_at_create\":\"0.06310787\",\"price\":78520.09,\"price_str\":\"78520.09\",\"is_liquidation\":false},\"channel\":\"live_orders_btcusd\",\"event\":\"order_deleted\",\"event_id\":\"00065a1d-7faf-3c30-0001-000100000020\",\"pre_event_id\":\"00065a1d-7faf-3c30-0000-000103000020\",\"order_source\":\"orderbook\"}","recorded_unix_us":1787932603055464}
{"message":"{\"data\":{\"id\":2044303885717505,\"id_str\":\"2044303885717505\",\"order_type\":0,\"order_subtype\":5,\"datetime\":\"1787932603\",\"microtimestamp\":\"1787932603006000\",\"amount\":20.235437,\"amount_str\":\"20.235437\",\"amount_traded\":\"0\",\"amount_at_create\":\"20.235437\",\"price\":2470.91,\"price_str\":\"2470.91\",\"is_liquidation\":false},\"channel\":\"live_orders_ethusd\",\"event\":\"order_created\",\"event_id\":\"00065a1d-7faf-3c30-0000-001201000020\",\"pre_event_id\":\"00065a1d-7faf-1908-0001-001200000020\",\"order_source\":\"orderbook\"}","recorded_unix_us":1787932603055495}
{"message":"{\"data\":{\"id\":2044303885725704,\"id_str\":\"2044303885725704\",\"order_type\":1,\"order_subtype\":5,\"datetime\":\"1787932603\",\"microtimestamp\":\"1787932603008000\",\"amount\":0.06310787,\"amount_str\":\"0.06310787\",\"amount_traded\":\"0\",\"amount_at_create\":\"0.06310787\",\"price\":78522.45,\"price_str\":\"78522.45\",\"is_liquidation\":false},\"channel\":\"live_orders_btcusd\",\"event\":\"order_created\",\"event_id\":\"00065a1d-7faf-4400-0000-000101000020\",\"pre_event_id\":\"00065a1d-7faf-3c30-0001-000100000020\",\"order_source\":\"orderbook\"}","recorded_unix_us":1787932603055582}
{"message":"{\"data\":{\"id\":2044303885725704,\"id_str\":\"2044303885725704\",\"order_type\":1,\"order_subtype\":5,\"datetime\":\"1787932603\",\"microtimestamp\":\"1787932603008000\",\"amount\":0.06310787,\"amount_str\":\"0.06310787\",\"amount_traded\":\"0\",\"amount_at_create\":\"0.06310787\",\"price\":78522.45,\"price_str\":\"78522.45\",\"is_liquidation\":false},\"channel\":\"live_orders_btcusd\",\"event\":\"order_deleted\",\"event_id\":\"00065a1d-7faf-4400-0001-000102000020\",\"pre_event_id\":\"00065a1d-7faf-4400-0000-000101000020\",\"order_source\":\"orderbook\"}","recorded_unix_us":1787932603055674}
{"message":"{\"data\":{\"id\":2044303885725703,\"id_str\":\"2044303885725703\",\"order_type\":1,\"order_subtype\":5,\"datetime\":\"1787932603\",\"microtimestamp\":\"1787932603008000\",\"amount\":0.1,\"amount_str\":\"0.10000000\",\"amount_traded\":\"0\",\"amount_at_create\":\"0.10000000\",\"price\":78522.62,\"price_str\":\"78522.62\",\"is_liquidation\":false},\"channel\":\"live_orders_btcusd\",\"event\":\"order_created\",\"event_id\":\"00065a1d-7faf-4400-0002-000103000020\",\"pre_event_id\":\"00065a1d-7faf-4400-0001-000102000020\",\"order_source\":\"orderbook\"}","recorded_unix_us":1787932603055740}
{"message":"{\"data\":{\"id\":2044303885725703,\"id_str\":\"2044303885725703\",\"order_type\":1,\"order_subtype\":5,\"datetime\":\"1787932603\",\"microtimestamp\":\"1787932603008000\",\"amount\":0.1,\"amount_str\":\"0.10000000\",\"amount_traded\":\"0\",\"amount_at_create\":\"0.10000000\",\"price\":78522.62,\"price_str\":\"78522.62\",\"is_liquidation\":false},\"channel\":\"live_orders_btcusd\",\"event\":\"order_deleted\",\"event_id\":\"00065a1d-7faf-4400-0003-000100000020\",\"pre_event_id\":\"00065a1d-7faf-4400-0002-000103000020\",\"order_source\":\"orderbook\"}","recorded_unix_us":1787932603055816}
{"message":"{\"data\":{\"id\":2044303885762566,\"id_str\":\"2044303885762566\",\"order_type\":1,\"order_subtype\":5,\"datetime\":\"1787932603\",\"microtimestamp\":\"1787932603018000\",\"amount\":1.27113313,\"amount_str\":\"1.27113313\",\"amount_traded\":\"0\",\"amount_at_create\":\"1.27113313\",\"price\":78669.97,\"price_str\":\"78669.97\",\"is_liquidation\":false},\"channel\":\"live_orders_btcusd\",\"event\":\"order_created\",\"event_id\":\"00065a1d-7faf-6b10-0000-000101000020\",\"pre_event_id\":\"00065a1d-7faf-4400-0003-000100000020\",\"order_source\":\"orderbook\"}","recorded_unix_us":1787932603069184}
{"message":"{\"data\":{\"id\":2044303885799426,\"id_str\":\"2044303885799426\",\"order_type\":0,\"order_subtype\":5,\"datetime\":\"1787932603\",\"microtimestamp\":\"1787932603027000\",\"amount\":0.00140266,\"amount_str\":\"0.00140266\",\"amount_traded\":\"0\",\"amount_at_create\":\"0.00140266\",\"price\":70666.76,\"price_str\":\"70666.76\",\"is_liquidation\":false},\"channel\":\"live_orders_btcusd\",\"event\":\"order_created\",\"event_id\":\"00065a1d-7faf-8e38-0000-000102000020\",\"pre_event_id\":\"00065a1d-7faf-6b10-0000-000101000020\",\"order_source\":\"orderbook\"}","recorded_unix_us":1787932603069342}
{"message":"{\"data\":{\"id\":2044303885807617,\"id_str\":\"2044303885807617\",\"order_type\":1,\"order_subtype\":5,\"datetime\":\"1787932603\",\"microtimestamp\":\"1787932603028000\",\"amount\":0.1,\"amount_str\":\"0.10000000\",\"amount_traded\":\"0\",\"amount_at_create\":\"0.10000000\",\"price\":78522.63,\"price_str\":\"78522.63\",\"is_liquidation\":false},\"channel\":\"live_orders_btcusd\",\"event\":\"order_created\",\"event_id\":\"00065a1d-7faf-9220-0000-000103000020\",\"pre_event_id\":\"00065a1d-7faf-8e38-0000-000102000020\",\"order_source\":\"orderbook\"}","recorded_unix_us":1787932603069449}
{"message":"{\"data\":{\"id\":2044303885807617,\"id_str\":\"2044303885807617\",\"order_type\":1,\"order_subtype\":5,\"datetime\":\"1787932603\",\"microtimestamp\":\"1787932603028000\",\"amount\":0.1,\"amount_str\":\"0.10000000\",\"amount_traded\":\"0\",\"amount_at_create\":\"0.10000000\",\"price\":78522.63,\"price_str\":\"78522.63\",\"is_liquidation\":false},\"channel\":\"live_orders_btcusd\",\"event\":\"order_deleted\",\"event_id\":\"00065a1d-7faf-9220-0001-000100000020\",\"pre_event_id\":\"00065a1d-7faf-9220-0000-000103000020\",\"order_source\":\"orderbook\"}","recorded_unix_us":1787932603069524}
{"message":"{\"data\":{\"id\":2044303885819905,\"id_str\":\"2044303885819905\",\"order_type\":0,\"order_subtype\":0,\"datetime\":\"1787932603\",\"microtimestamp\":\"1787932603031000\",\"amount\":1.35688,\"amount_str\":\"1.35688000\",\"amount_traded\":\"0\",\"amount_at_create\":\"1.35688000\",\"price\":0.03017117,\"price_str\":\"0.03017117\",\"is_liquidation\":false},\"channel\":\"live_orders_ethbtc\",\"event\":\"order_created\",\"event_id\":\"00065a1d-7faf-9dd8-0000-001100000020\",\"pre_event_id\":\"00065a1d-7fae-aba8-0002-001103000020\",\"order_source\":\"orderbook\"}","recorded_unix_us":1787932603084491}
{"message":"{\"data\":{\"id\":2044303883931650,\"id_str\":\"2044303883931650\",\"order_type\":1,\"order_subtype\":5,\"datetime\":\"1787932603\",\"microtimestamp\":\"1787932603033000\",\"amount\":2.01528391,\"amount_str\":\"2.01528391\",\"amount_traded\":\"0\",\"amount_at_create\":\"2.01528391\",\"price\":0.03160361,\"price_str\":\"0.03160361\",\"is_liquidation\":false},\"channel\":\"live_orders_ethbtc\",\"event\":\"order_deleted\",\"event_id\":\"00065a1d-7faf-a5a8-0000-001101000020\",\"pre_event_id\":\"00065a1d-7faf-9dd8-0000-001100000020\",\"order_source\":\"orderbook\"}","recorded_unix_us":1787932603084691}
{"message":"{\"data\":{\"id\":2044303885852688,\"id_str\":\"2044303885852688\",\"order_type\":1,\"order_subtype\":5,\"datetime\":\"1787932603\",\"microtimestamp\":\"1787932603040000\",\"amount\":0.6044871,\"amount_str\":\"0.60448710\",\"amount_traded\":\"0\",\"amount_at_create\":\"0.60448710\",\"price\":0.03160362,\"price_str\":\"0.03160362\",\"is_liquidation\":false},\"channel\":\"live_orders_ethbtc\",\"event\":\"order_created\",\"event_id\":\"00065a1d-7faf-c100-0000-001102000020\",\"pre_event_id\":\"00065a1d-7faf-a5a8-0000-001101000020\",\"order_source\":\"orderbook\"}","recorded_unix_us":1787932603084930}
{"message":"{\"data\":{\"id\":2044303885869060,\"id_str\":\"2044303885869060\",\"order_type\":1,\"order_subtype\":5,\"datetime\":\"1787932603\",\"microtimestamp\":\"1787932603043000\",\"amount\":0.06310787,\"amount_str\":\"0.06310787\",\"amount_traded\":\"0\",\"amount_at_create\":\"0.06310787\",\"price\":78520.06,\"price_str\":\"78520.06\",\"is_liquidation\":false},\"channel\":\"live_orders_btcusd\",\"event\":\"order_created\",\"event_id\":\"00065a1d-7faf-ccb8-0000-000101000020\",\"pre_event_id\":\"00065a1d-7faf-9220-0001-000100000020\",\"order_source\":\"orderbook\"}","recorded_unix_us":1787932603085056}
{"message":"{\"data\":{\"id\":2044303885869060,\"id_str\":\"2044303885869060\",\"order_type\":1,\"order_subtype\":5,\"datetime\":\"1787932603\",\"microtimestamp\":\"1787932603043000\",\"amount\":0.06310787,\"amount_str\":\"0.06310787\",\"amount_traded\":\"0\",\"amount_at_create\":\"0.06310787\",\"price\":78520.06,\"price_str\":\"78520.06\",\"is_liquidation\":false},\"channel\":\"live_orders_btcusd\",\"event\":\"order_deleted\",\"event_id\":\"00065a1d-7faf-ccb8-0001-000102000020\",\"pre_event_id\":\"00065a1d-7faf-ccb8-0000-000101000020\",\"order_source\":\"orderbook\"}","recorded_unix_us":1787932603085120}
{"message":"{\"data\":{\"id\":2044303885869065,\"id_str\":\"2044303885869065\",\"order_type\":1,\"order_subtype\":5,\"datetime\":\"1787932603\",\"microtimestamp\":\"1787932603043000\",\"amount\":0.06310787,\"amount_str\":\"0.06310787\",\"amount_traded\":\"0\",\"amount_at_create\":\"0.06310787\",\"price\":78522.42,\"price_str\":\"78522.42\",\"is_liquidation\":false},\"channel\":\"live_orders_btcusd\",\"event\":\"order_created\",\"event_id\":\"00065a1d-7faf-ccb8-0002-000103000020\",\"pre_event_id\":\"00065a1d-7faf-ccb8-0001-000102000020\",\"order_source\":\"orderbook\"}","recorded_unix_us":1787932603208570}
{"message":"{\"data\":{\"id\":2044303885869065,\"id_str\":\"2044303885869065\",\"order_type\":1,\"order_subtype\":5,\"datetime\":\"1787932603\",\"microtimestamp\":\"1787932603043000\",\"amount\":0.06310787,\"amount_str\":\"0.06310787\",\"amount_traded\":\"0\",\"amount_at_create\":\"0.06310787\",\"price\":78522.42,\"price_str\":\"78522.42\",\"is_liquidation\":false},\"channel\":\"live_orders_btcusd\",\"event\":\"order_deleted\",\"event_id\":\"00065a1d-7faf-ccb8-0003-000100000020\",\"pre_event_id\":\"00065a1d-7faf-ccb8-0002-000103000020\",\"order_source\":\"orderbook\"}","recorded_unix_us":1787932603208680}
{"message":"{\"data\":{\"id\":2044303885873156,\"id_str\":\"2044303885873156\",\"order_type\":1,\"order_subtype\":5,\"datetime\":\"1787932603\",\"microtimestamp\":\"1787932603044000\",\"amount\":0.06367563,\"amount_str\":\"0.06367563\",\"amount_traded\":\"0\",\"amount_at_create\":\"0.06367563\",\"price\":78522.98,\"price_str\":\"78522.98\",\"is_liquidation\":false},\"channel\":\"live_orders_btcusd\",\"event\":\"order_created\",\"event_id\":\"00065a1d-7faf-d0a0-0000-000101000020\",\"pre_event_id\":\"00065a1d-7faf-ccb8-0003-000100000020\",\"order_source\":\"orderbook\"}","recorded_unix_us":1787932603208932}
{"message":"{\"data\":{\"id\":2044303885873160,\"id_str\":\"2044303885873160\",\"order_type\":1,\"order_subtype\":5,\"datetime\":\"1787932603\",\"microtimestamp\":\"1787932603044000\",\"amount\":0.1,\"amount_str\":\"0.10000000\",\"amount_traded\":\"0\",\"amount_at_create\":\"0.10000000\",\"price\":78522.62,\"price_str\":\"78522.62\",\"is_liquidation\":false},\"channel\":\"live_orders_btcusd\",\"event\":\"order_created\",\"event_id\":\"00065a1d-7faf-d0a0-0001-000102000020\",\"pre_event_id\":\"00065a1d-7faf-d0a0-0000-000101000020\",\"order_source\":\"orderbook\"}","recorded_unix_us":1787932603208999}
{"message":"{\"data\":{\"id\":2044303885873160,\"id_str\":\"2044303885873160\",\"order_type\":1,\"order_subtype\":5,\"datetime\":\"1787932603\",\"microtimestamp\":\"1787932603044000\",\"amount\":0.1,\"amount_str\":\"0.10000000\",\"amount_traded\":\"0\",\"amount_at_create\":\"0.10000000\",\"price\":78522.62,\"price_str\":\"78522.62\",\"is_liquidation\":false},\"channel\":\"live_orders_btcusd\",\"event\":\"order_deleted\",\"event_id\":\"00065a1d-7faf-d0a0-0002-000103000020\",\"pre_event_id\":\"00065a1d-7faf-d0a0-0001-000102000020\",\"order_source\":\"orderbook\"}","recorded_unix_us":1787932603209038}
{"message":"{\"data\":{\"id\":2044303885881344,\"id_str\":\"2044303885881344\",\"order_type\":1,\"order_subtype\":5,\"datetime\":\"1787932603\",\"microtimestamp\":\"1787932603046000\",\"amount\":0.06367384,\"amount_str\":\"0.06367384\",\"amount_traded\":\"0\",\"amount_at_create\":\"0.06367384\",\"price\":78525.19,\"price_str\":\"78525.19\",\"is_liquidation\":false},\"channel\":\"live_orders_btcusd\",\"event\":\"order_created\",\"event_id\":\"00065a1d-7faf-d870-0000-000100000020\",\"pre_event_id\":\"00065a1d-7faf-d0a0-0002-000103000020\",\"order_source\":\"orderbook\"}","recorded_unix_us":1787932603209189}
{"message":"{\"data\":{\"id\":2044303885893633,\"id_str\":\"2044303885893633\",\"order_type\":1,\"order_subtype\":5,\"datetime\":\"1787932603\",\"microtimestamp\":\"1787932603049000\",\"amount\":0.25467128,\"amount_str\":\"0.25467128\",\"amount_traded\":\"0\",\"amount_at_create\":\"0.25467128\",\"price\":78532.61,\"price_str\":\"78532.61\",\"is_liquidation\":false},\"channel\":\"live_orders_btcusd\",\"event\":\"order_created\",\"event_id\":\"00065a1d-7faf-e428-0000-000101000020\",\"pre_event_id\":\"00065a1d-7faf-d870-0000-000100000020\",\"order_source\":\"orderbook\"}","recorded_unix_us":1787932603209308}
{"message":"{\"data\":{\"id\":2044303885922310,\"id_str\":\"2044303885922310\",\"order_type\":1,\"order_subtype\":5,\"datetime\":\"1787932603\",\"microtimestamp\":\"1787932603057000\",\"amount\":0.224274,\"amount_str\":\"0.224274\",\"amount_traded\":\"0\",\"amount_at_create\":\"0.224274\",\"price\":2481,\"price_str\":\"2481.00\",\"is_liquidation\":false},\"channel\":\"live_orders_ethusd\",\"event\":\"order_created\",\"event_id\":\"00065a1d-7fb0-0368-0000-001202000020\",\"pre_event_id\":\"00065a1d-7faf-3c30-0000-001201000020\",\"order_source\":\"orderbook\"}","recorded_unix_us":1787932603209428}
{"message":"{\"data\":{\"id\":2044303885922311,\"id_str\":\"2044303885922311\",\"order_type\":1,\"order_subtype\":5,\"datetime\":\"1787932603\",\"microtimestamp\":\"1787932603057000\",\"amount\":12.70451953,\"amount_str\":\"12.70451953\",\"amount_traded\":\"0\",\"amount_at_create\":\"12.70451953\",\"price\":78712.15,\"price_str\":\"78712.15\",\"is_liquidation\":false},\"channel\":\"live_orders_btcusd\",\"event\":\"order_created\",\"event_id\":\"00065a1d-7fb0-0368-0000-000102000020\",\"pre_event_id\":\"00065a1d-7faf-e428-0000-000101000020\",\"order_source\":\"orderbook\"}","recorded_unix_us":1787932603209539}
{"message":"{\"data\":{\"id\":2044303885926400,\"id_str\":\"2044303885926400\",\"order_type\":1,\"order_subtype\":5,\"datetime\":\"1787932603\",\"microtimestamp\":\"1787932603057000\",\"amount\":0.25466146,\"amount_str\":\"0.25466146\",\"amount_traded\":\"0\",\"amount_at_create\":\"0.25466146\",\"price\":78535.64,\"price_str\":\"78535.64\",\"is_liquidation\":false},\"channel\":\"live_orders_btcusd\",\"event\":\"order_created\",\"event_id\":\"00065a1d-7fb0-0368-0001-000103000020\",\"pre_event_id\":\"00065a1d-7fb0-0368-0000-000102000020\",\"order_source\":\"orderbook\"}","recorded_unix_us":1787932603209731}
{"message":"{\"data\":{\"id\":2044303885926405,\"id_str\":\"2044303885926405\",\"order_type\":1,\"order_subtype\":5,\"datetime\":\"1787932603\",\"microtimestamp\":\"1787932603058000\",\"amount\":1.26970017,\"amount_str\":\"1.26970017\",\"amount_traded\":\"0\",\"amount_at_create\":\"1.26970017\",\"price\":78758.76,\"price_str\":\"78758.76\",\"is_liquidation\":false},\"channel\":\"live_orders_btcusd\",\"event\":\"order_created\",\"event_id\":\"00065a1d-7fb0-0750-0000-000100000020\",\"pre_event_id\":\"00065a1d-7fb0-0368-0001-000103000020\",\"order_source\":\"orderbook\"}","recorded_unix_us":1787932603209768}
{"message":"{\"data\":{\"id\":2044303885926406,\"id_str\":\"2044303885926406\",\"order_type\":1,\"order_subtype\":5,\"datetime\":\"1787932603\",\"microtimestamp\":\"1787932603058000\",\"amount\":1.27209222,\"amount_str\":\"1.27209222\",\"amount_traded\":\"0\",\"amount_at_create\":\"1.27209222\",\"price\":78610.66,\"price_str\":\"78610.66\",\"is_liquidation\":false},\"channel\":\"live_orders_btcusd\",\"event\":\"order_created\",\"event_id\":\"00065a1d-7fb0-0750-0001-000101000020\",\"pre_event_id\":\"00065a1d-7fb0-0750-0000-000100000020\",\"order_source\":\"orderbook\"}","recorded_unix_us":1787932603209797}
{"message":"{\"data\":{\"id\":2044303882711043,\"id_str\":\"2044303882711043\",\"order_type\":0,\"order_subtype\":0,\"datetime\":\"1787932603\",\"microtimestamp\":\"1787932603059000\",\"amount\":0.042863,\"amount_str\":\"0.042863\",\"amount_traded\":\"0\",\"amount_at_create\":\"0.042863\",\"price\":2472.09,\"price_str\":\"2472.09\",\"is_liquidation\":false},\"channel\":\"live_orders_ethusd\",\"event\":\"order_deleted\",\"event_id\":\"00065a1d-7fb0-0b38-0000-001203000020\",\"pre_event_id\":\"00065a1d-7fb0-0368-0000-001202000020\",\"order_source\":\"orderbook\"}","recorded_unix_us":1787932603209983}
{"message":"{\"data\":{\"id\":2044303885930505,\"id_str\":\"2044303885930505\",\"order_type\":0,\"order_subtype\":0,\"datetime\":\"1787932603\",\"microtimestamp\":\"1787932603059000\",\"amount\":0.042865,\"amount_str\":\"0.042865\",\"amount_traded\":\"0\",\"amount_at_create\":\"0.042865\",\"price\":2472.09,\"price_str\":\"2472.09\",\"is_liquidation\":false},\"channel\":\"live_orders_ethusd\",\"event\":\"order_created\",\"event_id\":\"00065a1d-7fb0-0b38-0001-001200000020\",\"pre_event_id\":\"00065a1d-7fb0-0b38-0000-001203000020\",\"order_source\":\"orderbook\"}","recorded_unix_us":1787932603210053}
{"message":"{\"data\":{\"id\":2044303885934597,\"id_str\":\"2044303885934597\",\"order_type\":1,\"order_subtype\":5,\"datetime\":\"1787932603\",\"microtimestamp\":\"1787932603060000\",\"amount\":1.2684012,\"amount_str\":\"1.26840120\",\"amount_traded\":\"0\",\"amount_at_create\":\"1.26840120\",\"price\":78839.41,\"price_str\":\"78839.41\",\"is_liquidation\":false},\"channel\":\"live_orders_btcusd\",\"event\":\"order_created\",\"event_id\":\"00065a1d-7fb0-0f20-0000-000102000020\",\"pre_event_id\":\"00065a1d-7fb0-0750-0001-000101000020\",\"order_source\":\"orderbook\"}","recorded_unix_us":1787932603210090}
{"message":"{\"data\":{\"id\":2044303881838592,\"id_str\":\"2044303881838592\",\"order_type\":0,\"order_subtype\":5,\"datetime\":\"1787932603\",\"microtimestamp\":\"1787932603060000\",\"amount\":3,\"amount_str\":\"3.000000\",\"amount_traded\":\"0\",\"amount_at_create\":\"3.000000\",\"price\":2479.81,\"price_str\":\"2479.81\",\"is_liquidation\":false},\"channel\":\"live_orders_ethusd\",\"event\":\"order_deleted\",\"event_id\":\"00065a1d-7fb0-0f20-0000-001201000020\",\"pre_event_id\":\"00065a1d-7fb0-0b38-0001-001200000020\",\"order_source\":\"orderbook\"}","recorded_unix_us":1787932603210292}
{"message":"{\"data\":{\"id\":2044303881830404,\"id_str\":\"2044303881830404\",\"order_type\":0,\"order_subtype\":5,\"datetime\":\"1787932603\",\"microtimestamp\":\"1787932603060000\",\"amount\":3,\"amount_str\":\"3.000000\",\"amount_traded\":\"0\",\"amount_at_create\":\"3.000000\",\"price\":2479.81,\"price_str\":\"2479.81\",\"is_liquidation\":false},\"channel\":\"live_orders_ethusd\",\"event\":\"order_deleted\",\"event_id\":\"00065a1d-7fb0-0f20-0001-001202000020\",\"pre_event_id\":\"00065a1d-7fb0-0f20-0000-001201000020\",\"order_source\":\"orderbook\"}","recorded_unix_us":1787932603210331}
{"message":"{\"data\":{\"id\":2044303881842690,\"id_str\":\"2044303881842690\",\"order_type\":0,\"order_subtype\":5,\"datetime\":\"1787932603\",\"microtimestamp\":\"1787932603061000\",\"amount\":5,\"amount_str\":\"5.000000\",\"amount_traded\":\"0\",\"amount_at_create\":\"5.000000\",\"price\":2480.06,\"price_str\":\"2480.06\",\"is_liquidation\":false},\"channel\":\"live_orders_ethusd\",\"event\":\"order_deleted\",\"event_id\":\"00065a1d-7fb0-1308-0000-001203000020\",\"pre_event_id\":\"00065a1d-7fb0-0f20-0001-001202000020\",\"order_source\":\"orderbook\"}","recorded_unix_us":1787932603210359}
{"message":"{\"data\":{\"id\":2044303881867264,\"id_str\":\"2044303881867264\",\"order_type\":0,\"order_subtype\":5,\"datetime\":\"1787932603\",\"microtimestamp\":\"1787932603061000\",\"amount\":2,\"amount_str\":\"2.000000\",\"amount_traded\":\"0\",\"amount_at_create\":\"2.000000\",\"price\":2479.07,\"price_str\":\"2479.07\",\"is_liquidation\":false},\"channel\":\"live_orders_ethusd\",\"event\":\"order_deleted\",\"event_id\":\"00065a1d-7fb0-1308-0001-001200000020\",\"pre_event_id\":\"00065a1d-7fb0-1308-0000-001203000020\",\"order_source\":\"orderbook\"}","recorded_unix_us":1787932603210496}
{"message":"{\"data\":{\"id\":2044303884935174,\"id_str\":\"2044303884935174\",\"order_type\":0,\"order_subtype\":5,\"datetime\":\"1787932603\",\"microtimestamp\":\"1787932603062000\",\"amount\":6,\"amount_str\":\"6.000000\",\"amount_traded\":\"0\",\"amount_at_create\":\"6.000000\",\"price\":2479.07,\"price_str\":\"2479.07\",\"is_liquidation\":false},\"channel\":\"live_orders_ethusd\",\"event\":\"order_deleted\",\"event_id\":\"00065a1d-7fb0-16f0-0000-001201000020\",\"pre_event_id\":\"00065a1d-7fb0-1308-0001-001200000020\",\"order_source\":\"orderbook\"}","recorded_unix_us":1787932603210533}
{"message":"{\"data\":{\"id\":2044303885959171,\"id_str\":\"2044303885959171\",\"order_type\":1,\"order_subtype\":5,\"datetime\":\"1787932603\",\"microtimestamp\":\"1787932603066000\",\"amount\":0.1,\"amount_str\":\"0.10000000\",\"amount_traded\":\"0\",\"amount_at_create\":\"0.10000000\",\"price\":78522.63,\"price_str\":\"78522.63\",\"is_liquidation\":false},\"channel\":\"live_orders_btcusd\",\"event\":\"order_created\",\"event_id\":\"00065a1d-7fb0-2690-0000-000103000020\",\"pre_event_id\":\"00065a1d-7fb0-0f20-0000-000102000020\",\"order_source\":\"orderbook\"}","recorded_unix_us":1787932603210636}
{"message":"{\"data\":{\"id\":2044303885959171,\"id_str\":\"2044303885959171\",\"order_type\":1,\"order_subtype\":5,\"datetime\":\"1787932603\",\"microtimestamp\":\"1787932603066000\",\"amount\":0.1,\"amount_str\":\"0.10000000\",\"amount_traded\":\"0\",\"amount_at_create\":\"0.10000000\",\"price\":78522.63,\"price_str\":\"78522.63\",\"is_liquidation\":false},\"channel\":\"live_orders_btcusd\",\"event\":\"order_deleted\",\"event_id\":\"00065a1d-7fb0-2690-0001-000100000020\",\"pre_event_id\":\"00065a1d-7fb0-2690-0000-000103000020\",\"order_source\":\"orderbook\"}","recorded_unix_us":1787932603210735}
{"message":"{\"data\":{\"id\":2044303885975552,\"id_str\":\"2044303885975552\",\"order_type\":1,\"order_subtype\":5,\"datetime\":\"1787932603\",\"microtimestamp\":\"1787932603069000\",\"amount\":0.00395045,\"amount_str\":\"0.00395045\",\"amount_traded\":\"0\",\"amount_at_create\":\"0.00395045\",\"price\":78522.64,\"price_str\":\"78522.64\",\"is_liquidation\":false},\"channel\":\"live_orders_btcusd\",\"event\":\"order_created\",\"event_id\":\"00065a1d-7fb0-3248-0000-000101000020\",\"pre_event_id\":\"00065a1d-7fb0-2690-0001-000100000020\",\"order_source\":\"orderbook\"}","recorded_unix_us":1787932603210837}
{"message":"{\"data\":{\"id\":2044303885979653,\"id_str\":\"2044303885979653\",\"order_type\":0,\"order_subtype\":5,\"datetime\":\"1787932603\",\"microtimestamp\":\"1787932603071000\",\"amount\":0.06368171,\"amount_str\":\"0.06368171\",\"amount_traded\":\"0\",\"amount_at_create\":\"0.06368171\",\"price\":78515.46,\"price_str\":\"78515.46\",\"is_liquidation\":false},\"channel\":\"live_orders_btcusd\",\"event\":\"order_created\",\"event_id\":\"00065a1d-7fb0-3a18-0000-000102000020\",\"pre_event_id\":\"00065a1d-7fb0-3248-0000-000101000020\",\"order_source\":\"orderbook\"}","recorded_unix_us":1787932603210932}
{"message":"{\"data\":{\"id\":2044303885983753,\"id_str\":\"2044303885983753\",\"order_type\":0,\"order_subtype\":5,\"datetime\":\"1787932603\",\"microtimestamp\":\"1787932603071000\",\"amount\":0.06367953,\"amount_str\":\"0.06367953\",\"amount_traded\":\"0\",\"amount_at_create\":\"0.06367953\",\"price\":78518.15,\"price_str\":\"78518.15\",\"is_liquidation\":false},\"channel\":\"live_orders_btcusd\",\"event\":\"order_created\",\"event_id\":\"00065a1d-7fb0-3a18-0001-000103000020\",\"pre_event_id\":\"00065a1d-7fb0-3a18-0000-000102000020\",\"order_source\":\"orderbook\"}","recorded_unix_us":1787932603211031}
{"message":"{\"data\":{\"id\":2044303885983754,\"id_str\":\"2044303885983754\",\"order_type\":0,\"order_subtype\":5,\"datetime\":\"1787932603\",\"microtimestamp\":\"1787932603071000\",\"amount\":0.25478772,\"amount_str\":\"0.25478772\",\"amount_traded\":\"0\",\"amount_at_create\":\"0.25478772\",\"price\":78496.71,\"price_str\":\"78496.71\",\"is_liquidation\":false},\"channel\":\"live_orders_btcusd\",\"event\":\"order_created\",\"event_id\":\"00065a1d-7fb0-3a18-0002-000100000020\",\"pre_event_id\":\"00065a1d-7fb0-3a18-0001-000103000020\",\"order_source\":\"orderbook\"}","recorded_unix_us":1787932603211129}
{"message":"{\"data\":{\"id\":2044303885987844,\"id_str\":\"2044303885987844\",\"order_type\":0,\"order_subtype\":5,\"datetime\":\"1787932603\",\"microtimestamp\":\"1787932603072000\",\"amount\":0.25476924,\"amount_str\":\"0.25476924\",\"amount_traded\":\"0\",\"amount_at_create\":\"0.25476924\",\"price\":78502.41,\"price_str\":\"78502.41\",\"is_liquidation\":false},\"channel\":\"live_orders_btcusd\",\"event\":\"order_created\",\"event_id\":\"00065a1d-7fb0-3e00-0000-000101000020\",\"pre_event_id\":\"00065a1d-7fb0-3a18-0002-000100000020\",\"order_source\":\"orderbook\"}","recorded_unix_us":1787932603211245}
{"message":"{\"data\":{\"id\":2044303885987846,\"id_str\":\"2044303885987846\",\"order_type\":0,\"order_subtype\":5,\"datetime\":\"1787932603\",\"microtimestamp\":\"1787932603072000\",\"amount\":3.942649,\"amount_str\":\"3.942649\",\"amount_traded\":\"0\",\"amount_at_create\":\"3.942649\",\"price\":2480.3,\"price_str\":\"2480.30\",\"is_liquidation\":false},\"channel\":\"live_orders_ethusd\",\"event\":\"order_created\",\"event_id\":\"00065a1d-7fb0-3e00-0000-001202000020\",\"pre_event_id\":\"00065a1d-7fb0-16f0-0000-001201000020\",\"order_source\":\"orderbook\"}","recorded_unix_us":1787932603211372}
{"message":"{\"data\":{\"id\":2044303886000129,\"id_str\":\"2044303886000129\",\"order_type\":0,\"order_subtype\":5,\"datetime\":\"1787932603\",\"microtimestamp\":\"1787932603075000\",\"amount\":0.60475617,\"amount_str\":\"0.60475617\",\"amount_traded\":\"0\",\"amount_at_create\":\"0.60475617\",\"price\":0.03158982,\"price_str\":\"0.03158982\",\"is_liquidation\":false},\"channel\":\"live_orders_ethbtc\",\"event\":\"order_created\",\"event_id\":\"00065a1d-7fb0-49b8-0000-001103000020\",\"pre_event_id\":\"00065a1d-7faf-c100-0000-001102000020\",\"order_source\":\"orderbook\"}","recorded_unix_us":1787932603211481}
{"message":"{\"data\":{\"id\":2044303886000130,\"id_str\":\"2044303886000130\",\"order_type\":1,\"order_subtype\":5,\"datetime\":\"1787932603\",\"microtimestamp\":\"1787932603075000\",\"amount\":1.007365,\"amount_str\":\"1.00736500\",\"amount_traded\":\"0\",\"amount_at_create\":\"1.00736500\",\"price\":0.03160719,\"price_str\":\"0.03160719\",\"is_liquidation\":false},\"channel\":\"live_orders_ethbtc\",\"event\":\"order_created\",\"event_id\":\"00065a1d-7fb0-49b8-0001-001100000020\",\"pre_event_id\":\"00065a1d-7fb0-49b8-0000-001103000020\",\"order_source\":\"orderbook\"}","recorded_unix_us":1787932603211617}
{"message":"{\"data\":{\"id\":2044303886000131,\"id_str\":\"2044303886000131\",\"order_type\":1,\"order_subtype\":5,\"datetime\":\"1787932603\",\"microtimestamp\":\"1787932603076000\",\"amount\":4.02232075,\"amount_str\":\"4.02232075\",\"amount_traded\":\"0\",\"amount_at_create\":\"4.02232075\",\"price\":0.03165997,\"price_str\":\"0.03165997\",\"is_liquidation\":false},\"channel\":\"live_orders_ethbtc\",\"event\":\"order_created\",\"event_id\":\"00065a1d-7fb0-4da0-0000-001101000020\",\"pre_event_id\":\"00065a1d-7fb0-49b8-0001-001100000020\",\"order_source\":\"orderbook\"}","recorded_unix_us":1787932603211652}
{"message":"{\"data\":{\"id\":2044303886000133,\"id_str\":\"2044303886000133\",\"order_type\":1,\"order_subtype\":5,\"datetime\":\"1787932603\",\"microtimestamp\":\"1787932603076000\",\"amount\":3.02055629,\"amount_str\":\"3.02055629\",\"amount_traded\":\"0\",\"amount_at_create\":\"3.02055629\",\"price\":0.03162186,\"price_str\":\"0.03162186\",\"is_liquidation\":false},\"channel\":\"live_orders_ethbtc\",\"event\":\"order_created\",\"event_id\":\"00065a1d-7fb0-4da0-0001-001102000020\",\"pre_event_id\":\"00065a1d-7fb0-4da0-0000-001101000020\",\"order_source\":\"orderbook\"}","recorded_unix_us":1787932603211800}
{"message":"{\"data\":{\"id\":2044303886000134,\"id_str\":\"2044303886000134\",\"order_type\":1,\"order_subtype\":5,\"datetime\":\"1787932603\",\"microtimestamp\":\"1787932603076000\",\"amount\":2.01406611,\"amount_str\":\"2.01406611\",\"amount_traded\":\"0\",\"amount_at_create\":\"2.01406611\",\"price\":0.0316176,\"price_str\":\"0.03161760\",\"is_liquidation\":false},\"channel\":\"live_orders_ethbtc\",\"event\":\"order_created\",\"event_id\":\"00065a1d-7fb0-4da0-0002-001103000020\",\"pre_event_id\":\"00065a1d-7fb0-4da0-0001-001102000020\",\"order_source\":\"orderbook\"}","recorded_unix_us":1787932603211843}
{"message":"{\"data\":{\"id\":2044303886004224,\"id_str\":\"2044303886004224\",\"order_type\":0,\"order_subtype\":5,\"datetime\":\"1787932603\",\"microtimestamp\":\"1787932603077000\",\"amount\":1.27541152,\"amount_str\":\"1.27541152\",\"amount_traded\":\"0\",\"amount_at_create\":\"1.27541152\",\"price\":78406.06,\"price_str\":\"78406.06\",\"is_liquidation\":false},\"channel\":\"live_orders_btcusd\",\"event\":\"order_created\",\"event_id\":\"00065a1d-7fb0-5188-0000-000102000020\",\"pre_event_id\":\"00065a1d-7fb0-3e00-0000-000101000020\",\"order_source\":\"orderbook\"}","recorded_unix_us":1787932603211993}
{"message":"{\"data\":{\"id\":2044303886004225,\"id_str\":\"2044303886004225\",\"order_type\":0,\"order_subtype\":5,\"datetime\":\"1787932603\",\"microtimestamp\":\"1787932603077000\",\"amount\":2.01629689,\"amount_str\":\"2.01629689\",\"amount_traded\":\"0\",\"amount_at_create\":\"2.01629689\",\"price\":0.03157941,\"price_str\":\"0.03157941\",\"is_liquidation\":false},\"channel\":\"live_orders_ethbtc\",\"event\":\"order_created\",\"event_id\":\"00065a1d-7fb0-5188-0000-001100000020\",\"pre_event_id\":\"00065a1d-7fb0-4da0-0002-001103000020\",\"order_source\":\"orderbook\"}","recorded_unix_us":1787932603212027}
{"message":"{\"data\":{\"id\":2044303886004226,\"id_str\":\"2044303886004226\",\"order_type\":0,\"order_subtype\":5,\"datetime\":\"1787932603\",\"microtimestamp\":\"1787932603077000\",\"amount\":1.27507828,\"amount_str\":\"1.27507828\",\"amount_traded\":\"0\",\"amount_at_create\":\"1.27507828\",\"price\":78426.55,\"price_str\":\"78426.55\",\"is_liquidation\":false},\"channel\":\"live_orders_btcusd\",\"event\":\"order_created\",\"event_id\":\"00065a1d-7fb0-5188-0001-000103000020\",\"pre_event_id\":\"00065a1d-7fb0-5188-0000-000102000020\",\"order_source\":\"orderbook\"}","recorded_unix_us":1787932603212233}
{"message":"{\"data\":{\"id\":2044303886004227,\"id_str\":\"2044303886004227\",\"order_type\":0,\"order_subtype\":5,\"datetime\":\"1787932603\",\"microtimestamp\":\"1787932603077000\",\"amount\":3.02537254,\"amount_str\":\"3.02537254\",\"amount_traded\":\"0\",\"amount_at_create\":\"3.02537254\",\"price\":0.03156999,\"price_str\":\"0.03156999\",\"is_liquidation\":false},\"channel\":\"live_orders_ethbtc\",\"event\":\"order_created\",\"event_id\":\"00065a1d-7fb0-5188-0001-001101000020\",\"pre_event_id\":\"00065a1d-7fb0-5188-0000-001100000020\",\"order_source\":\"orderbook\"}","recorded_unix_us":1787932603212271}
{"message":"{\"data\":{\"id\":2044303886008320,\"id_str\":\"2044303886008320\",\"order_type\":0,\"order_subtype\":5,\"datetime\":\"1787932603\",\"microtimestamp\":\"1787932603077000\",\"amount\":4.03662068,\"amount_str\":\"4.03662068\",\"amount_traded\":\"0\",\"amount_at_create\":\"4.03662068\",\"price\":0.03154857,\"price_str\":\"0.03154857\",\"is_liquidation\":false},\"channel\":\"live_orders_ethbtc\",\"event\":\"order_created\",\"event_id\":\"00065a1d-7fb0-5188-0002-001102000020\",\"pre_event_id\":\"00065a1d-7fb0-5188-0001-001101000020\",\"order_source\":\"orderbook\"}","recorded_unix_us":1787932603212300}
{"message":"{\"data\":{\"id\":2044303886008321,\"id_str\":\"2044303886008321\",\"order_type\":0,\"order_subtype\":5,\"datetime\":\"1787932603\",\"microtimestamp\":\"1787932603078000\",\"amount\":1.00801353,\"amount_str\":\"1.00801353\",\"amount_traded\":\"0\",\"amount_at_create\":\"1.00801353\",\"price\":0.03158534,\"price_str\":\"0.03158534\",\"is_liquidation\":false},\"channel\":\"live_orders_ethbtc\",\"event\":\"order_created\",\"event_id\":\"00065a1d-7fb0-5570-0000-001103000020\",\"pre_event_id\":\"00065a1d-7fb0-5188-0002-001102000020\",\"order_source\":\"orderbook\"}","recorded_unix_us":1787932603212330}
{"message":"{\"data\":{\"id\":2044303886016513,\"id_str\":\"2044303886016513\",\"order_type\":1,\"order_subtype\":5,\"datetime\":\"1787932603\",\"microtimestamp\":\"1787932603079000\",\"amount\":0.06310787,\"amount_str\":\"0.06310787\",\"amount_traded\":\"0\",\"amount_at_create\":\"0.06310787\",\"price\":78521.08,\"price_str\":\"78521.08\",\"is_liquidation\":false},\"channel\":\"live_orders_btcusd\",\"event\":\"order_created\",\"event_id\":\"00065a1d-7fb0-5958-0000-000100000020\",\"pre_event_id\":\"00065a1d-7fb0-5188-0001-000103000020\",\"order_source\":\"orderbook\"}","recorded_unix_us":1787932603212430}
{"message":"{\"data\":{\"id\":2044303886016513,\"id_str\":\"2044303886016513\",\"order_type\":1,\"order_subtype\":5,\"datetime\":\"1787932603\",\"microtimestamp\":\"1787932603079000\",\"amount\":0.06310787,\"amount_str\":\"0.06310787\",\"amount_traded\":\"0\",\"amount_at_create\":\"0.06310787\",\"price\":78521.08,\"price_str\":\"78521.08\",\"is_liquidation\":false},\"channel\":\"live_orders_btcusd\",\"event\":\"order_deleted\",\"event_id\":\"00065a1d-7fb0-5958-0001-000101000020\",\"pre_event_id\":\"00065a1d-7fb0-5958-0000-000100000020\",\"order_source\":\"orderbook\"}","recorded_unix_us":1787932603212543}
{"message":"{\"data\":{\"id\":2044303886032900,\"id_str\":\"2044303886032900\",\"order_type\":0,\"order_subtype\":5,\"datetime\":\"1787932603\",\"microtimestamp\":\"1787932603084000\",\"amount\":1.27567513,\"amount_str\":\"1.27567513\",\"amount_traded\":\"0\",\"amount_at_create\":\"1.27567513\",\"price\":78389.86,\"price_str\":\"78389.86\",\"is_liquidation\":false},\"channel\":\"live_orders_btcusd\",\"event\":\"order_created\",\"event_id\":\"00065a1d-7fb0-6ce0-0000-000102000020\",\"pre_event_id\":\"00065a1d-7fb0-5958-0001-000101000020\",\"order_source\":\"orderbook\"}","recorded_unix_us":1787932603212771}
{"message":"{\"data\":{\"id\":2044303886045185,\"id_str\":\"2044303886045185\",\"order_type\":1,\"order_subtype\":5,\"datetime\":\"1787932603\",\"microtimestamp\":\"1787932603086000\",\"amount\":0.1,\"amount_str\":\"0.10000000\",\"amount_traded\":\"0\",\"amount_at_create\":\"0.10000000\",\"price\":78522.62,\"price_str\":\"78522.62\",\"is_liquidation\":false},\"channel\":\"live_orders_btcusd\",\"event\":\"order_created\",\"event_id\":\"00065a1d-7fb0-74b0-0000-000103000020\",\"pre_event_id\":\"00065a1d-7fb0-6ce0-0000-000102000020\",\"order_source\":\"orderbook\"}","recorded_unix_us":1787932603212830}
{"message":"{\"data\":{\"id\":2044303886045185,\"id_str\":\"2044303886045185\",\"order_type\":1,\"order_subtype\":5,\"datetime\":\"1787932603\",\"microtimestamp\":\"1787932603086000\",\"amount\":0.1,\"amount_str\":\"0.10000000\",\"amount_traded\":\"0\",\"amount_at_create\":\"0.10000000\",\"price\":78522.62,\"price_str\":\"78522.62\",\"is_liquidation\":false},\"channel\":\"live_orders_btcusd\",\"event\":\"order_deleted\",\"event_id\":\"00065a1d-7fb0-74b0-0001-000100000020\",\"pre_event_id\":\"00065a1d-7fb0-74b0-0000-000103000020\",\"order_source\":\"orderbook\"}","recorded_unix_us":1787932603212953}
{"message":"{\"data\":{\"id\":2044303886045190,\"id_str\":\"2044303886045190\",\"order_type\":0,\"order_subtype\":5,\"datetime\":\"1787932603\",\"microtimestamp\":\"1787932603086000\",\"amount\":12.76418733,\"amount_str\":\"12.76418733\",\"amount_traded\":\"0\",\"amount_at_create\":\"12.76418733\",\"price\":78344.19,\"price_str\":\"78344.19\",\"is_liquidation\":false},\"channel\":\"live_orders_btcusd\",\"event\":\"order_created\",\"event_id\":\"00065a1d-7fb0-74b0-0002-000101000020\",\"pre_event_id\":\"00065a1d-7fb0-74b0-0001-000100000020\",\"order_source\":\"orderbook\"}","recorded_unix_us":1787932603213051}
{"message":"{\"data\":{\"id\":2044303886049281,\"id_str\":\"2044303886049281\",\"order_type\":1,\"order_subtype\":5,\"datetime\":\"1787932603\",\"microtimestamp\":\"1787932603087000\",\"amount\":0.00023149,\"amount_str\":\"0.00023149\",\"amount_traded\":\"0\",\"amount_at_create\":\"0.00023149\",\"price\":78522.64,\"price_str\":\"78522.64\",\"is_liquidation\":false},\"channel\":\"live_orders_btcusd\",\"event\":\"order_created\",\"event_id\":\"00065a1d-7fb0-7898-0000-000102000020\",\"pre_event_id\":\"00065a1d-7fb0-74b0-0002-000101000020\",\"order_source\":\"orderbook\"}","recorded_unix_us":1787932603213207}
{"message":"{\"data\":{\"id\":2044303886073857,\"id_str\":\"2044303886073857\",\"order_type\":0,\"order_subtype\":5,\"datetime\":\"1787932603\",\"microtimestamp\":\"1787932603093000\",\"amount\":1.27757154,\"amount_str\":\"1.27757154\",\"amount_traded\":\"0\",\"amount_at_create\":\"1.27757154\",\"price\":78273.5,\"price_str\":\"78273.50\",\"is_liquidation\":false},\"channel\":\"live_orders_btcusd\",\"event\":\"order_created\",\"event_id\":\"00065a1d-7fb0-9008-0000-000103000020\",\"pre_event_id\":\"00065a1d-7fb0-7898-0000-000102000020\",\"order_source\":\"orderbook\"}","recorded_unix_us":1787932603213313}
{"message":"{\"data\":{\"id\":2044303885799426,\"id_str\":\"2044303885799426\",\"order_type\":0,\"order_subtype\":5,\"datetime\":\"1787932603\",\"microtimestamp\":\"1787932603098000\",\"amount\":0.00140266,\"amount_str\":\"0.00140266\",\"amount_traded\":\"0\",\"amount_at_create\":\"0.00140266\",\"price\":70666.76,\"price_str\":\"70666.76\",\"is_liquidation\":false},\"channel\":\"live_orders_btcusd\",\"event\":\"order_deleted\",\"event_id\":\"00065a1d-7fb0-a390-0000-000100000020\",\"pre_event_id\":\"00065a1d-7fb0-9008-0000-000103000020\",\"order_source\":\"orderbook\"}","recorded_unix_us":1787932603213421}
{"message":"{\"data\":{\"id\":2044303886127105,\"id_str\":\"2044303886127105\",\"order_type\":0,\"order_subtype\":5,\"datetime\":\"1787932603\",\"microtimestamp\":\"1787932603106000\",\"amount\":0.00140266,\"amount_str\":\"0.00140266\",\"amount_traded\":\"0\",\"amount_at_create\":\"0.00140266\",\"price\":70666.76,\"price_str\":\"70666.76\",\"is_liquidation\":false},\"channel\":\"live_orders_btcusd\",\"event\":\"order_created\",\"event_id\":\"00065a1d-7fb0-c2d0-0000-000101000020\",\"pre_event_id\":\"00065a1d-7fb0-a390-0000-000100000020\",\"order_source\":\"orderbook\"}","recorded_unix_us":1787932603213525}
{"message":"{\"data\":{\"id\":2044303886135319,\"id_str\":\"2044303886135319\",\"order_type\":0,\"order_subtype\":0,\"datetime\":\"1787932603\",\"microtimestamp\":\"1787932603109000\",\"amount\":2.016386,\"amount_str\":\"2.016386\",\"amount_traded\":\"0\",\"amount_at_create\":\"2.016386\",\"price\":2480.51,\"price_str\":\"2480.51\",\"is_liquidation\":false},\"channel\":\"live_orders_ethusd\",\"event\":\"order_created\",\"event_id\":\"00065a1d-7fb0-ce88-0000-001203000020\",\"pre_event_id\":\"00065a1d-7fb0-3e00-0000-001202000020\",\"order_source\":\"orderbook\"}","recorded_unix_us":1787932603213624}
{"message":"{\"data\":{\"id\":2044303886127105,\"id_str\":\"2044303886127105\",\"order_type\":0,\"order_subtype\":5,\"datetime\":\"1787932603\",\"microtimestamp\":\"1787932603109000\",\"amount\":0.00140266,\"amount_str\":\"0.00140266\",\"amount_traded\":\"0\",\"amount_at_create\":\"0.00140266\",\"price\":70666.76,\"price_str\":\"70666.76\",\"is_liquidation\":false},\"channel\":\"live_orders_btcusd\",\"event\":\"order_deleted\",\"event_id\":\"00065a1d-7fb0-ce88-0000-000102000020\",\"pre_event_id\":\"00065a1d-7fb0-c2d0-0000-000101000020\",\"order_source\":\"orderbook\"}","recorded_unix_us":1787932603213739}
{"message":"{\"data\":{\"id\":2044303886143490,\"id_str\":\"2044303886143490\",\"order_type\":1,\"order_subtype\":5,\"datetime\":\"1787932603\",\"microtimestamp\":\"1787932603110000\",\"amount\":0.1,\"amount_str\":\"0.10000000\",\"amount_traded\":\"0\",\"amount_at_create\":\"0.10000000\",\"price\":78522.63,\"price_str\":\"78522.63\",\"is_liquidation\":false},\"channel\":\"live_orders_btcusd\",\"event\":\"order_created\",\"event_id\":\"00065a1d-7fb0-d270-0000-000103000020\",\"pre_event_id\":\"00065a1d-7fb0-ce88-0000-000102000020\",\"order_source\":\"orderbook\"}","recorded_unix_us":1787932603213851}
{"message":"{\"data\":{\"id\":2044303886143490,\"id_str\":\"2044303886143490\",\"order_type\":1,\"order_subtype\":5,\"datetime\":\"1787932603\",\"microtimestamp\":\"1787932603110000\",\"amount\":0.1,\"amount_str\":\"0.10000000\",\"amount_traded\":\"0\",\"amount_at_create\":\"0.10000000\",\"price\":78522.63,\"price_str\":\"78522.63\",\"is_liquidation\":false},\"channel\":\"live_orders_btcusd\",\"event\":\"order_deleted\",\"event_id\":\"00065a1d-7fb0-d270-0001-000100000020\",\"pre_event_id\":\"00065a1d-7fb0-d270-0000-000103000020\",\"order_source\":\"orderbook\"}","recorded_unix_us":1787932603213951}
{"message":"{\"data\":{\"id\":2044303886155784,\"id_str\":\"2044303886155784\",\"order_type\":1,\"order_subtype\":5,\"datetime\":\"1787932603\",\"microtimestamp\":\"1787932603114000\",\"amount\":1.26842789,\"amount_str\":\"1.26842789\",\"amount_traded\":\"0\",\"amount_at_create\":\"1.26842789\",\"price\":78837.75,\"price_str\":\"78837.75\",\"is_liquidation\":false},\"channel\":\"live_orders_btcusd\",\"event\":\"order_created\",\"event_id\":\"00065a1d-7fb0-e210-0000-000101000020\",\"pre_event_id\":\"00065a1d-7fb0-d270-0001-000100000020\",\"order_source\":\"orderbook\"}","recorded_unix_us":1787932603214050}
{"message":"{\"data\":{\"id\":2044303886155788,\"id_str\":\"2044303886155788\",\"order_type\":0,\"order_subtype\":5,\"datetime\":\"1787932603\",\"microtimestamp\":\"1787932603114000\",\"amount\":1.27604867,\"amount_str\":\"1.27604867\",\"amount_traded\":\"0\",\"amount_at_create\":\"1.27604867\",\"price\":78366.91,\"price_str\":\"78366.91\",\"is_liquidation\":false},\"channel\":\"live_orders_btcusd\",\"event\":\"order_created\",\"event_id\":\"00065a1d-7fb0-e210-0001-000102000020\",\"pre_event_id\":\"00065a1d-7fb0-e210-0000-000101000020\",\"order_source\":\"orderbook\"}","recorded_unix_us":1787932603214184}
{"message":"{\"data\":{\"id\":2044303886155789,\"id_str\":\"2044303886155789\",\"order_type\":1,\"order_subtype\":5,\"datetime\":\"1787932603\",\"microtimestamp\":\"1787932603114000\",\"amount\":1.271772,\"amount_str\":\"1.27177200\",\"amount_traded\":\"0\",\"amount_at_create\":\"1.27177200\",\"price\":78630.45,\"price_str\":\"78630.45\",\"is_liquidation\":false},\"channel\":\"live_orders_btcusd\",\"event\":\"order_created\",\"event_id\":\"00065a1d-7fb0-e210-0002-000103000020\",\"pre_event_id\":\"00065a1d-7fb0-e210-0001-000102000020\",\"order_source\":\"orderbook\"}","recorded_unix_us":1787932603214221}
{"message":"{\"data\":{\"id\":2044303886159882,\"id_str\":\"2044303886159882\",\"order_type\":0,\"order_subtype\":5,\"datetime\":\"1787932603\",\"microtimestamp\":\"1787932603115000\",\"amount\":1.27817952,\"amount_str\":\"1.27817952\",\"amount_traded\":\"0\",\"amount_at_create\":\"1.27817952\",\"price\":78236.27,\"price_str\":\"78236.27\",\"is_liquidation\":false},\"channel\":\"live_orders_btcusd\",\"event\":\"order_created\",\"event_id\":\"00065a1d-7fb0-e5f8-0000-000100000020\",\"pre_event_id\":\"00065a1d-7fb0-e210-0002-000103000020\",\"order_source\":\"orderbook\"}","recorded_unix_us":1787932603214318}
{"message":"{\"data\":{\"id\":2044303886168076,\"id_str\":\"2044303886168076\",\"order_type\":0,\"order_subtype\":5,\"datetime\":\"1787932603\",\"microtimestamp\":\"1787932603117000\",\"amount\":5,\"amount_str\":\"5.000000\",\"amount_traded\":\"0\",\"amount_at_create\":\"5.000000\",\"price\":2479.8,\"price_str\":\"2479.80\",\"is_liquidation\":false},\"channel\":\"live_orders_ethusd\",\"event\":\"order_created\",\"event_id\":\"00065a1d-7fb0-edc8-0000-001200000020\",\"pre_event_id\":\"00065a1d-7fb0-ce88-0000-001203000020\",\"order_source\":\"orderbook\"}","recorded_unix_us":1787932603214453}
{"message":"{\"data\":{\"id\":2044303886168078,\"id_str\":\"2044303886168078\",\"order_type\":0,\"order_subtype\":5,\"datetime\":\"1787932603\",\"microtimestamp\":\"1787932603117000\",\"amount\":2,\"amount_str\":\"2.000000\",\"amount_traded\":\"0\",\"amount_at_create\":\"2.000000\",\"price\":2480.05,\"price_str\":\"2480.05\",\"is_liquidation\":false},\"channel\":\"live_orders_ethusd\",\"event\":\"order_created\",\"event_id\":\"00065a1d-7fb0-edc8-0001-001201000020\",\"pre_event_id\":\"00065a1d-7fb0-edc8-0000-001200000020\",\"order_source\":\"orderbook\"}","recorded_unix_us":1787932603214494}
{"message":"{\"data\":{\"id\":2044303886180352,\"id_str\":\"2044303886180352\",\"order_type\":0,\"order_subtype\":5,\"datetime\":\"1787932603\",\"microtimestamp\":\"1787932603119000\",\"amount\":3,\"amount_str\":\"3.000000\",\"amount_traded\":\"0\",\"amount_at_create\":\"3.000000\",\"price\":2480.05,\"price_str\":\"2480.05\",\"is_liquidation\":false},\"channel\":\"live_orders_ethusd\",\"event\":\"order_created\",\"event_id\":\"00065a1d-7fb0-f598-0000-001202000020\",\"pre_event_id\":\"00065a1d-7fb0-edc8-0001-001201000020\",\"order_source\":\"orderbook\"}","recorded_unix_us":1787932603214595}
{"message":"{\"data\":{\"id\":2044303886184454,\"id_str\":\"2044303886184454\",\"order_type\":0,\"order_subtype\":5,\"datetime\":\"1787932603\",\"microtimestamp\":\"1787932603120000\",\"amount\":2,\"amount_str\":\"2.000000\",\"amount_traded\":\"0\",\"amount_at_create\":\"2.000000\",\"price\":2479.06,\"price_str\":\"2479.06\",\"is_liquidation\":false},\"channel\":\"live_orders_ethusd\",\"event\":\"order_created\",\"event_id\":\"00065a1d-7fb0-f980-0000-001203000020\",\"pre_event_id\":\"00065a1d-7fb0-f598-0000-001202000020\",\"order_source\":\"orderbook\"}","recorded_unix_us":1787932603214696}
{"message":"{\"data\":{\"id\":2044303886188547,\"id_str\":\"2044303886188547\",\"order_type\":1,\"order_subtype\":5,\"datetime\":\"1787932603\",\"microtimestamp\":\"1787932603121000\",\"amount\":0.06310787,\"amount_str\":\"0.06310787\",\"amount_traded\":\"0\",\"amount_at_create\":\"0.06310787\",\"price\":78520.48,\"price_str\":\"78520.48\",\"is_liquidation\":false},\"channel\":\"live_orders_btcusd\",\"event\":\"order_created\",\"event_id\":\"00065a1d-7fb0-fd68-0000-000101000020\",\"pre_event_id\":\"00065a1d-7fb0-e5f8-0000-000100000020\",\"order_source\":\"orderbook\"}","recorded_unix_us":1787932603214829}
{"message":"{\"data\":{\"id\":2044303886188547,\"id_str\":\"2044303886188547\",\"order_type\":1,\"order_subtype\":5,\"datetime\":\"1787932603\",\"microtimestamp\":\"1787932603121000\",\"amount\":0.06310787,\"amount_str\":\"0.06310787\",\"amount_traded\":\"0\",\"amount_at_create\":\"0.06310787\",\"price\":78520.48,\"price_str\":\"78520.48\",\"is_liquidation\":false},\"channel\":\"live_orders_btcusd\",\"event\":\"order_deleted\",\"event_id\":\"00065a1d-7fb0-fd68-0001-000102000020\",\"pre_event_id\":\"00065a1d-7fb0-fd68-0000-000101000020\",\"order_source\":\"orderbook\"}","recorded_unix_us":1787932603214882}
{"message":"{\"data\":{\"id\":2044303886192644,\"id_str\":\"2044303886192644\",\"order_type\":1,\"order_subtype\":5,\"datetime\":\"1787932603\",\"microtimestamp\":\"1787932603122000\",\"amount\":0.1,\"amount_str\":\"0.10000000\",\"amount_traded\":\"0\",\"amount_at_create\":\"0.10000000\",\"price\":78522.62,\"price_str\":\"78522.62\",\"is_liquidation\":false},\"channel\":\"live_orders_btcusd\",\"event\":\"order_created\",\"event_id\":\"00065a1d-7fb1-0150-0000-000103000020\",\"pre_event_id\":\"00065a1d-7fb0-fd68-0001-000102000020\",\"order_source\":\"orderbook\"}","recorded_unix_us":1787932603215058}
{"message":"{\"data\":{\"id\":2044303886192644,\"id_str\":\"2044303886192644\",\"order_type\":1,\"order_subtype\":5,\"datetime\":\"1787932603\",\"microtimestamp\":\"1787932603122000\",\"amount\":0.1,\"amount_str\":\"0.10000000\",\"amount_traded\":\"0\",\"amount_at_create\":\"0.10000000\",\"price\":78522.62,\"price_str\":\"78522.62\",\"is_liquidation\":false},\"channel\":\"live_orders_btcusd\",\"event\":\"order_deleted\",\"event_id\":\"00065a1d-7fb1-0150-0001-000100000020\",\"pre_event_id\":\"00065a1d-7fb1-0150-0000-000103000020\",\"order_source\":\"orderbook\"}","recorded_unix_us":1787932603215091}
{"message":"{\"data\":{\"id\":2044303886196740,\"id_str\":\"2044303886196740\",\"order_type\":0,\"order_subtype\":5,\"datetime\":\"1787932603\",\"microtimestamp\":\"1787932603123000\",\"amount\":1,\"amount_str\":\"1.000000\",\"amount_traded\":\"0\",\"amount_at_create\":\"1.000000\",\"price\":2479.8,\"price_str\":\"2479.80\",\"is_liquidation\":false},\"channel\":\"live_orders_ethusd\",\"event\":\"order_created\",\"event_id\":\"00065a1d-7fb1-0538-0000-001200000020\",\"pre_event_id\":\"00065a1d-7fb0-f980-0000-001203000020\",\"order_source\":\"orderbook\"}","recorded_unix_us":1787932603215118}
{"message":"{\"data\":{\"id\":2044303886225416,\"id_str\":\"2044303886225416\",\"order_type\":1,\"order_subtype\":5,\"datetime\":\"1787932603\",\"microtimestamp\":\"1787932603131000\",\"amount\":1.27145262,\"amount_str\":\"1.27145262\",\"amount_traded\":\"0\",\"amount_at_create\":\"1.27145262\",\"price\":78650.2,\"price_str\":\"78650.20\",\"is_liquidation\":false},\"channel\":\"live_orders_btcusd\",\"event\":\"order_created\",\"event_id\":\"00065a1d-7fb1-2478-0000-000101000020\",\"pre_event_id\":\"00065a1d-7fb1-0150-0001-000100000020\",\"order_source\":\"orderbook\"}","recorded_unix_us":1787932603215214}
{"message":"{\"data\":{\"id\":2044303886237698,\"id_str\":\"2044303886237698\",\"order_type\":0,\"order_subtype\":5,\"datetime\":\"1787932603\",\"microtimestamp\":\"1787932603134000\",\"amount\":1.27888333,\"amount_str\":\"1.27888333\",\"amount_traded\":\"0\",\"amount_at_create\":\"1.27888333\",\"price\":78193.21,\"price_str\":\"78193.21\",\"is_liquidation\":false},\"channel\":\"live_orders_btcusd\",\"event\":\"order_created\",\"event_id\":\"00065a1d-7fb1-3030-0000-000102000020\",\"pre_event_id\":\"00065a1d-7fb1-2478-0000-000101000020\",\"order_source\":\"orderbook\"}","recorded_unix_us":1787932603215320}
{"message":"{\"data\":{\"id\":2044303885045769,\"id_str\":\"2044303885045769\",\"order_type\":1,\"order_subtype\":5,\"datetime\":\"1787932603\",\"microtimestamp\":\"1787932603140000\",\"amount\":5,\"amount_str\":\"5.000000\",\"amount_traded\":\"0\",\"amount_at_create\":\"5.000000\",\"price\":2481.72,\"price_str\":\"2481.72\",\"is_liquidation\":false},\"channel\":\"live_orders_ethusd\",\"event\":\"order_deleted\",\"event_id\":\"00065a1d-7fb1-47a0-0000-001201000020\",\"pre_event_id\":\"00065a1d-7fb1-0538-0000-001200000020\",\"order_source\":\"orderbook\"}","recorded_unix_us":1787932603215440}
{"message":"{\"data\":{\"id\":2044303885062150,\"id_str\":\"2044303885062150\",\"order_type\":1,\"order_subtype\":5,\"datetime\":\"1787932603\",\"microtimestamp\":\"1787932603142000\",\"amount\":5,\"amount_str\":\"5.000000\",\"amount_traded\":\"0\",\"amount_at_create\":\"5.000000\",\"price\":2481.97,\"price_str\":\"2481.97\",\"is_liquidation\":false},\"channel\":\"live_orders_ethusd\",\"event\":\"order_deleted\",\"event_id\":\"00065a1d-7fb1-4f70-0000-001202000020\",\"pre_event_id\":\"00065a1d-7fb1-47a0-0000-001201000020\",\"order_source\":\"orderbook\"}","recorded_unix_us":1787932603215587}
{"message":"{\"data\":{\"id\":2044303885512708,\"id_str\":\"2044303885512708\",\"order_type\":1,\"order_subtype\":5,\"datetime\":\"1787932603\",\"microtimestamp\":\"1787932603143000\",\"amount\":5,\"amount_str\":\"5.000000\",\"amount_traded\":\"0\",\"amount_at_create\":\"5.000000\",\"price\":2482.72,\"price_str\":\"2482.72\",\"is_liquidation\":false},\"channel\":\"live_orders_ethusd\",\"event\":\"order_deleted\",\"event_id\":\"00065a1d-7fb1-5358-0000-001203000020\",\"pre_event_id\":\"00065a1d-7fb1-4f70-0000-001202000020\",\"order_source\":\"orderbook\"}","recorded_unix_us":1787932603215713}
{"message":"{\"data\":{\"id\":2044303885049861,\"id_str\":\"2044303885049861\",\"order_type\":1,\"order_subtype\":5,\"datetime\":\"1787932603\",\"microtimestamp\":\"1787932603147000\",\"amount\":1,\"amount_str\":\"1.000000\",\"amount_traded\":\"0\",\"amount_at_create\":\"1.000000\",\"price\":2482.72,\"price_str\":\"2482.72\",\"is_liquidation\":false},\"channel\":\"live_orders_ethusd\",\"event\":\"order_deleted\",\"event_id\":\"00065a1d-7fb1-62f8-0000-001200000020\",\"pre_event_id\":\"00065a1d-7fb1-5358-0000-001203000020\",\"order_source\":\"orderbook\"}","recorded_unix_us":1787932603215807}
{"message":"{\"data\":{\"id\":2044303886311424,\"id_str\":\"2044303886311424\",\"order_type\":1,\"order_subtype\":5,\"datetime\":\"1787932603\",\"microtimestamp\":\"1787932603152000\",\"amount\":0.06310787,\"amount_str\":\"0.06310787\",\"amount_traded\":\"0\",\"amount_at_create\":\"0.06310787\",\"price\":78519.99,\"price_str\":\"78519.99\",\"is_liquidation\":false},\"channel\":\"live_orders_btcusd\",\"event\":\"order_created\",\"event_id\":\"00065a1d-7fb1-7680-0000-000103000020\",\"pre_event_id\":\"00065a1d-7fb1-3030-0000-000102000020\",\"order_source\":\"orderbook\"}","recorded_unix_us":1787932603215965}
{"message":"{\"data\":{\"id\":2044303886311424,\"id_str\":\"2044303886311424\",\"order_type\":1,\"order_subtype\":5,\"datetime\":\"1787932603\",\"microtimestamp\":\"1787932603152000\",\"amount\":0.06310787,\"amount_str\":\"0.06310787\",\"amount_traded\":\"0\",\"amount_at_create\":\"0.06310787\",\"price\":78519.99,\"price_str\":\"78519.99\",\"is_liquidation\":false},\"channel\":\"live_orders_btcusd\",\"event\":\"order_deleted\",\"event_id\":\"00065a1d-7fb1-7680-0001-000100000020\",\"pre_event_id\":\"00065a1d-7fb1-7680-0000-000103000020\",\"order_source\":\"orderbook\"}","recorded_unix_us":1787932603216009}
{"message":"{\"data\":{\"id\":2044303886315520,\"id_str\":\"2044303886315520\",\"order_type\":0,\"order_subtype\":5,\"datetime\":\"1787932603\",\"microtimestamp\":\"1787932603152000\",\"amount\":6,\"amount_str\":\"6.000000\",\"amount_traded\":\"0\",\"amount_at_create\":\"6.000000\",\"price\":2479.06,\"price_str\":\"2479.06\",\"is_liquidation\":false},\"channel\":\"live_orders_ethusd\",\"event\":\"order_created\",\"event_id\":\"00065a1d-7fb1-7680-0000-001201000020\",\"pre_event_id\":\"00065a1d-7fb1-62f8-0000-001200000020\",\"order_source\":\"orderbook\"}","recorded_unix_us":1787932603216114}
{"message":"{\"data\":{\"id\":2044303886319625,\"id_str\":\"2044303886319625\",\"order_type\":1,\"order_subtype\":5,\"datetime\":\"1787932603\",\"microtimestamp\":\"1787932603153000\",\"amount\":0.1,\"amount_str\":\"0.10000000\",\"amount_traded\":\"0\",\"amount_at_create\":\"0.10000000\",\"price\":78522.62,\"price_str\":\"78522.62\",\"is_liquidation\":false},\"channel\":\"live_orders_btcusd\",\"event\":\"order_created\",\"event_id\":\"00065a1d-7fb1-7a68-0000-000101000020\",\"pre_event_id\":\"00065a1d-7fb1-7680-0001-000100000020\",\"order_source\":\"orderbook\"}","recorded_unix_us":1787932603216222}
{"message":"{\"data\":{\"id\":2044303886319625,\"id_str\":\"2044303886319625\",\"order_type\":1,\"order_subtype\":5,\"datetime\":\"1787932603\",\"microtimestamp\":\"1787932603153000\",\"amount\":0.1,\"amount_str\":\"0.10000000\",\"amount_traded\":\"0\",\"amount_at_create\":\"0.10000000\",\"price\":78522.62,\"price_str\":\"78522.62\",\"is_liquidation\":false},\"channel\":\"live_orders_btcusd\",\"event\":\"order_deleted\",\"event_id\":\"00065a1d-7fb1-7a68-0001-000102000020\",\"pre_event_id\":\"00065a1d-7fb1-7a68-0000-000101000020\",\"order_source\":\"orderbook\"}","recorded_unix_us":1787932603216331}
{"message":"{\"data\":{\"id\":2044303883636739,\"id_str\":\"2044303883636739\",\"order_type\":0,\"order_subtype\":5,\"datetime\":\"1787932603\",\"microtimestamp\":\"1787932603154000\",\"amount\":0.044416,\"amount_str\":\"0.044416\",\"amount_traded\":\"0\",\"amount_at_create\":\"0.044416\",\"price\":2480.75,\"price_str\":\"2480.75\",\"is_liquidation\":false},\"channel\":\"live_orders_ethusd\",\"event\":\"order_deleted\",\"event_id\":\"00065a1d-7fb1-7e50-0000-001202000020\",\"pre_event_id\":\"00065a1d-7fb1-7680-0000-001201000020\",\"order_source\":\"orderbook\"}","recorded_unix_us":1787932603216435}
{"message":"{\"data\":{\"id\":2044303886319635,\"id_str\":\"2044303886319635\",\"order_type\":1,\"order_subtype\":5,\"datetime\":\"1787932603\",\"microtimestamp\":\"1787932603154000\",\"amount\":0.06310787,\"amount_str\":\"0.06310787\",\"amount_traded\":\"0\",\"amount_at_create\":\"0.06310787\",\"price\":78522.35,\"price_str\":\"78522.35\",\"is_liquidation\":false},\"channel\":\"live_orders_btcusd\",\"event\":\"order_created\",\"event_id\":\"00065a1d-7fb1-7e50-0000-000103000020\",\"pre_event_id\":\"00065a1d-7fb1-7a68-0001-000102000020\",\"order_source\":\"orderbook\"}","recorded_unix_us":1787932603216543}
{"message":"{\"data\":{\"id\":2044303886319635,\"id_str\":\"2044303886319635\",\"order_type\":1,\"order_subtype\":5,\"datetime\":\"1787932603\",\"microtimestamp\":\"1787932603154000\",\"amount\":0.06310787,\"amount_str\":\"0.06310787\",\"amount_traded\":\"0\",\"amount_at_create\":\"0.06310787\",\"price\":78522.35,\"price_str\":\"78522.35\",\"is_liquidation\":false},\"channel\":\"live_orders_btcusd\",\"event\":\"order_deleted\",\"event_id\":\"00065a1d-7fb1-7e50-0001-000100000020\",\"pre_event_id\":\"00065a1d-7fb1-7e50-0000-000103000020\",\"order_source\":\"orderbook\"}","recorded_unix_us":1787932603216640}
{"message":"{\"data\":{\"id\":2044303886323718,\"id_str\":\"2044303886323718\",\"order_type\":1,\"order_subtype\":5,\"datetime\":\"1787932603\",\"microtimestamp\":\"1787932603154000\",\"amount\":0.1,\"amount_str\":\"0.10000000\",\"amount_traded\":\"0\",\"amount_at_create\":\"0.10000000\",\"price\":78522.63,\"price_str\":\"78522.63\",\"is_liquidation\":false},\"channel\":\"live_orders_btcusd\",\"event\":\"order_created\",\"event_id\":\"00065a1d-7fb1-7e50-0002-000101000020\",\"pre_event_id\":\"00065a1d-7fb1-7e50-0001-000100000020\",\"order_source\":\"orderbook\"}","recorded_unix_us":1787932603216741}
{"message":"{\"data\":{\"id\":2044303886323718,\"id_str\":\"2044303886323718\",\"order_type\":1,\"order_subtype\":5,\"datetime\":\"1787932603\",\"microtimestamp\":\"1787932603154000\",\"amount\":0.1,\"amount_str\":\"0.10000000\",\"amount_traded\":\"0\",\"amount_at_create\":\"0.10000000\",\"price\":78522.63,\"price_str\":\"78522.63\",\"is_liquidation\":false},\"channel\":\"live_orders_btcusd\",\"event\":\"order_deleted\",\"event_id\":\"00065a1d-7fb1-7e50-0003-000102000020\",\"pre_event_id\":\"00065a1d-7fb1-7e50-0002-000101000020\",\"order_source\":\"orderbook\"}","recorded_unix_us":1787932603216869}
{"message":"{\"data\":{\"id\":2044303883616265,\"id_str\":\"2044303883616265\",\"order_type\":1,\"order_subtype\":5,\"datetime\":\"1787932603\",\"microtimestamp\":\"1787932603155000\",\"amount\":0.041769,\"amount_str\":\"0.041769\",\"amount_traded\":\"0\",\"amount_at_create\":\"0.041769\",\"price\":2480.85,\"price_str\":\"2480.85\",\"is_liquidation\":false},\"channel\":\"live_orders_ethusd\",\"event\":\"order_deleted\",\"event_id\":\"00065a1d-7fb1-8238-0000-001203000020\",\"pre_event_id\":\"00065a1d-7fb1-7e50-0000-001202000020\",\"order_source\":\"orderbook\"}","recorded_unix_us":1787932603216996}
{"message":"{\"data\":{\"id\":2044303886184454,\"id_str\":\"2044303886184454\",\"order_type\":0,\"order_subtype\":5,\"datetime\":\"1787932603\",\"microtimestamp\":\"1787932603164000\",\"amount\":2,\"amount_str\":\"2.000000\",\"amount_traded\":\"0\",\"amount_at_create\":\"2.000000\",\"price\":2479.06,\"price_str\":\"2479.06\",\"is_liquidation\":false},\"channel\":\"live_orders_ethusd\",\"event\":\"order_deleted\",\"event_id\":\"00065a1d-7fb1-a560-0000-001200000020\",\"pre_event_id\":\"00065a1d-7fb1-8238-0000-001203000020\",\"order_source\":\"orderbook\"}","recorded_unix_us":1787932603217216}
{"message":"{\"data\":{\"id\":2044303886315520,\"id_str\":\"2044303886315520\",\"order_type\":0,\"order_subtype\":5,\"datetime\":\"1787932603\",\"microtimestamp\":\"1787932603174000\",\"amount\":6,\"amount_str\":\"6.000000\",\"amount_traded\":\"0\",\"amount_at_create\":\"6.000000\",\"price\":2479.06,\"price_str\":\"2479.06\",\"is_liquidation\":false},\"channel\":\"live_orders_ethusd\",\"event\":\"order_deleted\",\"event_id\":\"00065a1d-7fb1-cc70-0000-001201000020\",\"pre_event_id\":\"00065a1d-7fb1-a560-0000-001200000020\",\"order_source\":\"orderbook\"}","recorded_unix_us":1787932603218046}
{"message":"{\"data\":{\"id\":2044303886409732,\"id_str\":\"2044303886409732\",\"order_type\":1,\"order_subtype\":5,\"datetime\":\"1787932603\",\"microtimestamp\":\"1787932603175000\",\"amount\":2.01528391,\"amount_str\":\"2.01528391\",\"amount_traded\":\"0\",\"amount_at_create\":\"2.01528391\",\"price\":0.03160361,\"price_str\":\"0.03160361\",\"is_liquidation\":false},\"channel\":\"live_orders_ethbtc\",\"event\":\"order_created\",\"event_id\":\"00065a1d-7fb1-d058-0000-001100000020\",\"pre_event_id\":\"00065a1d-7fb0-5570-0000-001103000020\",\"order_source\":\"orderbook\"}","recorded_unix_us":1787932603218148}
{"message":"{\"data\":{\"id\":2044303886417920,\"id_str\":\"2044303886417920\",\"order_type\":0,\"order_subtype\":5,\"datetime\":\"1787932603\",\"microtimestamp\":\"1787932603177000\",\"amount\":0.045102,\"amount_str\":\"0.045102\",\"amount_traded\":\"0\",\"amount_at_create\":\"0.045102\",\"price\":2480.81,\"price_str\":\"2480.81\",\"is_liquidation\":false},\"channel\":\"live_orders_ethusd\",\"event\":\"order_created\",\"event_id\":\"00065a1d-7fb1-d828-0000-001202000020\",\"pre_event_id\":\"00065a1d-7fb1-cc70-0000-001201000020\",\"order_source\":\"orderbook\"}","recorded_unix_us":1787932603229796}
{"message":"{\"data\":{\"id\":2044303886422018,\"id_str\":\"2044303886422018\",\"order_type\":1,\"order_subtype\":5,\"datetime\":\"1787932603\",\"microtimestamp\":\"1787932603179000\",\"amount\":0.041276,\"amount_str\":\"0.041276\",\"amount_traded\":\"0\",\"amount_at_create\":\"0.041276\",\"price\":2480.87,\"price_str\":\"2480.87\",\"is_liquidation\":false},\"channel\":\"live_orders_ethusd\",\"event\":\"order_created\",\"event_id\":\"00065a1d-7fb1-dff8-0000-001203000020\",\"pre_event_id\":\"00065a1d-7fb1-d828-0000-001202000020\",\"order_source\":\"orderbook\"}","recorded_unix_us":1787932603229891}
{"message":"{\"data\":{\"id\":2044303886434306,\"id_str\":\"2044303886434306\",\"order_type\":1,\"order_subtype\":5,\"datetime\":\"1787932603\",\"microtimestamp\":\"1787932603181000\",\"amount\":0.06310787,\"amount_str\":\"0.06310787\",\"amount_traded\":\"0\",\"amount_at_create\":\"0.06310787\",\"price\":78520.93,\"price_str\":\"78520.93\",\"is_liquidation\":false},\"channel\":\"live_orders_btcusd\",\"event\":\"order_created\",\"event_id\":\"00065a1d-7fb1-e7c8-0000-000103000020\",\"pre_event_id\":\"00065a1d-7fb1-7e50-0003-000102000020\",\"order_source\":\"orderbook\"}","recorded_unix_us":1787932603230102}
{"message":"{\"data\":{\"id\":2044303886434306,\"id_str\":\"2044303886434306\",\"order_type\":1,\"order_subtype\":5,\"datetime\":\"1787932603\",\"microtimestamp\":\"1787932603181000\",\"amount\":0.06310787,\"amount_str\":\"0.06310787\",\"amount_traded\":\"0\",\"amount_at_create\":\"0.06310787\",\"price\":78520.93,\"price_str\":\"78520.93\",\"is_liquidation\":false},\"channel\":\"live_orders_btcusd\",\"event\":\"order_deleted\",\"event_id\":\"00065a1d-7fb1-e7c8-0001-000100000020\",\"pre_event_id\":\"00065a1d-7fb1-e7c8-0000-000103000020\",\"order_source\":\"orderbook\"}","recorded_unix_us":1787932603230161}
{"message":"{\"data\":{\"id\":2044303886434315,\"id_str\":\"2044303886434315\",\"order_type\":1,\"order_subtype\":5,\"datetime\":\"1787932603\",\"microtimestamp\":\"1787932603182000\",\"amount\":0.1,\"amount_str\":\"0.10000000\",\"amount_traded\":\"0\",\"amount_at_create\":\"0.10000000\",\"price\":78522.62,\"price_str\":\"78522.62\",\"is_liquidation\":false},\"channel\":\"live_orders_btcusd\",\"event\":\"order_created\",\"event_id\":\"00065a1d-7fb1-ebb0-0000-000101000020\",\"pre_event_id\":\"00065a1d-7fb1-e7c8-0001-000100000020\",\"order_source\":\"orderbook\"}","recorded_unix_us":1787932603230294}
{"message":"{\"data\":{\"id\":2044303886434315,\"id_str\":\"2044303886434315\",\"order_type\":1,\"order_subtype\":5,\"datetime\":\"1787932603\",\"microtimestamp\":\"1787932603182000\",\"amount\":0.1,\"amount_str\":\"0.10000000\",\"amount_traded\":\"0\",\"amount_at_create\":\"0.10000000\",\"price\":78522.62,\"price_str\":\"78522.62\",\"is_liquidation\":false},\"channel\":\"live_orders_btcusd\",\"event\":\"order_deleted\",\"event_id\":\"00065a1d-7fb1-ebb0-0001-000102000020\",\"pre_event_id\":\"00065a1d-7fb1-ebb0-0000-000101000020\",\"order_source\":\"orderbook\"}","recorded_unix_us":1787932603230454}
{"message":"{\"data\":{\"id\":2044303886442497,\"id_str\":\"2044303886442497\",\"order_type\":1,\"order_subtype\":5,\"datetime\":\"1787932603\",\"microtimestamp\":\"1787932603183000\",\"amount\":0.1,\"amount_str\":\"0.10000000\",\"amount_traded\":\"0\",\"amount_at_create\":\"0.10000000\",\"price\":78522.63,\"price_str\":\"78522.63\",\"is_liquidation\":false},\"channel\":\"live_orders_btcusd\",\"event\":\"order_created\",\"event_id\":\"00065a1d-7fb1-ef98-0000-000103000020\",\"pre_event_id\":\"00065a1d-7fb1-ebb0-0001-000102000020\",\"order_source\":\"orderbook\"}","recorded_unix_us":1787932603230601}
{"message":"{\"data\":{\"id\":2044303886442497,\"id_str\":\"2044303886442497\",\"order_type\":1,\"order_subtype\":5,\"datetime\":\"1787932603\",\"microtimestamp\":\"1787932603183000\",\"amount\":0.1,\"amount_str\":\"0.10000000\",\"amount_traded\":\"0\",\"amount_at_create\":\"0.10000000\",\"price\":78522.63,\"price_str\":\"78522.63\",\"is_liquidation\":false},\"channel\":\"live_orders_btcusd\",\"event\":\"order_deleted\",\"event_id\":\"00065a1d-7fb1-ef98-0001-000100000020\",\"pre_event_id\":\"00065a1d-7fb1-ef98-0000-000103000020\",\"order_source\":\"orderbook\"}","recorded_unix_us":1787932603230650}
{"message":"{\"data\":{\"id\":2044303884034049,\"id_str\":\"2044303884034049\",\"order_type\":0,\"order_subtype\":5,\"datetime\":\"1787932603\",\"microtimestamp\":\"1787932603188000\",\"amount\":0.403091,\"amount_str\":\"0.403091\",\"amount_traded\":\"0\",\"amount_at_create\":\"0.403091\",\"price\":2480.1,\"price_str\":\"2480.10\",\"is_liquidation\":false},\"channel\":\"live_orders_ethusd\",\"event\":\"order_deleted\",\"event_id\":\"00065a1d-7fb2-0320-0000-001200000020\",\"pre_event_id\":\"00065a1d-7fb1-dff8-0000-001203000020\",\"order_source\":\"orderbook\"}","recorded_unix_us":1787932603231313}
{"message":"{\"data\":{\"id\":2044303886483462,\"id_str\":\"2044303886483462\",\"order_type\":0,\"order_subtype\":5,\"datetime\":\"1787932603\",\"microtimestamp\":\"1787932603194000\",\"amount\":0.00140266,\"amount_str\":\"0.00140266\",\"amount_traded\":\"0\",\"amount_at_create\":\"0.00140266\",\"price\":70668.36,\"price_str\":\"70668.36\",\"is_liquidation\":false},\"channel\":\"live_orders_btcusd\",\"event\":\"order_created\",\"event_id\":\"00065a1d-7fb2-1a90-0000-000101000020\",\"pre_event_id\":\"00065a1d-7fb1-ef98-0001-000100000020\",\"order_source\":\"orderbook\"}","recorded_unix_us":1787932603248577}
{"message":"{\"data\":{\"id\":2044303886495753,\"id_str\":\"2044303886495753\",\"order_type\":0,\"order_subtype\":5,\"datetime\":\"1787932603\",\"microtimestamp\":\"1787932603197000\",\"amount\":0.403093,\"amount_str\":\"0.403093\",\"amount_traded\":\"0\",\"amount_at_create\":\"0.403093\",\"price\":2480.07,\"price_str\":\"2480.07\",\"is_liquidation\":false},\"channel\":\"live_orders_ethusd\",\"event\":\"order_created\",\"event_id\":\"00065a1d-7fb2-2648-0000-001201000020\",\"pre_event_id\":\"00065a1d-7fb2-0320-0000-001200000020\",\"order_source\":\"orderbook\"}","recorded_unix_us":1787932603248777}
{"message":"{\"data\":{\"id\":2044303886508033,\"id_str\":\"2044303886508033\",\"order_type\":1,\"order_subtype\":5,\"datetime\":\"1787932603\",\"microtimestamp\":\"1787932603200000\",\"amount\":5,\"amount_str\":\"5.000000\",\"amount_traded\":\"0\",\"amount_at_create\":\"5.000000\",\"price\":2481.68,\"price_str\":\"2481.68\",\"is_liquidation\":false},\"channel\":\"live_orders_ethusd\",\"event\":\"order_created\",\"event_id\":\"00065a1d-7fb2-3200-0000-001202000020\",\"pre_event_id\":\"00065a1d-7fb2-2648-0000-001201000020\",\"order_source\":\"orderbook\"}","recorded_unix_us":1787932603248922}
{"message":"{\"data\":{\"id\":2044303885000705,\"id_str\":\"2044303885000705\",\"order_type\":1,\"order_subtype\":5,\"datetime\":\"1787932603\",\"microtimestamp\":\"1787932603206000\",\"amount\":12.087822,\"amount_str\":\"12.087822\",\"amount_traded\":\"0\",\"amount_at_create\":\"12.087822\",\"price\":2481.84,\"price_str\":\"2481.84\",\"is_liquidation\":false},\"channel\":\"live_orders_ethusd\",\"event\":\"order_deleted\",\"event_id\":\"00065a1d-7fb2-4970-0000-001203000020\",\"pre_event_id\":\"00065a1d-7fb2-3200-0000-001202000020\",\"order_source\":\"orderbook\"}","recorded_unix_us":1787932603255050}
{"message":"{\"data\":{\"id\":2044303885070339,\"id_str\":\"2044303885070339\",\"order_type\":1,\"order_subtype\":5,\"datetime\":\"1787932603\",\"microtimestamp\":\"1787932603207000\",\"amount\":4.028412,\"amount_str\":\"4.028412\",\"amount_traded\":\"0\",\"amount_at_create\":\"4.028412\",\"price\":2482.37,\"price_str\":\"2482.37\",\"is_liquidation\":false},\"channel\":\"live_orders_ethusd\",\"event\":\"order_deleted\",\"event_id\":\"00065a1d-7fb2-4d58-0000-001200000020\",\"pre_event_id\":\"00065a1d-7fb2-4970-0000-001203000020\",\"order_source\":\"orderbook\"}","recorded_unix_us":1787932603255134}
{"message":"{\"data\":{\"id\":2044303885070340,\"id_str\":\"2044303885070340\",\"order_type\":1,\"order_subtype\":5,\"datetime\":\"1787932603\",\"microtimestamp\":\"1787932603207000\",\"amount\":12.086444,\"amount_str\":\"12.086444\",\"amount_traded\":\"0\",\"amount_at_create\":\"12.086444\",\"price\":2482.12,\"price_str\":\"2482.12\",\"is_liquidation\":false},\"channel\":\"live_orders_ethusd\",\"event\":\"order_deleted\",\"event_id\":\"00065a1d-7fb2-4d58-0001-001201000020\",\"pre_event_id\":\"00065a1d-7fb2-4d58-0000-001200000020\",\"order_source\":\"orderbook\"}","recorded_unix_us":1787932603255262}
{"message":"{\"data\":{\"id\":2044303885070341,\"id_str\":\"2044303885070341\",\"order_type\":1,\"order_subtype\":5,\"datetime\":\"1787932603\",\"microtimestamp\":\"1787932603207000\",\"amount\":10.06507,\"amount_str\":\"10.065070\",\"amount_traded\":\"0\",\"amount_at_create\":\"10.065070\",\"price\":2483.84,\"price_str\":\"2483.84\",\"is_liquidation\":false},\"channel\":\"live_orders_ethusd\",\"event\":\"order_deleted\",\"event_id\":\"00065a1d-7fb2-4d58-0002-001202000020\",\"pre_event_id\":\"00065a1d-7fb2-4d58-0001-001201000020\",\"order_source\":\"orderbook\"}","recorded_unix_us":1787932603255293}
{"message":"{\"data\":{\"id\":2044303885070349,\"id_str\":\"2044303885070349\",\"order_type\":1,\"order_subtype\":5,\"datetime\":\"1787932603\",\"microtimestamp\":\"1787932603208000\",\"amount\":4.027018,\"amount_str\":\"4.027018\",\"amount_traded\":\"0\",\"amount_at_create\":\"4.027018\",\"price\":2483.23,\"price_str\":\"2483.23\",\"is_liquidation\":false},\"channel\":\"live_orders_ethusd\",\"event\":\"order_deleted\",\"event_id\":\"00065a1d-7fb2-5140-0000-001203000020\",\"pre_event_id\":\"00065a1d-7fb2-4d58-0002-001202000020\",\"order_source\":\"orderbook\"}","recorded_unix_us":1787932603255483}
{"message":"{\"data\":{\"id\":2044303885074437,\"id_str\":\"2044303885074437\",\"order_type\":1,\"order_subtype\":5,\"datetime\":\"1787932603\",\"microtimestamp\":\"1787932603208000\",\"amount\":10.057184,\"amount_str\":\"10.057184\",\"amount_traded\":\"0\",\"amount_at_create\":\"10.057184\",\"price\":2485.79,\"price_str\":\"2485.79\",\"is_liquidation\":false},\"channel\":\"live_orders_ethusd\",\"event\":\"order_deleted\",\"event_id\":\"00065a1d-7fb2-5140-0001-001200000020\",\"pre_event_id\":\"00065a1d-7fb2-5140-0000-001203000020\",\"order_source\":\"orderbook\"}","recorded_unix_us":1787932603255525}
{"message":"{\"data\":{\"id\":2044303885078531,\"id_str\":\"2044303885078531\",\"order_type\":1,\"order_subtype\":5,\"datetime\":\"1787932603\",\"microtimestamp\":\"1787932603208000\",\"amount\":20.097242,\"amount_str\":\"20.097242\",\"amount_traded\":\"0\",\"amount_at_create\":\"20.097242\",\"price\":2487.91,\"price_str\":\"2487.91\",\"is_liquidation\":false},\"channel\":\"live_orders_ethusd\",\"event\":\"order_deleted\",\"event_id\":\"00065a1d-7fb2-5140-0002-001201000020\",\"pre_event_id\":\"00065a1d-7fb2-5140-0001-001200000020\",\"order_source\":\"orderbook\"}","recorded_unix_us":1787932603255553}
{"message":"{\"data\":{\"id\":2044303885082627,\"id_str\":\"2044303885082627\",\"order_type\":1,\"order_subtype\":5,\"datetime\":\"1787932603\",\"microtimestamp\":\"1787932603209000\",\"amount\":40.09205,\"amount_str\":\"40.092050\",\"amount_traded\":\"0\",\"amount_at_create\":\"40.092050\",\"price\":2494.27,\"price_str\":\"2494.27\",\"is_liquidation\":false},\"channel\":\"live_orders_ethusd\",\"event\":\"order_deleted\",\"event_id\":\"00065a1d-7fb2-5528-0000-001202000020\",\"pre_event_id\":\"00065a1d-7fb2-5140-0002-001201000020\",\"order_source\":\"orderbook\"}","recorded_unix_us":1787932603255636}
{"message":"{\"data\":{\"id\":2044303885082633,\"id_str\":\"2044303885082633\",\"order_type\":1,\"order_subtype\":5,\"datetime\":\"1787932603\",\"microtimestamp\":\"1787932603209000\",\"amount\":39.969006,\"amount_str\":\"39.969006\",\"amount_traded\":\"0\",\"amount_at_create\":\"39.969006\",\"price\":2501.94,\"price_str\":\"2501.94\",\"is_liquidation\":false},\"channel\":\"live_orders_ethusd\",\"event\":\"order_deleted\",\"event_id\":\"00065a1d-7fb2-5528-0001-001203000020\",\"pre_event_id\":\"00065a1d-7fb2-5528-0000-001202000020\",\"order_source\":\"orderbook\"}","recorded_unix_us":1787932603261312}
{"message":"{\"data\":{\"id\":2044303885086723,\"id_str\":\"2044303885086723\",\"order_type\":1,\"order_subtype\":5,\"datetime\":\"1787932603\",\"microtimestamp\":\"1787932603209000\",\"amount\":20.088574,\"amount_str\":\"20.088574\",\"amount_traded\":\"0\",\"amount_at_create\":\"20.088574\",\"price\":2488.98,\"price_str\":\"2488.98\",\"is_liquidation\":false},\"channel\":\"live_orders_ethusd\",\"event\":\"order_deleted\",\"event_id\":\"00065a1d-7fb2-5528-0002-001200000020\",\"pre_event_id\":\"00065a1d-7fb2-5528-0001-001203000020\",\"order_source\":\"orderbook\"}","recorded_unix_us":1787932603261387}
{"message":"{\"data\":{\"id\":2044303886549001,\"id_str\":\"2044303886549001\",\"order_type\":1,\"order_subtype\":5,\"datetime\":\"1787932603\",\"microtimestamp\":\"1787932603210000\",\"amount\":5,\"amount_str\":\"5.000000\",\"amount_traded\":\"0\",\"amount_at_create\":\"5.000000\",\"price\":2481.93,\"price_str\":\"2481.93\",\"is_liquidation\":false},\"channel\":\"live_orders_ethusd\",\"event\":\"order_created\",\"event_id\":\"00065a1d-7fb2-5910-0000-001201000020\",\"pre_event_id\":\"00065a1d-7fb2-5528-0002-001200000020\",\"order_source\":\"orderbook\"}","recorded_unix_us":1787932603261525}
{"message":"{\"data\":{\"id\":2044303885209600,\"id_str\":\"2044303885209600\",\"order_type\":1,\"order_subtype\":5,\"datetime\":\"1787932603\",\"microtimestamp\":\"1787932603210000\",\"amount\":10.062547,\"amount_str\":\"10.062547\",\"amount_traded\":\"0\",\"amount_at_create\":\"10.062547\",\"price\":2484.47,\"price_str\":\"2484.47\",\"is_liquidation\":false},\"channel\":\"live_orders_ethusd\",\"event\":\"order_deleted\",\"event_id\":\"00065a1d-7fb2-5910-0001-001202000020\",\"pre_event_id\":\"00065a1d-7fb2-5910-0000-001201000020\",\"order_source\":\"orderbook\"}","recorded_unix_us":1787932603261560}
{"message":"{\"data\":{\"id\":2044303885209601,\"id_str\":\"2044303885209601\",\"order_type\":1,\"order_subtype\":5,\"datetime\":\"1787932603\",\"microtimestamp\":\"1787932603210000\",\"amount\":4.028003,\"amount_str\":\"4.028003\",\"amount_traded\":\"0\",\"amount_at_create\":\"4.028003\",\"price\":2482.62,\"price_str\":\"2482.62\",\"is_liquidation\":false},\"channel\":\"live_orders_ethusd\",\"event\":\"order_deleted\",\"event_id\":\"00065a1d-7fb2-5910-0002-001203000020\",\"pre_event_id\":\"00065a1d-7fb2-5910-0001-001202000020\",\"order_source\":\"orderbook\"}","recorded_unix_us":1787932603261730}
{"message":"{\"data\":{\"id\":2044303885209605,\"id_str\":\"2044303885209605\",\"order_type\":1,\"order_subtype\":5,\"datetime\":\"1787932603\",\"microtimestamp\":\"1787932603210000\",\"amount\":20.077182,\"amount_str\":\"20.077182\",\"amount_traded\":\"0\",\"amount_at_create\":\"20.077182\",\"price\":2490.39,\"price_str\":\"2490.39\",\"is_liquidation\":false},\"channel\":\"live_orders_ethusd\",\"event\":\"order_deleted\",\"event_id\":\"00065a1d-7fb2-5910-0003-001200000020\",\"pre_event_id\":\"00065a1d-7fb2-5910-0002-001203000020\",\"order_source\":\"orderbook\"}","recorded_unix_us":1787932603261761}
{"message":"{\"data\":{\"id\":2044303885209606,\"id_str\":\"2044303885209606\",\"order_type\":1,\"order_subtype\":5,\"datetime\":\"1787932603\",\"microtimestamp\":\"1787932603211000\",\"amount\":40.051178,\"amount_str\":\"40.051178\",\"amount_traded\":\"0\",\"amount_at_create\":\"40.051178\",\"price\":2496.81,\"price_str\":\"2496.81\",\"is_liquidation\":false},\"channel\":\"live_orders_ethusd\",\"event\":\"order_deleted\",\"event_id\":\"00065a1d-7fb2-5cf8-0000-001201000020\",\"pre_event_id\":\"00065a1d-7fb2-5910-0003-001200000020\",\"order_source\":\"orderbook\"}","recorded_unix_us":1787932603261784}
{"message":"{\"data\":{\"id\":2044303885213701,\"id_str\":\"2044303885213701\",\"order_type\":0,\"order_subtype\":5,\"datetime\":\"1787932603\",\"microtimestamp\":\"1787932603211000\",\"amount\":12.096984,\"amount_str\":\"12.096984\",\"amount_traded\":\"0\",\"amount_at_create\":\"12.096984\",\"price\":2479.95,\"price_str\":\"2479.95\",\"is_liquidation\":false},\"channel\":\"live_orders_ethusd\",\"event\":\"order_deleted\",\"event_id\":\"00065a1d-7fb2-5cf8-0001-001202000020\",\"pre_event_id\":\"00065a1d-7fb2-5cf8-0000-001201000020\",\"order_source\":\"orderbook\"}","recorded_unix_us":1787932603261809}
{"message":"{\"data\":{\"id\":2044303886573577,\"id_str\":\"2044303886573577\",\"order_type\":1,\"order_subtype\":5,\"datetime\":\"1787932603\",\"microtimestamp\":\"1787932603215000\",\"amount\":0.06310787,\"amount_str\":\"0.06310787\",\"amount_traded\":\"0\",\"amount_at_create\":\"0.06310787\",\"price\":78522.43,\"price_str\":\"78522.43\",\"is_liquidation\":false},\"channel\":\"live_orders_btcusd\",\"event\":\"order_created\",\"event_id\":\"00065a1d-7fb2-6c98-0000-000102000020\",\"pre_event_id\":\"00065a1d-7fb2-1a90-0000-000101000020\",\"order_source\":\"orderbook\"}","recorded_unix_us":1787932603261995}
{"message":"{\"data\":{\"id\":2044303886573577,\"id_str\":\"2044303886573577\",\"order_type\":1,\"order_subtype\":5,\"datetime\":\"1787932603\",\"microtimestamp\":\"1787932603215000\",\"amount\":0.06310787,\"amount_str\":\"0.06310787\",\"amount_traded\":\"0\",\"amount_at_create\":\"0.06310787\",\"price\":78522.43,\"price_str\":\"78522.43\",\"is_liquidation\":false},\"channel\":\"live_orders_btcusd\",\"event\":\"order_deleted\",\"event_id\":\"00065a1d-7fb2-6c98-0001-000103000020\",\"pre_event_id\":\"00065a1d-7fb2-6c98-0000-000102000020\",\"order_source\":\"orderbook\"}","recorded_unix_us":1787932603262037}
{"message":"{\"data\":{\"id\":2044303886573578,\"id_str\":\"2044303886573578\",\"order_type\":1,\"order_subtype\":5,\"datetime\":\"1787932603\",\"microtimestamp\":\"1787932603216000\",\"amount\":0.06310787,\"amount_str\":\"0.06310787\",\"amount_traded\":\"0\",\"amount_at_create\":\"0.06310787\",\"price\":78520.07,\"price_str\":\"78520.07\",\"is_liquidation\":false},\"channel\":\"live_orders_btcusd\",\"event\":\"order_created\",\"event_id\":\"00065a1d-7fb2-7080-0000-000100000020\",\"pre_event_id\":\"00065a1d-7fb2-6c98-0001-000103000020\",\"order_source\":\"orderbook\"}","recorded_unix_us":1787932603262191}
