{"message":"{\"data\":{\"id\":2044303880155139,\"id_str\":\"2044303880155139\",\"order_type\":1,\"order_subtype\":5,\"datetime\":\"1787932602\",\"microtimestamp\":\"1787932601770000\",\"amount\":5,\"amount_str\":\"5.000000\",\"amount_traded\":\"0\",\"amount_at_create\":\"5.000000\",\"price\":2481.48,\"price_str\":\"2481.48\",\"is_liquidation\":false},\"channel\":\"live_orders_ethusd\",\"event\":\"order_deleted\",\"event_id\":\"00065a1d-7f9c-6010-0000-001202000020\",\"pre_event_id\":\"00065a1d-7f9c-5070-0000-001201000020\",\"order_source\":\"orderbook\"}","recorded_unix_us":1787932601876835}
{"message":"{\"data\":{\"id\":2044303878246406,\"id_str\":\"2044303878246406\",\"order_type\":1,\"order_subtype\":5,\"datetime\":\"1787932602\",\"microtimestamp\":\"1787932601770000\",\"amount\":6,\"amount_str\":\"6.000000\",\"amount_traded\":\"0\",\"amount_at_create\":\"6.000000\",\"price\":2482.48,\"price_str\":\"2482.48\",\"is_liquidation\":false},\"channel\":\"live_orders_ethusd\",\"event\":\"order_deleted\",\"event_id\":\"00065a1d-7f9c-6010-0001-001203000020\",\"pre_event_id\":\"00065a1d-7f9c-6010-0000-001202000020\",\"order_source\":\"orderbook\"}","recorded_unix_us":1787932601876939}
{"message":"{\"data\":{\"id\":2044303876861955,\"id_str\":\"2044303876861955\",\"order_type\":1,\"order_subtype\":5,\"datetime\":\"1787932602\",\"microtimestamp\":\"1787932601778000\",\"amount\":0.042001,\"amount_str\":\"0.042001\",\"amount_traded\":\"0\",\"amount_at_create\":\"0.042001\",\"price\":2480.82,\"price_str\":\"2480.82\",\"is_liquidation\":false},\"channel\":\"live_orders_ethusd\",\"event\":\"order_deleted\",\"event_id\":\"00065a1d-7f9c-7f50-0000-001200000020\",\"pre_event_id\":\"00065a1d-7f9c-6010-0001-001203000020\",\"order_source\":\"orderbook\"}","recorded_unix_us":1787932601876961}
{"message":"{\"data\":{\"id\":2044303880699904,\"id_str\":\"2044303880699904\",\"order_type\":1,\"order_subtype\":5,\"datetime\":\"1787932602\",\"microtimestamp\":\"1787932601781000\",\"amount\":0.1,\"amount_str\":\"0.10000000\",\"amount_traded\":\"0\",\"amount_at_create\":\"0.10000000\",\"price\":78522.62,\"price_str\":\"78522.62\",\"is_liquidation\":false},\"channel\":\"live_orders_btcusd\",\"event\":\"order_created\",\"event_id\":\"00065a1d-7f9c-8b08-0000-000100000020\",\"pre_event_id\":\"00065a1d-7f9c-5070-0001-000103000020\",\"order_source\":\"orderbook\"}","recorded_unix_us":1787932601877054}
{"message":"{\"data\":{\"id\":2044303880699904,\"id_str\":\"2044303880699904\",\"order_type\":1,\"order_subtype\":5,\"datetime\":\"1787932602\",\"microtimestamp\":\"1787932601781000\",\"amount\":0.1,\"amount_str\":\"0.10000000\",\"amount_traded\":\"0\",\"amount_at_create\":\"0.10000000\",\"price\":78522.62,\"price_str\":\"78522.62\",\"is_liquidation\":false},\"channel\":\"live_orders_btcusd\",\"event\":\"order_deleted\",\"event_id\":\"00065a1d-7f9c-8b08-0001-000101000020\",\"pre_event_id\":\"00065a1d-7f9c-8b08-0000-000100000020\",\"order_source\":\"orderbook\"}","recorded_unix_us":1787932601877078}
{"message":"{\"data\":{\"id\":2044303880699914,\"id_str\":\"2044303880699914\",\"order_type\":1,\"order_subtype\":5,\"datetime\":\"1787932602\",\"microtimestamp\":\"1787932601782000\",\"amount\":12.08882,\"amount_str\":\"12.088820\",\"amount_traded\":\"0\",\"amount_at_create\":\"12.088820\",\"price\":2481.64,\"price_str\":\"2481.64\",\"is_liquidation\":false},\"channel\":\"live_orders_ethusd\",\"event\":\"order_created\",\"event_id\":\"00065a1d-7f9c-8ef0-0000-001201000020\",\"pre_event_id\":\"00065a1d-7f9c-7f50-0000-001200000020\",\"order_source\":\"orderbook\"}","recorded_unix_us":1787932601877195}
{"message":"{\"data\":{\"id\":2044303880699915,\"id_str\":\"2044303880699915\",\"order_type\":0,\"order_subtype\":5,\"datetime\":\"1787932602\",\"microtimestamp\":\"1787932601782000\",\"amount\":0.041163,\"amount_str\":\"0.041163\",\"amount_traded\":\"0\",\"amount_at_create\":\"0.041163\",\"price\":2480.68,\"price_str\":\"2480.68\",\"is_liquidation\":false},\"channel\":\"live_orders_ethusd\",\"event\":\"order_created\",\"event_id\":\"00065a1d-7f9c-8ef0-0001-001202000020\",\"pre_event_id\":\"00065a1d-7f9c-8ef0-0000-001201000020\",\"order_source\":\"orderbook\"}","recorded_unix_us":1787932601877218}
{"message":"{\"data\":{\"id\":2044303880704004,\"id_str\":\"2044303880704004\",\"order_type\":0,\"order_subtype\":5,\"datetime\":\"1787932602\",\"microtimestamp\":\"1787932601782000\",\"amount\":5,\"amount_str\":\"5.000000\",\"amount_traded\":\"0\",\"amount_at_create\":\"5.000000\",\"price\":2479.95,\"price_str\":\"2479.95\",\"is_liquidation\":false},\"channel\":\"live_orders_ethusd\",\"event\":\"order_created\",\"event_id\":\"00065a1d-7f9c-8ef0-0002-001203000020\",\"pre_event_id\":\"00065a1d-7f9c-8ef0-0001-001202000020\",\"order_source\":\"orderbook\"}","recorded_unix_us":1787932601877287}
{"message":"{\"data\":{\"id\":2044303880704008,\"id_str\":\"2044303880704008\",\"order_type\":1,\"order_subtype\":5,\"datetime\":\"1787932602\",\"microtimestamp\":\"1787932601783000\",\"amount\":12.087458,\"amount_str\":\"12.087458\",\"amount_traded\":\"0\",\"amount_at_create\":\"12.087458\",\"price\":2481.92,\"price_str\":\"2481.92\",\"is_liquidation\":false},\"channel\":\"live_orders_ethusd\",\"event\":\"order_created\",\"event_id\":\"00065a1d-7f9c-92d8-0000-001200000020\",\"pre_event_id\":\"00065a1d-7f9c-8ef0-0002-001203000020\",\"order_source\":\"orderbook\"}","recorded_unix_us":1787932601877410}
{"message":"{\"data\":{\"id\":2044303880716294,\"id_str\":\"2044303880716294\",\"order_type\":0,\"order_subtype\":5,\"datetime\":\"1787932602\",\"microtimestamp\":\"1787932601786000\",\"amount\":6,\"amount_str\":\"6.000000\",\"amount_traded\":\"0\",\"amount_at_create\":\"6.000000\",\"price\":2479.7,\"price_str\":\"2479.70\",\"is_liquidation\":false},\"channel\":\"live_orders_ethusd\",\"event\":\"order_created\",\"event_id\":\"00065a1d-7f9c-9e90-0000-001201000020\",\"pre_event_id\":\"00065a1d-7f9c-92d8-0000-001200000020\",\"order_source\":\"orderbook\"}","recorded_unix_us":1787932601877432}
{"message":"{\"data\":{\"id\":2044303878279172,\"id_str\":\"2044303878279172\",\"order_type\":0,\"order_subtype\":5,\"datetime\":\"1787932602\",\"microtimestamp\":\"1787932601786000\",\"amount\":0.6367979,\"amount_str\":\"0.63679790\",\"amount_traded\":\"0\",\"amount_at_create\":\"0.63679790\",\"price\":78480.38,\"price_str\":\"78480.38\",\"is_liquidation\":false},\"channel\":\"live_orders_btcusd\",\"event\":\"order_deleted\",\"event_id\":\"00065a1d-7f9c-9e90-0000-000102000020\",\"pre_event_id\":\"00065a1d-7f9c-8b08-0001-000101000020\",\"order_source\":\"orderbook\"}","recorded_unix_us":1787932601877549}
{"message":"{\"data\":{\"id\":2044303878283264,\"id_str\":\"2044303878283264\",\"order_type\":0,\"order_subtype\":5,\"datetime\":\"1787932602\",\"microtimestamp\":\"1787932601787000\",\"amount\":0.50943832,\"amount_str\":\"0.50943832\",\"amount_traded\":\"0\",\"amount_at_create\":\"0.50943832\",\"price\":78478.42,\"price_str\":\"78478.42\",\"is_liquidation\":false},\"channel\":\"live_orders_btcusd\",\"event\":\"order_deleted\",\"event_id\":\"00065a1d-7f9c-a278-0000-000103000020\",\"pre_event_id\":\"00065a1d-7f9c-9e90-0000-000102000020\",\"order_source\":\"orderbook\"}","recorded_unix_us":1787932601877573}
{"message":"{\"data\":{\"id\":2044303880724484,\"id_str\":\"2044303880724484\",\"order_type\":1,\"order_subtype\":5,\"datetime\":\"1787932602\",\"microtimestamp\":\"1787932601787000\",\"amount\":4.028874,\"amount_str\":\"4.028874\",\"amount_traded\":\"0\",\"amount_at_create\":\"4.028874\",\"price\":2482.09,\"price_str\":\"2482.09\",\"is_liquidation\":false},\"channel\":\"live_orders_ethusd\",\"event\":\"order_created\",\"event_id\":\"00065a1d-7f9c-a278-0000-001202000020\",\"pre_event_id\":\"00065a1d-7f9c-9e90-0000-001201000020\",\"order_source\":\"orderbook\"}","recorded_unix_us":1787932601877684}
{"message":"{\"data\":{\"id\":2044303880728576,\"id_str\":\"2044303880728576\",\"order_type\":1,\"order_subtype\":5,\"datetime\":\"1787932602\",\"microtimestamp\":\"1787932601788000\",\"amount\":10.057184,\"amount_str\":\"10.057184\",\"amount_traded\":\"0\",\"amount_at_create\":\"10.057184\",\"price\":2485.79,\"price_str\":\"2485.79\",\"is_liquidation\":false},\"channel\":\"live_orders_ethusd\",\"event\":\"order_created\",\"event_id\":\"00065a1d-7f9c-a660-0000-001203000020\",\"pre_event_id\":\"00065a1d-7f9c-a278-0000-001202000020\",\"order_source\":\"orderbook\"}","recorded_unix_us":1787932601877745}
{"message":"{\"data\":{\"id\":2044303880728580,\"id_str\":\"2044303880728580\",\"order_type\":1,\"order_subtype\":5,\"datetime\":\"1787932602\",\"microtimestamp\":\"1787932601789000\",\"amount\":10.06507,\"amount_str\":\"10.065070\",\"amount_traded\":\"0\",\"amount_at_create\":\"10.065070\",\"price\":2483.84,\"price_str\":\"2483.84\",\"is_liquidation\":false},\"channel\":\"live_orders_ethusd\",\"event\":\"order_created\",\"event_id\":\"00065a1d-7f9c-aa48-0000-001200000020\",\"pre_event_id\":\"00065a1d-7f9c-a660-0000-001203000020\",\"order_source\":\"orderbook\"}","recorded_unix_us":1787932601877769}
{"message":"{\"data\":{\"id\":2044303880728581,\"id_str\":\"2044303880728581\",\"order_type\":1,\"order_subtype\":5,\"datetime\":\"1787932602\",\"microtimestamp\":\"1787932601789000\",\"amount\":20.097242,\"amount_str\":\"20.097242\",\"amount_traded\":\"0\",\"amount_at_create\":\"20.097242\",\"price\":2487.91,\"price_str\":\"2487.91\",\"is_liquidation\":false},\"channel\":\"live_orders_ethusd\",\"event\":\"order_created\",\"event_id\":\"00065a1d-7f9c-aa48-0001-001201000020\",\"pre_event_id\":\"00065a1d-7f9c-aa48-0000-001200000020\",\"order_source\":\"orderbook\"}","recorded_unix_us":1787932601877881}
{"message":"{\"data\":{\"id\":2044303880732678,\"id_str\":\"2044303880732678\",\"order_type\":1,\"order_subtype\":5,\"datetime\":\"1787932602\",\"microtimestamp\":\"1787932601789000\",\"amount\":20.088574,\"amount_str\":\"20.088574\",\"amount_traded\":\"0\",\"amount_at_create\":\"20.088574\",\"price\":2488.98,\"price_str\":\"2488.98\",\"is_liquidation\":false},\"channel\":\"live_orders_ethusd\",\"event\":\"order_created\",\"event_id\":\"00065a1d-7f9c-aa48-0002-001202000020\",\"pre_event_id\":\"00065a1d-7f9c-aa48-0001-001201000020\",\"order_source\":\"orderbook\"}","recorded_unix_us":1787932601877904}
{"message":"{\"data\":{\"id\":2044303879569410,\"id_str\":\"2044303879569410\",\"order_type\":0,\"order_subtype\":5,\"datetime\":\"1787932602\",\"microtimestamp\":\"1787932601791000\",\"amount\":0.403104,\"amount_str\":\"0.403104\",\"amount_traded\":\"0\",\"amount_at_create\":\"0.403104\",\"price\":2479.66,\"price_str\":\"2479.66\",\"is_liquidation\":false},\"channel\":\"live_orders_ethusd\",\"event\":\"order_deleted\",\"event_id\":\"00065a1d-7f9c-b218-0000-001203000020\",\"pre_event_id\":\"00065a1d-7f9c-aa48-0002-001202000020\",\"order_source\":\"orderbook\"}","recorded_unix_us":1787932601878015}
{"message":"{\"data\":{\"id\":2044303880736780,\"id_str\":\"2044303880736780\",\"order_type\":1,\"order_subtype\":5,\"datetime\":\"1787932602\",\"microtimestamp\":\"1787932601791000\",\"amount\":39.969006,\"amount_str\":\"39.969006\",\"amount_traded\":\"0\",\"amount_at_create\":\"39.969006\",\"price\":2501.94,\"price_str\":\"2501.94\",\"is_liquidation\":false},\"channel\":\"live_orders_ethusd\",\"event\":\"order_created\",\"event_id\":\"00065a1d-7f9c-b218-0001-001200000020\",\"pre_event_id\":\"00065a1d-7f9c-b218-0000-001203000020\",\"order_source\":\"orderbook\"}","recorded_unix_us":1787932601878078}
{"message":"{\"data\":{\"id\":2044303880740872,\"id_str\":\"2044303880740872\",\"order_type\":1,\"order_subtype\":5,\"datetime\":\"1787932602\",\"microtimestamp\":\"1787932601792000\",\"amount\":40.09205,\"amount_str\":\"40.092050\",\"amount_traded\":\"0\",\"amount_at_create\":\"40.092050\",\"price\":2494.27,\"price_str\":\"2494.27\",\"is_liquidation\":false},\"channel\":\"live_orders_ethusd\",\"event\":\"order_created\",\"event_id\":\"00065a1d-7f9c-b600-0000-001201000020\",\"pre_event_id\":\"00065a1d-7f9c-b218-0001-001200000020\",\"order_source\":\"orderbook\"}","recorded_unix_us":1787932601878117}
{"message":"{\"data\":{\"id\":2044303880744966,\"id_str\":\"2044303880744966\",\"order_type\":0,\"order_subtype\":5,\"datetime\":\"1787932602\",\"microtimestamp\":\"1787932601793000\",\"amount\":12.098474,\"amount_str\":\"12.098474\",\"amount_traded\":\"0\",\"amount_at_create\":\"12.098474\",\"price\":2479.65,\"price_str\":\"2479.65\",\"is_liquidation\":false},\"channel\":\"live_orders_ethusd\",\"event\":\"order_created\",\"event_id\":\"00065a1d-7f9c-b9e8-0000-001202000020\",\"pre_event_id\":\"00065a1d-7f9c-b600-0000-001201000020\",\"order_source\":\"orderbook\"}","recorded_unix_us":1787932601878227}
{"message":"{\"data\":{\"id\":2044303880749056,\"id_str\":\"2044303880749056\",\"order_type\":0,\"order_subtype\":5,\"datetime\":\"1787932602\",\"microtimestamp\":\"1787932601793000\",\"amount\":12.096906,\"amount_str\":\"12.096906\",\"amount_traded\":\"0\",\"amount_at_create\":\"12.096906\",\"price\":2479.97,\"price_str\":\"2479.97\",\"is_liquidation\":false},\"channel\":\"live_orders_ethusd\",\"event\":\"order_created\",\"event_id\":\"00065a1d-7f9c-b9e8-0001-001203000020\",\"pre_event_id\":\"00065a1d-7f9c-b9e8-0000-001202000020\",\"order_source\":\"orderbook\"}","recorded_unix_us":1787932601878289}
{"message":"{\"data\":{\"id\":2044303880753154,\"id_str\":\"2044303880753154\",\"order_type\":0,\"order_subtype\":5,\"datetime\":\"1787932602\",\"microtimestamp\":\"1787932601794000\",\"amount\":10.095101,\"amount_str\":\"10.095101\",\"amount_traded\":\"0\",\"amount_at_create\":\"10.095101\",\"price\":2476.44,\"price_str\":\"2476.44\",\"is_liquidation\":false},\"channel\":\"live_orders_ethusd\",\"event\":\"order_created\",\"event_id\":\"00065a1d-7f9c-bdd0-0000-001200000020\",\"pre_event_id\":\"00065a1d-7f9c-b9e8-0001-001203000020\",\"order_source\":\"orderbook\"}","recorded_unix_us":1787932601878311}
{"message":"{\"data\":{\"id\":2044303880753152,\"id_str\":\"2044303880753152\",\"order_type\":1,\"order_subtype\":5,\"datetime\":\"1787932602\",\"microtimestamp\":\"1787932601794000\",\"amount\":0.1,\"amount_str\":\"0.10000000\",\"amount_traded\":\"0\",\"amount_at_create\":\"0.10000000\",\"price\":78522.63,\"price_str\":\"78522.63\",\"is_liquidation\":false},\"channel\":\"live_orders_btcusd\",\"event\":\"order_created\",\"event_id\":\"00065a1d-7f9c-bdd0-0000-000100000020\",\"pre_event_id\":\"00065a1d-7f9c-a278-0000-000103000020\",\"order_source\":\"orderbook\"}","recorded_unix_us":1787932601878423}
{"message":"{\"data\":{\"id\":2044303880753152,\"id_str\":\"2044303880753152\",\"order_type\":1,\"order_subtype\":5,\"datetime\":\"1787932602\",\"microtimestamp\":\"1787932601794000\",\"amount\":0.1,\"amount_str\":\"0.10000000\",\"amount_traded\":\"0\",\"amount_at_create\":\"0.10000000\",\"price\":78522.63,\"price_str\":\"78522.63\",\"is_liquidation\":false},\"channel\":\"live_orders_btcusd\",\"event\":\"order_deleted\",\"event_id\":\"00065a1d-7f9c-bdd0-0001-000101000020\",\"pre_event_id\":\"00065a1d-7f9c-bdd0-0000-000100000020\",\"order_source\":\"orderbook\"}","recorded_unix_us":1787932601878483}
{"message":"{\"data\":{\"id\":2044303880753156,\"id_str\":\"2044303880753156\",\"order_type\":0,\"order_subtype\":5,\"datetime\":\"1787932602\",\"microtimestamp\":\"1787932601794000\",\"amount\":4.033204,\"amount_str\":\"4.033204\",\"amount_traded\":\"0\",\"amount_at_create\":\"4.033204\",\"price\":2479.41,\"price_str\":\"2479.41\",\"is_liquidation\":false},\"channel\":\"live_orders_ethusd\",\"event\":\"order_created\",\"event_id\":\"00065a1d-7f9c-bdd0-0001-001201000020\",\"pre_event_id\":\"00065a1d-7f9c-bdd0-0000-001200000020\",\"order_source\":\"orderbook\"}","recorded_unix_us":1787932601878506}
{"message":"{\"data\":{\"id\":2044303880753158,\"id_str\":\"2044303880753158\",\"order_type\":1,\"order_subtype\":5,\"datetime\":\"1787932602\",\"microtimestamp\":\"1787932601795000\",\"amount\":0.06310787,\"amount_str\":\"0.06310787\",\"amount_traded\":\"0\",\"amount_at_create\":\"0.06310787\",\"price\":78520.18,\"price_str\":\"78520.18\",\"is_liquidation\":false},\"channel\":\"live_orders_btcusd\",\"event\":\"order_created\",\"event_id\":\"00065a1d-7f9c-c1b8-0000-000102000020\",\"pre_event_id\":\"00065a1d-7f9c-bdd0-0001-000101000020\",\"order_source\":\"orderbook\"}","recorded_unix_us":1787932601878599}
{"message":"{\"data\":{\"id\":2044303880753158,\"id_str\":\"2044303880753158\",\"order_type\":1,\"order_subtype\":5,\"datetime\":\"1787932602\",\"microtimestamp\":\"1787932601795000\",\"amount\":0.06310787,\"amount_str\":\"0.06310787\",\"amount_traded\":\"0\",\"amount_at_create\":\"0.06310787\",\"price\":78520.18,\"price_str\":\"78520.18\",\"is_liquidation\":false},\"channel\":\"live_orders_btcusd\",\"event\":\"order_deleted\",\"event_id\":\"00065a1d-7f9c-c1b8-0001-000103000020\",\"pre_event_id\":\"00065a1d-7f9c-c1b8-0000-000102000020\",\"order_source\":\"orderbook\"}","recorded_unix_us":1787932601878623}
{"message":"{\"data\":{\"id\":2044303880753160,\"id_str\":\"2044303880753160\",\"order_type\":0,\"order_subtype\":5,\"datetime\":\"1787932602\",\"microtimestamp\":\"1787932601795000\",\"amount\":10.090138,\"amount_str\":\"10.090138\",\"amount_traded\":\"0\",\"amount_at_create\":\"10.090138\",\"price\":2477.66,\"price_str\":\"2477.66\",\"is_liquidation\":false},\"channel\":\"live_orders_ethusd\",\"event\":\"order_created\",\"event_id\":\"00065a1d-7f9c-c1b8-0000-001202000020\",\"pre_event_id\":\"00065a1d-7f9c-bdd0-0001-001201000020\",\"order_source\":\"orderbook\"}","recorded_unix_us":1787932601878718}
{"message":"{\"data\":{\"id\":2044303880753159,\"id_str\":\"2044303880753159\",\"order_type\":0,\"order_subtype\":5,\"datetime\":\"1787932602\",\"microtimestamp\":\"1787932601795000\",\"amount\":20.204386,\"amount_str\":\"20.204386\",\"amount_traded\":\"0\",\"amount_at_create\":\"20.204386\",\"price\":2474.71,\"price_str\":\"2474.71\",\"is_liquidation\":false},\"channel\":\"live_orders_ethusd\",\"event\":\"order_created\",\"event_id\":\"00065a1d-7f9c-c1b8-0001-001203000020\",\"pre_event_id\":\"00065a1d-7f9c-c1b8-0000-001202000020\",\"order_source\":\"orderbook\"}","recorded_unix_us":1787932601878740}
{"message":"{\"data\":{\"id\":2044303880757250,\"id_str\":\"2044303880757250\",\"order_type\":0,\"order_subtype\":5,\"datetime\":\"1787932602\",\"microtimestamp\":\"1787932601795000\",\"amount\":4.033601,\"amount_str\":\"4.033601\",\"amount_traded\":\"0\",\"amount_at_create\":\"4.033601\",\"price\":2479.17,\"price_str\":\"2479.17\",\"is_liquidation\":false},\"channel\":\"live_orders_ethusd\",\"event\":\"order_created\",\"event_id\":\"00065a1d-7f9c-c1b8-0002-001200000020\",\"pre_event_id\":\"00065a1d-7f9c-c1b8-0001-001203000020\",\"order_source\":\"orderbook\"}","recorded_unix_us":1787932601878851}
{"message":"{\"data\":{\"id\":2044303880761355,\"id_str\":\"2044303880761355\",\"order_type\":1,\"order_subtype\":5,\"datetime\":\"1787932602\",\"microtimestamp\":\"1787932601796000\",\"amount\":0.06310787,\"amount_str\":\"0.06310787\",\"amount_traded\":\"0\",\"amount_at_create\":\"0.06310787\",\"price\":78522.54,\"price_str\":\"78522.54\",\"is_liquidation\":false},\"channel\":\"live_orders_btcusd\",\"event\":\"order_created\",\"event_id\":\"00065a1d-7f9c-c5a0-0000-000100000020\",\"pre_event_id\":\"00065a1d-7f9c-c1b8-0001-000103000020\",\"order_source\":\"orderbook\"}","recorded_unix_us":1787932601878913}
{"message":"{\"data\":{\"id\":2044303880761355,\"id_str\":\"2044303880761355\",\"order_type\":1,\"order_subtype\":5,\"datetime\":\"1787932602\",\"microtimestamp\":\"1787932601796000\",\"amount\":0.06310787,\"amount_str\":\"0.06310787\",\"amount_traded\":\"0\",\"amount_at_create\":\"0.06310787\",\"price\":78522.54,\"price_str\":\"78522.54\",\"is_liquidation\":false},\"channel\":\"live_orders_btcusd\",\"event\":\"order_deleted\",\"event_id\":\"00065a1d-7f9c-c5a0-0001-000101000020\",\"pre_event_id\":\"00065a1d-7f9c-c5a0-0000-000100000020\",\"order_source\":\"orderbook\"}","recorded_unix_us":1787932601878936}
{"message":"{\"data\":{\"id\":2044303880765442,\"id_str\":\"2044303880765442\",\"order_type\":0,\"order_subtype\":5,\"datetime\":\"1787932602\",\"microtimestamp\":\"1787932601797000\",\"amount\":0.50943592,\"amount_str\":\"0.50943592\",\"amount_traded\":\"0\",\"amount_at_create\":\"0.50943592\",\"price\":78479.72,\"price_str\":\"78479.72\",\"is_liquidation\":false},\"channel\":\"live_orders_btcusd\",\"event\":\"order_created\",\"event_id\":\"00065a1d-7f9c-c988-0000-000102000020\",\"pre_event_id\":\"00065a1d-7f9c-c5a0-0001-000101000020\",\"order_source\":\"orderbook\"}","recorded_unix_us":1787932601879048}
{"message":"{\"data\":{\"id\":2044303880769540,\"id_str\":\"2044303880769540\",\"order_type\":0,\"order_subtype\":5,\"datetime\":\"1787932602\",\"microtimestamp\":\"1787932601798000\",\"amount\":0.6367949,\"amount_str\":\"0.63679490\",\"amount_traded\":\"0\",\"amount_at_create\":\"0.63679490\",\"price\":78481.68,\"price_str\":\"78481.68\",\"is_liquidation\":false},\"channel\":\"live_orders_btcusd\",\"event\":\"order_created\",\"event_id\":\"00065a1d-7f9c-cd70-0000-000103000020\",\"pre_event_id\":\"00065a1d-7f9c-c988-0000-000102000020\",\"order_source\":\"orderbook\"}","recorded_unix_us":1787932601879071}
{"message":"{\"data\":{\"id\":2044303880413187,\"id_str\":\"2044303880413187\",\"order_type\":0,\"order_subtype\":5,\"datetime\":\"1787932602\",\"microtimestamp\":\"1787932601800000\",\"amount\":0.1910383,\"amount_str\":\"0.19103830\",\"amount_traded\":\"0\",\"amount_at_create\":\"0.19103830\",\"price\":78482.99,\"price_str\":\"78482.99\",\"is_liquidation\":false},\"channel\":\"live_orders_btcusd\",\"event\":\"order_deleted\",\"event_id\":\"00065a1d-7f9c-d540-0000-000100000020\",\"pre_event_id\":\"00065a1d-7f9c-cd70-0000-000103000020\",\"order_source\":\"orderbook\"}","recorded_unix_us":1787932601879150}
{"message":"{\"data\":{\"id\":2044303880777729,\"id_str\":\"2044303880777729\",\"order_type\":0,\"order_subtype\":5,\"datetime\":\"1787932602\",\"microtimestamp\":\"1787932601800000\",\"amount\":0.403101,\"amount_str\":\"0.403101\",\"amount_traded\":\"0\",\"amount_at_create\":\"0.403101\",\"price\":2479.8,\"price_str\":\"2479.80\",\"is_liquidation\":false},\"channel\":\"live_orders_ethusd\",\"event\":\"order_created\",\"event_id\":\"00065a1d-7f9c-d540-0000-001201000020\",\"pre_event_id\":\"00065a1d-7f9c-c1b8-0002-001200000020\",\"order_source\":\"orderbook\"}","recorded_unix_us":1787932601879257}
{"message":"{\"data\":{\"id\":2044303880785925,\"id_str\":\"2044303880785925\",\"order_type\":1,\"order_subtype\":5,\"datetime\":\"1787932602\",\"microtimestamp\":\"1787932601803000\",\"amount\":0.044018,\"amount_str\":\"0.044018\",\"amount_traded\":\"0\",\"amount_at_create\":\"0.044018\",\"price\":2480.82,\"price_str\":\"2480.82\",\"is_liquidation\":false},\"channel\":\"live_orders_ethusd\",\"event\":\"order_created\",\"event_id\":\"00065a1d-7f9c-e0f8-0000-001202000020\",\"pre_event_id\":\"00065a1d-7f9c-d540-0000-001201000020\",\"order_source\":\"orderbook\"}","recorded_unix_us":1787932601879279}
{"message":"{\"data\":{\"id\":2044303879004165,\"id_str\":\"2044303879004165\",\"order_type\":0,\"order_subtype\":5,\"datetime\":\"1787932602\",\"microtimestamp\":\"1787932601809000\",\"amount\":1.184652,\"amount_str\":\"1.184652\",\"amount_traded\":\"0\",\"amount_at_create\":\"1.184652\",\"price\":2480.14,\"price_str\":\"2480.14\",\"is_liquidation\":false},\"channel\":\"live_orders_ethusd\",\"event\":\"order_deleted\",\"event_id\":\"00065a1d-7f9c-f868-0000-001203000020\",\"pre_event_id\":\"00065a1d-7f9c-e0f8-0000-001202000020\",\"order_source\":\"orderbook\"}","recorded_unix_us":1787932601879391}
{"message":"{\"data\":{\"id\":2044303880814602,\"id_str\":\"2044303880814602\",\"order_type\":0,\"order_subtype\":5,\"datetime\":\"1787932602\",\"microtimestamp\":\"1787932601809000\",\"amount\":40.528033,\"amount_str\":\"40.528033\",\"amount_traded\":\"0\",\"amount_at_create\":\"40.528033\",\"price\":2467.42,\"price_str\":\"2467.42\",\"is_liquidation\":false},\"channel\":\"live_orders_ethusd\",\"event\":\"order_created\",\"event_id\":\"00065a1d-7f9c-f868-0001-001200000020\",\"pre_event_id\":\"00065a1d-7f9c-f868-0000-001203000020\",\"order_source\":\"orderbook\"}","recorded_unix_us":1787932601879452}
{"message":"{\"data\":{\"id\":2044303880818695,\"id_str\":\"2044303880818695\",\"order_type\":0,\"order_subtype\":5,\"datetime\":\"1787932602\",\"microtimestamp\":\"1787932601811000\",\"amount\":0.19103785,\"amount_str\":\"0.19103785\",\"amount_traded\":\"0\",\"amount_at_create\":\"0.19103785\",\"price\":78484.09,\"price_str\":\"78484.09\",\"is_liquidation\":false},\"channel\":\"live_orders_btcusd\",\"event\":\"order_created\",\"event_id\":\"00065a1d-7f9d-0038-0000-000101000020\",\"pre_event_id\":\"00065a1d-7f9c-d540-0000-000100000020\",\"order_source\":\"orderbook\"}","recorded_unix_us":1787932601879481}
{"message":"{\"data\":{\"id\":2044303880826884,\"id_str\":\"2044303880826884\",\"order_type\":1,\"order_subtype\":5,\"datetime\":\"1787932602\",\"microtimestamp\":\"1787932601812000\",\"amount\":0.1,\"amount_str\":\"0.10000000\",\"amount_traded\":\"0\",\"amount_at_create\":\"0.10000000\",\"price\":78522.62,\"price_str\":\"78522.62\",\"is_liquidation\":false},\"channel\":\"live_orders_btcusd\",\"event\":\"order_created\",\"event_id\":\"00065a1d-7f9d-0420-0000-000102000020\",\"pre_event_id\":\"00065a1d-7f9d-0038-0000-000101000020\",\"order_source\":\"orderbook\"}","recorded_unix_us":1787932601879576}
{"message":"{\"data\":{\"id\":2044303880826884,\"id_str\":\"2044303880826884\",\"order_type\":1,\"order_subtype\":5,\"datetime\":\"1787932602\",\"microtimestamp\":\"1787932601812000\",\"amount\":0.1,\"amount_str\":\"0.10000000\",\"amount_traded\":\"0\",\"amount_at_create\":\"0.10000000\",\"price\":78522.62,\"price_str\":\"78522.62\",\"is_liquidation\":false},\"channel\":\"live_orders_btcusd\",\"event\":\"order_deleted\",\"event_id\":\"00065a1d-7f9d-0420-0001-000103000020\",\"pre_event_id\":\"00065a1d-7f9d-0420-0000-000102000020\",\"order_source\":\"orderbook\"}","recorded_unix_us":1787932601879599}
{"message":"{\"data\":{\"id\":2044303880880129,\"id_str\":\"2044303880880129\",\"order_type\":0,\"order_subtype\":5,\"datetime\":\"1787932602\",\"microtimestamp\":\"1787932601825000\",\"amount\":8,\"amount_str\":\"8.000000\",\"amount_traded\":\"0\",\"amount_at_create\":\"8.000000\",\"price\":2478.96,\"price_str\":\"2478.96\",\"is_liquidation\":false},\"channel\":\"live_orders_ethusd\",\"event\":\"order_created\",\"event_id\":\"00065a1d-7f9d-36e8-0000-001201000020\",\"pre_event_id\":\"00065a1d-7f9c-f868-0001-001200000020\",\"order_source\":\"orderbook\"}","recorded_unix_us":1787932601879713}
{"message":"{\"data\":{\"id\":2044303880880134,\"id_str\":\"2044303880880134\",\"order_type\":0,\"order_subtype\":5,\"datetime\":\"1787932602\",\"microtimestamp\":\"1787932601825000\",\"amount\":40.650432,\"amount_str\":\"40.650432\",\"amount_traded\":\"0\",\"amount_at_create\":\"40.650432\",\"price\":2459.99,\"price_str\":\"2459.99\",\"is_liquidation\":false},\"channel\":\"live_orders_ethusd\",\"event\":\"order_created\",\"event_id\":\"00065a1d-7f9d-36e8-0001-001202000020\",\"pre_event_id\":\"00065a1d-7f9d-36e8-0000-001201000020\",\"order_source\":\"orderbook\"}","recorded_unix_us":1787932601879741}
{"message":"{\"data\":{\"id\":2044303880880133,\"id_str\":\"2044303880880133\",\"order_type\":0,\"order_subtype\":5,\"datetime\":\"1787932602\",\"microtimestamp\":\"1787932601825000\",\"amount\":0.00140266,\"amount_str\":\"0.00140266\",\"amount_traded\":\"0\",\"amount_at_create\":\"0.00140266\",\"price\":70667.51,\"price_str\":\"70667.51\",\"is_liquidation\":false},\"channel\":\"live_orders_btcusd\",\"event\":\"order_created\",\"event_id\":\"00065a1d-7f9d-36e8-0000-000100000020\",\"pre_event_id\":\"00065a1d-7f9d-0420-0001-000103000020\",\"order_source\":\"orderbook\"}","recorded_unix_us":1787932601879853}
{"message":"{\"data\":{\"id\":2044303880888320,\"id_str\":\"2044303880888320\",\"order_type\":1,\"order_subtype\":5,\"datetime\":\"1787932602\",\"microtimestamp\":\"1787932601827000\",\"amount\":0.1,\"amount_str\":\"0.10000000\",\"amount_traded\":\"0\",\"amount_at_create\":\"0.10000000\",\"price\":78522.63,\"price_str\":\"78522.63\",\"is_liquidation\":false},\"channel\":\"live_orders_btcusd\",\"event\":\"order_created\",\"event_id\":\"00065a1d-7f9d-3eb8-0000-000101000020\",\"pre_event_id\":\"00065a1d-7f9d-36e8-0000-000100000020\",\"order_source\":\"orderbook\"}","recorded_unix_us":1787932601879914}
{"message":"{\"data\":{\"id\":2044303880888320,\"id_str\":\"2044303880888320\",\"order_type\":1,\"order_subtype\":5,\"datetime\":\"1787932602\",\"microtimestamp\":\"1787932601827000\",\"amount\":0.1,\"amount_str\":\"0.10000000\",\"amount_traded\":\"0\",\"amount_at_create\":\"0.10000000\",\"price\":78522.63,\"price_str\":\"78522.63\",\"is_liquidation\":false},\"channel\":\"live_orders_btcusd\",\"event\":\"order_deleted\",\"event_id\":\"00065a1d-7f9d-3eb8-0001-000102000020\",\"pre_event_id\":\"00065a1d-7f9d-3eb8-0000-000101000020\",\"order_source\":\"orderbook\"}","recorded_unix_us":1787932601879937}
{"message":"{\"data\":{\"id\":2044303880892424,\"id_str\":\"2044303880892424\",\"order_type\":0,\"order_subtype\":0,\"datetime\":\"1787932602\",\"microtimestamp\":\"1787932601829000\",\"amount\":2.016386,\"amount_str\":\"2.016386\",\"amount_traded\":\"0\",\"amount_at_create\":\"2.016386\",\"price\":2480.09,\"price_str\":\"2480.09\",\"is_liquidation\":false},\"channel\":\"live_orders_ethusd\",\"event\":\"order_created\",\"event_id\":\"00065a1d-7f9d-4688-0000-001203000020\",\"pre_event_id\":\"00065a1d-7f9d-36e8-0001-001202000020\",\"order_source\":\"orderbook\"}","recorded_unix_us":1787932601880017}
{"message":"{\"data\":{\"id\":2044303880900611,\"id_str\":\"2044303880900611\",\"order_type\":0,\"order_subtype\":5,\"datetime\":\"1787932602\",\"microtimestamp\":\"1787932601830000\",\"amount\":0.12,\"amount_str\":\"0.12000000\",\"amount_traded\":\"0\",\"amount_at_create\":\"0.12000000\",\"price\":78508.22,\"price_str\":\"78508.22\",\"is_liquidation\":false},\"channel\":\"live_orders_btcusd\",\"event\":\"order_created\",\"event_id\":\"00065a1d-7f9d-4a70-0000-000103000020\",\"pre_event_id\":\"00065a1d-7f9d-3eb8-0001-000102000020\",\"order_source\":\"orderbook\"}","recorded_unix_us":1787932601880091}
{"message":"{\"data\":{\"id\":2044303878418442,\"id_str\":\"2044303878418442\",\"order_type\":0,\"order_subtype\":5,\"datetime\":\"1787932602\",\"microtimestamp\":\"1787932601832000\",\"amount\":0.12,\"amount_str\":\"0.12000000\",\"amount_traded\":\"0\",\"amount_at_create\":\"0.12000000\",\"price\":78507.07,\"price_str\":\"78507.07\",\"is_liquidation\":false},\"channel\":\"live_orders_btcusd\",\"event\":\"order_deleted\",\"event_id\":\"00065a1d-7f9d-5240-0000-000100000020\",\"pre_event_id\":\"00065a1d-7f9d-4a70-0000-000103000020\",\"order_source\":\"orderbook\"}","recorded_unix_us":1787932601880150}
{"message":"{\"data\":{\"id\":2044303867875332,\"id_str\":\"2044303867875332\",\"order_type\":1,\"order_subtype\":5,\"datetime\":\"1787932602\",\"microtimestamp\":\"1787932601835000\",\"amount\":5.283004,\"amount_str\":\"5.283004\",\"amount_traded\":\"0\",\"amount_at_create\":\"5.283004\",\"price\":2482.03,\"price_str\":\"2482.03\",\"is_liquidation\":false},\"channel\":\"live_orders_ethusd\",\"event\":\"order_deleted\",\"event_id\":\"00065a1d-7f9d-5df8-0000-001200000020\",\"pre_event_id\":\"00065a1d-7f9d-4688-0000-001203000020\",\"order_source\":\"orderbook\"}","recorded_unix_us":1787932601880226}
{"message":"{\"data\":{\"id\":2044303880699914,\"id_str\":\"2044303880699914\",\"order_type\":1,\"order_subtype\":5,\"datetime\":\"1787932602\",\"microtimestamp\":\"1787932601837000\",\"amount\":12.08882,\"amount_str\":\"12.088820\",\"amount_traded\":\"0\",\"amount_at_create\":\"12.088820\",\"price\":2481.64,\"price_str\":\"2481.64\",\"is_liquidation\":false},\"channel\":\"live_orders_ethusd\",\"event\":\"order_deleted\",\"event_id\":\"00065a1d-7f9d-65c8-0000-001201000020\",\"pre_event_id\":\"00065a1d-7f9d-5df8-0000-001200000020\",\"order_source\":\"orderbook\"}","recorded_unix_us":1787932601881053}
{"message":"{\"data\":{\"id\":2044303880933376,\"id_str\":\"2044303880933376\",\"order_type\":1,\"order_subtype\":5,\"datetime\":\"1787932602\",\"microtimestamp\":\"1787932601838000\",\"amount\":5,\"amount_str\":\"5.000000\",\"amount_traded\":\"0\",\"amount_at_create\":\"5.000000\",\"price\":2481.51,\"price_str\":\"2481.51\",\"is_liquidation\":false},\"channel\":\"live_orders_ethusd\",\"event\":\"order_created\",\"event_id\":\"00065a1d-7f9d-69b0-0000-001202000020\",\"pre_event_id\":\"00065a1d-7f9d-65c8-0000-001201000020\",\"order_source\":\"orderbook\"}","recorded_unix_us":1787932601881260}
{"message":"{\"data\":{\"id\":2044303880724484,\"id_str\":\"2044303880724484\",\"order_type\":1,\"order_subtype\":5,\"datetime\":\"1787932602\",\"microtimestamp\":\"1787932601838000\",\"amount\":4.028874,\"amount_str\":\"4.028874\",\"amount_traded\":\"0\",\"amount_at_create\":\"4.028874\",\"price\":2482.09,\"price_str\":\"2482.09\",\"is_liquidation\":false},\"channel\":\"live_orders_ethusd\",\"event\":\"order_deleted\",\"event_id\":\"00065a1d-7f9d-69b0-0001-001203000020\",\"pre_event_id\":\"00065a1d-7f9d-69b0-0000-001202000020\",\"order_source\":\"orderbook\"}","recorded_unix_us":1787932601881285}
{"message":"{\"data\":{\"id\":2044303880228867,\"id_str\":\"2044303880228867\",\"order_type\":0,\"order_subtype\":5,\"datetime\":\"1787932602\",\"microtimestamp\":\"1787932601838000\",\"amount\":0.00140266,\"amount_str\":\"0.00140266\",\"amount_traded\":\"0\",\"amount_at_create\":\"0.00140266\",\"price\":70667.51,\"price_str\":\"70667.51\",\"is_liquidation\":false},\"channel\":\"live_orders_btcusd\",\"event\":\"order_deleted\",\"event_id\":\"00065a1d-7f9d-69b0-0000-000101000020\",\"pre_event_id\":\"00065a1d-7f9d-5240-0000-000100000020\",\"order_source\":\"orderbook\"}","recorded_unix_us":1787932601881306}
{"message":"{\"data\":{\"id\":2044303880749056,\"id_str\":\"2044303880749056\",\"order_type\":0,\"order_subtype\":5,\"datetime\":\"1787932602\",\"microtimestamp\":\"1787932601839000\",\"amount\":12.096906,\"amount_str\":\"12.096906\",\"amount_traded\":\"0\",\"amount_at_create\":\"12.096906\",\"price\":2479.97,\"price_str\":\"2479.97\",\"is_liquidation\":false},\"channel\":\"live_orders_ethusd\",\"event\":\"order_deleted\",\"event_id\":\"00065a1d-7f9d-6d98-0000-001200000020\",\"pre_event_id\":\"00065a1d-7f9d-69b0-0001-001203000020\",\"order_source\":\"orderbook\"}","recorded_unix_us":1787932601881326}
{"message":"{\"data\":{\"id\":2044303880937472,\"id_str\":\"2044303880937472\",\"order_type\":1,\"order_subtype\":5,\"datetime\":\"1787932602\",\"microtimestamp\":\"1787932601839000\",\"amount\":6,\"amount_str\":\"6.000000\",\"amount_traded\":\"0\",\"amount_at_create\":\"6.000000\",\"price\":2482.5,\"price_str\":\"2482.50\",\"is_liquidation\":false},\"channel\":\"live_orders_ethusd\",\"event\":\"order_created\",\"event_id\":\"00065a1d-7f9d-6d98-0001-001201000020\",\"pre_event_id\":\"00065a1d-7f9d-6d98-0000-001200000020\",\"order_source\":\"orderbook\"}","recorded_unix_us":1787932601881389}
{"message":"{\"data\":{\"id\":2044303880744966,\"id_str\":\"2044303880744966\",\"order_type\":0,\"order_subtype\":5,\"datetime\":\"1787932602\",\"microtimestamp\":\"1787932601839000\",\"amount\":12.098474,\"amount_str\":\"12.098474\",\"amount_traded\":\"0\",\"amount_at_create\":\"12.098474\",\"price\":2479.65,\"price_str\":\"2479.65\",\"is_liquidation\":false},\"channel\":\"live_orders_ethusd\",\"event\":\"order_deleted\",\"event_id\":\"00065a1d-7f9d-6d98-0002-001202000020\",\"pre_event_id\":\"00065a1d-7f9d-6d98-0001-001201000020\",\"order_source\":\"orderbook\"}","recorded_unix_us":1787932601881487}
{"message":"{\"data\":{\"id\":2044303880941571,\"id_str\":\"2044303880941571\",\"order_type\":1,\"order_subtype\":5,\"datetime\":\"1787932602\",\"microtimestamp\":\"1787932601840000\",\"amount\":0.06310787,\"amount_str\":\"0.06310787\",\"amount_traded\":\"0\",\"amount_at_create\":\"0.06310787\",\"price\":78520.44,\"price_str\":\"78520.44\",\"is_liquidation\":false},\"channel\":\"live_orders_btcusd\",\"event\":\"order_created\",\"event_id\":\"00065a1d-7f9d-7180-0000-000102000020\",\"pre_event_id\":\"00065a1d-7f9d-69b0-0000-000101000020\",\"order_source\":\"orderbook\"}","recorded_unix_us":1787932601881510}
{"message":"{\"data\":{\"id\":2044303880941571,\"id_str\":\"2044303880941571\",\"order_type\":1,\"order_subtype\":5,\"datetime\":\"1787932602\",\"microtimestamp\":\"1787932601840000\",\"amount\":0.06310787,\"amount_str\":\"0.06310787\",\"amount_traded\":\"0\",\"amount_at_create\":\"0.06310787\",\"price\":78520.44,\"price_str\":\"78520.44\",\"is_liquidation\":false},\"channel\":\"live_orders_btcusd\",\"event\":\"order_deleted\",\"event_id\":\"00065a1d-7f9d-7180-0001-000103000020\",\"pre_event_id\":\"00065a1d-7f9d-7180-0000-000102000020\",\"order_source\":\"orderbook\"}","recorded_unix_us":1787932601881626}
{"message":"{\"data\":{\"id\":2044303880945679,\"id_str\":\"2044303880945679\",\"order_type\":1,\"order_subtype\":5,\"datetime\":\"1787932602\",\"microtimestamp\":\"1787932601842000\",\"amount\":5,\"amount_str\":\"5.000000\",\"amount_traded\":\"0\",\"amount_at_create\":\"5.000000\",\"price\":2481.76,\"price_str\":\"2481.76\",\"is_liquidation\":false},\"channel\":\"live_orders_ethusd\",\"event\":\"order_created\",\"event_id\":\"00065a1d-7f9d-7950-0000-001203000020\",\"pre_event_id\":\"00065a1d-7f9d-6d98-0002-001202000020\",\"order_source\":\"orderbook\"}","recorded_unix_us":1787932601881649}
{"message":"{\"data\":{\"id\":2044303880769540,\"id_str\":\"2044303880769540\",\"order_type\":0,\"order_subtype\":5,\"datetime\":\"1787932602\",\"microtimestamp\":\"1787932601849000\",\"amount\":0.6367949,\"amount_str\":\"0.63679490\",\"amount_traded\":\"0\",\"amount_at_create\":\"0.63679490\",\"price\":78481.68,\"price_str\":\"78481.68\",\"is_liquidation\":false},\"channel\":\"live_orders_btcusd\",\"event\":\"order_deleted\",\"event_id\":\"00065a1d-7f9d-94a8-0000-000100000020\",\"pre_event_id\":\"00065a1d-7f9d-7180-0001-000103000020\",\"order_source\":\"orderbook\"}","recorded_unix_us":1787932601894485}
{"message":"{\"data\":{\"id\":2044303880765442,\"id_str\":\"2044303880765442\",\"order_type\":0,\"order_subtype\":5,\"datetime\":\"1787932602\",\"microtimestamp\":\"1787932601850000\",\"amount\":0.50943592,\"amount_str\":\"0.50943592\",\"amount_traded\":\"0\",\"amount_at_create\":\"0.50943592\",\"price\":78479.72,\"price_str\":\"78479.72\",\"is_liquidation\":false},\"channel\":\"live_orders_btcusd\",\"event\":\"order_deleted\",\"event_id\":\"00065a1d-7f9d-9890-0000-000101000020\",\"pre_event_id\":\"00065a1d-7f9d-94a8-0000-000100000020\",\"order_source\":\"orderbook\"}","recorded_unix_us":1787932601894519}
{"message":"{\"data\":{\"id\":2044303880990722,\"id_str\":\"2044303880990722\",\"order_type\":1,\"order_subtype\":0,\"datetime\":\"1787932602\",\"microtimestamp\":\"1787932601852000\",\"amount\":0.06310787,\"amount_str\":\"0.06310787\",\"amount_traded\":\"0\",\"amount_at_create\":\"0.06310787\",\"price\":78549.2,\"price_str\":\"78549.20\",\"is_liquidation\":false},\"channel\":\"live_orders_btcusd\",\"event\":\"order_created\",\"event_id\":\"00065a1d-7f9d-a060-0000-000102000020\",\"pre_event_id\":\"00065a1d-7f9d-9890-0000-000101000020\",\"order_source\":\"orderbook\"}","recorded_unix_us":1787932601894609}
{"message":"{\"data\":{\"id\":2044303877296132,\"id_str\":\"2044303877296132\",\"order_type\":0,\"order_subtype\":5,\"datetime\":\"1787932602\",\"microtimestamp\":\"1787932601853000\",\"amount\":0.594864,\"amount_str\":\"0.594864\",\"amount_traded\":\"0\",\"amount_at_create\":\"0.594864\",\"price\":2479.8,\"price_str\":\"2479.80\",\"is_liquidation\":false},\"channel\":\"live_orders_ethusd\",\"event\":\"order_deleted\",\"event_id\":\"00065a1d-7f9d-a448-0000-001200000020\",\"pre_event_id\":\"00065a1d-7f9d-7950-0000-001203000020\",\"order_source\":\"orderbook\"}","recorded_unix_us":1787932601894695}
{"message":"{\"data\":{\"id\":2044303878631432,\"id_str\":\"2044303878631432\",\"order_type\":0,\"order_subtype\":5,\"datetime\":\"1787932602\",\"microtimestamp\":\"1787932601854000\",\"amount\":0.262273,\"amount_str\":\"0.262273\",\"amount_traded\":\"0\",\"amount_at_create\":\"0.262273\",\"price\":2480.01,\"price_str\":\"2480.01\",\"is_liquidation\":false},\"channel\":\"live_orders_ethusd\",\"event\":\"order_deleted\",\"event_id\":\"00065a1d-7f9d-a830-0000-001201000020\",\"pre_event_id\":\"00065a1d-7f9d-a448-0000-001200000020\",\"order_source\":\"orderbook\"}","recorded_unix_us":1787932601906882}
{"message":"{\"data\":{\"id\":2044303880699915,\"id_str\":\"2044303880699915\",\"order_type\":0,\"order_subtype\":5,\"datetime\":\"1787932602\",\"microtimestamp\":\"1787932601859000\",\"amount\":0.041163,\"amount_str\":\"0.041163\",\"amount_traded\":\"0\",\"amount_at_create\":\"0.041163\",\"price\":2480.68,\"price_str\":\"2480.68\",\"is_liquidation\":false},\"channel\":\"live_orders_ethusd\",\"event\":\"order_deleted\",\"event_id\":\"00065a1d-7f9d-bbb8-0000-001202000020\",\"pre_event_id\":\"00065a1d-7f9d-a830-0000-001201000020\",\"order_source\":\"orderbook\"}","recorded_unix_us":1787932601906966}
{"message":"{\"data\":{\"id\":2044303881019403,\"id_str\":\"2044303881019403\",\"order_type\":0,\"order_subtype\":5,\"datetime\":\"1787932602\",\"microtimestamp\":\"1787932601860000\",\"amount\":0.63679333,\"amount_str\":\"0.63679333\",\"amount_traded\":\"0\",\"amount_at_create\":\"0.63679333\",\"price\":78482.58,\"price_str\":\"78482.58\",\"is_liquidation\":false},\"channel\":\"live_orders_btcusd\",\"event\":\"order_created\",\"event_id\":\"00065a1d-7f9d-bfa0-0000-000103000020\",\"pre_event_id\":\"00065a1d-7f9d-a060-0000-000102000020\",\"order_source\":\"orderbook\"}","recorded_unix_us":1787932601907070}
{"message":"{\"data\":{\"id\":2044303880704008,\"id_str\":\"2044303880704008\",\"order_type\":1,\"order_subtype\":5,\"datetime\":\"1787932602\",\"microtimestamp\":\"1787932601860000\",\"amount\":12.087458,\"amount_str\":\"12.087458\",\"amount_traded\":\"0\",\"amount_at_create\":\"12.087458\",\"price\":2481.92,\"price_str\":\"2481.92\",\"is_liquidation\":false},\"channel\":\"live_orders_ethusd\",\"event\":\"order_deleted\",\"event_id\":\"00065a1d-7f9d-bfa0-0000-001203000020\",\"pre_event_id\":\"00065a1d-7f9d-bbb8-0000-001202000020\",\"order_source\":\"orderbook\"}","recorded_unix_us":1787932601907186}
{"message":"{\"data\":{\"id\":2044303881023494,\"id_str\":\"2044303881023494\",\"order_type\":0,\"order_subtype\":5,\"datetime\":\"1787932602\",\"microtimestamp\":\"1787932601860000\",\"amount\":0.50943466,\"amount_str\":\"0.50943466\",\"amount_traded\":\"0\",\"amount_at_create\":\"0.50943466\",\"price\":78480.62,\"price_str\":\"78480.62\",\"is_liquidation\":false},\"channel\":\"live_orders_btcusd\",\"event\":\"order_created\",\"event_id\":\"00065a1d-7f9d-bfa0-0001-000100000020\",\"pre_event_id\":\"00065a1d-7f9d-bfa0-0000-000103000020\",\"order_source\":\"orderbook\"}","recorded_unix_us":1787932601907213}
{"message":"{\"data\":{\"id\":2044303881023503,\"id_str\":\"2044303881023503\",\"order_type\":1,\"order_subtype\":5,\"datetime\":\"1787932602\",\"microtimestamp\":\"1787932601861000\",\"amount\":0.1,\"amount_str\":\"0.10000000\",\"amount_traded\":\"0\",\"amount_at_create\":\"0.10000000\",\"price\":78522.62,\"price_str\":\"78522.62\",\"is_liquidation\":false},\"channel\":\"live_orders_btcusd\",\"event\":\"order_created\",\"event_id\":\"00065a1d-7f9d-c388-0000-000101000020\",\"pre_event_id\":\"00065a1d-7f9d-bfa0-0001-000100000020\",\"order_source\":\"orderbook\"}","recorded_unix_us":1787932601907336}
{"message":"{\"data\":{\"id\":2044303881023503,\"id_str\":\"2044303881023503\",\"order_type\":1,\"order_subtype\":5,\"datetime\":\"1787932602\",\"microtimestamp\":\"1787932601861000\",\"amount\":0.1,\"amount_str\":\"0.10000000\",\"amount_traded\":\"0\",\"amount_at_create\":\"0.10000000\",\"price\":78522.62,\"price_str\":\"78522.62\",\"is_liquidation\":false},\"channel\":\"live_orders_btcusd\",\"event\":\"order_deleted\",\"event_id\":\"00065a1d-7f9d-c388-0001-000102000020\",\"pre_event_id\":\"00065a1d-7f9d-c388-0000-000101000020\",\"order_source\":\"orderbook\"}","recorded_unix_us":1787932601907360}
{"message":"{\"data\":{\"id\":2044303881027597,\"id_str\":\"2044303881027597\",\"order_type\":1,\"order_subtype\":5,\"datetime\":\"1787932602\",\"microtimestamp\":\"1787932601861000\",\"amount\":0.1,\"amount_str\":\"0.10000000\",\"amount_traded\":\"0\",\"amount_at_create\":\"0.10000000\",\"price\":78522.63,\"price_str\":\"78522.63\",\"is_liquidation\":false},\"channel\":\"live_orders_btcusd\",\"event\":\"order_created\",\"event_id\":\"00065a1d-7f9d-c388-0002-000103000020\",\"pre_event_id\":\"00065a1d-7f9d-c388-0001-000102000020\",\"order_source\":\"orderbook\"}","recorded_unix_us":1787932601907461}
{"message":"{\"data\":{\"id\":2044303881027597,\"id_str\":\"2044303881027597\",\"order_type\":1,\"order_subtype\":5,\"datetime\":\"1787932602\",\"microtimestamp\":\"1787932601861000\",\"amount\":0.1,\"amount_str\":\"0.10000000\",\"amount_traded\":\"0\",\"amount_at_create\":\"0.10000000\",\"price\":78522.63,\"price_str\":\"78522.63\",\"is_liquidation\":false},\"channel\":\"live_orders_btcusd\",\"event\":\"order_deleted\",\"event_id\":\"00065a1d-7f9d-c388-0003-000100000020\",\"pre_event_id\":\"00065a1d-7f9d-c388-0002-000103000020\",\"order_source\":\"orderbook\"}","recorded_unix_us":1787932601907485}
{"message":"{\"data\":{\"id\":2044303881027606,\"id_str\":\"2044303881027606\",\"order_type\":1,\"order_subtype\":5,\"datetime\":\"1787932602\",\"microtimestamp\":\"1787932601862000\",\"amount\":2.01528391,\"amount_str\":\"2.01528391\",\"amount_traded\":\"0\",\"amount_at_create\":\"2.01528391\",\"price\":0.03160299,\"price_str\":\"0.03160299\",\"is_liquidation\":false},\"channel\":\"live_orders_ethbtc\",\"event\":\"order_created\",\"event_id\":\"00065a1d-7f9d-c770-0000-001103000020\",\"pre_event_id\":\"00065a1d-7f9c-15d8-0000-001102000020\",\"order_source\":\"orderbook\"}","recorded_unix_us":1787932601907569}
{"message":"{\"data\":{\"id\":2044303881031692,\"id_str\":\"2044303881031692\",\"order_type\":1,\"order_subtype\":5,\"datetime\":\"1787932602\",\"microtimestamp\":\"1787932601862000\",\"amount\":2.015283,\"amount_str\":\"2.015283\",\"amount_traded\":\"0\",\"amount_at_create\":\"2.015283\",\"price\":2481.36,\"price_str\":\"2481.36\",\"is_liquidation\":false},\"channel\":\"live_orders_ethusd\",\"event\":\"order_created\",\"event_id\":\"00065a1d-7f9d-c770-0000-001200000020\",\"pre_event_id\":\"00065a1d-7f9d-bfa0-0000-001203000020\",\"order_source\":\"orderbook\"}","recorded_unix_us":1787932601907647}
{"message":"{\"data\":{\"id\":2044303881039873,\"id_str\":\"2044303881039873\",\"order_type\":0,\"order_subtype\":5,\"datetime\":\"1787932602\",\"microtimestamp\":\"1787932601864000\",\"amount\":0.336955,\"amount_str\":\"0.336955\",\"amount_traded\":\"0\",\"amount_at_create\":\"0.336955\",\"price\":2480.15,\"price_str\":\"2480.15\",\"is_liquidation\":false},\"channel\":\"live_orders_ethusd\",\"event\":\"order_created\",\"event_id\":\"00065a1d-7f9d-cf40-0000-001201000020\",\"pre_event_id\":\"00065a1d-7f9d-c770-0000-001200000020\",\"order_source\":\"orderbook\"}","recorded_unix_us":1787932601912176}
{"message":"{\"data\":{\"id\":2044303881039878,\"id_str\":\"2044303881039878\",\"order_type\":0,\"order_subtype\":5,\"datetime\":\"1787932602\",\"microtimestamp\":\"1787932601864000\",\"amount\":0.527206,\"amount_str\":\"0.527206\",\"amount_traded\":\"0\",\"amount_at_create\":\"0.527206\",\"price\":2480.02,\"price_str\":\"2480.02\",\"is_liquidation\":false},\"channel\":\"live_orders_ethusd\",\"event\":\"order_created\",\"event_id\":\"00065a1d-7f9d-cf40-0001-001202000020\",\"pre_event_id\":\"00065a1d-7f9d-cf40-0000-001201000020\",\"order_source\":\"orderbook\"}","recorded_unix_us":1787932601920100}
{"message":"{\"data\":{\"id\":2044303879614464,\"id_str\":\"2044303879614464\",\"order_type\":0,\"order_subtype\":5,\"datetime\":\"1787932602\",\"microtimestamp\":\"1787932601867000\",\"amount\":0.06368105,\"amount_str\":\"0.06368105\",\"amount_traded\":\"0\",\"amount_at_create\":\"0.06368105\",\"price\":78516.28,\"price_str\":\"78516.28\",\"is_liquidation\":false},\"channel\":\"live_orders_btcusd\",\"event\":\"order_deleted\",\"event_id\":\"00065a1d-7f9d-daf8-0000-000101000020\",\"pre_event_id\":\"00065a1d-7f9d-c388-0003-000100000020\",\"order_source\":\"orderbook\"}","recorded_unix_us":1787932601920127}
{"message":"{\"data\":{\"id\":2044303878021120,\"id_str\":\"2044303878021120\",\"order_type\":1,\"order_subtype\":5,\"datetime\":\"1787932602\",\"microtimestamp\":\"1787932601869000\",\"amount\":1.27113313,\"amount_str\":\"1.27113313\",\"amount_traded\":\"0\",\"amount_at_create\":\"1.27113313\",\"price\":78669.97,\"price_str\":\"78669.97\",\"is_liquidation\":false},\"channel\":\"live_orders_btcusd\",\"event\":\"order_deleted\",\"event_id\":\"00065a1d-7f9d-e2c8-0000-000102000020\",\"pre_event_id\":\"00065a1d-7f9d-daf8-0000-000101000020\",\"order_source\":\"orderbook\"}","recorded_unix_us":1787932601920209}
{"message":"{\"data\":{\"id\":2044303880945679,\"id_str\":\"2044303880945679\",\"order_type\":1,\"order_subtype\":5,\"datetime\":\"1787932602\",\"microtimestamp\":\"1787932601870000\",\"amount\":5,\"amount_str\":\"5.000000\",\"amount_traded\":\"0\",\"amount_at_create\":\"5.000000\",\"price\":2481.76,\"price_str\":\"2481.76\",\"is_liquidation\":false},\"channel\":\"live_orders_ethusd\",\"event\":\"order_deleted\",\"event_id\":\"00065a1d-7f9d-e6b0-0000-001203000020\",\"pre_event_id\":\"00065a1d-7f9d-cf40-0001-001202000020\",\"order_source\":\"orderbook\"}","recorded_unix_us":1787932601920336}
{"message":"{\"data\":{\"id\":2044303879241730,\"id_str\":\"2044303879241730\",\"order_type\":1,\"order_subtype\":5,\"datetime\":\"1787932602\",\"microtimestamp\":\"1787932601870000\",\"amount\":0.06367563,\"amount_str\":\"0.06367563\",\"amount_traded\":\"0\",\"amount_at_create\":\"0.06367563\",\"price\":78522.98,\"price_str\":\"78522.98\",\"is_liquidation\":false},\"channel\":\"live_orders_btcusd\",\"event\":\"order_deleted\",\"event_id\":\"00065a1d-7f9d-e6b0-0000-000103000020\",\"pre_event_id\":\"00065a1d-7f9d-e2c8-0000-000102000020\",\"order_source\":\"orderbook\"}","recorded_unix_us":1787932601920402}
{"message":"{\"data\":{\"id\":2044303880937472,\"id_str\":\"2044303880937472\",\"order_type\":1,\"order_subtype\":5,\"datetime\":\"1787932602\",\"microtimestamp\":\"1787932601870000\",\"amount\":6,\"amount_str\":\"6.000000\",\"amount_traded\":\"0\",\"amount_at_create\":\"6.000000\",\"price\":2482.5,\"price_str\":\"2482.50\",\"is_liquidation\":false},\"channel\":\"live_orders_ethusd\",\"event\":\"order_deleted\",\"event_id\":\"00065a1d-7f9d-e6b0-0001-001200000020\",\"pre_event_id\":\"00065a1d-7f9d-e6b0-0000-001203000020\",\"order_source\":\"orderbook\"}","recorded_unix_us":1787932601920427}
{"message":"{\"data\":{\"id\":2044303879331844,\"id_str\":\"2044303879331844\",\"order_type\":1,\"order_subtype\":5,\"datetime\":\"1787932602\",\"microtimestamp\":\"1787932601870000\",\"amount\":0.06367384,\"amount_str\":\"0.06367384\",\"amount_traded\":\"0\",\"amount_at_create\":\"0.06367384\",\"price\":78525.19,\"price_str\":\"78525.19\",\"is_liquidation\":false},\"channel\":\"live_orders_btcusd\",\"event\":\"order_deleted\",\"event_id\":\"00065a1d-7f9d-e6b0-0001-000100000020\",\"pre_event_id\":\"00065a1d-7f9d-e6b0-0000-000103000020\",\"order_source\":\"orderbook\"}","recorded_unix_us":1787932601920543}
{"message":"{\"data\":{\"id\":2044303879331849,\"id_str\":\"2044303879331849\",\"order_type\":1,\"order_subtype\":5,\"datetime\":\"1787932602\",\"microtimestamp\":\"1787932601871000\",\"amount\":0.25467128,\"amount_str\":\"0.25467128\",\"amount_traded\":\"0\",\"amount_at_create\":\"0.25467128\",\"price\":78532.61,\"price_str\":\"78532.61\",\"is_liquidation\":false},\"channel\":\"live_orders_btcusd\",\"event\":\"order_deleted\",\"event_id\":\"00065a1d-7f9d-ea98-0000-000101000020\",\"pre_event_id\":\"00065a1d-7f9d-e6b0-0001-000100000020\",\"order_source\":\"orderbook\"}","recorded_unix_us":1787932601920605}
{"message":"{\"data\":{\"id\":2044303880933376,\"id_str\":\"2044303880933376\",\"order_type\":1,\"order_subtype\":5,\"datetime\":\"1787932602\",\"microtimestamp\":\"1787932601871000\",\"amount\":5,\"amount_str\":\"5.000000\",\"amount_traded\":\"0\",\"amount_at_create\":\"5.000000\",\"price\":2481.51,\"price_str\":\"2481.51\",\"is_liquidation\":false},\"channel\":\"live_orders_ethusd\",\"event\":\"order_deleted\",\"event_id\":\"00065a1d-7f9d-ea98-0000-001201000020\",\"pre_event_id\":\"00065a1d-7f9d-e6b0-0001-001200000020\",\"order_source\":\"orderbook\"}","recorded_unix_us":1787932601920630}
{"message":"{\"data\":{\"id\":2044303879335936,\"id_str\":\"2044303879335936\",\"order_type\":1,\"order_subtype\":5,\"datetime\":\"1787932602\",\"microtimestamp\":\"1787932601871000\",\"amount\":0.25466146,\"amount_str\":\"0.25466146\",\"amount_traded\":\"0\",\"amount_at_create\":\"0.25466146\",\"price\":78535.64,\"price_str\":\"78535.64\",\"is_liquidation\":false},\"channel\":\"live_orders_btcusd\",\"event\":\"order_deleted\",\"event_id\":\"00065a1d-7f9d-ea98-0001-000102000020\",\"pre_event_id\":\"00065a1d-7f9d-ea98-0000-000101000020\",\"order_source\":\"orderbook\"}","recorded_unix_us":1787932601920749}
{"message":"{\"data\":{\"id\":2044303879340045,\"id_str\":\"2044303879340045\",\"order_type\":1,\"order_subtype\":5,\"datetime\":\"1787932602\",\"microtimestamp\":\"1787932601871000\",\"amount\":1.27209222,\"amount_str\":\"1.27209222\",\"amount_traded\":\"0\",\"amount_at_create\":\"1.27209222\",\"price\":78610.66,\"price_str\":\"78610.66\",\"is_liquidation\":false},\"channel\":\"live_orders_btcusd\",\"event\":\"order_deleted\",\"event_id\":\"00065a1d-7f9d-ea98-0002-000103000020\",\"pre_event_id\":\"00065a1d-7f9d-ea98-0001-000102000020\",\"order_source\":\"orderbook\"}","recorded_unix_us":1787932601920773}
{"message":"{\"data\":{\"id\":2044303879340046,\"id_str\":\"2044303879340046\",\"order_type\":1,\"order_subtype\":5,\"datetime\":\"1787932602\",\"microtimestamp\":\"1787932601872000\",\"amount\":12.70451953,\"amount_str\":\"12.70451953\",\"amount_traded\":\"0\",\"amount_at_create\":\"12.70451953\",\"price\":78712.15,\"price_str\":\"78712.15\",\"is_liquidation\":false},\"channel\":\"live_orders_btcusd\",\"event\":\"order_deleted\",\"event_id\":\"00065a1d-7f9d-ee80-0000-000100000020\",\"pre_event_id\":\"00065a1d-7f9d-ea98-0002-000103000020\",\"order_source\":\"orderbook\"}","recorded_unix_us":1787932601920792}
{"message":"{\"data\":{\"id\":2044303879352320,\"id_str\":\"2044303879352320\",\"order_type\":1,\"order_subtype\":5,\"datetime\":\"1787932602\",\"microtimestamp\":\"1787932601872000\",\"amount\":1.26970017,\"amount_str\":\"1.26970017\",\"amount_traded\":\"0\",\"amount_at_create\":\"1.26970017\",\"price\":78758.76,\"price_str\":\"78758.76\",\"is_liquidation\":false},\"channel\":\"live_orders_btcusd\",\"event\":\"order_deleted\",\"event_id\":\"00065a1d-7f9d-ee80-0001-000101000020\",\"pre_event_id\":\"00065a1d-7f9d-ee80-0000-000100000020\",\"order_source\":\"orderbook\"}","recorded_unix_us":1787932601921026}
{"message":"{\"data\":{\"id\":2044303879356416,\"id_str\":\"2044303879356416\",\"order_type\":1,\"order_subtype\":5,\"datetime\":\"1787932602\",\"microtimestamp\":\"1787932601872000\",\"amount\":1.2684012,\"amount_str\":\"1.26840120\",\"amount_traded\":\"0\",\"amount_at_create\":\"1.26840120\",\"price\":78839.41,\"price_str\":\"78839.41\",\"is_liquidation\":false},\"channel\":\"live_orders_btcusd\",\"event\":\"order_deleted\",\"event_id\":\"00065a1d-7f9d-ee80-0002-000102000020\",\"pre_event_id\":\"00065a1d-7f9d-ee80-0001-000101000020\",\"order_source\":\"orderbook\"}","recorded_unix_us":1787932601921047}
{"message":"{\"data\":{\"id\":2044303879360522,\"id_str\":\"2044303879360522\",\"order_type\":0,\"order_subtype\":5,\"datetime\":\"1787932602\",\"microtimestamp\":\"1787932601873000\",\"amount\":0.25476924,\"amount_str\":\"0.25476924\",\"amount_traded\":\"0\",\"amount_at_create\":\"0.25476924\",\"price\":78502.41,\"price_str\":\"78502.41\",\"is_liquidation\":false},\"channel\":\"live_orders_btcusd\",\"event\":\"order_deleted\",\"event_id\":\"00065a1d-7f9d-f268-0000-000103000020\",\"pre_event_id\":\"00065a1d-7f9d-ee80-0002-000102000020\",\"order_source\":\"orderbook\"}","recorded_unix_us":1787932601921066}
{"message":"{\"data\":{\"id\":2044303879364609,\"id_str\":\"2044303879364609\",\"order_type\":0,\"order_subtype\":5,\"datetime\":\"1787932602\",\"microtimestamp\":\"1787932601873000\",\"amount\":0.25478772,\"amount_str\":\"0.25478772\",\"amount_traded\":\"0\",\"amount_at_create\":\"0.25478772\",\"price\":78496.71,\"price_str\":\"78496.71\",\"is_liquidation\":false},\"channel\":\"live_orders_btcusd\",\"event\":\"order_deleted\",\"event_id\":\"00065a1d-7f9d-f268-0001-000100000020\",\"pre_event_id\":\"00065a1d-7f9d-f268-0000-000103000020\",\"order_source\":\"orderbook\"}","recorded_unix_us":1787932601921086}
{"message":"{\"data\":{\"id\":2044303879368706,\"id_str\":\"2044303879368706\",\"order_type\":0,\"order_subtype\":5,\"datetime\":\"1787932602\",\"microtimestamp\":\"1787932601873000\",\"amount\":1.27507828,\"amount_str\":\"1.27507828\",\"amount_traded\":\"0\",\"amount_at_create\":\"1.27507828\",\"price\":78426.55,\"price_str\":\"78426.55\",\"is_liquidation\":false},\"channel\":\"live_orders_btcusd\",\"event\":\"order_deleted\",\"event_id\":\"00065a1d-7f9d-f268-0002-000101000020\",\"pre_event_id\":\"00065a1d-7f9d-f268-0001-000100000020\",\"order_source\":\"orderbook\"}","recorded_unix_us":1787932601921106}
{"message":"{\"data\":{\"id\":2044303879372801,\"id_str\":\"2044303879372801\",\"order_type\":0,\"order_subtype\":5,\"datetime\":\"1787932602\",\"microtimestamp\":\"1787932601874000\",\"amount\":1.27541152,\"amount_str\":\"1.27541152\",\"amount_traded\":\"0\",\"amount_at_create\":\"1.27541152\",\"price\":78406.06,\"price_str\":\"78406.06\",\"is_liquidation\":false},\"channel\":\"live_orders_btcusd\",\"event\":\"order_deleted\",\"event_id\":\"00065a1d-7f9d-f650-0000-000102000020\",\"pre_event_id\":\"00065a1d-7f9d-f268-0002-000101000020\",\"order_source\":\"orderbook\"}","recorded_unix_us":1787932601921128}
{"message":"{\"data\":{\"id\":2044303879376897,\"id_str\":\"2044303879376897\",\"order_type\":0,\"order_subtype\":5,\"datetime\":\"1787932602\",\"microtimestamp\":\"1787932601874000\",\"amount\":12.76418733,\"amount_str\":\"12.76418733\",\"amount_traded\":\"0\",\"amount_at_create\":\"12.76418733\",\"price\":78344.19,\"price_str\":\"78344.19\",\"is_liquidation\":false},\"channel\":\"live_orders_btcusd\",\"event\":\"order_deleted\",\"event_id\":\"00065a1d-7f9d-f650-0001-000103000020\",\"pre_event_id\":\"00065a1d-7f9d-f650-0000-000102000020\",\"order_source\":\"orderbook\"}","recorded_unix_us":1787932601921148}
{"message":"{\"data\":{\"id\":2044303879376898,\"id_str\":\"2044303879376898\",\"order_type\":0,\"order_subtype\":5,\"datetime\":\"1787932602\",\"microtimestamp\":\"1787932601874000\",\"amount\":1.27567513,\"amount_str\":\"1.27567513\",\"amount_traded\":\"0\",\"amount_at_create\":\"1.27567513\",\"price\":78389.86,\"price_str\":\"78389.86\",\"is_liquidation\":false},\"channel\":\"live_orders_btcusd\",\"event\":\"order_deleted\",\"event_id\":\"00065a1d-7f9d-f650-0002-000100000020\",\"pre_event_id\":\"00065a1d-7f9d-f650-0001-000103000020\",\"order_source\":\"orderbook\"}","recorded_unix_us":1787932601921251}
{"message":"{\"data\":{\"id\":2044303879380996,\"id_str\":\"2044303879380996\",\"order_type\":0,\"order_subtype\":5,\"datetime\":\"1787932602\",\"microtimestamp\":\"1787932601875000\",\"amount\":1.27757154,\"amount_str\":\"1.27757154\",\"amount_traded\":\"0\",\"amount_at_create\":\"1.27757154\",\"price\":78273.5,\"price_str\":\"78273.50\",\"is_liquidation\":false},\"channel\":\"live_orders_btcusd\",\"event\":\"order_deleted\",\"event_id\":\"00065a1d-7f9d-fa38-0000-000101000020\",\"pre_event_id\":\"00065a1d-7f9d-f650-0002-000100000020\",\"order_source\":\"orderbook\"}","recorded_unix_us":1787932601921274}
{"message":"{\"data\":{\"id\":2044303881084928,\"id_str\":\"2044303881084928\",\"order_type\":1,\"order_subtype\":5,\"datetime\":\"1787932602\",\"microtimestamp\":\"1787932601875000\",\"amount\":0.06310787,\"amount_str\":\"0.06310787\",\"amount_traded\":\"0\",\"amount_at_create\":\"0.06310787\",\"price\":78522.24,\"price_str\":\"78522.24\",\"is_liquidation\":false},\"channel\":\"live_orders_btcusd\",\"event\":\"order_created\",\"event_id\":\"00065a1d-7f9d-fa38-0001-000102000020\",\"pre_event_id\":\"00065a1d-7f9d-fa38-0000-000101000020\",\"order_source\":\"orderbook\"}","recorded_unix_us":1787932601921348}
{"message":"{\"data\":{\"id\":2044303881084928,\"id_str\":\"2044303881084928\",\"order_type\":1,\"order_subtype\":5,\"datetime\":\"1787932602\",\"microtimestamp\":\"1787932601875000\",\"amount\":0.06310787,\"amount_str\":\"0.06310787\",\"amount_traded\":\"0\",\"amount_at_create\":\"0.06310787\",\"price\":78522.24,\"price_str\":\"78522.24\",\"is_liquidation\":false},\"channel\":\"live_orders_btcusd\",\"event\":\"order_deleted\",\"event_id\":\"00065a1d-7f9d-fa38-0002-000103000020\",\"pre_event_id\":\"00065a1d-7f9d-fa38-0001-000102000020\",\"order_source\":\"orderbook\"}","recorded_unix_us":1787932601921548}
{"message":"{\"data\":{\"id\":2044303879450628,\"id_str\":\"2044303879450628\",\"order_type\":1,\"order_subtype\":5,\"datetime\":\"1787932602\",\"microtimestamp\":\"1787932601875000\",\"amount\":1.26842789,\"amount_str\":\"1.26842789\",\"amount_traded\":\"0\",\"amount_at_create\":\"1.26842789\",\"price\":78837.75,\"price_str\":\"78837.75\",\"is_liquidation\":false},\"channel\":\"live_orders_btcusd\",\"event\":\"order_deleted\",\"event_id\":\"00065a1d-7f9d-fa38-0003-000100000020\",\"pre_event_id\":\"00065a1d-7f9d-fa38-0002-000103000020\",\"order_source\":\"orderbook\"}","recorded_unix_us":1787932601921569}
{"message":"{\"data\":{\"id\":2044303881084943,\"id_str\":\"2044303881084943\",\"order_type\":1,\"order_subtype\":5,\"datetime\":\"1787932602\",\"microtimestamp\":\"1787932601876000\",\"amount\":4.028412,\"amount_str\":\"4.028412\",\"amount_traded\":\"0\",\"amount_at_create\":\"4.028412\",\"price\":2482.37,\"price_str\":\"2482.37\",\"is_liquidation\":false},\"channel\":\"live_orders_ethusd\",\"event\":\"order_created\",\"event_id\":\"00065a1d-7f9d-fe20-0000-001202000020\",\"pre_event_id\":\"00065a1d-7f9d-ea98-0000-001201000020\",\"order_source\":\"orderbook\"}","recorded_unix_us":1787932601921588}
{"message":"{\"data\":{\"id\":2044303879450629,\"id_str\":\"2044303879450629\",\"order_type\":1,\"order_subtype\":5,\"datetime\":\"1787932602\",\"microtimestamp\":\"1787932601876000\",\"amount\":1.271772,\"amount_str\":\"1.27177200\",\"amount_traded\":\"0\",\"amount_at_create\":\"1.27177200\",\"price\":78630.45,\"price_str\":\"78630.45\",\"is_liquidation\":false},\"channel\":\"live_orders_btcusd\",\"event\":\"order_deleted\",\"event_id\":\"00065a1d-7f9d-fe20-0000-000101000020\",\"pre_event_id\":\"00065a1d-7f9d-fa38-0003-000100000020\",\"order_source\":\"orderbook\"}","recorded_unix_us":1787932601921608}
{"message":"{\"data\":{\"id\":2044303879458820,\"id_str\":\"2044303879458820\",\"order_type\":0,\"order_subtype\":5,\"datetime\":\"1787932602\",\"microtimestamp\":\"1787932601876000\",\"amount\":0.06368334,\"amount_str\":\"0.06368334\",\"amount_traded\":\"0\",\"amount_at_create\":\"0.06368334\",\"price\":78513.46,\"price_str\":\"78513.46\",\"is_liquidation\":false},\"channel\":\"live_orders_btcusd\",\"event\":\"order_deleted\",\"event_id\":\"00065a1d-7f9d-fe20-0001-000102000020\",\"pre_event_id\":\"00065a1d-7f9d-fe20-0000-000101000020\",\"order_source\":\"orderbook\"}","recorded_unix_us":1787932601921629}
{"message":"{\"data\":{\"id\":2044303881089031,\"id_str\":\"2044303881089031\",\"order_type\":1,\"order_subtype\":5,\"datetime\":\"1787932602\",\"microtimestamp\":\"1787932601876000\",\"amount\":4.027018,\"amount_str\":\"4.027018\",\"amount_traded\":\"0\",\"amount_at_create\":\"4.027018\",\"price\":2483.23,\"price_str\":\"2483.23\",\"is_liquidation\":false},\"channel\":\"live_orders_ethusd\",\"event\":\"order_created\",\"event_id\":\"00065a1d-7f9d-fe20-0001-001203000020\",\"pre_event_id\":\"00065a1d-7f9d-fe20-0000-001202000020\",\"order_source\":\"orderbook\"}","recorded_unix_us":1787932601921649}
{"message":"{\"data\":{\"id\":2044303879467021,\"id_str\":\"2044303879467021\",\"order_type\":0,\"order_subtype\":5,\"datetime\":\"1787932602\",\"microtimestamp\":\"1787932601876000\",\"amount\":1.27604867,\"amount_str\":\"1.27604867\",\"amount_traded\":\"0\",\"amount_at_create\":\"1.27604867\",\"price\":78366.91,\"price_str\":\"78366.91\",\"is_liquidation\":false},\"channel\":\"live_orders_btcusd\",\"event\":\"order_deleted\",\"event_id\":\"00065a1d-7f9d-fe20-0002-000103000020\",\"pre_event_id\":\"00065a1d-7f9d-fe20-0001-000102000020\",\"order_source\":\"orderbook\"}","recorded_unix_us":1787932601921795}
{"message":"{\"data\":{\"id\":2044303879475200,\"id_str\":\"2044303879475200\",\"order_type\":0,\"order_subtype\":5,\"datetime\":\"1787932602\",\"microtimestamp\":\"1787932601877000\",\"amount\":1.27817952,\"amount_str\":\"1.27817952\",\"amount_traded\":\"0\",\"amount_at_create\":\"1.27817952\",\"price\":78236.27,\"price_str\":\"78236.27\",\"is_liquidation\":false},\"channel\":\"live_orders_btcusd\",\"event\":\"order_deleted\",\"event_id\":\"00065a1d-7f9e-0208-0000-000100000020\",\"pre_event_id\":\"00065a1d-7f9d-fe20-0002-000103000020\",\"order_source\":\"orderbook\"}","recorded_unix_us":1787932601921818}
{"message":"{\"data\":{\"id\":2044303879536647,\"id_str\":\"2044303879536647\",\"order_type\":1,\"order_subtype\":5,\"datetime\":\"1787932602\",\"microtimestamp\":\"1787932601877000\",\"amount\":1.27145262,\"amount_str\":\"1.27145262\",\"amount_traded\":\"0\",\"amount_at_create\":\"1.27145262\",\"price\":78650.2,\"price_str\":\"78650.20\",\"is_liquidation\":false},\"channel\":\"live_orders_btcusd\",\"event\":\"order_deleted\",\"event_id\":\"00065a1d-7f9e-0208-0001-000101000020\",\"pre_event_id\":\"00065a1d-7f9e-0208-0000-000100000020\",\"order_source\":\"orderbook\"}","recorded_unix_us":1787932601927078}
{"message":"{\"data\":{\"id\":2044303879540737,\"id_str\":\"2044303879540737\",\"order_type\":0,\"order_subtype\":5,\"datetime\":\"1787932602\",\"microtimestamp\":\"1787932601878000\",\"amount\":1.27888333,\"amount_str\":\"1.27888333\",\"amount_traded\":\"0\",\"amount_at_create\":\"1.27888333\",\"price\":78193.21,\"price_str\":\"78193.21\",\"is_liquidation\":false},\"channel\":\"live_orders_btcusd\",\"event\":\"order_deleted\",\"event_id\":\"00065a1d-7f9e-05f0-0000-000102000020\",\"pre_event_id\":\"00065a1d-7f9e-0208-0001-000101000020\",\"order_source\":\"orderbook\"}","recorded_unix_us":1787932601944375}
{"message":"{\"data\":{\"id\":2044303881031692,\"id_str\":\"2044303881031692\",\"order_type\":1,\"order_subtype\":5,\"datetime\":\"1787932602\",\"microtimestamp\":\"1787932601879000\",\"amount\":2.015283,\"amount_str\":\"2.015283\",\"amount_traded\":\"0\",\"amount_at_create\":\"2.015283\",\"price\":2481.36,\"price_str\":\"2481.36\",\"is_liquidation\":false},\"channel\":\"live_orders_ethusd\",\"event\":\"order_deleted\",\"event_id\":\"00065a1d-7f9e-09d8-0000-001200000020\",\"pre_event_id\":\"00065a1d-7f9d-fe20-0001-001203000020\",\"order_source\":\"orderbook\"}","recorded_unix_us":1787932601944554}
{"message":"{\"data\":{\"id\":2044303881105408,\"id_str\":\"2044303881105408\",\"order_type\":0,\"order_subtype\":5,\"datetime\":\"1787932602\",\"microtimestamp\":\"1787932601880000\",\"amount\":0.043541,\"amount_str\":\"0.043541\",\"amount_traded\":\"0\",\"amount_at_create\":\"0.043541\",\"price\":2480.62,\"price_str\":\"2480.62\",\"is_liquidation\":false},\"channel\":\"live_orders_ethusd\",\"event\":\"order_created\",\"event_id\":\"00065a1d-7f9e-0dc0-0000-001201000020\",\"pre_event_id\":\"00065a1d-7f9e-09d8-0000-001200000020\",\"order_source\":\"orderbook\"}","recorded_unix_us":1787932601944664}
{"message":"{\"data\":{\"id\":2044303881105415,\"id_str\":\"2044303881105415\",\"order_type\":1,\"order_subtype\":5,\"datetime\":\"1787932602\",\"microtimestamp\":\"1787932601881000\",\"amount\":20.077182,\"amount_str\":\"20.077182\",\"amount_traded\":\"0\",\"amount_at_create\":\"20.077182\",\"price\":2490.39,\"price_str\":\"2490.39\",\"is_liquidation\":false},\"channel\":\"live_orders_ethusd\",\"event\":\"order_created\",\"event_id\":\"00065a1d-7f9e-11a8-0000-001202000020\",\"pre_event_id\":\"00065a1d-7f9e-0dc0-0000-001201000020\",\"order_source\":\"orderbook\"}","recorded_unix_us":1787932601944744}
{"message":"{\"data\":{\"id\":2044303881113600,\"id_str\":\"2044303881113600\",\"order_type\":1,\"order_subtype\":5,\"datetime\":\"1787932602\",\"microtimestamp\":\"1787932601882000\",\"amount\":10.062547,\"amount_str\":\"10.062547\",\"amount_traded\":\"0\",\"amount_at_create\":\"10.062547\",\"price\":2484.47,\"price_str\":\"2484.47\",\"is_liquidation\":false},\"channel\":\"live_orders_ethusd\",\"event\":\"order_created\",\"event_id\":\"00065a1d-7f9e-1590-0000-001203000020\",\"pre_event_id\":\"00065a1d-7f9e-11a8-0000-001202000020\",\"order_source\":\"orderbook\"}","recorded_unix_us":1787932601944842}
{"message":"{\"data\":{\"id\":2044303881027606,\"id_str\":\"2044303881027606\",\"order_type\":1,\"order_subtype\":5,\"datetime\":\"1787932602\",\"microtimestamp\":\"1787932601882000\",\"amount\":2.01528391,\"amount_str\":\"2.01528391\",\"amount_traded\":\"0\",\"amount_at_create\":\"2.01528391\",\"price\":0.03160299,\"price_str\":\"0.03160299\",\"is_liquidation\":false},\"channel\":\"live_orders_ethbtc\",\"event\":\"order_deleted\",\"event_id\":\"00065a1d-7f9e-1590-0000-001100000020\",\"pre_event_id\":\"00065a1d-7f9d-c770-0000-001103000020\",\"order_source\":\"orderbook\"}","recorded_unix_us":1787932601944870}
{"message":"{\"data\":{\"id\":2044303881117697,\"id_str\":\"2044303881117697\",\"order_type\":0,\"order_subtype\":5,\"datetime\":\"1787932602\",\"microtimestamp\":\"1787932601883000\",\"amount\":4.034214,\"amount_str\":\"4.034214\",\"amount_traded\":\"0\",\"amount_at_create\":\"4.034214\",\"price\":2478.79,\"price_str\":\"2478.79\",\"is_liquidation\":false},\"channel\":\"live_orders_ethusd\",\"event\":\"order_created\",\"event_id\":\"00065a1d-7f9e-1978-0000-001200000020\",\"pre_event_id\":\"00065a1d-7f9e-1590-0000-001203000020\",\"order_source\":\"orderbook\"}","recorded_unix_us":1787932601944967}
{"message":"{\"data\":{\"id\":2044303881117701,\"id_str\":\"2044303881117701\",\"order_type\":1,\"order_subtype\":5,\"datetime\":\"1787932602\",\"microtimestamp\":\"1787932601883000\",\"amount\":40.051178,\"amount_str\":\"40.051178\",\"amount_traded\":\"0\",\"amount_at_create\":\"40.051178\",\"price\":2496.81,\"price_str\":\"2496.81\",\"is_liquidation\":false},\"channel\":\"live_orders_ethusd\",\"event\":\"order_created\",\"event_id\":\"00065a1d-7f9e-1978-0001-001201000020\",\"pre_event_id\":\"00065a1d-7f9e-1978-0000-001200000020\",\"order_source\":\"orderbook\"}","recorded_unix_us":1787932601944993}
{"message":"{\"data\":{\"id\":2044303879073795,\"id_str\":\"2044303879073795\",\"order_type\":1,\"order_subtype\":5,\"datetime\":\"1787932602\",\"microtimestamp\":\"1787932601884000\",\"amount\":0.60450317,\"amount_str\":\"0.60450317\",\"amount_traded\":\"0\",\"amount_at_create\":\"0.60450317\",\"price\":0.031603,\"price_str\":\"0.03160300\",\"is_liquidation\":false},\"channel\":\"live_orders_ethbtc\",\"event\":\"order_deleted\",\"event_id\":\"00065a1d-7f9e-1d60-0000-001101000020\",\"pre_event_id\":\"00065a1d-7f9e-1590-0000-001100000020\",\"order_source\":\"orderbook\"}","recorded_unix_us":1787932601945060}
{"message":"{\"data\":{\"id\":2044303879073800,\"id_str\":\"2044303879073800\",\"order_type\":1,\"order_subtype\":5,\"datetime\":\"1787932602\",\"microtimestamp\":\"1787932601885000\",\"amount\":4.02232075,\"amount_str\":\"4.02232075\",\"amount_traded\":\"0\",\"amount_at_create\":\"4.02232075\",\"price\":0.03165997,\"price_str\":\"0.03165997\",\"is_liquidation\":false},\"channel\":\"live_orders_ethbtc\",\"event\":\"order_deleted\",\"event_id\":\"00065a1d-7f9e-2148-0000-001102000020\",\"pre_event_id\":\"00065a1d-7f9e-1d60-0000-001101000020\",\"order_source\":\"orderbook\"}","recorded_unix_us":1787932601945152}
{"message":"{\"data\":{\"id\":2044303879147520,\"id_str\":\"2044303879147520\",\"order_type\":1,\"order_subtype\":5,\"datetime\":\"1787932602\",\"microtimestamp\":\"1787932601885000\",\"amount\":2.01386943,\"amount_str\":\"2.01386943\",\"amount_traded\":\"0\",\"amount_at_create\":\"2.01386943\",\"price\":0.0316184,\"price_str\":\"0.03161840\",\"is_liquidation\":false},\"channel\":\"live_orders_ethbtc\",\"event\":\"order_deleted\",\"event_id\":\"00065a1d-7f9e-2148-0001-001103000020\",\"pre_event_id\":\"00065a1d-7f9e-2148-0000-001102000020\",\"order_source\":\"orderbook\"}","recorded_unix_us":1787932601945176}
{"message":"{\"data\":{\"id\":2044303879155717,\"id_str\":\"2044303879155717\",\"order_type\":1,\"order_subtype\":5,\"datetime\":\"1787932602\",\"microtimestamp\":\"1787932601885000\",\"amount\":1.00740464,\"amount_str\":\"1.00740464\",\"amount_traded\":\"0\",\"amount_at_create\":\"1.00740464\",\"price\":0.03160452,\"price_str\":\"0.03160452\",\"is_liquidation\":false},\"channel\":\"live_orders_ethbtc\",\"event\":\"order_deleted\",\"event_id\":\"00065a1d-7f9e-2148-0002-001100000020\",\"pre_event_id\":\"00065a1d-7f9e-2148-0001-001103000020\",\"order_source\":\"orderbook\"}","recorded_unix_us":1787932601945265}
{"message":"{\"data\":{\"id\":2044303879163906,\"id_str\":\"2044303879163906\",\"order_type\":1,\"order_subtype\":5,\"datetime\":\"1787932602\",\"microtimestamp\":\"1787932601886000\",\"amount\":3.02055629,\"amount_str\":\"3.02055629\",\"amount_traded\":\"0\",\"amount_at_create\":\"3.02055629\",\"price\":0.03162186,\"price_str\":\"0.03162186\",\"is_liquidation\":false},\"channel\":\"live_orders_ethbtc\",\"event\":\"order_deleted\",\"event_id\":\"00065a1d-7f9e-2530-0000-001101000020\",\"pre_event_id\":\"00065a1d-7f9e-2148-0002-001100000020\",\"order_source\":\"orderbook\"}","recorded_unix_us":1787932601945522}
{"message":"{\"data\":{\"id\":2044303881129985,\"id_str\":\"2044303881129985\",\"order_type\":0,\"order_subtype\":5,\"datetime\":\"1787932602\",\"microtimestamp\":\"1787932601886000\",\"amount\":20.215084,\"amount_str\":\"20.215084\",\"amount_traded\":\"0\",\"amount_at_create\":\"20.215084\",\"price\":2473.4,\"price_str\":\"2473.40\",\"is_liquidation\":false},\"channel\":\"live_orders_ethusd\",\"event\":\"order_created\",\"event_id\":\"00065a1d-7f9e-2530-0000-001202000020\",\"pre_event_id\":\"00065a1d-7f9e-1978-0001-001201000020\",\"order_source\":\"orderbook\"}","recorded_unix_us":1787932601945560}
{"message":"{\"data\":{\"id\":2044303879176196,\"id_str\":\"2044303879176196\",\"order_type\":0,\"order_subtype\":5,\"datetime\":\"1787932602\",\"microtimestamp\":\"1787932601886000\",\"amount\":1.00801353,\"amount_str\":\"1.00801353\",\"amount_traded\":\"0\",\"amount_at_create\":\"1.00801353\",\"price\":0.03158534,\"price_str\":\"0.03158534\",\"is_liquidation\":false},\"channel\":\"live_orders_ethbtc\",\"event\":\"order_deleted\",\"event_id\":\"00065a1d-7f9e-2530-0001-001102000020\",\"pre_event_id\":\"00065a1d-7f9e-2530-0000-001101000020\",\"order_source\":\"orderbook\"}","recorded_unix_us":1787932601945586}
{"message":"{\"data\":{\"id\":2044303881129986,\"id_str\":\"2044303881129986\",\"order_type\":0,\"order_subtype\":5,\"datetime\":\"1787932602\",\"microtimestamp\":\"1787932601886000\",\"amount\":10.092689,\"amount_str\":\"10.092689\",\"amount_traded\":\"0\",\"amount_at_create\":\"10.092689\",\"price\":2477.04,\"price_str\":\"2477.04\",\"is_liquidation\":false},\"channel\":\"live_orders_ethusd\",\"event\":\"order_created\",\"event_id\":\"00065a1d-7f9e-2530-0001-001203000020\",\"pre_event_id\":\"00065a1d-7f9e-2530-0000-001202000020\",\"order_source\":\"orderbook\"}","recorded_unix_us":1787932601945689}
{"message":"{\"data\":{\"id\":2044303879176203,\"id_str\":\"2044303879176203\",\"order_type\":0,\"order_subtype\":5,\"datetime\":\"1787932602\",\"microtimestamp\":\"1787932601886000\",\"amount\":2.01629689,\"amount_str\":\"2.01629689\",\"amount_traded\":\"0\",\"amount_at_create\":\"2.01629689\",\"price\":0.03157941,\"price_str\":\"0.03157941\",\"is_liquidation\":false},\"channel\":\"live_orders_ethbtc\",\"event\":\"order_deleted\",\"event_id\":\"00065a1d-7f9e-2530-0002-001103000020\",\"pre_event_id\":\"00065a1d-7f9e-2530-0001-001102000020\",\"order_source\":\"orderbook\"}","recorded_unix_us":1787932601945721}
{"message":"{\"data\":{\"id\":2044303879184384,\"id_str\":\"2044303879184384\",\"order_type\":0,\"order_subtype\":5,\"datetime\":\"1787932602\",\"microtimestamp\":\"1787932601887000\",\"amount\":3.02537254,\"amount_str\":\"3.02537254\",\"amount_traded\":\"0\",\"amount_at_create\":\"3.02537254\",\"price\":0.03156999,\"price_str\":\"0.03156999\",\"is_liquidation\":false},\"channel\":\"live_orders_ethbtc\",\"event\":\"order_deleted\",\"event_id\":\"00065a1d-7f9e-2918-0000-001100000020\",\"pre_event_id\":\"00065a1d-7f9e-2530-0002-001103000020\",\"order_source\":\"orderbook\"}","recorded_unix_us":1787932601945880}
{"message":"{\"data\":{\"id\":2044303879233536,\"id_str\":\"2044303879233536\",\"order_type\":0,\"order_subtype\":5,\"datetime\":\"1787932602\",\"microtimestamp\":\"1787932601887000\",\"amount\":4.03662068,\"amount_str\":\"4.03662068\",\"amount_traded\":\"0\",\"amount_at_create\":\"4.03662068\",\"price\":0.03154857,\"price_str\":\"0.03154857\",\"is_liquidation\":false},\"channel\":\"live_orders_ethbtc\",\"event\":\"order_deleted\",\"event_id\":\"00065a1d-7f9e-2918-0001-001101000020\",\"pre_event_id\":\"00065a1d-7f9e-2918-0000-001100000020\",\"order_source\":\"orderbook\"}","recorded_unix_us":1787932601945913}
{"message":"{\"data\":{\"id\":2044303880138752,\"id_str\":\"2044303880138752\",\"order_type\":0,\"order_subtype\":5,\"datetime\":\"1787932602\",\"microtimestamp\":\"1787932601887000\",\"amount\":0.60475617,\"amount_str\":\"0.60475617\",\"amount_traded\":\"0\",\"amount_at_create\":\"0.60475617\",\"price\":0.03158982,\"price_str\":\"0.03158982\",\"is_liquidation\":false},\"channel\":\"live_orders_ethbtc\",\"event\":\"order_deleted\",\"event_id\":\"00065a1d-7f9e-2918-0002-001102000020\",\"pre_event_id\":\"00065a1d-7f9e-2918-0001-001101000020\",\"order_source\":\"orderbook\"}","recorded_unix_us":1787932601946023}
{"message":"{\"data\":{\"id\":2044303881138178,\"id_str\":\"2044303881138178\",\"order_type\":0,\"order_subtype\":5,\"datetime\":\"1787932602\",\"microtimestamp\":\"1787932601888000\",\"amount\":40.568517,\"amount_str\":\"40.568517\",\"amount_traded\":\"0\",\"amount_at_create\":\"40.568517\",\"price\":2464.96,\"price_str\":\"2464.96\",\"is_liquidation\":false},\"channel\":\"live_orders_ethusd\",\"event\":\"order_created\",\"event_id\":\"00065a1d-7f9e-2d00-0000-001200000020\",\"pre_event_id\":\"00065a1d-7f9e-2530-0001-001203000020\",\"order_source\":\"orderbook\"}","recorded_unix_us":1787932601946051}
{"message":"{\"data\":{\"id\":2044303880818695,\"id_str\":\"2044303880818695\",\"order_type\":0,\"order_subtype\":5,\"datetime\":\"1787932602\",\"microtimestamp\":\"1787932601890000\",\"amount\":0.19103785,\"amount_str\":\"0.19103785\",\"amount_traded\":\"0\",\"amount_at_create\":\"0.19103785\",\"price\":78484.09,\"price_str\":\"78484.09\",\"is_liquidation\":false},\"channel\":\"live_orders_btcusd\",\"event\":\"order_deleted\",\"event_id\":\"00065a1d-7f9e-34d0-0000-000103000020\",\"pre_event_id\":\"00065a1d-7f9e-05f0-0000-000102000020\",\"order_source\":\"orderbook\"}","recorded_unix_us":1787932601946153}
{"message":"{\"data\":{\"id\":2044303881142283,\"id_str\":\"2044303881142283\",\"order_type\":0,\"order_subtype\":5,\"datetime\":\"1787932602\",\"microtimestamp\":\"1787932601890000\",\"amount\":10.097738,\"amount_str\":\"10.097738\",\"amount_traded\":\"0\",\"amount_at_create\":\"10.097738\",\"price\":2475.8,\"price_str\":\"2475.80\",\"is_liquidation\":false},\"channel\":\"live_orders_ethusd\",\"event\":\"order_created\",\"event_id\":\"00065a1d-7f9e-34d0-0000-001201000020\",\"pre_event_id\":\"00065a1d-7f9e-2d00-0000-001200000020\",\"order_source\":\"orderbook\"}","recorded_unix_us":1787932601946177}
{"message":"{\"data\":{\"id\":2044303881105408,\"id_str\":\"2044303881105408\",\"order_type\":0,\"order_subtype\":5,\"datetime\":\"1787932602\",\"microtimestamp\":\"1787932601893000\",\"amount\":0.043541,\"amount_str\":\"0.043541\",\"amount_traded\":\"0\",\"amount_at_create\":\"0.043541\",\"price\":2480.62,\"price_str\":\"2480.62\",\"is_liquidation\":false},\"channel\":\"live_orders_ethusd\",\"event\":\"order_deleted\",\"event_id\":\"00065a1d-7f9e-4088-0000-001202000020\",\"pre_event_id\":\"00065a1d-7f9e-34d0-0000-001201000020\",\"order_source\":\"orderbook\"}","recorded_unix_us":1787932601946252}
{"message":"{\"data\":{\"id\":2044303881162753,\"id_str\":\"2044303881162753\",\"order_type\":1,\"order_subtype\":5,\"datetime\":\"1787932602\",\"microtimestamp\":\"1787932601894000\",\"amount\":0.1,\"amount_str\":\"0.10000000\",\"amount_traded\":\"0\",\"amount_at_create\":\"0.10000000\",\"price\":78522.62,\"price_str\":\"78522.62\",\"is_liquidation\":false},\"channel\":\"live_orders_btcusd\",\"event\":\"order_created\",\"event_id\":\"00065a1d-7f9e-4470-0000-000100000020\",\"pre_event_id\":\"00065a1d-7f9e-34d0-0000-000103000020\",\"order_source\":\"orderbook\"}","recorded_unix_us":1787932601946341}
{"message":"{\"data\":{\"id\":2044303881162753,\"id_str\":\"2044303881162753\",\"order_type\":1,\"order_subtype\":5,\"datetime\":\"1787932602\",\"microtimestamp\":\"1787932601894000\",\"amount\":0.1,\"amount_str\":\"0.10000000\",\"amount_traded\":\"0\",\"amount_at_create\":\"0.10000000\",\"price\":78522.62,\"price_str\":\"78522.62\",\"is_liquidation\":false},\"channel\":\"live_orders_btcusd\",\"event\":\"order_deleted\",\"event_id\":\"00065a1d-7f9e-4470-0001-000101000020\",\"pre_event_id\":\"00065a1d-7f9e-4470-0000-000100000020\",\"order_source\":\"orderbook\"}","recorded_unix_us":1787932601946548}
{"message":"{\"data\":{\"id\":2044303881166852,\"id_str\":\"2044303881166852\",\"order_type\":1,\"order_subtype\":5,\"datetime\":\"1787932602\",\"microtimestamp\":\"1787932601895000\",\"amount\":0.1,\"amount_str\":\"0.10000000\",\"amount_traded\":\"0\",\"amount_at_create\":\"0.10000000\",\"price\":78522.63,\"price_str\":\"78522.63\",\"is_liquidation\":false},\"channel\":\"live_orders_btcusd\",\"event\":\"order_created\",\"event_id\":\"00065a1d-7f9e-4858-0000-000102000020\",\"pre_event_id\":\"00065a1d-7f9e-4470-0001-000101000020\",\"order_source\":\"orderbook\"}","recorded_unix_us":1787932601946572}
{"message":"{\"data\":{\"id\":2044303881166852,\"id_str\":\"2044303881166852\",\"order_type\":1,\"order_subtype\":5,\"datetime\":\"1787932602\",\"microtimestamp\":\"1787932601895000\",\"amount\":0.1,\"amount_str\":\"0.10000000\",\"amount_traded\":\"0\",\"amount_at_create\":\"0.10000000\",\"price\":78522.63,\"price_str\":\"78522.63\",\"is_liquidation\":false},\"channel\":\"live_orders_btcusd\",\"event\":\"order_deleted\",\"event_id\":\"00065a1d-7f9e-4858-0001-000103000020\",\"pre_event_id\":\"00065a1d-7f9e-4858-0000-000102000020\",\"order_source\":\"orderbook\"}","recorded_unix_us":1787932601946592}
{"message":"{\"data\":{\"id\":2044303872139264,\"id_str\":\"2044303872139264\",\"order_type\":1,\"order_subtype\":5,\"datetime\":\"1787932602\",\"microtimestamp\":\"1787932601896000\",\"amount\":1.56076612,\"amount_str\":\"1.56076612\",\"amount_traded\":\"0\",\"amount_at_create\":\"1.56076612\",\"price\":0.03317759,\"price_str\":\"0.03317759\",\"is_liquidation\":false},\"channel\":\"live_orders_ethbtc\",\"event\":\"order_deleted\",\"event_id\":\"00065a1d-7f9e-4c40-0000-001103000020\",\"pre_event_id\":\"00065a1d-7f9e-2918-0002-001102000020\",\"order_source\":\"orderbook\"}","recorded_unix_us":1787932601946612}
{"message":"{\"data\":{\"id\":2044303881175053,\"id_str\":\"2044303881175053\",\"order_type\":0,\"order_subtype\":5,\"datetime\":\"1787932602\",\"microtimestamp\":\"1787932601898000\",\"amount\":0.06368031,\"amount_str\":\"0.06368031\",\"amount_traded\":\"0\",\"amount_at_create\":\"0.06368031\",\"price\":78517.2,\"price_str\":\"78517.20\",\"is_liquidation\":false},\"channel\":\"live_orders_btcusd\",\"event\":\"order_created\",\"event_id\":\"00065a1d-7f9e-5410-0000-000100000020\",\"pre_event_id\":\"00065a1d-7f9e-4858-0001-000103000020\",\"order_source\":\"orderbook\"}","recorded_unix_us":1787932601946729}
{"message":"{\"data\":{\"id\":2044303881191426,\"id_str\":\"2044303881191426\",\"order_type\":0,\"order_subtype\":5,\"datetime\":\"1787932602\",\"microtimestamp\":\"1787932601901000\",\"amount\":0.19103753,\"amount_str\":\"0.19103753\",\"amount_traded\":\"0\",\"amount_at_create\":\"0.19103753\",\"price\":78485.11,\"price_str\":\"78485.11\",\"is_liquidation\":false},\"channel\":\"live_orders_btcusd\",\"event\":\"order_created\",\"event_id\":\"00065a1d-7f9e-5fc8-0000-000101000020\",\"pre_event_id\":\"00065a1d-7f9e-5410-0000-000100000020\",\"order_source\":\"orderbook\"}","recorded_unix_us":1787932601946760}
{"message":"{\"data\":{\"id\":2044303880880133,\"id_str\":\"2044303880880133\",\"order_type\":0,\"order_subtype\":5,\"datetime\":\"1787932602\",\"microtimestamp\":\"1787932601904000\",\"amount\":0.00140266,\"amount_str\":\"0.00140266\",\"amount_traded\":\"0\",\"amount_at_create\":\"0.00140266\",\"price\":70667.51,\"price_str\":\"70667.51\",\"is_liquidation\":false},\"channel\":\"live_orders_btcusd\",\"event\":\"order_deleted\",\"event_id\":\"00065a1d-7f9e-6b80-0000-000102000020\",\"pre_event_id\":\"00065a1d-7f9e-5fc8-0000-000101000020\",\"order_source\":\"orderbook\"}","recorded_unix_us":1787932601946888}
{"message":"{\"data\":{\"id\":2044303880556544,\"id_str\":\"2044303880556544\",\"order_type\":0,\"order_subtype\":5,\"datetime\":\"1787932602\",\"microtimestamp\":\"1787932601904000\",\"amount\":0.00140266,\"amount_str\":\"0.00140266\",\"amount_traded\":\"0\",\"amount_at_create\":\"0.00140266\",\"price\":70667.51,\"price_str\":\"70667.51\",\"is_liquidation\":false},\"channel\":\"live_orders_btcusd\",\"event\":\"order_deleted\",\"event_id\":\"00065a1d-7f9e-6b80-0001-000103000020\",\"pre_event_id\":\"00065a1d-7f9e-6b80-0000-000102000020\",\"order_source\":\"orderbook\"}","recorded_unix_us":1787932601946912}
{"message":"{\"data\":{\"id\":2044303881207816,\"id_str\":\"2044303881207816\",\"order_type\":0,\"order_subtype\":5,\"datetime\":\"1787932602\",\"microtimestamp\":\"1787932601906000\",\"amount\":0.00140266,\"amount_str\":\"0.00140266\",\"amount_traded\":\"0\",\"amount_at_create\":\"0.00140266\",\"price\":70667.51,\"price_str\":\"70667.51\",\"is_liquidation\":false},\"channel\":\"live_orders_btcusd\",\"event\":\"order_created\",\"event_id\":\"00065a1d-7f9e-7350-0000-000100000020\",\"pre_event_id\":\"00065a1d-7f9e-6b80-0001-000103000020\",\"order_source\":\"orderbook\"}","recorded_unix_us":1787932601946969}
{"message":"{\"data\":{\"id\":2044303881207816,\"id_str\":\"2044303881207816\",\"order_type\":0,\"order_subtype\":5,\"datetime\":\"1787932602\",\"microtimestamp\":\"1787932601909000\",\"amount\":0.00140266,\"amount_str\":\"0.00140266\",\"amount_traded\":\"0\",\"amount_at_create\":\"0.00140266\",\"price\":70667.51,\"price_str\":\"70667.51\",\"is_liquidation\":false},\"channel\":\"live_orders_btcusd\",\"event\":\"order_deleted\",\"event_id\":\"00065a1d-7f9e-7f08-0000-000101000020\",\"pre_event_id\":\"00065a1d-7f9e-7350-0000-000100000020\",\"order_source\":\"orderbook\"}","recorded_unix_us":1787932601947085}
{"message":"{\"data\":{\"id\":2044303881240580,\"id_str\":\"2044303881240580\",\"order_type\":1,\"order_subtype\":5,\"datetime\":\"1787932602\",\"microtimestamp\":\"1787932601913000\",\"amount\":12.086599,\"amount_str\":\"12.086599\",\"amount_traded\":\"0\",\"amount_at_create\":\"12.086599\",\"price\":2482.09,\"price_str\":\"2482.09\",\"is_liquidation\":false},\"channel\":\"live_orders_ethusd\",\"event\":\"order_created\",\"event_id\":\"00065a1d-7f9e-8ea8-0000-001203000020\",\"pre_event_id\":\"00065a1d-7f9e-4088-0000-001202000020\",\"order_source\":\"orderbook\"}","recorded_unix_us":1787932601960277}
{"message":"{\"data\":{\"id\":2044303881240586,\"id_str\":\"2044303881240586\",\"order_type\":1,\"order_subtype\":5,\"datetime\":\"1787932602\",\"microtimestamp\":\"1787932601914000\",\"amount\":0.06310787,\"amount_str\":\"0.06310787\",\"amount_traded\":\"0\",\"amount_at_create\":\"0.06310787\",\"price\":78521.24,\"price_str\":\"78521.24\",\"is_liquidation\":false},\"channel\":\"live_orders_btcusd\",\"event\":\"order_created\",\"event_id\":\"00065a1d-7f9e-9290-0000-000102000020\",\"pre_event_id\":\"00065a1d-7f9e-7f08-0000-000101000020\",\"order_source\":\"orderbook\"}","recorded_unix_us":1787932601960458}
{"message":"{\"data\":{\"id\":2044303881240586,\"id_str\":\"2044303881240586\",\"order_type\":1,\"order_subtype\":5,\"datetime\":\"1787932602\",\"microtimestamp\":\"1787932601914000\",\"amount\":0.06310787,\"amount_str\":\"0.06310787\",\"amount_traded\":\"0\",\"amount_at_create\":\"0.06310787\",\"price\":78521.24,\"price_str\":\"78521.24\",\"is_liquidation\":false},\"channel\":\"live_orders_btcusd\",\"event\":\"order_deleted\",\"event_id\":\"00065a1d-7f9e-9290-0001-000103000020\",\"pre_event_id\":\"00065a1d-7f9e-9290-0000-000102000020\",\"order_source\":\"orderbook\"}","recorded_unix_us":1787932601960499}
{"message":"{\"data\":{\"id\":2044303881244674,\"id_str\":\"2044303881244674\",\"order_type\":1,\"order_subtype\":5,\"datetime\":\"1787932602\",\"microtimestamp\":\"1787932601914000\",\"amount\":4.028003,\"amount_str\":\"4.028003\",\"amount_traded\":\"0\",\"amount_at_create\":\"4.028003\",\"price\":2482.62,\"price_str\":\"2482.62\",\"is_liquidation\":false},\"channel\":\"live_orders_ethusd\",\"event\":\"order_created\",\"event_id\":\"00065a1d-7f9e-9290-0000-001200000020\",\"pre_event_id\":\"00065a1d-7f9e-8ea8-0000-001203000020\",\"order_source\":\"orderbook\"}","recorded_unix_us":1787932601960584}
{"message":"{\"data\":{\"id\":2044303881244675,\"id_str\":\"2044303881244675\",\"order_type\":0,\"order_subtype\":5,\"datetime\":\"1787932602\",\"microtimestamp\":\"1787932601914000\",\"amount\":0.043457,\"amount_str\":\"0.043457\",\"amount_traded\":\"0\",\"amount_at_create\":\"0.043457\",\"price\":2480.73,\"price_str\":\"2480.73\",\"is_liquidation\":false},\"channel\":\"live_orders_ethusd\",\"event\":\"order_created\",\"event_id\":\"00065a1d-7f9e-9290-0001-001201000020\",\"pre_event_id\":\"00065a1d-7f9e-9290-0000-001200000020\",\"order_source\":\"orderbook\"}","recorded_unix_us":1787932601960660}
{"message":"{\"data\":{\"id\":2044303881244688,\"id_str\":\"2044303881244688\",\"order_type\":1,\"order_subtype\":5,\"datetime\":\"1787932602\",\"microtimestamp\":\"1787932601915000\",\"amount\":10.059779,\"amount_str\":\"10.059779\",\"amount_traded\":\"0\",\"amount_at_create\":\"10.059779\",\"price\":2485.15,\"price_str\":\"2485.15\",\"is_liquidation\":false},\"channel\":\"live_orders_ethusd\",\"event\":\"order_created\",\"event_id\":\"00065a1d-7f9e-9678-0000-001202000020\",\"pre_event_id\":\"00065a1d-7f9e-9290-0001-001201000020\",\"order_source\":\"orderbook\"}","recorded_unix_us":1787932601960734}
{"message":"{\"data\":{\"id\":2044303881252867,\"id_str\":\"2044303881252867\",\"order_type\":1,\"order_subtype\":5,\"datetime\":\"1787932602\",\"microtimestamp\":\"1787932601916000\",\"amount\":12.087961,\"amount_str\":\"12.087961\",\"amount_traded\":\"0\",\"amount_at_create\":\"12.087961\",\"price\":2481.81,\"price_str\":\"2481.81\",\"is_liquidation\":false},\"channel\":\"live_orders_ethusd\",\"event\":\"order_created\",\"event_id\":\"00065a1d-7f9e-9a60-0000-001203000020\",\"pre_event_id\":\"00065a1d-7f9e-9678-0000-001202000020\",\"order_source\":\"orderbook\"}","recorded_unix_us":1787932601960804}
{"message":"{\"data\":{\"id\":2044303881297922,\"id_str\":\"2044303881297922\",\"order_type\":1,\"order_subtype\":5,\"datetime\":\"1787932602\",\"microtimestamp\":\"1787932601927000\",\"amount\":20.063885,\"amount_str\":\"20.063885\",\"amount_traded\":\"0\",\"amount_at_create\":\"20.063885\",\"price\":2492.04,\"price_str\":\"2492.04\",\"is_liquidation\":false},\"channel\":\"live_orders_ethusd\",\"event\":\"order_created\",\"event_id\":\"00065a1d-7f9e-c558-0000-001200000020\",\"pre_event_id\":\"00065a1d-7f9e-9a60-0000-001203000020\",\"order_source\":\"orderbook\"}","recorded_unix_us":1787932601976517}
{"message":"{\"data\":{\"id\":2044303881297923,\"id_str\":\"2044303881297923\",\"order_type\":1,\"order_subtype\":5,\"datetime\":\"1787932602\",\"microtimestamp\":\"1787932601928000\",\"amount\":0.1,\"amount_str\":\"0.10000000\",\"amount_traded\":\"0\",\"amount_at_create\":\"0.10000000\",\"price\":78522.62,\"price_str\":\"78522.62\",\"is_liquidation\":false},\"channel\":\"live_orders_btcusd\",\"event\":\"order_created\",\"event_id\":\"00065a1d-7f9e-c940-0000-000100000020\",\"pre_event_id\":\"00065a1d-7f9e-9290-0001-000103000020\",\"order_source\":\"orderbook\"}","recorded_unix_us":1787932601977017}
{"message":"{\"data\":{\"id\":2044303881297923,\"id_str\":\"2044303881297923\",\"order_type\":1,\"order_subtype\":5,\"datetime\":\"1787932602\",\"microtimestamp\":\"1787932601928000\",\"amount\":0.1,\"amount_str\":\"0.10000000\",\"amount_traded\":\"0\",\"amount_at_create\":\"0.10000000\",\"price\":78522.62,\"price_str\":\"78522.62\",\"is_liquidation\":false},\"channel\":\"live_orders_btcusd\",\"event\":\"order_deleted\",\"event_id\":\"00065a1d-7f9e-c940-0001-000101000020\",\"pre_event_id\":\"00065a1d-7f9e-c940-0000-000100000020\",\"order_source\":\"orderbook\"}","recorded_unix_us":1787932601977073}
{"message":"{\"data\":{\"id\":2044303881302021,\"id_str\":\"2044303881302021\",\"order_type\":0,\"order_subtype\":5,\"datetime\":\"1787932602\",\"microtimestamp\":\"1787932601929000\",\"amount\":12.096046,\"amount_str\":\"12.096046\",\"amount_traded\":\"0\",\"amount_at_create\":\"12.096046\",\"price\":2480.14,\"price_str\":\"2480.14\",\"is_liquidation\":false},\"channel\":\"live_orders_ethusd\",\"event\":\"order_created\",\"event_id\":\"00065a1d-7f9e-cd28-0000-001201000020\",\"pre_event_id\":\"00065a1d-7f9e-c558-0000-001200000020\",\"order_source\":\"orderbook\"}","recorded_unix_us":1787932601977102}
{"message":"{\"data\":{\"id\":2044303881306112,\"id_str\":\"2044303881306112\",\"order_type\":1,\"order_subtype\":5,\"datetime\":\"1787932602\",\"microtimestamp\":\"1787932601929000\",\"amount\":40.010118,\"amount_str\":\"40.010118\",\"amount_traded\":\"0\",\"amount_at_create\":\"40.010118\",\"price\":2499.37,\"price_str\":\"2499.37\",\"is_liquidation\":false},\"channel\":\"live_orders_ethusd\",\"event\":\"order_created\",\"event_id\":\"00065a1d-7f9e-cd28-0001-001202000020\",\"pre_event_id\":\"00065a1d-7f9e-cd28-0000-001201000020\",\"order_source\":\"orderbook\"}","recorded_unix_us":1787932601985556}
{"message":"{\"data\":{\"id\":2044303881306113,\"id_str\":\"2044303881306113\",\"order_type\":1,\"order_subtype\":5,\"datetime\":\"1787932602\",\"microtimestamp\":\"1787932601929000\",\"amount\":0.1,\"amount_str\":\"0.10000000\",\"amount_traded\":\"0\",\"amount_at_create\":\"0.10000000\",\"price\":78522.63,\"price_str\":\"78522.63\",\"is_liquidation\":false},\"channel\":\"live_orders_btcusd\",\"event\":\"order_created\",\"event_id\":\"00065a1d-7f9e-cd28-0000-000102000020\",\"pre_event_id\":\"00065a1d-7f9e-c940-0001-000101000020\",\"order_source\":\"orderbook\"}","recorded_unix_us":1787932601985792}
{"message":"{\"data\":{\"id\":2044303881306113,\"id_str\":\"2044303881306113\",\"order_type\":1,\"order_subtype\":5,\"datetime\":\"1787932602\",\"microtimestamp\":\"1787932601929000\",\"amount\":0.1,\"amount_str\":\"0.10000000\",\"amount_traded\":\"0\",\"amount_at_create\":\"0.10000000\",\"price\":78522.63,\"price_str\":\"78522.63\",\"is_liquidation\":false},\"channel\":\"live_orders_btcusd\",\"event\":\"order_deleted\",\"event_id\":\"00065a1d-7f9e-cd28-0001-000103000020\",\"pre_event_id\":\"00065a1d-7f9e-cd28-0000-000102000020\",\"order_source\":\"orderbook\"}","recorded_unix_us":1787932601985924}
{"message":"{\"data\":{\"id\":2044303881322500,\"id_str\":\"2044303881322500\",\"order_type\":0,\"order_subtype\":5,\"datetime\":\"1787932602\",\"microtimestamp\":\"1787932601933000\",\"amount\":12.09718,\"amount_str\":\"12.097180\",\"amount_traded\":\"0\",\"amount_at_create\":\"12.097180\",\"price\":2479.91,\"price_str\":\"2479.91\",\"is_liquidation\":false},\"channel\":\"live_orders_ethusd\",\"event\":\"order_created\",\"event_id\":\"00065a1d-7f9e-dcc8-0000-001203000020\",\"pre_event_id\":\"00065a1d-7f9e-cd28-0001-001202000020\",\"order_source\":\"orderbook\"}","recorded_unix_us":1787932601986036}
{"message":"{\"data\":{\"id\":2044303881347095,\"id_str\":\"2044303881347095\",\"order_type\":0,\"order_subtype\":5,\"datetime\":\"1787932602\",\"microtimestamp\":\"1787932601940000\",\"amount\":20.225289,\"amount_str\":\"20.225289\",\"amount_traded\":\"0\",\"amount_at_create\":\"20.225289\",\"price\":2472.15,\"price_str\":\"2472.15\",\"is_liquidation\":false},\"channel\":\"live_orders_ethusd\",\"event\":\"order_created\",\"event_id\":\"00065a1d-7f9e-f820-0000-001200000020\",\"pre_event_id\":\"00065a1d-7f9e-dcc8-0000-001203000020\",\"order_source\":\"orderbook\"}","recorded_unix_us":1787932601986152}
{"message":"{\"data\":{\"id\":2044303881355264,\"id_str\":\"2044303881355264\",\"order_type\":0,\"order_subtype\":5,\"datetime\":\"1787932602\",\"microtimestamp\":\"1787932601941000\",\"amount\":40.609081,\"amount_str\":\"40.609081\",\"amount_traded\":\"0\",\"amount_at_create\":\"40.609081\",\"price\":2462.5,\"price_str\":\"2462.50\",\"is_liquidation\":false},\"channel\":\"live_orders_ethusd\",\"event\":\"order_created\",\"event_id\":\"00065a1d-7f9e-fc08-0000-001201000020\",\"pre_event_id\":\"00065a1d-7f9e-f820-0000-001200000020\",\"order_source\":\"orderbook\"}","recorded_unix_us":1787932601986252}
{"message":"{\"data\":{\"id\":2044303881359361,\"id_str\":\"2044303881359361\",\"order_type\":1,\"order_subtype\":5,\"datetime\":\"1787932602\",\"microtimestamp\":\"1787932601942000\",\"amount\":5,\"amount_str\":\"5.000000\",\"amount_traded\":\"0\",\"amount_at_create\":\"5.000000\",\"price\":2481.77,\"price_str\":\"2481.77\",\"is_liquidation\":false},\"channel\":\"live_orders_ethusd\",\"event\":\"order_created\",\"event_id\":\"00065a1d-7f9e-fff0-0000-001202000020\",\"pre_event_id\":\"00065a1d-7f9e-fc08-0000-001201000020\",\"order_source\":\"orderbook\"}","recorded_unix_us":1787932601986364}
{"message":"{\"data\":{\"id\":2044303881359362,\"id_str\":\"2044303881359362\",\"order_type\":1,\"order_subtype\":5,\"datetime\":\"1787932602\",\"microtimestamp\":\"1787932601942000\",\"amount\":5,\"amount_str\":\"5.000000\",\"amount_traded\":\"0\",\"amount_at_create\":\"5.000000\",\"price\":2481.52,\"price_str\":\"2481.52\",\"is_liquidation\":false},\"channel\":\"live_orders_ethusd\",\"event\":\"order_created\",\"event_id\":\"00065a1d-7f9e-fff0-0001-001203000020\",\"pre_event_id\":\"00065a1d-7f9e-fff0-0000-001202000020\",\"order_source\":\"orderbook\"}","recorded_unix_us":1787932601986471}
{"message":"{\"data\":{\"id\":2044303881019403,\"id_str\":\"2044303881019403\",\"order_type\":0,\"order_subtype\":5,\"datetime\":\"1787932602\",\"microtimestamp\":\"1787932601948000\",\"amount\":0.63679333,\"amount_str\":\"0.63679333\",\"amount_traded\":\"0\",\"amount_at_create\":\"0.63679333\",\"price\":78482.58,\"price_str\":\"78482.58\",\"is_liquidation\":false},\"channel\":\"live_orders_btcusd\",\"event\":\"order_deleted\",\"event_id\":\"00065a1d-7f9f-1760-0000-000100000020\",\"pre_event_id\":\"00065a1d-7f9e-cd28-0001-000103000020\",\"order_source\":\"orderbook\"}","recorded_unix_us":1787932601995443}
{"message":"{\"data\":{\"id\":2044303881400320,\"id_str\":\"2044303881400320\",\"order_type\":0,\"order_subtype\":5,\"datetime\":\"1787932602\",\"microtimestamp\":\"1787932601952000\",\"amount\":0.24452731,\"amount_str\":\"0.24452731\",\"amount_traded\":\"0\",\"amount_at_create\":\"0.24452731\",\"price\":0.03020013,\"price_str\":\"0.03020013\",\"is_liquidation\":false},\"channel\":\"live_orders_ethbtc\",\"event\":\"order_created\",\"event_id\":\"00065a1d-7f9f-2700-0000-001100000020\",\"pre_event_id\":\"00065a1d-7f9e-4c40-0000-001103000020\",\"order_source\":\"orderbook\"}","recorded_unix_us":1787932601995636}
{"message":"{\"data\":{\"id\":2044303880122368,\"id_str\":\"2044303880122368\",\"order_type\":0,\"order_subtype\":5,\"datetime\":\"1787932602\",\"microtimestamp\":\"1787932601958000\",\"amount\":0.26750492,\"amount_str\":\"0.26750492\",\"amount_traded\":\"0\",\"amount_at_create\":\"0.26750492\",\"price\":78482.59,\"price_str\":\"78482.59\",\"is_liquidation\":false},\"channel\":\"live_orders_btcusd\",\"event\":\"order_deleted\",\"event_id\":\"00065a1d-7f9f-3e70-0000-000101000020\",\"pre_event_id\":\"00065a1d-7f9f-1760-0000-000100000020\",\"order_source\":\"orderbook\"}","recorded_unix_us":1787932601995802}
{"message":"{\"data\":{\"id\":2044303881424900,\"id_str\":\"2044303881424900\",\"order_type\":0,\"order_subtype\":5,\"datetime\":\"1787932602\",\"microtimestamp\":\"1787932601958000\",\"amount\":0.26750492,\"amount_str\":\"0.26750492\",\"amount_traded\":\"0\",\"amount_at_create\":\"0.26750492\",\"price\":78482.59,\"price_str\":\"78482.59\",\"is_liquidation\":false},\"channel\":\"live_orders_btcusd\",\"event\":\"order_created\",\"event_id\":\"00065a1d-7f9f-3e70-0001-000102000020\",\"pre_event_id\":\"00065a1d-7f9f-3e70-0000-000101000020\",\"order_source\":\"orderbook\"}","recorded_unix_us":1787932601995842}
{"message":"{\"data\":{\"id\":2044303881428997,\"id_str\":\"2044303881428997\",\"order_type\":0,\"order_subtype\":5,\"datetime\":\"1787932602\",\"microtimestamp\":\"1787932601959000\",\"amount\":0.63679897,\"amount_str\":\"0.63679897\",\"amount_traded\":\"0\",\"amount_at_create\":\"0.63679897\",\"price\":78483.23,\"price_str\":\"78483.23\",\"is_liquidation\":false},\"channel\":\"live_orders_btcusd\",\"event\":\"order_created\",\"event_id\":\"00065a1d-7f9f-4258-0000-000103000020\",\"pre_event_id\":\"00065a1d-7f9f-3e70-0001-000102000020\",\"order_source\":\"orderbook\"}","recorded_unix_us":1787932601995939}
{"message":"{\"data\":{\"id\":2044303881441288,\"id_str\":\"2044303881441288\",\"order_type\":1,\"order_subtype\":5,\"datetime\":\"1787932602\",\"microtimestamp\":\"1787932601963000\",\"amount\":4.027586,\"amount_str\":\"4.027586\",\"amount_traded\":\"0\",\"amount_at_create\":\"4.027586\",\"price\":2482.88,\"price_str\":\"2482.88\",\"is_liquidation\":false},\"channel\":\"live_orders_ethusd\",\"event\":\"order_created\",\"event_id\":\"00065a1d-7f9f-51f8-0000-001200000020\",\"pre_event_id\":\"00065a1d-7f9e-fff0-0001-001203000020\",\"order_source\":\"orderbook\"}","recorded_unix_us":1787932602009170}
{"message":"{\"data\":{\"id\":2044303881453575,\"id_str\":\"2044303881453575\",\"order_type\":1,\"order_subtype\":5,\"datetime\":\"1787932602\",\"microtimestamp\":\"1787932601966000\",\"amount\":0.20969786,\"amount_str\":\"0.20969786\",\"amount_traded\":\"0\",\"amount_at_create\":\"0.20969786\",\"price\":0.03348999,\"price_str\":\"0.03348999\",\"is_liquidation\":false},\"channel\":\"live_orders_ethbtc\",\"event\":\"order_created\",\"event_id\":\"00065a1d-7f9f-5db0-0000-001101000020\",\"pre_event_id\":\"00065a1d-7f9f-2700-0000-001100000020\",\"order_source\":\"orderbook\"}","recorded_unix_us":1787932602009390}
{"message":"{\"data\":{\"id\":2044303881457666,\"id_str\":\"2044303881457666\",\"order_type\":0,\"order_subtype\":5,\"datetime\":\"1787932602\",\"microtimestamp\":\"1787932601966000\",\"amount\":20.235437,\"amount_str\":\"20.235437\",\"amount_traded\":\"0\",\"amount_at_create\":\"20.235437\",\"price\":2470.91,\"price_str\":\"2470.91\",\"is_liquidation\":false},\"channel\":\"live_orders_ethusd\",\"event\":\"order_created\",\"event_id\":\"00065a1d-7f9f-5db0-0000-001201000020\",\"pre_event_id\":\"00065a1d-7f9f-51f8-0000-001200000020\",\"order_source\":\"orderbook\"}","recorded_unix_us":1787932602009519}
{"message":"{\"data\":{\"id\":2044303881457676,\"id_str\":\"2044303881457676\",\"order_type\":1,\"order_subtype\":5,\"datetime\":\"1787932602\",\"microtimestamp\":\"1787932601967000\",\"amount\":1.27113313,\"amount_str\":\"1.27113313\",\"amount_traded\":\"0\",\"amount_at_create\":\"1.27113313\",\"price\":78669.97,\"price_str\":\"78669.97\",\"is_liquidation\":false},\"channel\":\"live_orders_btcusd\",\"event\":\"order_created\",\"event_id\":\"00065a1d-7f9f-6198-0000-000100000020\",\"pre_event_id\":\"00065a1d-7f9f-4258-0000-000103000020\",\"order_source\":\"orderbook\"}","recorded_unix_us":1787932602009616}
{"message":"{\"data\":{\"id\":2044303881474048,\"id_str\":\"2044303881474048\",\"order_type\":1,\"order_subtype\":5,\"datetime\":\"1787932602\",\"microtimestamp\":\"1787932601970000\",\"amount\":0.06310787,\"amount_str\":\"0.06310787\",\"amount_traded\":\"0\",\"amount_at_create\":\"0.06310787\",\"price\":78522.55,\"price_str\":\"78522.55\",\"is_liquidation\":false},\"channel\":\"live_orders_btcusd\",\"event\":\"order_created\",\"event_id\":\"00065a1d-7f9f-6d50-0000-000101000020\",\"pre_event_id\":\"00065a1d-7f9f-6198-0000-000100000020\",\"order_source\":\"orderbook\"}","recorded_unix_us":1787932602009709}
{"message":"{\"data\":{\"id\":2044303881474048,\"id_str\":\"2044303881474048\",\"order_type\":1,\"order_subtype\":5,\"datetime\":\"1787932602\",\"microtimestamp\":\"1787932601970000\",\"amount\":0.06310787,\"amount_str\":\"0.06310787\",\"amount_traded\":\"0\",\"amount_at_create\":\"0.06310787\",\"price\":78522.55,\"price_str\":\"78522.55\",\"is_liquidation\":false},\"channel\":\"live_orders_btcusd\",\"event\":\"order_deleted\",\"event_id\":\"00065a1d-7f9f-6d50-0001-000102000020\",\"pre_event_id\":\"00065a1d-7f9f-6d50-0000-000101000020\",\"order_source\":\"orderbook\"}","recorded_unix_us":1787932602009801}
{"message":"{\"data\":{\"id\":2044303881359362,\"id_str\":\"2044303881359362\",\"order_type\":1,\"order_subtype\":5,\"datetime\":\"1787932602\",\"microtimestamp\":\"1787932601970000\",\"amount\":5,\"amount_str\":\"5.000000\",\"amount_traded\":\"0\",\"amount_at_create\":\"5.000000\",\"price\":2481.52,\"price_str\":\"2481.52\",\"is_liquidation\":false},\"channel\":\"live_orders_ethusd\",\"event\":\"order_deleted\",\"event_id\":\"00065a1d-7f9f-6d50-0000-001202000020\",\"pre_event_id\":\"00065a1d-7f9f-5db0-0000-001201000020\",\"order_source\":\"orderbook\"}","recorded_unix_us":1787932602009930}
{"message":"{\"data\":{\"id\":2044303881359361,\"id_str\":\"2044303881359361\",\"order_type\":1,\"order_subtype\":5,\"datetime\":\"1787932602\",\"microtimestamp\":\"1787932601970000\",\"amount\":5,\"amount_str\":\"5.000000\",\"amount_traded\":\"0\",\"amount_at_create\":\"5.000000\",\"price\":2481.77,\"price_str\":\"2481.77\",\"is_liquidation\":false},\"channel\":\"live_orders_ethusd\",\"event\":\"order_deleted\",\"event_id\":\"00065a1d-7f9f-6d50-0001-001203000020\",\"pre_event_id\":\"00065a1d-7f9f-6d50-0000-001202000020\",\"order_source\":\"orderbook\"}","recorded_unix_us":1787932602009958}
{"message":"{\"data\":{\"id\":2044303881490433,\"id_str\":\"2044303881490433\",\"order_type\":1,\"order_subtype\":5,\"datetime\":\"1787932602\",\"microtimestamp\":\"1787932601974000\",\"amount\":0.1,\"amount_str\":\"0.10000000\",\"amount_traded\":\"0\",\"amount_at_create\":\"0.10000000\",\"price\":78522.62,\"price_str\":\"78522.62\",\"is_liquidation\":false},\"channel\":\"live_orders_btcusd\",\"event\":\"order_created\",\"event_id\":\"00065a1d-7f9f-7cf0-0000-000103000020\",\"pre_event_id\":\"00065a1d-7f9f-6d50-0001-000102000020\",\"order_source\":\"orderbook\"}","recorded_unix_us":1787932602010127}
{"message":"{\"data\":{\"id\":2044303881490433,\"id_str\":\"2044303881490433\",\"order_type\":1,\"order_subtype\":5,\"datetime\":\"1787932602\",\"microtimestamp\":\"1787932601974000\",\"amount\":0.1,\"amount_str\":\"0.10000000\",\"amount_traded\":\"0\",\"amount_at_create\":\"0.10000000\",\"price\":78522.62,\"price_str\":\"78522.62\",\"is_liquidation\":false},\"channel\":\"live_orders_btcusd\",\"event\":\"order_deleted\",\"event_id\":\"00065a1d-7f9f-7cf0-0001-000100000020\",\"pre_event_id\":\"00065a1d-7f9f-7cf0-0000-000103000020\",\"order_source\":\"orderbook\"}","recorded_unix_us":1787932602010155}
{"message":"{\"data\":{\"id\":2044303881490434,\"id_str\":\"2044303881490434\",\"order_type\":1,\"order_subtype\":5,\"datetime\":\"1787932602\",\"microtimestamp\":\"1787932601974000\",\"amount\":0.1,\"amount_str\":\"0.10000000\",\"amount_traded\":\"0\",\"amount_at_create\":\"0.10000000\",\"price\":78522.63,\"price_str\":\"78522.63\",\"is_liquidation\":false},\"channel\":\"live_orders_btcusd\",\"event\":\"order_created\",\"event_id\":\"00065a1d-7f9f-7cf0-0002-000101000020\",\"pre_event_id\":\"00065a1d-7f9f-7cf0-0001-000100000020\",\"order_source\":\"orderbook\"}","recorded_unix_us":1787932602010179}
{"message":"{\"data\":{\"id\":2044303881490434,\"id_str\":\"2044303881490434\",\"order_type\":1,\"order_subtype\":5,\"datetime\":\"1787932602\",\"microtimestamp\":\"1787932601974000\",\"amount\":0.1,\"amount_str\":\"0.10000000\",\"amount_traded\":\"0\",\"amount_at_create\":\"0.10000000\",\"price\":78522.63,\"price_str\":\"78522.63\",\"is_liquidation\":false},\"channel\":\"live_orders_btcusd\",\"event\":\"order_deleted\",\"event_id\":\"00065a1d-7f9f-7cf0-0003-000102000020\",\"pre_event_id\":\"00065a1d-7f9f-7cf0-0002-000101000020\",\"order_source\":\"orderbook\"}","recorded_unix_us":1787932602010202}
{"message":"{\"data\":{\"id\":2044303881023494,\"id_str\":\"2044303881023494\",\"order_type\":0,\"order_subtype\":5,\"datetime\":\"1787932602\",\"microtimestamp\":\"1787932601980000\",\"amount\":0.50943466,\"amount_str\":\"0.50943466\",\"amount_traded\":\"0\",\"amount_at_create\":\"0.50943466\",\"price\":78480.62,\"price_str\":\"78480.62\",\"is_liquidation\":false},\"channel\":\"live_orders_btcusd\",\"event\":\"order_deleted\",\"event_id\":\"00065a1d-7f9f-9460-0000-000103000020\",\"pre_event_id\":\"00065a1d-7f9f-7cf0-0003-000102000020\",\"order_source\":\"orderbook\"}","recorded_unix_us":1787932602022224}
{"message":"{\"data\":{\"id\":2044303881531399,\"id_str\":\"2044303881531399\",\"order_type\":1,\"order_subtype\":5,\"datetime\":\"1787932602\",\"microtimestamp\":\"1787932601985000\",\"amount\":0.6044871,\"amount_str\":\"0.60448710\",\"amount_traded\":\"0\",\"amount_at_create\":\"0.60448710\",\"price\":0.03160362,\"price_str\":\"0.03160362\",\"is_liquidation\":false},\"channel\":\"live_orders_ethbtc\",\"event\":\"order_created\",\"event_id\":\"00065a1d-7f9f-a7e8-0000-001102000020\",\"pre_event_id\":\"00065a1d-7f9f-5db0-0000-001101000020\",\"order_source\":\"orderbook\"}","recorded_unix_us":1787932602022538}
{"message":"{\"data\":{\"id\":2044303881543680,\"id_str\":\"2044303881543680\",\"order_type\":1,\"order_subtype\":5,\"datetime\":\"1787932602\",\"microtimestamp\":\"1787932601987000\",\"amount\":1.007365,\"amount_str\":\"1.00736500\",\"amount_traded\":\"0\",\"amount_at_create\":\"1.00736500\",\"price\":0.03160719,\"price_str\":\"0.03160719\",\"is_liquidation\":false},\"channel\":\"live_orders_ethbtc\",\"event\":\"order_created\",\"event_id\":\"00065a1d-7f9f-afb8-0000-001103000020\",\"pre_event_id\":\"00065a1d-7f9f-a7e8-0000-001102000020\",\"order_source\":\"orderbook\"}","recorded_unix_us":1787932602022682}
{"message":"{\"data\":{\"id\":2044303881543684,\"id_str\":\"2044303881543684\",\"order_type\":0,\"order_subtype\":5,\"datetime\":\"1787932602\",\"microtimestamp\":\"1787932601988000\",\"amount\":0.00140266,\"amount_str\":\"0.00140266\",\"amount_traded\":\"0\",\"amount_at_create\":\"0.00140266\",\"price\":70667.93,\"price_str\":\"70667.93\",\"is_liquidation\":false},\"channel\":\"live_orders_btcusd\",\"event\":\"order_created\",\"event_id\":\"00065a1d-7f9f-b3a0-0000-000100000020\",\"pre_event_id\":\"00065a1d-7f9f-9460-0000-000103000020\",\"order_source\":\"orderbook\"}","recorded_unix_us":1787932602022717}
{"message":"{\"data\":{\"id\":2044303881547776,\"id_str\":\"2044303881547776\",\"order_type\":1,\"order_subtype\":5,\"datetime\":\"1787932602\",\"microtimestamp\":\"1787932601988000\",\"amount\":2.01406611,\"amount_str\":\"2.01406611\",\"amount_traded\":\"0\",\"amount_at_create\":\"2.01406611\",\"price\":0.0316176,\"price_str\":\"0.03161760\",\"is_liquidation\":false},\"channel\":\"live_orders_ethbtc\",\"event\":\"order_created\",\"event_id\":\"00065a1d-7f9f-b3a0-0000-001100000020\",\"pre_event_id\":\"00065a1d-7f9f-afb8-0000-001103000020\",\"order_source\":\"orderbook\"}","recorded_unix_us":1787932602022883}
{"message":"{\"data\":{\"id\":2044303880880129,\"id_str\":\"2044303880880129\",\"order_type\":0,\"order_subtype\":5,\"datetime\":\"1787932602\",\"microtimestamp\":\"1787932601990000\",\"amount\":8,\"amount_str\":\"8.000000\",\"amount_traded\":\"0\",\"amount_at_create\":\"8.000000\",\"price\":2478.96,\"price_str\":\"2478.96\",\"is_liquidation\":false},\"channel\":\"live_orders_ethusd\",\"event\":\"order_deleted\",\"event_id\":\"00065a1d-7f9f-bb70-0000-001200000020\",\"pre_event_id\":\"00065a1d-7f9f-6d50-0001-001203000020\",\"order_source\":\"orderbook\"}","recorded_unix_us":1787932602036253}
{"message":"{\"data\":{\"id\":2044303880704004,\"id_str\":\"2044303880704004\",\"order_type\":0,\"order_subtype\":5,\"datetime\":\"1787932602\",\"microtimestamp\":\"1787932601990000\",\"amount\":5,\"amount_str\":\"5.000000\",\"amount_traded\":\"0\",\"amount_at_create\":\"5.000000\",\"price\":2479.95,\"price_str\":\"2479.95\",\"is_liquidation\":false},\"channel\":\"live_orders_ethusd\",\"event\":\"order_deleted\",\"event_id\":\"00065a1d-7f9f-bb70-0001-001201000020\",\"pre_event_id\":\"00065a1d-7f9f-bb70-0000-001200000020\",\"order_source\":\"orderbook\"}","recorded_unix_us":1787932602036331}
{"message":"{\"data\":{\"id\":2044303880716294,\"id_str\":\"2044303880716294\",\"order_type\":0,\"order_subtype\":5,\"datetime\":\"1787932602\",\"microtimestamp\":\"1787932601990000\",\"amount\":6,\"amount_str\":\"6.000000\",\"amount_traded\":\"0\",\"amount_at_create\":\"6.000000\",\"price\":2479.7,\"price_str\":\"2479.70\",\"is_liquidation\":false},\"channel\":\"live_orders_ethusd\",\"event\":\"order_deleted\",\"event_id\":\"00065a1d-7f9f-bb70-0002-001202000020\",\"pre_event_id\":\"00065a1d-7f9f-bb70-0001-001201000020\",\"order_source\":\"orderbook\"}","recorded_unix_us":1787932602036421}
{"message":"{\"data\":{\"id\":2044303881560074,\"id_str\":\"2044303881560074\",\"order_type\":1,\"order_subtype\":5,\"datetime\":\"1787932602\",\"microtimestamp\":\"1787932601991000\",\"amount\":4.02232075,\"amount_str\":\"4.02232075\",\"amount_traded\":\"0\",\"amount_at_create\":\"4.02232075\",\"price\":0.03165997,\"price_str\":\"0.03165997\",\"is_liquidation\":false},\"channel\":\"live_orders_ethbtc\",\"event\":\"order_created\",\"event_id\":\"00065a1d-7f9f-bf58-0000-001101000020\",\"pre_event_id\":\"00065a1d-7f9f-b3a0-0000-001100000020\",\"order_source\":\"orderbook\"}","recorded_unix_us":1787932602036491}
{"message":"{\"data\":{\"id\":2044303881564169,\"id_str\":\"2044303881564169\",\"order_type\":0,\"order_subtype\":5,\"datetime\":\"1787932602\",\"microtimestamp\":\"1787932601993000\",\"amount\":0.50943161,\"amount_str\":\"0.50943161\",\"amount_traded\":\"0\",\"amount_at_create\":\"0.50943161\",\"price\":78481.52,\"price_str\":\"78481.52\",\"is_liquidation\":false},\"channel\":\"live_orders_btcusd\",\"event\":\"order_created\",\"event_id\":\"00065a1d-7f9f-c728-0000-000101000020\",\"pre_event_id\":\"00065a1d-7f9f-b3a0-0000-000100000020\",\"order_source\":\"orderbook\"}","recorded_unix_us":1787932602036617}
{"message":"{\"data\":{\"id\":2044303859556354,\"id_str\":\"2044303859556354\",\"order_type\":0,\"order_subtype\":5,\"datetime\":\"1787932602\",\"microtimestamp\":\"1787932601995000\",\"amount\":0.0372,\"amount_str\":\"0.03720000\",\"amount_traded\":\"0\",\"amount_at_create\":\"0.03720000\",\"price\":0.03155239,\"price_str\":\"0.03155239\",\"is_liquidation\":false},\"channel\":\"live_orders_ethbtc\",\"event\":\"order_deleted\",\"event_id\":\"00065a1d-7f9f-cef8-0000-001102000020\",\"pre_event_id\":\"00065a1d-7f9f-bf58-0000-001101000020\",\"order_source\":\"orderbook\"}","recorded_unix_us":1787932602036669}
{"message":"{\"data\":{\"id\":2044303859507202,\"id_str\":\"2044303859507202\",\"order_type\":1,\"order_subtype\":5,\"datetime\":\"1787932602\",\"microtimestamp\":\"1787932601995000\",\"amount\":0.0372,\"amount_str\":\"0.03720000\",\"amount_traded\":\"0\",\"amount_at_create\":\"0.03720000\",\"price\":0.03164078,\"price_str\":\"0.03164078\",\"is_liquidation\":false},\"channel\":\"live_orders_ethbtc\",\"event\":\"order_deleted\",\"event_id\":\"00065a1d-7f9f-cef8-0001-001103000020\",\"pre_event_id\":\"00065a1d-7f9f-cef8-0000-001102000020\",\"order_source\":\"orderbook\"}","recorded_unix_us":1787932602036765}
{"message":"{\"data\":{\"id\":2044303881605126,\"id_str\":\"2044303881605126\",\"order_type\":1,\"order_subtype\":5,\"datetime\":\"1787932602\",\"microtimestamp\":\"1787932602003000\",\"amount\":0.06310787,\"amount_str\":\"0.06310787\",\"amount_traded\":\"0\",\"amount_at_create\":\"0.06310787\",\"price\":78521.25,\"price_str\":\"78521.25\",\"is_liquidation\":false},\"channel\":\"live_orders_btcusd\",\"event\":\"order_created\",\"event_id\":\"00065a1d-7f9f-ee38-0000-000102000020\",\"pre_event_id\":\"00065a1d-7f9f-c728-0000-000101000020\",\"order_source\":\"orderbook\"}","recorded_unix_us":1787932602036905}
{"message":"{\"data\":{\"id\":2044303881605126,\"id_str\":\"2044303881605126\",\"order_type\":1,\"order_subtype\":5,\"datetime\":\"1787932602\",\"microtimestamp\":\"1787932602003000\",\"amount\":0.06310787,\"amount_str\":\"0.06310787\",\"amount_traded\":\"0\",\"amount_at_create\":\"0.06310787\",\"price\":78521.25,\"price_str\":\"78521.25\",\"is_liquidation\":false},\"channel\":\"live_orders_btcusd\",\"event\":\"order_deleted\",\"event_id\":\"00065a1d-7f9f-ee38-0001-000103000020\",\"pre_event_id\":\"00065a1d-7f9f-ee38-0000-000102000020\",\"order_source\":\"orderbook\"}","recorded_unix_us":1787932602036940}
{"message":"{\"data\":{\"id\":2044303881613312,\"id_str\":\"2044303881613312\",\"order_type\":1,\"order_subtype\":5,\"datetime\":\"1787932602\",\"microtimestamp\":\"1787932602004000\",\"amount\":0.1,\"amount_str\":\"0.10000000\",\"amount_traded\":\"0\",\"amount_at_create\":\"0.10000000\",\"price\":78522.62,\"price_str\":\"78522.62\",\"is_liquidation\":false},\"channel\":\"live_orders_btcusd\",\"event\":\"order_created\",\"event_id\":\"00065a1d-7f9f-f220-0000-000100000020\",\"pre_event_id\":\"00065a1d-7f9f-ee38-0001-000103000020\",\"order_source\":\"orderbook\"}","recorded_unix_us":1787932602037057}
{"message":"{\"data\":{\"id\":2044303881613312,\"id_str\":\"2044303881613312\",\"order_type\":1,\"order_subtype\":5,\"datetime\":\"1787932602\",\"microtimestamp\":\"1787932602004000\",\"amount\":0.1,\"amount_str\":\"0.10000000\",\"amount_traded\":\"0\",\"amount_at_create\":\"0.10000000\",\"price\":78522.62,\"price_str\":\"78522.62\",\"is_liquidation\":false},\"channel\":\"live_orders_btcusd\",\"event\":\"order_deleted\",\"event_id\":\"00065a1d-7f9f-f220-0001-000101000020\",\"pre_event_id\":\"00065a1d-7f9f-f220-0000-000100000020\",\"order_source\":\"orderbook\"}","recorded_unix_us":1787932602037087}
{"message":"{\"data\":{\"id\":2044303881613313,\"id_str\":\"2044303881613313\",\"order_type\":1,\"order_subtype\":5,\"datetime\":\"1787932602\",\"microtimestamp\":\"1787932602004000\",\"amount\":0.1,\"amount_str\":\"0.10000000\",\"amount_traded\":\"0\",\"amount_at_create\":\"0.10000000\",\"price\":78522.63,\"price_str\":\"78522.63\",\"is_liquidation\":false},\"channel\":\"live_orders_btcusd\",\"event\":\"order_created\",\"event_id\":\"00065a1d-7f9f-f220-0002-000102000020\",\"pre_event_id\":\"00065a1d-7f9f-f220-0001-000101000020\",\"order_source\":\"orderbook\"}","recorded_unix_us":1787932602049610}
{"message":"{\"data\":{\"id\":2044303881613313,\"id_str\":\"2044303881613313\",\"order_type\":1,\"order_subtype\":5,\"datetime\":\"1787932602\",\"microtimestamp\":\"1787932602004000\",\"amount\":0.1,\"amount_str\":\"0.10000000\",\"amount_traded\":\"0\",\"amount_at_create\":\"0.10000000\",\"price\":78522.63,\"price_str\":\"78522.63\",\"is_liquidation\":false},\"channel\":\"live_orders_btcusd\",\"event\":\"order_deleted\",\"event_id\":\"00065a1d-7f9f-f220-0003-000103000020\",\"pre_event_id\":\"00065a1d-7f9f-f220-0002-000102000020\",\"order_source\":\"orderbook\"}","recorded_unix_us":1787932602049638}
{"message":"{\"data\":{\"id\":2044303881191426,\"id_str\":\"2044303881191426\",\"order_type\":0,\"order_subtype\":5,\"datetime\":\"1787932602\",\"microtimestamp\":\"1787932602021000\",\"amount\":0.19103753,\"amount_str\":\"0.19103753\",\"amount_traded\":\"0\",\"amount_at_create\":\"0.19103753\",\"price\":78485.11,\"price_str\":\"78485.11\",\"is_liquidation\":false},\"channel\":\"live_orders_btcusd\",\"event\":\"order_deleted\",\"event_id\":\"00065a1d-7fa0-3488-0000-000100000020\",\"pre_event_id\":\"00065a1d-7f9f-f220-0003-000103000020\",\"order_source\":\"orderbook\"}","recorded_unix_us":1787932602064426}
{"message":"{\"data\":{\"id\":2044303881428997,\"id_str\":\"2044303881428997\",\"order_type\":0,\"order_subtype\":5,\"datetime\":\"1787932602\",\"microtimestamp\":\"1787932602022000\",\"amount\":0.63679897,\"amount_str\":\"0.63679897\",\"amount_traded\":\"0\",\"amount_at_create\":\"0.63679897\",\"price\":78483.23,\"price_str\":\"78483.23\",\"is_liquidation\":false},\"channel\":\"live_orders_btcusd\",\"event\":\"order_deleted\",\"event_id\":\"00065a1d-7fa0-3870-0000-000101000020\",\"pre_event_id\":\"00065a1d-7fa0-3488-0000-000100000020\",\"order_source\":\"orderbook\"}","recorded_unix_us":1787932602064455}
{"message":"{\"data\":{\"id\":2044303881564169,\"id_str\":\"2044303881564169\",\"order_type\":0,\"order_subtype\":5,\"datetime\":\"1787932602\",\"microtimestamp\":\"1787932602022000\",\"amount\":0.50943161,\"amount_str\":\"0.50943161\",\"amount_traded\":\"0\",\"amount_at_create\":\"0.50943161\",\"price\":78481.52,\"price_str\":\"78481.52\",\"is_liquidation\":false},\"channel\":\"live_orders_btcusd\",\"event\":\"order_deleted\",\"event_id\":\"00065a1d-7fa0-3870-0001-000102000020\",\"pre_event_id\":\"00065a1d-7fa0-3870-0000-000101000020\",\"order_source\":\"orderbook\"}","recorded_unix_us":1787932602064542}
{"message":"{\"data\":{\"id\":2044303881175053,\"id_str\":\"2044303881175053\",\"order_type\":0,\"order_subtype\":5,\"datetime\":\"1787932602\",\"microtimestamp\":\"1787932602023000\",\"amount\":0.06368031,\"amount_str\":\"0.06368031\",\"amount_traded\":\"0\",\"amount_at_create\":\"0.06368031\",\"price\":78517.2,\"price_str\":\"78517.20\",\"is_liquidation\":false},\"channel\":\"live_orders_btcusd\",\"event\":\"order_deleted\",\"event_id\":\"00065a1d-7fa0-3c58-0000-000103000020\",\"pre_event_id\":\"00065a1d-7fa0-3870-0001-000102000020\",\"order_source\":\"orderbook\"}","recorded_unix_us":1787932602064645}
{"message":"{\"data\":{\"id\":2044303876300813,\"id_str\":\"2044303876300813\",\"order_type\":1,\"order_subtype\":5,\"datetime\":\"1787932602\",\"microtimestamp\":\"1787932602027000\",\"amount\":0.50938943,\"amount_str\":\"0.50938943\",\"amount_traded\":\"0\",\"amount_at_create\":\"0.50938943\",\"price\":78522.64,\"price_str\":\"78522.64\",\"is_liquidation\":false},\"channel\":\"live_orders_btcusd\",\"event\":\"order_deleted\",\"event_id\":\"00065a1d-7fa0-4bf8-0000-000100000020\",\"pre_event_id\":\"00065a1d-7fa0-3c58-0000-000103000020\",\"order_source\":\"orderbook\"}","recorded_unix_us":1787932602066514}
{"message":"{\"data\":{\"id\":2044303852109824,\"id_str\":\"2044303852109824\",\"order_type\":1,\"order_subtype\":5,\"datetime\":\"1787932602\",\"microtimestamp\":\"1787932602028000\",\"amount\":0.19101517,\"amount_str\":\"0.19101517\",\"amount_traded\":\"0\",\"amount_at_create\":\"0.19101517\",\"price\":78522.64,\"price_str\":\"78522.64\",\"is_liquidation\":false},\"channel\":\"live_orders_btcusd\",\"event\":\"order_deleted\",\"event_id\":\"00065a1d-7fa0-4fe0-0000-000101000020\",\"pre_event_id\":\"00065a1d-7fa0-4bf8-0000-000100000020\",\"order_source\":\"orderbook\"}","recorded_unix_us":1787932602066680}
{"message":"{\"data\":{\"id\":2044303876247591,\"id_str\":\"2044303876247591\",\"order_type\":1,\"order_subtype\":5,\"datetime\":\"1787932602\",\"microtimestamp\":\"1787932602029000\",\"amount\":0.6367311,\"amount_str\":\"0.63673110\",\"amount_traded\":\"0\",\"amount_at_create\":\"0.63673110\",\"price\":78522.64,\"price_str\":\"78522.64\",\"is_liquidation\":false},\"channel\":\"live_orders_btcusd\",\"event\":\"order_deleted\",\"event_id\":\"00065a1d-7fa0-53c8-0000-000102000020\",\"pre_event_id\":\"00065a1d-7fa0-4fe0-0000-000101000020\",\"order_source\":\"orderbook\"}","recorded_unix_us":1787932602066721}
{"message":"{\"data\":{\"id\":2044303881736194,\"id_str\":\"2044303881736194\",\"order_type\":1,\"order_subtype\":5,\"datetime\":\"1787932602\",\"microtimestamp\":\"1787932602034000\",\"amount\":0.1,\"amount_str\":\"0.10000000\",\"amount_traded\":\"0\",\"amount_at_create\":\"0.10000000\",\"price\":78522.62,\"price_str\":\"78522.62\",\"is_liquidation\":false},\"channel\":\"live_orders_btcusd\",\"event\":\"order_created\",\"event_id\":\"00065a1d-7fa0-6750-0000-000103000020\",\"pre_event_id\":\"00065a1d-7fa0-53c8-0000-000102000020\",\"order_source\":\"orderbook\"}","recorded_unix_us":1787932602087168}
{"message":"{\"data\":{\"id\":2044303881736194,\"id_str\":\"2044303881736194\",\"order_type\":1,\"order_subtype\":5,\"datetime\":\"1787932602\",\"microtimestamp\":\"1787932602034000\",\"amount\":0.1,\"amount_str\":\"0.10000000\",\"amount_traded\":\"0\",\"amount_at_create\":\"0.10000000\",\"price\":78522.62,\"price_str\":\"78522.62\",\"is_liquidation\":false},\"channel\":\"live_orders_btcusd\",\"event\":\"order_deleted\",\"event_id\":\"00065a1d-7fa0-6750-0001-000100000020\",\"pre_event_id\":\"00065a1d-7fa0-6750-0000-000103000020\",\"order_source\":\"orderbook\"}","recorded_unix_us":1787932602087204}
{"message":"{\"data\":{\"id\":2044303881736196,\"id_str\":\"2044303881736196\",\"order_type\":0,\"order_subtype\":5,\"datetime\":\"1787932602\",\"microtimestamp\":\"1787932602035000\",\"amount\":0.19103754,\"amount_str\":\"0.19103754\",\"amount_traded\":\"0\",\"amount_at_create\":\"0.19103754\",\"price\":78486.13,\"price_str\":\"78486.13\",\"is_liquidation\":false},\"channel\":\"live_orders_btcusd\",\"event\":\"order_created\",\"event_id\":\"00065a1d-7fa0-6b38-0000-000101000020\",\"pre_event_id\":\"00065a1d-7fa0-6750-0001-000100000020\",\"order_source\":\"orderbook\"}","recorded_unix_us":1787932602087226}
{"message":"{\"data\":{\"id\":2044303881744388,\"id_str\":\"2044303881744388\",\"order_type\":0,\"order_subtype\":5,\"datetime\":\"1787932602\",\"microtimestamp\":\"1787932602036000\",\"amount\":0.50943344,\"amount_str\":\"0.50943344\",\"amount_traded\":\"0\",\"amount_at_create\":\"0.50943344\",\"price\":78482.2,\"price_str\":\"78482.20\",\"is_liquidation\":false},\"channel\":\"live_orders_btcusd\",\"event\":\"order_created\",\"event_id\":\"00065a1d-7fa0-6f20-0000-000102000020\",\"pre_event_id\":\"00065a1d-7fa0-6b38-0000-000101000020\",\"order_source\":\"orderbook\"}","recorded_unix_us":1787932602087341}
{"message":"{\"data\":{\"id\":2044303881744391,\"id_str\":\"2044303881744391\",\"order_type\":0,\"order_subtype\":5,\"datetime\":\"1787932602\",\"microtimestamp\":\"1787932602036000\",\"amount\":0.6367918,\"amount_str\":\"0.63679180\",\"amount_traded\":\"0\",\"amount_at_create\":\"0.63679180\",\"price\":78484.17,\"price_str\":\"78484.17\",\"is_liquidation\":false},\"channel\":\"live_orders_btcusd\",\"event\":\"order_created\",\"event_id\":\"00065a1d-7fa0-6f20-0001-000103000020\",\"pre_event_id\":\"00065a1d-7fa0-6f20-0000-000102000020\",\"order_source\":\"orderbook\"}","recorded_unix_us":1787932602087371}
{"message":"{\"data\":{\"id\":2044303880777729,\"id_str\":\"2044303880777729\",\"order_type\":0,\"order_subtype\":5,\"datetime\":\"1787932602\",\"microtimestamp\":\"1787932602038000\",\"amount\":0.403101,\"amount_str\":\"0.403101\",\"amount_traded\":\"0\",\"amount_at_create\":\"0.403101\",\"price\":2479.8,\"price_str\":\"2479.80\",\"is_liquidation\":false},\"channel\":\"live_orders_ethusd\",\"event\":\"order_deleted\",\"event_id\":\"00065a1d-7fa0-76f0-0000-001203000020\",\"pre_event_id\":\"00065a1d-7f9f-bb70-0002-001202000020\",\"order_source\":\"orderbook\"}","recorded_unix_us":1787932602087495}
{"message":"{\"data\":{\"id\":2044303881756676,\"id_str\":\"2044303881756676\",\"order_type\":1,\"order_subtype\":5,\"datetime\":\"1787932602\",\"microtimestamp\":\"1787932602040000\",\"amount\":0.0372,\"amount_str\":\"0.03720000\",\"amount_traded\":\"0\",\"amount_at_create\":\"0.03720000\",\"price\":0.03164077,\"price_str\":\"0.03164077\",\"is_liquidation\":false},\"channel\":\"live_orders_ethbtc\",\"event\":\"order_created\",\"event_id\":\"00065a1d-7fa0-7ec0-0000-001100000020\",\"pre_event_id\":\"00065a1d-7f9f-cef8-0001-001103000020\",\"order_source\":\"orderbook\"}","recorded_unix_us":1787932602087520}
{"message":"{\"data\":{\"id\":2044303881768960,\"id_str\":\"2044303881768960\",\"order_type\":1,\"order_subtype\":5,\"datetime\":\"1787932602\",\"microtimestamp\":\"1787932602042000\",\"amount\":3.02055629,\"amount_str\":\"3.02055629\",\"amount_traded\":\"0\",\"amount_at_create\":\"3.02055629\",\"price\":0.03162186,\"price_str\":\"0.03162186\",\"is_liquidation\":false},\"channel\":\"live_orders_ethbtc\",\"event\":\"order_created\",\"event_id\":\"00065a1d-7fa0-8690-0000-001101000020\",\"pre_event_id\":\"00065a1d-7fa0-7ec0-0000-001100000020\",\"order_source\":\"orderbook\"}","recorded_unix_us":1787932602087596}
{"message":"{\"data\":{\"id\":2044303881768963,\"id_str\":\"2044303881768963\",\"order_type\":1,\"order_subtype\":5,\"datetime\":\"1787932602\",\"microtimestamp\":\"1787932602042000\",\"amount\":1.56076612,\"amount_str\":\"1.56076612\",\"amount_traded\":\"0\",\"amount_at_create\":\"1.56076612\",\"price\":0.03317746,\"price_str\":\"0.03317746\",\"is_liquidation\":false},\"channel\":\"live_orders_ethbtc\",\"event\":\"order_created\",\"event_id\":\"00065a1d-7fa0-8690-0001-001102000020\",\"pre_event_id\":\"00065a1d-7fa0-8690-0000-001101000020\",\"order_source\":\"orderbook\"}","recorded_unix_us":1787932602087672}
{"message":"{\"data\":{\"id\":2044303881768966,\"id_str\":\"2044303881768966\",\"order_type\":0,\"order_subtype\":5,\"datetime\":\"1787932602\",\"microtimestamp\":\"1787932602043000\",\"amount\":0.60475617,\"amount_str\":\"0.60475617\",\"amount_traded\":\"0\",\"amount_at_create\":\"0.60475617\",\"price\":0.03158982,\"price_str\":\"0.03158982\",\"is_liquidation\":false},\"channel\":\"live_orders_ethbtc\",\"event\":\"order_created\",\"event_id\":\"00065a1d-7fa0-8a78-0000-001103000020\",\"pre_event_id\":\"00065a1d-7fa0-8690-0001-001102000020\",\"order_source\":\"orderbook\"}","recorded_unix_us":1787932602087832}
{"message":"{\"data\":{\"id\":2044303881773058,\"id_str\":\"2044303881773058\",\"order_type\":0,\"order_subtype\":5,\"datetime\":\"1787932602\",\"microtimestamp\":\"1787932602043000\",\"amount\":1.00801353,\"amount_str\":\"1.00801353\",\"amount_traded\":\"0\",\"amount_at_create\":\"1.00801353\",\"price\":0.03158534,\"price_str\":\"0.03158534\",\"is_liquidation\":false},\"channel\":\"live_orders_ethbtc\",\"event\":\"order_created\",\"event_id\":\"00065a1d-7fa0-8a78-0001-001100000020\",\"pre_event_id\":\"00065a1d-7fa0-8a78-0000-001103000020\",\"order_source\":\"orderbook\"}","recorded_unix_us":1787932602087857}
{"message":"{\"data\":{\"id\":2044303881773063,\"id_str\":\"2044303881773063\",\"order_type\":0,\"order_subtype\":5,\"datetime\":\"1787932602\",\"microtimestamp\":\"1787932602043000\",\"amount\":2.01629689,\"amount_str\":\"2.01629689\",\"amount_traded\":\"0\",\"amount_at_create\":\"2.01629689\",\"price\":0.03157941,\"price_str\":\"0.03157941\",\"is_liquidation\":false},\"channel\":\"live_orders_ethbtc\",\"event\":\"order_created\",\"event_id\":\"00065a1d-7fa0-8a78-0002-001101000020\",\"pre_event_id\":\"00065a1d-7fa0-8a78-0001-001100000020\",\"order_source\":\"orderbook\"}","recorded_unix_us":1787932602087878}
{"message":"{\"data\":{\"id\":2044303881773064,\"id_str\":\"2044303881773064\",\"order_type\":1,\"order_subtype\":5,\"datetime\":\"1787932602\",\"microtimestamp\":\"1787932602044000\",\"amount\":0.06310787,\"amount_str\":\"0.06310787\",\"amount_traded\":\"0\",\"amount_at_create\":\"0.06310787\",\"price\":78522.11,\"price_str\":\"78522.11\",\"is_liquidation\":false},\"channel\":\"live_orders_btcusd\",\"event\":\"order_created\",\"event_id\":\"00065a1d-7fa0-8e60-0000-000100000020\",\"pre_event_id\":\"00065a1d-7fa0-6f20-0001-000103000020\",\"order_source\":\"orderbook\"}","recorded_unix_us":1787932602087897}
{"message":"{\"data\":{\"id\":2044303881773064,\"id_str\":\"2044303881773064\",\"order_type\":1,\"order_subtype\":5,\"datetime\":\"1787932602\",\"microtimestamp\":\"1787932602044000\",\"amount\":0.06310787,\"amount_str\":\"0.06310787\",\"amount_traded\":\"0\",\"amount_at_create\":\"0.06310787\",\"price\":78522.11,\"price_str\":\"78522.11\",\"is_liquidation\":false},\"channel\":\"live_orders_btcusd\",\"event\":\"order_deleted\",\"event_id\":\"00065a1d-7fa0-8e60-0001-000101000020\",\"pre_event_id\":\"00065a1d-7fa0-8e60-0000-000100000020\",\"order_source\":\"orderbook\"}","recorded_unix_us":1787932602088014}
{"message":"{\"data\":{\"id\":2044303881777153,\"id_str\":\"2044303881777153\",\"order_type\":0,\"order_subtype\":5,\"datetime\":\"1787932602\",\"microtimestamp\":\"1787932602044000\",\"amount\":3.02537254,\"amount_str\":\"3.02537254\",\"amount_traded\":\"0\",\"amount_at_create\":\"3.02537254\",\"price\":0.03156999,\"price_str\":\"0.03156999\",\"is_liquidation\":false},\"channel\":\"live_orders_ethbtc\",\"event\":\"order_created\",\"event_id\":\"00065a1d-7fa0-8e60-0000-001102000020\",\"pre_event_id\":\"00065a1d-7fa0-8a78-0002-001101000020\",\"order_source\":\"orderbook\"}","recorded_unix_us":1787932602088037}
{"message":"{\"data\":{\"id\":2044303881785349,\"id_str\":\"2044303881785349\",\"order_type\":0,\"order_subtype\":5,\"datetime\":\"1787932602\",\"microtimestamp\":\"1787932602047000\",\"amount\":4.03662068,\"amount_str\":\"4.03662068\",\"amount_traded\":\"0\",\"amount_at_create\":\"4.03662068\",\"price\":0.03154857,\"price_str\":\"0.03154857\",\"is_liquidation\":false},\"channel\":\"live_orders_ethbtc\",\"event\":\"order_created\",\"event_id\":\"00065a1d-7fa0-9a18-0000-001103000020\",\"pre_event_id\":\"00065a1d-7fa0-8e60-0000-001102000020\",\"order_source\":\"orderbook\"}","recorded_unix_us":1787932602088108}
{"message":"{\"data\":{\"id\":2044303881793543,\"id_str\":\"2044303881793543\",\"order_type\":0,\"order_subtype\":5,\"datetime\":\"1787932602\",\"microtimestamp\":\"1787932602048000\",\"amount\":0.40309,\"amount_str\":\"0.403090\",\"amount_traded\":\"0\",\"amount_at_create\":\"0.403090\",\"price\":2480.01,\"price_str\":\"2480.01\",\"is_liquidation\":false},\"channel\":\"live_orders_ethusd\",\"event\":\"order_created\",\"event_id\":\"00065a1d-7fa0-9e00-0000-001200000020\",\"pre_event_id\":\"00065a1d-7fa0-76f0-0000-001203000020\",\"order_source\":\"orderbook\"}","recorded_unix_us":1787932602088185}
{"message":"{\"data\":{\"id\":2044303881793550,\"id_str\":\"2044303881793550\",\"order_type\":1,\"order_subtype\":5,\"datetime\":\"1787932602\",\"microtimestamp\":\"1787932602049000\",\"amount\":0.1,\"amount_str\":\"0.10000000\",\"amount_traded\":\"0\",\"amount_at_create\":\"0.10000000\",\"price\":78522.63,\"price_str\":\"78522.63\",\"is_liquidation\":false},\"channel\":\"live_orders_btcusd\",\"event\":\"order_created\",\"event_id\":\"00065a1d-7fa0-a1e8-0000-000102000020\",\"pre_event_id\":\"00065a1d-7fa0-8e60-0001-000101000020\",\"order_source\":\"orderbook\"}","recorded_unix_us":1787932602097418}
{"message":"{\"data\":{\"id\":2044303881793550,\"id_str\":\"2044303881793550\",\"order_type\":1,\"order_subtype\":5,\"datetime\":\"1787932602\",\"microtimestamp\":\"1787932602049000\",\"amount\":0.1,\"amount_str\":\"0.10000000\",\"amount_traded\":\"0\",\"amount_at_create\":\"0.10000000\",\"price\":78522.63,\"price_str\":\"78522.63\",\"is_liquidation\":false},\"channel\":\"live_orders_btcusd\",\"event\":\"order_deleted\",\"event_id\":\"00065a1d-7fa0-a1e8-0001-000103000020\",\"pre_event_id\":\"00065a1d-7fa0-a1e8-0000-000102000020\",\"order_source\":\"orderbook\"}","recorded_unix_us":1787932602097446}
{"message":"{\"data\":{\"id\":2044303881543684,\"id_str\":\"2044303881543684\",\"order_type\":0,\"order_subtype\":5,\"datetime\":\"1787932602\",\"microtimestamp\":\"1787932602054000\",\"amount\":0.00140266,\"amount_str\":\"0.00140266\",\"amount_traded\":\"0\",\"amount_at_create\":\"0.00140266\",\"price\":70667.93,\"price_str\":\"70667.93\",\"is_liquidation\":false},\"channel\":\"live_orders_btcusd\",\"event\":\"order_deleted\",\"event_id\":\"00065a1d-7fa0-b570-0000-000100000020\",\"pre_event_id\":\"00065a1d-7fa0-a1e8-0001-000103000020\",\"order_source\":\"orderbook\"}","recorded_unix_us":1787932602097591}
{"message":"{\"data\":{\"id\":2044303881830404,\"id_str\":\"2044303881830404\",\"order_type\":0,\"order_subtype\":5,\"datetime\":\"1787932602\",\"microtimestamp\":\"1787932602058000\",\"amount\":3,\"amount_str\":\"3.000000\",\"amount_traded\":\"0\",\"amount_at_create\":\"3.000000\",\"price\":2479.81,\"price_str\":\"2479.81\",\"is_liquidation\":false},\"channel\":\"live_orders_ethusd\",\"event\":\"order_created\",\"event_id\":\"00065a1d-7fa0-c510-0000-001201000020\",\"pre_event_id\":\"00065a1d-7fa0-9e00-0000-001200000020\",\"order_source\":\"orderbook\"}","recorded_unix_us":1787932602097622}
{"message":"{\"data\":{\"id\":2044303881838592,\"id_str\":\"2044303881838592\",\"order_type\":0,\"order_subtype\":5,\"datetime\":\"1787932602\",\"microtimestamp\":\"1787932602059000\",\"amount\":3,\"amount_str\":\"3.000000\",\"amount_traded\":\"0\",\"amount_at_create\":\"3.000000\",\"price\":2479.81,\"price_str\":\"2479.81\",\"is_liquidation\":false},\"channel\":\"live_orders_ethusd\",\"event\":\"order_created\",\"event_id\":\"00065a1d-7fa0-c8f8-0000-001202000020\",\"pre_event_id\":\"00065a1d-7fa0-c510-0000-001201000020\",\"order_source\":\"orderbook\"}","recorded_unix_us":1787932602097746}
{"message":"{\"data\":{\"id\":2044303881842690,\"id_str\":\"2044303881842690\",\"order_type\":0,\"order_subtype\":5,\"datetime\":\"1787932602\",\"microtimestamp\":\"1787932602060000\",\"amount\":5,\"amount_str\":\"5.000000\",\"amount_traded\":\"0\",\"amount_at_create\":\"5.000000\",\"price\":2480.06,\"price_str\":\"2480.06\",\"is_liquidation\":false},\"channel\":\"live_orders_ethusd\",\"event\":\"order_created\",\"event_id\":\"00065a1d-7fa0-cce0-0000-001203000020\",\"pre_event_id\":\"00065a1d-7fa0-c8f8-0000-001202000020\",\"order_source\":\"orderbook\"}","recorded_unix_us":1787932602097776}
{"message":"{\"data\":{\"id\":2044303881244675,\"id_str\":\"2044303881244675\",\"order_type\":0,\"order_subtype\":5,\"datetime\":\"1787932602\",\"microtimestamp\":\"1787932602063000\",\"amount\":0.043457,\"amount_str\":\"0.043457\",\"amount_traded\":\"0\",\"amount_at_create\":\"0.043457\",\"price\":2480.73,\"price_str\":\"2480.73\",\"is_liquidation\":false},\"channel\":\"live_orders_ethusd\",\"event\":\"order_deleted\",\"event_id\":\"00065a1d-7fa0-d898-0000-001200000020\",\"pre_event_id\":\"00065a1d-7fa0-cce0-0000-001203000020\",\"order_source\":\"orderbook\"}","recorded_unix_us":1787932602097906}
{"message":"{\"data\":{\"id\":2044303881850882,\"id_str\":\"2044303881850882\",\"order_type\":1,\"order_subtype\":5,\"datetime\":\"1787932602\",\"microtimestamp\":\"1787932602063000\",\"amount\":2.015283,\"amount_str\":\"2.015283\",\"amount_traded\":\"0\",\"amount_at_create\":\"2.015283\",\"price\":2481.51,\"price_str\":\"2481.51\",\"is_liquidation\":false},\"channel\":\"live_orders_ethusd\",\"event\":\"order_created\",\"event_id\":\"00065a1d-7fa0-d898-0001-001201000020\",\"pre_event_id\":\"00065a1d-7fa0-d898-0000-001200000020\",\"order_source\":\"orderbook\"}","recorded_unix_us":1787932602097943}
{"message":"{\"data\":{\"id\":2044303881854976,\"id_str\":\"2044303881854976\",\"order_type\":1,\"order_subtype\":5,\"datetime\":\"1787932602\",\"microtimestamp\":\"1787932602063000\",\"amount\":2.01528391,\"amount_str\":\"2.01528391\",\"amount_traded\":\"0\",\"amount_at_create\":\"2.01528391\",\"price\":0.03163293,\"price_str\":\"0.03163293\",\"is_liquidation\":false},\"channel\":\"live_orders_ethbtc\",\"event\":\"order_created\",\"event_id\":\"00065a1d-7fa0-d898-0000-001100000020\",\"pre_event_id\":\"00065a1d-7fa0-9a18-0000-001103000020\",\"order_source\":\"orderbook\"}","recorded_unix_us":1787932602098046}
{"message":"{\"data\":{\"id\":2044303880785925,\"id_str\":\"2044303880785925\",\"order_type\":1,\"order_subtype\":5,\"datetime\":\"1787932602\",\"microtimestamp\":\"1787932602063000\",\"amount\":0.044018,\"amount_str\":\"0.044018\",\"amount_traded\":\"0\",\"amount_at_create\":\"0.044018\",\"price\":2480.82,\"price_str\":\"2480.82\",\"is_liquidation\":false},\"channel\":\"live_orders_ethusd\",\"event\":\"order_deleted\",\"event_id\":\"00065a1d-7fa0-d898-0002-001202000020\",\"pre_event_id\":\"00065a1d-7fa0-d898-0001-001201000020\",\"order_source\":\"orderbook\"}","recorded_unix_us":1787932602098147}
{"message":"{\"data\":{\"id\":2044303881863168,\"id_str\":\"2044303881863168\",\"order_type\":0,\"order_subtype\":5,\"datetime\":\"1787932602\",\"microtimestamp\":\"1787932602065000\",\"amount\":0.00140266,\"amount_str\":\"0.00140266\",\"amount_traded\":\"0\",\"amount_at_create\":\"0.00140266\",\"price\":70666.76,\"price_str\":\"70666.76\",\"is_liquidation\":false},\"channel\":\"live_orders_btcusd\",\"event\":\"order_created\",\"event_id\":\"00065a1d-7fa0-e068-0000-000101000020\",\"pre_event_id\":\"00065a1d-7fa0-b570-0000-000100000020\",\"order_source\":\"orderbook\"}","recorded_unix_us":1787932602117247}
{"message":"{\"data\":{\"id\":2044303881867264,\"id_str\":\"2044303881867264\",\"order_type\":0,\"order_subtype\":5,\"datetime\":\"1787932602\",\"microtimestamp\":\"1787932602066000\",\"amount\":2,\"amount_str\":\"2.000000\",\"amount_traded\":\"0\",\"amount_at_create\":\"2.000000\",\"price\":2479.07,\"price_str\":\"2479.07\",\"is_liquidation\":false},\"channel\":\"live_orders_ethusd\",\"event\":\"order_created\",\"event_id\":\"00065a1d-7fa0-e450-0000-001203000020\",\"pre_event_id\":\"00065a1d-7fa0-d898-0002-001202000020\",\"order_source\":\"orderbook\"}","recorded_unix_us":1787932602117437}
{"message":"{\"data\":{\"id\":2044303881904133,\"id_str\":\"2044303881904133\",\"order_type\":1,\"order_subtype\":5,\"datetime\":\"1787932602\",\"microtimestamp\":\"1787932602076000\",\"amount\":0.1,\"amount_str\":\"0.10000000\",\"amount_traded\":\"0\",\"amount_at_create\":\"0.10000000\",\"price\":78522.62,\"price_str\":\"78522.62\",\"is_liquidation\":false},\"channel\":\"live_orders_btcusd\",\"event\":\"order_created\",\"event_id\":\"00065a1d-7fa1-0b60-0000-000102000020\",\"pre_event_id\":\"00065a1d-7fa0-e068-0000-000101000020\",\"order_source\":\"orderbook\"}","recorded_unix_us":1787932602117580}
{"message":"{\"data\":{\"id\":2044303881904133,\"id_str\":\"2044303881904133\",\"order_type\":1,\"order_subtype\":5,\"datetime\":\"1787932602\",\"microtimestamp\":\"1787932602076000\",\"amount\":0.1,\"amount_str\":\"0.10000000\",\"amount_traded\":\"0\",\"amount_at_create\":\"0.10000000\",\"price\":78522.62,\"price_str\":\"78522.62\",\"is_liquidation\":false},\"channel\":\"live_orders_btcusd\",\"event\":\"order_deleted\",\"event_id\":\"00065a1d-7fa1-0b60-0001-000103000020\",\"pre_event_id\":\"00065a1d-7fa1-0b60-0000-000102000020\",\"order_source\":\"orderbook\"}","recorded_unix_us":1787932602117614}
{"message":"{\"data\":{\"id\":2044303881908224,\"id_str\":\"2044303881908224\",\"order_type\":1,\"order_subtype\":5,\"datetime\":\"1787932602\",\"microtimestamp\":\"1787932602076000\",\"amount\":0.06310787,\"amount_str\":\"0.06310787\",\"amount_traded\":\"0\",\"amount_at_create\":\"0.06310787\",\"price\":78521.55,\"price_str\":\"78521.55\",\"is_liquidation\":false},\"channel\":\"live_orders_btcusd\",\"event\":\"order_created\",\"event_id\":\"00065a1d-7fa1-0b60-0002-000100000020\",\"pre_event_id\":\"00065a1d-7fa1-0b60-0001-000103000020\",\"order_source\":\"orderbook\"}","recorded_unix_us":1787932602117701}
{"message":"{\"data\":{\"id\":2044303881908224,\"id_str\":\"2044303881908224\",\"order_type\":1,\"order_subtype\":5,\"datetime\":\"1787932602\",\"microtimestamp\":\"1787932602076000\",\"amount\":0.06310787,\"amount_str\":\"0.06310787\",\"amount_traded\":\"0\",\"amount_at_create\":\"0.06310787\",\"price\":78521.55,\"price_str\":\"78521.55\",\"is_liquidation\":false},\"channel\":\"live_orders_btcusd\",\"event\":\"order_deleted\",\"event_id\":\"00065a1d-7fa1-0b60-0003-000101000020\",\"pre_event_id\":\"00065a1d-7fa1-0b60-0002-000100000020\",\"order_source\":\"orderbook\"}","recorded_unix_us":1787932602117863}
{"message":"{\"data\":{\"id\":2044303881039878,\"id_str\":\"2044303881039878\",\"order_type\":0,\"order_subtype\":5,\"datetime\":\"1787932602\",\"microtimestamp\":\"1787932602079000\",\"amount\":0.527206,\"amount_str\":\"0.527206\",\"amount_traded\":\"0\",\"amount_at_create\":\"0.527206\",\"price\":2480.02,\"price_str\":\"2480.02\",\"is_liquidation\":false},\"channel\":\"live_orders_ethusd\",\"event\":\"order_deleted\",\"event_id\":\"00065a1d-7fa1-1718-0000-001200000020\",\"pre_event_id\":\"00065a1d-7fa0-e450-0000-001203000020\",\"order_source\":\"orderbook\"}","recorded_unix_us":1787932602125285}
{"message":"{\"data\":{\"id\":2044303881940995,\"id_str\":\"2044303881940995\",\"order_type\":1,\"order_subtype\":5,\"datetime\":\"1787932602\",\"microtimestamp\":\"1787932602085000\",\"amount\":0.5094342,\"amount_str\":\"0.50943420\",\"amount_traded\":\"0\",\"amount_at_create\":\"0.50943420\",\"price\":78522.64,\"price_str\":\"78522.64\",\"is_liquidation\":false},\"channel\":\"live_orders_btcusd\",\"event\":\"order_created\",\"event_id\":\"00065a1d-7fa1-2e88-0000-000102000020\",\"pre_event_id\":\"00065a1d-7fa1-0b60-0003-000101000020\",\"order_source\":\"orderbook\"}","recorded_unix_us":1787932602125404}
{"message":"{\"data\":{\"id\":2044303881940997,\"id_str\":\"2044303881940997\",\"order_type\":0,\"order_subtype\":5,\"datetime\":\"1787932602\",\"microtimestamp\":\"1787932602085000\",\"amount\":0.042508,\"amount_str\":\"0.042508\",\"amount_traded\":\"0\",\"amount_at_create\":\"0.042508\",\"price\":2480.8,\"price_str\":\"2480.80\",\"is_liquidation\":false},\"channel\":\"live_orders_ethusd\",\"event\":\"order_created\",\"event_id\":\"00065a1d-7fa1-2e88-0000-001201000020\",\"pre_event_id\":\"00065a1d-7fa1-1718-0000-001200000020\",\"order_source\":\"orderbook\"}","recorded_unix_us":1787932602125572}
{"message":"{\"data\":{\"id\":2044303881940996,\"id_str\":\"2044303881940996\",\"order_type\":1,\"order_subtype\":5,\"datetime\":\"1787932602\",\"microtimestamp\":\"1787932602085000\",\"amount\":0.06367384,\"amount_str\":\"0.06367384\",\"amount_traded\":\"0\",\"amount_at_create\":\"0.06367384\",\"price\":78525.19,\"price_str\":\"78525.19\",\"is_liquidation\":false},\"channel\":\"live_orders_btcusd\",\"event\":\"order_created\",\"event_id\":\"00065a1d-7fa1-2e88-0001-000103000020\",\"pre_event_id\":\"00065a1d-7fa1-2e88-0000-000102000020\",\"order_source\":\"orderbook\"}","recorded_unix_us":1787932602125607}
{"message":"{\"data\":{\"id\":2044303881945090,\"id_str\":\"2044303881945090\",\"order_type\":1,\"order_subtype\":5,\"datetime\":\"1787932602\",\"microtimestamp\":\"1787932602085000\",\"amount\":0.043646,\"amount_str\":\"0.043646\",\"amount_traded\":\"0\",\"amount_at_create\":\"0.043646\",\"price\":2480.89,\"price_str\":\"2480.89\",\"is_liquidation\":false},\"channel\":\"live_orders_ethusd\",\"event\":\"order_created\",\"event_id\":\"00065a1d-7fa1-2e88-0001-001202000020\",\"pre_event_id\":\"00065a1d-7fa1-2e88-0000-001201000020\",\"order_source\":\"orderbook\"}","recorded_unix_us":1787932602125631}
{"message":"{\"data\":{\"id\":2044303881945092,\"id_str\":\"2044303881945092\",\"order_type\":1,\"order_subtype\":5,\"datetime\":\"1787932602\",\"microtimestamp\":\"1787932602085000\",\"amount\":0.06367563,\"amount_str\":\"0.06367563\",\"amount_traded\":\"0\",\"amount_at_create\":\"0.06367563\",\"price\":78522.98,\"price_str\":\"78522.98\",\"is_liquidation\":false},\"channel\":\"live_orders_btcusd\",\"event\":\"order_created\",\"event_id\":\"00065a1d-7fa1-2e88-0002-000100000020\",\"pre_event_id\":\"00065a1d-7fa1-2e88-0001-000103000020\",\"order_source\":\"orderbook\"}","recorded_unix_us":1787932602125707}
{"message":"{\"data\":{\"id\":2044303881949184,\"id_str\":\"2044303881949184\",\"order_type\":1,\"order_subtype\":5,\"datetime\":\"1787932602\",\"microtimestamp\":\"1787932602086000\",\"amount\":0.63679275,\"amount_str\":\"0.63679275\",\"amount_traded\":\"0\",\"amount_at_create\":\"0.63679275\",\"price\":78522.64,\"price_str\":\"78522.64\",\"is_liquidation\":false},\"channel\":\"live_orders_btcusd\",\"event\":\"order_created\",\"event_id\":\"00065a1d-7fa1-3270-0000-000101000020\",\"pre_event_id\":\"00065a1d-7fa1-2e88-0002-000100000020\",\"order_source\":\"orderbook\"}","recorded_unix_us":1787932602125790}
{"message":"{\"data\":{\"id\":2044303881949185,\"id_str\":\"2044303881949185\",\"order_type\":1,\"order_subtype\":5,\"datetime\":\"1787932602\",\"microtimestamp\":\"1787932602086000\",\"amount\":0.19103782,\"amount_str\":\"0.19103782\",\"amount_traded\":\"0\",\"amount_at_create\":\"0.19103782\",\"price\":78522.64,\"price_str\":\"78522.64\",\"is_liquidation\":false},\"channel\":\"live_orders_btcusd\",\"event\":\"order_created\",\"event_id\":\"00065a1d-7fa1-3270-0001-000102000020\",\"pre_event_id\":\"00065a1d-7fa1-3270-0000-000101000020\",\"order_source\":\"orderbook\"}","recorded_unix_us":1787932602125862}
{"message":"{\"data\":{\"id\":2044303880323082,\"id_str\":\"2044303880323082\",\"order_type\":0,\"order_subtype\":5,\"datetime\":\"1787932602\",\"microtimestamp\":\"1787932602086000\",\"amount\":0.403104,\"amount_str\":\"0.403104\",\"amount_traded\":\"0\",\"amount_at_create\":\"0.403104\",\"price\":2480.15,\"price_str\":\"2480.15\",\"is_liquidation\":false},\"channel\":\"live_orders_ethusd\",\"event\":\"order_deleted\",\"event_id\":\"00065a1d-7fa1-3270-0000-001203000020\",\"pre_event_id\":\"00065a1d-7fa1-2e88-0001-001202000020\",\"order_source\":\"orderbook\"}","recorded_unix_us":1787932602125931}
{"message":"{\"data\":{\"id\":2044303881949188,\"id_str\":\"2044303881949188\",\"order_type\":1,\"order_subtype\":5,\"datetime\":\"1787932602\",\"microtimestamp\":\"1787932602087000\",\"amount\":0.25467128,\"amount_str\":\"0.25467128\",\"amount_traded\":\"0\",\"amount_at_create\":\"0.25467128\",\"price\":78532.61,\"price_str\":\"78532.61\",\"is_liquidation\":false},\"channel\":\"live_orders_btcusd\",\"event\":\"order_created\",\"event_id\":\"00065a1d-7fa1-3658-0000-000103000020\",\"pre_event_id\":\"00065a1d-7fa1-3270-0001-000102000020\",\"order_source\":\"orderbook\"}","recorded_unix_us":1787932602126002}
{"message":"{\"data\":{\"id\":2044303881957376,\"id_str\":\"2044303881957376\",\"order_type\":1,\"order_subtype\":5,\"datetime\":\"1787932602\",\"microtimestamp\":\"1787932602088000\",\"amount\":0.25466146,\"amount_str\":\"0.25466146\",\"amount_traded\":\"0\",\"amount_at_create\":\"0.25466146\",\"price\":78535.64,\"price_str\":\"78535.64\",\"is_liquidation\":false},\"channel\":\"live_orders_btcusd\",\"event\":\"order_created\",\"event_id\":\"00065a1d-7fa1-3a40-0000-000100000020\",\"pre_event_id\":\"00065a1d-7fa1-3658-0000-000103000020\",\"order_source\":\"orderbook\"}","recorded_unix_us":1787932602126070}
{"message":"{\"data\":{\"id\":2044303881957380,\"id_str\":\"2044303881957380\",\"order_type\":1,\"order_subtype\":5,\"datetime\":\"1787932602\",\"microtimestamp\":\"1787932602089000\",\"amount\":1.26970017,\"amount_str\":\"1.26970017\",\"amount_traded\":\"0\",\"amount_at_create\":\"1.26970017\",\"price\":78758.76,\"price_str\":\"78758.76\",\"is_liquidation\":false},\"channel\":\"live_orders_btcusd\",\"event\":\"order_created\",\"event_id\":\"00065a1d-7fa1-3e28-0000-000101000020\",\"pre_event_id\":\"00065a1d-7fa1-3a40-0000-000100000020\",\"order_source\":\"orderbook\"}","recorded_unix_us":1787932602126219}
{"message":"{\"data\":{\"id\":2044303881957382,\"id_str\":\"2044303881957382\",\"order_type\":1,\"order_subtype\":5,\"datetime\":\"1787932602\",\"microtimestamp\":\"1787932602089000\",\"amount\":1.27209222,\"amount_str\":\"1.27209222\",\"amount_traded\":\"0\",\"amount_at_create\":\"1.27209222\",\"price\":78610.66,\"price_str\":\"78610.66\",\"is_liquidation\":false},\"channel\":\"live_orders_btcusd\",\"event\":\"order_created\",\"event_id\":\"00065a1d-7fa1-3e28-0001-000102000020\",\"pre_event_id\":\"00065a1d-7fa1-3e28-0000-000101000020\",\"order_source\":\"orderbook\"}","recorded_unix_us":1787932602126244}
{"message":"{\"data\":{\"id\":2044303881961472,\"id_str\":\"2044303881961472\",\"order_type\":0,\"order_subtype\":5,\"datetime\":\"1787932602\",\"microtimestamp\":\"1787932602089000\",\"amount\":0.562275,\"amount_str\":\"0.562275\",\"amount_traded\":\"0\",\"amount_at_create\":\"0.562275\",\"price\":2480.16,\"price_str\":\"2480.16\",\"is_liquidation\":false},\"channel\":\"live_orders_ethusd\",\"event\":\"order_created\",\"event_id\":\"00065a1d-7fa1-3e28-0000-001200000020\",\"pre_event_id\":\"00065a1d-7fa1-3270-0000-001203000020\",\"order_source\":\"orderbook\"}","recorded_unix_us":1787932602126266}
{"message":"{\"data\":{\"id\":2044303881961473,\"id_str\":\"2044303881961473\",\"order_type\":1,\"order_subtype\":5,\"datetime\":\"1787932602\",\"microtimestamp\":\"1787932602089000\",\"amount\":12.70451953,\"amount_str\":\"12.70451953\",\"amount_traded\":\"0\",\"amount_at_create\":\"12.70451953\",\"price\":78712.15,\"price_str\":\"78712.15\",\"is_liquidation\":false},\"channel\":\"live_orders_btcusd\",\"event\":\"order_created\",\"event_id\":\"00065a1d-7fa1-3e28-0002-000103000020\",\"pre_event_id\":\"00065a1d-7fa1-3e28-0001-000102000020\",\"order_source\":\"orderbook\"}","recorded_unix_us":1787932602126290}
{"message":"{\"data\":{\"id\":2044303881965574,\"id_str\":\"2044303881965574\",\"order_type\":1,\"order_subtype\":5,\"datetime\":\"1787932602\",\"microtimestamp\":\"1787932602091000\",\"amount\":0.1,\"amount_str\":\"0.10000000\",\"amount_traded\":\"0\",\"amount_at_create\":\"0.10000000\",\"price\":78522.63,\"price_str\":\"78522.63\",\"is_liquidation\":false},\"channel\":\"live_orders_btcusd\",\"event\":\"order_created\",\"event_id\":\"00065a1d-7fa1-45f8-0000-000100000020\",\"pre_event_id\":\"00065a1d-7fa1-3e28-0002-000103000020\",\"order_source\":\"orderbook\"}","recorded_unix_us":1787932602126383}
{"message":"{\"data\":{\"id\":2044303881965574,\"id_str\":\"2044303881965574\",\"order_type\":1,\"order_subtype\":5,\"datetime\":\"1787932602\",\"microtimestamp\":\"1787932602091000\",\"amount\":0.1,\"amount_str\":\"0.10000000\",\"amount_traded\":\"0\",\"amount_at_create\":\"0.10000000\",\"price\":78522.63,\"price_str\":\"78522.63\",\"is_liquidation\":false},\"channel\":\"live_orders_btcusd\",\"event\":\"order_deleted\",\"event_id\":\"00065a1d-7fa1-45f8-0001-000101000020\",\"pre_event_id\":\"00065a1d-7fa1-45f8-0000-000100000020\",\"order_source\":\"orderbook\"}","recorded_unix_us":1787932602126406}
{"message":"{\"data\":{\"id\":2044303881973764,\"id_str\":\"2044303881973764\",\"order_type\":0,\"order_subtype\":5,\"datetime\":\"1787932602\",\"microtimestamp\":\"1787932602092000\",\"amount\":0.403088,\"amount_str\":\"0.403088\",\"amount_traded\":\"0\",\"amount_at_create\":\"0.403088\",\"price\":2480.1,\"price_str\":\"2480.10\",\"is_liquidation\":false},\"channel\":\"live_orders_ethusd\",\"event\":\"order_created\",\"event_id\":\"00065a1d-7fa1-49e0-0000-001201000020\",\"pre_event_id\":\"00065a1d-7fa1-3e28-0000-001200000020\",\"order_source\":\"orderbook\"}","recorded_unix_us":1787932602154101}
{"message":"{\"data\":{\"id\":2044303881973767,\"id_str\":\"2044303881973767\",\"order_type\":1,\"order_subtype\":5,\"datetime\":\"1787932602\",\"microtimestamp\":\"1787932602093000\",\"amount\":1.2684012,\"amount_str\":\"1.26840120\",\"amount_traded\":\"0\",\"amount_at_create\":\"1.26840120\",\"price\":78839.41,\"price_str\":\"78839.41\",\"is_liquidation\":false},\"channel\":\"live_orders_btcusd\",\"event\":\"order_created\",\"event_id\":\"00065a1d-7fa1-4dc8-0000-000102000020\",\"pre_event_id\":\"00065a1d-7fa1-45f8-0001-000101000020\",\"order_source\":\"orderbook\"}","recorded_unix_us":1787932602154477}
{"message":"{\"data\":{\"id\":2044303881736196,\"id_str\":\"2044303881736196\",\"order_type\":0,\"order_subtype\":5,\"datetime\":\"1787932602\",\"microtimestamp\":\"1787932602094000\",\"amount\":0.19103754,\"amount_str\":\"0.19103754\",\"amount_traded\":\"0\",\"amount_at_create\":\"0.19103754\",\"price\":78486.13,\"price_str\":\"78486.13\",\"is_liquidation\":false},\"channel\":\"live_orders_btcusd\",\"event\":\"order_deleted\",\"event_id\":\"00065a1d-7fa1-51b0-0000-000103000020\",\"pre_event_id\":\"00065a1d-7fa1-4dc8-0000-000102000020\",\"order_source\":\"orderbook\"}","recorded_unix_us":1787932602154541}
{"message":"{\"data\":{\"id\":2044303881744391,\"id_str\":\"2044303881744391\",\"order_type\":0,\"order_subtype\":5,\"datetime\":\"1787932602\",\"microtimestamp\":\"1787932602094000\",\"amount\":0.6367918,\"amount_str\":\"0.63679180\",\"amount_traded\":\"0\",\"amount_at_create\":\"0.63679180\",\"price\":78484.17,\"price_str\":\"78484.17\",\"is_liquidation\":false},\"channel\":\"live_orders_btcusd\",\"event\":\"order_deleted\",\"event_id\":\"00065a1d-7fa1-51b0-0001-000100000020\",\"pre_event_id\":\"00065a1d-7fa1-51b0-0000-000103000020\",\"order_source\":\"orderbook\"}","recorded_unix_us":1787932602154700}
{"message":"{\"data\":{\"id\":2044303881744388,\"id_str\":\"2044303881744388\",\"order_type\":0,\"order_subtype\":5,\"datetime\":\"1787932602\",\"microtimestamp\":\"1787932602095000\",\"amount\":0.50943344,\"amount_str\":\"0.50943344\",\"amount_traded\":\"0\",\"amount_at_create\":\"0.50943344\",\"price\":78482.2,\"price_str\":\"78482.20\",\"is_liquidation\":false},\"channel\":\"live_orders_btcusd\",\"event\":\"order_deleted\",\"event_id\":\"00065a1d-7fa1-5598-0000-000101000020\",\"pre_event_id\":\"00065a1d-7fa1-51b0-0001-000100000020\",\"order_source\":\"orderbook\"}","recorded_unix_us":1787932602154738}
{"message":"{\"data\":{\"id\":2044303881986050,\"id_str\":\"2044303881986050\",\"order_type\":0,\"order_subtype\":5,\"datetime\":\"1787932602\",\"microtimestamp\":\"1787932602095000\",\"amount\":0.06367953,\"amount_str\":\"0.06367953\",\"amount_traded\":\"0\",\"amount_at_create\":\"0.06367953\",\"price\":78518.15,\"price_str\":\"78518.15\",\"is_liquidation\":false},\"channel\":\"live_orders_btcusd\",\"event\":\"order_created\",\"event_id\":\"00065a1d-7fa1-5598-0001-000102000020\",\"pre_event_id\":\"00065a1d-7fa1-5598-0000-000101000020\",\"order_source\":\"orderbook\"}","recorded_unix_us":1787932602154766}
{"message":"{\"data\":{\"id\":2044303881986057,\"id_str\":\"2044303881986057\",\"order_type\":0,\"order_subtype\":5,\"datetime\":\"1787932602\",\"microtimestamp\":\"1787932602095000\",\"amount\":0.25476924,\"amount_str\":\"0.25476924\",\"amount_traded\":\"0\",\"amount_at_create\":\"0.25476924\",\"price\":78502.41,\"price_str\":\"78502.41\",\"is_liquidation\":false},\"channel\":\"live_orders_btcusd\",\"event\":\"order_created\",\"event_id\":\"00065a1d-7fa1-5598-0002-000103000020\",\"pre_event_id\":\"00065a1d-7fa1-5598-0001-000102000020\",\"order_source\":\"orderbook\"}","recorded_unix_us":1787932602154897}
{"message":"{\"data\":{\"id\":2044303881990146,\"id_str\":\"2044303881990146\",\"order_type\":0,\"order_subtype\":5,\"datetime\":\"1787932602\",\"microtimestamp\":\"1787932602096000\",\"amount\":0.25478772,\"amount_str\":\"0.25478772\",\"amount_traded\":\"0\",\"amount_at_create\":\"0.25478772\",\"price\":78496.71,\"price_str\":\"78496.71\",\"is_liquidation\":false},\"channel\":\"live_orders_btcusd\",\"event\":\"order_created\",\"event_id\":\"00065a1d-7fa1-5980-0000-000100000020\",\"pre_event_id\":\"00065a1d-7fa1-5598-0002-000103000020\",\"order_source\":\"orderbook\"}","recorded_unix_us":1787932602155058}
{"message":"{\"data\":{\"id\":2044303882002434,\"id_str\":\"2044303882002434\",\"order_type\":0,\"order_subtype\":5,\"datetime\":\"1787932602\",\"microtimestamp\":\"1787932602099000\",\"amount\":1.27507828,\"amount_str\":\"1.27507828\",\"amount_traded\":\"0\",\"amount_at_create\":\"1.27507828\",\"price\":78426.55,\"price_str\":\"78426.55\",\"is_liquidation\":false},\"channel\":\"live_orders_btcusd\",\"event\":\"order_created\",\"event_id\":\"00065a1d-7fa1-6538-0000-000101000020\",\"pre_event_id\":\"00065a1d-7fa1-5980-0000-000100000020\",\"order_source\":\"orderbook\"}","recorded_unix_us":1787932602155233}
{"message":"{\"data\":{\"id\":2044303881961472,\"id_str\":\"2044303881961472\",\"order_type\":0,\"order_subtype\":5,\"datetime\":\"1787932602\",\"microtimestamp\":\"1787932602100000\",\"amount\":0.562275,\"amount_str\":\"0.562275\",\"amount_traded\":\"0\",\"amount_at_create\":\"0.562275\",\"price\":2480.16,\"price_str\":\"2480.16\",\"is_liquidation\":false},\"channel\":\"live_orders_ethusd\",\"event\":\"order_deleted\",\"event_id\":\"00065a1d-7fa1-6920-0000-001202000020\",\"pre_event_id\":\"00065a1d-7fa1-49e0-0000-001201000020\",\"order_source\":\"orderbook\"}","recorded_unix_us":1787932602155289}
{"message":"{\"data\":{\"id\":2044303882014723,\"id_str\":\"2044303882014723\",\"order_type\":0,\"order_subtype\":5,\"datetime\":\"1787932602\",\"microtimestamp\":\"1787932602102000\",\"amount\":1.27541152,\"amount_str\":\"1.27541152\",\"amount_traded\":\"0\",\"amount_at_create\":\"1.27541152\",\"price\":78406.06,\"price_str\":\"78406.06\",\"is_liquidation\":false},\"channel\":\"live_orders_btcusd\",\"event\":\"order_created\",\"event_id\":\"00065a1d-7fa1-70f0-0000-000102000020\",\"pre_event_id\":\"00065a1d-7fa1-6538-0000-000101000020\",\"order_source\":\"orderbook\"}","recorded_unix_us":1787932602155435}
{"message":"{\"data\":{\"id\":2044303882014724,\"id_str\":\"2044303882014724\",\"order_type\":0,\"order_subtype\":5,\"datetime\":\"1787932602\",\"microtimestamp\":\"1787932602103000\",\"amount\":12.76418733,\"amount_str\":\"12.76418733\",\"amount_traded\":\"0\",\"amount_at_create\":\"12.76418733\",\"price\":78344.19,\"price_str\":\"78344.19\",\"is_liquidation\":false},\"channel\":\"live_orders_btcusd\",\"event\":\"order_created\",\"event_id\":\"00065a1d-7fa1-74d8-0000-000103000020\",\"pre_event_id\":\"00065a1d-7fa1-70f0-0000-000102000020\",\"order_source\":\"orderbook\"}","recorded_unix_us":1787932602155471}
{"message":"{\"data\":{\"id\":2044303882018821,\"id_str\":\"2044303882018821\",\"order_type\":0,\"order_subtype\":5,\"datetime\":\"1787932602\",\"microtimestamp\":\"1787932602104000\",\"amount\":1.27567513,\"amount_str\":\"1.27567513\",\"amount_traded\":\"0\",\"amount_at_create\":\"1.27567513\",\"price\":78389.86,\"price_str\":\"78389.86\",\"is_liquidation\":false},\"channel\":\"live_orders_btcusd\",\"event\":\"order_created\",\"event_id\":\"00065a1d-7fa1-78c0-0000-000100000020\",\"pre_event_id\":\"00065a1d-7fa1-74d8-0000-000103000020\",\"order_source\":\"orderbook\"}","recorded_unix_us":1787932602155566}
{"message":"{\"data\":{\"id\":2044303882027014,\"id_str\":\"2044303882027014\",\"order_type\":1,\"order_subtype\":5,\"datetime\":\"1787932602\",\"microtimestamp\":\"1787932602106000\",\"amount\":0.06310787,\"amount_str\":\"0.06310787\",\"amount_traded\":\"0\",\"amount_at_create\":\"0.06310787\",\"price\":78520.73,\"price_str\":\"78520.73\",\"is_liquidation\":false},\"channel\":\"live_orders_btcusd\",\"event\":\"order_created\",\"event_id\":\"00065a1d-7fa1-8090-0000-000101000020\",\"pre_event_id\":\"00065a1d-7fa1-78c0-0000-000100000020\",\"order_source\":\"orderbook\"}","recorded_unix_us":1787932602155675}
{"message":"{\"data\":{\"id\":2044303882027014,\"id_str\":\"2044303882027014\",\"order_type\":1,\"order_subtype\":5,\"datetime\":\"1787932602\",\"microtimestamp\":\"1787932602106000\",\"amount\":0.06310787,\"amount_str\":\"0.06310787\",\"amount_traded\":\"0\",\"amount_at_create\":\"0.06310787\",\"price\":78520.73,\"price_str\":\"78520.73\",\"is_liquidation\":false},\"channel\":\"live_orders_btcusd\",\"event\":\"order_deleted\",\"event_id\":\"00065a1d-7fa1-8090-0001-000102000020\",\"pre_event_id\":\"00065a1d-7fa1-8090-0000-000101000020\",\"order_source\":\"orderbook\"}","recorded_unix_us":1787932602155762}
{"message":"{\"data\":{\"id\":2044303882031107,\"id_str\":\"2044303882031107\",\"order_type\":0,\"order_subtype\":5,\"datetime\":\"1787932602\",\"microtimestamp\":\"1787932602107000\",\"amount\":0.19104003,\"amount_str\":\"0.19104003\",\"amount_traded\":\"0\",\"amount_at_create\":\"0.19104003\",\"price\":78485.62,\"price_str\":\"78485.62\",\"is_liquidation\":false},\"channel\":\"live_orders_btcusd\",\"event\":\"order_created\",\"event_id\":\"00065a1d-7fa1-8478-0000-000103000020\",\"pre_event_id\":\"00065a1d-7fa1-8090-0001-000102000020\",\"order_source\":\"orderbook\"}","recorded_unix_us":1787932602155854}
{"message":"{\"data\":{\"id\":2044303881793543,\"id_str\":\"2044303881793543\",\"order_type\":0,\"order_subtype\":5,\"datetime\":\"1787932602\",\"microtimestamp\":\"1787932602107000\",\"amount\":0.40309,\"amount_str\":\"0.403090\",\"amount_traded\":\"0\",\"amount_at_create\":\"0.403090\",\"price\":2480.01,\"price_str\":\"2480.01\",\"is_liquidation\":false},\"channel\":\"live_orders_ethusd\",\"event\":\"order_deleted\",\"event_id\":\"00065a1d-7fa1-8478-0000-001203000020\",\"pre_event_id\":\"00065a1d-7fa1-6920-0000-001202000020\",\"order_source\":\"orderbook\"}","recorded_unix_us":1787932602155968}
{"message":"{\"data\":{\"id\":2044303882035207,\"id_str\":\"2044303882035207\",\"order_type\":0,\"order_subtype\":5,\"datetime\":\"1787932602\",\"microtimestamp\":\"1787932602107000\",\"amount\":1.27757154,\"amount_str\":\"1.27757154\",\"amount_traded\":\"0\",\"amount_at_create\":\"1.27757154\",\"price\":78273.5,\"price_str\":\"78273.50\",\"is_liquidation\":false},\"channel\":\"live_orders_btcusd\",\"event\":\"order_created\",\"event_id\":\"00065a1d-7fa1-8478-0001-000100000020\",\"pre_event_id\":\"00065a1d-7fa1-8478-0000-000103000020\",\"order_source\":\"orderbook\"}","recorded_unix_us":1787932602155999}
{"message":"{\"data\":{\"id\":2044303882035211,\"id_str\":\"2044303882035211\",\"order_type\":1,\"order_subtype\":5,\"datetime\":\"1787932602\",\"microtimestamp\":\"1787932602108000\",\"amount\":0.1,\"amount_str\":\"0.10000000\",\"amount_traded\":\"0\",\"amount_at_create\":\"0.10000000\",\"price\":78522.62,\"price_str\":\"78522.62\",\"is_liquidation\":false},\"channel\":\"live_orders_btcusd\",\"event\":\"order_created\",\"event_id\":\"00065a1d-7fa1-8860-0000-000101000020\",\"pre_event_id\":\"00065a1d-7fa1-8478-0001-000100000020\",\"order_source\":\"orderbook\"}","recorded_unix_us":1787932602156114}
{"message":"{\"data\":{\"id\":2044303882035211,\"id_str\":\"2044303882035211\",\"order_type\":1,\"order_subtype\":5,\"datetime\":\"1787932602\",\"microtimestamp\":\"1787932602108000\",\"amount\":0.1,\"amount_str\":\"0.10000000\",\"amount_traded\":\"0\",\"amount_at_create\":\"0.10000000\",\"price\":78522.62,\"price_str\":\"78522.62\",\"is_liquidation\":false},\"channel\":\"live_orders_btcusd\",\"event\":\"order_deleted\",\"event_id\":\"00065a1d-7fa1-8860-0001-000102000020\",\"pre_event_id\":\"00065a1d-7fa1-8860-0000-000101000020\",\"order_source\":\"orderbook\"}","recorded_unix_us":1787932602156143}
{"message":"{\"data\":{\"id\":2044303882039300,\"id_str\":\"2044303882039300\",\"order_type\":0,\"order_subtype\":5,\"datetime\":\"1787932602\",\"microtimestamp\":\"1787932602108000\",\"amount\":0.63680011,\"amount_str\":\"0.63680011\",\"amount_traded\":\"0\",\"amount_at_create\":\"0.63680011\",\"price\":78483.66,\"price_str\":\"78483.66\",\"is_liquidation\":false},\"channel\":\"live_orders_btcusd\",\"event\":\"order_created\",\"event_id\":\"00065a1d-7fa1-8860-0002-000103000020\",\"pre_event_id\":\"00065a1d-7fa1-8860-0001-000102000020\",\"order_source\":\"orderbook\"}","recorded_unix_us":1787932602156221}
{"message":"{\"data\":{\"id\":2044303882039302,\"id_str\":\"2044303882039302\",\"order_type\":0,\"order_subtype\":5,\"datetime\":\"1787932602\",\"microtimestamp\":\"1787932602109000\",\"amount\":0.50944009,\"amount_str\":\"0.50944009\",\"amount_traded\":\"0\",\"amount_at_create\":\"0.50944009\",\"price\":78481.69,\"price_str\":\"78481.69\",\"is_liquidation\":false},\"channel\":\"live_orders_btcusd\",\"event\":\"order_created\",\"event_id\":\"00065a1d-7fa1-8c48-0000-000100000020\",\"pre_event_id\":\"00065a1d-7fa1-8860-0002-000103000020\",\"order_source\":\"orderbook\"}","recorded_unix_us":1787932602156302}
{"message":"{\"data\":{\"id\":2044303882043392,\"id_str\":\"2044303882043392\",\"order_type\":0,\"order_subtype\":5,\"datetime\":\"1787932602\",\"microtimestamp\":\"1787932602109000\",\"amount\":0.546944,\"amount_str\":\"0.546944\",\"amount_traded\":\"0\",\"amount_at_create\":\"0.546944\",\"price\":2480.1,\"price_str\":\"2480.10\",\"is_liquidation\":false},\"channel\":\"live_orders_ethusd\",\"event\":\"order_created\",\"event_id\":\"00065a1d-7fa1-8c48-0000-001200000020\",\"pre_event_id\":\"00065a1d-7fa1-8478-0000-001203000020\",\"order_source\":\"orderbook\"}","recorded_unix_us":1787932602156380}
{"message":"{\"data\":{\"id\":2044303882072069,\"id_str\":\"2044303882072069\",\"order_type\":0,\"order_subtype\":5,\"datetime\":\"1787932602\",\"microtimestamp\":\"1787932602116000\",\"amount\":0.403091,\"amount_str\":\"0.403091\",\"amount_traded\":\"0\",\"amount_at_create\":\"0.403091\",\"price\":2479.96,\"price_str\":\"2479.96\",\"is_liquidation\":false},\"channel\":\"live_orders_ethusd\",\"event\":\"order_created\",\"event_id\":\"00065a1d-7fa1-a7a0-0000-001201000020\",\"pre_event_id\":\"00065a1d-7fa1-8c48-0000-001200000020\",\"order_source\":\"orderbook\"}","recorded_unix_us":1787932602156465}
{"message":"{\"data\":{\"id\":2044303882088448,\"id_str\":\"2044303882088448\",\"order_type\":1,\"order_subtype\":5,\"datetime\":\"1787932602\",\"microtimestamp\":\"1787932602120000\",\"amount\":0.0372,\"amount_str\":\"0.03720000\",\"amount_traded\":\"0\",\"amount_at_create\":\"0.03720000\",\"price\":0.0316289,\"price_str\":\"0.03162890\",\"is_liquidation\":false},\"channel\":\"live_orders_ethbtc\",\"event\":\"order_created\",\"event_id\":\"00065a1d-7fa1-b740-0000-001101000020\",\"pre_event_id\":\"00065a1d-7fa0-d898-0000-001100000020\",\"order_source\":\"orderbook\"}","recorded_unix_us":1787932602156590}
{"message":"{\"data\":{\"id\":2044303882043392,\"id_str\":\"2044303882043392\",\"order_type\":0,\"order_subtype\":5,\"datetime\":\"1787932602\",\"microtimestamp\":\"1787932602121000\",\"amount\":0.546944,\"amount_str\":\"0.546944\",\"amount_traded\":\"0\",\"amount_at_create\":\"0.546944\",\"price\":2480.1,\"price_str\":\"2480.10\",\"is_liquidation\":false},\"channel\":\"live_orders_ethusd\",\"event\":\"order_deleted\",\"event_id\":\"00065a1d-7fa1-bb28-0000-001202000020\",\"pre_event_id\":\"00065a1d-7fa1-a7a0-0000-001201000020\",\"order_source\":\"orderbook\"}","recorded_unix_us":1787932602163356}
{"message":"{\"data\":{\"id\":2044303882096644,\"id_str\":\"2044303882096644\",\"order_type\":1,\"order_subtype\":5,\"datetime\":\"1787932602\",\"microtimestamp\":\"1787932602123000\",\"amount\":1.271772,\"amount_str\":\"1.27177200\",\"amount_traded\":\"0\",\"amount_at_create\":\"1.27177200\",\"price\":78630.45,\"price_str\":\"78630.45\",\"is_liquidation\":false},\"channel\":\"live_orders_btcusd\",\"event\":\"order_created\",\"event_id\":\"00065a1d-7fa1-c2f8-0000-000101000020\",\"pre_event_id\":\"00065a1d-7fa1-8c48-0000-000100000020\",\"order_source\":\"orderbook\"}","recorded_unix_us":1787932602163491}
{"message":"{\"data\":{\"id\":2044303882104836,\"id_str\":\"2044303882104836\",\"order_type\":1,\"order_subtype\":5,\"datetime\":\"1787932602\",\"microtimestamp\":\"1787932602124000\",\"amount\":0.1,\"amount_str\":\"0.10000000\",\"amount_traded\":\"0\",\"amount_at_create\":\"0.10000000\",\"price\":78522.63,\"price_str\":\"78522.63\",\"is_liquidation\":false},\"channel\":\"live_orders_btcusd\",\"event\":\"order_created\",\"event_id\":\"00065a1d-7fa1-c6e0-0000-000102000020\",\"pre_event_id\":\"00065a1d-7fa1-c2f8-0000-000101000020\",\"order_source\":\"orderbook\"}","recorded_unix_us":1787932602167112}
{"message":"{\"data\":{\"id\":2044303882104836,\"id_str\":\"2044303882104836\",\"order_type\":1,\"order_subtype\":5,\"datetime\":\"1787932602\",\"microtimestamp\":\"1787932602124000\",\"amount\":0.1,\"amount_str\":\"0.10000000\",\"amount_traded\":\"0\",\"amount_at_create\":\"0.10000000\",\"price\":78522.63,\"price_str\":\"78522.63\",\"is_liquidation\":false},\"channel\":\"live_orders_btcusd\",\"event\":\"order_deleted\",\"event_id\":\"00065a1d-7fa1-c6e0-0001-000103000020\",\"pre_event_id\":\"00065a1d-7fa1-c6e0-0000-000102000020\",\"order_source\":\"orderbook\"}","recorded_unix_us":1787932602167311}
{"message":"{\"data\":{\"id\":2044303882104841,\"id_str\":\"2044303882104841\",\"order_type\":0,\"order_subtype\":5,\"datetime\":\"1787932602\",\"microtimestamp\":\"1787932602125000\",\"amount\":1.27604867,\"amount_str\":\"1.27604867\",\"amount_traded\":\"0\",\"amount_at_create\":\"1.27604867\",\"price\":78366.91,\"price_str\":\"78366.91\",\"is_liquidation\":false},\"channel\":\"live_orders_btcusd\",\"event\":\"order_created\",\"event_id\":\"00065a1d-7fa1-cac8-0000-000100000020\",\"pre_event_id\":\"00065a1d-7fa1-c6e0-0001-000103000020\",\"order_source\":\"orderbook\"}","recorded_unix_us":1787932602167374}
{"message":"{\"data\":{\"id\":2044303882108933,\"id_str\":\"2044303882108933\",\"order_type\":1,\"order_subtype\":5,\"datetime\":\"1787932602\",\"microtimestamp\":\"1787932602125000\",\"amount\":1.26842789,\"amount_str\":\"1.26842789\",\"amount_traded\":\"0\",\"amount_at_create\":\"1.26842789\",\"price\":78837.75,\"price_str\":\"78837.75\",\"is_liquidation\":false},\"channel\":\"live_orders_btcusd\",\"event\":\"order_created\",\"event_id\":\"00065a1d-7fa1-cac8-0001-000101000020\",\"pre_event_id\":\"00065a1d-7fa1-cac8-0000-000100000020\",\"order_source\":\"orderbook\"}","recorded_unix_us":1787932602173645}
{"message":"{\"data\":{\"id\":2044303881863168,\"id_str\":\"2044303881863168\",\"order_type\":0,\"order_subtype\":5,\"datetime\":\"1787932602\",\"microtimestamp\":\"1787932602126000\",\"amount\":0.00140266,\"amount_str\":\"0.00140266\",\"amount_traded\":\"0\",\"amount_at_create\":\"0.00140266\",\"price\":70666.76,\"price_str\":\"70666.76\",\"is_liquidation\":false},\"channel\":\"live_orders_btcusd\",\"event\":\"order_deleted\",\"event_id\":\"00065a1d-7fa1-ceb0-0000-000102000020\",\"pre_event_id\":\"00065a1d-7fa1-cac8-0001-000101000020\",\"order_source\":\"orderbook\"}","recorded_unix_us":1787932602173721}
{"message":"{\"data\":{\"id\":2044303882113034,\"id_str\":\"2044303882113034\",\"order_type\":0,\"order_subtype\":5,\"datetime\":\"1787932602\",\"microtimestamp\":\"1787932602127000\",\"amount\":0.06368171,\"amount_str\":\"0.06368171\",\"amount_traded\":\"0\",\"amount_at_create\":\"0.06368171\",\"price\":78515.46,\"price_str\":\"78515.46\",\"is_liquidation\":false},\"channel\":\"live_orders_btcusd\",\"event\":\"order_created\",\"event_id\":\"00065a1d-7fa1-d298-0000-000103000020\",\"pre_event_id\":\"00065a1d-7fa1-ceb0-0000-000102000020\",\"order_source\":\"orderbook\"}","recorded_unix_us":1787932602173837}
{"message":"{\"data\":{\"id\":2044303882117122,\"id_str\":\"2044303882117122\",\"order_type\":0,\"order_subtype\":5,\"datetime\":\"1787932602\",\"microtimestamp\":\"1787932602127000\",\"amount\":1.27817952,\"amount_str\":\"1.27817952\",\"amount_traded\":\"0\",\"amount_at_create\":\"1.27817952\",\"price\":78236.27,\"price_str\":\"78236.27\",\"is_liquidation\":false},\"channel\":\"live_orders_btcusd\",\"event\":\"order_created\",\"event_id\":\"00065a1d-7fa1-d298-0001-000100000020\",\"pre_event_id\":\"00065a1d-7fa1-d298-0000-000103000020\",\"order_source\":\"orderbook\"}","recorded_unix_us":1787932602173959}
{"message":"{\"data\":{\"id\":2044303882133515,\"id_str\":\"2044303882133515\",\"order_type\":0,\"order_subtype\":5,\"datetime\":\"1787932602\",\"microtimestamp\":\"1787932602132000\",\"amount\":0.481961,\"amount_str\":\"0.481961\",\"amount_traded\":\"0\",\"amount_at_create\":\"0.481961\",\"price\":2480.02,\"price_str\":\"2480.02\",\"is_liquidation\":false},\"channel\":\"live_orders_ethusd\",\"event\":\"order_created\",\"event_id\":\"00065a1d-7fa1-e620-0000-001203000020\",\"pre_event_id\":\"00065a1d-7fa1-bb28-0000-001202000020\",\"order_source\":\"orderbook\"}","recorded_unix_us":1787932602174082}
{"message":"{\"data\":{\"id\":2044303882149893,\"id_str\":\"2044303882149893\",\"order_type\":1,\"order_subtype\":5,\"datetime\":\"1787932602\",\"microtimestamp\":\"1787932602136000\",\"amount\":0.06310787,\"amount_str\":\"0.06310787\",\"amount_traded\":\"0\",\"amount_at_create\":\"0.06310787\",\"price\":78522.06,\"price_str\":\"78522.06\",\"is_liquidation\":false},\"channel\":\"live_orders_btcusd\",\"event\":\"order_created\",\"event_id\":\"00065a1d-7fa1-f5c0-0000-000101000020\",\"pre_event_id\":\"00065a1d-7fa1-d298-0001-000100000020\",\"order_source\":\"orderbook\"}","recorded_unix_us":1787932602179333}
{"message":"{\"data\":{\"id\":2044303882149893,\"id_str\":\"2044303882149893\",\"order_type\":1,\"order_subtype\":5,\"datetime\":\"1787932602\",\"microtimestamp\":\"1787932602136000\",\"amount\":0.06310787,\"amount_str\":\"0.06310787\",\"amount_traded\":\"0\",\"amount_at_create\":\"0.06310787\",\"price\":78522.06,\"price_str\":\"78522.06\",\"is_liquidation\":false},\"channel\":\"live_orders_btcusd\",\"event\":\"order_deleted\",\"event_id\":\"00065a1d-7fa1-f5c0-0001-000102000020\",\"pre_event_id\":\"00065a1d-7fa1-f5c0-0000-000101000020\",\"order_source\":\"orderbook\"}","recorded_unix_us":1787932602179404}
{"message":"{\"data\":{\"id\":2044303877349390,\"id_str\":\"2044303877349390\",\"order_type\":1,\"order_subtype\":5,\"datetime\":\"1787932602\",\"microtimestamp\":\"1787932602141000\",\"amount\":1,\"amount_str\":\"1.000000\",\"amount_traded\":\"0\",\"amount_at_create\":\"1.000000\",\"price\":2480.82,\"price_str\":\"2480.82\",\"is_liquidation\":false},\"channel\":\"live_orders_ethusd\",\"event\":\"order_deleted\",\"event_id\":\"00065a1d-7fa2-0948-0000-001200000020\",\"pre_event_id\":\"00065a1d-7fa1-e620-0000-001203000020\",\"order_source\":\"orderbook\"}","recorded_unix_us":1787932602179564}
{"message":"{\"data\":{\"id\":2044303882178560,\"id_str\":\"2044303882178560\",\"order_type\":1,\"order_subtype\":5,\"datetime\":\"1787932602\",\"microtimestamp\":\"1787932602142000\",\"amount\":1.27145262,\"amount_str\":\"1.27145262\",\"amount_traded\":\"0\",\"amount_at_create\":\"1.27145262\",\"price\":78650.2,\"price_str\":\"78650.20\",\"is_liquidation\":false},\"channel\":\"live_orders_btcusd\",\"event\":\"order_created\",\"event_id\":\"00065a1d-7fa2-0d30-0000-000103000020\",\"pre_event_id\":\"00065a1d-7fa1-f5c0-0001-000102000020\",\"order_source\":\"orderbook\"}","recorded_unix_us":1787932602179604}
{"message":"{\"data\":{\"id\":2044303882186762,\"id_str\":\"2044303882186762\",\"order_type\":0,\"order_subtype\":5,\"datetime\":\"1787932602\",\"microtimestamp\":\"1787932602144000\",\"amount\":1.27888333,\"amount_str\":\"1.27888333\",\"amount_traded\":\"0\",\"amount_at_create\":\"1.27888333\",\"price\":78193.21,\"price_str\":\"78193.21\",\"is_liquidation\":false},\"channel\":\"live_orders_btcusd\",\"event\":\"order_created\",\"event_id\":\"00065a1d-7fa2-1500-0000-000100000020\",\"pre_event_id\":\"00065a1d-7fa2-0d30-0000-000103000020\",\"order_source\":\"orderbook\"}","recorded_unix_us":1787932602179728}
{"message":"{\"data\":{\"id\":2044303882190850,\"id_str\":\"2044303882190850\",\"order_type\":0,\"order_subtype\":5,\"datetime\":\"1787932602\",\"microtimestamp\":\"1787932602145000\",\"amount\":0.00140266,\"amount_str\":\"0.00140266\",\"amount_traded\":\"0\",\"amount_at_create\":\"0.00140266\",\"price\":70668.36,\"price_str\":\"70668.36\",\"is_liquidation\":false},\"channel\":\"live_orders_btcusd\",\"event\":\"order_created\",\"event_id\":\"00065a1d-7fa2-18e8-0000-000101000020\",\"pre_event_id\":\"00065a1d-7fa2-1500-0000-000100000020\",\"order_source\":\"orderbook\"}","recorded_unix_us":1787932602179859}
{"message":"{\"data\":{\"id\":2044303881252867,\"id_str\":\"2044303881252867\",\"order_type\":1,\"order_subtype\":5,\"datetime\":\"1787932602\",\"microtimestamp\":\"1787932602146000\",\"amount\":12.087961,\"amount_str\":\"12.087961\",\"amount_traded\":\"0\",\"amount_at_create\":\"12.087961\",\"price\":2481.81,\"price_str\":\"2481.81\",\"is_liquidation\":false},\"channel\":\"live_orders_ethusd\",\"event\":\"order_deleted\",\"event_id\":\"00065a1d-7fa2-1cd0-0000-001201000020\",\"pre_event_id\":\"00065a1d-7fa2-0948-0000-001200000020\",\"order_source\":\"orderbook\"}","recorded_unix_us":1787932602180058}
{"message":"{\"data\":{\"id\":2044303881302021,\"id_str\":\"2044303881302021\",\"order_type\":0,\"order_subtype\":5,\"datetime\":\"1787932602\",\"microtimestamp\":\"1787932602147000\",\"amount\":12.096046,\"amount_str\":\"12.096046\",\"amount_traded\":\"0\",\"amount_at_create\":\"12.096046\",\"price\":2480.14,\"price_str\":\"2480.14\",\"is_liquidation\":false},\"channel\":\"live_orders_ethusd\",\"event\":\"order_deleted\",\"event_id\":\"00065a1d-7fa2-20b8-0000-001202000020\",\"pre_event_id\":\"00065a1d-7fa2-1cd0-0000-001201000020\",\"order_source\":\"orderbook\"}","recorded_unix_us":1787932602180094}
{"message":"{\"data\":{\"id\":2044303882199041,\"id_str\":\"2044303882199041\",\"order_type\":1,\"order_subtype\":5,\"datetime\":\"1787932602\",\"microtimestamp\":\"1787932602148000\",\"amount\":0.1,\"amount_str\":\"0.10000000\",\"amount_traded\":\"0\",\"amount_at_create\":\"0.10000000\",\"price\":78522.62,\"price_str\":\"78522.62\",\"is_liquidation\":false},\"channel\":\"live_orders_btcusd\",\"event\":\"order_created\",\"event_id\":\"00065a1d-7fa2-24a0-0000-000102000020\",\"pre_event_id\":\"00065a1d-7fa2-18e8-0000-000101000020\",\"order_source\":\"orderbook\"}","recorded_unix_us":1787932602180124}
{"message":"{\"data\":{\"id\":2044303882199041,\"id_str\":\"2044303882199041\",\"order_type\":1,\"order_subtype\":5,\"datetime\":\"1787932602\",\"microtimestamp\":\"1787932602148000\",\"amount\":0.1,\"amount_str\":\"0.10000000\",\"amount_traded\":\"0\",\"amount_at_create\":\"0.10000000\",\"price\":78522.62,\"price_str\":\"78522.62\",\"is_liquidation\":false},\"channel\":\"live_orders_btcusd\",\"event\":\"order_deleted\",\"event_id\":\"00065a1d-7fa2-24a0-0001-000103000020\",\"pre_event_id\":\"00065a1d-7fa2-24a0-0000-000102000020\",\"order_source\":\"orderbook\"}","recorded_unix_us":1787932602180319}
{"message":"{\"data\":{\"id\":2044303882133515,\"id_str\":\"2044303882133515\",\"order_type\":0,\"order_subtype\":5,\"datetime\":\"1787932602\",\"microtimestamp\":\"1787932602148000\",\"amount\":0.481961,\"amount_str\":\"0.481961\",\"amount_traded\":\"0\",\"amount_at_create\":\"0.481961\",\"price\":2480.02,\"price_str\":\"2480.02\",\"is_liquidation\":false},\"channel\":\"live_orders_ethusd\",\"event\":\"order_deleted\",\"event_id\":\"00065a1d-7fa2-24a0-0000-001203000020\",\"pre_event_id\":\"00065a1d-7fa2-20b8-0000-001202000020\",\"order_source\":\"orderbook\"}","recorded_unix_us":1787932602180376}
{"message":"{\"data\":{\"id\":2044303882072069,\"id_str\":\"2044303882072069\",\"order_type\":0,\"order_subtype\":5,\"datetime\":\"1787932602\",\"microtimestamp\":\"1787932602149000\",\"amount\":0.403091,\"amount_str\":\"0.403091\",\"amount_traded\":\"0\",\"amount_at_create\":\"0.403091\",\"price\":2479.96,\"price_str\":\"2479.96\",\"is_liquidation\":false},\"channel\":\"live_orders_ethusd\",\"event\":\"order_deleted\",\"event_id\":\"00065a1d-7fa2-2888-0000-001200000020\",\"pre_event_id\":\"00065a1d-7fa2-24a0-0000-001203000020\",\"order_source\":\"orderbook\"}","recorded_unix_us":1787932602180412}
{"message":"{\"data\":{\"id\":2044303882223618,\"id_str\":\"2044303882223618\",\"order_type\":0,\"order_subtype\":5,\"datetime\":\"1787932602\",\"microtimestamp\":\"1787932602154000\",\"amount\":0.080642,\"amount_str\":\"0.080642\",\"amount_traded\":\"0\",\"amount_at_create\":\"0.080642\",\"price\":2480.1,\"price_str\":\"2480.10\",\"is_liquidation\":false},\"channel\":\"live_orders_ethusd\",\"event\":\"order_created\",\"event_id\":\"00065a1d-7fa2-3c10-0000-001201000020\",\"pre_event_id\":\"00065a1d-7fa2-2888-0000-001200000020\",\"order_source\":\"orderbook\"}","recorded_unix_us":1787932602196525}
{"message":"{\"data\":{\"id\":2044303881240580,\"id_str\":\"2044303881240580\",\"order_type\":1,\"order_subtype\":5,\"datetime\":\"1787932602\",\"microtimestamp\":\"1787932602155000\",\"amount\":12.086599,\"amount_str\":\"12.086599\",\"amount_traded\":\"0\",\"amount_at_create\":\"12.086599\",\"price\":2482.09,\"price_str\":\"2482.09\",\"is_liquidation\":false},\"channel\":\"live_orders_ethusd\",\"event\":\"order_deleted\",\"event_id\":\"00065a1d-7fa2-3ff8-0000-001202000020\",\"pre_event_id\":\"00065a1d-7fa2-3c10-0000-001201000020\",\"order_source\":\"orderbook\"}","recorded_unix_us":1787932602196770}
{"message":"{\"data\":{\"id\":2044303876526081,\"id_str\":\"2044303876526081\",\"order_type\":0,\"order_subtype\":5,\"datetime\":\"1787932602\",\"microtimestamp\":\"1787932602155000\",\"amount\":2.542775,\"amount_str\":\"2.542775\",\"amount_traded\":\"0\",\"amount_at_create\":\"2.542775\",\"price\":2455.46,\"price_str\":\"2455.46\",\"is_liquidation\":false},\"channel\":\"live_orders_ethusd\",\"event\":\"order_deleted\",\"event_id\":\"00065a1d-7fa2-3ff8-0001-001203000020\",\"pre_event_id\":\"00065a1d-7fa2-3ff8-0000-001202000020\",\"order_source\":\"orderbook\"}","recorded_unix_us":1787932602196975}
{"message":"{\"data\":{\"id\":2044303881117697,\"id_str\":\"2044303881117697\",\"order_type\":0,\"order_subtype\":5,\"datetime\":\"1787932602\",\"microtimestamp\":\"1787932602156000\",\"amount\":4.034214,\"amount_str\":\"4.034214\",\"amount_traded\":\"0\",\"amount_at_create\":\"4.034214\",\"price\":2478.79,\"price_str\":\"2478.79\",\"is_liquidation\":false},\"channel\":\"live_orders_ethusd\",\"event\":\"order_deleted\",\"event_id\":\"00065a1d-7fa2-43e0-0000-001200000020\",\"pre_event_id\":\"00065a1d-7fa2-3ff8-0001-001203000020\",\"order_source\":\"orderbook\"}","recorded_unix_us":1787932602197023}
{"message":"{\"data\":{\"id\":2044303881322500,\"id_str\":\"2044303881322500\",\"order_type\":0,\"order_subtype\":5,\"datetime\":\"1787932602\",\"microtimestamp\":\"1787932602159000\",\"amount\":12.09718,\"amount_str\":\"12.097180\",\"amount_traded\":\"0\",\"amount_at_create\":\"12.097180\",\"price\":2479.91,\"price_str\":\"2479.91\",\"is_liquidation\":false},\"channel\":\"live_orders_ethusd\",\"event\":\"order_deleted\",\"event_id\":\"00065a1d-7fa2-4f98-0000-001201000020\",\"pre_event_id\":\"00065a1d-7fa2-43e0-0000-001200000020\",\"order_source\":\"orderbook\"}","recorded_unix_us":1787932602197187}
{"message":"{\"data\":{\"id\":2044303882248198,\"id_str\":\"2044303882248198\",\"order_type\":0,\"order_subtype\":5,\"datetime\":\"1787932602\",\"microtimestamp\":\"1787932602160000\",\"amount\":0.524518,\"amount_str\":\"0.524518\",\"amount_traded\":\"0\",\"amount_at_create\":\"0.524518\",\"price\":2480.1,\"price_str\":\"2480.10\",\"is_liquidation\":false},\"channel\":\"live_orders_ethusd\",\"event\":\"order_created\",\"event_id\":\"00065a1d-7fa2-5380-0000-001202000020\",\"pre_event_id\":\"00065a1d-7fa2-4f98-0000-001201000020\",\"order_source\":\"orderbook\"}","recorded_unix_us":1787932602197338}
{"message":"{\"data\":{\"id\":2044303882252297,\"id_str\":\"2044303882252297\",\"order_type\":0,\"order_subtype\":5,\"datetime\":\"1787932602\",\"microtimestamp\":\"1787932602161000\",\"amount\":0.403088,\"amount_str\":\"0.403088\",\"amount_traded\":\"0\",\"amount_at_create\":\"0.403088\",\"price\":2480.02,\"price_str\":\"2480.02\",\"is_liquidation\":false},\"channel\":\"live_orders_ethusd\",\"event\":\"order_created\",\"event_id\":\"00065a1d-7fa2-5768-0000-001203000020\",\"pre_event_id\":\"00065a1d-7fa2-5380-0000-001202000020\",\"order_source\":\"orderbook\"}","recorded_unix_us":1787932602197466}
{"message":"{\"data\":{\"id\":2044303882256389,\"id_str\":\"2044303882256389\",\"order_type\":1,\"order_subtype\":5,\"datetime\":\"1787932602\",\"microtimestamp\":\"1787932602162000\",\"amount\":0.1,\"amount_str\":\"0.10000000\",\"amount_traded\":\"0\",\"amount_at_create\":\"0.10000000\",\"price\":78522.63,\"price_str\":\"78522.63\",\"is_liquidation\":false},\"channel\":\"live_orders_btcusd\",\"event\":\"order_created\",\"event_id\":\"00065a1d-7fa2-5b50-0000-000100000020\",\"pre_event_id\":\"00065a1d-7fa2-24a0-0001-000103000020\",\"order_source\":\"orderbook\"}","recorded_unix_us":1787932602197589}
{"message":"{\"data\":{\"id\":2044303882256389,\"id_str\":\"2044303882256389\",\"order_type\":1,\"order_subtype\":5,\"datetime\":\"1787932602\",\"microtimestamp\":\"1787932602162000\",\"amount\":0.1,\"amount_str\":\"0.10000000\",\"amount_traded\":\"0\",\"amount_at_create\":\"0.10000000\",\"price\":78522.63,\"price_str\":\"78522.63\",\"is_liquidation\":false},\"channel\":\"live_orders_btcusd\",\"event\":\"order_deleted\",\"event_id\":\"00065a1d-7fa2-5b50-0001-000101000020\",\"pre_event_id\":\"00065a1d-7fa2-5b50-0000-000100000020\",\"order_source\":\"orderbook\"}","recorded_unix_us":1787932602197770}
{"message":"{\"data\":{\"id\":2044303882248198,\"id_str\":\"2044303882248198\",\"order_type\":0,\"order_subtype\":5,\"datetime\":\"1787932602\",\"microtimestamp\":\"1787932602163000\",\"amount\":0.524518,\"amount_str\":\"0.524518\",\"amount_traded\":\"0\",\"amount_at_create\":\"0.524518\",\"price\":2480.1,\"price_str\":\"2480.10\",\"is_liquidation\":false},\"channel\":\"live_orders_ethusd\",\"event\":\"order_deleted\",\"event_id\":\"00065a1d-7fa2-5f38-0000-001200000020\",\"pre_event_id\":\"00065a1d-7fa2-5768-0000-001203000020\",\"order_source\":\"orderbook\"}","recorded_unix_us":1787932602207105}
{"message":"{\"data\":{\"id\":2044303882268672,\"id_str\":\"2044303882268672\",\"order_type\":0,\"order_subtype\":5,\"datetime\":\"1787932602\",\"microtimestamp\":\"1787932602164000\",\"amount\":0.595025,\"amount_str\":\"0.595025\",\"amount_traded\":\"0\",\"amount_at_create\":\"0.595025\",\"price\":2480.16,\"price_str\":\"2480.16\",\"is_liquidation\":false},\"channel\":\"live_orders_ethusd\",\"event\":\"order_created\",\"event_id\":\"00065a1d-7fa2-6320-0000-001201000020\",\"pre_event_id\":\"00065a1d-7fa2-5f38-0000-001200000020\",\"order_source\":\"orderbook\"}","recorded_unix_us":1787932602207346}
{"message":"{\"data\":{\"id\":2044303882305543,\"id_str\":\"2044303882305543\",\"order_type\":1,\"order_subtype\":5,\"datetime\":\"1787932602\",\"microtimestamp\":\"1787932602174000\",\"amount\":0.06310787,\"amount_str\":\"0.06310787\",\"amount_traded\":\"0\",\"amount_at_create\":\"0.06310787\",\"price\":78521.64,\"price_str\":\"78521.64\",\"is_liquidation\":false},\"channel\":\"live_orders_btcusd\",\"event\":\"order_created\",\"event_id\":\"00065a1d-7fa2-8a30-0000-000102000020\",\"pre_event_id\":\"00065a1d-7fa2-5b50-0001-000101000020\",\"order_source\":\"orderbook\"}","recorded_unix_us":1787932602207494}
{"message":"{\"data\":{\"id\":2044303882305543,\"id_str\":\"2044303882305543\",\"order_type\":1,\"order_subtype\":5,\"datetime\":\"1787932602\",\"microtimestamp\":\"1787932602174000\",\"amount\":0.06310787,\"amount_str\":\"0.06310787\",\"amount_traded\":\"0\",\"amount_at_create\":\"0.06310787\",\"price\":78521.64,\"price_str\":\"78521.64\",\"is_liquidation\":false},\"channel\":\"live_orders_btcusd\",\"event\":\"order_deleted\",\"event_id\":\"00065a1d-7fa2-8a30-0001-000103000020\",\"pre_event_id\":\"00065a1d-7fa2-8a30-0000-000102000020\",\"order_source\":\"orderbook\"}","recorded_unix_us":1787932602207618}
{"message":"{\"data\":{\"id\":2044303882321931,\"id_str\":\"2044303882321931\",\"order_type\":1,\"order_subtype\":5,\"datetime\":\"1787932602\",\"microtimestamp\":\"1787932602178000\",\"amount\":0.1,\"amount_str\":\"0.10000000\",\"amount_traded\":\"0\",\"amount_at_create\":\"0.10000000\",\"price\":78522.62,\"price_str\":\"78522.62\",\"is_liquidation\":false},\"channel\":\"live_orders_btcusd\",\"event\":\"order_created\",\"event_id\":\"00065a1d-7fa2-99d0-0000-000100000020\",\"pre_event_id\":\"00065a1d-7fa2-8a30-0001-000103000020\",\"order_source\":\"orderbook\"}","recorded_unix_us":1787932602224124}
{"message":"{\"data\":{\"id\":2044303882321931,\"id_str\":\"2044303882321931\",\"order_type\":1,\"order_subtype\":5,\"datetime\":\"1787932602\",\"microtimestamp\":\"1787932602178000\",\"amount\":0.1,\"amount_str\":\"0.10000000\",\"amount_traded\":\"0\",\"amount_at_create\":\"0.10000000\",\"price\":78522.62,\"price_str\":\"78522.62\",\"is_liquidation\":false},\"channel\":\"live_orders_btcusd\",\"event\":\"order_deleted\",\"event_id\":\"00065a1d-7fa2-99d0-0001-000101000020\",\"pre_event_id\":\"00065a1d-7fa2-99d0-0000-000100000020\",\"order_source\":\"orderbook\"}","recorded_unix_us":1787932602224354}
{"message":"{\"data\":{\"id\":2044303881854976,\"id_str\":\"2044303881854976\",\"order_type\":1,\"order_subtype\":5,\"datetime\":\"1787932602\",\"microtimestamp\":\"1787932602183000\",\"amount\":2.01528391,\"amount_str\":\"2.01528391\",\"amount_traded\":\"0\",\"amount_at_create\":\"2.01528391\",\"price\":0.03163293,\"price_str\":\"0.03163293\",\"is_liquidation\":false},\"channel\":\"live_orders_ethbtc\",\"event\":\"order_deleted\",\"event_id\":\"00065a1d-7fa2-ad58-0000-001102000020\",\"pre_event_id\":\"00065a1d-7fa1-b740-0000-001101000020\",\"order_source\":\"orderbook\"}","recorded_unix_us":1787932602224569}
{"message":"{\"data\":{\"id\":2044303882371072,\"id_str\":\"2044303882371072\",\"order_type\":1,\"order_subtype\":5,\"datetime\":\"1787932602\",\"microtimestamp\":\"1787932602189000\",\"amount\":0.1,\"amount_str\":\"0.10000000\",\"amount_traded\":\"0\",\"amount_at_create\":\"0.10000000\",\"price\":78522.63,\"price_str\":\"78522.63\",\"is_liquidation\":false},\"channel\":\"live_orders_btcusd\",\"event\":\"order_created\",\"event_id\":\"00065a1d-7fa2-c4c8-0000-000102000020\",\"pre_event_id\":\"00065a1d-7fa2-99d0-0001-000101000020\",\"order_source\":\"orderbook\"}","recorded_unix_us":1787932602236443}
{"message":"{\"data\":{\"id\":2044303882371072,\"id_str\":\"2044303882371072\",\"order_type\":1,\"order_subtype\":5,\"datetime\":\"1787932602\",\"microtimestamp\":\"1787932602189000\",\"amount\":0.1,\"amount_str\":\"0.10000000\",\"amount_traded\":\"0\",\"amount_at_create\":\"0.10000000\",\"price\":78522.63,\"price_str\":\"78522.63\",\"is_liquidation\":false},\"channel\":\"live_orders_btcusd\",\"event\":\"order_deleted\",\"event_id\":\"00065a1d-7fa2-c4c8-0001-000103000020\",\"pre_event_id\":\"00065a1d-7fa2-c4c8-0000-000102000020\",\"order_source\":\"orderbook\"}","recorded_unix_us":1787932602236723}
{"message":"{\"data\":{\"id\":2044303880622094,\"id_str\":\"2044303880622094\",\"order_type\":0,\"order_subtype\":5,\"datetime\":\"1787932602\",\"microtimestamp\":\"1787932602192000\",\"amount\":4.034022,\"amount_str\":\"4.034022\",\"amount_traded\":\"0\",\"amount_at_create\":\"4.034022\",\"price\":2478.91,\"price_str\":\"2478.91\",\"is_liquidation\":false},\"channel\":\"live_orders_ethusd\",\"event\":\"order_deleted\",\"event_id\":\"00065a1d-7fa2-d080-0000-001202000020\",\"pre_event_id\":\"00065a1d-7fa2-6320-0000-001201000020\",\"order_source\":\"orderbook\"}","recorded_unix_us":1787932602236909}
{"message":"{\"data\":{\"id\":2044303882383360,\"id_str\":\"2044303882383360\",\"order_type\":1,\"order_subtype\":5,\"datetime\":\"1787932602\",\"microtimestamp\":\"1787932602192000\",\"amount\":5,\"amount_str\":\"5.000000\",\"amount_traded\":\"0\",\"amount_at_create\":\"5.000000\",\"price\":2481.7,\"price_str\":\"2481.70\",\"is_liquidation\":false},\"channel\":\"live_orders_ethusd\",\"event\":\"order_created\",\"event_id\":\"00065a1d-7fa2-d080-0001-001203000020\",\"pre_event_id\":\"00065a1d-7fa2-d080-0000-001202000020\",\"order_source\":\"orderbook\"}","recorded_unix_us":1787932602237168}
{"message":"{\"data\":{\"id\":2044303880728576,\"id_str\":\"2044303880728576\",\"order_type\":1,\"order_subtype\":5,\"datetime\":\"1787932602\",\"microtimestamp\":\"1787932602192000\",\"amount\":10.057184,\"amount_str\":\"10.057184\",\"amount_traded\":\"0\",\"amount_at_create\":\"10.057184\",\"price\":2485.79,\"price_str\":\"2485.79\",\"is_liquidation\":false},\"channel\":\"live_orders_ethusd\",\"event\":\"order_deleted\",\"event_id\":\"00065a1d-7fa2-d080-0002-001200000020\",\"pre_event_id\":\"00065a1d-7fa2-d080-0001-001203000020\",\"order_source\":\"orderbook\"}","recorded_unix_us":1787932602237221}
{"message":"{\"data\":{\"id\":2044303880728580,\"id_str\":\"2044303880728580\",\"order_type\":1,\"order_subtype\":5,\"datetime\":\"1787932602\",\"microtimestamp\":\"1787932602192000\",\"amount\":10.06507,\"amount_str\":\"10.065070\",\"amount_traded\":\"0\",\"amount_at_create\":\"10.065070\",\"price\":2483.84,\"price_str\":\"2483.84\",\"is_liquidation\":false},\"channel\":\"live_orders_ethusd\",\"event\":\"order_deleted\",\"event_id\":\"00065a1d-7fa2-d080-0003-001201000020\",\"pre_event_id\":\"00065a1d-7fa2-d080-0002-001200000020\",\"order_source\":\"orderbook\"}","recorded_unix_us":1787932602237274}
{"message":"{\"data\":{\"id\":2044303880728581,\"id_str\":\"2044303880728581\",\"order_type\":1,\"order_subtype\":5,\"datetime\":\"1787932602\",\"microtimestamp\":\"1787932602193000\",\"amount\":20.097242,\"amount_str\":\"20.097242\",\"amount_traded\":\"0\",\"amount_at_create\":\"20.097242\",\"price\":2487.91,\"price_str\":\"2487.91\",\"is_liquidation\":false},\"channel\":\"live_orders_ethusd\",\"event\":\"order_deleted\",\"event_id\":\"00065a1d-7fa2-d468-0000-001202000020\",\"pre_event_id\":\"00065a1d-7fa2-d080-0003-001201000020\",\"order_source\":\"orderbook\"}","recorded_unix_us":1787932602237311}
{"message":"{\"data\":{\"id\":2044303880732678,\"id_str\":\"2044303880732678\",\"order_type\":1,\"order_subtype\":5,\"datetime\":\"1787932602\",\"microtimestamp\":\"1787932602193000\",\"amount\":20.088574,\"amount_str\":\"20.088574\",\"amount_traded\":\"0\",\"amount_at_create\":\"20.088574\",\"price\":2488.98,\"price_str\":\"2488.98\",\"is_liquidation\":false},\"channel\":\"live_orders_ethusd\",\"event\":\"order_deleted\",\"event_id\":\"00065a1d-7fa2-d468-0001-001203000020\",\"pre_event_id\":\"00065a1d-7fa2-d468-0000-001202000020\",\"order_source\":\"orderbook\"}","recorded_unix_us":1787932602237437}
{"message":"{\"data\":{\"id\":2044303880736780,\"id_str\":\"2044303880736780\",\"order_type\":1,\"order_subtype\":5,\"datetime\":\"1787932602\",\"microtimestamp\":\"1787932602193000\",\"amount\":39.969006,\"amount_str\":\"39.969006\",\"amount_traded\":\"0\",\"amount_at_create\":\"39.969006\",\"price\":2501.94,\"price_str\":\"2501.94\",\"is_liquidation\":false},\"channel\":\"live_orders_ethusd\",\"event\":\"order_deleted\",\"event_id\":\"00065a1d-7fa2-d468-0002-001200000020\",\"pre_event_id\":\"00065a1d-7fa2-d468-0001-001203000020\",\"order_source\":\"orderbook\"}","recorded_unix_us":1787932602237589}
{"message":"{\"data\":{\"id\":2044303880740872,\"id_str\":\"2044303880740872\",\"order_type\":1,\"order_subtype\":5,\"datetime\":\"1787932602\",\"microtimestamp\":\"1787932602194000\",\"amount\":40.09205,\"amount_str\":\"40.092050\",\"amount_traded\":\"0\",\"amount_at_create\":\"40.092050\",\"price\":2494.27,\"price_str\":\"2494.27\",\"is_liquidation\":false},\"channel\":\"live_orders_ethusd\",\"event\":\"order_deleted\",\"event_id\":\"00065a1d-7fa2-d850-0000-001201000020\",\"pre_event_id\":\"00065a1d-7fa2-d468-0002-001200000020\",\"order_source\":\"orderbook\"}","recorded_unix_us":1787932602237630}
