{"message":"{\"event\":\"bts:subscription_succeeded\",\"channel\":\"live_orders_btcusd\",\"data\":{}}","recorded_unix_us":1787932601207779}
{"message":"{\"event\":\"bts:subscription_succeeded\",\"channel\":\"live_orders_ethusd\",\"data\":{}}","recorded_unix_us":1787932601207935}
{"message":"{\"event\":\"bts:subscription_succeeded\",\"channel\":\"live_orders_ethbtc\",\"data\":{}}","recorded_unix_us":1787932601207986}
{"message":"{\"data\":{\"id\":2044303878127633,\"id_str\":\"2044303878127633\",\"order_type\":1,\"order_subtype\":5,\"datetime\":\"1787932601\",\"microtimestamp\":\"1787932601154000\",\"amount\":0.1,\"amount_str\":\"0.10000000\",\"amount_traded\":\"0\",\"amount_at_create\":\"0.10000000\",\"price\":78523.32,\"price_str\":\"78523.32\",\"is_liquidation\":false},\"channel\":\"live_orders_btcusd\",\"event\":\"order_created\",\"event_id\":\"00065a1d-7f92-f9d0-0000-000100000020\",\"pre_event_id\":\"00065a1d-7f92-de78-0000-000103000020\",\"order_source\":\"orderbook\"}","recorded_unix_us":1787932601208155}
{"message":"{\"data\":{\"id\":2044303848652817,\"id_str\":\"2044303848652817\",\"order_type\":1,\"order_subtype\":5,\"datetime\":\"1787932601\",\"microtimestamp\":\"1787932601154000\",\"amount\":4.23144408,\"amount_str\":\"4.23144408\",\"amount_traded\":\"0\",\"amount_at_create\":\"4.23144408\",\"price\":0.03161039,\"price_str\":\"0.03161039\",\"is_liquidation\":false},\"channel\":\"live_orders_ethbtc\",\"event\":\"order_deleted\",\"event_id\":\"00065a1d-7f92-f9d0-0000-001102000020\",\"pre_event_id\":\"00065a1d-7f92-9058-0000-001101000020\",\"order_source\":\"orderbook\"}","recorded_unix_us":1787932601208293}
{"message":"{\"data\":{\"id\":2044303877451783,\"id_str\":\"2044303877451783\",\"order_type\":0,\"order_subtype\":5,\"datetime\":\"1787932601\",\"microtimestamp\":\"1787932601156000\",\"amount\":0.19103952,\"amount_str\":\"0.19103952\",\"amount_traded\":\"0\",\"amount_at_create\":\"0.19103952\",\"price\":78479.69,\"price_str\":\"78479.69\",\"is_liquidation\":false},\"channel\":\"live_orders_btcusd\",\"event\":\"order_deleted\",\"event_id\":\"00065a1d-7f93-01a0-0000-000101000020\",\"pre_event_id\":\"00065a1d-7f92-f9d0-0000-000100000020\",\"order_source\":\"orderbook\"}","recorded_unix_us":1787932601208411}
{"message":"{\"data\":{\"id\":2044303878144010,\"id_str\":\"2044303878144010\",\"order_type\":1,\"order_subtype\":5,\"datetime\":\"1787932601\",\"microtimestamp\":\"1787932601158000\",\"amount\":0.1,\"amount_str\":\"0.10000000\",\"amount_traded\":\"0\",\"amount_at_create\":\"0.10000000\",\"price\":78522.62,\"price_str\":\"78522.62\",\"is_liquidation\":false},\"channel\":\"live_orders_btcusd\",\"event\":\"order_created\",\"event_id\":\"00065a1d-7f93-0970-0000-000102000020\",\"pre_event_id\":\"00065a1d-7f93-01a0-0000-000101000020\",\"order_source\":\"orderbook\"}","recorded_unix_us":1787932601208546}
{"message":"{\"data\":{\"id\":2044303878144010,\"id_str\":\"2044303878144010\",\"order_type\":1,\"order_subtype\":5,\"datetime\":\"1787932601\",\"microtimestamp\":\"1787932601158000\",\"amount\":0.1,\"amount_str\":\"0.10000000\",\"amount_traded\":\"0\",\"amount_at_create\":\"0.10000000\",\"price\":78522.62,\"price_str\":\"78522.62\",\"is_liquidation\":false},\"channel\":\"live_orders_btcusd\",\"event\":\"order_deleted\",\"event_id\":\"00065a1d-7f93-0970-0001-000103000020\",\"pre_event_id\":\"00065a1d-7f93-0970-0000-000102000020\",\"order_source\":\"orderbook\"}","recorded_unix_us":1787932601208580}
{"message":"{\"data\":{\"id\":2044303878144016,\"id_str\":\"2044303878144016\",\"order_type\":0,\"order_subtype\":5,\"datetime\":\"1787932601\",\"microtimestamp\":\"1787932601158000\",\"amount\":6.044921,\"amount_str\":\"6.044921\",\"amount_traded\":\"0\",\"amount_at_create\":\"6.044921\",\"price\":2480,\"price_str\":\"2480.00\",\"is_liquidation\":false},\"channel\":\"live_orders_ethusd\",\"event\":\"order_created\",\"event_id\":\"00065a1d-7f93-0970-0000-001200000020\",\"pre_event_id\":\"00065a1d-7f92-f200-0000-001203000020\",\"order_source\":\"orderbook\"}","recorded_unix_us":1787932601208673}
{"message":"{\"data\":{\"id\":2044303878152198,\"id_str\":\"2044303878152198\",\"order_type\":1,\"order_subtype\":5,\"datetime\":\"1787932601\",\"microtimestamp\":\"1787932601159000\",\"amount\":6.044921,\"amount_str\":\"6.044921\",\"amount_traded\":\"0\",\"amount_at_create\":\"6.044921\",\"price\":2481.75,\"price_str\":\"2481.75\",\"is_liquidation\":false},\"channel\":\"live_orders_ethusd\",\"event\":\"order_created\",\"event_id\":\"00065a1d-7f93-0d58-0000-001201000020\",\"pre_event_id\":\"00065a1d-7f93-0970-0000-001200000020\",\"order_source\":\"orderbook\"}","recorded_unix_us":1787932601208785}
{"message":"{\"data\":{\"id\":2044303878176779,\"id_str\":\"2044303878176779\",\"order_type\":0,\"order_subtype\":5,\"datetime\":\"1787932601\",\"microtimestamp\":\"1787932601166000\",\"amount\":0.1910414,\"amount_str\":\"0.19104140\",\"amount_traded\":\"0\",\"amount_at_create\":\"0.19104140\",\"price\":78481.58,\"price_str\":\"78481.58\",\"is_liquidation\":false},\"channel\":\"live_orders_btcusd\",\"event\":\"order_created\",\"event_id\":\"00065a1d-7f93-28b0-0000-000100000020\",\"pre_event_id\":\"00065a1d-7f93-0970-0001-000103000020\",\"order_source\":\"orderbook\"}","recorded_unix_us":1787932601208855}
{"message":"{\"data\":{\"id\":2044303878205450,\"id_str\":\"2044303878205450\",\"order_type\":0,\"order_subtype\":5,\"datetime\":\"1787932601\",\"microtimestamp\":\"1787932601173000\",\"amount\":4.034894,\"amount_str\":\"4.034894\",\"amount_traded\":\"0\",\"amount_at_create\":\"4.034894\",\"price\":2478.37,\"price_str\":\"2478.37\",\"is_liquidation\":false},\"channel\":\"live_orders_ethusd\",\"event\":\"order_created\",\"event_id\":\"00065a1d-7f93-4408-0000-001202000020\",\"pre_event_id\":\"00065a1d-7f93-0d58-0000-001201000020\",\"order_source\":\"orderbook\"}","recorded_unix_us":1787932601208945}
{"message":"{\"data\":{\"id\":2044303878213635,\"id_str\":\"2044303878213635\",\"order_type\":0,\"order_subtype\":5,\"datetime\":\"1787932601\",\"microtimestamp\":\"1787932601174000\",\"amount\":20.235437,\"amount_str\":\"20.235437\",\"amount_traded\":\"0\",\"amount_at_create\":\"20.235437\",\"price\":2470.91,\"price_str\":\"2470.91\",\"is_liquidation\":false},\"channel\":\"live_orders_ethusd\",\"event\":\"order_created\",\"event_id\":\"00065a1d-7f93-47f0-0000-001203000020\",\"pre_event_id\":\"00065a1d-7f93-4408-0000-001202000020\",\"order_source\":\"orderbook\"}","recorded_unix_us":1787932601317771}
{"message":"{\"data\":{\"id\":2044303878217731,\"id_str\":\"2044303878217731\",\"order_type\":1,\"order_subtype\":5,\"datetime\":\"1787932601\",\"microtimestamp\":\"1787932601175000\",\"amount\":0.1,\"amount_str\":\"0.10000000\",\"amount_traded\":\"0\",\"amount_at_create\":\"0.10000000\",\"price\":78522.63,\"price_str\":\"78522.63\",\"is_liquidation\":false},\"channel\":\"live_orders_btcusd\",\"event\":\"order_created\",\"event_id\":\"00065a1d-7f93-4bd8-0000-000101000020\",\"pre_event_id\":\"00065a1d-7f93-28b0-0000-000100000020\",\"order_source\":\"orderbook\"}","recorded_unix_us":1787932601317990}
{"message":"{\"data\":{\"id\":2044303878217731,\"id_str\":\"2044303878217731\",\"order_type\":1,\"order_subtype\":5,\"datetime\":\"1787932601\",\"microtimestamp\":\"1787932601175000\",\"amount\":0.1,\"amount_str\":\"0.10000000\",\"amount_traded\":\"0\",\"amount_at_create\":\"0.10000000\",\"price\":78522.63,\"price_str\":\"78522.63\",\"is_liquidation\":false},\"channel\":\"live_orders_btcusd\",\"event\":\"order_deleted\",\"event_id\":\"00065a1d-7f93-4bd8-0001-000102000020\",\"pre_event_id\":\"00065a1d-7f93-4bd8-0000-000101000020\",\"order_source\":\"orderbook\"}","recorded_unix_us":1787932601318490}
{"message":"{\"data\":{\"id\":2044303878225930,\"id_str\":\"2044303878225930\",\"order_type\":0,\"order_subtype\":5,\"datetime\":\"1787932601\",\"microtimestamp\":\"1787932601178000\",\"amount\":0.5,\"amount_str\":\"0.50000000\",\"amount_traded\":\"0\",\"amount_at_create\":\"0.50000000\",\"price\":78507.73,\"price_str\":\"78507.73\",\"is_liquidation\":false},\"channel\":\"live_orders_btcusd\",\"event\":\"order_created\",\"event_id\":\"00065a1d-7f93-5790-0000-000103000020\",\"pre_event_id\":\"00065a1d-7f93-4bd8-0001-000102000020\",\"order_source\":\"orderbook\"}","recorded_unix_us":1787932601318538}
{"message":"{\"data\":{\"id\":2044303878234112,\"id_str\":\"2044303878234112\",\"order_type\":0,\"order_subtype\":5,\"datetime\":\"1787932601\",\"microtimestamp\":\"1787932601179000\",\"amount\":0.25,\"amount_str\":\"0.25000000\",\"amount_traded\":\"0\",\"amount_at_create\":\"0.25000000\",\"price\":78511.65,\"price_str\":\"78511.65\",\"is_liquidation\":false},\"channel\":\"live_orders_btcusd\",\"event\":\"order_created\",\"event_id\":\"00065a1d-7f93-5b78-0000-000100000020\",\"pre_event_id\":\"00065a1d-7f93-5790-0000-000103000020\",\"order_source\":\"orderbook\"}","recorded_unix_us":1787932601318567}
{"message":"{\"data\":{\"id\":2044303877533697,\"id_str\":\"2044303877533697\",\"order_type\":0,\"order_subtype\":5,\"datetime\":\"1787932601\",\"microtimestamp\":\"1787932601179000\",\"amount\":0.63679819,\"amount_str\":\"0.63679819\",\"amount_traded\":\"0\",\"amount_at_create\":\"0.63679819\",\"price\":78477.98,\"price_str\":\"78477.98\",\"is_liquidation\":false},\"channel\":\"live_orders_btcusd\",\"event\":\"order_deleted\",\"event_id\":\"00065a1d-7f93-5b78-0001-000101000020\",\"pre_event_id\":\"00065a1d-7f93-5b78-0000-000100000020\",\"order_source\":\"orderbook\"}","recorded_unix_us":1787932601318592}
{"message":"{\"data\":{\"id\":2044303877595137,\"id_str\":\"2044303877595137\",\"order_type\":0,\"order_subtype\":5,\"datetime\":\"1787932601\",\"microtimestamp\":\"1787932601180000\",\"amount\":0.50943865,\"amount_str\":\"0.50943865\",\"amount_traded\":\"0\",\"amount_at_create\":\"0.50943865\",\"price\":78476.17,\"price_str\":\"78476.17\",\"is_liquidation\":false},\"channel\":\"live_orders_btcusd\",\"event\":\"order_deleted\",\"event_id\":\"00065a1d-7f93-5f60-0000-000102000020\",\"pre_event_id\":\"00065a1d-7f93-5b78-0001-000101000020\",\"order_source\":\"orderbook\"}","recorded_unix_us":1787932601318618}
{"message":"{\"data\":{\"id\":2044303878246406,\"id_str\":\"2044303878246406\",\"order_type\":1,\"order_subtype\":5,\"datetime\":\"1787932601\",\"microtimestamp\":\"1787932601183000\",\"amount\":6,\"amount_str\":\"6.000000\",\"amount_traded\":\"0\",\"amount_at_create\":\"6.000000\",\"price\":2482.48,\"price_str\":\"2482.48\",\"is_liquidation\":false},\"channel\":\"live_orders_ethusd\",\"event\":\"order_created\",\"event_id\":\"00065a1d-7f93-6b18-0000-001200000020\",\"pre_event_id\":\"00065a1d-7f93-47f0-0000-001203000020\",\"order_source\":\"orderbook\"}","recorded_unix_us":1787932601318720}
{"message":"{\"data\":{\"id\":2044303878266885,\"id_str\":\"2044303878266885\",\"order_type\":0,\"order_subtype\":5,\"datetime\":\"1787932601\",\"microtimestamp\":\"1787932601187000\",\"amount\":0.00140266,\"amount_str\":\"0.00140266\",\"amount_traded\":\"0\",\"amount_at_create\":\"0.00140266\",\"price\":70670.37,\"price_str\":\"70670.37\",\"is_liquidation\":false},\"channel\":\"live_orders_btcusd\",\"event\":\"order_created\",\"event_id\":\"00065a1d-7f93-7ab8-0000-000103000020\",\"pre_event_id\":\"00065a1d-7f93-5f60-0000-000102000020\",\"order_source\":\"orderbook\"}","recorded_unix_us":1787932601319094}
{"message":"{\"data\":{\"id\":2044303878279172,\"id_str\":\"2044303878279172\",\"order_type\":0,\"order_subtype\":5,\"datetime\":\"1787932601\",\"microtimestamp\":\"1787932601190000\",\"amount\":0.6367979,\"amount_str\":\"0.63679790\",\"amount_traded\":\"0\",\"amount_at_create\":\"0.63679790\",\"price\":78480.38,\"price_str\":\"78480.38\",\"is_liquidation\":false},\"channel\":\"live_orders_btcusd\",\"event\":\"order_created\",\"event_id\":\"00065a1d-7f93-8670-0000-000100000020\",\"pre_event_id\":\"00065a1d-7f93-7ab8-0000-000103000020\",\"order_source\":\"orderbook\"}","recorded_unix_us":1787932601319133}
{"message":"{\"data\":{\"id\":2044303878283264,\"id_str\":\"2044303878283264\",\"order_type\":0,\"order_subtype\":5,\"datetime\":\"1787932601\",\"microtimestamp\":\"1787932601191000\",\"amount\":0.50943832,\"amount_str\":\"0.50943832\",\"amount_traded\":\"0\",\"amount_at_create\":\"0.50943832\",\"price\":78478.42,\"price_str\":\"78478.42\",\"is_liquidation\":false},\"channel\":\"live_orders_btcusd\",\"event\":\"order_created\",\"event_id\":\"00065a1d-7f93-8a58-0000-000101000020\",\"pre_event_id\":\"00065a1d-7f93-8670-0000-000100000020\",\"order_source\":\"orderbook\"}","recorded_unix_us":1787932601319159}
{"message":"{\"data\":{\"id\":2044303876714497,\"id_str\":\"2044303876714497\",\"order_type\":1,\"order_subtype\":5,\"datetime\":\"1787932601\",\"microtimestamp\":\"1787932601191000\",\"amount\":0.1,\"amount_str\":\"0.10000000\",\"amount_traded\":\"0\",\"amount_at_create\":\"0.10000000\",\"price\":78523.51,\"price_str\":\"78523.51\",\"is_liquidation\":false},\"channel\":\"live_orders_btcusd\",\"event\":\"order_deleted\",\"event_id\":\"00065a1d-7f93-8a58-0001-000102000020\",\"pre_event_id\":\"00065a1d-7f93-8a58-0000-000101000020\",\"order_source\":\"orderbook\"}","recorded_unix_us":1787932601319186}
{"message":"{\"data\":{\"id\":2044303878283276,\"id_str\":\"2044303878283276\",\"order_type\":1,\"order_subtype\":5,\"datetime\":\"1787932601\",\"microtimestamp\":\"1787932601192000\",\"amount\":0.1,\"amount_str\":\"0.10000000\",\"amount_traded\":\"0\",\"amount_at_create\":\"0.10000000\",\"price\":78522.62,\"price_str\":\"78522.62\",\"is_liquidation\":false},\"channel\":\"live_orders_btcusd\",\"event\":\"order_created\",\"event_id\":\"00065a1d-7f93-8e40-0000-000103000020\",\"pre_event_id\":\"00065a1d-7f93-8a58-0001-000102000020\",\"order_source\":\"orderbook\"}","recorded_unix_us":1787932601319211}
{"message":"{\"data\":{\"id\":2044303878283276,\"id_str\":\"2044303878283276\",\"order_type\":1,\"order_subtype\":5,\"datetime\":\"1787932601\",\"microtimestamp\":\"1787932601192000\",\"amount\":0.1,\"amount_str\":\"0.10000000\",\"amount_traded\":\"0\",\"amount_at_create\":\"0.10000000\",\"price\":78522.62,\"price_str\":\"78522.62\",\"is_liquidation\":false},\"channel\":\"live_orders_btcusd\",\"event\":\"order_deleted\",\"event_id\":\"00065a1d-7f93-8e40-0001-000100000020\",\"pre_event_id\":\"00065a1d-7f93-8e40-0000-000103000020\",\"order_source\":\"orderbook\"}","recorded_unix_us":1787932601319237}
{"message":"{\"data\":{\"id\":2044303878287371,\"id_str\":\"2044303878287371\",\"order_type\":0,\"order_subtype\":5,\"datetime\":\"1787932601\",\"microtimestamp\":\"1787932601193000\",\"amount\":10.090138,\"amount_str\":\"10.090138\",\"amount_traded\":\"0\",\"amount_at_create\":\"10.090138\",\"price\":2477.66,\"price_str\":\"2477.66\",\"is_liquidation\":false},\"channel\":\"live_orders_ethusd\",\"event\":\"order_created\",\"event_id\":\"00065a1d-7f93-9228-0000-001201000020\",\"pre_event_id\":\"00065a1d-7f93-6b18-0000-001200000020\",\"order_source\":\"orderbook\"}","recorded_unix_us":1787932601319262}
{"message":"{\"data\":{\"id\":2044303878291459,\"id_str\":\"2044303878291459\",\"order_type\":1,\"order_subtype\":5,\"datetime\":\"1787932601\",\"microtimestamp\":\"1787932601193000\",\"amount\":0.1,\"amount_str\":\"0.10000000\",\"amount_traded\":\"0\",\"amount_at_create\":\"0.10000000\",\"price\":78523.24,\"price_str\":\"78523.24\",\"is_liquidation\":false},\"channel\":\"live_orders_btcusd\",\"event\":\"order_created\",\"event_id\":\"00065a1d-7f93-9228-0000-000101000020\",\"pre_event_id\":\"00065a1d-7f93-8e40-0001-000100000020\",\"order_source\":\"orderbook\"}","recorded_unix_us":1787932601319350}
{"message":"{\"data\":{\"id\":2044303878291460,\"id_str\":\"2044303878291460\",\"order_type\":0,\"order_subtype\":5,\"datetime\":\"1787932601\",\"microtimestamp\":\"1787932601193000\",\"amount\":10.095101,\"amount_str\":\"10.095101\",\"amount_traded\":\"0\",\"amount_at_create\":\"10.095101\",\"price\":2476.44,\"price_str\":\"2476.44\",\"is_liquidation\":false},\"channel\":\"live_orders_ethusd\",\"event\":\"order_created\",\"event_id\":\"00065a1d-7f93-9228-0001-001202000020\",\"pre_event_id\":\"00065a1d-7f93-9228-0000-001201000020\",\"order_source\":\"orderbook\"}","recorded_unix_us":1787932601319476}
{"message":"{\"data\":{\"id\":2044303878291467,\"id_str\":\"2044303878291467\",\"order_type\":0,\"order_subtype\":5,\"datetime\":\"1787932601\",\"microtimestamp\":\"1787932601194000\",\"amount\":40.650432,\"amount_str\":\"40.650432\",\"amount_traded\":\"0\",\"amount_at_create\":\"40.650432\",\"price\":2459.99,\"price_str\":\"2459.99\",\"is_liquidation\":false},\"channel\":\"live_orders_ethusd\",\"event\":\"order_created\",\"event_id\":\"00065a1d-7f93-9610-0000-001203000020\",\"pre_event_id\":\"00065a1d-7f93-9228-0001-001202000020\",\"order_source\":\"orderbook\"}","recorded_unix_us":1787932601319523}
{"message":"{\"data\":{\"id\":2044303878295552,\"id_str\":\"2044303878295552\",\"order_type\":0,\"order_subtype\":5,\"datetime\":\"1787932601\",\"microtimestamp\":\"1787932601194000\",\"amount\":4.033601,\"amount_str\":\"4.033601\",\"amount_traded\":\"0\",\"amount_at_create\":\"4.033601\",\"price\":2479.17,\"price_str\":\"2479.17\",\"is_liquidation\":false},\"channel\":\"live_orders_ethusd\",\"event\":\"order_created\",\"event_id\":\"00065a1d-7f93-9610-0001-001200000020\",\"pre_event_id\":\"00065a1d-7f93-9610-0000-001203000020\",\"order_source\":\"orderbook\"}","recorded_unix_us":1787932601319611}
{"message":"{\"data\":{\"id\":2044303878295553,\"id_str\":\"2044303878295553\",\"order_type\":0,\"order_subtype\":5,\"datetime\":\"1787932601\",\"microtimestamp\":\"1787932601194000\",\"amount\":20.204386,\"amount_str\":\"20.204386\",\"amount_traded\":\"0\",\"amount_at_create\":\"20.204386\",\"price\":2474.71,\"price_str\":\"2474.71\",\"is_liquidation\":false},\"channel\":\"live_orders_ethusd\",\"event\":\"order_created\",\"event_id\":\"00065a1d-7f93-9610-0002-001201000020\",\"pre_event_id\":\"00065a1d-7f93-9610-0001-001200000020\",\"order_source\":\"orderbook\"}","recorded_unix_us":1787932601319895}
{"message":"{\"data\":{\"id\":2044303878295557,\"id_str\":\"2044303878295557\",\"order_type\":0,\"order_subtype\":5,\"datetime\":\"1787932601\",\"microtimestamp\":\"1787932601194000\",\"amount\":40.528033,\"amount_str\":\"40.528033\",\"amount_traded\":\"0\",\"amount_at_create\":\"40.528033\",\"price\":2467.42,\"price_str\":\"2467.42\",\"is_liquidation\":false},\"channel\":\"live_orders_ethusd\",\"event\":\"order_created\",\"event_id\":\"00065a1d-7f93-9610-0003-001202000020\",\"pre_event_id\":\"00065a1d-7f93-9610-0002-001201000020\",\"order_source\":\"orderbook\"}","recorded_unix_us":1787932601319929}
{"message":"{\"data\":{\"id\":2044303877603330,\"id_str\":\"2044303877603330\",\"order_type\":0,\"order_subtype\":5,\"datetime\":\"1787932601\",\"microtimestamp\":\"1787932601199000\",\"amount\":0.00140266,\"amount_str\":\"0.00140266\",\"amount_traded\":\"0\",\"amount_at_create\":\"0.00140266\",\"price\":70670.37,\"price_str\":\"70670.37\",\"is_liquidation\":false},\"channel\":\"live_orders_btcusd\",\"event\":\"order_deleted\",\"event_id\":\"00065a1d-7f93-a998-0000-000102000020\",\"pre_event_id\":\"00065a1d-7f93-9228-0000-000101000020\",\"order_source\":\"orderbook\"}","recorded_unix_us":1787932601319954}
{"message":"{\"data\":{\"id\":2044303837663234,\"id_str\":\"2044303837663234\",\"order_type\":1,\"order_subtype\":0,\"datetime\":\"1787932601\",\"microtimestamp\":\"1787932601202000\",\"amount\":0.00025,\"amount_str\":\"0.00025000\",\"amount_traded\":\"0\",\"amount_at_create\":\"0.00025000\",\"price\":78588,\"price_str\":\"78588.00\",\"is_liquidation\":false},\"channel\":\"live_orders_btcusd\",\"event\":\"order_deleted\",\"event_id\":\"00065a1d-7f93-b550-0000-000103000020\",\"pre_event_id\":\"00065a1d-7f93-a998-0000-000102000020\",\"order_source\":\"orderbook\"}","recorded_unix_us":1787932601319978}
{"message":"{\"data\":{\"id\":2044303878336525,\"id_str\":\"2044303878336525\",\"order_type\":1,\"order_subtype\":5,\"datetime\":\"1787932601\",\"microtimestamp\":\"1787932601205000\",\"amount\":0.1,\"amount_str\":\"0.10000000\",\"amount_traded\":\"0\",\"amount_at_create\":\"0.10000000\",\"price\":78522.63,\"price_str\":\"78522.63\",\"is_liquidation\":false},\"channel\":\"live_orders_btcusd\",\"event\":\"order_created\",\"event_id\":\"00065a1d-7f93-c108-0000-000100000020\",\"pre_event_id\":\"00065a1d-7f93-b550-0000-000103000020\",\"order_source\":\"orderbook\"}","recorded_unix_us":1787932601320059}
{"message":"{\"data\":{\"id\":2044303878336525,\"id_str\":\"2044303878336525\",\"order_type\":1,\"order_subtype\":5,\"datetime\":\"1787932601\",\"microtimestamp\":\"1787932601205000\",\"amount\":0.1,\"amount_str\":\"0.10000000\",\"amount_traded\":\"0\",\"amount_at_create\":\"0.10000000\",\"price\":78522.63,\"price_str\":\"78522.63\",\"is_liquidation\":false},\"channel\":\"live_orders_btcusd\",\"event\":\"order_deleted\",\"event_id\":\"00065a1d-7f93-c108-0001-000101000020\",\"pre_event_id\":\"00065a1d-7f93-c108-0000-000100000020\",\"order_source\":\"orderbook\"}","recorded_unix_us":1787932601320150}
{"message":"{\"data\":{\"id\":2044303878365186,\"id_str\":\"2044303878365186\",\"order_type\":0,\"order_subtype\":5,\"datetime\":\"1787932601\",\"microtimestamp\":\"1787932601211000\",\"amount\":12.096906,\"amount_str\":\"12.096906\",\"amount_traded\":\"0\",\"amount_at_create\":\"12.096906\",\"price\":2479.97,\"price_str\":\"2479.97\",\"is_liquidation\":false},\"channel\":\"live_orders_ethusd\",\"event\":\"order_created\",\"event_id\":\"00065a1d-7f93-d878-0000-001203000020\",\"pre_event_id\":\"00065a1d-7f93-9610-0003-001202000020\",\"order_source\":\"orderbook\"}","recorded_unix_us":1787932601320360}
{"message":"{\"data\":{\"id\":2044303878365189,\"id_str\":\"2044303878365189\",\"order_type\":0,\"order_subtype\":5,\"datetime\":\"1787932601\",\"microtimestamp\":\"1787932601211000\",\"amount\":12.098474,\"amount_str\":\"12.098474\",\"amount_traded\":\"0\",\"amount_at_create\":\"12.098474\",\"price\":2479.65,\"price_str\":\"2479.65\",\"is_liquidation\":false},\"channel\":\"live_orders_ethusd\",\"event\":\"order_created\",\"event_id\":\"00065a1d-7f93-d878-0001-001200000020\",\"pre_event_id\":\"00065a1d-7f93-d878-0000-001203000020\",\"order_source\":\"orderbook\"}","recorded_unix_us":1787932601320760}
{"message":"{\"data\":{\"id\":2044303878418442,\"id_str\":\"2044303878418442\",\"order_type\":0,\"order_subtype\":5,\"datetime\":\"1787932601\",\"microtimestamp\":\"1787932601225000\",\"amount\":0.12,\"amount_str\":\"0.12000000\",\"amount_traded\":\"0\",\"amount_at_create\":\"0.12000000\",\"price\":78507.07,\"price_str\":\"78507.07\",\"is_liquidation\":false},\"channel\":\"live_orders_btcusd\",\"event\":\"order_created\",\"event_id\":\"00065a1d-7f94-0f28-0000-000102000020\",\"pre_event_id\":\"00065a1d-7f93-c108-0001-000101000020\",\"order_source\":\"orderbook\"}","recorded_unix_us":1787932601320856}
{"message":"{\"data\":{\"id\":2044303878463488,\"id_str\":\"2044303878463488\",\"order_type\":1,\"order_subtype\":5,\"datetime\":\"1787932601\",\"microtimestamp\":\"1787932601235000\",\"amount\":0.1,\"amount_str\":\"0.10000000\",\"amount_traded\":\"0\",\"amount_at_create\":\"0.10000000\",\"price\":78523.14,\"price_str\":\"78523.14\",\"is_liquidation\":false},\"channel\":\"live_orders_btcusd\",\"event\":\"order_created\",\"event_id\":\"00065a1d-7f94-3638-0000-000103000020\",\"pre_event_id\":\"00065a1d-7f94-0f28-0000-000102000020\",\"order_source\":\"orderbook\"}","recorded_unix_us":1787932601320968}
{"message":"{\"data\":{\"id\":2044303878463489,\"id_str\":\"2044303878463489\",\"order_type\":1,\"order_subtype\":5,\"datetime\":\"1787932601\",\"microtimestamp\":\"1787932601235000\",\"amount\":0.1,\"amount_str\":\"0.10000000\",\"amount_traded\":\"0\",\"amount_at_create\":\"0.10000000\",\"price\":78522.62,\"price_str\":\"78522.62\",\"is_liquidation\":false},\"channel\":\"live_orders_btcusd\",\"event\":\"order_created\",\"event_id\":\"00065a1d-7f94-3638-0001-000100000020\",\"pre_event_id\":\"00065a1d-7f94-3638-0000-000103000020\",\"order_source\":\"orderbook\"}","recorded_unix_us":1787932601321134}
{"message":"{\"data\":{\"id\":2044303878463489,\"id_str\":\"2044303878463489\",\"order_type\":1,\"order_subtype\":5,\"datetime\":\"1787932601\",\"microtimestamp\":\"1787932601235000\",\"amount\":0.1,\"amount_str\":\"0.10000000\",\"amount_traded\":\"0\",\"amount_at_create\":\"0.10000000\",\"price\":78522.62,\"price_str\":\"78522.62\",\"is_liquidation\":false},\"channel\":\"live_orders_btcusd\",\"event\":\"order_deleted\",\"event_id\":\"00065a1d-7f94-3638-0002-000101000020\",\"pre_event_id\":\"00065a1d-7f94-3638-0001-000100000020\",\"order_source\":\"orderbook\"}","recorded_unix_us":1787932601321330}
{"message":"{\"data\":{\"id\":2044303878471682,\"id_str\":\"2044303878471682\",\"order_type\":1,\"order_subtype\":5,\"datetime\":\"1787932601\",\"microtimestamp\":\"1787932601237000\",\"amount\":0.1,\"amount_str\":\"0.10000000\",\"amount_traded\":\"0\",\"amount_at_create\":\"0.10000000\",\"price\":78522.63,\"price_str\":\"78522.63\",\"is_liquidation\":false},\"channel\":\"live_orders_btcusd\",\"event\":\"order_created\",\"event_id\":\"00065a1d-7f94-3e08-0000-000102000020\",\"pre_event_id\":\"00065a1d-7f94-3638-0002-000101000020\",\"order_source\":\"orderbook\"}","recorded_unix_us":1787932601321491}
{"message":"{\"data\":{\"id\":2044303878471682,\"id_str\":\"2044303878471682\",\"order_type\":1,\"order_subtype\":5,\"datetime\":\"1787932601\",\"microtimestamp\":\"1787932601237000\",\"amount\":0.1,\"amount_str\":\"0.10000000\",\"amount_traded\":\"0\",\"amount_at_create\":\"0.10000000\",\"price\":78522.63,\"price_str\":\"78522.63\",\"is_liquidation\":false},\"channel\":\"live_orders_btcusd\",\"event\":\"order_deleted\",\"event_id\":\"00065a1d-7f94-3e08-0001-000103000020\",\"pre_event_id\":\"00065a1d-7f94-3e08-0000-000102000020\",\"order_source\":\"orderbook\"}","recorded_unix_us":1787932601321539}
{"message":"{\"data\":{\"id\":2044303878488064,\"id_str\":\"2044303878488064\",\"order_type\":1,\"order_subtype\":4,\"datetime\":\"1787932601\",\"microtimestamp\":\"1787932601241000\",\"amount\":0.00006244,\"amount_str\":\"0.00006244\",\"amount_traded\":\"0\",\"amount_at_create\":\"0.00006244\",\"price\":80878,\"price_str\":\"80878.00\",\"is_liquidation\":false},\"channel\":\"live_orders_btcusd\",\"event\":\"order_created\",\"event_id\":\"00065a1d-7f94-4da8-0000-000100000020\",\"pre_event_id\":\"00065a1d-7f94-3e08-0001-000103000020\",\"order_source\":\"orderbook\"}","recorded_unix_us":1787932601321696}
{"message":"{\"data\":{\"id\":2044303878488064,\"id_str\":\"2044303878488064\",\"order_type\":1,\"order_subtype\":4,\"datetime\":\"1787932601\",\"microtimestamp\":\"1787932601241000\",\"amount\":0.00006244,\"amount_str\":\"0.00006244\",\"amount_traded\":\"0\",\"amount_at_create\":\"0.00006244\",\"price\":80878,\"price_str\":\"80878.00\",\"is_liquidation\":false},\"channel\":\"live_orders_btcusd\",\"event\":\"order_deleted\",\"event_id\":\"00065a1d-7f94-4da8-0001-000101000020\",\"pre_event_id\":\"00065a1d-7f94-4da8-0000-000100000020\",\"order_source\":\"orderbook\"}","recorded_unix_us":1787932601321732}
{"message":"{\"data\":{\"id\":2044303876886533,\"id_str\":\"2044303876886533\",\"order_type\":1,\"order_subtype\":5,\"datetime\":\"1787932601\",\"microtimestamp\":\"1787932601252000\",\"amount\":0.1,\"amount_str\":\"0.10000000\",\"amount_traded\":\"0\",\"amount_at_create\":\"0.10000000\",\"price\":78523.46,\"price_str\":\"78523.46\",\"is_liquidation\":false},\"channel\":\"live_orders_btcusd\",\"event\":\"order_deleted\",\"event_id\":\"00065a1d-7f94-78a0-0000-000102000020\",\"pre_event_id\":\"00065a1d-7f94-4da8-0001-000101000020\",\"order_source\":\"orderbook\"}","recorded_unix_us":1787932601321834}
{"message":"{\"data\":{\"id\":2044303878000647,\"id_str\":\"2044303878000647\",\"order_type\":0,\"order_subtype\":5,\"datetime\":\"1787932601\",\"microtimestamp\":\"1787932601266000\",\"amount\":0.468499,\"amount_str\":\"0.468499\",\"amount_traded\":\"0\",\"amount_at_create\":\"0.468499\",\"price\":2479.8,\"price_str\":\"2479.80\",\"is_liquidation\":false},\"channel\":\"live_orders_ethusd\",\"event\":\"order_deleted\",\"event_id\":\"00065a1d-7f94-af50-0000-001201000020\",\"pre_event_id\":\"00065a1d-7f93-d878-0001-001200000020\",\"order_source\":\"orderbook\"}","recorded_unix_us":1787932601321944}
{"message":"{\"data\":{\"id\":2044303877074948,\"id_str\":\"2044303877074948\",\"order_type\":0,\"order_subtype\":5,\"datetime\":\"1787932601\",\"microtimestamp\":\"1787932601266000\",\"amount\":0.403104,\"amount_str\":\"0.403104\",\"amount_traded\":\"0\",\"amount_at_create\":\"0.403104\",\"price\":2479.5,\"price_str\":\"2479.50\",\"is_liquidation\":false},\"channel\":\"live_orders_ethusd\",\"event\":\"order_deleted\",\"event_id\":\"00065a1d-7f94-af50-0001-001202000020\",\"pre_event_id\":\"00065a1d-7f94-af50-0000-001201000020\",\"order_source\":\"orderbook\"}","recorded_unix_us":1787932601322077}
{"message":"{\"data\":{\"id\":2044303878176779,\"id_str\":\"2044303878176779\",\"order_type\":0,\"order_subtype\":5,\"datetime\":\"1787932601\",\"microtimestamp\":\"1787932601266000\",\"amount\":0.1910414,\"amount_str\":\"0.19104140\",\"amount_traded\":\"0\",\"amount_at_create\":\"0.19104140\",\"price\":78481.58,\"price_str\":\"78481.58\",\"is_liquidation\":false},\"channel\":\"live_orders_btcusd\",\"event\":\"order_deleted\",\"event_id\":\"00065a1d-7f94-af50-0000-000103000020\",\"pre_event_id\":\"00065a1d-7f94-78a0-0000-000102000020\",\"order_source\":\"orderbook\"}","recorded_unix_us":1787932601322112}
{"message":"{\"data\":{\"id\":2044303878602752,\"id_str\":\"2044303878602752\",\"order_type\":1,\"order_subtype\":5,\"datetime\":\"1787932601\",\"microtimestamp\":\"1787932601269000\",\"amount\":0.1,\"amount_str\":\"0.10000000\",\"amount_traded\":\"0\",\"amount_at_create\":\"0.10000000\",\"price\":78522.62,\"price_str\":\"78522.62\",\"is_liquidation\":false},\"channel\":\"live_orders_btcusd\",\"event\":\"order_created\",\"event_id\":\"00065a1d-7f94-bb08-0000-000100000020\",\"pre_event_id\":\"00065a1d-7f94-af50-0000-000103000020\",\"order_source\":\"orderbook\"}","recorded_unix_us":1787932601322212}
{"message":"{\"data\":{\"id\":2044303878602752,\"id_str\":\"2044303878602752\",\"order_type\":1,\"order_subtype\":5,\"datetime\":\"1787932601\",\"microtimestamp\":\"1787932601269000\",\"amount\":0.1,\"amount_str\":\"0.10000000\",\"amount_traded\":\"0\",\"amount_at_create\":\"0.10000000\",\"price\":78522.62,\"price_str\":\"78522.62\",\"is_liquidation\":false},\"channel\":\"live_orders_btcusd\",\"event\":\"order_deleted\",\"event_id\":\"00065a1d-7f94-bb08-0001-000101000020\",\"pre_event_id\":\"00065a1d-7f94-bb08-0000-000100000020\",\"order_source\":\"orderbook\"}","recorded_unix_us":1787932601322312}
{"message":"{\"data\":{\"id\":2044303878602766,\"id_str\":\"2044303878602766\",\"order_type\":0,\"order_subtype\":5,\"datetime\":\"1787932601\",\"microtimestamp\":\"1787932601270000\",\"amount\":0.00140266,\"amount_str\":\"0.00140266\",\"amount_traded\":\"0\",\"amount_at_create\":\"0.00140266\",\"price\":70670.37,\"price_str\":\"70670.37\",\"is_liquidation\":false},\"channel\":\"live_orders_btcusd\",\"event\":\"order_created\",\"event_id\":\"00065a1d-7f94-bef0-0000-000102000020\",\"pre_event_id\":\"00065a1d-7f94-bb08-0001-000101000020\",\"order_source\":\"orderbook\"}","recorded_unix_us":1787932601322437}
{"message":"{\"data\":{\"id\":2044303878606856,\"id_str\":\"2044303878606856\",\"order_type\":1,\"order_subtype\":5,\"datetime\":\"1787932601\",\"microtimestamp\":\"1787932601271000\",\"amount\":0.1,\"amount_str\":\"0.10000000\",\"amount_traded\":\"0\",\"amount_at_create\":\"0.10000000\",\"price\":78522.63,\"price_str\":\"78522.63\",\"is_liquidation\":false},\"channel\":\"live_orders_btcusd\",\"event\":\"order_created\",\"event_id\":\"00065a1d-7f94-c2d8-0000-000103000020\",\"pre_event_id\":\"00065a1d-7f94-bef0-0000-000102000020\",\"order_source\":\"orderbook\"}","recorded_unix_us":1787932601322461}
{"message":"{\"data\":{\"id\":2044303878606856,\"id_str\":\"2044303878606856\",\"order_type\":1,\"order_subtype\":5,\"datetime\":\"1787932601\",\"microtimestamp\":\"1787932601271000\",\"amount\":0.1,\"amount_str\":\"0.10000000\",\"amount_traded\":\"0\",\"amount_at_create\":\"0.10000000\",\"price\":78522.63,\"price_str\":\"78522.63\",\"is_liquidation\":false},\"channel\":\"live_orders_btcusd\",\"event\":\"order_deleted\",\"event_id\":\"00065a1d-7f94-c2d8-0001-000100000020\",\"pre_event_id\":\"00065a1d-7f94-c2d8-0000-000103000020\",\"order_source\":\"orderbook\"}","recorded_unix_us":1787932601322539}
{"message":"{\"data\":{\"id\":2044303878619144,\"id_str\":\"2044303878619144\",\"order_type\":1,\"order_subtype\":5,\"datetime\":\"1787932601\",\"microtimestamp\":\"1787932601274000\",\"amount\":0.1,\"amount_str\":\"0.10000000\",\"amount_traded\":\"0\",\"amount_at_create\":\"0.10000000\",\"price\":78523.05,\"price_str\":\"78523.05\",\"is_liquidation\":false},\"channel\":\"live_orders_btcusd\",\"event\":\"order_created\",\"event_id\":\"00065a1d-7f94-ce90-0000-000101000020\",\"pre_event_id\":\"00065a1d-7f94-c2d8-0001-000100000020\",\"order_source\":\"orderbook\"}","recorded_unix_us":1787932601322654}
{"message":"{\"data\":{\"id\":2044303878631428,\"id_str\":\"2044303878631428\",\"order_type\":0,\"order_subtype\":5,\"datetime\":\"1787932601\",\"microtimestamp\":\"1787932601276000\",\"amount\":0.19103753,\"amount_str\":\"0.19103753\",\"amount_traded\":\"0\",\"amount_at_create\":\"0.19103753\",\"price\":78483.49,\"price_str\":\"78483.49\",\"is_liquidation\":false},\"channel\":\"live_orders_btcusd\",\"event\":\"order_created\",\"event_id\":\"00065a1d-7f94-d660-0000-000102000020\",\"pre_event_id\":\"00065a1d-7f94-ce90-0000-000101000020\",\"order_source\":\"orderbook\"}","recorded_unix_us":1787932601334778}
{"message":"{\"data\":{\"id\":2044303878631432,\"id_str\":\"2044303878631432\",\"order_type\":0,\"order_subtype\":5,\"datetime\":\"1787932601\",\"microtimestamp\":\"1787932601277000\",\"amount\":0.262273,\"amount_str\":\"0.262273\",\"amount_traded\":\"0\",\"amount_at_create\":\"0.262273\",\"price\":2480.01,\"price_str\":\"2480.01\",\"is_liquidation\":false},\"channel\":\"live_orders_ethusd\",\"event\":\"order_created\",\"event_id\":\"00065a1d-7f94-da48-0000-001203000020\",\"pre_event_id\":\"00065a1d-7f94-af50-0001-001202000020\",\"order_source\":\"orderbook\"}","recorded_unix_us":1787932601334850}
{"message":"{\"data\":{\"id\":2044303878643712,\"id_str\":\"2044303878643712\",\"order_type\":0,\"order_subtype\":5,\"datetime\":\"1787932601\",\"microtimestamp\":\"1787932601279000\",\"amount\":1.65847856,\"amount_str\":\"1.65847856\",\"amount_traded\":\"0\",\"amount_at_create\":\"1.65847856\",\"price\":0.03020012,\"price_str\":\"0.03020012\",\"is_liquidation\":false},\"channel\":\"live_orders_ethbtc\",\"event\":\"order_created\",\"event_id\":\"00065a1d-7f94-e218-0000-001103000020\",\"pre_event_id\":\"00065a1d-7f92-f9d0-0000-001102000020\",\"order_source\":\"orderbook\"}","recorded_unix_us":1787932601334982}
{"message":"{\"data\":{\"id\":2044303877955592,\"id_str\":\"2044303877955592\",\"order_type\":0,\"order_subtype\":5,\"datetime\":\"1787932601\",\"microtimestamp\":\"1787932601283000\",\"amount\":0.00140266,\"amount_str\":\"0.00140266\",\"amount_traded\":\"0\",\"amount_at_create\":\"0.00140266\",\"price\":70670.37,\"price_str\":\"70670.37\",\"is_liquidation\":false},\"channel\":\"live_orders_btcusd\",\"event\":\"order_deleted\",\"event_id\":\"00065a1d-7f94-f1b8-0000-000103000020\",\"pre_event_id\":\"00065a1d-7f94-d660-0000-000102000020\",\"order_source\":\"orderbook\"}","recorded_unix_us":1787932601335105}
{"message":"{\"data\":{\"id\":2044303878639616,\"id_str\":\"2044303878639616\",\"order_type\":0,\"order_subtype\":5,\"datetime\":\"1787932601\",\"microtimestamp\":\"1787932601283000\",\"amount\":0.403103,\"amount_str\":\"0.403103\",\"amount_traded\":\"0\",\"amount_at_create\":\"0.403103\",\"price\":2479.78,\"price_str\":\"2479.78\",\"is_liquidation\":false},\"channel\":\"live_orders_ethusd\",\"event\":\"order_created\",\"event_id\":\"00065a1d-7f94-f1b8-0000-001200000020\",\"pre_event_id\":\"00065a1d-7f94-da48-0000-001203000020\",\"order_source\":\"orderbook\"}","recorded_unix_us":1787932601335145}
{"message":"{\"data\":{\"id\":2044303878008837,\"id_str\":\"2044303878008837\",\"order_type\":0,\"order_subtype\":5,\"datetime\":\"1787932601\",\"microtimestamp\":\"1787932601283000\",\"amount\":0.403103,\"amount_str\":\"0.403103\",\"amount_traded\":\"0\",\"amount_at_create\":\"0.403103\",\"price\":2480.25,\"price_str\":\"2480.25\",\"is_liquidation\":false},\"channel\":\"live_orders_ethusd\",\"event\":\"order_deleted\",\"event_id\":\"00065a1d-7f94-f1b8-0001-001201000020\",\"pre_event_id\":\"00065a1d-7f94-f1b8-0000-001200000020\",\"order_source\":\"orderbook\"}","recorded_unix_us":1787932601335223}
{"message":"{\"data\":{\"id\":2044303878660115,\"id_str\":\"2044303878660115\",\"order_type\":1,\"order_subtype\":0,\"datetime\":\"1787932601\",\"microtimestamp\":\"1787932601284000\",\"amount\":0.00025,\"amount_str\":\"0.00025000\",\"amount_traded\":\"0\",\"amount_at_create\":\"0.00025000\",\"price\":78587,\"price_str\":\"78587.00\",\"is_liquidation\":false},\"channel\":\"live_orders_btcusd\",\"event\":\"order_created\",\"event_id\":\"00065a1d-7f94-f5a0-0000-000100000020\",\"pre_event_id\":\"00065a1d-7f94-f1b8-0000-000103000020\",\"order_source\":\"orderbook\"}","recorded_unix_us":1787932601335291}
{"message":"{\"data\":{\"id\":2044303878639616,\"id_str\":\"2044303878639616\",\"order_type\":0,\"order_subtype\":5,\"datetime\":\"1787932601\",\"microtimestamp\":\"1787932601287000\",\"amount\":0.403103,\"amount_str\":\"0.403103\",\"amount_traded\":\"0\",\"amount_at_create\":\"0.403103\",\"price\":2479.78,\"price_str\":\"2479.78\",\"is_liquidation\":false},\"channel\":\"live_orders_ethusd\",\"event\":\"order_deleted\",\"event_id\":\"00065a1d-7f95-0158-0000-001202000020\",\"pre_event_id\":\"00065a1d-7f94-f1b8-0001-001201000020\",\"order_source\":\"orderbook\"}","recorded_unix_us":1787932601335359}
{"message":"{\"data\":{\"id\":2044303878676498,\"id_str\":\"2044303878676498\",\"order_type\":0,\"order_subtype\":5,\"datetime\":\"1787932601\",\"microtimestamp\":\"1787932601288000\",\"amount\":0.403104,\"amount_str\":\"0.403104\",\"amount_traded\":\"0\",\"amount_at_create\":\"0.403104\",\"price\":2479.5,\"price_str\":\"2479.50\",\"is_liquidation\":false},\"channel\":\"live_orders_ethusd\",\"event\":\"order_created\",\"event_id\":\"00065a1d-7f95-0540-0000-001203000020\",\"pre_event_id\":\"00065a1d-7f95-0158-0000-001202000020\",\"order_source\":\"orderbook\"}","recorded_unix_us":1787932601335425}
{"message":"{\"data\":{\"id\":2044303878680580,\"id_str\":\"2044303878680580\",\"order_type\":1,\"order_subtype\":5,\"datetime\":\"1787932601\",\"microtimestamp\":\"1787932601288000\",\"amount\":0.00254665,\"amount_str\":\"0.00254665\",\"amount_traded\":\"0\",\"amount_at_create\":\"0.00254665\",\"price\":78534.59,\"price_str\":\"78534.59\",\"is_liquidation\":false},\"channel\":\"live_orders_btcusd\",\"event\":\"order_created\",\"event_id\":\"00065a1d-7f95-0540-0000-000101000020\",\"pre_event_id\":\"00065a1d-7f94-f5a0-0000-000100000020\",\"order_source\":\"orderbook\"}","recorded_unix_us":1787932601335490}
{"message":"{\"data\":{\"id\":2044303878684678,\"id_str\":\"2044303878684678\",\"order_type\":0,\"order_subtype\":5,\"datetime\":\"1787932601\",\"microtimestamp\":\"1787932601289000\",\"amount\":0.403103,\"amount_str\":\"0.403103\",\"amount_traded\":\"0\",\"amount_at_create\":\"0.403103\",\"price\":2480.01,\"price_str\":\"2480.01\",\"is_liquidation\":false},\"channel\":\"live_orders_ethusd\",\"event\":\"order_created\",\"event_id\":\"00065a1d-7f95-0928-0000-001200000020\",\"pre_event_id\":\"00065a1d-7f95-0540-0000-001203000020\",\"order_source\":\"orderbook\"}","recorded_unix_us":1787932601335555}
{"message":"{\"data\":{\"id\":2044303877971968,\"id_str\":\"2044303877971968\",\"order_type\":1,\"order_subtype\":5,\"datetime\":\"1787932601\",\"microtimestamp\":\"1787932601297000\",\"amount\":0.1,\"amount_str\":\"0.10000000\",\"amount_traded\":\"0\",\"amount_at_create\":\"0.10000000\",\"price\":78523.45,\"price_str\":\"78523.45\",\"is_liquidation\":false},\"channel\":\"live_orders_btcusd\",\"event\":\"order_deleted\",\"event_id\":\"00065a1d-7f95-2868-0000-000102000020\",\"pre_event_id\":\"00065a1d-7f95-0540-0000-000101000020\",\"order_source\":\"orderbook\"}","recorded_unix_us":1787932601335622}
{"message":"{\"data\":{\"id\":2044303878725651,\"id_str\":\"2044303878725651\",\"order_type\":0,\"order_subtype\":5,\"datetime\":\"1787932601\",\"microtimestamp\":\"1787932601300000\",\"amount\":0.0025477,\"amount_str\":\"0.00254770\",\"amount_traded\":\"0\",\"amount_at_create\":\"0.00254770\",\"price\":78502.27,\"price_str\":\"78502.27\",\"is_liquidation\":false},\"channel\":\"live_orders_btcusd\",\"event\":\"order_created\",\"event_id\":\"00065a1d-7f95-3420-0000-000103000020\",\"pre_event_id\":\"00065a1d-7f95-2868-0000-000102000020\",\"order_source\":\"orderbook\"}","recorded_unix_us":1787932601344563}
{"message":"{\"data\":{\"id\":2044303877378048,\"id_str\":\"2044303877378048\",\"order_type\":1,\"order_subtype\":5,\"datetime\":\"1787932601\",\"microtimestamp\":\"1787932601310000\",\"amount\":0.06367563,\"amount_str\":\"0.06367563\",\"amount_traded\":\"0\",\"amount_at_create\":\"0.06367563\",\"price\":78522.98,\"price_str\":\"78522.98\",\"is_liquidation\":false},\"channel\":\"live_orders_btcusd\",\"event\":\"order_deleted\",\"event_id\":\"00065a1d-7f95-5b30-0000-000100000020\",\"pre_event_id\":\"00065a1d-7f95-3420-0000-000103000020\",\"order_source\":\"orderbook\"}","recorded_unix_us":1787932601345739}
{"message":"{\"data\":{\"id\":2044303877513221,\"id_str\":\"2044303877513221\",\"order_type\":1,\"order_subtype\":5,\"datetime\":\"1787932601\",\"microtimestamp\":\"1787932601311000\",\"amount\":0.06367384,\"amount_str\":\"0.06367384\",\"amount_traded\":\"0\",\"amount_at_create\":\"0.06367384\",\"price\":78525.19,\"price_str\":\"78525.19\",\"is_liquidation\":false},\"channel\":\"live_orders_btcusd\",\"event\":\"order_deleted\",\"event_id\":\"00065a1d-7f95-5f18-0000-000101000020\",\"pre_event_id\":\"00065a1d-7f95-5b30-0000-000100000020\",\"order_source\":\"orderbook\"}","recorded_unix_us":1787932601345763}
{"message":"{\"data\":{\"id\":2044303877513222,\"id_str\":\"2044303877513222\",\"order_type\":1,\"order_subtype\":5,\"datetime\":\"1787932601\",\"microtimestamp\":\"1787932601311000\",\"amount\":0.25467128,\"amount_str\":\"0.25467128\",\"amount_traded\":\"0\",\"amount_at_create\":\"0.25467128\",\"price\":78532.61,\"price_str\":\"78532.61\",\"is_liquidation\":false},\"channel\":\"live_orders_btcusd\",\"event\":\"order_deleted\",\"event_id\":\"00065a1d-7f95-5f18-0001-000102000020\",\"pre_event_id\":\"00065a1d-7f95-5f18-0000-000101000020\",\"order_source\":\"orderbook\"}","recorded_unix_us":1787932601345847}
{"message":"{\"data\":{\"id\":2044303877517313,\"id_str\":\"2044303877517313\",\"order_type\":1,\"order_subtype\":5,\"datetime\":\"1787932601\",\"microtimestamp\":\"1787932601311000\",\"amount\":0.25466146,\"amount_str\":\"0.25466146\",\"amount_traded\":\"0\",\"amount_at_create\":\"0.25466146\",\"price\":78535.64,\"price_str\":\"78535.64\",\"is_liquidation\":false},\"channel\":\"live_orders_btcusd\",\"event\":\"order_deleted\",\"event_id\":\"00065a1d-7f95-5f18-0002-000103000020\",\"pre_event_id\":\"00065a1d-7f95-5f18-0001-000102000020\",\"order_source\":\"orderbook\"}","recorded_unix_us":1787932601345961}
{"message":"{\"data\":{\"id\":2044303877517320,\"id_str\":\"2044303877517320\",\"order_type\":1,\"order_subtype\":5,\"datetime\":\"1787932601\",\"microtimestamp\":\"1787932601312000\",\"amount\":1.27209222,\"amount_str\":\"1.27209222\",\"amount_traded\":\"0\",\"amount_at_create\":\"1.27209222\",\"price\":78610.66,\"price_str\":\"78610.66\",\"is_liquidation\":false},\"channel\":\"live_orders_btcusd\",\"event\":\"order_deleted\",\"event_id\":\"00065a1d-7f95-6300-0000-000100000020\",\"pre_event_id\":\"00065a1d-7f95-5f18-0002-000103000020\",\"order_source\":\"orderbook\"}","recorded_unix_us":1787932601345984}
{"message":"{\"data\":{\"id\":2044303878774791,\"id_str\":\"2044303878774791\",\"order_type\":1,\"order_subtype\":5,\"datetime\":\"1787932601\",\"microtimestamp\":\"1787932601312000\",\"amount\":0.1,\"amount_str\":\"0.10000000\",\"amount_traded\":\"0\",\"amount_at_create\":\"0.10000000\",\"price\":78522.62,\"price_str\":\"78522.62\",\"is_liquidation\":false},\"channel\":\"live_orders_btcusd\",\"event\":\"order_created\",\"event_id\":\"00065a1d-7f95-6300-0001-000101000020\",\"pre_event_id\":\"00065a1d-7f95-6300-0000-000100000020\",\"order_source\":\"orderbook\"}","recorded_unix_us":1787932601420717}
{"message":"{\"data\":{\"id\":2044303878774791,\"id_str\":\"2044303878774791\",\"order_type\":1,\"order_subtype\":5,\"datetime\":\"1787932601\",\"microtimestamp\":\"1787932601312000\",\"amount\":0.1,\"amount_str\":\"0.10000000\",\"amount_traded\":\"0\",\"amount_at_create\":\"0.10000000\",\"price\":78522.62,\"price_str\":\"78522.62\",\"is_liquidation\":false},\"channel\":\"live_orders_btcusd\",\"event\":\"order_deleted\",\"event_id\":\"00065a1d-7f95-6300-0002-000102000020\",\"pre_event_id\":\"00065a1d-7f95-6300-0001-000101000020\",\"order_source\":\"orderbook\"}","recorded_unix_us":1787932601420776}
{"message":"{\"data\":{\"id\":2044303877521409,\"id_str\":\"2044303877521409\",\"order_type\":1,\"order_subtype\":5,\"datetime\":\"1787932601\",\"microtimestamp\":\"1787932601312000\",\"amount\":12.70451953,\"amount_str\":\"12.70451953\",\"amount_traded\":\"0\",\"amount_at_create\":\"12.70451953\",\"price\":78712.15,\"price_str\":\"78712.15\",\"is_liquidation\":false},\"channel\":\"live_orders_btcusd\",\"event\":\"order_deleted\",\"event_id\":\"00065a1d-7f95-6300-0003-000103000020\",\"pre_event_id\":\"00065a1d-7f95-6300-0002-000102000020\",\"order_source\":\"orderbook\"}","recorded_unix_us":1787932601420925}
{"message":"{\"data\":{\"id\":2044303877521413,\"id_str\":\"2044303877521413\",\"order_type\":1,\"order_subtype\":5,\"datetime\":\"1787932601\",\"microtimestamp\":\"1787932601312000\",\"amount\":1.2684012,\"amount_str\":\"1.26840120\",\"amount_traded\":\"0\",\"amount_at_create\":\"1.26840120\",\"price\":78839.41,\"price_str\":\"78839.41\",\"is_liquidation\":false},\"channel\":\"live_orders_btcusd\",\"event\":\"order_deleted\",\"event_id\":\"00065a1d-7f95-6300-0004-000100000020\",\"pre_event_id\":\"00065a1d-7f95-6300-0003-000103000020\",\"order_source\":\"orderbook\"}","recorded_unix_us":1787932601420952}
{"message":"{\"data\":{\"id\":2044303877525504,\"id_str\":\"2044303877525504\",\"order_type\":1,\"order_subtype\":5,\"datetime\":\"1787932601\",\"microtimestamp\":\"1787932601312000\",\"amount\":1.26970017,\"amount_str\":\"1.26970017\",\"amount_traded\":\"0\",\"amount_at_create\":\"1.26970017\",\"price\":78758.76,\"price_str\":\"78758.76\",\"is_liquidation\":false},\"channel\":\"live_orders_btcusd\",\"event\":\"order_deleted\",\"event_id\":\"00065a1d-7f95-6300-0005-000101000020\",\"pre_event_id\":\"00065a1d-7f95-6300-0004-000100000020\",\"order_source\":\"orderbook\"}","recorded_unix_us":1787932601421057}
{"message":"{\"data\":{\"id\":2044303877648389,\"id_str\":\"2044303877648389\",\"order_type\":1,\"order_subtype\":5,\"datetime\":\"1787932601\",\"microtimestamp\":\"1787932601313000\",\"amount\":1.26842789,\"amount_str\":\"1.26842789\",\"amount_traded\":\"0\",\"amount_at_create\":\"1.26842789\",\"price\":78837.75,\"price_str\":\"78837.75\",\"is_liquidation\":false},\"channel\":\"live_orders_btcusd\",\"event\":\"order_deleted\",\"event_id\":\"00065a1d-7f95-66e8-0000-000102000020\",\"pre_event_id\":\"00065a1d-7f95-6300-0005-000101000020\",\"order_source\":\"orderbook\"}","recorded_unix_us":1787932601421168}
{"message":"{\"data\":{\"id\":2044303877660694,\"id_str\":\"2044303877660694\",\"order_type\":1,\"order_subtype\":5,\"datetime\":\"1787932601\",\"microtimestamp\":\"1787932601313000\",\"amount\":1.271772,\"amount_str\":\"1.27177200\",\"amount_traded\":\"0\",\"amount_at_create\":\"1.27177200\",\"price\":78630.45,\"price_str\":\"78630.45\",\"is_liquidation\":false},\"channel\":\"live_orders_btcusd\",\"event\":\"order_deleted\",\"event_id\":\"00065a1d-7f95-66e8-0001-000103000020\",\"pre_event_id\":\"00065a1d-7f95-66e8-0000-000102000020\",\"order_source\":\"orderbook\"}","recorded_unix_us":1787932601421296}
{"message":"{\"data\":{\"id\":2044303877681159,\"id_str\":\"2044303877681159\",\"order_type\":0,\"order_subtype\":5,\"datetime\":\"1787932601\",\"microtimestamp\":\"1787932601313000\",\"amount\":0.06368334,\"amount_str\":\"0.06368334\",\"amount_traded\":\"0\",\"amount_at_create\":\"0.06368334\",\"price\":78513.46,\"price_str\":\"78513.46\",\"is_liquidation\":false},\"channel\":\"live_orders_btcusd\",\"event\":\"order_deleted\",\"event_id\":\"00065a1d-7f95-66e8-0002-000100000020\",\"pre_event_id\":\"00065a1d-7f95-66e8-0001-000103000020\",\"order_source\":\"orderbook\"}","recorded_unix_us":1787932601421345}
{"message":"{\"data\":{\"id\":2044303877685248,\"id_str\":\"2044303877685248\",\"order_type\":0,\"order_subtype\":5,\"datetime\":\"1787932601\",\"microtimestamp\":\"1787932601314000\",\"amount\":0.25478772,\"amount_str\":\"0.25478772\",\"amount_traded\":\"0\",\"amount_at_create\":\"0.25478772\",\"price\":78496.71,\"price_str\":\"78496.71\",\"is_liquidation\":false},\"channel\":\"live_orders_btcusd\",\"event\":\"order_deleted\",\"event_id\":\"00065a1d-7f95-6ad0-0000-000101000020\",\"pre_event_id\":\"00065a1d-7f95-66e8-0002-000100000020\",\"order_source\":\"orderbook\"}","recorded_unix_us":1787932601421467}
{"message":"{\"data\":{\"id\":2044303878787072,\"id_str\":\"2044303878787072\",\"order_type\":1,\"order_subtype\":5,\"datetime\":\"1787932601\",\"microtimestamp\":\"1787932601314000\",\"amount\":0.1,\"amount_str\":\"0.10000000\",\"amount_traded\":\"0\",\"amount_at_create\":\"0.10000000\",\"price\":78522.63,\"price_str\":\"78522.63\",\"is_liquidation\":false},\"channel\":\"live_orders_btcusd\",\"event\":\"order_created\",\"event_id\":\"00065a1d-7f95-6ad0-0001-000102000020\",\"pre_event_id\":\"00065a1d-7f95-6ad0-0000-000101000020\",\"order_source\":\"orderbook\"}","recorded_unix_us":1787932601421501}
{"message":"{\"data\":{\"id\":2044303878787072,\"id_str\":\"2044303878787072\",\"order_type\":1,\"order_subtype\":5,\"datetime\":\"1787932601\",\"microtimestamp\":\"1787932601314000\",\"amount\":0.1,\"amount_str\":\"0.10000000\",\"amount_traded\":\"0\",\"amount_at_create\":\"0.10000000\",\"price\":78522.63,\"price_str\":\"78522.63\",\"is_liquidation\":false},\"channel\":\"live_orders_btcusd\",\"event\":\"order_deleted\",\"event_id\":\"00065a1d-7f95-6ad0-0002-000103000020\",\"pre_event_id\":\"00065a1d-7f95-6ad0-0001-000102000020\",\"order_source\":\"orderbook\"}","recorded_unix_us":1787932601421640}
{"message":"{\"data\":{\"id\":2044303877689348,\"id_str\":\"2044303877689348\",\"order_type\":0,\"order_subtype\":5,\"datetime\":\"1787932601\",\"microtimestamp\":\"1787932601314000\",\"amount\":1.27567513,\"amount_str\":\"1.27567513\",\"amount_traded\":\"0\",\"amount_at_create\":\"1.27567513\",\"price\":78389.86,\"price_str\":\"78389.86\",\"is_liquidation\":false},\"channel\":\"live_orders_btcusd\",\"event\":\"order_deleted\",\"event_id\":\"00065a1d-7f95-6ad0-0003-000100000020\",\"pre_event_id\":\"00065a1d-7f95-6ad0-0002-000103000020\",\"order_source\":\"orderbook\"}","recorded_unix_us":1787932601421671}
{"message":"{\"data\":{\"id\":2044303878787076,\"id_str\":\"2044303878787076\",\"order_type\":1,\"order_subtype\":5,\"datetime\":\"1787932601\",\"microtimestamp\":\"1787932601314000\",\"amount\":0.1,\"amount_str\":\"0.10000000\",\"amount_traded\":\"0\",\"amount_at_create\":\"0.10000000\",\"price\":78523,\"price_str\":\"78523.00\",\"is_liquidation\":false},\"channel\":\"live_orders_btcusd\",\"event\":\"order_created\",\"event_id\":\"00065a1d-7f95-6ad0-0004-000101000020\",\"pre_event_id\":\"00065a1d-7f95-6ad0-0003-000100000020\",\"order_source\":\"orderbook\"}","recorded_unix_us":1787932601421694}
{"message":"{\"data\":{\"id\":2044303877689349,\"id_str\":\"2044303877689349\",\"order_type\":0,\"order_subtype\":5,\"datetime\":\"1787932601\",\"microtimestamp\":\"1787932601314000\",\"amount\":1.27541152,\"amount_str\":\"1.27541152\",\"amount_traded\":\"0\",\"amount_at_create\":\"1.27541152\",\"price\":78406.06,\"price_str\":\"78406.06\",\"is_liquidation\":false},\"channel\":\"live_orders_btcusd\",\"event\":\"order_deleted\",\"event_id\":\"00065a1d-7f95-6ad0-0005-000102000020\",\"pre_event_id\":\"00065a1d-7f95-6ad0-0004-000101000020\",\"order_source\":\"orderbook\"}","recorded_unix_us":1787932601421775}
{"message":"{\"data\":{\"id\":2044303877693441,\"id_str\":\"2044303877693441\",\"order_type\":0,\"order_subtype\":5,\"datetime\":\"1787932601\",\"microtimestamp\":\"1787932601315000\",\"amount\":1.27507828,\"amount_str\":\"1.27507828\",\"amount_traded\":\"0\",\"amount_at_create\":\"1.27507828\",\"price\":78426.55,\"price_str\":\"78426.55\",\"is_liquidation\":false},\"channel\":\"live_orders_btcusd\",\"event\":\"order_deleted\",\"event_id\":\"00065a1d-7f95-6eb8-0000-000103000020\",\"pre_event_id\":\"00065a1d-7f95-6ad0-0005-000102000020\",\"order_source\":\"orderbook\"}","recorded_unix_us":1787932601421882}
{"message":"{\"data\":{\"id\":2044303877742596,\"id_str\":\"2044303877742596\",\"order_type\":0,\"order_subtype\":5,\"datetime\":\"1787932601\",\"microtimestamp\":\"1787932601315000\",\"amount\":12.76418733,\"amount_str\":\"12.76418733\",\"amount_traded\":\"0\",\"amount_at_create\":\"12.76418733\",\"price\":78344.19,\"price_str\":\"78344.19\",\"is_liquidation\":false},\"channel\":\"live_orders_btcusd\",\"event\":\"order_deleted\",\"event_id\":\"00065a1d-7f95-6eb8-0001-000100000020\",\"pre_event_id\":\"00065a1d-7f95-6eb8-0000-000103000020\",\"order_source\":\"orderbook\"}","recorded_unix_us":1787932601421907}
{"message":"{\"data\":{\"id\":2044303877795854,\"id_str\":\"2044303877795854\",\"order_type\":0,\"order_subtype\":5,\"datetime\":\"1787932601\",\"microtimestamp\":\"1787932601315000\",\"amount\":1.27757154,\"amount_str\":\"1.27757154\",\"amount_traded\":\"0\",\"amount_at_create\":\"1.27757154\",\"price\":78273.5,\"price_str\":\"78273.50\",\"is_liquidation\":false},\"channel\":\"live_orders_btcusd\",\"event\":\"order_deleted\",\"event_id\":\"00065a1d-7f95-6eb8-0002-000101000020\",\"pre_event_id\":\"00065a1d-7f95-6eb8-0001-000100000020\",\"order_source\":\"orderbook\"}","recorded_unix_us":1787932601421988}
{"message":"{\"data\":{\"id\":2044303877918729,\"id_str\":\"2044303877918729\",\"order_type\":1,\"order_subtype\":5,\"datetime\":\"1787932601\",\"microtimestamp\":\"1787932601316000\",\"amount\":1.27145262,\"amount_str\":\"1.27145262\",\"amount_traded\":\"0\",\"amount_at_create\":\"1.27145262\",\"price\":78650.2,\"price_str\":\"78650.20\",\"is_liquidation\":false},\"channel\":\"live_orders_btcusd\",\"event\":\"order_deleted\",\"event_id\":\"00065a1d-7f95-72a0-0000-000102000020\",\"pre_event_id\":\"00065a1d-7f95-6eb8-0002-000101000020\",\"order_source\":\"orderbook\"}","recorded_unix_us":1787932601422097}
{"message":"{\"data\":{\"id\":2044303877935115,\"id_str\":\"2044303877935115\",\"order_type\":0,\"order_subtype\":5,\"datetime\":\"1787932601\",\"microtimestamp\":\"1787932601316000\",\"amount\":1.27604867,\"amount_str\":\"1.27604867\",\"amount_traded\":\"0\",\"amount_at_create\":\"1.27604867\",\"price\":78366.91,\"price_str\":\"78366.91\",\"is_liquidation\":false},\"channel\":\"live_orders_btcusd\",\"event\":\"order_deleted\",\"event_id\":\"00065a1d-7f95-72a0-0001-000103000020\",\"pre_event_id\":\"00065a1d-7f95-72a0-0000-000102000020\",\"order_source\":\"orderbook\"}","recorded_unix_us":1787932601422124}
{"message":"{\"data\":{\"id\":2044303877939204,\"id_str\":\"2044303877939204\",\"order_type\":0,\"order_subtype\":5,\"datetime\":\"1787932601\",\"microtimestamp\":\"1787932601316000\",\"amount\":1.27817952,\"amount_str\":\"1.27817952\",\"amount_traded\":\"0\",\"amount_at_create\":\"1.27817952\",\"price\":78236.27,\"price_str\":\"78236.27\",\"is_liquidation\":false},\"channel\":\"live_orders_btcusd\",\"event\":\"order_deleted\",\"event_id\":\"00065a1d-7f95-72a0-0002-000100000020\",\"pre_event_id\":\"00065a1d-7f95-72a0-0001-000103000020\",\"order_source\":\"orderbook\"}","recorded_unix_us":1787932601422198}
{"message":"{\"data\":{\"id\":2044303878811654,\"id_str\":\"2044303878811654\",\"order_type\":1,\"order_subtype\":5,\"datetime\":\"1787932601\",\"microtimestamp\":\"1787932601320000\",\"amount\":2.01528391,\"amount_str\":\"2.01528391\",\"amount_traded\":\"0\",\"amount_at_create\":\"2.01528391\",\"price\":0.03160301,\"price_str\":\"0.03160301\",\"is_liquidation\":false},\"channel\":\"live_orders_ethbtc\",\"event\":\"order_created\",\"event_id\":\"00065a1d-7f95-8240-0000-001100000020\",\"pre_event_id\":\"00065a1d-7f94-e218-0000-001103000020\",\"order_source\":\"orderbook\"}","recorded_unix_us":1787932601422343}
{"message":"{\"data\":{\"id\":2044303877382144,\"id_str\":\"2044303877382144\",\"order_type\":1,\"order_subtype\":5,\"datetime\":\"1787932601\",\"microtimestamp\":\"1787932601328000\",\"amount\":4.02232075,\"amount_str\":\"4.02232075\",\"amount_traded\":\"0\",\"amount_at_create\":\"4.02232075\",\"price\":0.03165997,\"price_str\":\"0.03165997\",\"is_liquidation\":false},\"channel\":\"live_orders_ethbtc\",\"event\":\"order_deleted\",\"event_id\":\"00065a1d-7f95-a180-0000-001101000020\",\"pre_event_id\":\"00065a1d-7f95-8240-0000-001100000020\",\"order_source\":\"orderbook\"}","recorded_unix_us":1787932601422369}
{"message":"{\"data\":{\"id\":2044303877517317,\"id_str\":\"2044303877517317\",\"order_type\":1,\"order_subtype\":5,\"datetime\":\"1787932601\",\"microtimestamp\":\"1787932601329000\",\"amount\":0.60446465,\"amount_str\":\"0.60446465\",\"amount_traded\":\"0\",\"amount_at_create\":\"0.60446465\",\"price\":0.03160302,\"price_str\":\"0.03160302\",\"is_liquidation\":false},\"channel\":\"live_orders_ethbtc\",\"event\":\"order_deleted\",\"event_id\":\"00065a1d-7f95-a568-0000-001102000020\",\"pre_event_id\":\"00065a1d-7f95-a180-0000-001101000020\",\"order_source\":\"orderbook\"}","recorded_unix_us":1787932601422465}
{"message":"{\"data\":{\"id\":2044303877525505,\"id_str\":\"2044303877525505\",\"order_type\":1,\"order_subtype\":5,\"datetime\":\"1787932601\",\"microtimestamp\":\"1787932601329000\",\"amount\":3.02055629,\"amount_str\":\"3.02055629\",\"amount_traded\":\"0\",\"amount_at_create\":\"3.02055629\",\"price\":0.03162186,\"price_str\":\"0.03162186\",\"is_liquidation\":false},\"channel\":\"live_orders_ethbtc\",\"event\":\"order_deleted\",\"event_id\":\"00065a1d-7f95-a568-0001-001103000020\",\"pre_event_id\":\"00065a1d-7f95-a568-0000-001102000020\",\"order_source\":\"orderbook\"}","recorded_unix_us":1787932601422694}
{"message":"{\"data\":{\"id\":2044303877525506,\"id_str\":\"2044303877525506\",\"order_type\":1,\"order_subtype\":5,\"datetime\":\"1787932601\",\"microtimestamp\":\"1787932601329000\",\"amount\":2.01386943,\"amount_str\":\"2.01386943\",\"amount_traded\":\"0\",\"amount_at_create\":\"2.01386943\",\"price\":0.0316184,\"price_str\":\"0.03161840\",\"is_liquidation\":false},\"channel\":\"live_orders_ethbtc\",\"event\":\"order_deleted\",\"event_id\":\"00065a1d-7f95-a568-0002-001100000020\",\"pre_event_id\":\"00065a1d-7f95-a568-0001-001103000020\",\"order_source\":\"orderbook\"}","recorded_unix_us":1787932601422720}
{"message":"{\"data\":{\"id\":2044303877529603,\"id_str\":\"2044303877529603\",\"order_type\":0,\"order_subtype\":5,\"datetime\":\"1787932601\",\"microtimestamp\":\"1787932601330000\",\"amount\":0.6048199,\"amount_str\":\"0.60481990\",\"amount_traded\":\"0\",\"amount_at_create\":\"0.60481990\",\"price\":0.03158573,\"price_str\":\"0.03158573\",\"is_liquidation\":false},\"channel\":\"live_orders_ethbtc\",\"event\":\"order_deleted\",\"event_id\":\"00065a1d-7f95-a950-0000-001101000020\",\"pre_event_id\":\"00065a1d-7f95-a568-0002-001100000020\",\"order_source\":\"orderbook\"}","recorded_unix_us":1787932601422741}
{"message":"{\"data\":{\"id\":2044303877533698,\"id_str\":\"2044303877533698\",\"order_type\":0,\"order_subtype\":5,\"datetime\":\"1787932601\",\"microtimestamp\":\"1787932601330000\",\"amount\":1.00801353,\"amount_str\":\"1.00801353\",\"amount_traded\":\"0\",\"amount_at_create\":\"1.00801353\",\"price\":0.03158534,\"price_str\":\"0.03158534\",\"is_liquidation\":false},\"channel\":\"live_orders_ethbtc\",\"event\":\"order_deleted\",\"event_id\":\"00065a1d-7f95-a950-0001-001102000020\",\"pre_event_id\":\"00065a1d-7f95-a950-0000-001101000020\",\"order_source\":\"orderbook\"}","recorded_unix_us":1787932601422849}
{"message":"{\"data\":{\"id\":2044303877533699,\"id_str\":\"2044303877533699\",\"order_type\":1,\"order_subtype\":5,\"datetime\":\"1787932601\",\"microtimestamp\":\"1787932601330000\",\"amount\":1.00740464,\"amount_str\":\"1.00740464\",\"amount_traded\":\"0\",\"amount_at_create\":\"1.00740464\",\"price\":0.03160452,\"price_str\":\"0.03160452\",\"is_liquidation\":false},\"channel\":\"live_orders_ethbtc\",\"event\":\"order_deleted\",\"event_id\":\"00065a1d-7f95-a950-0002-001103000020\",\"pre_event_id\":\"00065a1d-7f95-a950-0001-001102000020\",\"order_source\":\"orderbook\"}","recorded_unix_us":1787932601422884}
{"message":"{\"data\":{\"id\":2044303877537801,\"id_str\":\"2044303877537801\",\"order_type\":0,\"order_subtype\":5,\"datetime\":\"1787932601\",\"microtimestamp\":\"1787932601331000\",\"amount\":2.01629689,\"amount_str\":\"2.01629689\",\"amount_traded\":\"0\",\"amount_at_create\":\"2.01629689\",\"price\":0.03157941,\"price_str\":\"0.03157941\",\"is_liquidation\":false},\"channel\":\"live_orders_ethbtc\",\"event\":\"order_deleted\",\"event_id\":\"00065a1d-7f95-ad38-0000-001100000020\",\"pre_event_id\":\"00065a1d-7f95-a950-0002-001103000020\",\"order_source\":\"orderbook\"}","recorded_unix_us":1787932601422999}
{"message":"{\"data\":{\"id\":2044303877537803,\"id_str\":\"2044303877537803\",\"order_type\":0,\"order_subtype\":5,\"datetime\":\"1787932601\",\"microtimestamp\":\"1787932601331000\",\"amount\":4.03662068,\"amount_str\":\"4.03662068\",\"amount_traded\":\"0\",\"amount_at_create\":\"4.03662068\",\"price\":0.03154857,\"price_str\":\"0.03154857\",\"is_liquidation\":false},\"channel\":\"live_orders_ethbtc\",\"event\":\"order_deleted\",\"event_id\":\"00065a1d-7f95-ad38-0001-001101000020\",\"pre_event_id\":\"00065a1d-7f95-ad38-0000-001100000020\",\"order_source\":\"orderbook\"}","recorded_unix_us":1787932601423024}
{"message":"{\"data\":{\"id\":2044303877537806,\"id_str\":\"2044303877537806\",\"order_type\":0,\"order_subtype\":5,\"datetime\":\"1787932601\",\"microtimestamp\":\"1787932601331000\",\"amount\":3.02537254,\"amount_str\":\"3.02537254\",\"amount_traded\":\"0\",\"amount_at_create\":\"3.02537254\",\"price\":0.03156999,\"price_str\":\"0.03156999\",\"is_liquidation\":false},\"channel\":\"live_orders_ethbtc\",\"event\":\"order_deleted\",\"event_id\":\"00065a1d-7f95-ad38-0002-001102000020\",\"pre_event_id\":\"00065a1d-7f95-ad38-0001-001101000020\",\"order_source\":\"orderbook\"}","recorded_unix_us":1787932601423141}
{"message":"{\"data\":{\"id\":2044303878901771,\"id_str\":\"2044303878901771\",\"order_type\":1,\"order_subtype\":5,\"datetime\":\"1787932601\",\"microtimestamp\":\"1787932601343000\",\"amount\":0.1,\"amount_str\":\"0.10000000\",\"amount_traded\":\"0\",\"amount_at_create\":\"0.10000000\",\"price\":78522.62,\"price_str\":\"78522.62\",\"is_liquidation\":false},\"channel\":\"live_orders_btcusd\",\"event\":\"order_created\",\"event_id\":\"00065a1d-7f95-dc18-0000-000101000020\",\"pre_event_id\":\"00065a1d-7f95-72a0-0002-000100000020\",\"order_source\":\"orderbook\"}","recorded_unix_us":1787932601423218}
{"message":"{\"data\":{\"id\":2044303878901771,\"id_str\":\"2044303878901771\",\"order_type\":1,\"order_subtype\":5,\"datetime\":\"1787932601\",\"microtimestamp\":\"1787932601343000\",\"amount\":0.1,\"amount_str\":\"0.10000000\",\"amount_traded\":\"0\",\"amount_at_create\":\"0.10000000\",\"price\":78522.62,\"price_str\":\"78522.62\",\"is_liquidation\":false},\"channel\":\"live_orders_btcusd\",\"event\":\"order_deleted\",\"event_id\":\"00065a1d-7f95-dc18-0001-000102000020\",\"pre_event_id\":\"00065a1d-7f95-dc18-0000-000101000020\",\"order_source\":\"orderbook\"}","recorded_unix_us":1787932601423288}
{"message":"{\"data\":{\"id\":2044303878922240,\"id_str\":\"2044303878922240\",\"order_type\":0,\"order_subtype\":5,\"datetime\":\"1787932601\",\"microtimestamp\":\"1787932601347000\",\"amount\":0.00140266,\"amount_str\":\"0.00140266\",\"amount_traded\":\"0\",\"amount_at_create\":\"0.00140266\",\"price\":70670.37,\"price_str\":\"70670.37\",\"is_liquidation\":false},\"channel\":\"live_orders_btcusd\",\"event\":\"order_created\",\"event_id\":\"00065a1d-7f95-ebb8-0000-000103000020\",\"pre_event_id\":\"00065a1d-7f95-dc18-0001-000102000020\",\"order_source\":\"orderbook\"}","recorded_unix_us":1787932601423414}
{"message":"{\"data\":{\"id\":2044303878266885,\"id_str\":\"2044303878266885\",\"order_type\":0,\"order_subtype\":5,\"datetime\":\"1787932601\",\"microtimestamp\":\"1787932601359000\",\"amount\":0.00140266,\"amount_str\":\"0.00140266\",\"amount_traded\":\"0\",\"amount_at_create\":\"0.00140266\",\"price\":70670.37,\"price_str\":\"70670.37\",\"is_liquidation\":false},\"channel\":\"live_orders_btcusd\",\"event\":\"order_deleted\",\"event_id\":\"00065a1d-7f96-1a98-0000-000100000020\",\"pre_event_id\":\"00065a1d-7f95-ebb8-0000-000103000020\",\"order_source\":\"orderbook\"}","recorded_unix_us":1787932601423445}
{"message":"{\"data\":{\"id\":2044303878127633,\"id_str\":\"2044303878127633\",\"order_type\":1,\"order_subtype\":5,\"datetime\":\"1787932601\",\"microtimestamp\":\"1787932601363000\",\"amount\":0.1,\"amount_str\":\"0.10000000\",\"amount_traded\":\"0\",\"amount_at_create\":\"0.10000000\",\"price\":78523.32,\"price_str\":\"78523.32\",\"is_liquidation\":false},\"channel\":\"live_orders_btcusd\",\"event\":\"order_deleted\",\"event_id\":\"00065a1d-7f96-2a38-0000-000101000020\",\"pre_event_id\":\"00065a1d-7f96-1a98-0000-000100000020\",\"order_source\":\"orderbook\"}","recorded_unix_us":1787932601423540}
{"message":"{\"data\":{\"id\":2044303879000072,\"id_str\":\"2044303879000072\",\"order_type\":1,\"order_subtype\":5,\"datetime\":\"1787932601\",\"microtimestamp\":\"1787932601366000\",\"amount\":0.1,\"amount_str\":\"0.10000000\",\"amount_traded\":\"0\",\"amount_at_create\":\"0.10000000\",\"price\":78522.63,\"price_str\":\"78522.63\",\"is_liquidation\":false},\"channel\":\"live_orders_btcusd\",\"event\":\"order_created\",\"event_id\":\"00065a1d-7f96-35f0-0000-000102000020\",\"pre_event_id\":\"00065a1d-7f96-2a38-0000-000101000020\",\"order_source\":\"orderbook\"}","recorded_unix_us":1787932601423675}
{"message":"{\"data\":{\"id\":2044303879000072,\"id_str\":\"2044303879000072\",\"order_type\":1,\"order_subtype\":5,\"datetime\":\"1787932601\",\"microtimestamp\":\"1787932601366000\",\"amount\":0.1,\"amount_str\":\"0.10000000\",\"amount_traded\":\"0\",\"amount_at_create\":\"0.10000000\",\"price\":78522.63,\"price_str\":\"78522.63\",\"is_liquidation\":false},\"channel\":\"live_orders_btcusd\",\"event\":\"order_deleted\",\"event_id\":\"00065a1d-7f96-35f0-0001-000103000020\",\"pre_event_id\":\"00065a1d-7f96-35f0-0000-000102000020\",\"order_source\":\"orderbook\"}","recorded_unix_us":1787932601423697}
{"message":"{\"data\":{\"id\":2044303879004165,\"id_str\":\"2044303879004165\",\"order_type\":0,\"order_subtype\":5,\"datetime\":\"1787932601\",\"microtimestamp\":\"1787932601367000\",\"amount\":1.184652,\"amount_str\":\"1.184652\",\"amount_traded\":\"0\",\"amount_at_create\":\"1.184652\",\"price\":2480.14,\"price_str\":\"2480.14\",\"is_liquidation\":false},\"channel\":\"live_orders_ethusd\",\"event\":\"order_created\",\"event_id\":\"00065a1d-7f96-39d8-0000-001201000020\",\"pre_event_id\":\"00065a1d-7f95-0928-0000-001200000020\",\"order_source\":\"orderbook\"}","recorded_unix_us":1787932601423716}
{"message":"{\"data\":{\"id\":2044303879032836,\"id_str\":\"2044303879032836\",\"order_type\":1,\"order_subtype\":5,\"datetime\":\"1787932601\",\"microtimestamp\":\"1787932601374000\",\"amount\":0.1,\"amount_str\":\"0.10000000\",\"amount_traded\":\"0\",\"amount_at_create\":\"0.10000000\",\"price\":78522.79,\"price_str\":\"78522.79\",\"is_liquidation\":false},\"channel\":\"live_orders_btcusd\",\"event\":\"order_created\",\"event_id\":\"00065a1d-7f96-5530-0000-000100000020\",\"pre_event_id\":\"00065a1d-7f96-35f0-0001-000103000020\",\"order_source\":\"orderbook\"}","recorded_unix_us":1787932601423795}
{"message":"{\"data\":{\"id\":2044303879061513,\"id_str\":\"2044303879061513\",\"order_type\":1,\"order_subtype\":5,\"datetime\":\"1787932601\",\"microtimestamp\":\"1787932601382000\",\"amount\":0.1,\"amount_str\":\"0.10000000\",\"amount_traded\":\"0\",\"amount_at_create\":\"0.10000000\",\"price\":78522.62,\"price_str\":\"78522.62\",\"is_liquidation\":false},\"channel\":\"live_orders_btcusd\",\"event\":\"order_created\",\"event_id\":\"00065a1d-7f96-7470-0000-000101000020\",\"pre_event_id\":\"00065a1d-7f96-5530-0000-000100000020\",\"order_source\":\"orderbook\"}","recorded_unix_us":1787932601423901}
{"message":"{\"data\":{\"id\":2044303879061513,\"id_str\":\"2044303879061513\",\"order_type\":1,\"order_subtype\":5,\"datetime\":\"1787932601\",\"microtimestamp\":\"1787932601382000\",\"amount\":0.1,\"amount_str\":\"0.10000000\",\"amount_traded\":\"0\",\"amount_at_create\":\"0.10000000\",\"price\":78522.62,\"price_str\":\"78522.62\",\"is_liquidation\":false},\"channel\":\"live_orders_btcusd\",\"event\":\"order_deleted\",\"event_id\":\"00065a1d-7f96-7470-0001-000102000020\",\"pre_event_id\":\"00065a1d-7f96-7470-0000-000101000020\",\"order_source\":\"orderbook\"}","recorded_unix_us":1787932601423927}
{"message":"{\"data\":{\"id\":2044303879073795,\"id_str\":\"2044303879073795\",\"order_type\":1,\"order_subtype\":5,\"datetime\":\"1787932601\",\"microtimestamp\":\"1787932601384000\",\"amount\":0.60450317,\"amount_str\":\"0.60450317\",\"amount_traded\":\"0\",\"amount_at_create\":\"0.60450317\",\"price\":0.031603,\"price_str\":\"0.03160300\",\"is_liquidation\":false},\"channel\":\"live_orders_ethbtc\",\"event\":\"order_created\",\"event_id\":\"00065a1d-7f96-7c40-0000-001103000020\",\"pre_event_id\":\"00065a1d-7f95-ad38-0002-001102000020\",\"order_source\":\"orderbook\"}","recorded_unix_us":1787932601424063}
{"message":"{\"data\":{\"id\":2044303879073800,\"id_str\":\"2044303879073800\",\"order_type\":1,\"order_subtype\":5,\"datetime\":\"1787932601\",\"microtimestamp\":\"1787932601385000\",\"amount\":4.02232075,\"amount_str\":\"4.02232075\",\"amount_traded\":\"0\",\"amount_at_create\":\"4.02232075\",\"price\":0.03165997,\"price_str\":\"0.03165997\",\"is_liquidation\":false},\"channel\":\"live_orders_ethbtc\",\"event\":\"order_created\",\"event_id\":\"00065a1d-7f96-8028-0000-001100000020\",\"pre_event_id\":\"00065a1d-7f96-7c40-0000-001103000020\",\"order_source\":\"orderbook\"}","recorded_unix_us":1787932601424091}
{"message":"{\"data\":{\"id\":2044303878291459,\"id_str\":\"2044303878291459\",\"order_type\":1,\"order_subtype\":5,\"datetime\":\"1787932601\",\"microtimestamp\":\"1787932601393000\",\"amount\":0.1,\"amount_str\":\"0.10000000\",\"amount_traded\":\"0\",\"amount_at_create\":\"0.10000000\",\"price\":78523.24,\"price_str\":\"78523.24\",\"is_liquidation\":false},\"channel\":\"live_orders_btcusd\",\"event\":\"order_deleted\",\"event_id\":\"00065a1d-7f96-9f68-0000-000103000020\",\"pre_event_id\":\"00065a1d-7f96-7470-0001-000102000020\",\"order_source\":\"orderbook\"}","recorded_unix_us":1787932601428314}
{"message":"{\"data\":{\"id\":2044303879139328,\"id_str\":\"2044303879139328\",\"order_type\":1,\"order_subtype\":5,\"datetime\":\"1787932601\",\"microtimestamp\":\"1787932601400000\",\"amount\":0.1,\"amount_str\":\"0.10000000\",\"amount_traded\":\"0\",\"amount_at_create\":\"0.10000000\",\"price\":78522.63,\"price_str\":\"78522.63\",\"is_liquidation\":false},\"channel\":\"live_orders_btcusd\",\"event\":\"order_created\",\"event_id\":\"00065a1d-7f96-bac0-0000-000100000020\",\"pre_event_id\":\"00065a1d-7f96-9f68-0000-000103000020\",\"order_source\":\"orderbook\"}","recorded_unix_us":1787932601441154}
{"message":"{\"data\":{\"id\":2044303879139328,\"id_str\":\"2044303879139328\",\"order_type\":1,\"order_subtype\":5,\"datetime\":\"1787932601\",\"microtimestamp\":\"1787932601400000\",\"amount\":0.1,\"amount_str\":\"0.10000000\",\"amount_traded\":\"0\",\"amount_at_create\":\"0.10000000\",\"price\":78522.63,\"price_str\":\"78522.63\",\"is_liquidation\":false},\"channel\":\"live_orders_btcusd\",\"event\":\"order_deleted\",\"event_id\":\"00065a1d-7f96-bac0-0001-000101000020\",\"pre_event_id\":\"00065a1d-7f96-bac0-0000-000100000020\",\"order_source\":\"orderbook\"}","recorded_unix_us":1787932601441253}
{"message":"{\"data\":{\"id\":2044303879147520,\"id_str\":\"2044303879147520\",\"order_type\":1,\"order_subtype\":5,\"datetime\":\"1787932601\",\"microtimestamp\":\"1787932601403000\",\"amount\":2.01386943,\"amount_str\":\"2.01386943\",\"amount_traded\":\"0\",\"amount_at_create\":\"2.01386943\",\"price\":0.0316184,\"price_str\":\"0.03161840\",\"is_liquidation\":false},\"channel\":\"live_orders_ethbtc\",\"event\":\"order_created\",\"event_id\":\"00065a1d-7f96-c678-0000-001101000020\",\"pre_event_id\":\"00065a1d-7f96-8028-0000-001100000020\",\"order_source\":\"orderbook\"}","recorded_unix_us":1787932601442281}
{"message":"{\"data\":{\"id\":2044303879155717,\"id_str\":\"2044303879155717\",\"order_type\":1,\"order_subtype\":5,\"datetime\":\"1787932601\",\"microtimestamp\":\"1787932601404000\",\"amount\":1.00740464,\"amount_str\":\"1.00740464\",\"amount_traded\":\"0\",\"amount_at_create\":\"1.00740464\",\"price\":0.03160452,\"price_str\":\"0.03160452\",\"is_liquidation\":false},\"channel\":\"live_orders_ethbtc\",\"event\":\"order_created\",\"event_id\":\"00065a1d-7f96-ca60-0000-001102000020\",\"pre_event_id\":\"00065a1d-7f96-c678-0000-001101000020\",\"order_source\":\"orderbook\"}","recorded_unix_us":1787932601442347}
{"message":"{\"data\":{\"id\":2044303879163906,\"id_str\":\"2044303879163906\",\"order_type\":1,\"order_subtype\":5,\"datetime\":\"1787932601\",\"microtimestamp\":\"1787932601406000\",\"amount\":3.02055629,\"amount_str\":\"3.02055629\",\"amount_traded\":\"0\",\"amount_at_create\":\"3.02055629\",\"price\":0.03162186,\"price_str\":\"0.03162186\",\"is_liquidation\":false},\"channel\":\"live_orders_ethbtc\",\"event\":\"order_created\",\"event_id\":\"00065a1d-7f96-d230-0000-001103000020\",\"pre_event_id\":\"00065a1d-7f96-ca60-0000-001102000020\",\"order_source\":\"orderbook\"}","recorded_unix_us":1787932601442415}
{"message":"{\"data\":{\"id\":2044303879176196,\"id_str\":\"2044303879176196\",\"order_type\":0,\"order_subtype\":5,\"datetime\":\"1787932601\",\"microtimestamp\":\"1787932601409000\",\"amount\":1.00801353,\"amount_str\":\"1.00801353\",\"amount_traded\":\"0\",\"amount_at_create\":\"1.00801353\",\"price\":0.03158534,\"price_str\":\"0.03158534\",\"is_liquidation\":false},\"channel\":\"live_orders_ethbtc\",\"event\":\"order_created\",\"event_id\":\"00065a1d-7f96-dde8-0000-001100000020\",\"pre_event_id\":\"00065a1d-7f96-d230-0000-001103000020\",\"order_source\":\"orderbook\"}","recorded_unix_us":1787932601442469}
{"message":"{\"data\":{\"id\":2044303879176203,\"id_str\":\"2044303879176203\",\"order_type\":0,\"order_subtype\":5,\"datetime\":\"1787932601\",\"microtimestamp\":\"1787932601410000\",\"amount\":2.01629689,\"amount_str\":\"2.01629689\",\"amount_traded\":\"0\",\"amount_at_create\":\"2.01629689\",\"price\":0.03157941,\"price_str\":\"0.03157941\",\"is_liquidation\":false},\"channel\":\"live_orders_ethbtc\",\"event\":\"order_created\",\"event_id\":\"00065a1d-7f96-e1d0-0000-001101000020\",\"pre_event_id\":\"00065a1d-7f96-dde8-0000-001100000020\",\"order_source\":\"orderbook\"}","recorded_unix_us":1787932601443889}
{"message":"{\"data\":{\"id\":2044303879180296,\"id_str\":\"2044303879180296\",\"order_type\":0,\"order_subtype\":5,\"datetime\":\"1787932601\",\"microtimestamp\":\"1787932601411000\",\"amount\":0.6048199,\"amount_str\":\"0.60481990\",\"amount_traded\":\"0\",\"amount_at_create\":\"0.60481990\",\"price\":0.03158573,\"price_str\":\"0.03158573\",\"is_liquidation\":false},\"channel\":\"live_orders_ethbtc\",\"event\":\"order_created\",\"event_id\":\"00065a1d-7f96-e5b8-0000-001102000020\",\"pre_event_id\":\"00065a1d-7f96-e1d0-0000-001101000020\",\"order_source\":\"orderbook\"}","recorded_unix_us":1787932601443905}
{"message":"{\"data\":{\"id\":2044303879184384,\"id_str\":\"2044303879184384\",\"order_type\":0,\"order_subtype\":5,\"datetime\":\"1787932601\",\"microtimestamp\":\"1787932601411000\",\"amount\":3.02537254,\"amount_str\":\"3.02537254\",\"amount_traded\":\"0\",\"amount_at_create\":\"3.02537254\",\"price\":0.03156999,\"price_str\":\"0.03156999\",\"is_liquidation\":false},\"channel\":\"live_orders_ethbtc\",\"event\":\"order_created\",\"event_id\":\"00065a1d-7f96-e5b8-0001-001103000020\",\"pre_event_id\":\"00065a1d-7f96-e5b8-0000-001102000020\",\"order_source\":\"orderbook\"}","recorded_unix_us":1787932601443918}
{"message":"{\"data\":{\"id\":2044303879180296,\"id_str\":\"2044303879180296\",\"order_type\":0,\"order_subtype\":5,\"datetime\":\"1787932601\",\"microtimestamp\":\"1787932601411000\",\"amount\":0.6048199,\"amount_str\":\"0.60481990\",\"amount_traded\":\"0\",\"amount_at_create\":\"0.60481990\",\"price\":0.03158573,\"price_str\":\"0.03158573\",\"is_liquidation\":false},\"channel\":\"live_orders_ethbtc\",\"event\":\"order_deleted\",\"event_id\":\"00065a1d-7f96-e5b8-0002-001100000020\",\"pre_event_id\":\"00065a1d-7f96-e5b8-0001-001103000020\",\"order_source\":\"orderbook\"}","recorded_unix_us":1787932601443995}
{"message":"{\"data\":{\"id\":2044303879184389,\"id_str\":\"2044303879184389\",\"order_type\":1,\"order_subtype\":5,\"datetime\":\"1787932601\",\"microtimestamp\":\"1787932601412000\",\"amount\":0.1,\"amount_str\":\"0.10000000\",\"amount_traded\":\"0\",\"amount_at_create\":\"0.10000000\",\"price\":78522.74,\"price_str\":\"78522.74\",\"is_liquidation\":false},\"channel\":\"live_orders_btcusd\",\"event\":\"order_created\",\"event_id\":\"00065a1d-7f96-e9a0-0000-000102000020\",\"pre_event_id\":\"00065a1d-7f96-bac0-0001-000101000020\",\"order_source\":\"orderbook\"}","recorded_unix_us":1787932601444055}
{"message":"{\"data\":{\"id\":2044303879188480,\"id_str\":\"2044303879188480\",\"order_type\":1,\"order_subtype\":5,\"datetime\":\"1787932601\",\"microtimestamp\":\"1787932601412000\",\"amount\":0.1,\"amount_str\":\"0.10000000\",\"amount_traded\":\"0\",\"amount_at_create\":\"0.10000000\",\"price\":78522.62,\"price_str\":\"78522.62\",\"is_liquidation\":false},\"channel\":\"live_orders_btcusd\",\"event\":\"order_created\",\"event_id\":\"00065a1d-7f96-e9a0-0001-000103000020\",\"pre_event_id\":\"00065a1d-7f96-e9a0-0000-000102000020\",\"order_source\":\"orderbook\"}","recorded_unix_us":1787932601444069}
{"message":"{\"data\":{\"id\":2044303879188480,\"id_str\":\"2044303879188480\",\"order_type\":1,\"order_subtype\":5,\"datetime\":\"1787932601\",\"microtimestamp\":\"1787932601412000\",\"amount\":0.1,\"amount_str\":\"0.10000000\",\"amount_traded\":\"0\",\"amount_at_create\":\"0.10000000\",\"price\":78522.62,\"price_str\":\"78522.62\",\"is_liquidation\":false},\"channel\":\"live_orders_btcusd\",\"event\":\"order_deleted\",\"event_id\":\"00065a1d-7f96-e9a0-0002-000100000020\",\"pre_event_id\":\"00065a1d-7f96-e9a0-0001-000103000020\",\"order_source\":\"orderbook\"}","recorded_unix_us":1787932601444081}
{"message":"{\"data\":{\"id\":2044303878463488,\"id_str\":\"2044303878463488\",\"order_type\":1,\"order_subtype\":5,\"datetime\":\"1787932601\",\"microtimestamp\":\"1787932601413000\",\"amount\":0.1,\"amount_str\":\"0.10000000\",\"amount_traded\":\"0\",\"amount_at_create\":\"0.10000000\",\"price\":78523.14,\"price_str\":\"78523.14\",\"is_liquidation\":false},\"channel\":\"live_orders_btcusd\",\"event\":\"order_deleted\",\"event_id\":\"00065a1d-7f96-ed88-0000-000101000020\",\"pre_event_id\":\"00065a1d-7f96-e9a0-0002-000100000020\",\"order_source\":\"orderbook\"}","recorded_unix_us":1787932601455701}
{"message":"{\"data\":{\"id\":2044303879233536,\"id_str\":\"2044303879233536\",\"order_type\":0,\"order_subtype\":5,\"datetime\":\"1787932601\",\"microtimestamp\":\"1787932601423000\",\"amount\":4.03662068,\"amount_str\":\"4.03662068\",\"amount_traded\":\"0\",\"amount_at_create\":\"4.03662068\",\"price\":0.03154857,\"price_str\":\"0.03154857\",\"is_liquidation\":false},\"channel\":\"live_orders_ethbtc\",\"event\":\"order_created\",\"event_id\":\"00065a1d-7f97-1498-0000-001101000020\",\"pre_event_id\":\"00065a1d-7f96-e5b8-0002-001100000020\",\"order_source\":\"orderbook\"}","recorded_unix_us":1787932601457679}
{"message":"{\"data\":{\"id\":2044303879241730,\"id_str\":\"2044303879241730\",\"order_type\":1,\"order_subtype\":5,\"datetime\":\"1787932601\",\"microtimestamp\":\"1787932601425000\",\"amount\":0.06367563,\"amount_str\":\"0.06367563\",\"amount_traded\":\"0\",\"amount_at_create\":\"0.06367563\",\"price\":78522.98,\"price_str\":\"78522.98\",\"is_liquidation\":false},\"channel\":\"live_orders_btcusd\",\"event\":\"order_created\",\"event_id\":\"00065a1d-7f97-1c68-0000-000102000020\",\"pre_event_id\":\"00065a1d-7f96-ed88-0000-000101000020\",\"order_source\":\"orderbook\"}","recorded_unix_us":1787932601457759}
{"message":"{\"data\":{\"id\":2044303879249922,\"id_str\":\"2044303879249922\",\"order_type\":0,\"order_subtype\":5,\"datetime\":\"1787932601\",\"microtimestamp\":\"1787932601428000\",\"amount\":0.00140266,\"amount_str\":\"0.00140266\",\"amount_traded\":\"0\",\"amount_at_create\":\"0.00140266\",\"price\":70670.37,\"price_str\":\"70670.37\",\"is_liquidation\":false},\"channel\":\"live_orders_btcusd\",\"event\":\"order_created\",\"event_id\":\"00065a1d-7f97-2820-0000-000103000020\",\"pre_event_id\":\"00065a1d-7f97-1c68-0000-000102000020\",\"order_source\":\"orderbook\"}","recorded_unix_us":1787932601457773}
{"message":"{\"data\":{\"id\":2044303878602766,\"id_str\":\"2044303878602766\",\"order_type\":0,\"order_subtype\":5,\"datetime\":\"1787932601\",\"microtimestamp\":\"1787932601438000\",\"amount\":0.00140266,\"amount_str\":\"0.00140266\",\"amount_traded\":\"0\",\"amount_at_create\":\"0.00140266\",\"price\":70670.37,\"price_str\":\"70670.37\",\"is_liquidation\":false},\"channel\":\"live_orders_btcusd\",\"event\":\"order_deleted\",\"event_id\":\"00065a1d-7f97-4f30-0000-000100000020\",\"pre_event_id\":\"00065a1d-7f97-2820-0000-000103000020\",\"order_source\":\"orderbook\"}","recorded_unix_us":1787932601482247}
{"message":"{\"data\":{\"id\":2044303879303170,\"id_str\":\"2044303879303170\",\"order_type\":1,\"order_subtype\":5,\"datetime\":\"1787932601\",\"microtimestamp\":\"1787932601440000\",\"amount\":0.1,\"amount_str\":\"0.10000000\",\"amount_traded\":\"0\",\"amount_at_create\":\"0.10000000\",\"price\":78522.63,\"price_str\":\"78522.63\",\"is_liquidation\":false},\"channel\":\"live_orders_btcusd\",\"event\":\"order_created\",\"event_id\":\"00065a1d-7f97-5700-0000-000101000020\",\"pre_event_id\":\"00065a1d-7f97-4f30-0000-000100000020\",\"order_source\":\"orderbook\"}","recorded_unix_us":1787932601482436}
{"message":"{\"data\":{\"id\":2044303879303170,\"id_str\":\"2044303879303170\",\"order_type\":1,\"order_subtype\":5,\"datetime\":\"1787932601\",\"microtimestamp\":\"1787932601440000\",\"amount\":0.1,\"amount_str\":\"0.10000000\",\"amount_traded\":\"0\",\"amount_at_create\":\"0.10000000\",\"price\":78522.63,\"price_str\":\"78522.63\",\"is_liquidation\":false},\"channel\":\"live_orders_btcusd\",\"event\":\"order_deleted\",\"event_id\":\"00065a1d-7f97-5700-0001-000102000020\",\"pre_event_id\":\"00065a1d-7f97-5700-0000-000101000020\",\"order_source\":\"orderbook\"}","recorded_unix_us":1787932601482472}
{"message":"{\"data\":{\"id\":2044303879307268,\"id_str\":\"2044303879307268\",\"order_type\":1,\"order_subtype\":5,\"datetime\":\"1787932601\",\"microtimestamp\":\"1787932601442000\",\"amount\":0.1,\"amount_str\":\"0.10000000\",\"amount_traded\":\"0\",\"amount_at_create\":\"0.10000000\",\"price\":78522.62,\"price_str\":\"78522.62\",\"is_liquidation\":false},\"channel\":\"live_orders_btcusd\",\"event\":\"order_created\",\"event_id\":\"00065a1d-7f97-5ed0-0000-000103000020\",\"pre_event_id\":\"00065a1d-7f97-5700-0001-000102000020\",\"order_source\":\"orderbook\"}","recorded_unix_us":1787932601482493}
{"message":"{\"data\":{\"id\":2044303879307268,\"id_str\":\"2044303879307268\",\"order_type\":1,\"order_subtype\":5,\"datetime\":\"1787932601\",\"microtimestamp\":\"1787932601442000\",\"amount\":0.1,\"amount_str\":\"0.10000000\",\"amount_traded\":\"0\",\"amount_at_create\":\"0.10000000\",\"price\":78522.62,\"price_str\":\"78522.62\",\"is_liquidation\":false},\"channel\":\"live_orders_btcusd\",\"event\":\"order_deleted\",\"event_id\":\"00065a1d-7f97-5ed0-0001-000100000020\",\"pre_event_id\":\"00065a1d-7f97-5ed0-0000-000103000020\",\"order_source\":\"orderbook\"}","recorded_unix_us":1787932601482509}
{"message":"{\"data\":{\"id\":2044303876800512,\"id_str\":\"2044303876800512\",\"order_type\":1,\"order_subtype\":5,\"datetime\":\"1787932601\",\"microtimestamp\":\"1787932601447000\",\"amount\":1.732162,\"amount_str\":\"1.732162\",\"amount_traded\":\"0\",\"amount_at_create\":\"1.732162\",\"price\":2481.02,\"price_str\":\"2481.02\",\"is_liquidation\":false},\"channel\":\"live_orders_ethusd\",\"event\":\"order_deleted\",\"event_id\":\"00065a1d-7f97-7258-0000-001202000020\",\"pre_event_id\":\"00065a1d-7f96-39d8-0000-001201000020\",\"order_source\":\"orderbook\"}","recorded_unix_us":1787932601485048}
{"message":"{\"data\":{\"id\":2044303879327745,\"id_str\":\"2044303879327745\",\"order_type\":1,\"order_subtype\":5,\"datetime\":\"1787932601\",\"microtimestamp\":\"1787932601447000\",\"amount\":1.732162,\"amount_str\":\"1.732162\",\"amount_traded\":\"0\",\"amount_at_create\":\"1.732162\",\"price\":2481.02,\"price_str\":\"2481.02\",\"is_liquidation\":false},\"channel\":\"live_orders_ethusd\",\"event\":\"order_created\",\"event_id\":\"00065a1d-7f97-7258-0001-001203000020\",\"pre_event_id\":\"00065a1d-7f97-7258-0000-001202000020\",\"order_source\":\"orderbook\"}","recorded_unix_us":1787932601485073}
{"message":"{\"data\":{\"id\":2044303879331844,\"id_str\":\"2044303879331844\",\"order_type\":1,\"order_subtype\":5,\"datetime\":\"1787932601\",\"microtimestamp\":\"1787932601447000\",\"amount\":0.06367384,\"amount_str\":\"0.06367384\",\"amount_traded\":\"0\",\"amount_at_create\":\"0.06367384\",\"price\":78525.19,\"price_str\":\"78525.19\",\"is_liquidation\":false},\"channel\":\"live_orders_btcusd\",\"event\":\"order_created\",\"event_id\":\"00065a1d-7f97-7258-0000-000101000020\",\"pre_event_id\":\"00065a1d-7f97-5ed0-0001-000100000020\",\"order_source\":\"orderbook\"}","recorded_unix_us":1787932601485089}
{"message":"{\"data\":{\"id\":2044303879331849,\"id_str\":\"2044303879331849\",\"order_type\":1,\"order_subtype\":5,\"datetime\":\"1787932601\",\"microtimestamp\":\"1787932601448000\",\"amount\":0.25467128,\"amount_str\":\"0.25467128\",\"amount_traded\":\"0\",\"amount_at_create\":\"0.25467128\",\"price\":78532.61,\"price_str\":\"78532.61\",\"is_liquidation\":false},\"channel\":\"live_orders_btcusd\",\"event\":\"order_created\",\"event_id\":\"00065a1d-7f97-7640-0000-000102000020\",\"pre_event_id\":\"00065a1d-7f97-7258-0000-000101000020\",\"order_source\":\"orderbook\"}","recorded_unix_us":1787932601485170}
{"message":"{\"data\":{\"id\":2044303879335936,\"id_str\":\"2044303879335936\",\"order_type\":1,\"order_subtype\":5,\"datetime\":\"1787932601\",\"microtimestamp\":\"1787932601448000\",\"amount\":0.25466146,\"amount_str\":\"0.25466146\",\"amount_traded\":\"0\",\"amount_at_create\":\"0.25466146\",\"price\":78535.64,\"price_str\":\"78535.64\",\"is_liquidation\":false},\"channel\":\"live_orders_btcusd\",\"event\":\"order_created\",\"event_id\":\"00065a1d-7f97-7640-0001-000103000020\",\"pre_event_id\":\"00065a1d-7f97-7640-0000-000102000020\",\"order_source\":\"orderbook\"}","recorded_unix_us":1787932601485262}
{"message":"{\"data\":{\"id\":2044303879340046,\"id_str\":\"2044303879340046\",\"order_type\":1,\"order_subtype\":5,\"datetime\":\"1787932601\",\"microtimestamp\":\"1787932601450000\",\"amount\":12.70451953,\"amount_str\":\"12.70451953\",\"amount_traded\":\"0\",\"amount_at_create\":\"12.70451953\",\"price\":78712.15,\"price_str\":\"78712.15\",\"is_liquidation\":false},\"channel\":\"live_orders_btcusd\",\"event\":\"order_created\",\"event_id\":\"00065a1d-7f97-7e10-0000-000100000020\",\"pre_event_id\":\"00065a1d-7f97-7640-0001-000103000020\",\"order_source\":\"orderbook\"}","recorded_unix_us":1787932601485332}
{"message":"{\"data\":{\"id\":2044303879340045,\"id_str\":\"2044303879340045\",\"order_type\":1,\"order_subtype\":5,\"datetime\":\"1787932601\",\"microtimestamp\":\"1787932601450000\",\"amount\":1.27209222,\"amount_str\":\"1.27209222\",\"amount_traded\":\"0\",\"amount_at_create\":\"1.27209222\",\"price\":78610.66,\"price_str\":\"78610.66\",\"is_liquidation\":false},\"channel\":\"live_orders_btcusd\",\"event\":\"order_created\",\"event_id\":\"00065a1d-7f97-7e10-0001-000101000020\",\"pre_event_id\":\"00065a1d-7f97-7e10-0000-000100000020\",\"order_source\":\"orderbook\"}","recorded_unix_us":1787932601485354}
{"message":"{\"data\":{\"id\":2044303879344135,\"id_str\":\"2044303879344135\",\"order_type\":1,\"order_subtype\":4,\"datetime\":\"1787932601\",\"microtimestamp\":\"1787932601450000\",\"amount\":0.00006244,\"amount_str\":\"0.00006244\",\"amount_traded\":\"0\",\"amount_at_create\":\"0.00006244\",\"price\":80878,\"price_str\":\"80878.00\",\"is_liquidation\":false},\"channel\":\"live_orders_btcusd\",\"event\":\"order_created\",\"event_id\":\"00065a1d-7f97-7e10-0002-000102000020\",\"pre_event_id\":\"00065a1d-7f97-7e10-0001-000101000020\",\"order_source\":\"orderbook\"}","recorded_unix_us":1787932601485370}
{"message":"{\"data\":{\"id\":2044303879344135,\"id_str\":\"2044303879344135\",\"order_type\":1,\"order_subtype\":4,\"datetime\":\"1787932601\",\"microtimestamp\":\"1787932601450000\",\"amount\":0.00006244,\"amount_str\":\"0.00006244\",\"amount_traded\":\"0\",\"amount_at_create\":\"0.00006244\",\"price\":80878,\"price_str\":\"80878.00\",\"is_liquidation\":false},\"channel\":\"live_orders_btcusd\",\"event\":\"order_deleted\",\"event_id\":\"00065a1d-7f97-7e10-0003-000103000020\",\"pre_event_id\":\"00065a1d-7f97-7e10-0002-000102000020\",\"order_source\":\"orderbook\"}","recorded_unix_us":1787932601485456}
{"message":"{\"data\":{\"id\":2044303879352320,\"id_str\":\"2044303879352320\",\"order_type\":1,\"order_subtype\":5,\"datetime\":\"1787932601\",\"microtimestamp\":\"1787932601452000\",\"amount\":1.26970017,\"amount_str\":\"1.26970017\",\"amount_traded\":\"0\",\"amount_at_create\":\"1.26970017\",\"price\":78758.76,\"price_str\":\"78758.76\",\"is_liquidation\":false},\"channel\":\"live_orders_btcusd\",\"event\":\"order_created\",\"event_id\":\"00065a1d-7f97-85e0-0000-000100000020\",\"pre_event_id\":\"00065a1d-7f97-7e10-0003-000103000020\",\"order_source\":\"orderbook\"}","recorded_unix_us":1787932601485474}
{"message":"{\"data\":{\"id\":2044303879352323,\"id_str\":\"2044303879352323\",\"order_type\":0,\"order_subtype\":5,\"datetime\":\"1787932601\",\"microtimestamp\":\"1787932601453000\",\"amount\":0.675,\"amount_str\":\"0.67500000\",\"amount_traded\":\"0\",\"amount_at_create\":\"0.67500000\",\"price\":78487.36,\"price_str\":\"78487.36\",\"is_liquidation\":false},\"channel\":\"live_orders_btcusd\",\"event\":\"order_created\",\"event_id\":\"00065a1d-7f97-89c8-0000-000101000020\",\"pre_event_id\":\"00065a1d-7f97-85e0-0000-000100000020\",\"order_source\":\"orderbook\"}","recorded_unix_us":1787932601485546}
{"message":"{\"data\":{\"id\":2044303879356416,\"id_str\":\"2044303879356416\",\"order_type\":1,\"order_subtype\":5,\"datetime\":\"1787932601\",\"microtimestamp\":\"1787932601453000\",\"amount\":1.2684012,\"amount_str\":\"1.26840120\",\"amount_traded\":\"0\",\"amount_at_create\":\"1.26840120\",\"price\":78839.41,\"price_str\":\"78839.41\",\"is_liquidation\":false},\"channel\":\"live_orders_btcusd\",\"event\":\"order_created\",\"event_id\":\"00065a1d-7f97-89c8-0001-000102000020\",\"pre_event_id\":\"00065a1d-7f97-89c8-0000-000101000020\",\"order_source\":\"orderbook\"}","recorded_unix_us":1787932601485567}
{"message":"{\"data\":{\"id\":2044303879360514,\"id_str\":\"2044303879360514\",\"order_type\":1,\"order_subtype\":4,\"datetime\":\"1787932601\",\"microtimestamp\":\"1787932601454000\",\"amount\":0.01500079,\"amount_str\":\"0.01500079\",\"amount_traded\":\"0\",\"amount_at_create\":\"0.01500079\",\"price\":78486.44,\"price_str\":\"78486.44\",\"is_liquidation\":false},\"channel\":\"live_orders_btcusd\",\"event\":\"order_created\",\"event_id\":\"00065a1d-7f97-8db0-0000-000103000020\",\"pre_event_id\":\"00065a1d-7f97-89c8-0001-000102000020\",\"order_source\":\"orderbook\"}","recorded_unix_us":1787932601485702}
{"message":"{\"data\":{\"id\":2044303879360514,\"id_str\":\"2044303879360514\",\"order_type\":1,\"order_subtype\":4,\"datetime\":\"1787932601\",\"microtimestamp\":\"1787932601454000\",\"amount\":0,\"amount_str\":\"0\",\"amount_traded\":\"0.01500079\",\"amount_at_create\":\"0.01500079\",\"price\":78522.63,\"price_str\":\"78522.63\",\"is_liquidation\":false},\"channel\":\"live_orders_btcusd\",\"event\":\"order_deleted\",\"event_id\":\"00065a1d-7f97-8db0-0001-000100000020\",\"pre_event_id\":\"00065a1d-7f97-8db0-0000-000103000020\",\"order_source\":\"orderbook\"}","recorded_unix_us":1787932601485718}
{"message":"{\"data\":{\"id\":2044303819288576,\"id_str\":\"2044303819288576\",\"order_type\":0,\"order_subtype\":5,\"datetime\":\"1787932601\",\"microtimestamp\":\"1787932601454000\",\"amount\":0.06013098,\"amount_str\":\"0.06013098\",\"amount_traded\":\"0.01500079\",\"amount_at_create\":\"0.07984607\",\"price\":78522.63,\"price_str\":\"78522.63\",\"is_liquidation\":false},\"channel\":\"live_orders_btcusd\",\"event\":\"order_changed\",\"event_id\":\"00065a1d-7f97-8db0-0002-000101000020\",\"pre_event_id\":\"00065a1d-7f97-8db0-0001-000100000020\",\"order_source\":\"orderbook\"}","recorded_unix_us":1787932601485732}
{"message":"{\"data\":{\"id\":2044303879360515,\"id_str\":\"2044303879360515\",\"order_type\":1,\"order_subtype\":5,\"datetime\":\"1787932601\",\"microtimestamp\":\"1787932601454000\",\"amount\":0.1,\"amount_str\":\"0.10000000\",\"amount_traded\":\"0\",\"amount_at_create\":\"0.10000000\",\"price\":78522.64,\"price_str\":\"78522.64\",\"is_liquidation\":false},\"channel\":\"live_orders_btcusd\",\"event\":\"order_created\",\"event_id\":\"00065a1d-7f97-8db0-0003-000102000020\",\"pre_event_id\":\"00065a1d-7f97-8db0-0002-000101000020\",\"order_source\":\"orderbook\"}","recorded_unix_us":1787932601485746}
{"message":"{\"data\":{\"id\":2044303879360520,\"id_str\":\"2044303879360520\",\"order_type\":0,\"order_subtype\":5,\"datetime\":\"1787932601\",\"microtimestamp\":\"1787932601454000\",\"amount\":0.06368219,\"amount_str\":\"0.06368219\",\"amount_traded\":\"0\",\"amount_at_create\":\"0.06368219\",\"price\":78514.87,\"price_str\":\"78514.87\",\"is_liquidation\":false},\"channel\":\"live_orders_btcusd\",\"event\":\"order_created\",\"event_id\":\"00065a1d-7f97-8db0-0004-000103000020\",\"pre_event_id\":\"00065a1d-7f97-8db0-0003-000102000020\",\"order_source\":\"orderbook\"}","recorded_unix_us":1787932601485759}
{"message":"{\"data\":{\"id\":2044303879360522,\"id_str\":\"2044303879360522\",\"order_type\":0,\"order_subtype\":5,\"datetime\":\"1787932601\",\"microtimestamp\":\"1787932601455000\",\"amount\":0.25476924,\"amount_str\":\"0.25476924\",\"amount_traded\":\"0\",\"amount_at_create\":\"0.25476924\",\"price\":78502.41,\"price_str\":\"78502.41\",\"is_liquidation\":false},\"channel\":\"live_orders_btcusd\",\"event\":\"order_created\",\"event_id\":\"00065a1d-7f97-9198-0000-000100000020\",\"pre_event_id\":\"00065a1d-7f97-8db0-0004-000103000020\",\"order_source\":\"orderbook\"}","recorded_unix_us":1787932601485882}
{"message":"{\"data\":{\"id\":2044303879364609,\"id_str\":\"2044303879364609\",\"order_type\":0,\"order_subtype\":5,\"datetime\":\"1787932601\",\"microtimestamp\":\"1787932601455000\",\"amount\":0.25478772,\"amount_str\":\"0.25478772\",\"amount_traded\":\"0\",\"amount_at_create\":\"0.25478772\",\"price\":78496.71,\"price_str\":\"78496.71\",\"is_liquidation\":false},\"channel\":\"live_orders_btcusd\",\"event\":\"order_created\",\"event_id\":\"00065a1d-7f97-9198-0001-000101000020\",\"pre_event_id\":\"00065a1d-7f97-9198-0000-000100000020\",\"order_source\":\"orderbook\"}","recorded_unix_us":1787932601485898}
{"message":"{\"data\":{\"id\":2044303879368706,\"id_str\":\"2044303879368706\",\"order_type\":0,\"order_subtype\":5,\"datetime\":\"1787932601\",\"microtimestamp\":\"1787932601456000\",\"amount\":1.27507828,\"amount_str\":\"1.27507828\",\"amount_traded\":\"0\",\"amount_at_create\":\"1.27507828\",\"price\":78426.55,\"price_str\":\"78426.55\",\"is_liquidation\":false},\"channel\":\"live_orders_btcusd\",\"event\":\"order_created\",\"event_id\":\"00065a1d-7f97-9580-0000-000102000020\",\"pre_event_id\":\"00065a1d-7f97-9198-0001-000101000020\",\"order_source\":\"orderbook\"}","recorded_unix_us":1787932601502634}
{"message":"{\"data\":{\"id\":2044303879360515,\"id_str\":\"2044303879360515\",\"order_type\":1,\"order_subtype\":5,\"datetime\":\"1787932601\",\"microtimestamp\":\"1787932601457000\",\"amount\":0.1,\"amount_str\":\"0.10000000\",\"amount_traded\":\"0\",\"amount_at_create\":\"0.10000000\",\"price\":78522.64,\"price_str\":\"78522.64\",\"is_liquidation\":false},\"channel\":\"live_orders_btcusd\",\"event\":\"order_deleted\",\"event_id\":\"00065a1d-7f97-9968-0000-000103000020\",\"pre_event_id\":\"00065a1d-7f97-9580-0000-000102000020\",\"order_source\":\"orderbook\"}","recorded_unix_us":1787932601502694}
{"message":"{\"data\":{\"id\":2044303879372801,\"id_str\":\"2044303879372801\",\"order_type\":0,\"order_subtype\":5,\"datetime\":\"1787932601\",\"microtimestamp\":\"1787932601457000\",\"amount\":1.27541152,\"amount_str\":\"1.27541152\",\"amount_traded\":\"0\",\"amount_at_create\":\"1.27541152\",\"price\":78406.06,\"price_str\":\"78406.06\",\"is_liquidation\":false},\"channel\":\"live_orders_btcusd\",\"event\":\"order_created\",\"event_id\":\"00065a1d-7f97-9968-0001-000100000020\",\"pre_event_id\":\"00065a1d-7f97-9968-0000-000103000020\",\"order_source\":\"orderbook\"}","recorded_unix_us":1787932601502770}
{"message":"{\"data\":{\"id\":2044303879376898,\"id_str\":\"2044303879376898\",\"order_type\":0,\"order_subtype\":5,\"datetime\":\"1787932601\",\"microtimestamp\":\"1787932601458000\",\"amount\":1.27567513,\"amount_str\":\"1.27567513\",\"amount_traded\":\"0\",\"amount_at_create\":\"1.27567513\",\"price\":78389.86,\"price_str\":\"78389.86\",\"is_liquidation\":false},\"channel\":\"live_orders_btcusd\",\"event\":\"order_created\",\"event_id\":\"00065a1d-7f97-9d50-0000-000101000020\",\"pre_event_id\":\"00065a1d-7f97-9968-0001-000100000020\",\"order_source\":\"orderbook\"}","recorded_unix_us":1787932601502788}
{"message":"{\"data\":{\"id\":2044303879376897,\"id_str\":\"2044303879376897\",\"order_type\":0,\"order_subtype\":5,\"datetime\":\"1787932601\",\"microtimestamp\":\"1787932601458000\",\"amount\":12.76418733,\"amount_str\":\"12.76418733\",\"amount_traded\":\"0\",\"amount_at_create\":\"12.76418733\",\"price\":78344.19,\"price_str\":\"78344.19\",\"is_liquidation\":false},\"channel\":\"live_orders_btcusd\",\"event\":\"order_created\",\"event_id\":\"00065a1d-7f97-9d50-0001-000102000020\",\"pre_event_id\":\"00065a1d-7f97-9d50-0000-000101000020\",\"order_source\":\"orderbook\"}","recorded_unix_us":1787932601502883}
{"message":"{\"data\":{\"id\":2044303879380996,\"id_str\":\"2044303879380996\",\"order_type\":0,\"order_subtype\":5,\"datetime\":\"1787932601\",\"microtimestamp\":\"1787932601459000\",\"amount\":1.27757154,\"amount_str\":\"1.27757154\",\"amount_traded\":\"0\",\"amount_at_create\":\"1.27757154\",\"price\":78273.5,\"price_str\":\"78273.50\",\"is_liquidation\":false},\"channel\":\"live_orders_btcusd\",\"event\":\"order_created\",\"event_id\":\"00065a1d-7f97-a138-0000-000103000020\",\"pre_event_id\":\"00065a1d-7f97-9d50-0001-000102000020\",\"order_source\":\"orderbook\"}","recorded_unix_us":1787932601502901}
{"message":"{\"data\":{\"id\":2044303879421954,\"id_str\":\"2044303879421954\",\"order_type\":1,\"order_subtype\":5,\"datetime\":\"1787932601\",\"microtimestamp\":\"1787932601470000\",\"amount\":0.1,\"amount_str\":\"0.10000000\",\"amount_traded\":\"0\",\"amount_at_create\":\"0.10000000\",\"price\":78522.63,\"price_str\":\"78522.63\",\"is_liquidation\":false},\"channel\":\"live_orders_btcusd\",\"event\":\"order_created\",\"event_id\":\"00065a1d-7f97-cc30-0000-000100000020\",\"pre_event_id\":\"00065a1d-7f97-a138-0000-000103000020\",\"order_source\":\"orderbook\"}","recorded_unix_us":1787932601502973}
{"message":"{\"data\":{\"id\":2044303879421954,\"id_str\":\"2044303879421954\",\"order_type\":1,\"order_subtype\":5,\"datetime\":\"1787932601\",\"microtimestamp\":\"1787932601470000\",\"amount\":0.1,\"amount_str\":\"0.10000000\",\"amount_traded\":\"0\",\"amount_at_create\":\"0.10000000\",\"price\":78522.63,\"price_str\":\"78522.63\",\"is_liquidation\":false},\"channel\":\"live_orders_btcusd\",\"event\":\"order_deleted\",\"event_id\":\"00065a1d-7f97-cc30-0001-000101000020\",\"pre_event_id\":\"00065a1d-7f97-cc30-0000-000100000020\",\"order_source\":\"orderbook\"}","recorded_unix_us":1787932601502989}
{"message":"{\"data\":{\"id\":2044303879430144,\"id_str\":\"2044303879430144\",\"order_type\":1,\"order_subtype\":5,\"datetime\":\"1787932601\",\"microtimestamp\":\"1787932601471000\",\"amount\":0.1,\"amount_str\":\"0.10000000\",\"amount_traded\":\"0\",\"amount_at_create\":\"0.10000000\",\"price\":78522.62,\"price_str\":\"78522.62\",\"is_liquidation\":false},\"channel\":\"live_orders_btcusd\",\"event\":\"order_created\",\"event_id\":\"00065a1d-7f97-d018-0000-000102000020\",\"pre_event_id\":\"00065a1d-7f97-cc30-0001-000101000020\",\"order_source\":\"orderbook\"}","recorded_unix_us":1787932601530974}
{"message":"{\"data\":{\"id\":2044303879430144,\"id_str\":\"2044303879430144\",\"order_type\":1,\"order_subtype\":5,\"datetime\":\"1787932601\",\"microtimestamp\":\"1787932601471000\",\"amount\":0.1,\"amount_str\":\"0.10000000\",\"amount_traded\":\"0\",\"amount_at_create\":\"0.10000000\",\"price\":78522.62,\"price_str\":\"78522.62\",\"is_liquidation\":false},\"channel\":\"live_orders_btcusd\",\"event\":\"order_deleted\",\"event_id\":\"00065a1d-7f97-d018-0001-000103000020\",\"pre_event_id\":\"00065a1d-7f97-d018-0000-000102000020\",\"order_source\":\"orderbook\"}","recorded_unix_us":1787932601531005}
{"message":"{\"data\":{\"id\":2044303859847170,\"id_str\":\"2044303859847170\",\"order_type\":1,\"order_subtype\":0,\"datetime\":\"1787932601\",\"microtimestamp\":\"1787932601476000\",\"amount\":0.06310787,\"amount_str\":\"0.06310787\",\"amount_traded\":\"0\",\"amount_at_create\":\"0.06310787\",\"price\":78555.58,\"price_str\":\"78555.58\",\"is_liquidation\":false},\"channel\":\"live_orders_btcusd\",\"event\":\"order_deleted\",\"event_id\":\"00065a1d-7f97-e3a0-0000-000100000020\",\"pre_event_id\":\"00065a1d-7f97-d018-0001-000103000020\",\"order_source\":\"orderbook\"}","recorded_unix_us":1787932601531102}
{"message":"{\"data\":{\"id\":2044303878922240,\"id_str\":\"2044303878922240\",\"order_type\":0,\"order_subtype\":5,\"datetime\":\"1787932601\",\"microtimestamp\":\"1787932601476000\",\"amount\":0.00140266,\"amount_str\":\"0.00140266\",\"amount_traded\":\"0\",\"amount_at_create\":\"0.00140266\",\"price\":70670.37,\"price_str\":\"70670.37\",\"is_liquidation\":false},\"channel\":\"live_orders_btcusd\",\"event\":\"order_deleted\",\"event_id\":\"00065a1d-7f97-e3a0-0001-000101000020\",\"pre_event_id\":\"00065a1d-7f97-e3a0-0000-000100000020\",\"order_source\":\"orderbook\"}","recorded_unix_us":1787932601531187}
{"message":"{\"data\":{\"id\":2044303879450628,\"id_str\":\"2044303879450628\",\"order_type\":1,\"order_subtype\":5,\"datetime\":\"1787932601\",\"microtimestamp\":\"1787932601476000\",\"amount\":1.26842789,\"amount_str\":\"1.26842789\",\"amount_traded\":\"0\",\"amount_at_create\":\"1.26842789\",\"price\":78837.75,\"price_str\":\"78837.75\",\"is_liquidation\":false},\"channel\":\"live_orders_btcusd\",\"event\":\"order_created\",\"event_id\":\"00065a1d-7f97-e3a0-0002-000102000020\",\"pre_event_id\":\"00065a1d-7f97-e3a0-0001-000101000020\",\"order_source\":\"orderbook\"}","recorded_unix_us":1787932601531310}
{"message":"{\"data\":{\"id\":2044303879249922,\"id_str\":\"2044303879249922\",\"order_type\":0,\"order_subtype\":5,\"datetime\":\"1787932601\",\"microtimestamp\":\"1787932601476000\",\"amount\":0.00140266,\"amount_str\":\"0.00140266\",\"amount_traded\":\"0\",\"amount_at_create\":\"0.00140266\",\"price\":70670.37,\"price_str\":\"70670.37\",\"is_liquidation\":false},\"channel\":\"live_orders_btcusd\",\"event\":\"order_deleted\",\"event_id\":\"00065a1d-7f97-e3a0-0003-000103000020\",\"pre_event_id\":\"00065a1d-7f97-e3a0-0002-000102000020\",\"order_source\":\"orderbook\"}","recorded_unix_us":1787932601531335}
{"message":"{\"data\":{\"id\":2044303879450629,\"id_str\":\"2044303879450629\",\"order_type\":1,\"order_subtype\":5,\"datetime\":\"1787932601\",\"microtimestamp\":\"1787932601476000\",\"amount\":1.271772,\"amount_str\":\"1.27177200\",\"amount_traded\":\"0\",\"amount_at_create\":\"1.27177200\",\"price\":78630.45,\"price_str\":\"78630.45\",\"is_liquidation\":false},\"channel\":\"live_orders_btcusd\",\"event\":\"order_created\",\"event_id\":\"00065a1d-7f97-e3a0-0004-000100000020\",\"pre_event_id\":\"00065a1d-7f97-e3a0-0003-000103000020\",\"order_source\":\"orderbook\"}","recorded_unix_us":1787932601531467}
{"message":"{\"data\":{\"id\":2044303879458820,\"id_str\":\"2044303879458820\",\"order_type\":0,\"order_subtype\":5,\"datetime\":\"1787932601\",\"microtimestamp\":\"1787932601479000\",\"amount\":0.06368334,\"amount_str\":\"0.06368334\",\"amount_traded\":\"0\",\"amount_at_create\":\"0.06368334\",\"price\":78513.46,\"price_str\":\"78513.46\",\"is_liquidation\":false},\"channel\":\"live_orders_btcusd\",\"event\":\"order_created\",\"event_id\":\"00065a1d-7f97-ef58-0000-000101000020\",\"pre_event_id\":\"00065a1d-7f97-e3a0-0004-000100000020\",\"order_source\":\"orderbook\"}","recorded_unix_us":1787932601531494}
{"message":"{\"data\":{\"id\":2044303879467021,\"id_str\":\"2044303879467021\",\"order_type\":0,\"order_subtype\":5,\"datetime\":\"1787932601\",\"microtimestamp\":\"1787932601481000\",\"amount\":1.27604867,\"amount_str\":\"1.27604867\",\"amount_traded\":\"0\",\"amount_at_create\":\"1.27604867\",\"price\":78366.91,\"price_str\":\"78366.91\",\"is_liquidation\":false},\"channel\":\"live_orders_btcusd\",\"event\":\"order_created\",\"event_id\":\"00065a1d-7f97-f728-0000-000102000020\",\"pre_event_id\":\"00065a1d-7f97-ef58-0000-000101000020\",\"order_source\":\"orderbook\"}","recorded_unix_us":1787932601531599}
{"message":"{\"data\":{\"id\":2044303879475200,\"id_str\":\"2044303879475200\",\"order_type\":0,\"order_subtype\":5,\"datetime\":\"1787932601\",\"microtimestamp\":\"1787932601482000\",\"amount\":1.27817952,\"amount_str\":\"1.27817952\",\"amount_traded\":\"0\",\"amount_at_create\":\"1.27817952\",\"price\":78236.27,\"price_str\":\"78236.27\",\"is_liquidation\":false},\"channel\":\"live_orders_btcusd\",\"event\":\"order_created\",\"event_id\":\"00065a1d-7f97-fb10-0000-000103000020\",\"pre_event_id\":\"00065a1d-7f97-f728-0000-000102000020\",\"order_source\":\"orderbook\"}","recorded_unix_us":1787932601531622}
{"message":"{\"data\":{\"id\":2044303879184389,\"id_str\":\"2044303879184389\",\"order_type\":1,\"order_subtype\":5,\"datetime\":\"1787932601\",\"microtimestamp\":\"1787932601484000\",\"amount\":0.1,\"amount_str\":\"0.10000000\",\"amount_traded\":\"0\",\"amount_at_create\":\"0.10000000\",\"price\":78522.74,\"price_str\":\"78522.74\",\"is_liquidation\":false},\"channel\":\"live_orders_btcusd\",\"event\":\"order_deleted\",\"event_id\":\"00065a1d-7f98-02e0-0000-000100000020\",\"pre_event_id\":\"00065a1d-7f97-fb10-0000-000103000020\",\"order_source\":\"orderbook\"}","recorded_unix_us":1787932601531694}
{"message":"{\"data\":{\"id\":2044303879032836,\"id_str\":\"2044303879032836\",\"order_type\":1,\"order_subtype\":5,\"datetime\":\"1787932601\",\"microtimestamp\":\"1787932601485000\",\"amount\":0.1,\"amount_str\":\"0.10000000\",\"amount_traded\":\"0\",\"amount_at_create\":\"0.10000000\",\"price\":78522.79,\"price_str\":\"78522.79\",\"is_liquidation\":false},\"channel\":\"live_orders_btcusd\",\"event\":\"order_deleted\",\"event_id\":\"00065a1d-7f98-06c8-0000-000101000020\",\"pre_event_id\":\"00065a1d-7f98-02e0-0000-000100000020\",\"order_source\":\"orderbook\"}","recorded_unix_us":1787932601531770}
{"message":"{\"data\":{\"id\":2044303878787076,\"id_str\":\"2044303878787076\",\"order_type\":1,\"order_subtype\":5,\"datetime\":\"1787932601\",\"microtimestamp\":\"1787932601485000\",\"amount\":0.1,\"amount_str\":\"0.10000000\",\"amount_traded\":\"0\",\"amount_at_create\":\"0.10000000\",\"price\":78523,\"price_str\":\"78523.00\",\"is_liquidation\":false},\"channel\":\"live_orders_btcusd\",\"event\":\"order_deleted\",\"event_id\":\"00065a1d-7f98-06c8-0001-000102000020\",\"pre_event_id\":\"00065a1d-7f98-06c8-0000-000101000020\",\"order_source\":\"orderbook\"}","recorded_unix_us":1787932601531843}
{"message":"{\"data\":{\"id\":2044303878619144,\"id_str\":\"2044303878619144\",\"order_type\":1,\"order_subtype\":5,\"datetime\":\"1787932601\",\"microtimestamp\":\"1787932601486000\",\"amount\":0.1,\"amount_str\":\"0.10000000\",\"amount_traded\":\"0\",\"amount_at_create\":\"0.10000000\",\"price\":78523.05,\"price_str\":\"78523.05\",\"is_liquidation\":false},\"channel\":\"live_orders_btcusd\",\"event\":\"order_deleted\",\"event_id\":\"00065a1d-7f98-0ab0-0000-000103000020\",\"pre_event_id\":\"00065a1d-7f98-06c8-0001-000102000020\",\"order_source\":\"orderbook\"}","recorded_unix_us":1787932601567797}
{"message":"{\"data\":{\"id\":2044303879491587,\"id_str\":\"2044303879491587\",\"order_type\":1,\"order_subtype\":5,\"datetime\":\"1787932601\",\"microtimestamp\":\"1787932601487000\",\"amount\":0.06310787,\"amount_str\":\"0.06310787\",\"amount_traded\":\"0\",\"amount_at_create\":\"0.06310787\",\"price\":78520.83,\"price_str\":\"78520.83\",\"is_liquidation\":false},\"channel\":\"live_orders_btcusd\",\"event\":\"order_created\",\"event_id\":\"00065a1d-7f98-0e98-0000-000100000020\",\"pre_event_id\":\"00065a1d-7f98-0ab0-0000-000103000020\",\"order_source\":\"orderbook\"}","recorded_unix_us":1787932601567980}
{"message":"{\"data\":{\"id\":2044303879491587,\"id_str\":\"2044303879491587\",\"order_type\":1,\"order_subtype\":5,\"datetime\":\"1787932601\",\"microtimestamp\":\"1787932601487000\",\"amount\":0.06310787,\"amount_str\":\"0.06310787\",\"amount_traded\":\"0\",\"amount_at_create\":\"0.06310787\",\"price\":78520.83,\"price_str\":\"78520.83\",\"is_liquidation\":false},\"channel\":\"live_orders_btcusd\",\"event\":\"order_deleted\",\"event_id\":\"00065a1d-7f98-0e98-0001-000101000020\",\"pre_event_id\":\"00065a1d-7f98-0e98-0000-000100000020\",\"order_source\":\"orderbook\"}","recorded_unix_us":1787932601568134}
{"message":"{\"data\":{\"id\":2044303879360520,\"id_str\":\"2044303879360520\",\"order_type\":0,\"order_subtype\":5,\"datetime\":\"1787932601\",\"microtimestamp\":\"1787932601491000\",\"amount\":0.06368219,\"amount_str\":\"0.06368219\",\"amount_traded\":\"0\",\"amount_at_create\":\"0.06368219\",\"price\":78514.87,\"price_str\":\"78514.87\",\"is_liquidation\":false},\"channel\":\"live_orders_btcusd\",\"event\":\"order_deleted\",\"event_id\":\"00065a1d-7f98-1e38-0000-000102000020\",\"pre_event_id\":\"00065a1d-7f98-0e98-0001-000101000020\",\"order_source\":\"orderbook\"}","recorded_unix_us":1787932601568253}
{"message":"{\"data\":{\"id\":2044303879516162,\"id_str\":\"2044303879516162\",\"order_type\":1,\"order_subtype\":5,\"datetime\":\"1787932601\",\"microtimestamp\":\"1787932601492000\",\"amount\":0.1,\"amount_str\":\"0.10000000\",\"amount_traded\":\"0\",\"amount_at_create\":\"0.10000000\",\"price\":78522.64,\"price_str\":\"78522.64\",\"is_liquidation\":false},\"channel\":\"live_orders_btcusd\",\"event\":\"order_created\",\"event_id\":\"00065a1d-7f98-2220-0000-000103000020\",\"pre_event_id\":\"00065a1d-7f98-1e38-0000-000102000020\",\"order_source\":\"orderbook\"}","recorded_unix_us":1787932601568366}
{"message":"{\"data\":{\"id\":2044303879516162,\"id_str\":\"2044303879516162\",\"order_type\":1,\"order_subtype\":5,\"datetime\":\"1787932601\",\"microtimestamp\":\"1787932601495000\",\"amount\":0.1,\"amount_str\":\"0.10000000\",\"amount_traded\":\"0\",\"amount_at_create\":\"0.10000000\",\"price\":78522.64,\"price_str\":\"78522.64\",\"is_liquidation\":false},\"channel\":\"live_orders_btcusd\",\"event\":\"order_deleted\",\"event_id\":\"00065a1d-7f98-2dd8-0000-000100000020\",\"pre_event_id\":\"00065a1d-7f98-2220-0000-000103000020\",\"order_source\":\"orderbook\"}","recorded_unix_us":1787932601568460}
{"message":"{\"data\":{\"id\":2044303878676498,\"id_str\":\"2044303878676498\",\"order_type\":0,\"order_subtype\":5,\"datetime\":\"1787932601\",\"microtimestamp\":\"1787932601496000\",\"amount\":0.403104,\"amount_str\":\"0.403104\",\"amount_traded\":\"0\",\"amount_at_create\":\"0.403104\",\"price\":2479.5,\"price_str\":\"2479.50\",\"is_liquidation\":false},\"channel\":\"live_orders_ethusd\",\"event\":\"order_deleted\",\"event_id\":\"00065a1d-7f98-31c0-0000-001200000020\",\"pre_event_id\":\"00065a1d-7f97-7258-0001-001203000020\",\"order_source\":\"orderbook\"}","recorded_unix_us":1787932601568556}
{"message":"{\"data\":{\"id\":2044303879536647,\"id_str\":\"2044303879536647\",\"order_type\":1,\"order_subtype\":5,\"datetime\":\"1787932601\",\"microtimestamp\":\"1787932601497000\",\"amount\":1.27145262,\"amount_str\":\"1.27145262\",\"amount_traded\":\"0\",\"amount_at_create\":\"1.27145262\",\"price\":78650.2,\"price_str\":\"78650.20\",\"is_liquidation\":false},\"channel\":\"live_orders_btcusd\",\"event\":\"order_created\",\"event_id\":\"00065a1d-7f98-35a8-0000-000101000020\",\"pre_event_id\":\"00065a1d-7f98-2dd8-0000-000100000020\",\"order_source\":\"orderbook\"}","recorded_unix_us":1787932601568664}
{"message":"{\"data\":{\"id\":2044303879540737,\"id_str\":\"2044303879540737\",\"order_type\":0,\"order_subtype\":5,\"datetime\":\"1787932601\",\"microtimestamp\":\"1787932601498000\",\"amount\":1.27888333,\"amount_str\":\"1.27888333\",\"amount_traded\":\"0\",\"amount_at_create\":\"1.27888333\",\"price\":78193.21,\"price_str\":\"78193.21\",\"is_liquidation\":false},\"channel\":\"live_orders_btcusd\",\"event\":\"order_created\",\"event_id\":\"00065a1d-7f98-3990-0000-000102000020\",\"pre_event_id\":\"00065a1d-7f98-35a8-0000-000101000020\",\"order_source\":\"orderbook\"}","recorded_unix_us":1787932601568849}
{"message":"{\"data\":{\"id\":2044303878205450,\"id_str\":\"2044303878205450\",\"order_type\":0,\"order_subtype\":5,\"datetime\":\"1787932602\",\"microtimestamp\":\"1787932601500000\",\"amount\":4.034894,\"amount_str\":\"4.034894\",\"amount_traded\":\"0\",\"amount_at_create\":\"4.034894\",\"price\":2478.37,\"price_str\":\"2478.37\",\"is_liquidation\":false},\"channel\":\"live_orders_ethusd\",\"event\":\"order_deleted\",\"event_id\":\"00065a1d-7f98-4160-0000-001201000020\",\"pre_event_id\":\"00065a1d-7f98-31c0-0000-001200000020\",\"order_source\":\"orderbook\"}","recorded_unix_us":1787932601568881}
{"message":"{\"data\":{\"id\":2044303879548929,\"id_str\":\"2044303879548929\",\"order_type\":1,\"order_subtype\":5,\"datetime\":\"1787932602\",\"microtimestamp\":\"1787932601500000\",\"amount\":0.1,\"amount_str\":\"0.10000000\",\"amount_traded\":\"0\",\"amount_at_create\":\"0.10000000\",\"price\":78522.63,\"price_str\":\"78522.63\",\"is_liquidation\":false},\"channel\":\"live_orders_btcusd\",\"event\":\"order_created\",\"event_id\":\"00065a1d-7f98-4160-0000-000103000020\",\"pre_event_id\":\"00065a1d-7f98-3990-0000-000102000020\",\"order_source\":\"orderbook\"}","recorded_unix_us":1787932601568907}
{"message":"{\"data\":{\"id\":2044303879548929,\"id_str\":\"2044303879548929\",\"order_type\":1,\"order_subtype\":5,\"datetime\":\"1787932602\",\"microtimestamp\":\"1787932601500000\",\"amount\":0.1,\"amount_str\":\"0.10000000\",\"amount_traded\":\"0\",\"amount_at_create\":\"0.10000000\",\"price\":78522.63,\"price_str\":\"78522.63\",\"is_liquidation\":false},\"channel\":\"live_orders_btcusd\",\"event\":\"order_deleted\",\"event_id\":\"00065a1d-7f98-4160-0001-000100000020\",\"pre_event_id\":\"00065a1d-7f98-4160-0000-000103000020\",\"order_source\":\"orderbook\"}","recorded_unix_us":1787932601568994}
{"message":"{\"data\":{\"id\":2044303879569410,\"id_str\":\"2044303879569410\",\"order_type\":0,\"order_subtype\":5,\"datetime\":\"1787932602\",\"microtimestamp\":\"1787932601505000\",\"amount\":0.403104,\"amount_str\":\"0.403104\",\"amount_traded\":\"0\",\"amount_at_create\":\"0.403104\",\"price\":2479.66,\"price_str\":\"2479.66\",\"is_liquidation\":false},\"channel\":\"live_orders_ethusd\",\"event\":\"order_created\",\"event_id\":\"00065a1d-7f98-54e8-0000-001202000020\",\"pre_event_id\":\"00065a1d-7f98-4160-0000-001201000020\",\"order_source\":\"orderbook\"}","recorded_unix_us":1787932601569119}
{"message":"{\"data\":{\"id\":2044303879569417,\"id_str\":\"2044303879569417\",\"order_type\":0,\"order_subtype\":5,\"datetime\":\"1787932602\",\"microtimestamp\":\"1787932601506000\",\"amount\":0.00140266,\"amount_str\":\"0.00140266\",\"amount_traded\":\"0\",\"amount_at_create\":\"0.00140266\",\"price\":70666.88,\"price_str\":\"70666.88\",\"is_liquidation\":false},\"channel\":\"live_orders_btcusd\",\"event\":\"order_created\",\"event_id\":\"00065a1d-7f98-58d0-0000-000101000020\",\"pre_event_id\":\"00065a1d-7f98-4160-0001-000100000020\",\"order_source\":\"orderbook\"}","recorded_unix_us":1787932601569218}
{"message":"{\"data\":{\"id\":2044303879606276,\"id_str\":\"2044303879606276\",\"order_type\":1,\"order_subtype\":5,\"datetime\":\"1787932602\",\"microtimestamp\":\"1787932601514000\",\"amount\":12.08882,\"amount_str\":\"12.088820\",\"amount_traded\":\"0\",\"amount_at_create\":\"12.088820\",\"price\":2481.64,\"price_str\":\"2481.64\",\"is_liquidation\":false},\"channel\":\"live_orders_ethusd\",\"event\":\"order_created\",\"event_id\":\"00065a1d-7f98-7810-0000-001203000020\",\"pre_event_id\":\"00065a1d-7f98-54e8-0000-001202000020\",\"order_source\":\"orderbook\"}","recorded_unix_us":1787932601569315}
{"message":"{\"data\":{\"id\":2044303879610369,\"id_str\":\"2044303879610369\",\"order_type\":1,\"order_subtype\":5,\"datetime\":\"1787932602\",\"microtimestamp\":\"1787932601516000\",\"amount\":12.087458,\"amount_str\":\"12.087458\",\"amount_traded\":\"0\",\"amount_at_create\":\"12.087458\",\"price\":2481.92,\"price_str\":\"2481.92\",\"is_liquidation\":false},\"channel\":\"live_orders_ethusd\",\"event\":\"order_created\",\"event_id\":\"00065a1d-7f98-7fe0-0000-001200000020\",\"pre_event_id\":\"00065a1d-7f98-7810-0000-001203000020\",\"order_source\":\"orderbook\"}","recorded_unix_us":1787932601569456}
{"message":"{\"data\":{\"id\":2044303879614464,\"id_str\":\"2044303879614464\",\"order_type\":0,\"order_subtype\":5,\"datetime\":\"1787932602\",\"microtimestamp\":\"1787932601516000\",\"amount\":0.06368105,\"amount_str\":\"0.06368105\",\"amount_traded\":\"0\",\"amount_at_create\":\"0.06368105\",\"price\":78516.28,\"price_str\":\"78516.28\",\"is_liquidation\":false},\"channel\":\"live_orders_btcusd\",\"event\":\"order_created\",\"event_id\":\"00065a1d-7f98-7fe0-0000-000102000020\",\"pre_event_id\":\"00065a1d-7f98-58d0-0000-000101000020\",\"order_source\":\"orderbook\"}","recorded_unix_us":1787932601569483}
{"message":"{\"data\":{\"id\":2044303879614465,\"id_str\":\"2044303879614465\",\"order_type\":1,\"order_subtype\":5,\"datetime\":\"1787932602\",\"microtimestamp\":\"1787932601517000\",\"amount\":10.06507,\"amount_str\":\"10.065070\",\"amount_traded\":\"0\",\"amount_at_create\":\"10.065070\",\"price\":2483.84,\"price_str\":\"2483.84\",\"is_liquidation\":false},\"channel\":\"live_orders_ethusd\",\"event\":\"order_created\",\"event_id\":\"00065a1d-7f98-83c8-0000-001201000020\",\"pre_event_id\":\"00065a1d-7f98-7fe0-0000-001200000020\",\"order_source\":\"orderbook\"}","recorded_unix_us":1787932601569578}
{"message":"{\"data\":{\"id\":2044303879622656,\"id_str\":\"2044303879622656\",\"order_type\":1,\"order_subtype\":5,\"datetime\":\"1787932602\",\"microtimestamp\":\"1787932601518000\",\"amount\":4.028874,\"amount_str\":\"4.028874\",\"amount_traded\":\"0\",\"amount_at_create\":\"4.028874\",\"price\":2482.09,\"price_str\":\"2482.09\",\"is_liquidation\":false},\"channel\":\"live_orders_ethusd\",\"event\":\"order_created\",\"event_id\":\"00065a1d-7f98-87b0-0000-001202000020\",\"pre_event_id\":\"00065a1d-7f98-83c8-0000-001201000020\",\"order_source\":\"orderbook\"}","recorded_unix_us":1787932601569709}
{"message":"{\"data\":{\"id\":2044303879622658,\"id_str\":\"2044303879622658\",\"order_type\":1,\"order_subtype\":5,\"datetime\":\"1787932602\",\"microtimestamp\":\"1787932601518000\",\"amount\":10.057184,\"amount_str\":\"10.057184\",\"amount_traded\":\"0\",\"amount_at_create\":\"10.057184\",\"price\":2485.79,\"price_str\":\"2485.79\",\"is_liquidation\":false},\"channel\":\"live_orders_ethusd\",\"event\":\"order_created\",\"event_id\":\"00065a1d-7f98-87b0-0001-001203000020\",\"pre_event_id\":\"00065a1d-7f98-87b0-0000-001202000020\",\"order_source\":\"orderbook\"}","recorded_unix_us":1787932601569750}
{"message":"{\"data\":{\"id\":2044303879622659,\"id_str\":\"2044303879622659\",\"order_type\":1,\"order_subtype\":5,\"datetime\":\"1787932602\",\"microtimestamp\":\"1787932601519000\",\"amount\":20.097242,\"amount_str\":\"20.097242\",\"amount_traded\":\"0\",\"amount_at_create\":\"20.097242\",\"price\":2487.91,\"price_str\":\"2487.91\",\"is_liquidation\":false},\"channel\":\"live_orders_ethusd\",\"event\":\"order_created\",\"event_id\":\"00065a1d-7f98-8b98-0000-001200000020\",\"pre_event_id\":\"00065a1d-7f98-87b0-0001-001203000020\",\"order_source\":\"orderbook\"}","recorded_unix_us":1787932601569777}
{"message":"{\"data\":{\"id\":2044303879626752,\"id_str\":\"2044303879626752\",\"order_type\":1,\"order_subtype\":5,\"datetime\":\"1787932602\",\"microtimestamp\":\"1787932601519000\",\"amount\":20.088574,\"amount_str\":\"20.088574\",\"amount_traded\":\"0\",\"amount_at_create\":\"20.088574\",\"price\":2488.98,\"price_str\":\"2488.98\",\"is_liquidation\":false},\"channel\":\"live_orders_ethusd\",\"event\":\"order_created\",\"event_id\":\"00065a1d-7f98-8b98-0001-001201000020\",\"pre_event_id\":\"00065a1d-7f98-8b98-0000-001200000020\",\"order_source\":\"orderbook\"}","recorded_unix_us":1787932601569878}
{"message":"{\"data\":{\"id\":2044303879630850,\"id_str\":\"2044303879630850\",\"order_type\":1,\"order_subtype\":5,\"datetime\":\"1787932602\",\"microtimestamp\":\"1787932601521000\",\"amount\":39.969006,\"amount_str\":\"39.969006\",\"amount_traded\":\"0\",\"amount_at_create\":\"39.969006\",\"price\":2501.94,\"price_str\":\"2501.94\",\"is_liquidation\":false},\"channel\":\"live_orders_ethusd\",\"event\":\"order_created\",\"event_id\":\"00065a1d-7f98-9368-0000-001202000020\",\"pre_event_id\":\"00065a1d-7f98-8b98-0001-001201000020\",\"order_source\":\"orderbook\"}","recorded_unix_us":1787932601586981}
{"message":"{\"data\":{\"id\":2044303879634947,\"id_str\":\"2044303879634947\",\"order_type\":1,\"order_subtype\":5,\"datetime\":\"1787932602\",\"microtimestamp\":\"1787932601521000\",\"amount\":40.09205,\"amount_str\":\"40.092050\",\"amount_traded\":\"0\",\"amount_at_create\":\"40.092050\",\"price\":2494.27,\"price_str\":\"2494.27\",\"is_liquidation\":false},\"channel\":\"live_orders_ethusd\",\"event\":\"order_created\",\"event_id\":\"00065a1d-7f98-9368-0001-001203000020\",\"pre_event_id\":\"00065a1d-7f98-9368-0000-001202000020\",\"order_source\":\"orderbook\"}","recorded_unix_us":1787932601587070}
{"message":"{\"data\":{\"id\":2044303879634948,\"id_str\":\"2044303879634948\",\"order_type\":0,\"order_subtype\":5,\"datetime\":\"1787932602\",\"microtimestamp\":\"1787932601521000\",\"amount\":4.033204,\"amount_str\":\"4.033204\",\"amount_traded\":\"0\",\"amount_at_create\":\"4.033204\",\"price\":2479.41,\"price_str\":\"2479.41\",\"is_liquidation\":false},\"channel\":\"live_orders_ethusd\",\"event\":\"order_created\",\"event_id\":\"00065a1d-7f98-9368-0002-001200000020\",\"pre_event_id\":\"00065a1d-7f98-9368-0001-001203000020\",\"order_source\":\"orderbook\"}","recorded_unix_us":1787932601587101}
{"message":"{\"data\":{\"id\":2044303879651332,\"id_str\":\"2044303879651332\",\"order_type\":1,\"order_subtype\":5,\"datetime\":\"1787932602\",\"microtimestamp\":\"1787932601526000\",\"amount\":0.1,\"amount_str\":\"0.10000000\",\"amount_traded\":\"0\",\"amount_at_create\":\"0.10000000\",\"price\":78522.62,\"price_str\":\"78522.62\",\"is_liquidation\":false},\"channel\":\"live_orders_btcusd\",\"event\":\"order_created\",\"event_id\":\"00065a1d-7f98-a6f0-0000-000103000020\",\"pre_event_id\":\"00065a1d-7f98-7fe0-0000-000102000020\",\"order_source\":\"orderbook\"}","recorded_unix_us":1787932601587567}
{"message":"{\"data\":{\"id\":2044303879651332,\"id_str\":\"2044303879651332\",\"order_type\":1,\"order_subtype\":5,\"datetime\":\"1787932602\",\"microtimestamp\":\"1787932601526000\",\"amount\":0.1,\"amount_str\":\"0.10000000\",\"amount_traded\":\"0\",\"amount_at_create\":\"0.10000000\",\"price\":78522.62,\"price_str\":\"78522.62\",\"is_liquidation\":false},\"channel\":\"live_orders_btcusd\",\"event\":\"order_deleted\",\"event_id\":\"00065a1d-7f98-a6f0-0001-000100000020\",\"pre_event_id\":\"00065a1d-7f98-a6f0-0000-000103000020\",\"order_source\":\"orderbook\"}","recorded_unix_us":1787932601587614}
{"message":"{\"data\":{\"id\":2044303879704578,\"id_str\":\"2044303879704578\",\"order_type\":1,\"order_subtype\":5,\"datetime\":\"1787932602\",\"microtimestamp\":\"1787932601538000\",\"amount\":4.028412,\"amount_str\":\"4.028412\",\"amount_traded\":\"0\",\"amount_at_create\":\"4.028412\",\"price\":2482.37,\"price_str\":\"2482.37\",\"is_liquidation\":false},\"channel\":\"live_orders_ethusd\",\"event\":\"order_created\",\"event_id\":\"00065a1d-7f98-d5d0-0000-001201000020\",\"pre_event_id\":\"00065a1d-7f98-9368-0002-001200000020\",\"order_source\":\"orderbook\"}","recorded_unix_us":1787932601587639}
{"message":"{\"data\":{\"id\":2044303879704580,\"id_str\":\"2044303879704580\",\"order_type\":1,\"order_subtype\":5,\"datetime\":\"1787932602\",\"microtimestamp\":\"1787932601539000\",\"amount\":20.077182,\"amount_str\":\"20.077182\",\"amount_traded\":\"0\",\"amount_at_create\":\"20.077182\",\"price\":2490.39,\"price_str\":\"2490.39\",\"is_liquidation\":false},\"channel\":\"live_orders_ethusd\",\"event\":\"order_created\",\"event_id\":\"00065a1d-7f98-d9b8-0000-001202000020\",\"pre_event_id\":\"00065a1d-7f98-d5d0-0000-001201000020\",\"order_source\":\"orderbook\"}","recorded_unix_us":1787932601587662}
{"message":"{\"data\":{\"id\":2044303879569417,\"id_str\":\"2044303879569417\",\"order_type\":0,\"order_subtype\":5,\"datetime\":\"1787932602\",\"microtimestamp\":\"1787932601539000\",\"amount\":0.00140266,\"amount_str\":\"0.00140266\",\"amount_traded\":\"0\",\"amount_at_create\":\"0.00140266\",\"price\":70666.88,\"price_str\":\"70666.88\",\"is_liquidation\":false},\"channel\":\"live_orders_btcusd\",\"event\":\"order_deleted\",\"event_id\":\"00065a1d-7f98-d9b8-0000-000101000020\",\"pre_event_id\":\"00065a1d-7f98-a6f0-0001-000100000020\",\"order_source\":\"orderbook\"}","recorded_unix_us":1787932601587684}
{"message":"{\"data\":{\"id\":2044303879704581,\"id_str\":\"2044303879704581\",\"order_type\":1,\"order_subtype\":5,\"datetime\":\"1787932602\",\"microtimestamp\":\"1787932601539000\",\"amount\":10.062547,\"amount_str\":\"10.062547\",\"amount_traded\":\"0\",\"amount_at_create\":\"10.062547\",\"price\":2484.47,\"price_str\":\"2484.47\",\"is_liquidation\":false},\"channel\":\"live_orders_ethusd\",\"event\":\"order_created\",\"event_id\":\"00065a1d-7f98-d9b8-0001-001203000020\",\"pre_event_id\":\"00065a1d-7f98-d9b8-0000-001202000020\",\"order_source\":\"orderbook\"}","recorded_unix_us":1787932601587758}
{"message":"{\"data\":{\"id\":2044303879708681,\"id_str\":\"2044303879708681\",\"order_type\":1,\"order_subtype\":5,\"datetime\":\"1787932602\",\"microtimestamp\":\"1787932601540000\",\"amount\":40.051178,\"amount_str\":\"40.051178\",\"amount_traded\":\"0\",\"amount_at_create\":\"40.051178\",\"price\":2496.81,\"price_str\":\"2496.81\",\"is_liquidation\":false},\"channel\":\"live_orders_ethusd\",\"event\":\"order_created\",\"event_id\":\"00065a1d-7f98-dda0-0000-001200000020\",\"pre_event_id\":\"00065a1d-7f98-d9b8-0001-001203000020\",\"order_source\":\"orderbook\"}","recorded_unix_us":1787932601587862}
{"message":"{\"data\":{\"id\":2044303879733256,\"id_str\":\"2044303879733256\",\"order_type\":1,\"order_subtype\":5,\"datetime\":\"1787932602\",\"microtimestamp\":\"1787932601546000\",\"amount\":0.06310787,\"amount_str\":\"0.06310787\",\"amount_traded\":\"0\",\"amount_at_create\":\"0.06310787\",\"price\":78520.44,\"price_str\":\"78520.44\",\"is_liquidation\":false},\"channel\":\"live_orders_btcusd\",\"event\":\"order_created\",\"event_id\":\"00065a1d-7f98-f510-0000-000102000020\",\"pre_event_id\":\"00065a1d-7f98-d9b8-0000-000101000020\",\"order_source\":\"orderbook\"}","recorded_unix_us":1787932601587909}
{"message":"{\"data\":{\"id\":2044303879733256,\"id_str\":\"2044303879733256\",\"order_type\":1,\"order_subtype\":5,\"datetime\":\"1787932602\",\"microtimestamp\":\"1787932601546000\",\"amount\":0.06310787,\"amount_str\":\"0.06310787\",\"amount_traded\":\"0\",\"amount_at_create\":\"0.06310787\",\"price\":78520.44,\"price_str\":\"78520.44\",\"is_liquidation\":false},\"channel\":\"live_orders_btcusd\",\"event\":\"order_deleted\",\"event_id\":\"00065a1d-7f98-f510-0001-000103000020\",\"pre_event_id\":\"00065a1d-7f98-f510-0000-000102000020\",\"order_source\":\"orderbook\"}","recorded_unix_us":1787932601587933}
{"message":"{\"data\":{\"id\":2044303879757827,\"id_str\":\"2044303879757827\",\"order_type\":1,\"order_subtype\":5,\"datetime\":\"1787932602\",\"microtimestamp\":\"1787932601552000\",\"amount\":0.1,\"amount_str\":\"0.10000000\",\"amount_traded\":\"0\",\"amount_at_create\":\"0.10000000\",\"price\":78522.63,\"price_str\":\"78522.63\",\"is_liquidation\":false},\"channel\":\"live_orders_btcusd\",\"event\":\"order_created\",\"event_id\":\"00065a1d-7f99-0c80-0000-000100000020\",\"pre_event_id\":\"00065a1d-7f98-f510-0001-000103000020\",\"order_source\":\"orderbook\"}","recorded_unix_us":1787932601593002}
{"message":"{\"data\":{\"id\":2044303879757827,\"id_str\":\"2044303879757827\",\"order_type\":1,\"order_subtype\":5,\"datetime\":\"1787932602\",\"microtimestamp\":\"1787932601552000\",\"amount\":0.1,\"amount_str\":\"0.10000000\",\"amount_traded\":\"0\",\"amount_at_create\":\"0.10000000\",\"price\":78522.63,\"price_str\":\"78522.63\",\"is_liquidation\":false},\"channel\":\"live_orders_btcusd\",\"event\":\"order_deleted\",\"event_id\":\"00065a1d-7f99-0c80-0001-000101000020\",\"pre_event_id\":\"00065a1d-7f99-0c80-0000-000100000020\",\"order_source\":\"orderbook\"}","recorded_unix_us":1787932601593032}
{"message":"{\"data\":{\"id\":2044303879774213,\"id_str\":\"2044303879774213\",\"order_type\":1,\"order_subtype\":5,\"datetime\":\"1787932602\",\"microtimestamp\":\"1787932601556000\",\"amount\":4.028003,\"amount_str\":\"4.028003\",\"amount_traded\":\"0\",\"amount_at_create\":\"4.028003\",\"price\":2482.62,\"price_str\":\"2482.62\",\"is_liquidation\":false},\"channel\":\"live_orders_ethusd\",\"event\":\"order_created\",\"event_id\":\"00065a1d-7f99-1c20-0000-001201000020\",\"pre_event_id\":\"00065a1d-7f98-dda0-0000-001200000020\",\"order_source\":\"orderbook\"}","recorded_unix_us":1787932601593178}
{"message":"{\"data\":{\"id\":2044303879778310,\"id_str\":\"2044303879778310\",\"order_type\":1,\"order_subtype\":5,\"datetime\":\"1787932602\",\"microtimestamp\":\"1787932601557000\",\"amount\":10.059779,\"amount_str\":\"10.059779\",\"amount_traded\":\"0\",\"amount_at_create\":\"10.059779\",\"price\":2485.15,\"price_str\":\"2485.15\",\"is_liquidation\":false},\"channel\":\"live_orders_ethusd\",\"event\":\"order_created\",\"event_id\":\"00065a1d-7f99-2008-0000-001202000020\",\"pre_event_id\":\"00065a1d-7f99-1c20-0000-001201000020\",\"order_source\":\"orderbook\"}","recorded_unix_us":1787932601593225}
{"message":"{\"data\":{\"id\":2044303879782401,\"id_str\":\"2044303879782401\",\"order_type\":1,\"order_subtype\":5,\"datetime\":\"1787932602\",\"microtimestamp\":\"1787932601557000\",\"amount\":20.063885,\"amount_str\":\"20.063885\",\"amount_traded\":\"0\",\"amount_at_create\":\"20.063885\",\"price\":2492.04,\"price_str\":\"2492.04\",\"is_liquidation\":false},\"channel\":\"live_orders_ethusd\",\"event\":\"order_created\",\"event_id\":\"00065a1d-7f99-2008-0001-001203000020\",\"pre_event_id\":\"00065a1d-7f99-2008-0000-001202000020\",\"order_source\":\"orderbook\"}","recorded_unix_us":1787932601593362}
{"message":"{\"data\":{\"id\":2044303879786499,\"id_str\":\"2044303879786499\",\"order_type\":1,\"order_subtype\":5,\"datetime\":\"1787932602\",\"microtimestamp\":\"1787932601559000\",\"amount\":40.010118,\"amount_str\":\"40.010118\",\"amount_traded\":\"0\",\"amount_at_create\":\"40.010118\",\"price\":2499.37,\"price_str\":\"2499.37\",\"is_liquidation\":false},\"channel\":\"live_orders_ethusd\",\"event\":\"order_created\",\"event_id\":\"00065a1d-7f99-27d8-0000-001200000020\",\"pre_event_id\":\"00065a1d-7f99-2008-0001-001203000020\",\"order_source\":\"orderbook\"}","recorded_unix_us":1787932601593392}
{"message":"{\"data\":{\"id\":2044303879794694,\"id_str\":\"2044303879794694\",\"order_type\":1,\"order_subtype\":5,\"datetime\":\"1787932602\",\"microtimestamp\":\"1787932601561000\",\"amount\":0.1,\"amount_str\":\"0.10000000\",\"amount_traded\":\"0\",\"amount_at_create\":\"0.10000000\",\"price\":78522.62,\"price_str\":\"78522.62\",\"is_liquidation\":false},\"channel\":\"live_orders_btcusd\",\"event\":\"order_created\",\"event_id\":\"00065a1d-7f99-2fa8-0000-000102000020\",\"pre_event_id\":\"00065a1d-7f99-0c80-0001-000101000020\",\"order_source\":\"orderbook\"}","recorded_unix_us":1787932601606244}
{"message":"{\"data\":{\"id\":2044303879794694,\"id_str\":\"2044303879794694\",\"order_type\":1,\"order_subtype\":5,\"datetime\":\"1787932602\",\"microtimestamp\":\"1787932601561000\",\"amount\":0.1,\"amount_str\":\"0.10000000\",\"amount_traded\":\"0\",\"amount_at_create\":\"0.10000000\",\"price\":78522.62,\"price_str\":\"78522.62\",\"is_liquidation\":false},\"channel\":\"live_orders_btcusd\",\"event\":\"order_deleted\",\"event_id\":\"00065a1d-7f99-2fa8-0001-000103000020\",\"pre_event_id\":\"00065a1d-7f99-2fa8-0000-000102000020\",\"order_source\":\"orderbook\"}","recorded_unix_us":1787932601606324}
{"message":"{\"data\":{\"id\":2044303879835654,\"id_str\":\"2044303879835654\",\"order_type\":0,\"order_subtype\":5,\"datetime\":\"1787932602\",\"microtimestamp\":\"1787932601571000\",\"amount\":1.2,\"amount_str\":\"1.20000000\",\"amount_traded\":\"0\",\"amount_at_create\":\"1.20000000\",\"price\":78482,\"price_str\":\"78482.00\",\"is_liquidation\":false},\"channel\":\"live_orders_btcusd\",\"event\":\"order_created\",\"event_id\":\"00065a1d-7f99-56b8-0000-000100000020\",\"pre_event_id\":\"00065a1d-7f99-2fa8-0001-000103000020\",\"order_source\":\"orderbook\"}","recorded_unix_us":1787932601606455}
{"message":"{\"data\":{\"id\":2044303879839747,\"id_str\":\"2044303879839747\",\"order_type\":1,\"order_subtype\":5,\"datetime\":\"1787932602\",\"microtimestamp\":\"1787932601572000\",\"amount\":0.06310787,\"amount_str\":\"0.06310787\",\"amount_traded\":\"0\",\"amount_at_create\":\"0.06310787\",\"price\":78520.35,\"price_str\":\"78520.35\",\"is_liquidation\":false},\"channel\":\"live_orders_btcusd\",\"event\":\"order_created\",\"event_id\":\"00065a1d-7f99-5aa0-0000-000101000020\",\"pre_event_id\":\"00065a1d-7f99-56b8-0000-000100000020\",\"order_source\":\"orderbook\"}","recorded_unix_us":1787932601606522}
{"message":"{\"data\":{\"id\":2044303879839747,\"id_str\":\"2044303879839747\",\"order_type\":1,\"order_subtype\":5,\"datetime\":\"1787932602\",\"microtimestamp\":\"1787932601572000\",\"amount\":0.06310787,\"amount_str\":\"0.06310787\",\"amount_traded\":\"0\",\"amount_at_create\":\"0.06310787\",\"price\":78520.35,\"price_str\":\"78520.35\",\"is_liquidation\":false},\"channel\":\"live_orders_btcusd\",\"event\":\"order_deleted\",\"event_id\":\"00065a1d-7f99-5aa0-0001-000102000020\",\"pre_event_id\":\"00065a1d-7f99-5aa0-0000-000101000020\",\"order_source\":\"orderbook\"}","recorded_unix_us":1787932601606549}
{"message":"{\"data\":{\"id\":2044303879847937,\"id_str\":\"2044303879847937\",\"order_type\":1,\"order_subtype\":5,\"datetime\":\"1787932602\",\"microtimestamp\":\"1787932601573000\",\"amount\":4.027586,\"amount_str\":\"4.027586\",\"amount_traded\":\"0\",\"amount_at_create\":\"4.027586\",\"price\":2482.88,\"price_str\":\"2482.88\",\"is_liquidation\":false},\"channel\":\"live_orders_ethusd\",\"event\":\"order_created\",\"event_id\":\"00065a1d-7f99-5e88-0000-001201000020\",\"pre_event_id\":\"00065a1d-7f99-27d8-0000-001200000020\",\"order_source\":\"orderbook\"}","recorded_unix_us":1787932601606627}
{"message":"{\"data\":{\"id\":2044303879860225,\"id_str\":\"2044303879860225\",\"order_type\":1,\"order_subtype\":5,\"datetime\":\"1787932602\",\"microtimestamp\":\"1787932601577000\",\"amount\":1.2,\"amount_str\":\"1.20000000\",\"amount_traded\":\"0\",\"amount_at_create\":\"1.20000000\",\"price\":78525,\"price_str\":\"78525.00\",\"is_liquidation\":false},\"channel\":\"live_orders_btcusd\",\"event\":\"order_created\",\"event_id\":\"00065a1d-7f99-6e28-0000-000103000020\",\"pre_event_id\":\"00065a1d-7f99-5aa0-0001-000102000020\",\"order_source\":\"orderbook\"}","recorded_unix_us":1787932601624968}
{"message":"{\"data\":{\"id\":2044303877263369,\"id_str\":\"2044303877263369\",\"order_type\":1,\"order_subtype\":5,\"datetime\":\"1787932602\",\"microtimestamp\":\"1787932601580000\",\"amount\":5,\"amount_str\":\"5.000000\",\"amount_traded\":\"0\",\"amount_at_create\":\"5.000000\",\"price\":2481.49,\"price_str\":\"2481.49\",\"is_liquidation\":false},\"channel\":\"live_orders_ethusd\",\"event\":\"order_deleted\",\"event_id\":\"00065a1d-7f99-79e0-0000-001202000020\",\"pre_event_id\":\"00065a1d-7f99-5e88-0000-001201000020\",\"order_source\":\"orderbook\"}","recorded_unix_us":1787932601625158}
{"message":"{\"data\":{\"id\":2044303877292039,\"id_str\":\"2044303877292039\",\"order_type\":1,\"order_subtype\":5,\"datetime\":\"1787932602\",\"microtimestamp\":\"1787932601580000\",\"amount\":5,\"amount_str\":\"5.000000\",\"amount_traded\":\"0\",\"amount_at_create\":\"5.000000\",\"price\":2481.74,\"price_str\":\"2481.74\",\"is_liquidation\":false},\"channel\":\"live_orders_ethusd\",\"event\":\"order_deleted\",\"event_id\":\"00065a1d-7f99-79e0-0001-001203000020\",\"pre_event_id\":\"00065a1d-7f99-79e0-0000-001202000020\",\"order_source\":\"orderbook\"}","recorded_unix_us":1787932601625261}
{"message":"{\"data\":{\"id\":2044303879913472,\"id_str\":\"2044303879913472\",\"order_type\":1,\"order_subtype\":5,\"datetime\":\"1787932602\",\"microtimestamp\":\"1787932601589000\",\"amount\":0.1,\"amount_str\":\"0.10000000\",\"amount_traded\":\"0\",\"amount_at_create\":\"0.10000000\",\"price\":78522.63,\"price_str\":\"78522.63\",\"is_liquidation\":false},\"channel\":\"live_orders_btcusd\",\"event\":\"order_created\",\"event_id\":\"00065a1d-7f99-9d08-0000-000100000020\",\"pre_event_id\":\"00065a1d-7f99-6e28-0000-000103000020\",\"order_source\":\"orderbook\"}","recorded_unix_us":1787932601625362}
{"message":"{\"data\":{\"id\":2044303879913472,\"id_str\":\"2044303879913472\",\"order_type\":1,\"order_subtype\":5,\"datetime\":\"1787932602\",\"microtimestamp\":\"1787932601589000\",\"amount\":0.1,\"amount_str\":\"0.10000000\",\"amount_traded\":\"0\",\"amount_at_create\":\"0.10000000\",\"price\":78522.63,\"price_str\":\"78522.63\",\"is_liquidation\":false},\"channel\":\"live_orders_btcusd\",\"event\":\"order_deleted\",\"event_id\":\"00065a1d-7f99-9d08-0001-000101000020\",\"pre_event_id\":\"00065a1d-7f99-9d08-0000-000100000020\",\"order_source\":\"orderbook\"}","recorded_unix_us":1787932601625449}
{"message":"{\"data\":{\"id\":2044303879917571,\"id_str\":\"2044303879917571\",\"order_type\":0,\"order_subtype\":5,\"datetime\":\"1787932602\",\"microtimestamp\":\"1787932601590000\",\"amount\":0.00140266,\"amount_str\":\"0.00140266\",\"amount_traded\":\"0\",\"amount_at_create\":\"0.00140266\",\"price\":70667.51,\"price_str\":\"70667.51\",\"is_liquidation\":false},\"channel\":\"live_orders_btcusd\",\"event\":\"order_created\",\"event_id\":\"00065a1d-7f99-a0f0-0000-000102000020\",\"pre_event_id\":\"00065a1d-7f99-9d08-0001-000101000020\",\"order_source\":\"orderbook\"}","recorded_unix_us":1787932601630093}
{"message":"{\"data\":{\"id\":2044303859847183,\"id_str\":\"2044303859847183\",\"order_type\":1,\"order_subtype\":0,\"datetime\":\"1787932602\",\"microtimestamp\":\"1787932601594000\",\"amount\":0.06310787,\"amount_str\":\"0.06310787\",\"amount_traded\":\"0\",\"amount_at_create\":\"0.06310787\",\"price\":78550.86,\"price_str\":\"78550.86\",\"is_liquidation\":false},\"channel\":\"live_orders_btcusd\",\"event\":\"order_deleted\",\"event_id\":\"00065a1d-7f99-b090-0000-000103000020\",\"pre_event_id\":\"00065a1d-7f99-a0f0-0000-000102000020\",\"order_source\":\"orderbook\"}","recorded_unix_us":1787932601630218}
{"message":"{\"data\":{\"id\":2044303879962625,\"id_str\":\"2044303879962625\",\"order_type\":1,\"order_subtype\":5,\"datetime\":\"1787932602\",\"microtimestamp\":\"1787932601602000\",\"amount\":0.06310787,\"amount_str\":\"0.06310787\",\"amount_traded\":\"0\",\"amount_at_create\":\"0.06310787\",\"price\":78520.22,\"price_str\":\"78520.22\",\"is_liquidation\":false},\"channel\":\"live_orders_btcusd\",\"event\":\"order_created\",\"event_id\":\"00065a1d-7f99-cfd0-0000-000100000020\",\"pre_event_id\":\"00065a1d-7f99-b090-0000-000103000020\",\"order_source\":\"orderbook\"}","recorded_unix_us":1787932601630361}
{"message":"{\"data\":{\"id\":2044303879962625,\"id_str\":\"2044303879962625\",\"order_type\":1,\"order_subtype\":5,\"datetime\":\"1787932602\",\"microtimestamp\":\"1787932601602000\",\"amount\":0.06310787,\"amount_str\":\"0.06310787\",\"amount_traded\":\"0\",\"amount_at_create\":\"0.06310787\",\"price\":78520.22,\"price_str\":\"78520.22\",\"is_liquidation\":false},\"channel\":\"live_orders_btcusd\",\"event\":\"order_deleted\",\"event_id\":\"00065a1d-7f99-cfd0-0001-000101000020\",\"pre_event_id\":\"00065a1d-7f99-cfd0-0000-000100000020\",\"order_source\":\"orderbook\"}","recorded_unix_us":1787932601630391}
{"message":"{\"data\":{\"id\":2044303879974913,\"id_str\":\"2044303879974913\",\"order_type\":1,\"order_subtype\":5,\"datetime\":\"1787932602\",\"microtimestamp\":\"1787932601604000\",\"amount\":0.1,\"amount_str\":\"0.10000000\",\"amount_traded\":\"0\",\"amount_at_create\":\"0.10000000\",\"price\":78522.62,\"price_str\":\"78522.62\",\"is_liquidation\":false},\"channel\":\"live_orders_btcusd\",\"event\":\"order_created\",\"event_id\":\"00065a1d-7f99-d7a0-0000-000102000020\",\"pre_event_id\":\"00065a1d-7f99-cfd0-0001-000101000020\",\"order_source\":\"orderbook\"}","recorded_unix_us":1787932601648900}
{"message":"{\"data\":{\"id\":2044303879974913,\"id_str\":\"2044303879974913\",\"order_type\":1,\"order_subtype\":5,\"datetime\":\"1787932602\",\"microtimestamp\":\"1787932601604000\",\"amount\":0.1,\"amount_str\":\"0.10000000\",\"amount_traded\":\"0\",\"amount_at_create\":\"0.10000000\",\"price\":78522.62,\"price_str\":\"78522.62\",\"is_liquidation\":false},\"channel\":\"live_orders_btcusd\",\"event\":\"order_deleted\",\"event_id\":\"00065a1d-7f99-d7a0-0001-000103000020\",\"pre_event_id\":\"00065a1d-7f99-d7a0-0000-000102000020\",\"order_source\":\"orderbook\"}","recorded_unix_us":1787932601649128}
{"message":"{\"data\":{\"id\":2044303879979008,\"id_str\":\"2044303879979008\",\"order_type\":1,\"order_subtype\":5,\"datetime\":\"1787932602\",\"microtimestamp\":\"1787932601606000\",\"amount\":0.06310787,\"amount_str\":\"0.06310787\",\"amount_traded\":\"0\",\"amount_at_create\":\"0.06310787\",\"price\":78522.58,\"price_str\":\"78522.58\",\"is_liquidation\":false},\"channel\":\"live_orders_btcusd\",\"event\":\"order_created\",\"event_id\":\"00065a1d-7f99-df70-0000-000100000020\",\"pre_event_id\":\"00065a1d-7f99-d7a0-0001-000103000020\",\"order_source\":\"orderbook\"}","recorded_unix_us":1787932601649175}
{"message":"{\"data\":{\"id\":2044303879979008,\"id_str\":\"2044303879979008\",\"order_type\":1,\"order_subtype\":5,\"datetime\":\"1787932602\",\"microtimestamp\":\"1787932601606000\",\"amount\":0.06310787,\"amount_str\":\"0.06310787\",\"amount_traded\":\"0\",\"amount_at_create\":\"0.06310787\",\"price\":78522.58,\"price_str\":\"78522.58\",\"is_liquidation\":false},\"channel\":\"live_orders_btcusd\",\"event\":\"order_deleted\",\"event_id\":\"00065a1d-7f99-df70-0001-000101000020\",\"pre_event_id\":\"00065a1d-7f99-df70-0000-000100000020\",\"order_source\":\"orderbook\"}","recorded_unix_us":1787932601649293}
{"message":"{\"data\":{\"id\":2044303880036355,\"id_str\":\"2044303880036355\",\"order_type\":1,\"order_subtype\":5,\"datetime\":\"1787932602\",\"microtimestamp\":\"1787932601619000\",\"amount\":0.1,\"amount_str\":\"0.10000000\",\"amount_traded\":\"0\",\"amount_at_create\":\"0.10000000\",\"price\":78522.63,\"price_str\":\"78522.63\",\"is_liquidation\":false},\"channel\":\"live_orders_btcusd\",\"event\":\"order_created\",\"event_id\":\"00065a1d-7f9a-1238-0000-000102000020\",\"pre_event_id\":\"00065a1d-7f99-df70-0001-000101000020\",\"order_source\":\"orderbook\"}","recorded_unix_us":1787932601663126}
{"message":"{\"data\":{\"id\":2044303880036355,\"id_str\":\"2044303880036355\",\"order_type\":1,\"order_subtype\":5,\"datetime\":\"1787932602\",\"microtimestamp\":\"1787932601619000\",\"amount\":0.1,\"amount_str\":\"0.10000000\",\"amount_traded\":\"0\",\"amount_at_create\":\"0.10000000\",\"price\":78522.63,\"price_str\":\"78522.63\",\"is_liquidation\":false},\"channel\":\"live_orders_btcusd\",\"event\":\"order_deleted\",\"event_id\":\"00065a1d-7f9a-1238-0001-000103000020\",\"pre_event_id\":\"00065a1d-7f9a-1238-0000-000102000020\",\"order_source\":\"orderbook\"}","recorded_unix_us":1787932601663238}
{"message":"{\"data\":{\"id\":2044303844184069,\"id_str\":\"2044303844184069\",\"order_type\":1,\"order_subtype\":5,\"datetime\":\"1787932602\",\"microtimestamp\":\"1787932601637000\",\"amount\":0.13516584,\"amount_str\":\"0.13516584\",\"amount_traded\":\"0\",\"amount_at_create\":\"0.13516584\",\"price\":0.03429999,\"price_str\":\"0.03429999\",\"is_liquidation\":false},\"channel\":\"live_orders_ethbtc\",\"event\":\"order_deleted\",\"event_id\":\"00065a1d-7f9a-5888-0000-001102000020\",\"pre_event_id\":\"00065a1d-7f97-1498-0000-001101000020\",\"order_source\":\"orderbook\"}","recorded_unix_us":1787932601676242}
{"message":"{\"data\":{\"id\":2044303877484546,\"id_str\":\"2044303877484546\",\"order_type\":0,\"order_subtype\":5,\"datetime\":\"1787932602\",\"microtimestamp\":\"1787932601641000\",\"amount\":0.35667323,\"amount_str\":\"0.35667323\",\"amount_traded\":\"0\",\"amount_at_create\":\"0.35667323\",\"price\":78486.82,\"price_str\":\"78486.82\",\"is_liquidation\":false},\"channel\":\"live_orders_btcusd\",\"event\":\"order_deleted\",\"event_id\":\"00065a1d-7f9a-6828-0000-000100000020\",\"pre_event_id\":\"00065a1d-7f9a-1238-0001-000103000020\",\"order_source\":\"orderbook\"}","recorded_unix_us":1787932601676442}
{"message":"{\"data\":{\"id\":2044303880122368,\"id_str\":\"2044303880122368\",\"order_type\":0,\"order_subtype\":5,\"datetime\":\"1787932602\",\"microtimestamp\":\"1787932601641000\",\"amount\":0.26750492,\"amount_str\":\"0.26750492\",\"amount_traded\":\"0\",\"amount_at_create\":\"0.26750492\",\"price\":78486.82,\"price_str\":\"78486.82\",\"is_liquidation\":false},\"channel\":\"live_orders_btcusd\",\"event\":\"order_created\",\"event_id\":\"00065a1d-7f9a-6828-0001-000101000020\",\"pre_event_id\":\"00065a1d-7f9a-6828-0000-000100000020\",\"order_source\":\"orderbook\"}","recorded_unix_us":1787932601676560}
{"message":"{\"data\":{\"id\":2044303880138752,\"id_str\":\"2044303880138752\",\"order_type\":0,\"order_subtype\":5,\"datetime\":\"1787932602\",\"microtimestamp\":\"1787932601645000\",\"amount\":0.60475617,\"amount_str\":\"0.60475617\",\"amount_traded\":\"0\",\"amount_at_create\":\"0.60475617\",\"price\":0.03158982,\"price_str\":\"0.03158982\",\"is_liquidation\":false},\"channel\":\"live_orders_ethbtc\",\"event\":\"order_created\",\"event_id\":\"00065a1d-7f9a-77c8-0000-001103000020\",\"pre_event_id\":\"00065a1d-7f9a-5888-0000-001102000020\",\"order_source\":\"orderbook\"}","recorded_unix_us":1787932601676644}
{"message":"{\"data\":{\"id\":2044303880151042,\"id_str\":\"2044303880151042\",\"order_type\":1,\"order_subtype\":5,\"datetime\":\"1787932602\",\"microtimestamp\":\"1787932601648000\",\"amount\":0.06310787,\"amount_str\":\"0.06310787\",\"amount_traded\":\"0\",\"amount_at_create\":\"0.06310787\",\"price\":78520.32,\"price_str\":\"78520.32\",\"is_liquidation\":false},\"channel\":\"live_orders_btcusd\",\"event\":\"order_created\",\"event_id\":\"00065a1d-7f9a-8380-0000-000102000020\",\"pre_event_id\":\"00065a1d-7f9a-6828-0001-000101000020\",\"order_source\":\"orderbook\"}","recorded_unix_us":1787932601676752}
{"message":"{\"data\":{\"id\":2044303880151042,\"id_str\":\"2044303880151042\",\"order_type\":1,\"order_subtype\":5,\"datetime\":\"1787932602\",\"microtimestamp\":\"1787932601648000\",\"amount\":0.06310787,\"amount_str\":\"0.06310787\",\"amount_traded\":\"0\",\"amount_at_create\":\"0.06310787\",\"price\":78520.32,\"price_str\":\"78520.32\",\"is_liquidation\":false},\"channel\":\"live_orders_btcusd\",\"event\":\"order_deleted\",\"event_id\":\"00065a1d-7f9a-8380-0001-000103000020\",\"pre_event_id\":\"00065a1d-7f9a-8380-0000-000102000020\",\"order_source\":\"orderbook\"}","recorded_unix_us":1787932601676779}
{"message":"{\"data\":{\"id\":2044303880155139,\"id_str\":\"2044303880155139\",\"order_type\":1,\"order_subtype\":5,\"datetime\":\"1787932602\",\"microtimestamp\":\"1787932601648000\",\"amount\":5,\"amount_str\":\"5.000000\",\"amount_traded\":\"0\",\"amount_at_create\":\"5.000000\",\"price\":2481.48,\"price_str\":\"2481.48\",\"is_liquidation\":false},\"channel\":\"live_orders_ethusd\",\"event\":\"order_created\",\"event_id\":\"00065a1d-7f9a-8380-0000-001200000020\",\"pre_event_id\":\"00065a1d-7f99-79e0-0001-001203000020\",\"order_source\":\"orderbook\"}","recorded_unix_us":1787932601676906}
{"message":"{\"data\":{\"id\":2044303880159233,\"id_str\":\"2044303880159233\",\"order_type\":1,\"order_subtype\":5,\"datetime\":\"1787932602\",\"microtimestamp\":\"1787932601649000\",\"amount\":0.1,\"amount_str\":\"0.10000000\",\"amount_traded\":\"0\",\"amount_at_create\":\"0.10000000\",\"price\":78522.62,\"price_str\":\"78522.62\",\"is_liquidation\":false},\"channel\":\"live_orders_btcusd\",\"event\":\"order_created\",\"event_id\":\"00065a1d-7f9a-8768-0000-000100000020\",\"pre_event_id\":\"00065a1d-7f9a-8380-0001-000103000020\",\"order_source\":\"orderbook\"}","recorded_unix_us":1787932601691193}
{"message":"{\"data\":{\"id\":2044303880159233,\"id_str\":\"2044303880159233\",\"order_type\":1,\"order_subtype\":5,\"datetime\":\"1787932602\",\"microtimestamp\":\"1787932601649000\",\"amount\":0.1,\"amount_str\":\"0.10000000\",\"amount_traded\":\"0\",\"amount_at_create\":\"0.10000000\",\"price\":78522.62,\"price_str\":\"78522.62\",\"is_liquidation\":false},\"channel\":\"live_orders_btcusd\",\"event\":\"order_deleted\",\"event_id\":\"00065a1d-7f9a-8768-0001-000101000020\",\"pre_event_id\":\"00065a1d-7f9a-8768-0000-000100000020\",\"order_source\":\"orderbook\"}","recorded_unix_us":1787932601691587}
{"message":"{\"data\":{\"id\":2044303880212480,\"id_str\":\"2044303880212480\",\"order_type\":1,\"order_subtype\":5,\"datetime\":\"1787932602\",\"microtimestamp\":\"1787932601662000\",\"amount\":0.1,\"amount_str\":\"0.10000000\",\"amount_traded\":\"0\",\"amount_at_create\":\"0.10000000\",\"price\":78522.63,\"price_str\":\"78522.63\",\"is_liquidation\":false},\"channel\":\"live_orders_btcusd\",\"event\":\"order_created\",\"event_id\":\"00065a1d-7f9a-ba30-0000-000102000020\",\"pre_event_id\":\"00065a1d-7f9a-8768-0001-000101000020\",\"order_source\":\"orderbook\"}","recorded_unix_us":1787932601705366}
{"message":"{\"data\":{\"id\":2044303880212480,\"id_str\":\"2044303880212480\",\"order_type\":1,\"order_subtype\":5,\"datetime\":\"1787932602\",\"microtimestamp\":\"1787932601662000\",\"amount\":0.1,\"amount_str\":\"0.10000000\",\"amount_traded\":\"0\",\"amount_at_create\":\"0.10000000\",\"price\":78522.63,\"price_str\":\"78522.63\",\"is_liquidation\":false},\"channel\":\"live_orders_btcusd\",\"event\":\"order_deleted\",\"event_id\":\"00065a1d-7f9a-ba30-0001-000103000020\",\"pre_event_id\":\"00065a1d-7f9a-ba30-0000-000102000020\",\"order_source\":\"orderbook\"}","recorded_unix_us":1787932601705399}
{"message":"{\"data\":{\"id\":2044303800680448,\"id_str\":\"2044303800680448\",\"order_type\":0,\"order_subtype\":5,\"datetime\":\"1787932602\",\"microtimestamp\":\"1787932601666000\",\"amount\":0.18113665,\"amount_str\":\"0.18113665\",\"amount_traded\":\"0\",\"amount_at_create\":\"0.18113665\",\"price\":0.03020011,\"price_str\":\"0.03020011\",\"is_liquidation\":false},\"channel\":\"live_orders_ethbtc\",\"event\":\"order_deleted\",\"event_id\":\"00065a1d-7f9a-c9d0-0000-001100000020\",\"pre_event_id\":\"00065a1d-7f9a-77c8-0000-001103000020\",\"order_source\":\"orderbook\"}","recorded_unix_us":1787932601705516}
{"message":"{\"data\":{\"id\":2044303790809101,\"id_str\":\"2044303790809101\",\"order_type\":0,\"order_subtype\":5,\"datetime\":\"1787932602\",\"microtimestamp\":\"1787932601667000\",\"amount\":0.08102965,\"amount_str\":\"0.08102965\",\"amount_traded\":\"0\",\"amount_at_create\":\"0.08102965\",\"price\":0.03020009,\"price_str\":\"0.03020009\",\"is_liquidation\":false},\"channel\":\"live_orders_ethbtc\",\"event\":\"order_deleted\",\"event_id\":\"00065a1d-7f9a-cdb8-0000-001101000020\",\"pre_event_id\":\"00065a1d-7f9a-c9d0-0000-001100000020\",\"order_source\":\"orderbook\"}","recorded_unix_us":1787932601705628}
{"message":"{\"data\":{\"id\":2044303880228867,\"id_str\":\"2044303880228867\",\"order_type\":0,\"order_subtype\":5,\"datetime\":\"1787932602\",\"microtimestamp\":\"1787932601667000\",\"amount\":0.00140266,\"amount_str\":\"0.00140266\",\"amount_traded\":\"0\",\"amount_at_create\":\"0.00140266\",\"price\":70667.51,\"price_str\":\"70667.51\",\"is_liquidation\":false},\"channel\":\"live_orders_btcusd\",\"event\":\"order_created\",\"event_id\":\"00065a1d-7f9a-cdb8-0000-000100000020\",\"pre_event_id\":\"00065a1d-7f9a-ba30-0001-000103000020\",\"order_source\":\"orderbook\"}","recorded_unix_us":1787932601705732}
{"message":"{\"data\":{\"id\":2044303880253440,\"id_str\":\"2044303880253440\",\"order_type\":1,\"order_subtype\":5,\"datetime\":\"1787932602\",\"microtimestamp\":\"1787932601673000\",\"amount\":0.06310787,\"amount_str\":\"0.06310787\",\"amount_traded\":\"0\",\"amount_at_create\":\"0.06310787\",\"price\":78520.04,\"price_str\":\"78520.04\",\"is_liquidation\":false},\"channel\":\"live_orders_btcusd\",\"event\":\"order_created\",\"event_id\":\"00065a1d-7f9a-e528-0000-000101000020\",\"pre_event_id\":\"00065a1d-7f9a-cdb8-0000-000100000020\",\"order_source\":\"orderbook\"}","recorded_unix_us":1787932601705835}
{"message":"{\"data\":{\"id\":2044303880253440,\"id_str\":\"2044303880253440\",\"order_type\":1,\"order_subtype\":5,\"datetime\":\"1787932602\",\"microtimestamp\":\"1787932601673000\",\"amount\":0.06310787,\"amount_str\":\"0.06310787\",\"amount_traded\":\"0\",\"amount_at_create\":\"0.06310787\",\"price\":78520.04,\"price_str\":\"78520.04\",\"is_liquidation\":false},\"channel\":\"live_orders_btcusd\",\"event\":\"order_deleted\",\"event_id\":\"00065a1d-7f9a-e528-0001-000102000020\",\"pre_event_id\":\"00065a1d-7f9a-e528-0000-000101000020\",\"order_source\":\"orderbook\"}","recorded_unix_us":1787932601705949}
{"message":"{\"data\":{\"id\":2044303880261632,\"id_str\":\"2044303880261632\",\"order_type\":1,\"order_subtype\":5,\"datetime\":\"1787932602\",\"microtimestamp\":\"1787932601675000\",\"amount\":0.06310787,\"amount_str\":\"0.06310787\",\"amount_traded\":\"0\",\"amount_at_create\":\"0.06310787\",\"price\":78522.4,\"price_str\":\"78522.40\",\"is_liquidation\":false},\"channel\":\"live_orders_btcusd\",\"event\":\"order_created\",\"event_id\":\"00065a1d-7f9a-ecf8-0000-000103000020\",\"pre_event_id\":\"00065a1d-7f9a-e528-0001-000102000020\",\"order_source\":\"orderbook\"}","recorded_unix_us":1787932601713827}
{"message":"{\"data\":{\"id\":2044303880261632,\"id_str\":\"2044303880261632\",\"order_type\":1,\"order_subtype\":5,\"datetime\":\"1787932602\",\"microtimestamp\":\"1787932601675000\",\"amount\":0.06310787,\"amount_str\":\"0.06310787\",\"amount_traded\":\"0\",\"amount_at_create\":\"0.06310787\",\"price\":78522.4,\"price_str\":\"78522.40\",\"is_liquidation\":false},\"channel\":\"live_orders_btcusd\",\"event\":\"order_deleted\",\"event_id\":\"00065a1d-7f9a-ecf8-0001-000100000020\",\"pre_event_id\":\"00065a1d-7f9a-ecf8-0000-000103000020\",\"order_source\":\"orderbook\"}","recorded_unix_us":1787932601714032}
{"message":"{\"data\":{\"id\":2044303878684678,\"id_str\":\"2044303878684678\",\"order_type\":0,\"order_subtype\":5,\"datetime\":\"1787932602\",\"microtimestamp\":\"1787932601684000\",\"amount\":0.403103,\"amount_str\":\"0.403103\",\"amount_traded\":\"0\",\"amount_at_create\":\"0.403103\",\"price\":2480.01,\"price_str\":\"2480.01\",\"is_liquidation\":false},\"channel\":\"live_orders_ethusd\",\"event\":\"order_deleted\",\"event_id\":\"00065a1d-7f9b-1020-0000-001201000020\",\"pre_event_id\":\"00065a1d-7f9a-8380-0000-001200000020\",\"order_source\":\"orderbook\"}","recorded_unix_us":1787932601717231}
{"message":"{\"data\":{\"id\":2044303880318976,\"id_str\":\"2044303880318976\",\"order_type\":1,\"order_subtype\":5,\"datetime\":\"1787932602\",\"microtimestamp\":\"1787932601688000\",\"amount\":0.1,\"amount_str\":\"0.10000000\",\"amount_traded\":\"0\",\"amount_at_create\":\"0.10000000\",\"price\":78522.62,\"price_str\":\"78522.62\",\"is_liquidation\":false},\"channel\":\"live_orders_btcusd\",\"event\":\"order_created\",\"event_id\":\"00065a1d-7f9b-1fc0-0000-000101000020\",\"pre_event_id\":\"00065a1d-7f9a-ecf8-0001-000100000020\",\"order_source\":\"orderbook\"}","recorded_unix_us":1787932601749792}
{"message":"{\"data\":{\"id\":2044303880318976,\"id_str\":\"2044303880318976\",\"order_type\":1,\"order_subtype\":5,\"datetime\":\"1787932602\",\"microtimestamp\":\"1787932601688000\",\"amount\":0.1,\"amount_str\":\"0.10000000\",\"amount_traded\":\"0\",\"amount_at_create\":\"0.10000000\",\"price\":78522.62,\"price_str\":\"78522.62\",\"is_liquidation\":false},\"channel\":\"live_orders_btcusd\",\"event\":\"order_deleted\",\"event_id\":\"00065a1d-7f9b-1fc0-0001-000102000020\",\"pre_event_id\":\"00065a1d-7f9b-1fc0-0000-000101000020\",\"order_source\":\"orderbook\"}","recorded_unix_us":1787932601749866}
{"message":"{\"data\":{\"id\":2044303880323082,\"id_str\":\"2044303880323082\",\"order_type\":0,\"order_subtype\":5,\"datetime\":\"1787932602\",\"microtimestamp\":\"1787932601690000\",\"amount\":0.403104,\"amount_str\":\"0.403104\",\"amount_traded\":\"0\",\"amount_at_create\":\"0.403104\",\"price\":2480.15,\"price_str\":\"2480.15\",\"is_liquidation\":false},\"channel\":\"live_orders_ethusd\",\"event\":\"order_created\",\"event_id\":\"00065a1d-7f9b-2790-0000-001202000020\",\"pre_event_id\":\"00065a1d-7f9b-1020-0000-001201000020\",\"order_source\":\"orderbook\"}","recorded_unix_us":1787932601753278}
{"message":"{\"data\":{\"id\":2044303878041600,\"id_str\":\"2044303878041600\",\"order_type\":0,\"order_subtype\":5,\"datetime\":\"1787932602\",\"microtimestamp\":\"1787932601698000\",\"amount\":4.034022,\"amount_str\":\"4.034022\",\"amount_traded\":\"0\",\"amount_at_create\":\"4.034022\",\"price\":2478.91,\"price_str\":\"2478.91\",\"is_liquidation\":false},\"channel\":\"live_orders_ethusd\",\"event\":\"order_deleted\",\"event_id\":\"00065a1d-7f9b-46d0-0000-001203000020\",\"pre_event_id\":\"00065a1d-7f9b-2790-0000-001202000020\",\"order_source\":\"orderbook\"}","recorded_unix_us":1787932601753351}
{"message":"{\"data\":{\"id\":2044303880359937,\"id_str\":\"2044303880359937\",\"order_type\":1,\"order_subtype\":5,\"datetime\":\"1787932602\",\"microtimestamp\":\"1787932601698000\",\"amount\":0.1,\"amount_str\":\"0.10000000\",\"amount_traded\":\"0\",\"amount_at_create\":\"0.10000000\",\"price\":78522.63,\"price_str\":\"78522.63\",\"is_liquidation\":false},\"channel\":\"live_orders_btcusd\",\"event\":\"order_created\",\"event_id\":\"00065a1d-7f9b-46d0-0000-000103000020\",\"pre_event_id\":\"00065a1d-7f9b-1fc0-0001-000102000020\",\"order_source\":\"orderbook\"}","recorded_unix_us":1787932601753376}
{"message":"{\"data\":{\"id\":2044303880359937,\"id_str\":\"2044303880359937\",\"order_type\":1,\"order_subtype\":5,\"datetime\":\"1787932602\",\"microtimestamp\":\"1787932601698000\",\"amount\":0.1,\"amount_str\":\"0.10000000\",\"amount_traded\":\"0\",\"amount_at_create\":\"0.10000000\",\"price\":78522.63,\"price_str\":\"78522.63\",\"is_liquidation\":false},\"channel\":\"live_orders_btcusd\",\"event\":\"order_deleted\",\"event_id\":\"00065a1d-7f9b-46d0-0001-000100000020\",\"pre_event_id\":\"00065a1d-7f9b-46d0-0000-000103000020\",\"order_source\":\"orderbook\"}","recorded_unix_us":1787932601753398}
{"message":"{\"data\":{\"id\":2044303878041604,\"id_str\":\"2044303878041604\",\"order_type\":0,\"order_subtype\":5,\"datetime\":\"1787932602\",\"microtimestamp\":\"1787932601698000\",\"amount\":20.215084,\"amount_str\":\"20.215084\",\"amount_traded\":\"0\",\"amount_at_create\":\"20.215084\",\"price\":2473.4,\"price_str\":\"2473.40\",\"is_liquidation\":false},\"channel\":\"live_orders_ethusd\",\"event\":\"order_deleted\",\"event_id\":\"00065a1d-7f9b-46d0-0001-001200000020\",\"pre_event_id\":\"00065a1d-7f9b-46d0-0000-001203000020\",\"order_source\":\"orderbook\"}","recorded_unix_us":1787932601753418}
{"message":"{\"data\":{\"id\":2044303878041611,\"id_str\":\"2044303878041611\",\"order_type\":0,\"order_subtype\":5,\"datetime\":\"1787932602\",\"microtimestamp\":\"1787932601699000\",\"amount\":40.568517,\"amount_str\":\"40.568517\",\"amount_traded\":\"0\",\"amount_at_create\":\"40.568517\",\"price\":2464.96,\"price_str\":\"2464.96\",\"is_liquidation\":false},\"channel\":\"live_orders_ethusd\",\"event\":\"order_deleted\",\"event_id\":\"00065a1d-7f9b-4ab8-0000-001201000020\",\"pre_event_id\":\"00065a1d-7f9b-46d0-0001-001200000020\",\"order_source\":\"orderbook\"}","recorded_unix_us":1787932601753505}
{"message":"{\"data\":{\"id\":2044303878631428,\"id_str\":\"2044303878631428\",\"order_type\":0,\"order_subtype\":5,\"datetime\":\"1787932602\",\"microtimestamp\":\"1787932601699000\",\"amount\":0.19103753,\"amount_str\":\"0.19103753\",\"amount_traded\":\"0\",\"amount_at_create\":\"0.19103753\",\"price\":78483.49,\"price_str\":\"78483.49\",\"is_liquidation\":false},\"channel\":\"live_orders_btcusd\",\"event\":\"order_deleted\",\"event_id\":\"00065a1d-7f9b-4ab8-0000-000101000020\",\"pre_event_id\":\"00065a1d-7f9b-46d0-0001-000100000020\",\"order_source\":\"orderbook\"}","recorded_unix_us":1787932601753647}
{"message":"{\"data\":{\"id\":2044303878041612,\"id_str\":\"2044303878041612\",\"order_type\":0,\"order_subtype\":5,\"datetime\":\"1787932602\",\"microtimestamp\":\"1787932601699000\",\"amount\":10.092689,\"amount_str\":\"10.092689\",\"amount_traded\":\"0\",\"amount_at_create\":\"10.092689\",\"price\":2477.04,\"price_str\":\"2477.04\",\"is_liquidation\":false},\"channel\":\"live_orders_ethusd\",\"event\":\"order_deleted\",\"event_id\":\"00065a1d-7f9b-4ab8-0001-001202000020\",\"pre_event_id\":\"00065a1d-7f9b-4ab8-0000-001201000020\",\"order_source\":\"orderbook\"}","recorded_unix_us":1787932601872565}
{"message":"{\"data\":{\"id\":2044303878045704,\"id_str\":\"2044303878045704\",\"order_type\":0,\"order_subtype\":5,\"datetime\":\"1787932602\",\"microtimestamp\":\"1787932601699000\",\"amount\":10.097738,\"amount_str\":\"10.097738\",\"amount_traded\":\"0\",\"amount_at_create\":\"10.097738\",\"price\":2475.8,\"price_str\":\"2475.80\",\"is_liquidation\":false},\"channel\":\"live_orders_ethusd\",\"event\":\"order_deleted\",\"event_id\":\"00065a1d-7f9b-4ab8-0002-001203000020\",\"pre_event_id\":\"00065a1d-7f9b-4ab8-0001-001202000020\",\"order_source\":\"orderbook\"}","recorded_unix_us":1787932601872608}
{"message":"{\"data\":{\"id\":2044303878115334,\"id_str\":\"2044303878115334\",\"order_type\":0,\"order_subtype\":5,\"datetime\":\"1787932602\",\"microtimestamp\":\"1787932601700000\",\"amount\":4.034214,\"amount_str\":\"4.034214\",\"amount_traded\":\"0\",\"amount_at_create\":\"4.034214\",\"price\":2478.79,\"price_str\":\"2478.79\",\"is_liquidation\":false},\"channel\":\"live_orders_ethusd\",\"event\":\"order_deleted\",\"event_id\":\"00065a1d-7f9b-4ea0-0000-001200000020\",\"pre_event_id\":\"00065a1d-7f9b-4ab8-0002-001203000020\",\"order_source\":\"orderbook\"}","recorded_unix_us":1787932601872734}
{"message":"{\"data\":{\"id\":2044303878115341,\"id_str\":\"2044303878115341\",\"order_type\":0,\"order_subtype\":5,\"datetime\":\"1787932602\",\"microtimestamp\":\"1787932601700000\",\"amount\":20.225289,\"amount_str\":\"20.225289\",\"amount_traded\":\"0\",\"amount_at_create\":\"20.225289\",\"price\":2472.15,\"price_str\":\"2472.15\",\"is_liquidation\":false},\"channel\":\"live_orders_ethusd\",\"event\":\"order_deleted\",\"event_id\":\"00065a1d-7f9b-4ea0-0001-001201000020\",\"pre_event_id\":\"00065a1d-7f9b-4ea0-0000-001200000020\",\"order_source\":\"orderbook\"}","recorded_unix_us":1787932601872782}
{"message":"{\"data\":{\"id\":2044303878119437,\"id_str\":\"2044303878119437\",\"order_type\":0,\"order_subtype\":5,\"datetime\":\"1787932602\",\"microtimestamp\":\"1787932601700000\",\"amount\":40.609081,\"amount_str\":\"40.609081\",\"amount_traded\":\"0\",\"amount_at_create\":\"40.609081\",\"price\":2462.5,\"price_str\":\"2462.50\",\"is_liquidation\":false},\"channel\":\"live_orders_ethusd\",\"event\":\"order_deleted\",\"event_id\":\"00065a1d-7f9b-4ea0-0002-001202000020\",\"pre_event_id\":\"00065a1d-7f9b-4ea0-0001-001201000020\",\"order_source\":\"orderbook\"}","recorded_unix_us":1787932601872872}
{"message":"{\"data\":{\"id\":2044303878213635,\"id_str\":\"2044303878213635\",\"order_type\":0,\"order_subtype\":5,\"datetime\":\"1787932602\",\"microtimestamp\":\"1787932601701000\",\"amount\":20.235437,\"amount_str\":\"20.235437\",\"amount_traded\":\"0\",\"amount_at_create\":\"20.235437\",\"price\":2470.91,\"price_str\":\"2470.91\",\"is_liquidation\":false},\"channel\":\"live_orders_ethusd\",\"event\":\"order_deleted\",\"event_id\":\"00065a1d-7f9b-5288-0000-001203000020\",\"pre_event_id\":\"00065a1d-7f9b-4ea0-0002-001202000020\",\"order_source\":\"orderbook\"}","recorded_unix_us":1787932601873002}
{"message":"{\"data\":{\"id\":2044303878287371,\"id_str\":\"2044303878287371\",\"order_type\":0,\"order_subtype\":5,\"datetime\":\"1787932602\",\"microtimestamp\":\"1787932601701000\",\"amount\":10.090138,\"amount_str\":\"10.090138\",\"amount_traded\":\"0\",\"amount_at_create\":\"10.090138\",\"price\":2477.66,\"price_str\":\"2477.66\",\"is_liquidation\":false},\"channel\":\"live_orders_ethusd\",\"event\":\"order_deleted\",\"event_id\":\"00065a1d-7f9b-5288-0001-001200000020\",\"pre_event_id\":\"00065a1d-7f9b-5288-0000-001203000020\",\"order_source\":\"orderbook\"}","recorded_unix_us":1787932601873031}
{"message":"{\"data\":{\"id\":2044303878291460,\"id_str\":\"2044303878291460\",\"order_type\":0,\"order_subtype\":5,\"datetime\":\"1787932602\",\"microtimestamp\":\"1787932601702000\",\"amount\":10.095101,\"amount_str\":\"10.095101\",\"amount_traded\":\"0\",\"amount_at_create\":\"10.095101\",\"price\":2476.44,\"price_str\":\"2476.44\",\"is_liquidation\":false},\"channel\":\"live_orders_ethusd\",\"event\":\"order_deleted\",\"event_id\":\"00065a1d-7f9b-5670-0000-001201000020\",\"pre_event_id\":\"00065a1d-7f9b-5288-0001-001200000020\",\"order_source\":\"orderbook\"}","recorded_unix_us":1787932601873158}
{"message":"{\"data\":{\"id\":2044303877025794,\"id_str\":\"2044303877025794\",\"order_type\":0,\"order_subtype\":5,\"datetime\":\"1787932602\",\"microtimestamp\":\"1787932601702000\",\"amount\":5,\"amount_str\":\"5.000000\",\"amount_traded\":\"0\",\"amount_at_create\":\"5.000000\",\"price\":2480.78,\"price_str\":\"2480.78\",\"is_liquidation\":false},\"channel\":\"live_orders_ethusd\",\"event\":\"order_deleted\",\"event_id\":\"00065a1d-7f9b-5670-0001-001202000020\",\"pre_event_id\":\"00065a1d-7f9b-5670-0000-001201000020\",\"order_source\":\"orderbook\"}","recorded_unix_us":1787932601873183}
{"message":"{\"data\":{\"id\":2044303878291467,\"id_str\":\"2044303878291467\",\"order_type\":0,\"order_subtype\":5,\"datetime\":\"1787932602\",\"microtimestamp\":\"1787932601702000\",\"amount\":40.650432,\"amount_str\":\"40.650432\",\"amount_traded\":\"0\",\"amount_at_create\":\"40.650432\",\"price\":2459.99,\"price_str\":\"2459.99\",\"is_liquidation\":false},\"channel\":\"live_orders_ethusd\",\"event\":\"order_deleted\",\"event_id\":\"00065a1d-7f9b-5670-0002-001203000020\",\"pre_event_id\":\"00065a1d-7f9b-5670-0001-001202000020\",\"order_source\":\"orderbook\"}","recorded_unix_us":1787932601873203}
{"message":"{\"data\":{\"id\":2044303878295552,\"id_str\":\"2044303878295552\",\"order_type\":0,\"order_subtype\":5,\"datetime\":\"1787932602\",\"microtimestamp\":\"1787932601702000\",\"amount\":4.033601,\"amount_str\":\"4.033601\",\"amount_traded\":\"0\",\"amount_at_create\":\"4.033601\",\"price\":2479.17,\"price_str\":\"2479.17\",\"is_liquidation\":false},\"channel\":\"live_orders_ethusd\",\"event\":\"order_deleted\",\"event_id\":\"00065a1d-7f9b-5670-0003-001200000020\",\"pre_event_id\":\"00065a1d-7f9b-5670-0002-001203000020\",\"order_source\":\"orderbook\"}","recorded_unix_us":1787932601873313}
{"message":"{\"data\":{\"id\":2044303878295553,\"id_str\":\"2044303878295553\",\"order_type\":0,\"order_subtype\":5,\"datetime\":\"1787932602\",\"microtimestamp\":\"1787932601703000\",\"amount\":20.204386,\"amount_str\":\"20.204386\",\"amount_traded\":\"0\",\"amount_at_create\":\"20.204386\",\"price\":2474.71,\"price_str\":\"2474.71\",\"is_liquidation\":false},\"channel\":\"live_orders_ethusd\",\"event\":\"order_deleted\",\"event_id\":\"00065a1d-7f9b-5a58-0000-001201000020\",\"pre_event_id\":\"00065a1d-7f9b-5670-0003-001200000020\",\"order_source\":\"orderbook\"}","recorded_unix_us":1787932601873429}
{"message":"{\"data\":{\"id\":2044303878295557,\"id_str\":\"2044303878295557\",\"order_type\":0,\"order_subtype\":5,\"datetime\":\"1787932602\",\"microtimestamp\":\"1787932601703000\",\"amount\":40.528033,\"amount_str\":\"40.528033\",\"amount_traded\":\"0\",\"amount_at_create\":\"40.528033\",\"price\":2467.42,\"price_str\":\"2467.42\",\"is_liquidation\":false},\"channel\":\"live_orders_ethusd\",\"event\":\"order_deleted\",\"event_id\":\"00065a1d-7f9b-5a58-0001-001202000020\",\"pre_event_id\":\"00065a1d-7f9b-5a58-0000-001201000020\",\"order_source\":\"orderbook\"}","recorded_unix_us":1787932601873460}
{"message":"{\"data\":{\"id\":2044303878365186,\"id_str\":\"2044303878365186\",\"order_type\":0,\"order_subtype\":5,\"datetime\":\"1787932602\",\"microtimestamp\":\"1787932601703000\",\"amount\":12.096906,\"amount_str\":\"12.096906\",\"amount_traded\":\"0\",\"amount_at_create\":\"12.096906\",\"price\":2479.97,\"price_str\":\"2479.97\",\"is_liquidation\":false},\"channel\":\"live_orders_ethusd\",\"event\":\"order_deleted\",\"event_id\":\"00065a1d-7f9b-5a58-0002-001203000020\",\"pre_event_id\":\"00065a1d-7f9b-5a58-0001-001202000020\",\"order_source\":\"orderbook\"}","recorded_unix_us":1787932601873618}
{"message":"{\"data\":{\"id\":2044303878365189,\"id_str\":\"2044303878365189\",\"order_type\":0,\"order_subtype\":5,\"datetime\":\"1787932602\",\"microtimestamp\":\"1787932601704000\",\"amount\":12.098474,\"amount_str\":\"12.098474\",\"amount_traded\":\"0\",\"amount_at_create\":\"12.098474\",\"price\":2479.65,\"price_str\":\"2479.65\",\"is_liquidation\":false},\"channel\":\"live_orders_ethusd\",\"event\":\"order_deleted\",\"event_id\":\"00065a1d-7f9b-5e40-0000-001200000020\",\"pre_event_id\":\"00065a1d-7f9b-5a58-0002-001203000020\",\"order_source\":\"orderbook\"}","recorded_unix_us":1787932601873650}
{"message":"{\"data\":{\"id\":2044303879606276,\"id_str\":\"2044303879606276\",\"order_type\":1,\"order_subtype\":5,\"datetime\":\"1787932602\",\"microtimestamp\":\"1787932601704000\",\"amount\":12.08882,\"amount_str\":\"12.088820\",\"amount_traded\":\"0\",\"amount_at_create\":\"12.088820\",\"price\":2481.64,\"price_str\":\"2481.64\",\"is_liquidation\":false},\"channel\":\"live_orders_ethusd\",\"event\":\"order_deleted\",\"event_id\":\"00065a1d-7f9b-5e40-0001-001201000020\",\"pre_event_id\":\"00065a1d-7f9b-5e40-0000-001200000020\",\"order_source\":\"orderbook\"}","recorded_unix_us":1787932601873678}
{"message":"{\"data\":{\"id\":2044303879610369,\"id_str\":\"2044303879610369\",\"order_type\":1,\"order_subtype\":5,\"datetime\":\"1787932602\",\"microtimestamp\":\"1787932601704000\",\"amount\":12.087458,\"amount_str\":\"12.087458\",\"amount_traded\":\"0\",\"amount_at_create\":\"12.087458\",\"price\":2481.92,\"price_str\":\"2481.92\",\"is_liquidation\":false},\"channel\":\"live_orders_ethusd\",\"event\":\"order_deleted\",\"event_id\":\"00065a1d-7f9b-5e40-0002-001202000020\",\"pre_event_id\":\"00065a1d-7f9b-5e40-0001-001201000020\",\"order_source\":\"orderbook\"}","recorded_unix_us":1787932601873778}
{"message":"{\"data\":{\"id\":2044303879614465,\"id_str\":\"2044303879614465\",\"order_type\":1,\"order_subtype\":5,\"datetime\":\"1787932602\",\"microtimestamp\":\"1787932601705000\",\"amount\":10.06507,\"amount_str\":\"10.065070\",\"amount_traded\":\"0\",\"amount_at_create\":\"10.065070\",\"price\":2483.84,\"price_str\":\"2483.84\",\"is_liquidation\":false},\"channel\":\"live_orders_ethusd\",\"event\":\"order_deleted\",\"event_id\":\"00065a1d-7f9b-6228-0000-001203000020\",\"pre_event_id\":\"00065a1d-7f9b-5e40-0002-001202000020\",\"order_source\":\"orderbook\"}","recorded_unix_us":1787932601873929}
{"message":"{\"data\":{\"id\":2044303879622656,\"id_str\":\"2044303879622656\",\"order_type\":1,\"order_subtype\":5,\"datetime\":\"1787932602\",\"microtimestamp\":\"1787932601705000\",\"amount\":4.028874,\"amount_str\":\"4.028874\",\"amount_traded\":\"0\",\"amount_at_create\":\"4.028874\",\"price\":2482.09,\"price_str\":\"2482.09\",\"is_liquidation\":false},\"channel\":\"live_orders_ethusd\",\"event\":\"order_deleted\",\"event_id\":\"00065a1d-7f9b-6228-0001-001200000020\",\"pre_event_id\":\"00065a1d-7f9b-6228-0000-001203000020\",\"order_source\":\"orderbook\"}","recorded_unix_us":1787932601873960}
{"message":"{\"data\":{\"id\":2044303879622658,\"id_str\":\"2044303879622658\",\"order_type\":1,\"order_subtype\":5,\"datetime\":\"1787932602\",\"microtimestamp\":\"1787932601705000\",\"amount\":10.057184,\"amount_str\":\"10.057184\",\"amount_traded\":\"0\",\"amount_at_create\":\"10.057184\",\"price\":2485.79,\"price_str\":\"2485.79\",\"is_liquidation\":false},\"channel\":\"live_orders_ethusd\",\"event\":\"order_deleted\",\"event_id\":\"00065a1d-7f9b-6228-0002-001201000020\",\"pre_event_id\":\"00065a1d-7f9b-6228-0001-001200000020\",\"order_source\":\"orderbook\"}","recorded_unix_us":1787932601874114}
{"message":"{\"data\":{\"id\":2044303879622659,\"id_str\":\"2044303879622659\",\"order_type\":1,\"order_subtype\":5,\"datetime\":\"1787932602\",\"microtimestamp\":\"1787932601706000\",\"amount\":20.097242,\"amount_str\":\"20.097242\",\"amount_traded\":\"0\",\"amount_at_create\":\"20.097242\",\"price\":2487.91,\"price_str\":\"2487.91\",\"is_liquidation\":false},\"channel\":\"live_orders_ethusd\",\"event\":\"order_deleted\",\"event_id\":\"00065a1d-7f9b-6610-0000-001202000020\",\"pre_event_id\":\"00065a1d-7f9b-6228-0002-001201000020\",\"order_source\":\"orderbook\"}","recorded_unix_us":1787932601874196}
{"message":"{\"data\":{\"id\":2044303879626752,\"id_str\":\"2044303879626752\",\"order_type\":1,\"order_subtype\":5,\"datetime\":\"1787932602\",\"microtimestamp\":\"1787932601706000\",\"amount\":20.088574,\"amount_str\":\"20.088574\",\"amount_traded\":\"0\",\"amount_at_create\":\"20.088574\",\"price\":2488.98,\"price_str\":\"2488.98\",\"is_liquidation\":false},\"channel\":\"live_orders_ethusd\",\"event\":\"order_deleted\",\"event_id\":\"00065a1d-7f9b-6610-0001-001203000020\",\"pre_event_id\":\"00065a1d-7f9b-6610-0000-001202000020\",\"order_source\":\"orderbook\"}","recorded_unix_us":1787932601874227}
{"message":"{\"data\":{\"id\":2044303879630850,\"id_str\":\"2044303879630850\",\"order_type\":1,\"order_subtype\":5,\"datetime\":\"1787932602\",\"microtimestamp\":\"1787932601706000\",\"amount\":39.969006,\"amount_str\":\"39.969006\",\"amount_traded\":\"0\",\"amount_at_create\":\"39.969006\",\"price\":2501.94,\"price_str\":\"2501.94\",\"is_liquidation\":false},\"channel\":\"live_orders_ethusd\",\"event\":\"order_deleted\",\"event_id\":\"00065a1d-7f9b-6610-0002-001200000020\",\"pre_event_id\":\"00065a1d-7f9b-6610-0001-001203000020\",\"order_source\":\"orderbook\"}","recorded_unix_us":1787932601874435}
{"message":"{\"data\":{\"id\":2044303879634947,\"id_str\":\"2044303879634947\",\"order_type\":1,\"order_subtype\":5,\"datetime\":\"1787932602\",\"microtimestamp\":\"1787932601707000\",\"amount\":40.09205,\"amount_str\":\"40.092050\",\"amount_traded\":\"0\",\"amount_at_create\":\"40.092050\",\"price\":2494.27,\"price_str\":\"2494.27\",\"is_liquidation\":false},\"channel\":\"live_orders_ethusd\",\"event\":\"order_deleted\",\"event_id\":\"00065a1d-7f9b-69f8-0000-001201000020\",\"pre_event_id\":\"00065a1d-7f9b-6610-0002-001200000020\",\"order_source\":\"orderbook\"}","recorded_unix_us":1787932601874465}
{"message":"{\"data\":{\"id\":2044303879634948,\"id_str\":\"2044303879634948\",\"order_type\":0,\"order_subtype\":5,\"datetime\":\"1787932602\",\"microtimestamp\":\"1787932601707000\",\"amount\":4.033204,\"amount_str\":\"4.033204\",\"amount_traded\":\"0\",\"amount_at_create\":\"4.033204\",\"price\":2479.41,\"price_str\":\"2479.41\",\"is_liquidation\":false},\"channel\":\"live_orders_ethusd\",\"event\":\"order_deleted\",\"event_id\":\"00065a1d-7f9b-69f8-0001-001202000020\",\"pre_event_id\":\"00065a1d-7f9b-69f8-0000-001201000020\",\"order_source\":\"orderbook\"}","recorded_unix_us":1787932601874491}
{"message":"{\"data\":{\"id\":2044303879704578,\"id_str\":\"2044303879704578\",\"order_type\":1,\"order_subtype\":5,\"datetime\":\"1787932602\",\"microtimestamp\":\"1787932601707000\",\"amount\":4.028412,\"amount_str\":\"4.028412\",\"amount_traded\":\"0\",\"amount_at_create\":\"4.028412\",\"price\":2482.37,\"price_str\":\"2482.37\",\"is_liquidation\":false},\"channel\":\"live_orders_ethusd\",\"event\":\"order_deleted\",\"event_id\":\"00065a1d-7f9b-69f8-0002-001203000020\",\"pre_event_id\":\"00065a1d-7f9b-69f8-0001-001202000020\",\"order_source\":\"orderbook\"}","recorded_unix_us":1787932601874516}
{"message":"{\"data\":{\"id\":2044303879704580,\"id_str\":\"2044303879704580\",\"order_type\":1,\"order_subtype\":5,\"datetime\":\"1787932602\",\"microtimestamp\":\"1787932601708000\",\"amount\":20.077182,\"amount_str\":\"20.077182\",\"amount_traded\":\"0\",\"amount_at_create\":\"20.077182\",\"price\":2490.39,\"price_str\":\"2490.39\",\"is_liquidation\":false},\"channel\":\"live_orders_ethusd\",\"event\":\"order_deleted\",\"event_id\":\"00065a1d-7f9b-6de0-0000-001200000020\",\"pre_event_id\":\"00065a1d-7f9b-69f8-0002-001203000020\",\"order_source\":\"orderbook\"}","recorded_unix_us":1787932601874642}
{"message":"{\"data\":{\"id\":2044303879704581,\"id_str\":\"2044303879704581\",\"order_type\":1,\"order_subtype\":5,\"datetime\":\"1787932602\",\"microtimestamp\":\"1787932601708000\",\"amount\":10.062547,\"amount_str\":\"10.062547\",\"amount_traded\":\"0\",\"amount_at_create\":\"10.062547\",\"price\":2484.47,\"price_str\":\"2484.47\",\"is_liquidation\":false},\"channel\":\"live_orders_ethusd\",\"event\":\"order_deleted\",\"event_id\":\"00065a1d-7f9b-6de0-0001-001201000020\",\"pre_event_id\":\"00065a1d-7f9b-6de0-0000-001200000020\",\"order_source\":\"orderbook\"}","recorded_unix_us":1787932601874670}
{"message":"{\"data\":{\"id\":2044303879708681,\"id_str\":\"2044303879708681\",\"order_type\":1,\"order_subtype\":5,\"datetime\":\"1787932602\",\"microtimestamp\":\"1787932601708000\",\"amount\":40.051178,\"amount_str\":\"40.051178\",\"amount_traded\":\"0\",\"amount_at_create\":\"40.051178\",\"price\":2496.81,\"price_str\":\"2496.81\",\"is_liquidation\":false},\"channel\":\"live_orders_ethusd\",\"event\":\"order_deleted\",\"event_id\":\"00065a1d-7f9b-6de0-0002-001202000020\",\"pre_event_id\":\"00065a1d-7f9b-6de0-0001-001201000020\",\"order_source\":\"orderbook\"}","recorded_unix_us":1787932601874765}
{"message":"{\"data\":{\"id\":2044303879774213,\"id_str\":\"2044303879774213\",\"order_type\":1,\"order_subtype\":5,\"datetime\":\"1787932602\",\"microtimestamp\":\"1787932601709000\",\"amount\":4.028003,\"amount_str\":\"4.028003\",\"amount_traded\":\"0\",\"amount_at_create\":\"4.028003\",\"price\":2482.62,\"price_str\":\"2482.62\",\"is_liquidation\":false},\"channel\":\"live_orders_ethusd\",\"event\":\"order_deleted\",\"event_id\":\"00065a1d-7f9b-71c8-0000-001203000020\",\"pre_event_id\":\"00065a1d-7f9b-6de0-0002-001202000020\",\"order_source\":\"orderbook\"}","recorded_unix_us":1787932601874788}
{"message":"{\"data\":{\"id\":2044303880404997,\"id_str\":\"2044303880404997\",\"order_type\":0,\"order_subtype\":4,\"datetime\":\"1787932602\",\"microtimestamp\":\"1787932601709000\",\"amount\":0.00006631,\"amount_str\":\"0.00006631\",\"amount_traded\":\"0\",\"amount_at_create\":\"0.00006631\",\"price\":76166.96,\"price_str\":\"76166.96\",\"is_liquidation\":false},\"channel\":\"live_orders_btcusd\",\"event\":\"order_created\",\"event_id\":\"00065a1d-7f9b-71c8-0000-000102000020\",\"pre_event_id\":\"00065a1d-7f9b-4ab8-0000-000101000020\",\"order_source\":\"orderbook\"}","recorded_unix_us":1787932601874907}
{"message":"{\"data\":{\"id\":2044303880404997,\"id_str\":\"2044303880404997\",\"order_type\":0,\"order_subtype\":4,\"datetime\":\"1787932602\",\"microtimestamp\":\"1787932601709000\",\"amount\":0.00006631,\"amount_str\":\"0.00006631\",\"amount_traded\":\"0\",\"amount_at_create\":\"0.00006631\",\"price\":76166.96,\"price_str\":\"76166.96\",\"is_liquidation\":false},\"channel\":\"live_orders_btcusd\",\"event\":\"order_deleted\",\"event_id\":\"00065a1d-7f9b-71c8-0001-000103000020\",\"pre_event_id\":\"00065a1d-7f9b-71c8-0000-000102000020\",\"order_source\":\"orderbook\"}","recorded_unix_us":1787932601874969}
{"message":"{\"data\":{\"id\":2044303879778310,\"id_str\":\"2044303879778310\",\"order_type\":1,\"order_subtype\":5,\"datetime\":\"1787932602\",\"microtimestamp\":\"1787932601709000\",\"amount\":10.059779,\"amount_str\":\"10.059779\",\"amount_traded\":\"0\",\"amount_at_create\":\"10.059779\",\"price\":2485.15,\"price_str\":\"2485.15\",\"is_liquidation\":false},\"channel\":\"live_orders_ethusd\",\"event\":\"order_deleted\",\"event_id\":\"00065a1d-7f9b-71c8-0001-001200000020\",\"pre_event_id\":\"00065a1d-7f9b-71c8-0000-001203000020\",\"order_source\":\"orderbook\"}","recorded_unix_us":1787932601874992}
{"message":"{\"data\":{\"id\":2044303879782401,\"id_str\":\"2044303879782401\",\"order_type\":1,\"order_subtype\":5,\"datetime\":\"1787932602\",\"microtimestamp\":\"1787932601709000\",\"amount\":20.063885,\"amount_str\":\"20.063885\",\"amount_traded\":\"0\",\"amount_at_create\":\"20.063885\",\"price\":2492.04,\"price_str\":\"2492.04\",\"is_liquidation\":false},\"channel\":\"live_orders_ethusd\",\"event\":\"order_deleted\",\"event_id\":\"00065a1d-7f9b-71c8-0002-001201000020\",\"pre_event_id\":\"00065a1d-7f9b-71c8-0001-001200000020\",\"order_source\":\"orderbook\"}","recorded_unix_us":1787932601875086}
{"message":"{\"data\":{\"id\":2044303879786499,\"id_str\":\"2044303879786499\",\"order_type\":1,\"order_subtype\":5,\"datetime\":\"1787932602\",\"microtimestamp\":\"1787932601710000\",\"amount\":40.010118,\"amount_str\":\"40.010118\",\"amount_traded\":\"0\",\"amount_at_create\":\"40.010118\",\"price\":2499.37,\"price_str\":\"2499.37\",\"is_liquidation\":false},\"channel\":\"live_orders_ethusd\",\"event\":\"order_deleted\",\"event_id\":\"00065a1d-7f9b-75b0-0000-001202000020\",\"pre_event_id\":\"00065a1d-7f9b-71c8-0002-001201000020\",\"order_source\":\"orderbook\"}","recorded_unix_us":1787932601875110}
{"message":"{\"data\":{\"id\":2044303879847937,\"id_str\":\"2044303879847937\",\"order_type\":1,\"order_subtype\":5,\"datetime\":\"1787932602\",\"microtimestamp\":\"1787932601710000\",\"amount\":4.027586,\"amount_str\":\"4.027586\",\"amount_traded\":\"0\",\"amount_at_create\":\"4.027586\",\"price\":2482.88,\"price_str\":\"2482.88\",\"is_liquidation\":false},\"channel\":\"live_orders_ethusd\",\"event\":\"order_deleted\",\"event_id\":\"00065a1d-7f9b-75b0-0001-001203000020\",\"pre_event_id\":\"00065a1d-7f9b-75b0-0000-001202000020\",\"order_source\":\"orderbook\"}","recorded_unix_us":1787932601875225}
{"message":"{\"data\":{\"id\":2044303880413187,\"id_str\":\"2044303880413187\",\"order_type\":0,\"order_subtype\":5,\"datetime\":\"1787932602\",\"microtimestamp\":\"1787932601711000\",\"amount\":0.1910383,\"amount_str\":\"0.19103830\",\"amount_traded\":\"0\",\"amount_at_create\":\"0.19103830\",\"price\":78482.99,\"price_str\":\"78482.99\",\"is_liquidation\":false},\"channel\":\"live_orders_btcusd\",\"event\":\"order_created\",\"event_id\":\"00065a1d-7f9b-7998-0000-000100000020\",\"pre_event_id\":\"00065a1d-7f9b-71c8-0001-000103000020\",\"order_source\":\"orderbook\"}","recorded_unix_us":1787932601875247}
{"message":"{\"data\":{\"id\":2044303880417287,\"id_str\":\"2044303880417287\",\"order_type\":1,\"order_subtype\":5,\"datetime\":\"1787932602\",\"microtimestamp\":\"1787932601712000\",\"amount\":0.06310787,\"amount_str\":\"0.06310787\",\"amount_traded\":\"0\",\"amount_at_create\":\"0.06310787\",\"price\":78520.2,\"price_str\":\"78520.20\",\"is_liquidation\":false},\"channel\":\"live_orders_btcusd\",\"event\":\"order_created\",\"event_id\":\"00065a1d-7f9b-7d80-0000-000101000020\",\"pre_event_id\":\"00065a1d-7f9b-7998-0000-000100000020\",\"order_source\":\"orderbook\"}","recorded_unix_us":1787932601875342}
{"message":"{\"data\":{\"id\":2044303880417287,\"id_str\":\"2044303880417287\",\"order_type\":1,\"order_subtype\":5,\"datetime\":\"1787932602\",\"microtimestamp\":\"1787932601712000\",\"amount\":0.06310787,\"amount_str\":\"0.06310787\",\"amount_traded\":\"0\",\"amount_at_create\":\"0.06310787\",\"price\":78520.2,\"price_str\":\"78520.20\",\"is_liquidation\":false},\"channel\":\"live_orders_btcusd\",\"event\":\"order_deleted\",\"event_id\":\"00065a1d-7f9b-7d80-0001-000102000020\",\"pre_event_id\":\"00065a1d-7f9b-7d80-0000-000101000020\",\"order_source\":\"orderbook\"}","recorded_unix_us":1787932601875369}
{"message":"{\"data\":{\"id\":2044303880417290,\"id_str\":\"2044303880417290\",\"order_type\":1,\"order_subtype\":5,\"datetime\":\"1787932602\",\"microtimestamp\":\"1787932601713000\",\"amount\":0.06310787,\"amount_str\":\"0.06310787\",\"amount_traded\":\"0\",\"amount_at_create\":\"0.06310787\",\"price\":78522.56,\"price_str\":\"78522.56\",\"is_liquidation\":false},\"channel\":\"live_orders_btcusd\",\"event\":\"order_created\",\"event_id\":\"00065a1d-7f9b-8168-0000-000103000020\",\"pre_event_id\":\"00065a1d-7f9b-7d80-0001-000102000020\",\"order_source\":\"orderbook\"}","recorded_unix_us":1787932601875443}
{"message":"{\"data\":{\"id\":2044303880417290,\"id_str\":\"2044303880417290\",\"order_type\":1,\"order_subtype\":5,\"datetime\":\"1787932602\",\"microtimestamp\":\"1787932601713000\",\"amount\":0.06310787,\"amount_str\":\"0.06310787\",\"amount_traded\":\"0\",\"amount_at_create\":\"0.06310787\",\"price\":78522.56,\"price_str\":\"78522.56\",\"is_liquidation\":false},\"channel\":\"live_orders_btcusd\",\"event\":\"order_deleted\",\"event_id\":\"00065a1d-7f9b-8168-0001-000100000020\",\"pre_event_id\":\"00065a1d-7f9b-8168-0000-000103000020\",\"order_source\":\"orderbook\"}","recorded_unix_us":1787932601875559}
{"message":"{\"data\":{\"id\":2044303880556544,\"id_str\":\"2044303880556544\",\"order_type\":0,\"order_subtype\":5,\"datetime\":\"1787932602\",\"microtimestamp\":\"1787932601746000\",\"amount\":0.00140266,\"amount_str\":\"0.00140266\",\"amount_traded\":\"0\",\"amount_at_create\":\"0.00140266\",\"price\":70667.51,\"price_str\":\"70667.51\",\"is_liquidation\":false},\"channel\":\"live_orders_btcusd\",\"event\":\"order_created\",\"event_id\":\"00065a1d-7f9c-0250-0000-000101000020\",\"pre_event_id\":\"00065a1d-7f9b-8168-0001-000100000020\",\"order_source\":\"orderbook\"}","recorded_unix_us":1787932601875582}
{"message":"{\"data\":{\"id\":2044303880560653,\"id_str\":\"2044303880560653\",\"order_type\":1,\"order_subtype\":5,\"datetime\":\"1787932602\",\"microtimestamp\":\"1787932601747000\",\"amount\":0.1,\"amount_str\":\"0.10000000\",\"amount_traded\":\"0\",\"amount_at_create\":\"0.10000000\",\"price\":78522.62,\"price_str\":\"78522.62\",\"is_liquidation\":false},\"channel\":\"live_orders_btcusd\",\"event\":\"order_created\",\"event_id\":\"00065a1d-7f9c-0638-0000-000102000020\",\"pre_event_id\":\"00065a1d-7f9c-0250-0000-000101000020\",\"order_source\":\"orderbook\"}","recorded_unix_us":1787932601875685}
{"message":"{\"data\":{\"id\":2044303880560653,\"id_str\":\"2044303880560653\",\"order_type\":1,\"order_subtype\":5,\"datetime\":\"1787932602\",\"microtimestamp\":\"1787932601747000\",\"amount\":0.1,\"amount_str\":\"0.10000000\",\"amount_traded\":\"0\",\"amount_at_create\":\"0.10000000\",\"price\":78522.62,\"price_str\":\"78522.62\",\"is_liquidation\":false},\"channel\":\"live_orders_btcusd\",\"event\":\"order_deleted\",\"event_id\":\"00065a1d-7f9c-0638-0001-000103000020\",\"pre_event_id\":\"00065a1d-7f9c-0638-0000-000102000020\",\"order_source\":\"orderbook\"}","recorded_unix_us":1787932601875717}
{"message":"{\"data\":{\"id\":2044303878811654,\"id_str\":\"2044303878811654\",\"order_type\":1,\"order_subtype\":5,\"datetime\":\"1787932602\",\"microtimestamp\":\"1787932601751000\",\"amount\":2.01528391,\"amount_str\":\"2.01528391\",\"amount_traded\":\"0\",\"amount_at_create\":\"2.01528391\",\"price\":0.03160301,\"price_str\":\"0.03160301\",\"is_liquidation\":false},\"channel\":\"live_orders_ethbtc\",\"event\":\"order_deleted\",\"event_id\":\"00065a1d-7f9c-15d8-0000-001102000020\",\"pre_event_id\":\"00065a1d-7f9a-cdb8-0000-001101000020\",\"order_source\":\"orderbook\"}","recorded_unix_us":1787932601875800}
{"message":"{\"data\":{\"id\":2044303874117635,\"id_str\":\"2044303874117635\",\"order_type\":1,\"order_subtype\":5,\"datetime\":\"1787932602\",\"microtimestamp\":\"1787932601751000\",\"amount\":2.014812,\"amount_str\":\"2.014812\",\"amount_traded\":\"0\",\"amount_at_create\":\"2.014812\",\"price\":2481.66,\"price_str\":\"2481.66\",\"is_liquidation\":false},\"channel\":\"live_orders_ethusd\",\"event\":\"order_deleted\",\"event_id\":\"00065a1d-7f9c-15d8-0000-001200000020\",\"pre_event_id\":\"00065a1d-7f9b-75b0-0001-001203000020\",\"order_source\":\"orderbook\"}","recorded_unix_us":1787932601875964}
{"message":"{\"data\":{\"id\":2044303880589315,\"id_str\":\"2044303880589315\",\"order_type\":1,\"order_subtype\":5,\"datetime\":\"1787932602\",\"microtimestamp\":\"1787932601754000\",\"amount\":0.1,\"amount_str\":\"0.10000000\",\"amount_traded\":\"0\",\"amount_at_create\":\"0.10000000\",\"price\":78522.63,\"price_str\":\"78522.63\",\"is_liquidation\":false},\"channel\":\"live_orders_btcusd\",\"event\":\"order_created\",\"event_id\":\"00065a1d-7f9c-2190-0000-000100000020\",\"pre_event_id\":\"00065a1d-7f9c-0638-0001-000103000020\",\"order_source\":\"orderbook\"}","recorded_unix_us":1787932601875987}
{"message":"{\"data\":{\"id\":2044303880589315,\"id_str\":\"2044303880589315\",\"order_type\":1,\"order_subtype\":5,\"datetime\":\"1787932602\",\"microtimestamp\":\"1787932601754000\",\"amount\":0.1,\"amount_str\":\"0.10000000\",\"amount_traded\":\"0\",\"amount_at_create\":\"0.10000000\",\"price\":78522.63,\"price_str\":\"78522.63\",\"is_liquidation\":false},\"channel\":\"live_orders_btcusd\",\"event\":\"order_deleted\",\"event_id\":\"00065a1d-7f9c-2190-0001-000101000020\",\"pre_event_id\":\"00065a1d-7f9c-2190-0000-000100000020\",\"order_source\":\"orderbook\"}","recorded_unix_us":1787932601876090}
{"message":"{\"data\":{\"id\":2044303880593408,\"id_str\":\"2044303880593408\",\"order_type\":1,\"order_subtype\":0,\"datetime\":\"1787932602\",\"microtimestamp\":\"1787932601755000\",\"amount\":0.01273518,\"amount_str\":\"0.01273518\",\"amount_traded\":\"0\",\"amount_at_create\":\"0.01273518\",\"price\":80486,\"price_str\":\"80486.00\",\"is_liquidation\":false},\"channel\":\"live_orders_btcusd\",\"event\":\"order_created\",\"event_id\":\"00065a1d-7f9c-2578-0000-000102000020\",\"pre_event_id\":\"00065a1d-7f9c-2190-0001-000101000020\",\"order_source\":\"orderbook\"}","recorded_unix_us":1787932601876113}
{"message":"{\"data\":{\"id\":2044303879917571,\"id_str\":\"2044303879917571\",\"order_type\":0,\"order_subtype\":5,\"datetime\":\"1787932602\",\"microtimestamp\":\"1787932601758000\",\"amount\":0.00140266,\"amount_str\":\"0.00140266\",\"amount_traded\":\"0\",\"amount_at_create\":\"0.00140266\",\"price\":70667.51,\"price_str\":\"70667.51\",\"is_liquidation\":false},\"channel\":\"live_orders_btcusd\",\"event\":\"order_deleted\",\"event_id\":\"00065a1d-7f9c-3130-0000-000103000020\",\"pre_event_id\":\"00065a1d-7f9c-2578-0000-000102000020\",\"order_source\":\"orderbook\"}","recorded_unix_us":1787932601876225}
{"message":"{\"data\":{\"id\":2044303864287236,\"id_str\":\"2044303864287236\",\"order_type\":0,\"order_subtype\":5,\"datetime\":\"1787932602\",\"microtimestamp\":\"1787932601762000\",\"amount\":11.694045,\"amount_str\":\"11.694045\",\"amount_traded\":\"0\",\"amount_at_create\":\"11.694045\",\"price\":2475.9,\"price_str\":\"2475.90\",\"is_liquidation\":false},\"channel\":\"live_orders_ethusd\",\"event\":\"order_deleted\",\"event_id\":\"00065a1d-7f9c-40d0-0000-001201000020\",\"pre_event_id\":\"00065a1d-7f9c-15d8-0000-001200000020\",\"order_source\":\"orderbook\"}","recorded_unix_us":1787932601876289}
{"message":"{\"data\":{\"id\":2044303880617994,\"id_str\":\"2044303880617994\",\"order_type\":0,\"order_subtype\":5,\"datetime\":\"1787932602\",\"microtimestamp\":\"1787932601762000\",\"amount\":11.691606,\"amount_str\":\"11.691606\",\"amount_traded\":\"0\",\"amount_at_create\":\"11.691606\",\"price\":2475.9,\"price_str\":\"2475.90\",\"is_liquidation\":false},\"channel\":\"live_orders_ethusd\",\"event\":\"order_created\",\"event_id\":\"00065a1d-7f9c-40d0-0001-001202000020\",\"pre_event_id\":\"00065a1d-7f9c-40d0-0000-001201000020\",\"order_source\":\"orderbook\"}","recorded_unix_us":1787932601876313}
{"message":"{\"data\":{\"id\":2044303876444170,\"id_str\":\"2044303876444170\",\"order_type\":0,\"order_subtype\":5,\"datetime\":\"1787932602\",\"microtimestamp\":\"1787932601763000\",\"amount\":0.042033,\"amount_str\":\"0.042033\",\"amount_traded\":\"0\",\"amount_at_create\":\"0.042033\",\"price\":2480.57,\"price_str\":\"2480.57\",\"is_liquidation\":false},\"channel\":\"live_orders_ethusd\",\"event\":\"order_deleted\",\"event_id\":\"00065a1d-7f9c-44b8-0000-001203000020\",\"pre_event_id\":\"00065a1d-7f9c-40d0-0001-001202000020\",\"order_source\":\"orderbook\"}","recorded_unix_us":1787932601876407}
{"message":"{\"data\":{\"id\":2044303880622094,\"id_str\":\"2044303880622094\",\"order_type\":0,\"order_subtype\":5,\"datetime\":\"1787932602\",\"microtimestamp\":\"1787932601763000\",\"amount\":4.034022,\"amount_str\":\"4.034022\",\"amount_traded\":\"0\",\"amount_at_create\":\"4.034022\",\"price\":2478.91,\"price_str\":\"2478.91\",\"is_liquidation\":false},\"channel\":\"live_orders_ethusd\",\"event\":\"order_created\",\"event_id\":\"00065a1d-7f9c-44b8-0001-001200000020\",\"pre_event_id\":\"00065a1d-7f9c-44b8-0000-001203000020\",\"order_source\":\"orderbook\"}","recorded_unix_us":1787932601876431}
{"message":"{\"data\":{\"id\":2044303880630275,\"id_str\":\"2044303880630275\",\"order_type\":1,\"order_subtype\":5,\"datetime\":\"1787932602\",\"microtimestamp\":\"1787932601764000\",\"amount\":0.06310787,\"amount_str\":\"0.06310787\",\"amount_traded\":\"0\",\"amount_at_create\":\"0.06310787\",\"price\":78520.16,\"price_str\":\"78520.16\",\"is_liquidation\":false},\"channel\":\"live_orders_btcusd\",\"event\":\"order_created\",\"event_id\":\"00065a1d-7f9c-48a0-0000-000100000020\",\"pre_event_id\":\"00065a1d-7f9c-3130-0000-000103000020\",\"order_source\":\"orderbook\"}","recorded_unix_us":1787932601876543}
{"message":"{\"data\":{\"id\":2044303880630275,\"id_str\":\"2044303880630275\",\"order_type\":1,\"order_subtype\":5,\"datetime\":\"1787932602\",\"microtimestamp\":\"1787932601764000\",\"amount\":0.06310787,\"amount_str\":\"0.06310787\",\"amount_traded\":\"0\",\"amount_at_create\":\"0.06310787\",\"price\":78520.16,\"price_str\":\"78520.16\",\"is_liquidation\":false},\"channel\":\"live_orders_btcusd\",\"event\":\"order_deleted\",\"event_id\":\"00065a1d-7f9c-48a0-0001-000101000020\",\"pre_event_id\":\"00065a1d-7f9c-48a0-0000-000100000020\",\"order_source\":\"orderbook\"}","recorded_unix_us":1787932601876565}
{"message":"{\"data\":{\"id\":2044303880634375,\"id_str\":\"2044303880634375\",\"order_type\":0,\"order_subtype\":5,\"datetime\":\"1787932602\",\"microtimestamp\":\"1787932601766000\",\"amount\":5,\"amount_str\":\"5.000000\",\"amount_traded\":\"0\",\"amount_at_create\":\"5.000000\",\"price\":2480.77,\"price_str\":\"2480.77\",\"is_liquidation\":false},\"channel\":\"live_orders_ethusd\",\"event\":\"order_created\",\"event_id\":\"00065a1d-7f9c-5070-0000-001201000020\",\"pre_event_id\":\"00065a1d-7f9c-44b8-0001-001200000020\",\"order_source\":\"orderbook\"}","recorded_unix_us":1787932601876648}
{"message":"{\"data\":{\"id\":2044303880634380,\"id_str\":\"2044303880634380\",\"order_type\":1,\"order_subtype\":5,\"datetime\":\"1787932602\",\"microtimestamp\":\"1787932601766000\",\"amount\":0.06310787,\"amount_str\":\"0.06310787\",\"amount_traded\":\"0\",\"amount_at_create\":\"0.06310787\",\"price\":78522.52,\"price_str\":\"78522.52\",\"is_liquidation\":false},\"channel\":\"live_orders_btcusd\",\"event\":\"order_created\",\"event_id\":\"00065a1d-7f9c-5070-0000-000102000020\",\"pre_event_id\":\"00065a1d-7f9c-48a0-0001-000101000020\",\"order_source\":\"orderbook\"}","recorded_unix_us":1787932601876732}
{"message":"{\"data\":{\"id\":2044303880634380,\"id_str\":\"2044303880634380\",\"order_type\":1,\"order_subtype\":5,\"datetime\":\"1787932602\",\"microtimestamp\":\"1787932601766000\",\"amount\":0.06310787,\"amount_str\":\"0.06310787\",\"amount_traded\":\"0\",\"amount_at_create\":\"0.06310787\",\"price\":78522.52,\"price_str\":\"78522.52\",\"is_liquidation\":false},\"channel\":\"live_orders_btcusd\",\"event\":\"order_deleted\",\"event_id\":\"00065a1d-7f9c-5070-0001-000103000020\",\"pre_event_id\":\"00065a1d-7f9c-5070-0000-000102000020\",\"order_source\":\"orderbook\"}","recorded_unix_us":1787932601876756}
