{"message":"{\"data\":{\"id\":2044303880753154,\"id_str\":\"2044303880753154\",\"order_type\":0,\"order_subtype\":5,\"datetime\":\"1787932602\",\"microtimestamp\":\"1787932602194000\",\"amount\":10.095101,\"amount_str\":\"10.095101\",\"amount_traded\":\"0\",\"amount_at_create\":\"10.095101\",\"price\":2476.44,\"price_str\":\"2476.44\",\"is_liquidation\":false},\"channel\":\"live_orders_ethusd\",\"event\":\"order_deleted\",\"event_id\":\"00065a1d-7fa2-d850-0001-001202000020\",\"pre_event_id\":\"00065a1d-7fa2-d850-0000-001201000020\",\"order_source\":\"orderbook\"}","recorded_unix_us":1787932602237741}
{"message":"{\"data\":{\"id\":2044303880753156,\"id_str\":\"2044303880753156\",\"order_type\":0,\"order_subtype\":5,\"datetime\":\"1787932602\",\"microtimestamp\":\"1787932602194000\",\"amount\":4.033204,\"amount_str\":\"4.033204\",\"amount_traded\":\"0\",\"amount_at_create\":\"4.033204\",\"price\":2479.41,\"price_str\":\"2479.41\",\"is_liquidation\":false},\"channel\":\"live_orders_ethusd\",\"event\":\"order_deleted\",\"event_id\":\"00065a1d-7fa2-d850-0002-001203000020\",\"pre_event_id\":\"00065a1d-7fa2-d850-0001-001202000020\",\"order_source\":\"orderbook\"}","recorded_unix_us":1787932602238067}
{"message":"{\"data\":{\"id\":2044303880753159,\"id_str\":\"2044303880753159\",\"order_type\":0,\"order_subtype\":5,\"datetime\":\"1787932602\",\"microtimestamp\":\"1787932602195000\",\"amount\":20.204386,\"amount_str\":\"20.204386\",\"amount_traded\":\"0\",\"amount_at_create\":\"20.204386\",\"price\":2474.71,\"price_str\":\"2474.71\",\"is_liquidation\":false},\"channel\":\"live_orders_ethusd\",\"event\":\"order_deleted\",\"event_id\":\"00065a1d-7fa2-dc38-0000-001200000020\",\"pre_event_id\":\"00065a1d-7fa2-d850-0002-001203000020\",\"order_source\":\"orderbook\"}","recorded_unix_us":1787932602238104}
{"message":"{\"data\":{\"id\":2044303880753160,\"id_str\":\"2044303880753160\",\"order_type\":0,\"order_subtype\":5,\"datetime\":\"1787932602\",\"microtimestamp\":\"1787932602195000\",\"amount\":10.090138,\"amount_str\":\"10.090138\",\"amount_traded\":\"0\",\"amount_at_create\":\"10.090138\",\"price\":2477.66,\"price_str\":\"2477.66\",\"is_liquidation\":false},\"channel\":\"live_orders_ethusd\",\"event\":\"order_deleted\",\"event_id\":\"00065a1d-7fa2-dc38-0001-001201000020\",\"pre_event_id\":\"00065a1d-7fa2-dc38-0000-001200000020\",\"order_source\":\"orderbook\"}","recorded_unix_us":1787932602238165}
{"message":"{\"data\":{\"id\":2044303880757250,\"id_str\":\"2044303880757250\",\"order_type\":0,\"order_subtype\":5,\"datetime\":\"1787932602\",\"microtimestamp\":\"1787932602195000\",\"amount\":4.033601,\"amount_str\":\"4.033601\",\"amount_traded\":\"0\",\"amount_at_create\":\"4.033601\",\"price\":2479.17,\"price_str\":\"2479.17\",\"is_liquidation\":false},\"channel\":\"live_orders_ethusd\",\"event\":\"order_deleted\",\"event_id\":\"00065a1d-7fa2-dc38-0002-001202000020\",\"pre_event_id\":\"00065a1d-7fa2-dc38-0001-001201000020\",\"order_source\":\"orderbook\"}","recorded_unix_us":1787932602238196}
{"message":"{\"data\":{\"id\":2044303880814602,\"id_str\":\"2044303880814602\",\"order_type\":0,\"order_subtype\":5,\"datetime\":\"1787932602\",\"microtimestamp\":\"1787932602196000\",\"amount\":40.528033,\"amount_str\":\"40.528033\",\"amount_traded\":\"0\",\"amount_at_create\":\"40.528033\",\"price\":2467.42,\"price_str\":\"2467.42\",\"is_liquidation\":false},\"channel\":\"live_orders_ethusd\",\"event\":\"order_deleted\",\"event_id\":\"00065a1d-7fa2-e020-0000-001203000020\",\"pre_event_id\":\"00065a1d-7fa2-dc38-0002-001202000020\",\"order_source\":\"orderbook\"}","recorded_unix_us":1787932602238547}
{"message":"{\"data\":{\"id\":2044303880880134,\"id_str\":\"2044303880880134\",\"order_type\":0,\"order_subtype\":5,\"datetime\":\"1787932602\",\"microtimestamp\":\"1787932602196000\",\"amount\":40.650432,\"amount_str\":\"40.650432\",\"amount_traded\":\"0\",\"amount_at_create\":\"40.650432\",\"price\":2459.99,\"price_str\":\"2459.99\",\"is_liquidation\":false},\"channel\":\"live_orders_ethusd\",\"event\":\"order_deleted\",\"event_id\":\"00065a1d-7fa2-e020-0001-001200000020\",\"pre_event_id\":\"00065a1d-7fa2-e020-0000-001203000020\",\"order_source\":\"orderbook\"}","recorded_unix_us":1787932602238591}
{"message":"{\"data\":{\"id\":2044303881084943,\"id_str\":\"2044303881084943\",\"order_type\":1,\"order_subtype\":5,\"datetime\":\"1787932602\",\"microtimestamp\":\"1787932602196000\",\"amount\":4.028412,\"amount_str\":\"4.028412\",\"amount_traded\":\"0\",\"amount_at_create\":\"4.028412\",\"price\":2482.37,\"price_str\":\"2482.37\",\"is_liquidation\":false},\"channel\":\"live_orders_ethusd\",\"event\":\"order_deleted\",\"event_id\":\"00065a1d-7fa2-e020-0002-001201000020\",\"pre_event_id\":\"00065a1d-7fa2-e020-0001-001200000020\",\"order_source\":\"orderbook\"}","recorded_unix_us":1787932602238621}
{"message":"{\"data\":{\"id\":2044303881089031,\"id_str\":\"2044303881089031\",\"order_type\":1,\"order_subtype\":5,\"datetime\":\"1787932602\",\"microtimestamp\":\"1787932602197000\",\"amount\":4.027018,\"amount_str\":\"4.027018\",\"amount_traded\":\"0\",\"amount_at_create\":\"4.027018\",\"price\":2483.23,\"price_str\":\"2483.23\",\"is_liquidation\":false},\"channel\":\"live_orders_ethusd\",\"event\":\"order_deleted\",\"event_id\":\"00065a1d-7fa2-e408-0000-001202000020\",\"pre_event_id\":\"00065a1d-7fa2-e020-0002-001201000020\",\"order_source\":\"orderbook\"}","recorded_unix_us":1787932602238649}
{"message":"{\"data\":{\"id\":2044303881105415,\"id_str\":\"2044303881105415\",\"order_type\":1,\"order_subtype\":5,\"datetime\":\"1787932602\",\"microtimestamp\":\"1787932602197000\",\"amount\":20.077182,\"amount_str\":\"20.077182\",\"amount_traded\":\"0\",\"amount_at_create\":\"20.077182\",\"price\":2490.39,\"price_str\":\"2490.39\",\"is_liquidation\":false},\"channel\":\"live_orders_ethusd\",\"event\":\"order_deleted\",\"event_id\":\"00065a1d-7fa2-e408-0001-001203000020\",\"pre_event_id\":\"00065a1d-7fa2-e408-0000-001202000020\",\"order_source\":\"orderbook\"}","recorded_unix_us":1787932602238838}
{"message":"{\"data\":{\"id\":2044303881113600,\"id_str\":\"2044303881113600\",\"order_type\":1,\"order_subtype\":5,\"datetime\":\"1787932602\",\"microtimestamp\":\"1787932602197000\",\"amount\":10.062547,\"amount_str\":\"10.062547\",\"amount_traded\":\"0\",\"amount_at_create\":\"10.062547\",\"price\":2484.47,\"price_str\":\"2484.47\",\"is_liquidation\":false},\"channel\":\"live_orders_ethusd\",\"event\":\"order_deleted\",\"event_id\":\"00065a1d-7fa2-e408-0002-001200000020\",\"pre_event_id\":\"00065a1d-7fa2-e408-0001-001203000020\",\"order_source\":\"orderbook\"}","recorded_unix_us":1787932602238873}
{"message":"{\"data\":{\"id\":2044303881117701,\"id_str\":\"2044303881117701\",\"order_type\":1,\"order_subtype\":5,\"datetime\":\"1787932602\",\"microtimestamp\":\"1787932602198000\",\"amount\":40.051178,\"amount_str\":\"40.051178\",\"amount_traded\":\"0\",\"amount_at_create\":\"40.051178\",\"price\":2496.81,\"price_str\":\"2496.81\",\"is_liquidation\":false},\"channel\":\"live_orders_ethusd\",\"event\":\"order_deleted\",\"event_id\":\"00065a1d-7fa2-e7f0-0000-001201000020\",\"pre_event_id\":\"00065a1d-7fa2-e408-0002-001200000020\",\"order_source\":\"orderbook\"}","recorded_unix_us":1787932602238901}
{"message":"{\"data\":{\"id\":2044303881129985,\"id_str\":\"2044303881129985\",\"order_type\":0,\"order_subtype\":5,\"datetime\":\"1787932602\",\"microtimestamp\":\"1787932602198000\",\"amount\":20.215084,\"amount_str\":\"20.215084\",\"amount_traded\":\"0\",\"amount_at_create\":\"20.215084\",\"price\":2473.4,\"price_str\":\"2473.40\",\"is_liquidation\":false},\"channel\":\"live_orders_ethusd\",\"event\":\"order_deleted\",\"event_id\":\"00065a1d-7fa2-e7f0-0001-001202000020\",\"pre_event_id\":\"00065a1d-7fa2-e7f0-0000-001201000020\",\"order_source\":\"orderbook\"}","recorded_unix_us":1787932602238929}
{"message":"{\"data\":{\"id\":2044303881129986,\"id_str\":\"2044303881129986\",\"order_type\":0,\"order_subtype\":5,\"datetime\":\"1787932602\",\"microtimestamp\":\"1787932602198000\",\"amount\":10.092689,\"amount_str\":\"10.092689\",\"amount_traded\":\"0\",\"amount_at_create\":\"10.092689\",\"price\":2477.04,\"price_str\":\"2477.04\",\"is_liquidation\":false},\"channel\":\"live_orders_ethusd\",\"event\":\"order_deleted\",\"event_id\":\"00065a1d-7fa2-e7f0-0002-001203000020\",\"pre_event_id\":\"00065a1d-7fa2-e7f0-0001-001202000020\",\"order_source\":\"orderbook\"}","recorded_unix_us":1787932602239031}
{"message":"{\"data\":{\"id\":2044303881138178,\"id_str\":\"2044303881138178\",\"order_type\":0,\"order_subtype\":5,\"datetime\":\"1787932602\",\"microtimestamp\":\"1787932602199000\",\"amount\":40.568517,\"amount_str\":\"40.568517\",\"amount_traded\":\"0\",\"amount_at_create\":\"40.568517\",\"price\":2464.96,\"price_str\":\"2464.96\",\"is_liquidation\":false},\"channel\":\"live_orders_ethusd\",\"event\":\"order_deleted\",\"event_id\":\"00065a1d-7fa2-ebd8-0000-001200000020\",\"pre_event_id\":\"00065a1d-7fa2-e7f0-0002-001203000020\",\"order_source\":\"orderbook\"}","recorded_unix_us":1787932602239204}
{"message":"{\"data\":{\"id\":2044303881142283,\"id_str\":\"2044303881142283\",\"order_type\":0,\"order_subtype\":5,\"datetime\":\"1787932602\",\"microtimestamp\":\"1787932602199000\",\"amount\":10.097738,\"amount_str\":\"10.097738\",\"amount_traded\":\"0\",\"amount_at_create\":\"10.097738\",\"price\":2475.8,\"price_str\":\"2475.80\",\"is_liquidation\":false},\"channel\":\"live_orders_ethusd\",\"event\":\"order_deleted\",\"event_id\":\"00065a1d-7fa2-ebd8-0001-001201000020\",\"pre_event_id\":\"00065a1d-7fa2-ebd8-0000-001200000020\",\"order_source\":\"orderbook\"}","recorded_unix_us":1787932602239246}
{"message":"{\"data\":{\"id\":2044303881244674,\"id_str\":\"2044303881244674\",\"order_type\":1,\"order_subtype\":5,\"datetime\":\"1787932602\",\"microtimestamp\":\"1787932602200000\",\"amount\":4.028003,\"amount_str\":\"4.028003\",\"amount_traded\":\"0\",\"amount_at_create\":\"4.028003\",\"price\":2482.62,\"price_str\":\"2482.62\",\"is_liquidation\":false},\"channel\":\"live_orders_ethusd\",\"event\":\"order_deleted\",\"event_id\":\"00065a1d-7fa2-efc0-0000-001202000020\",\"pre_event_id\":\"00065a1d-7fa2-ebd8-0001-001201000020\",\"order_source\":\"orderbook\"}","recorded_unix_us":1787932602239522}
{"message":"{\"data\":{\"id\":2044303881244688,\"id_str\":\"2044303881244688\",\"order_type\":1,\"order_subtype\":5,\"datetime\":\"1787932602\",\"microtimestamp\":\"1787932602200000\",\"amount\":10.059779,\"amount_str\":\"10.059779\",\"amount_traded\":\"0\",\"amount_at_create\":\"10.059779\",\"price\":2485.15,\"price_str\":\"2485.15\",\"is_liquidation\":false},\"channel\":\"live_orders_ethusd\",\"event\":\"order_deleted\",\"event_id\":\"00065a1d-7fa2-efc0-0001-001203000020\",\"pre_event_id\":\"00065a1d-7fa2-efc0-0000-001202000020\",\"order_source\":\"orderbook\"}","recorded_unix_us":1787932602239569}
{"message":"{\"data\":{\"id\":2044303881297922,\"id_str\":\"2044303881297922\",\"order_type\":1,\"order_subtype\":5,\"datetime\":\"1787932602\",\"microtimestamp\":\"1787932602200000\",\"amount\":20.063885,\"amount_str\":\"20.063885\",\"amount_traded\":\"0\",\"amount_at_create\":\"20.063885\",\"price\":2492.04,\"price_str\":\"2492.04\",\"is_liquidation\":false},\"channel\":\"live_orders_ethusd\",\"event\":\"order_deleted\",\"event_id\":\"00065a1d-7fa2-efc0-0002-001200000020\",\"pre_event_id\":\"00065a1d-7fa2-efc0-0001-001203000020\",\"order_source\":\"orderbook\"}","recorded_unix_us":1787932602239712}
{"message":"{\"data\":{\"id\":2044303881306112,\"id_str\":\"2044303881306112\",\"order_type\":1,\"order_subtype\":5,\"datetime\":\"1787932602\",\"microtimestamp\":\"1787932602200000\",\"amount\":40.010118,\"amount_str\":\"40.010118\",\"amount_traded\":\"0\",\"amount_at_create\":\"40.010118\",\"price\":2499.37,\"price_str\":\"2499.37\",\"is_liquidation\":false},\"channel\":\"live_orders_ethusd\",\"event\":\"order_deleted\",\"event_id\":\"00065a1d-7fa2-efc0-0003-001201000020\",\"pre_event_id\":\"00065a1d-7fa2-efc0-0002-001200000020\",\"order_source\":\"orderbook\"}","recorded_unix_us":1787932602239749}
{"message":"{\"data\":{\"id\":2044303881347095,\"id_str\":\"2044303881347095\",\"order_type\":0,\"order_subtype\":5,\"datetime\":\"1787932602\",\"microtimestamp\":\"1787932602201000\",\"amount\":20.225289,\"amount_str\":\"20.225289\",\"amount_traded\":\"0\",\"amount_at_create\":\"20.225289\",\"price\":2472.15,\"price_str\":\"2472.15\",\"is_liquidation\":false},\"channel\":\"live_orders_ethusd\",\"event\":\"order_deleted\",\"event_id\":\"00065a1d-7fa2-f3a8-0000-001202000020\",\"pre_event_id\":\"00065a1d-7fa2-efc0-0003-001201000020\",\"order_source\":\"orderbook\"}","recorded_unix_us":1787932602239870}
{"message":"{\"data\":{\"id\":2044303881355264,\"id_str\":\"2044303881355264\",\"order_type\":0,\"order_subtype\":5,\"datetime\":\"1787932602\",\"microtimestamp\":\"1787932602201000\",\"amount\":40.609081,\"amount_str\":\"40.609081\",\"amount_traded\":\"0\",\"amount_at_create\":\"40.609081\",\"price\":2462.5,\"price_str\":\"2462.50\",\"is_liquidation\":false},\"channel\":\"live_orders_ethusd\",\"event\":\"order_deleted\",\"event_id\":\"00065a1d-7fa2-f3a8-0001-001203000020\",\"pre_event_id\":\"00065a1d-7fa2-f3a8-0000-001202000020\",\"order_source\":\"orderbook\"}","recorded_unix_us":1787932602240073}
{"message":"{\"data\":{\"id\":2044303881441288,\"id_str\":\"2044303881441288\",\"order_type\":1,\"order_subtype\":5,\"datetime\":\"1787932602\",\"microtimestamp\":\"1787932602202000\",\"amount\":4.027586,\"amount_str\":\"4.027586\",\"amount_traded\":\"0\",\"amount_at_create\":\"4.027586\",\"price\":2482.88,\"price_str\":\"2482.88\",\"is_liquidation\":false},\"channel\":\"live_orders_ethusd\",\"event\":\"order_deleted\",\"event_id\":\"00065a1d-7fa2-f790-0000-001200000020\",\"pre_event_id\":\"00065a1d-7fa2-f3a8-0001-001203000020\",\"order_source\":\"orderbook\"}","recorded_unix_us":1787932602240117}
{"message":"{\"data\":{\"id\":2044303881457666,\"id_str\":\"2044303881457666\",\"order_type\":0,\"order_subtype\":5,\"datetime\":\"1787932602\",\"microtimestamp\":\"1787932602202000\",\"amount\":20.235437,\"amount_str\":\"20.235437\",\"amount_traded\":\"0\",\"amount_at_create\":\"20.235437\",\"price\":2470.91,\"price_str\":\"2470.91\",\"is_liquidation\":false},\"channel\":\"live_orders_ethusd\",\"event\":\"order_deleted\",\"event_id\":\"00065a1d-7fa2-f790-0001-001201000020\",\"pre_event_id\":\"00065a1d-7fa2-f790-0000-001200000020\",\"order_source\":\"orderbook\"}","recorded_unix_us":1787932602240149}
{"message":"{\"data\":{\"id\":2044303882424331,\"id_str\":\"2044303882424331\",\"order_type\":1,\"order_subtype\":5,\"datetime\":\"1787932602\",\"microtimestamp\":\"1787932602202000\",\"amount\":0.06310787,\"amount_str\":\"0.06310787\",\"amount_traded\":\"0\",\"amount_at_create\":\"0.06310787\",\"price\":78521.1,\"price_str\":\"78521.10\",\"is_liquidation\":false},\"channel\":\"live_orders_btcusd\",\"event\":\"order_created\",\"event_id\":\"00065a1d-7fa2-f790-0000-000100000020\",\"pre_event_id\":\"00065a1d-7fa2-c4c8-0001-000103000020\",\"order_source\":\"orderbook\"}","recorded_unix_us":1787932602240247}
{"message":"{\"data\":{\"id\":2044303882424331,\"id_str\":\"2044303882424331\",\"order_type\":1,\"order_subtype\":5,\"datetime\":\"1787932602\",\"microtimestamp\":\"1787932602202000\",\"amount\":0.06310787,\"amount_str\":\"0.06310787\",\"amount_traded\":\"0\",\"amount_at_create\":\"0.06310787\",\"price\":78521.1,\"price_str\":\"78521.10\",\"is_liquidation\":false},\"channel\":\"live_orders_btcusd\",\"event\":\"order_deleted\",\"event_id\":\"00065a1d-7fa2-f790-0001-000101000020\",\"pre_event_id\":\"00065a1d-7fa2-f790-0000-000100000020\",\"order_source\":\"orderbook\"}","recorded_unix_us":1787932602240366}
{"message":"{\"data\":{\"id\":2044303882252297,\"id_str\":\"2044303882252297\",\"order_type\":0,\"order_subtype\":5,\"datetime\":\"1787932602\",\"microtimestamp\":\"1787932602213000\",\"amount\":0.403088,\"amount_str\":\"0.403088\",\"amount_traded\":\"0\",\"amount_at_create\":\"0.403088\",\"price\":2480.02,\"price_str\":\"2480.02\",\"is_liquidation\":false},\"channel\":\"live_orders_ethusd\",\"event\":\"order_deleted\",\"event_id\":\"00065a1d-7fa3-2288-0000-001202000020\",\"pre_event_id\":\"00065a1d-7fa2-f790-0001-001201000020\",\"order_source\":\"orderbook\"}","recorded_unix_us":1787932602249326}
{"message":"{\"data\":{\"id\":2044303882489873,\"id_str\":\"2044303882489873\",\"order_type\":1,\"order_subtype\":5,\"datetime\":\"1787932602\",\"microtimestamp\":\"1787932602219000\",\"amount\":0.1,\"amount_str\":\"0.10000000\",\"amount_traded\":\"0\",\"amount_at_create\":\"0.10000000\",\"price\":78522.62,\"price_str\":\"78522.62\",\"is_liquidation\":false},\"channel\":\"live_orders_btcusd\",\"event\":\"order_created\",\"event_id\":\"00065a1d-7fa3-39f8-0000-000102000020\",\"pre_event_id\":\"00065a1d-7fa2-f790-0001-000101000020\",\"order_source\":\"orderbook\"}","recorded_unix_us":1787932602249550}
{"message":"{\"data\":{\"id\":2044303882489873,\"id_str\":\"2044303882489873\",\"order_type\":1,\"order_subtype\":5,\"datetime\":\"1787932602\",\"microtimestamp\":\"1787932602219000\",\"amount\":0.1,\"amount_str\":\"0.10000000\",\"amount_traded\":\"0\",\"amount_at_create\":\"0.10000000\",\"price\":78522.62,\"price_str\":\"78522.62\",\"is_liquidation\":false},\"channel\":\"live_orders_btcusd\",\"event\":\"order_deleted\",\"event_id\":\"00065a1d-7fa3-39f8-0001-000103000020\",\"pre_event_id\":\"00065a1d-7fa3-39f8-0000-000102000020\",\"order_source\":\"orderbook\"}","recorded_unix_us":1787932602249600}
{"message":"{\"data\":{\"id\":2044303882510346,\"id_str\":\"2044303882510346\",\"order_type\":0,\"order_subtype\":5,\"datetime\":\"1787932602\",\"microtimestamp\":\"1787932602224000\",\"amount\":0.403085,\"amount_str\":\"0.403085\",\"amount_traded\":\"0\",\"amount_at_create\":\"0.403085\",\"price\":2480.1,\"price_str\":\"2480.10\",\"is_liquidation\":false},\"channel\":\"live_orders_ethusd\",\"event\":\"order_created\",\"event_id\":\"00065a1d-7fa3-4d80-0000-001203000020\",\"pre_event_id\":\"00065a1d-7fa3-2288-0000-001202000020\",\"order_source\":\"orderbook\"}","recorded_unix_us":1787932602265843}
{"message":"{\"data\":{\"id\":2044303882510346,\"id_str\":\"2044303882510346\",\"order_type\":0,\"order_subtype\":5,\"datetime\":\"1787932602\",\"microtimestamp\":\"1787932602227000\",\"amount\":0.403085,\"amount_str\":\"0.403085\",\"amount_traded\":\"0\",\"amount_at_create\":\"0.403085\",\"price\":2480.1,\"price_str\":\"2480.10\",\"is_liquidation\":false},\"channel\":\"live_orders_ethusd\",\"event\":\"order_deleted\",\"event_id\":\"00065a1d-7fa3-5938-0000-001200000020\",\"pre_event_id\":\"00065a1d-7fa3-4d80-0000-001203000020\",\"order_source\":\"orderbook\"}","recorded_unix_us":1787932602266118}
{"message":"{\"data\":{\"id\":2044303882530818,\"id_str\":\"2044303882530818\",\"order_type\":0,\"order_subtype\":5,\"datetime\":\"1787932602\",\"microtimestamp\":\"1787932602228000\",\"amount\":0.00140266,\"amount_str\":\"0.00140266\",\"amount_traded\":\"0\",\"amount_at_create\":\"0.00140266\",\"price\":70668.36,\"price_str\":\"70668.36\",\"is_liquidation\":false},\"channel\":\"live_orders_btcusd\",\"event\":\"order_created\",\"event_id\":\"00065a1d-7fa3-5d20-0000-000100000020\",\"pre_event_id\":\"00065a1d-7fa3-39f8-0001-000103000020\",\"order_source\":\"orderbook\"}","recorded_unix_us":1787932602266208}
{"message":"{\"data\":{\"id\":2044303882551300,\"id_str\":\"2044303882551300\",\"order_type\":1,\"order_subtype\":5,\"datetime\":\"1787932602\",\"microtimestamp\":\"1787932602233000\",\"amount\":0.275637,\"amount_str\":\"0.275637\",\"amount_traded\":\"0\",\"amount_at_create\":\"0.275637\",\"price\":2481.27,\"price_str\":\"2481.27\",\"is_liquidation\":false},\"channel\":\"live_orders_ethusd\",\"event\":\"order_created\",\"event_id\":\"00065a1d-7fa3-70a8-0000-001201000020\",\"pre_event_id\":\"00065a1d-7fa3-5938-0000-001200000020\",\"order_source\":\"orderbook\"}","recorded_unix_us":1787932602266498}
{"message":"{\"data\":{\"id\":2044303882551307,\"id_str\":\"2044303882551307\",\"order_type\":1,\"order_subtype\":5,\"datetime\":\"1787932602\",\"microtimestamp\":\"1787932602234000\",\"amount\":0.06310787,\"amount_str\":\"0.06310787\",\"amount_traded\":\"0\",\"amount_at_create\":\"0.06310787\",\"price\":78520.44,\"price_str\":\"78520.44\",\"is_liquidation\":false},\"channel\":\"live_orders_btcusd\",\"event\":\"order_created\",\"event_id\":\"00065a1d-7fa3-7490-0000-000101000020\",\"pre_event_id\":\"00065a1d-7fa3-5d20-0000-000100000020\",\"order_source\":\"orderbook\"}","recorded_unix_us":1787932602275298}
{"message":"{\"data\":{\"id\":2044303882551307,\"id_str\":\"2044303882551307\",\"order_type\":1,\"order_subtype\":5,\"datetime\":\"1787932602\",\"microtimestamp\":\"1787932602234000\",\"amount\":0.06310787,\"amount_str\":\"0.06310787\",\"amount_traded\":\"0\",\"amount_at_create\":\"0.06310787\",\"price\":78520.44,\"price_str\":\"78520.44\",\"is_liquidation\":false},\"channel\":\"live_orders_btcusd\",\"event\":\"order_deleted\",\"event_id\":\"00065a1d-7fa3-7490-0001-000102000020\",\"pre_event_id\":\"00065a1d-7fa3-7490-0000-000101000020\",\"order_source\":\"orderbook\"}","recorded_unix_us":1787932602275492}
{"message":"{\"data\":{\"id\":2044303882555395,\"id_str\":\"2044303882555395\",\"order_type\":1,\"order_subtype\":5,\"datetime\":\"1787932602\",\"microtimestamp\":\"1787932602234000\",\"amount\":0.1,\"amount_str\":\"0.10000000\",\"amount_traded\":\"0\",\"amount_at_create\":\"0.10000000\",\"price\":78522.63,\"price_str\":\"78522.63\",\"is_liquidation\":false},\"channel\":\"live_orders_btcusd\",\"event\":\"order_created\",\"event_id\":\"00065a1d-7fa3-7490-0002-000103000020\",\"pre_event_id\":\"00065a1d-7fa3-7490-0001-000102000020\",\"order_source\":\"orderbook\"}","recorded_unix_us":1787932602275654}
{"message":"{\"data\":{\"id\":2044303882555395,\"id_str\":\"2044303882555395\",\"order_type\":1,\"order_subtype\":5,\"datetime\":\"1787932602\",\"microtimestamp\":\"1787932602234000\",\"amount\":0.1,\"amount_str\":\"0.10000000\",\"amount_traded\":\"0\",\"amount_at_create\":\"0.10000000\",\"price\":78522.63,\"price_str\":\"78522.63\",\"is_liquidation\":false},\"channel\":\"live_orders_btcusd\",\"event\":\"order_deleted\",\"event_id\":\"00065a1d-7fa3-7490-0003-000100000020\",\"pre_event_id\":\"00065a1d-7fa3-7490-0002-000103000020\",\"order_source\":\"orderbook\"}","recorded_unix_us":1787932602278504}
{"message":"{\"data\":{\"id\":2044303882563594,\"id_str\":\"2044303882563594\",\"order_type\":0,\"order_subtype\":5,\"datetime\":\"1787932602\",\"microtimestamp\":\"1787932602237000\",\"amount\":0.403087,\"amount_str\":\"0.403087\",\"amount_traded\":\"0\",\"amount_at_create\":\"0.403087\",\"price\":2480.03,\"price_str\":\"2480.03\",\"is_liquidation\":false},\"channel\":\"live_orders_ethusd\",\"event\":\"order_created\",\"event_id\":\"00065a1d-7fa3-8048-0000-001202000020\",\"pre_event_id\":\"00065a1d-7fa3-70a8-0000-001201000020\",\"order_source\":\"orderbook\"}","recorded_unix_us":1787932602278567}
{"message":"{\"data\":{\"id\":2044303882584076,\"id_str\":\"2044303882584076\",\"order_type\":1,\"order_subtype\":4,\"datetime\":\"1787932602\",\"microtimestamp\":\"1787932602242000\",\"amount\":0.00006244,\"amount_str\":\"0.00006244\",\"amount_traded\":\"0\",\"amount_at_create\":\"0.00006244\",\"price\":80878,\"price_str\":\"80878.00\",\"is_liquidation\":false},\"channel\":\"live_orders_btcusd\",\"event\":\"order_created\",\"event_id\":\"00065a1d-7fa3-93d0-0000-000101000020\",\"pre_event_id\":\"00065a1d-7fa3-7490-0003-000100000020\",\"order_source\":\"orderbook\"}","recorded_unix_us":1787932602278717}
{"message":"{\"data\":{\"id\":2044303882584076,\"id_str\":\"2044303882584076\",\"order_type\":1,\"order_subtype\":4,\"datetime\":\"1787932602\",\"microtimestamp\":\"1787932602242000\",\"amount\":0.00006244,\"amount_str\":\"0.00006244\",\"amount_traded\":\"0\",\"amount_at_create\":\"0.00006244\",\"price\":80878,\"price_str\":\"80878.00\",\"is_liquidation\":false},\"channel\":\"live_orders_btcusd\",\"event\":\"order_deleted\",\"event_id\":\"00065a1d-7fa3-93d0-0001-000102000020\",\"pre_event_id\":\"00065a1d-7fa3-93d0-0000-000101000020\",\"order_source\":\"orderbook\"}","recorded_unix_us":1787932602278753}
{"message":"{\"data\":{\"id\":2044303882604554,\"id_str\":\"2044303882604554\",\"order_type\":1,\"order_subtype\":5,\"datetime\":\"1787932602\",\"microtimestamp\":\"1787932602247000\",\"amount\":4.23144408,\"amount_str\":\"4.23144408\",\"amount_traded\":\"0\",\"amount_at_create\":\"4.23144408\",\"price\":0.03161011,\"price_str\":\"0.03161011\",\"is_liquidation\":false},\"channel\":\"live_orders_ethbtc\",\"event\":\"order_created\",\"event_id\":\"00065a1d-7fa3-a758-0000-001103000020\",\"pre_event_id\":\"00065a1d-7fa2-ad58-0000-001102000020\",\"order_source\":\"orderbook\"}","recorded_unix_us":1787932602278861}
{"message":"{\"data\":{\"id\":2044303882563594,\"id_str\":\"2044303882563594\",\"order_type\":0,\"order_subtype\":5,\"datetime\":\"1787932602\",\"microtimestamp\":\"1787932602248000\",\"amount\":0.403087,\"amount_str\":\"0.403087\",\"amount_traded\":\"0\",\"amount_at_create\":\"0.403087\",\"price\":2480.03,\"price_str\":\"2480.03\",\"is_liquidation\":false},\"channel\":\"live_orders_ethusd\",\"event\":\"order_deleted\",\"event_id\":\"00065a1d-7fa3-ab40-0000-001203000020\",\"pre_event_id\":\"00065a1d-7fa3-8048-0000-001202000020\",\"order_source\":\"orderbook\"}","recorded_unix_us":1787932602293906}
{"message":"{\"data\":{\"id\":2044303882612741,\"id_str\":\"2044303882612741\",\"order_type\":0,\"order_subtype\":5,\"datetime\":\"1787932602\",\"microtimestamp\":\"1787932602249000\",\"amount\":2.734871,\"amount_str\":\"2.734871\",\"amount_traded\":\"0\",\"amount_at_create\":\"2.734871\",\"price\":2480.21,\"price_str\":\"2480.21\",\"is_liquidation\":false},\"channel\":\"live_orders_ethusd\",\"event\":\"order_created\",\"event_id\":\"00065a1d-7fa3-af28-0000-001200000020\",\"pre_event_id\":\"00065a1d-7fa3-ab40-0000-001203000020\",\"order_source\":\"orderbook\"}","recorded_unix_us":1787932602294137}
{"message":"{\"data\":{\"id\":2044303882625030,\"id_str\":\"2044303882625030\",\"order_type\":1,\"order_subtype\":5,\"datetime\":\"1787932602\",\"microtimestamp\":\"1787932602251000\",\"amount\":0.1,\"amount_str\":\"0.10000000\",\"amount_traded\":\"0\",\"amount_at_create\":\"0.10000000\",\"price\":78522.62,\"price_str\":\"78522.62\",\"is_liquidation\":false},\"channel\":\"live_orders_btcusd\",\"event\":\"order_created\",\"event_id\":\"00065a1d-7fa3-b6f8-0000-000103000020\",\"pre_event_id\":\"00065a1d-7fa3-93d0-0001-000102000020\",\"order_source\":\"orderbook\"}","recorded_unix_us":1787932602294292}
{"message":"{\"data\":{\"id\":2044303882625030,\"id_str\":\"2044303882625030\",\"order_type\":1,\"order_subtype\":5,\"datetime\":\"1787932602\",\"microtimestamp\":\"1787932602251000\",\"amount\":0.1,\"amount_str\":\"0.10000000\",\"amount_traded\":\"0\",\"amount_at_create\":\"0.10000000\",\"price\":78522.62,\"price_str\":\"78522.62\",\"is_liquidation\":false},\"channel\":\"live_orders_btcusd\",\"event\":\"order_deleted\",\"event_id\":\"00065a1d-7fa3-b6f8-0001-000100000020\",\"pre_event_id\":\"00065a1d-7fa3-b6f8-0000-000103000020\",\"order_source\":\"orderbook\"}","recorded_unix_us":1787932602294418}
{"message":"{\"data\":{\"id\":2044303882661889,\"id_str\":\"2044303882661889\",\"order_type\":0,\"order_subtype\":5,\"datetime\":\"1787932602\",\"microtimestamp\":\"1787932602260000\",\"amount\":0.403086,\"amount_str\":\"0.403086\",\"amount_traded\":\"0\",\"amount_at_create\":\"0.403086\",\"price\":2480.1,\"price_str\":\"2480.10\",\"is_liquidation\":false},\"channel\":\"live_orders_ethusd\",\"event\":\"order_created\",\"event_id\":\"00065a1d-7fa3-da20-0000-001201000020\",\"pre_event_id\":\"00065a1d-7fa3-af28-0000-001200000020\",\"order_source\":\"orderbook\"}","recorded_unix_us":1787932602294566}
{"message":"{\"data\":{\"id\":2044303881973764,\"id_str\":\"2044303881973764\",\"order_type\":0,\"order_subtype\":5,\"datetime\":\"1787932602\",\"microtimestamp\":\"1787932602261000\",\"amount\":0.403088,\"amount_str\":\"0.403088\",\"amount_traded\":\"0\",\"amount_at_create\":\"0.403088\",\"price\":2480.1,\"price_str\":\"2480.10\",\"is_liquidation\":false},\"channel\":\"live_orders_ethusd\",\"event\":\"order_deleted\",\"event_id\":\"00065a1d-7fa3-de08-0000-001202000020\",\"pre_event_id\":\"00065a1d-7fa3-da20-0000-001201000020\",\"order_source\":\"orderbook\"}","recorded_unix_us":1787932602306938}
{"message":"{\"data\":{\"id\":2044303882694659,\"id_str\":\"2044303882694659\",\"order_type\":0,\"order_subtype\":5,\"datetime\":\"1787932602\",\"microtimestamp\":\"1787932602268000\",\"amount\":0.403086,\"amount_str\":\"0.403086\",\"amount_traded\":\"0\",\"amount_at_create\":\"0.403086\",\"price\":2480.16,\"price_str\":\"2480.16\",\"is_liquidation\":false},\"channel\":\"live_orders_ethusd\",\"event\":\"order_created\",\"event_id\":\"00065a1d-7fa3-f960-0000-001203000020\",\"pre_event_id\":\"00065a1d-7fa3-de08-0000-001202000020\",\"order_source\":\"orderbook\"}","recorded_unix_us":1787932602307182}
{"message":"{\"data\":{\"id\":2044303874338819,\"id_str\":\"2044303874338819\",\"order_type\":0,\"order_subtype\":0,\"datetime\":\"1787932602\",\"microtimestamp\":\"1787932602272000\",\"amount\":0.042969,\"amount_str\":\"0.042969\",\"amount_traded\":\"0\",\"amount_at_create\":\"0.042969\",\"price\":2472.16,\"price_str\":\"2472.16\",\"is_liquidation\":false},\"channel\":\"live_orders_ethusd\",\"event\":\"order_deleted\",\"event_id\":\"00065a1d-7fa4-0900-0000-001200000020\",\"pre_event_id\":\"00065a1d-7fa3-f960-0000-001203000020\",\"order_source\":\"orderbook\"}","recorded_unix_us":1787932602307328}
{"message":"{\"data\":{\"id\":2044303882711043,\"id_str\":\"2044303882711043\",\"order_type\":0,\"order_subtype\":0,\"datetime\":\"1787932602\",\"microtimestamp\":\"1787932602272000\",\"amount\":0.042863,\"amount_str\":\"0.042863\",\"amount_traded\":\"0\",\"amount_at_create\":\"0.042863\",\"price\":2472.16,\"price_str\":\"2472.16\",\"is_liquidation\":false},\"channel\":\"live_orders_ethusd\",\"event\":\"order_created\",\"event_id\":\"00065a1d-7fa4-0900-0001-001201000020\",\"pre_event_id\":\"00065a1d-7fa4-0900-0000-001200000020\",\"order_source\":\"orderbook\"}","recorded_unix_us":1787932602307478}
{"message":"{\"data\":{\"id\":2044303882383360,\"id_str\":\"2044303882383360\",\"order_type\":1,\"order_subtype\":5,\"datetime\":\"1787932602\",\"microtimestamp\":\"1787932602273000\",\"amount\":5,\"amount_str\":\"5.000000\",\"amount_traded\":\"0\",\"amount_at_create\":\"5.000000\",\"price\":2481.7,\"price_str\":\"2481.70\",\"is_liquidation\":false},\"channel\":\"live_orders_ethusd\",\"event\":\"order_deleted\",\"event_id\":\"00065a1d-7fa4-0ce8-0000-001202000020\",\"pre_event_id\":\"00065a1d-7fa4-0900-0001-001201000020\",\"order_source\":\"orderbook\"}","recorded_unix_us":1787932602307625}
{"message":"{\"data\":{\"id\":2044303882719235,\"id_str\":\"2044303882719235\",\"order_type\":1,\"order_subtype\":5,\"datetime\":\"1787932602\",\"microtimestamp\":\"1787932602274000\",\"amount\":0.06310787,\"amount_str\":\"0.06310787\",\"amount_traded\":\"0\",\"amount_at_create\":\"0.06310787\",\"price\":78520.86,\"price_str\":\"78520.86\",\"is_liquidation\":false},\"channel\":\"live_orders_btcusd\",\"event\":\"order_created\",\"event_id\":\"00065a1d-7fa4-10d0-0000-000101000020\",\"pre_event_id\":\"00065a1d-7fa3-b6f8-0001-000100000020\",\"order_source\":\"orderbook\"}","recorded_unix_us":1787932602307798}
{"message":"{\"data\":{\"id\":2044303882719235,\"id_str\":\"2044303882719235\",\"order_type\":1,\"order_subtype\":5,\"datetime\":\"1787932602\",\"microtimestamp\":\"1787932602274000\",\"amount\":0.06310787,\"amount_str\":\"0.06310787\",\"amount_traded\":\"0\",\"amount_at_create\":\"0.06310787\",\"price\":78520.86,\"price_str\":\"78520.86\",\"is_liquidation\":false},\"channel\":\"live_orders_btcusd\",\"event\":\"order_deleted\",\"event_id\":\"00065a1d-7fa4-10d0-0001-000102000020\",\"pre_event_id\":\"00065a1d-7fa4-10d0-0000-000101000020\",\"order_source\":\"orderbook\"}","recorded_unix_us":1787932602307837}
{"message":"{\"data\":{\"id\":2044303882719244,\"id_str\":\"2044303882719244\",\"order_type\":1,\"order_subtype\":5,\"datetime\":\"1787932602\",\"microtimestamp\":\"1787932602275000\",\"amount\":0.1,\"amount_str\":\"0.10000000\",\"amount_traded\":\"0\",\"amount_at_create\":\"0.10000000\",\"price\":78522.63,\"price_str\":\"78522.63\",\"is_liquidation\":false},\"channel\":\"live_orders_btcusd\",\"event\":\"order_created\",\"event_id\":\"00065a1d-7fa4-14b8-0000-000103000020\",\"pre_event_id\":\"00065a1d-7fa4-10d0-0001-000102000020\",\"order_source\":\"orderbook\"}","recorded_unix_us":1787932602308038}
{"message":"{\"data\":{\"id\":2044303882719244,\"id_str\":\"2044303882719244\",\"order_type\":1,\"order_subtype\":5,\"datetime\":\"1787932602\",\"microtimestamp\":\"1787932602275000\",\"amount\":0.1,\"amount_str\":\"0.10000000\",\"amount_traded\":\"0\",\"amount_at_create\":\"0.10000000\",\"price\":78522.63,\"price_str\":\"78522.63\",\"is_liquidation\":false},\"channel\":\"live_orders_btcusd\",\"event\":\"order_deleted\",\"event_id\":\"00065a1d-7fa4-14b8-0001-000100000020\",\"pre_event_id\":\"00065a1d-7fa4-14b8-0000-000103000020\",\"order_source\":\"orderbook\"}","recorded_unix_us":1787932602308164}
{"message":"{\"data\":{\"id\":2044303882780684,\"id_str\":\"2044303882780684\",\"order_type\":1,\"order_subtype\":5,\"datetime\":\"1787932602\",\"microtimestamp\":\"1787932602290000\",\"amount\":0.1,\"amount_str\":\"0.10000000\",\"amount_traded\":\"0\",\"amount_at_create\":\"0.10000000\",\"price\":78522.62,\"price_str\":\"78522.62\",\"is_liquidation\":false},\"channel\":\"live_orders_btcusd\",\"event\":\"order_created\",\"event_id\":\"00065a1d-7fa4-4f50-0000-000101000020\",\"pre_event_id\":\"00065a1d-7fa4-14b8-0001-000100000020\",\"order_source\":\"orderbook\"}","recorded_unix_us":1787932602321277}
{"message":"{\"data\":{\"id\":2044303882780684,\"id_str\":\"2044303882780684\",\"order_type\":1,\"order_subtype\":5,\"datetime\":\"1787932602\",\"microtimestamp\":\"1787932602290000\",\"amount\":0.1,\"amount_str\":\"0.10000000\",\"amount_traded\":\"0\",\"amount_at_create\":\"0.10000000\",\"price\":78522.62,\"price_str\":\"78522.62\",\"is_liquidation\":false},\"channel\":\"live_orders_btcusd\",\"event\":\"order_deleted\",\"event_id\":\"00065a1d-7fa4-4f50-0001-000102000020\",\"pre_event_id\":\"00065a1d-7fa4-4f50-0000-000101000020\",\"order_source\":\"orderbook\"}","recorded_unix_us":1787932602321536}
{"message":"{\"data\":{\"id\":2044303881424900,\"id_str\":\"2044303881424900\",\"order_type\":0,\"order_subtype\":5,\"datetime\":\"1787932602\",\"microtimestamp\":\"1787932602290000\",\"amount\":0.26750492,\"amount_str\":\"0.26750492\",\"amount_traded\":\"0\",\"amount_at_create\":\"0.26750492\",\"price\":78486.82,\"price_str\":\"78486.82\",\"is_liquidation\":false},\"channel\":\"live_orders_btcusd\",\"event\":\"order_deleted\",\"event_id\":\"00065a1d-7fa4-4f50-0002-000103000020\",\"pre_event_id\":\"00065a1d-7fa4-4f50-0001-000102000020\",\"order_source\":\"orderbook\"}","recorded_unix_us":1787932602333317}
{"message":"{\"data\":{\"id\":2044303882784773,\"id_str\":\"2044303882784773\",\"order_type\":0,\"order_subtype\":5,\"datetime\":\"1787932602\",\"microtimestamp\":\"1787932602290000\",\"amount\":0.26750492,\"amount_str\":\"0.26750492\",\"amount_traded\":\"0\",\"amount_at_create\":\"0.26750492\",\"price\":78486.82,\"price_str\":\"78486.82\",\"is_liquidation\":false},\"channel\":\"live_orders_btcusd\",\"event\":\"order_created\",\"event_id\":\"00065a1d-7fa4-4f50-0003-000100000020\",\"pre_event_id\":\"00065a1d-7fa4-4f50-0002-000103000020\",\"order_source\":\"orderbook\"}","recorded_unix_us":1787932602333434}
{"message":"{\"data\":{\"id\":2044303882833933,\"id_str\":\"2044303882833933\",\"order_type\":1,\"order_subtype\":5,\"datetime\":\"1787932602\",\"microtimestamp\":\"1787932602303000\",\"amount\":0.06310787,\"amount_str\":\"0.06310787\",\"amount_traded\":\"0\",\"amount_at_create\":\"0.06310787\",\"price\":78520.39,\"price_str\":\"78520.39\",\"is_liquidation\":false},\"channel\":\"live_orders_btcusd\",\"event\":\"order_created\",\"event_id\":\"00065a1d-7fa4-8218-0000-000101000020\",\"pre_event_id\":\"00065a1d-7fa4-4f50-0003-000100000020\",\"order_source\":\"orderbook\"}","recorded_unix_us":1787932602335146}
{"message":"{\"data\":{\"id\":2044303882833933,\"id_str\":\"2044303882833933\",\"order_type\":1,\"order_subtype\":5,\"datetime\":\"1787932602\",\"microtimestamp\":\"1787932602303000\",\"amount\":0.06310787,\"amount_str\":\"0.06310787\",\"amount_traded\":\"0\",\"amount_at_create\":\"0.06310787\",\"price\":78520.39,\"price_str\":\"78520.39\",\"is_liquidation\":false},\"channel\":\"live_orders_btcusd\",\"event\":\"order_deleted\",\"event_id\":\"00065a1d-7fa4-8218-0001-000102000020\",\"pre_event_id\":\"00065a1d-7fa4-8218-0000-000101000020\",\"order_source\":\"orderbook\"}","recorded_unix_us":1787932602335240}
{"message":"{\"data\":{\"id\":2044303882842112,\"id_str\":\"2044303882842112\",\"order_type\":1,\"order_subtype\":5,\"datetime\":\"1787932602\",\"microtimestamp\":\"1787932602304000\",\"amount\":0.1,\"amount_str\":\"0.10000000\",\"amount_traded\":\"0\",\"amount_at_create\":\"0.10000000\",\"price\":78522.63,\"price_str\":\"78522.63\",\"is_liquidation\":false},\"channel\":\"live_orders_btcusd\",\"event\":\"order_created\",\"event_id\":\"00065a1d-7fa4-8600-0000-000103000020\",\"pre_event_id\":\"00065a1d-7fa4-8218-0001-000102000020\",\"order_source\":\"orderbook\"}","recorded_unix_us":1787932602350611}
{"message":"{\"data\":{\"id\":2044303882842112,\"id_str\":\"2044303882842112\",\"order_type\":1,\"order_subtype\":5,\"datetime\":\"1787932602\",\"microtimestamp\":\"1787932602304000\",\"amount\":0.1,\"amount_str\":\"0.10000000\",\"amount_traded\":\"0\",\"amount_at_create\":\"0.10000000\",\"price\":78522.63,\"price_str\":\"78522.63\",\"is_liquidation\":false},\"channel\":\"live_orders_btcusd\",\"event\":\"order_deleted\",\"event_id\":\"00065a1d-7fa4-8600-0001-000100000020\",\"pre_event_id\":\"00065a1d-7fa4-8600-0000-000103000020\",\"order_source\":\"orderbook\"}","recorded_unix_us":1787932602350817}
{"message":"{\"data\":{\"id\":2044303882031107,\"id_str\":\"2044303882031107\",\"order_type\":0,\"order_subtype\":5,\"datetime\":\"1787932602\",\"microtimestamp\":\"1787932602305000\",\"amount\":0.19104003,\"amount_str\":\"0.19104003\",\"amount_traded\":\"0\",\"amount_at_create\":\"0.19104003\",\"price\":78485.62,\"price_str\":\"78485.62\",\"is_liquidation\":false},\"channel\":\"live_orders_btcusd\",\"event\":\"order_deleted\",\"event_id\":\"00065a1d-7fa4-89e8-0000-000101000020\",\"pre_event_id\":\"00065a1d-7fa4-8600-0001-000100000020\",\"order_source\":\"orderbook\"}","recorded_unix_us":1787932602350971}
{"message":"{\"data\":{\"id\":2044303882039300,\"id_str\":\"2044303882039300\",\"order_type\":0,\"order_subtype\":5,\"datetime\":\"1787932602\",\"microtimestamp\":\"1787932602305000\",\"amount\":0.63680011,\"amount_str\":\"0.63680011\",\"amount_traded\":\"0\",\"amount_at_create\":\"0.63680011\",\"price\":78483.66,\"price_str\":\"78483.66\",\"is_liquidation\":false},\"channel\":\"live_orders_btcusd\",\"event\":\"order_deleted\",\"event_id\":\"00065a1d-7fa4-89e8-0001-000102000020\",\"pre_event_id\":\"00065a1d-7fa4-89e8-0000-000101000020\",\"order_source\":\"orderbook\"}","recorded_unix_us":1787932602351099}
{"message":"{\"data\":{\"id\":2044303882039302,\"id_str\":\"2044303882039302\",\"order_type\":0,\"order_subtype\":5,\"datetime\":\"1787932602\",\"microtimestamp\":\"1787932602306000\",\"amount\":0.50944009,\"amount_str\":\"0.50944009\",\"amount_traded\":\"0\",\"amount_at_create\":\"0.50944009\",\"price\":78481.69,\"price_str\":\"78481.69\",\"is_liquidation\":false},\"channel\":\"live_orders_btcusd\",\"event\":\"order_deleted\",\"event_id\":\"00065a1d-7fa4-8dd0-0000-000103000020\",\"pre_event_id\":\"00065a1d-7fa4-89e8-0001-000102000020\",\"order_source\":\"orderbook\"}","recorded_unix_us":1787932602351222}
{"message":"{\"data\":{\"id\":2044303882854404,\"id_str\":\"2044303882854404\",\"order_type\":0,\"order_subtype\":5,\"datetime\":\"1787932602\",\"microtimestamp\":\"1787932602307000\",\"amount\":0.00140266,\"amount_str\":\"0.00140266\",\"amount_traded\":\"0\",\"amount_at_create\":\"0.00140266\",\"price\":70668.36,\"price_str\":\"70668.36\",\"is_liquidation\":false},\"channel\":\"live_orders_btcusd\",\"event\":\"order_created\",\"event_id\":\"00065a1d-7fa4-91b8-0000-000100000020\",\"pre_event_id\":\"00065a1d-7fa4-8dd0-0000-000103000020\",\"order_source\":\"orderbook\"}","recorded_unix_us":1787932602351461}
{"message":"{\"data\":{\"id\":2044303882661889,\"id_str\":\"2044303882661889\",\"order_type\":0,\"order_subtype\":5,\"datetime\":\"1787932602\",\"microtimestamp\":\"1787932602309000\",\"amount\":0.403086,\"amount_str\":\"0.403086\",\"amount_traded\":\"0\",\"amount_at_create\":\"0.403086\",\"price\":2480.1,\"price_str\":\"2480.10\",\"is_liquidation\":false},\"channel\":\"live_orders_ethusd\",\"event\":\"order_deleted\",\"event_id\":\"00065a1d-7fa4-9988-0000-001203000020\",\"pre_event_id\":\"00065a1d-7fa4-0ce8-0000-001202000020\",\"order_source\":\"orderbook\"}","recorded_unix_us":1787932602351562}
{"message":"{\"data\":{\"id\":2044303882887181,\"id_str\":\"2044303882887181\",\"order_type\":0,\"order_subtype\":5,\"datetime\":\"1787932602\",\"microtimestamp\":\"1787932602316000\",\"amount\":0.1910377,\"amount_str\":\"0.19103770\",\"amount_traded\":\"0\",\"amount_at_create\":\"0.19103770\",\"price\":78485,\"price_str\":\"78485.00\",\"is_liquidation\":false},\"channel\":\"live_orders_btcusd\",\"event\":\"order_created\",\"event_id\":\"00065a1d-7fa4-b4e0-0000-000101000020\",\"pre_event_id\":\"00065a1d-7fa4-91b8-0000-000100000020\",\"order_source\":\"orderbook\"}","recorded_unix_us":1787932602351838}
{"message":"{\"data\":{\"id\":2044303882899463,\"id_str\":\"2044303882899463\",\"order_type\":0,\"order_subtype\":5,\"datetime\":\"1787932602\",\"microtimestamp\":\"1787932602318000\",\"amount\":0.403089,\"amount_str\":\"0.403089\",\"amount_traded\":\"0\",\"amount_at_create\":\"0.403089\",\"price\":2480.07,\"price_str\":\"2480.07\",\"is_liquidation\":false},\"channel\":\"live_orders_ethusd\",\"event\":\"order_created\",\"event_id\":\"00065a1d-7fa4-bcb0-0000-001200000020\",\"pre_event_id\":\"00065a1d-7fa4-9988-0000-001203000020\",\"order_source\":\"orderbook\"}","recorded_unix_us":1787932602351951}
{"message":"{\"data\":{\"id\":2044303882190850,\"id_str\":\"2044303882190850\",\"order_type\":0,\"order_subtype\":5,\"datetime\":\"1787932602\",\"microtimestamp\":\"1787932602318000\",\"amount\":0.00140266,\"amount_str\":\"0.00140266\",\"amount_traded\":\"0\",\"amount_at_create\":\"0.00140266\",\"price\":70668.36,\"price_str\":\"70668.36\",\"is_liquidation\":false},\"channel\":\"live_orders_btcusd\",\"event\":\"order_deleted\",\"event_id\":\"00065a1d-7fa4-bcb0-0000-000102000020\",\"pre_event_id\":\"00065a1d-7fa4-b4e0-0000-000101000020\",\"order_source\":\"orderbook\"}","recorded_unix_us":1787932602351997}
{"message":"{\"data\":{\"id\":2044303882911744,\"id_str\":\"2044303882911744\",\"order_type\":0,\"order_subtype\":5,\"datetime\":\"1787932602\",\"microtimestamp\":\"1787932602321000\",\"amount\":0.63679235,\"amount_str\":\"0.63679235\",\"amount_traded\":\"0\",\"amount_at_create\":\"0.63679235\",\"price\":78483.04,\"price_str\":\"78483.04\",\"is_liquidation\":false},\"channel\":\"live_orders_btcusd\",\"event\":\"order_created\",\"event_id\":\"00065a1d-7fa4-c868-0000-000103000020\",\"pre_event_id\":\"00065a1d-7fa4-bcb0-0000-000102000020\",\"order_source\":\"orderbook\"}","recorded_unix_us":1787932602362524}
{"message":"{\"data\":{\"id\":2044303882911754,\"id_str\":\"2044303882911754\",\"order_type\":0,\"order_subtype\":5,\"datetime\":\"1787932602\",\"microtimestamp\":\"1787932602321000\",\"amount\":0.50943388,\"amount_str\":\"0.50943388\",\"amount_traded\":\"0\",\"amount_at_create\":\"0.50943388\",\"price\":78481.08,\"price_str\":\"78481.08\",\"is_liquidation\":false},\"channel\":\"live_orders_btcusd\",\"event\":\"order_created\",\"event_id\":\"00065a1d-7fa4-c868-0001-000100000020\",\"pre_event_id\":\"00065a1d-7fa4-c868-0000-000103000020\",\"order_source\":\"orderbook\"}","recorded_unix_us":1787932602362735}
{"message":"{\"data\":{\"id\":2044303882915840,\"id_str\":\"2044303882915840\",\"order_type\":1,\"order_subtype\":5,\"datetime\":\"1787932602\",\"microtimestamp\":\"1787932602322000\",\"amount\":0.1,\"amount_str\":\"0.10000000\",\"amount_traded\":\"0\",\"amount_at_create\":\"0.10000000\",\"price\":78522.62,\"price_str\":\"78522.62\",\"is_liquidation\":false},\"channel\":\"live_orders_btcusd\",\"event\":\"order_created\",\"event_id\":\"00065a1d-7fa4-cc50-0000-000101000020\",\"pre_event_id\":\"00065a1d-7fa4-c868-0001-000100000020\",\"order_source\":\"orderbook\"}","recorded_unix_us":1787932602362928}
{"message":"{\"data\":{\"id\":2044303882915840,\"id_str\":\"2044303882915840\",\"order_type\":1,\"order_subtype\":5,\"datetime\":\"1787932602\",\"microtimestamp\":\"1787932602322000\",\"amount\":0.1,\"amount_str\":\"0.10000000\",\"amount_traded\":\"0\",\"amount_at_create\":\"0.10000000\",\"price\":78522.62,\"price_str\":\"78522.62\",\"is_liquidation\":false},\"channel\":\"live_orders_btcusd\",\"event\":\"order_deleted\",\"event_id\":\"00065a1d-7fa4-cc50-0001-000102000020\",\"pre_event_id\":\"00065a1d-7fa4-cc50-0000-000101000020\",\"order_source\":\"orderbook\"}","recorded_unix_us":1787932602363119}
{"message":"{\"data\":{\"id\":2044303880990722,\"id_str\":\"2044303880990722\",\"order_type\":1,\"order_subtype\":0,\"datetime\":\"1787932602\",\"microtimestamp\":\"1787932602323000\",\"amount\":0.06310787,\"amount_str\":\"0.06310787\",\"amount_traded\":\"0\",\"amount_at_create\":\"0.06310787\",\"price\":78549.2,\"price_str\":\"78549.20\",\"is_liquidation\":false},\"channel\":\"live_orders_btcusd\",\"event\":\"order_deleted\",\"event_id\":\"00065a1d-7fa4-d038-0000-000103000020\",\"pre_event_id\":\"00065a1d-7fa4-cc50-0001-000102000020\",\"order_source\":\"orderbook\"}","recorded_unix_us":1787932602363241}
{"message":"{\"data\":{\"id\":2044303882956805,\"id_str\":\"2044303882956805\",\"order_type\":1,\"order_subtype\":5,\"datetime\":\"1787932602\",\"microtimestamp\":\"1787932602332000\",\"amount\":0.06310787,\"amount_str\":\"0.06310787\",\"amount_traded\":\"0\",\"amount_at_create\":\"0.06310787\",\"price\":78520.12,\"price_str\":\"78520.12\",\"is_liquidation\":false},\"channel\":\"live_orders_btcusd\",\"event\":\"order_created\",\"event_id\":\"00065a1d-7fa4-f360-0000-000100000020\",\"pre_event_id\":\"00065a1d-7fa4-d038-0000-000103000020\",\"order_source\":\"orderbook\"}","recorded_unix_us":1787932602365320}
{"message":"{\"data\":{\"id\":2044303882956805,\"id_str\":\"2044303882956805\",\"order_type\":1,\"order_subtype\":5,\"datetime\":\"1787932602\",\"microtimestamp\":\"1787932602332000\",\"amount\":0.06310787,\"amount_str\":\"0.06310787\",\"amount_traded\":\"0\",\"amount_at_create\":\"0.06310787\",\"price\":78520.12,\"price_str\":\"78520.12\",\"is_liquidation\":false},\"channel\":\"live_orders_btcusd\",\"event\":\"order_deleted\",\"event_id\":\"00065a1d-7fa4-f360-0001-000101000020\",\"pre_event_id\":\"00065a1d-7fa4-f360-0000-000100000020\",\"order_source\":\"orderbook\"}","recorded_unix_us":1787932602365460}
{"message":"{\"data\":{\"id\":2044303882964992,\"id_str\":\"2044303882964992\",\"order_type\":1,\"order_subtype\":5,\"datetime\":\"1787932602\",\"microtimestamp\":\"1787932602334000\",\"amount\":0.06310787,\"amount_str\":\"0.06310787\",\"amount_traded\":\"0\",\"amount_at_create\":\"0.06310787\",\"price\":78522.48,\"price_str\":\"78522.48\",\"is_liquidation\":false},\"channel\":\"live_orders_btcusd\",\"event\":\"order_created\",\"event_id\":\"00065a1d-7fa4-fb30-0000-000102000020\",\"pre_event_id\":\"00065a1d-7fa4-f360-0001-000101000020\",\"order_source\":\"orderbook\"}","recorded_unix_us":1787932602375232}
{"message":"{\"data\":{\"id\":2044303882964992,\"id_str\":\"2044303882964992\",\"order_type\":1,\"order_subtype\":5,\"datetime\":\"1787932602\",\"microtimestamp\":\"1787932602334000\",\"amount\":0.06310787,\"amount_str\":\"0.06310787\",\"amount_traded\":\"0\",\"amount_at_create\":\"0.06310787\",\"price\":78522.48,\"price_str\":\"78522.48\",\"is_liquidation\":false},\"channel\":\"live_orders_btcusd\",\"event\":\"order_deleted\",\"event_id\":\"00065a1d-7fa4-fb30-0001-000103000020\",\"pre_event_id\":\"00065a1d-7fa4-fb30-0000-000102000020\",\"order_source\":\"orderbook\"}","recorded_unix_us":1787932602375766}
{"message":"{\"data\":{\"id\":2044303877599234,\"id_str\":\"2044303877599234\",\"order_type\":1,\"order_subtype\":5,\"datetime\":\"1787932602\",\"microtimestamp\":\"1787932602339000\",\"amount\":0.12,\"amount_str\":\"0.12000000\",\"amount_traded\":\"0\",\"amount_at_create\":\"0.12000000\",\"price\":78541,\"price_str\":\"78541.00\",\"is_liquidation\":false},\"channel\":\"live_orders_btcusd\",\"event\":\"order_deleted\",\"event_id\":\"00065a1d-7fa5-0eb8-0000-000100000020\",\"pre_event_id\":\"00065a1d-7fa4-fb30-0001-000103000020\",\"order_source\":\"orderbook\"}","recorded_unix_us":1787932602376099}
{"message":"{\"data\":{\"id\":2044303883022336,\"id_str\":\"2044303883022336\",\"order_type\":1,\"order_subtype\":5,\"datetime\":\"1787932602\",\"microtimestamp\":\"1787932602348000\",\"amount\":0.1,\"amount_str\":\"0.10000000\",\"amount_traded\":\"0\",\"amount_at_create\":\"0.10000000\",\"price\":78522.63,\"price_str\":\"78522.63\",\"is_liquidation\":false},\"channel\":\"live_orders_btcusd\",\"event\":\"order_created\",\"event_id\":\"00065a1d-7fa5-31e0-0000-000101000020\",\"pre_event_id\":\"00065a1d-7fa5-0eb8-0000-000100000020\",\"order_source\":\"orderbook\"}","recorded_unix_us":1787932602388826}
{"message":"{\"data\":{\"id\":2044303883022336,\"id_str\":\"2044303883022336\",\"order_type\":1,\"order_subtype\":5,\"datetime\":\"1787932602\",\"microtimestamp\":\"1787932602348000\",\"amount\":0.1,\"amount_str\":\"0.10000000\",\"amount_traded\":\"0\",\"amount_at_create\":\"0.10000000\",\"price\":78522.63,\"price_str\":\"78522.63\",\"is_liquidation\":false},\"channel\":\"live_orders_btcusd\",\"event\":\"order_deleted\",\"event_id\":\"00065a1d-7fa5-31e0-0001-000102000020\",\"pre_event_id\":\"00065a1d-7fa5-31e0-0000-000101000020\",\"order_source\":\"orderbook\"}","recorded_unix_us":1787932602389013}
{"message":"{\"data\":{\"id\":2044303883046920,\"id_str\":\"2044303883046920\",\"order_type\":1,\"order_subtype\":5,\"datetime\":\"1787932602\",\"microtimestamp\":\"1787932602355000\",\"amount\":5.206947,\"amount_str\":\"5.206947\",\"amount_traded\":\"0\",\"amount_at_create\":\"5.206947\",\"price\":2482.05,\"price_str\":\"2482.05\",\"is_liquidation\":false},\"channel\":\"live_orders_ethusd\",\"event\":\"order_created\",\"event_id\":\"00065a1d-7fa5-4d38-0000-001201000020\",\"pre_event_id\":\"00065a1d-7fa4-bcb0-0000-001200000020\",\"order_source\":\"orderbook\"}","recorded_unix_us":1787932602392650}
{"message":"{\"data\":{\"id\":2044303883079685,\"id_str\":\"2044303883079685\",\"order_type\":1,\"order_subtype\":5,\"datetime\":\"1787932602\",\"microtimestamp\":\"1787932602362000\",\"amount\":0.1,\"amount_str\":\"0.10000000\",\"amount_traded\":\"0\",\"amount_at_create\":\"0.10000000\",\"price\":78522.62,\"price_str\":\"78522.62\",\"is_liquidation\":false},\"channel\":\"live_orders_btcusd\",\"event\":\"order_created\",\"event_id\":\"00065a1d-7fa5-6890-0000-000103000020\",\"pre_event_id\":\"00065a1d-7fa5-31e0-0001-000102000020\",\"order_source\":\"orderbook\"}","recorded_unix_us":1787932602407682}
{"message":"{\"data\":{\"id\":2044303883079685,\"id_str\":\"2044303883079685\",\"order_type\":1,\"order_subtype\":5,\"datetime\":\"1787932602\",\"microtimestamp\":\"1787932602362000\",\"amount\":0.1,\"amount_str\":\"0.10000000\",\"amount_traded\":\"0\",\"amount_at_create\":\"0.10000000\",\"price\":78522.62,\"price_str\":\"78522.62\",\"is_liquidation\":false},\"channel\":\"live_orders_btcusd\",\"event\":\"order_deleted\",\"event_id\":\"00065a1d-7fa5-6890-0001-000100000020\",\"pre_event_id\":\"00065a1d-7fa5-6890-0000-000103000020\",\"order_source\":\"orderbook\"}","recorded_unix_us":1787932602407771}
{"message":"{\"data\":{\"id\":2044303881457676,\"id_str\":\"2044303881457676\",\"order_type\":1,\"order_subtype\":5,\"datetime\":\"1787932602\",\"microtimestamp\":\"1787932602365000\",\"amount\":1.27113313,\"amount_str\":\"1.27113313\",\"amount_traded\":\"0\",\"amount_at_create\":\"1.27113313\",\"price\":78669.97,\"price_str\":\"78669.97\",\"is_liquidation\":false},\"channel\":\"live_orders_btcusd\",\"event\":\"order_deleted\",\"event_id\":\"00065a1d-7fa5-7448-0000-000101000020\",\"pre_event_id\":\"00065a1d-7fa5-6890-0001-000100000020\",\"order_source\":\"orderbook\"}","recorded_unix_us":1787932602407871}
{"message":"{\"data\":{\"id\":2044303881940996,\"id_str\":\"2044303881940996\",\"order_type\":1,\"order_subtype\":5,\"datetime\":\"1787932602\",\"microtimestamp\":\"1787932602365000\",\"amount\":0.06367384,\"amount_str\":\"0.06367384\",\"amount_traded\":\"0\",\"amount_at_create\":\"0.06367384\",\"price\":78525.19,\"price_str\":\"78525.19\",\"is_liquidation\":false},\"channel\":\"live_orders_btcusd\",\"event\":\"order_deleted\",\"event_id\":\"00065a1d-7fa5-7448-0001-000102000020\",\"pre_event_id\":\"00065a1d-7fa5-7448-0000-000101000020\",\"order_source\":\"orderbook\"}","recorded_unix_us":1787932602407985}
{"message":"{\"data\":{\"id\":2044303881945092,\"id_str\":\"2044303881945092\",\"order_type\":1,\"order_subtype\":5,\"datetime\":\"1787932602\",\"microtimestamp\":\"1787932602366000\",\"amount\":0.06367563,\"amount_str\":\"0.06367563\",\"amount_traded\":\"0\",\"amount_at_create\":\"0.06367563\",\"price\":78522.98,\"price_str\":\"78522.98\",\"is_liquidation\":false},\"channel\":\"live_orders_btcusd\",\"event\":\"order_deleted\",\"event_id\":\"00065a1d-7fa5-7830-0000-000103000020\",\"pre_event_id\":\"00065a1d-7fa5-7448-0001-000102000020\",\"order_source\":\"orderbook\"}","recorded_unix_us":1787932602408010}
{"message":"{\"data\":{\"id\":2044303881949188,\"id_str\":\"2044303881949188\",\"order_type\":1,\"order_subtype\":5,\"datetime\":\"1787932602\",\"microtimestamp\":\"1787932602366000\",\"amount\":0.25467128,\"amount_str\":\"0.25467128\",\"amount_traded\":\"0\",\"amount_at_create\":\"0.25467128\",\"price\":78532.61,\"price_str\":\"78532.61\",\"is_liquidation\":false},\"channel\":\"live_orders_btcusd\",\"event\":\"order_deleted\",\"event_id\":\"00065a1d-7fa5-7830-0001-000100000020\",\"pre_event_id\":\"00065a1d-7fa5-7830-0000-000103000020\",\"order_source\":\"orderbook\"}","recorded_unix_us":1787932602408129}
{"message":"{\"data\":{\"id\":2044303881957376,\"id_str\":\"2044303881957376\",\"order_type\":1,\"order_subtype\":5,\"datetime\":\"1787932602\",\"microtimestamp\":\"1787932602367000\",\"amount\":0.25466146,\"amount_str\":\"0.25466146\",\"amount_traded\":\"0\",\"amount_at_create\":\"0.25466146\",\"price\":78535.64,\"price_str\":\"78535.64\",\"is_liquidation\":false},\"channel\":\"live_orders_btcusd\",\"event\":\"order_deleted\",\"event_id\":\"00065a1d-7fa5-7c18-0000-000101000020\",\"pre_event_id\":\"00065a1d-7fa5-7830-0001-000100000020\",\"order_source\":\"orderbook\"}","recorded_unix_us":1787932602408201}
{"message":"{\"data\":{\"id\":2044303881957380,\"id_str\":\"2044303881957380\",\"order_type\":1,\"order_subtype\":5,\"datetime\":\"1787932602\",\"microtimestamp\":\"1787932602367000\",\"amount\":1.26970017,\"amount_str\":\"1.26970017\",\"amount_traded\":\"0\",\"amount_at_create\":\"1.26970017\",\"price\":78758.76,\"price_str\":\"78758.76\",\"is_liquidation\":false},\"channel\":\"live_orders_btcusd\",\"event\":\"order_deleted\",\"event_id\":\"00065a1d-7fa5-7c18-0001-000102000020\",\"pre_event_id\":\"00065a1d-7fa5-7c18-0000-000101000020\",\"order_source\":\"orderbook\"}","recorded_unix_us":1787932602408224}
{"message":"{\"data\":{\"id\":2044303881957382,\"id_str\":\"2044303881957382\",\"order_type\":1,\"order_subtype\":5,\"datetime\":\"1787932602\",\"microtimestamp\":\"1787932602367000\",\"amount\":1.27209222,\"amount_str\":\"1.27209222\",\"amount_traded\":\"0\",\"amount_at_create\":\"1.27209222\",\"price\":78610.66,\"price_str\":\"78610.66\",\"is_liquidation\":false},\"channel\":\"live_orders_btcusd\",\"event\":\"order_deleted\",\"event_id\":\"00065a1d-7fa5-7c18-0002-000103000020\",\"pre_event_id\":\"00065a1d-7fa5-7c18-0001-000102000020\",\"order_source\":\"orderbook\"}","recorded_unix_us":1787932602408344}
{"message":"{\"data\":{\"id\":2044303881961473,\"id_str\":\"2044303881961473\",\"order_type\":1,\"order_subtype\":5,\"datetime\":\"1787932602\",\"microtimestamp\":\"1787932602368000\",\"amount\":12.70451953,\"amount_str\":\"12.70451953\",\"amount_traded\":\"0\",\"amount_at_create\":\"12.70451953\",\"price\":78712.15,\"price_str\":\"78712.15\",\"is_liquidation\":false},\"channel\":\"live_orders_btcusd\",\"event\":\"order_deleted\",\"event_id\":\"00065a1d-7fa5-8000-0000-000100000020\",\"pre_event_id\":\"00065a1d-7fa5-7c18-0002-000103000020\",\"order_source\":\"orderbook\"}","recorded_unix_us":1787932602408405}
{"message":"{\"data\":{\"id\":2044303881973767,\"id_str\":\"2044303881973767\",\"order_type\":1,\"order_subtype\":5,\"datetime\":\"1787932602\",\"microtimestamp\":\"1787932602368000\",\"amount\":1.2684012,\"amount_str\":\"1.26840120\",\"amount_traded\":\"0\",\"amount_at_create\":\"1.26840120\",\"price\":78839.41,\"price_str\":\"78839.41\",\"is_liquidation\":false},\"channel\":\"live_orders_btcusd\",\"event\":\"order_deleted\",\"event_id\":\"00065a1d-7fa5-8000-0001-000101000020\",\"pre_event_id\":\"00065a1d-7fa5-8000-0000-000100000020\",\"order_source\":\"orderbook\"}","recorded_unix_us":1787932602408429}
{"message":"{\"data\":{\"id\":2044303881986050,\"id_str\":\"2044303881986050\",\"order_type\":0,\"order_subtype\":5,\"datetime\":\"1787932602\",\"microtimestamp\":\"1787932602368000\",\"amount\":0.06367953,\"amount_str\":\"0.06367953\",\"amount_traded\":\"0\",\"amount_at_create\":\"0.06367953\",\"price\":78518.15,\"price_str\":\"78518.15\",\"is_liquidation\":false},\"channel\":\"live_orders_btcusd\",\"event\":\"order_deleted\",\"event_id\":\"00065a1d-7fa5-8000-0002-000102000020\",\"pre_event_id\":\"00065a1d-7fa5-8000-0001-000101000020\",\"order_source\":\"orderbook\"}","recorded_unix_us":1787932602408555}
{"message":"{\"data\":{\"id\":2044303878094874,\"id_str\":\"2044303878094874\",\"order_type\":0,\"order_subtype\":5,\"datetime\":\"1787932602\",\"microtimestamp\":\"1787932602369000\",\"amount\":4.838915,\"amount_str\":\"4.838915\",\"amount_traded\":\"0\",\"amount_at_create\":\"4.838915\",\"price\":2480.07,\"price_str\":\"2480.07\",\"is_liquidation\":false},\"channel\":\"live_orders_ethusd\",\"event\":\"order_deleted\",\"event_id\":\"00065a1d-7fa5-83e8-0000-001202000020\",\"pre_event_id\":\"00065a1d-7fa5-4d38-0000-001201000020\",\"order_source\":\"orderbook\"}","recorded_unix_us":1787932602408584}
{"message":"{\"data\":{\"id\":2044303883104262,\"id_str\":\"2044303883104262\",\"order_type\":0,\"order_subtype\":5,\"datetime\":\"1787932602\",\"microtimestamp\":\"1787932602369000\",\"amount\":4.837906,\"amount_str\":\"4.837906\",\"amount_traded\":\"0\",\"amount_at_create\":\"4.837906\",\"price\":2480.07,\"price_str\":\"2480.07\",\"is_liquidation\":false},\"channel\":\"live_orders_ethusd\",\"event\":\"order_created\",\"event_id\":\"00065a1d-7fa5-83e8-0001-001203000020\",\"pre_event_id\":\"00065a1d-7fa5-83e8-0000-001202000020\",\"order_source\":\"orderbook\"}","recorded_unix_us":1787932602408749}
{"message":"{\"data\":{\"id\":2044303881986057,\"id_str\":\"2044303881986057\",\"order_type\":0,\"order_subtype\":5,\"datetime\":\"1787932602\",\"microtimestamp\":\"1787932602369000\",\"amount\":0.25476924,\"amount_str\":\"0.25476924\",\"amount_traded\":\"0\",\"amount_at_create\":\"0.25476924\",\"price\":78502.41,\"price_str\":\"78502.41\",\"is_liquidation\":false},\"channel\":\"live_orders_btcusd\",\"event\":\"order_deleted\",\"event_id\":\"00065a1d-7fa5-83e8-0000-000103000020\",\"pre_event_id\":\"00065a1d-7fa5-8000-0002-000102000020\",\"order_source\":\"orderbook\"}","recorded_unix_us":1787932602408779}
{"message":"{\"data\":{\"id\":2044303881990146,\"id_str\":\"2044303881990146\",\"order_type\":0,\"order_subtype\":5,\"datetime\":\"1787932602\",\"microtimestamp\":\"1787932602369000\",\"amount\":0.25478772,\"amount_str\":\"0.25478772\",\"amount_traded\":\"0\",\"amount_at_create\":\"0.25478772\",\"price\":78496.71,\"price_str\":\"78496.71\",\"is_liquidation\":false},\"channel\":\"live_orders_btcusd\",\"event\":\"order_deleted\",\"event_id\":\"00065a1d-7fa5-83e8-0001-000100000020\",\"pre_event_id\":\"00065a1d-7fa5-83e8-0000-000103000020\",\"order_source\":\"orderbook\"}","recorded_unix_us":1787932602408804}
{"message":"{\"data\":{\"id\":2044303882002434,\"id_str\":\"2044303882002434\",\"order_type\":0,\"order_subtype\":5,\"datetime\":\"1787932602\",\"microtimestamp\":\"1787932602369000\",\"amount\":1.27507828,\"amount_str\":\"1.27507828\",\"amount_traded\":\"0\",\"amount_at_create\":\"1.27507828\",\"price\":78426.55,\"price_str\":\"78426.55\",\"is_liquidation\":false},\"channel\":\"live_orders_btcusd\",\"event\":\"order_deleted\",\"event_id\":\"00065a1d-7fa5-83e8-0002-000101000020\",\"pre_event_id\":\"00065a1d-7fa5-83e8-0001-000100000020\",\"order_source\":\"orderbook\"}","recorded_unix_us":1787932602410318}
{"message":"{\"data\":{\"id\":2044303882014723,\"id_str\":\"2044303882014723\",\"order_type\":0,\"order_subtype\":5,\"datetime\":\"1787932602\",\"microtimestamp\":\"1787932602370000\",\"amount\":1.27541152,\"amount_str\":\"1.27541152\",\"amount_traded\":\"0\",\"amount_at_create\":\"1.27541152\",\"price\":78406.06,\"price_str\":\"78406.06\",\"is_liquidation\":false},\"channel\":\"live_orders_btcusd\",\"event\":\"order_deleted\",\"event_id\":\"00065a1d-7fa5-87d0-0000-000102000020\",\"pre_event_id\":\"00065a1d-7fa5-83e8-0002-000101000020\",\"order_source\":\"orderbook\"}","recorded_unix_us":1787932602410346}
{"message":"{\"data\":{\"id\":2044303882014724,\"id_str\":\"2044303882014724\",\"order_type\":0,\"order_subtype\":5,\"datetime\":\"1787932602\",\"microtimestamp\":\"1787932602370000\",\"amount\":12.76418733,\"amount_str\":\"12.76418733\",\"amount_traded\":\"0\",\"amount_at_create\":\"12.76418733\",\"price\":78344.19,\"price_str\":\"78344.19\",\"is_liquidation\":false},\"channel\":\"live_orders_btcusd\",\"event\":\"order_deleted\",\"event_id\":\"00065a1d-7fa5-87d0-0001-000103000020\",\"pre_event_id\":\"00065a1d-7fa5-87d0-0000-000102000020\",\"order_source\":\"orderbook\"}","recorded_unix_us":1787932602410371}
{"message":"{\"data\":{\"id\":2044303882018821,\"id_str\":\"2044303882018821\",\"order_type\":0,\"order_subtype\":5,\"datetime\":\"1787932602\",\"microtimestamp\":\"1787932602370000\",\"amount\":1.27567513,\"amount_str\":\"1.27567513\",\"amount_traded\":\"0\",\"amount_at_create\":\"1.27567513\",\"price\":78389.86,\"price_str\":\"78389.86\",\"is_liquidation\":false},\"channel\":\"live_orders_btcusd\",\"event\":\"order_deleted\",\"event_id\":\"00065a1d-7fa5-87d0-0002-000100000020\",\"pre_event_id\":\"00065a1d-7fa5-87d0-0001-000103000020\",\"order_source\":\"orderbook\"}","recorded_unix_us":1787932602410523}
{"message":"{\"data\":{\"id\":2044303882035207,\"id_str\":\"2044303882035207\",\"order_type\":0,\"order_subtype\":5,\"datetime\":\"1787932602\",\"microtimestamp\":\"1787932602371000\",\"amount\":1.27757154,\"amount_str\":\"1.27757154\",\"amount_traded\":\"0\",\"amount_at_create\":\"1.27757154\",\"price\":78273.5,\"price_str\":\"78273.50\",\"is_liquidation\":false},\"channel\":\"live_orders_btcusd\",\"event\":\"order_deleted\",\"event_id\":\"00065a1d-7fa5-8bb8-0000-000101000020\",\"pre_event_id\":\"00065a1d-7fa5-87d0-0002-000100000020\",\"order_source\":\"orderbook\"}","recorded_unix_us":1787932602410553}
{"message":"{\"data\":{\"id\":2044303882096644,\"id_str\":\"2044303882096644\",\"order_type\":1,\"order_subtype\":5,\"datetime\":\"1787932602\",\"microtimestamp\":\"1787932602371000\",\"amount\":1.271772,\"amount_str\":\"1.27177200\",\"amount_traded\":\"0\",\"amount_at_create\":\"1.27177200\",\"price\":78630.45,\"price_str\":\"78630.45\",\"is_liquidation\":false},\"channel\":\"live_orders_btcusd\",\"event\":\"order_deleted\",\"event_id\":\"00065a1d-7fa5-8bb8-0001-000102000020\",\"pre_event_id\":\"00065a1d-7fa5-8bb8-0000-000101000020\",\"order_source\":\"orderbook\"}","recorded_unix_us":1787932602410701}
{"message":"{\"data\":{\"id\":2044303882104841,\"id_str\":\"2044303882104841\",\"order_type\":0,\"order_subtype\":5,\"datetime\":\"1787932602\",\"microtimestamp\":\"1787932602371000\",\"amount\":1.27604867,\"amount_str\":\"1.27604867\",\"amount_traded\":\"0\",\"amount_at_create\":\"1.27604867\",\"price\":78366.91,\"price_str\":\"78366.91\",\"is_liquidation\":false},\"channel\":\"live_orders_btcusd\",\"event\":\"order_deleted\",\"event_id\":\"00065a1d-7fa5-8bb8-0002-000103000020\",\"pre_event_id\":\"00065a1d-7fa5-8bb8-0001-000102000020\",\"order_source\":\"orderbook\"}","recorded_unix_us":1787932602410730}
{"message":"{\"data\":{\"id\":2044303882108933,\"id_str\":\"2044303882108933\",\"order_type\":1,\"order_subtype\":5,\"datetime\":\"1787932602\",\"microtimestamp\":\"1787932602372000\",\"amount\":1.26842789,\"amount_str\":\"1.26842789\",\"amount_traded\":\"0\",\"amount_at_create\":\"1.26842789\",\"price\":78837.75,\"price_str\":\"78837.75\",\"is_liquidation\":false},\"channel\":\"live_orders_btcusd\",\"event\":\"order_deleted\",\"event_id\":\"00065a1d-7fa5-8fa0-0000-000100000020\",\"pre_event_id\":\"00065a1d-7fa5-8bb8-0002-000103000020\",\"order_source\":\"orderbook\"}","recorded_unix_us":1787932602410881}
{"message":"{\"data\":{\"id\":2044303883116554,\"id_str\":\"2044303883116554\",\"order_type\":1,\"order_subtype\":5,\"datetime\":\"1787932602\",\"microtimestamp\":\"1787932602372000\",\"amount\":0.06310787,\"amount_str\":\"0.06310787\",\"amount_traded\":\"0\",\"amount_at_create\":\"0.06310787\",\"price\":78520.03,\"price_str\":\"78520.03\",\"is_liquidation\":false},\"channel\":\"live_orders_btcusd\",\"event\":\"order_created\",\"event_id\":\"00065a1d-7fa5-8fa0-0001-000101000020\",\"pre_event_id\":\"00065a1d-7fa5-8fa0-0000-000100000020\",\"order_source\":\"orderbook\"}","recorded_unix_us":1787932602410911}
{"message":"{\"data\":{\"id\":2044303883116554,\"id_str\":\"2044303883116554\",\"order_type\":1,\"order_subtype\":5,\"datetime\":\"1787932602\",\"microtimestamp\":\"1787932602372000\",\"amount\":0.06310787,\"amount_str\":\"0.06310787\",\"amount_traded\":\"0\",\"amount_at_create\":\"0.06310787\",\"price\":78520.03,\"price_str\":\"78520.03\",\"is_liquidation\":false},\"channel\":\"live_orders_btcusd\",\"event\":\"order_deleted\",\"event_id\":\"00065a1d-7fa5-8fa0-0002-000102000020\",\"pre_event_id\":\"00065a1d-7fa5-8fa0-0001-000101000020\",\"order_source\":\"orderbook\"}","recorded_unix_us":1787932602410936}
{"message":"{\"data\":{\"id\":2044303882113034,\"id_str\":\"2044303882113034\",\"order_type\":0,\"order_subtype\":5,\"datetime\":\"1787932602\",\"microtimestamp\":\"1787932602372000\",\"amount\":0.06368171,\"amount_str\":\"0.06368171\",\"amount_traded\":\"0\",\"amount_at_create\":\"0.06368171\",\"price\":78515.46,\"price_str\":\"78515.46\",\"is_liquidation\":false},\"channel\":\"live_orders_btcusd\",\"event\":\"order_deleted\",\"event_id\":\"00065a1d-7fa5-8fa0-0003-000103000020\",\"pre_event_id\":\"00065a1d-7fa5-8fa0-0002-000102000020\",\"order_source\":\"orderbook\"}","recorded_unix_us":1787932602411090}
{"message":"{\"data\":{\"id\":2044303882117122,\"id_str\":\"2044303882117122\",\"order_type\":0,\"order_subtype\":5,\"datetime\":\"1787932602\",\"microtimestamp\":\"1787932602372000\",\"amount\":1.27817952,\"amount_str\":\"1.27817952\",\"amount_traded\":\"0\",\"amount_at_create\":\"1.27817952\",\"price\":78236.27,\"price_str\":\"78236.27\",\"is_liquidation\":false},\"channel\":\"live_orders_btcusd\",\"event\":\"order_deleted\",\"event_id\":\"00065a1d-7fa5-8fa0-0004-000100000020\",\"pre_event_id\":\"00065a1d-7fa5-8fa0-0003-000103000020\",\"order_source\":\"orderbook\"}","recorded_unix_us":1787932602411118}
{"message":"{\"data\":{\"id\":2044303882178560,\"id_str\":\"2044303882178560\",\"order_type\":1,\"order_subtype\":5,\"datetime\":\"1787932602\",\"microtimestamp\":\"1787932602373000\",\"amount\":1.27145262,\"amount_str\":\"1.27145262\",\"amount_traded\":\"0\",\"amount_at_create\":\"1.27145262\",\"price\":78650.2,\"price_str\":\"78650.20\",\"is_liquidation\":false},\"channel\":\"live_orders_btcusd\",\"event\":\"order_deleted\",\"event_id\":\"00065a1d-7fa5-9388-0000-000101000020\",\"pre_event_id\":\"00065a1d-7fa5-8fa0-0004-000100000020\",\"order_source\":\"orderbook\"}","recorded_unix_us":1787932602411241}
{"message":"{\"data\":{\"id\":2044303882186762,\"id_str\":\"2044303882186762\",\"order_type\":0,\"order_subtype\":5,\"datetime\":\"1787932602\",\"microtimestamp\":\"1787932602373000\",\"amount\":1.27888333,\"amount_str\":\"1.27888333\",\"amount_traded\":\"0\",\"amount_at_create\":\"1.27888333\",\"price\":78193.21,\"price_str\":\"78193.21\",\"is_liquidation\":false},\"channel\":\"live_orders_btcusd\",\"event\":\"order_deleted\",\"event_id\":\"00065a1d-7fa5-9388-0001-000102000020\",\"pre_event_id\":\"00065a1d-7fa5-9388-0000-000101000020\",\"order_source\":\"orderbook\"}","recorded_unix_us":1787932602411271}
{"message":"{\"data\":{\"id\":2044303883124746,\"id_str\":\"2044303883124746\",\"order_type\":1,\"order_subtype\":5,\"datetime\":\"1787932602\",\"microtimestamp\":\"1787932602374000\",\"amount\":0.06310787,\"amount_str\":\"0.06310787\",\"amount_traded\":\"0\",\"amount_at_create\":\"0.06310787\",\"price\":78522.39,\"price_str\":\"78522.39\",\"is_liquidation\":false},\"channel\":\"live_orders_btcusd\",\"event\":\"order_created\",\"event_id\":\"00065a1d-7fa5-9770-0000-000103000020\",\"pre_event_id\":\"00065a1d-7fa5-9388-0001-000102000020\",\"order_source\":\"orderbook\"}","recorded_unix_us":1787932602411362}
{"message":"{\"data\":{\"id\":2044303883124746,\"id_str\":\"2044303883124746\",\"order_type\":1,\"order_subtype\":5,\"datetime\":\"1787932602\",\"microtimestamp\":\"1787932602374000\",\"amount\":0.06310787,\"amount_str\":\"0.06310787\",\"amount_traded\":\"0\",\"amount_at_create\":\"0.06310787\",\"price\":78522.39,\"price_str\":\"78522.39\",\"is_liquidation\":false},\"channel\":\"live_orders_btcusd\",\"event\":\"order_deleted\",\"event_id\":\"00065a1d-7fa5-9770-0001-000100000020\",\"pre_event_id\":\"00065a1d-7fa5-9770-0000-000103000020\",\"order_source\":\"orderbook\"}","recorded_unix_us":1787932602411452}
{"message":"{\"data\":{\"id\":2044303883177995,\"id_str\":\"2044303883177995\",\"order_type\":0,\"order_subtype\":5,\"datetime\":\"1787932602\",\"microtimestamp\":\"1787932602387000\",\"amount\":0.00140266,\"amount_str\":\"0.00140266\",\"amount_traded\":\"0\",\"amount_at_create\":\"0.00140266\",\"price\":70668.36,\"price_str\":\"70668.36\",\"is_liquidation\":false},\"channel\":\"live_orders_btcusd\",\"event\":\"order_created\",\"event_id\":\"00065a1d-7fa5-ca38-0000-000101000020\",\"pre_event_id\":\"00065a1d-7fa5-9770-0001-000100000020\",\"order_source\":\"orderbook\"}","recorded_unix_us":1787932602430732}
{"message":"{\"data\":{\"id\":2044303883182091,\"id_str\":\"2044303883182091\",\"order_type\":1,\"order_subtype\":5,\"datetime\":\"1787932602\",\"microtimestamp\":\"1787932602388000\",\"amount\":0.1,\"amount_str\":\"0.10000000\",\"amount_traded\":\"0\",\"amount_at_create\":\"0.10000000\",\"price\":78522.63,\"price_str\":\"78522.63\",\"is_liquidation\":false},\"channel\":\"live_orders_btcusd\",\"event\":\"order_created\",\"event_id\":\"00065a1d-7fa5-ce20-0000-000102000020\",\"pre_event_id\":\"00065a1d-7fa5-ca38-0000-000101000020\",\"order_source\":\"orderbook\"}","recorded_unix_us":1787932602430822}
{"message":"{\"data\":{\"id\":2044303883182091,\"id_str\":\"2044303883182091\",\"order_type\":1,\"order_subtype\":5,\"datetime\":\"1787932602\",\"microtimestamp\":\"1787932602388000\",\"amount\":0.1,\"amount_str\":\"0.10000000\",\"amount_traded\":\"0\",\"amount_at_create\":\"0.10000000\",\"price\":78522.63,\"price_str\":\"78522.63\",\"is_liquidation\":false},\"channel\":\"live_orders_btcusd\",\"event\":\"order_deleted\",\"event_id\":\"00065a1d-7fa5-ce20-0001-000103000020\",\"pre_event_id\":\"00065a1d-7fa5-ce20-0000-000102000020\",\"order_source\":\"orderbook\"}","recorded_unix_us":1787932602430914}
{"message":"{\"data\":{\"id\":2044303882854404,\"id_str\":\"2044303882854404\",\"order_type\":0,\"order_subtype\":5,\"datetime\":\"1787932602\",\"microtimestamp\":\"1787932602398000\",\"amount\":0.00140266,\"amount_str\":\"0.00140266\",\"amount_traded\":\"0\",\"amount_at_create\":\"0.00140266\",\"price\":70668.36,\"price_str\":\"70668.36\",\"is_liquidation\":false},\"channel\":\"live_orders_btcusd\",\"event\":\"order_deleted\",\"event_id\":\"00065a1d-7fa5-f530-0000-000100000020\",\"pre_event_id\":\"00065a1d-7fa5-ce20-0001-000103000020\",\"order_source\":\"orderbook\"}","recorded_unix_us":1787932602448149}
{"message":"{\"data\":{\"id\":2044303883177995,\"id_str\":\"2044303883177995\",\"order_type\":0,\"order_subtype\":5,\"datetime\":\"1787932602\",\"microtimestamp\":\"1787932602398000\",\"amount\":0.00140266,\"amount_str\":\"0.00140266\",\"amount_traded\":\"0\",\"amount_at_create\":\"0.00140266\",\"price\":70668.36,\"price_str\":\"70668.36\",\"is_liquidation\":false},\"channel\":\"live_orders_btcusd\",\"event\":\"order_deleted\",\"event_id\":\"00065a1d-7fa5-f530-0001-000101000020\",\"pre_event_id\":\"00065a1d-7fa5-f530-0000-000100000020\",\"order_source\":\"orderbook\"}","recorded_unix_us":1787932602484945}
{"message":"{\"data\":{\"id\":2044303882530818,\"id_str\":\"2044303882530818\",\"order_type\":0,\"order_subtype\":5,\"datetime\":\"1787932602\",\"microtimestamp\":\"1787932602398000\",\"amount\":0.00140266,\"amount_str\":\"0.00140266\",\"amount_traded\":\"0\",\"amount_at_create\":\"0.00140266\",\"price\":70668.36,\"price_str\":\"70668.36\",\"is_liquidation\":false},\"channel\":\"live_orders_btcusd\",\"event\":\"order_deleted\",\"event_id\":\"00065a1d-7fa5-f530-0002-000102000020\",\"pre_event_id\":\"00065a1d-7fa5-f530-0001-000101000020\",\"order_source\":\"orderbook\"}","recorded_unix_us":1787932602485157}
{"message":"{\"data\":{\"id\":2044303617581071,\"id_str\":\"2044303617581071\",\"order_type\":0,\"order_subtype\":5,\"datetime\":\"1787932602\",\"microtimestamp\":\"1787932602399000\",\"amount\":0.5062,\"amount_str\":\"0.506200\",\"amount_traded\":\"0\",\"amount_at_create\":\"0.506200\",\"price\":2476.66,\"price_str\":\"2476.66\",\"is_liquidation\":false},\"channel\":\"live_orders_ethusd\",\"event\":\"order_deleted\",\"event_id\":\"00065a1d-7fa5-f918-0000-001200000020\",\"pre_event_id\":\"00065a1d-7fa5-83e8-0001-001203000020\",\"order_source\":\"orderbook\"}","recorded_unix_us":1787932602485424}
{"message":"{\"data\":{\"id\":2044303876309017,\"id_str\":\"2044303876309017\",\"order_type\":1,\"order_subtype\":5,\"datetime\":\"1787932602\",\"microtimestamp\":\"1787932602400000\",\"amount\":0.5062,\"amount_str\":\"0.506200\",\"amount_traded\":\"0\",\"amount_at_create\":\"0.506200\",\"price\":2482.58,\"price_str\":\"2482.58\",\"is_liquidation\":false},\"channel\":\"live_orders_ethusd\",\"event\":\"order_deleted\",\"event_id\":\"00065a1d-7fa5-fd00-0000-001201000020\",\"pre_event_id\":\"00065a1d-7fa5-f918-0000-001200000020\",\"order_source\":\"orderbook\"}","recorded_unix_us":1787932602485469}
{"message":"{\"data\":{\"id\":2044303881531399,\"id_str\":\"2044303881531399\",\"order_type\":1,\"order_subtype\":5,\"datetime\":\"1787932602\",\"microtimestamp\":\"1787932602403000\",\"amount\":0.6044871,\"amount_str\":\"0.60448710\",\"amount_traded\":\"0\",\"amount_at_create\":\"0.60448710\",\"price\":0.03160362,\"price_str\":\"0.03160362\",\"is_liquidation\":false},\"channel\":\"live_orders_ethbtc\",\"event\":\"order_deleted\",\"event_id\":\"00065a1d-7fa6-08b8-0000-001100000020\",\"pre_event_id\":\"00065a1d-7fa3-a758-0000-001103000020\",\"order_source\":\"orderbook\"}","recorded_unix_us":1787932602485556}
{"message":"{\"data\":{\"id\":2044303881543680,\"id_str\":\"2044303881543680\",\"order_type\":1,\"order_subtype\":5,\"datetime\":\"1787932602\",\"microtimestamp\":\"1787932602403000\",\"amount\":1.007365,\"amount_str\":\"1.00736500\",\"amount_traded\":\"0\",\"amount_at_create\":\"1.00736500\",\"price\":0.03160719,\"price_str\":\"0.03160719\",\"is_liquidation\":false},\"channel\":\"live_orders_ethbtc\",\"event\":\"order_deleted\",\"event_id\":\"00065a1d-7fa6-08b8-0001-001101000020\",\"pre_event_id\":\"00065a1d-7fa6-08b8-0000-001100000020\",\"order_source\":\"orderbook\"}","recorded_unix_us":1787932602485841}
{"message":"{\"data\":{\"id\":2044303881547776,\"id_str\":\"2044303881547776\",\"order_type\":1,\"order_subtype\":5,\"datetime\":\"1787932602\",\"microtimestamp\":\"1787932602403000\",\"amount\":2.01406611,\"amount_str\":\"2.01406611\",\"amount_traded\":\"0\",\"amount_at_create\":\"2.01406611\",\"price\":0.0316176,\"price_str\":\"0.03161760\",\"is_liquidation\":false},\"channel\":\"live_orders_ethbtc\",\"event\":\"order_deleted\",\"event_id\":\"00065a1d-7fa6-08b8-0002-001102000020\",\"pre_event_id\":\"00065a1d-7fa6-08b8-0001-001101000020\",\"order_source\":\"orderbook\"}","recorded_unix_us":1787932602485894}
{"message":"{\"data\":{\"id\":2044303881560074,\"id_str\":\"2044303881560074\",\"order_type\":1,\"order_subtype\":5,\"datetime\":\"1787932602\",\"microtimestamp\":\"1787932602404000\",\"amount\":4.02232075,\"amount_str\":\"4.02232075\",\"amount_traded\":\"0\",\"amount_at_create\":\"4.02232075\",\"price\":0.03165997,\"price_str\":\"0.03165997\",\"is_liquidation\":false},\"channel\":\"live_orders_ethbtc\",\"event\":\"order_deleted\",\"event_id\":\"00065a1d-7fa6-0ca0-0000-001103000020\",\"pre_event_id\":\"00065a1d-7fa6-08b8-0002-001102000020\",\"order_source\":\"orderbook\"}","recorded_unix_us":1787932602485924}
{"message":"{\"data\":{\"id\":2044303881768960,\"id_str\":\"2044303881768960\",\"order_type\":1,\"order_subtype\":5,\"datetime\":\"1787932602\",\"microtimestamp\":\"1787932602404000\",\"amount\":3.02055629,\"amount_str\":\"3.02055629\",\"amount_traded\":\"0\",\"amount_at_create\":\"3.02055629\",\"price\":0.03162186,\"price_str\":\"0.03162186\",\"is_liquidation\":false},\"channel\":\"live_orders_ethbtc\",\"event\":\"order_deleted\",\"event_id\":\"00065a1d-7fa6-0ca0-0001-001100000020\",\"pre_event_id\":\"00065a1d-7fa6-0ca0-0000-001103000020\",\"order_source\":\"orderbook\"}","recorded_unix_us":1787932602485953}
{"message":"{\"data\":{\"id\":2044303881768966,\"id_str\":\"2044303881768966\",\"order_type\":0,\"order_subtype\":5,\"datetime\":\"1787932602\",\"microtimestamp\":\"1787932602404000\",\"amount\":0.60475617,\"amount_str\":\"0.60475617\",\"amount_traded\":\"0\",\"amount_at_create\":\"0.60475617\",\"price\":0.03158982,\"price_str\":\"0.03158982\",\"is_liquidation\":false},\"channel\":\"live_orders_ethbtc\",\"event\":\"order_deleted\",\"event_id\":\"00065a1d-7fa6-0ca0-0002-001101000020\",\"pre_event_id\":\"00065a1d-7fa6-0ca0-0001-001100000020\",\"order_source\":\"orderbook\"}","recorded_unix_us":1787932602485980}
{"message":"{\"data\":{\"id\":2044303881773058,\"id_str\":\"2044303881773058\",\"order_type\":0,\"order_subtype\":5,\"datetime\":\"1787932602\",\"microtimestamp\":\"1787932602405000\",\"amount\":1.00801353,\"amount_str\":\"1.00801353\",\"amount_traded\":\"0\",\"amount_at_create\":\"1.00801353\",\"price\":0.03158534,\"price_str\":\"0.03158534\",\"is_liquidation\":false},\"channel\":\"live_orders_ethbtc\",\"event\":\"order_deleted\",\"event_id\":\"00065a1d-7fa6-1088-0000-001102000020\",\"pre_event_id\":\"00065a1d-7fa6-0ca0-0002-001101000020\",\"order_source\":\"orderbook\"}","recorded_unix_us":1787932602486212}
{"message":"{\"data\":{\"id\":2044303881773063,\"id_str\":\"2044303881773063\",\"order_type\":0,\"order_subtype\":5,\"datetime\":\"1787932602\",\"microtimestamp\":\"1787932602405000\",\"amount\":2.01629689,\"amount_str\":\"2.01629689\",\"amount_traded\":\"0\",\"amount_at_create\":\"2.01629689\",\"price\":0.03157941,\"price_str\":\"0.03157941\",\"is_liquidation\":false},\"channel\":\"live_orders_ethbtc\",\"event\":\"order_deleted\",\"event_id\":\"00065a1d-7fa6-1088-0001-001103000020\",\"pre_event_id\":\"00065a1d-7fa6-1088-0000-001102000020\",\"order_source\":\"orderbook\"}","recorded_unix_us":1787932602486265}
{"message":"{\"data\":{\"id\":2044303881777153,\"id_str\":\"2044303881777153\",\"order_type\":0,\"order_subtype\":5,\"datetime\":\"1787932602\",\"microtimestamp\":\"1787932602405000\",\"amount\":3.02537254,\"amount_str\":\"3.02537254\",\"amount_traded\":\"0\",\"amount_at_create\":\"3.02537254\",\"price\":0.03156999,\"price_str\":\"0.03156999\",\"is_liquidation\":false},\"channel\":\"live_orders_ethbtc\",\"event\":\"order_deleted\",\"event_id\":\"00065a1d-7fa6-1088-0002-001100000020\",\"pre_event_id\":\"00065a1d-7fa6-1088-0001-001103000020\",\"order_source\":\"orderbook\"}","recorded_unix_us":1787932602486301}
{"message":"{\"data\":{\"id\":2044303881785349,\"id_str\":\"2044303881785349\",\"order_type\":0,\"order_subtype\":5,\"datetime\":\"1787932602\",\"microtimestamp\":\"1787932602406000\",\"amount\":4.03662068,\"amount_str\":\"4.03662068\",\"amount_traded\":\"0\",\"amount_at_create\":\"4.03662068\",\"price\":0.03154857,\"price_str\":\"0.03154857\",\"is_liquidation\":false},\"channel\":\"live_orders_ethbtc\",\"event\":\"order_deleted\",\"event_id\":\"00065a1d-7fa6-1470-0000-001101000020\",\"pre_event_id\":\"00065a1d-7fa6-1088-0002-001100000020\",\"order_source\":\"orderbook\"}","recorded_unix_us":1787932602486332}
{"message":"{\"data\":{\"id\":2044303883259907,\"id_str\":\"2044303883259907\",\"order_type\":1,\"order_subtype\":5,\"datetime\":\"1787932602\",\"microtimestamp\":\"1787932602406000\",\"amount\":0.1,\"amount_str\":\"0.10000000\",\"amount_traded\":\"0\",\"amount_at_create\":\"0.10000000\",\"price\":78522.62,\"price_str\":\"78522.62\",\"is_liquidation\":false},\"channel\":\"live_orders_btcusd\",\"event\":\"order_created\",\"event_id\":\"00065a1d-7fa6-1470-0000-000103000020\",\"pre_event_id\":\"00065a1d-7fa5-f530-0002-000102000020\",\"order_source\":\"orderbook\"}","recorded_unix_us":1787932602486445}
{"message":"{\"data\":{\"id\":2044303883259907,\"id_str\":\"2044303883259907\",\"order_type\":1,\"order_subtype\":5,\"datetime\":\"1787932602\",\"microtimestamp\":\"1787932602406000\",\"amount\":0.1,\"amount_str\":\"0.10000000\",\"amount_traded\":\"0\",\"amount_at_create\":\"0.10000000\",\"price\":78522.62,\"price_str\":\"78522.62\",\"is_liquidation\":false},\"channel\":\"live_orders_btcusd\",\"event\":\"order_deleted\",\"event_id\":\"00065a1d-7fa6-1470-0001-000100000020\",\"pre_event_id\":\"00065a1d-7fa6-1470-0000-000103000020\",\"order_source\":\"orderbook\"}","recorded_unix_us":1787932602486570}
{"message":"{\"data\":{\"id\":2044303883264008,\"id_str\":\"2044303883264008\",\"order_type\":1,\"order_subtype\":5,\"datetime\":\"1787932602\",\"microtimestamp\":\"1787932602408000\",\"amount\":0.06310787,\"amount_str\":\"0.06310787\",\"amount_traded\":\"0\",\"amount_at_create\":\"0.06310787\",\"price\":78520.1,\"price_str\":\"78520.10\",\"is_liquidation\":false},\"channel\":\"live_orders_btcusd\",\"event\":\"order_created\",\"event_id\":\"00065a1d-7fa6-1c40-0000-000101000020\",\"pre_event_id\":\"00065a1d-7fa6-1470-0001-000100000020\",\"order_source\":\"orderbook\"}","recorded_unix_us":1787932602486677}
{"message":"{\"data\":{\"id\":2044303883264008,\"id_str\":\"2044303883264008\",\"order_type\":1,\"order_subtype\":5,\"datetime\":\"1787932602\",\"microtimestamp\":\"1787932602408000\",\"amount\":0.06310787,\"amount_str\":\"0.06310787\",\"amount_traded\":\"0\",\"amount_at_create\":\"0.06310787\",\"price\":78520.1,\"price_str\":\"78520.10\",\"is_liquidation\":false},\"channel\":\"live_orders_btcusd\",\"event\":\"order_deleted\",\"event_id\":\"00065a1d-7fa6-1c40-0001-000102000020\",\"pre_event_id\":\"00065a1d-7fa6-1c40-0000-000101000020\",\"order_source\":\"orderbook\"}","recorded_unix_us":1787932602486775}
{"message":"{\"data\":{\"id\":2044303883268098,\"id_str\":\"2044303883268098\",\"order_type\":1,\"order_subtype\":5,\"datetime\":\"1787932602\",\"microtimestamp\":\"1787932602408000\",\"amount\":0.06310787,\"amount_str\":\"0.06310787\",\"amount_traded\":\"0\",\"amount_at_create\":\"0.06310787\",\"price\":78522.46,\"price_str\":\"78522.46\",\"is_liquidation\":false},\"channel\":\"live_orders_btcusd\",\"event\":\"order_created\",\"event_id\":\"00065a1d-7fa6-1c40-0002-000103000020\",\"pre_event_id\":\"00065a1d-7fa6-1c40-0001-000102000020\",\"order_source\":\"orderbook\"}","recorded_unix_us":1787932602486866}
{"message":"{\"data\":{\"id\":2044303883268098,\"id_str\":\"2044303883268098\",\"order_type\":1,\"order_subtype\":5,\"datetime\":\"1787932602\",\"microtimestamp\":\"1787932602408000\",\"amount\":0.06310787,\"amount_str\":\"0.06310787\",\"amount_traded\":\"0\",\"amount_at_create\":\"0.06310787\",\"price\":78522.46,\"price_str\":\"78522.46\",\"is_liquidation\":false},\"channel\":\"live_orders_btcusd\",\"event\":\"order_deleted\",\"event_id\":\"00065a1d-7fa6-1c40-0003-000100000020\",\"pre_event_id\":\"00065a1d-7fa6-1c40-0002-000103000020\",\"order_source\":\"orderbook\"}","recorded_unix_us":1787932602486951}
{"message":"{\"data\":{\"id\":2044303816470529,\"id_str\":\"2044303816470529\",\"order_type\":0,\"order_subtype\":5,\"datetime\":\"1787932602\",\"microtimestamp\":\"1787932602415000\",\"amount\":6.985269,\"amount_str\":\"6.985269\",\"amount_traded\":\"0\",\"amount_at_create\":\"6.985269\",\"price\":2477.88,\"price_str\":\"2477.88\",\"is_liquidation\":false},\"channel\":\"live_orders_ethusd\",\"event\":\"order_deleted\",\"event_id\":\"00065a1d-7fa6-3798-0000-001202000020\",\"pre_event_id\":\"00065a1d-7fa5-fd00-0000-001201000020\",\"order_source\":\"orderbook\"}","recorded_unix_us":1787932602487508}
{"message":"{\"data\":{\"id\":2044303883321354,\"id_str\":\"2044303883321354\",\"order_type\":1,\"order_subtype\":5,\"datetime\":\"1787932602\",\"microtimestamp\":\"1787932602422000\",\"amount\":0.1,\"amount_str\":\"0.10000000\",\"amount_traded\":\"0\",\"amount_at_create\":\"0.10000000\",\"price\":78522.63,\"price_str\":\"78522.63\",\"is_liquidation\":false},\"channel\":\"live_orders_btcusd\",\"event\":\"order_created\",\"event_id\":\"00065a1d-7fa6-52f0-0000-000101000020\",\"pre_event_id\":\"00065a1d-7fa6-1c40-0003-000100000020\",\"order_source\":\"orderbook\"}","recorded_unix_us":1787932602487548}
{"message":"{\"data\":{\"id\":2044303883321354,\"id_str\":\"2044303883321354\",\"order_type\":1,\"order_subtype\":5,\"datetime\":\"1787932602\",\"microtimestamp\":\"1787932602422000\",\"amount\":0.1,\"amount_str\":\"0.10000000\",\"amount_traded\":\"0\",\"amount_at_create\":\"0.10000000\",\"price\":78522.63,\"price_str\":\"78522.63\",\"is_liquidation\":false},\"channel\":\"live_orders_btcusd\",\"event\":\"order_deleted\",\"event_id\":\"00065a1d-7fa6-52f0-0001-000102000020\",\"pre_event_id\":\"00065a1d-7fa6-52f0-0000-000101000020\",\"order_source\":\"orderbook\"}","recorded_unix_us":1787932602553927}
{"message":"{\"data\":{\"id\":2044303882899463,\"id_str\":\"2044303882899463\",\"order_type\":0,\"order_subtype\":5,\"datetime\":\"1787932602\",\"microtimestamp\":\"1787932602426000\",\"amount\":0.403089,\"amount_str\":\"0.403089\",\"amount_traded\":\"0\",\"amount_at_create\":\"0.403089\",\"price\":2480.07,\"price_str\":\"2480.07\",\"is_liquidation\":false},\"channel\":\"live_orders_ethusd\",\"event\":\"order_deleted\",\"event_id\":\"00065a1d-7fa6-6290-0000-001203000020\",\"pre_event_id\":\"00065a1d-7fa6-3798-0000-001202000020\",\"order_source\":\"orderbook\"}","recorded_unix_us":1787932602554398}
{"message":"{\"data\":{\"id\":2044303883350020,\"id_str\":\"2044303883350020\",\"order_type\":0,\"order_subtype\":0,\"datetime\":\"1787932602\",\"microtimestamp\":\"1787932602428000\",\"amount\":0.00006631,\"amount_str\":\"0.00006631\",\"amount_traded\":\"0\",\"amount_at_create\":\"0.00006631\",\"price\":76167,\"price_str\":\"76167.00\",\"is_liquidation\":false},\"channel\":\"live_orders_btcusd\",\"event\":\"order_created\",\"event_id\":\"00065a1d-7fa6-6a60-0000-000103000020\",\"pre_event_id\":\"00065a1d-7fa6-52f0-0001-000102000020\",\"order_source\":\"orderbook\"}","recorded_unix_us":1787932602554572}
{"message":"{\"data\":{\"id\":2044303883358220,\"id_str\":\"2044303883358220\",\"order_type\":0,\"order_subtype\":5,\"datetime\":\"1787932602\",\"microtimestamp\":\"1787932602431000\",\"amount\":7.967962,\"amount_str\":\"7.967962\",\"amount_traded\":\"0\",\"amount_at_create\":\"7.967962\",\"price\":2476.96,\"price_str\":\"2476.96\",\"is_liquidation\":false},\"channel\":\"live_orders_ethusd\",\"event\":\"order_created\",\"event_id\":\"00065a1d-7fa6-7618-0000-001200000020\",\"pre_event_id\":\"00065a1d-7fa6-6290-0000-001203000020\",\"order_source\":\"orderbook\"}","recorded_unix_us":1787932602554727}
{"message":"{\"data\":{\"id\":2044303883362316,\"id_str\":\"2044303883362316\",\"order_type\":1,\"order_subtype\":5,\"datetime\":\"1787932602\",\"microtimestamp\":\"1787932602432000\",\"amount\":1.27113313,\"amount_str\":\"1.27113313\",\"amount_traded\":\"0\",\"amount_at_create\":\"1.27113313\",\"price\":78669.97,\"price_str\":\"78669.97\",\"is_liquidation\":false},\"channel\":\"live_orders_btcusd\",\"event\":\"order_created\",\"event_id\":\"00065a1d-7fa6-7a00-0000-000100000020\",\"pre_event_id\":\"00065a1d-7fa6-6a60-0000-000103000020\",\"order_source\":\"orderbook\"}","recorded_unix_us":1787932602554861}
{"message":"{\"data\":{\"id\":2044303883374610,\"id_str\":\"2044303883374610\",\"order_type\":0,\"order_subtype\":5,\"datetime\":\"1787932602\",\"microtimestamp\":\"1787932602435000\",\"amount\":0.403094,\"amount_str\":\"0.403094\",\"amount_traded\":\"0\",\"amount_at_create\":\"0.403094\",\"price\":2480.02,\"price_str\":\"2480.02\",\"is_liquidation\":false},\"channel\":\"live_orders_ethusd\",\"event\":\"order_created\",\"event_id\":\"00065a1d-7fa6-85b8-0000-001201000020\",\"pre_event_id\":\"00065a1d-7fa6-7618-0000-001200000020\",\"order_source\":\"orderbook\"}","recorded_unix_us":1787932602554990}
{"message":"{\"data\":{\"id\":2044303883390996,\"id_str\":\"2044303883390996\",\"order_type\":1,\"order_subtype\":5,\"datetime\":\"1787932602\",\"microtimestamp\":\"1787932602439000\",\"amount\":0.1,\"amount_str\":\"0.10000000\",\"amount_traded\":\"0\",\"amount_at_create\":\"0.10000000\",\"price\":78522.62,\"price_str\":\"78522.62\",\"is_liquidation\":false},\"channel\":\"live_orders_btcusd\",\"event\":\"order_created\",\"event_id\":\"00065a1d-7fa6-9558-0000-000101000020\",\"pre_event_id\":\"00065a1d-7fa6-7a00-0000-000100000020\",\"order_source\":\"orderbook\"}","recorded_unix_us":1787932602555128}
{"message":"{\"data\":{\"id\":2044303883390996,\"id_str\":\"2044303883390996\",\"order_type\":1,\"order_subtype\":5,\"datetime\":\"1787932602\",\"microtimestamp\":\"1787932602439000\",\"amount\":0.1,\"amount_str\":\"0.10000000\",\"amount_traded\":\"0\",\"amount_at_create\":\"0.10000000\",\"price\":78522.62,\"price_str\":\"78522.62\",\"is_liquidation\":false},\"channel\":\"live_orders_btcusd\",\"event\":\"order_deleted\",\"event_id\":\"00065a1d-7fa6-9558-0001-000102000020\",\"pre_event_id\":\"00065a1d-7fa6-9558-0000-000101000020\",\"order_source\":\"orderbook\"}","recorded_unix_us":1787932602555245}
{"message":"{\"data\":{\"id\":2044303883395093,\"id_str\":\"2044303883395093\",\"order_type\":1,\"order_subtype\":5,\"datetime\":\"1787932602\",\"microtimestamp\":\"1787932602439000\",\"amount\":0.06310787,\"amount_str\":\"0.06310787\",\"amount_traded\":\"0\",\"amount_at_create\":\"0.06310787\",\"price\":78520.3,\"price_str\":\"78520.30\",\"is_liquidation\":false},\"channel\":\"live_orders_btcusd\",\"event\":\"order_created\",\"event_id\":\"00065a1d-7fa6-9558-0002-000103000020\",\"pre_event_id\":\"00065a1d-7fa6-9558-0001-000102000020\",\"order_source\":\"orderbook\"}","recorded_unix_us":1787932602555355}
{"message":"{\"data\":{\"id\":2044303883395093,\"id_str\":\"2044303883395093\",\"order_type\":1,\"order_subtype\":5,\"datetime\":\"1787932602\",\"microtimestamp\":\"1787932602439000\",\"amount\":0.06310787,\"amount_str\":\"0.06310787\",\"amount_traded\":\"0\",\"amount_at_create\":\"0.06310787\",\"price\":78520.3,\"price_str\":\"78520.30\",\"is_liquidation\":false},\"channel\":\"live_orders_btcusd\",\"event\":\"order_deleted\",\"event_id\":\"00065a1d-7fa6-9558-0003-000100000020\",\"pre_event_id\":\"00065a1d-7fa6-9558-0002-000103000020\",\"order_source\":\"orderbook\"}","recorded_unix_us":1787932602555459}
{"message":"{\"data\":{\"id\":2044303883411464,\"id_str\":\"2044303883411464\",\"order_type\":1,\"order_subtype\":4,\"datetime\":\"1787932602\",\"microtimestamp\":\"1787932602443000\",\"amount\":0.00006244,\"amount_str\":\"0.00006244\",\"amount_traded\":\"0\",\"amount_at_create\":\"0.00006244\",\"price\":80878,\"price_str\":\"80878.00\",\"is_liquidation\":false},\"channel\":\"live_orders_btcusd\",\"event\":\"order_created\",\"event_id\":\"00065a1d-7fa6-a4f8-0000-000101000020\",\"pre_event_id\":\"00065a1d-7fa6-9558-0003-000100000020\",\"order_source\":\"orderbook\"}","recorded_unix_us":1787932602555605}
{"message":"{\"data\":{\"id\":2044303883411464,\"id_str\":\"2044303883411464\",\"order_type\":1,\"order_subtype\":4,\"datetime\":\"1787932602\",\"microtimestamp\":\"1787932602443000\",\"amount\":0.00006244,\"amount_str\":\"0.00006244\",\"amount_traded\":\"0\",\"amount_at_create\":\"0.00006244\",\"price\":80878,\"price_str\":\"80878.00\",\"is_liquidation\":false},\"channel\":\"live_orders_btcusd\",\"event\":\"order_deleted\",\"event_id\":\"00065a1d-7fa6-a4f8-0001-000102000020\",\"pre_event_id\":\"00065a1d-7fa6-a4f8-0000-000101000020\",\"order_source\":\"orderbook\"}","recorded_unix_us":1787932602555649}
{"message":"{\"data\":{\"id\":2044303883431937,\"id_str\":\"2044303883431937\",\"order_type\":1,\"order_subtype\":5,\"datetime\":\"1787932602\",\"microtimestamp\":\"1787932602448000\",\"amount\":0.6044871,\"amount_str\":\"0.60448710\",\"amount_traded\":\"0\",\"amount_at_create\":\"0.60448710\",\"price\":0.03160362,\"price_str\":\"0.03160362\",\"is_liquidation\":false},\"channel\":\"live_orders_ethbtc\",\"event\":\"order_created\",\"event_id\":\"00065a1d-7fa6-b880-0000-001102000020\",\"pre_event_id\":\"00065a1d-7fa6-1470-0000-001101000020\",\"order_source\":\"orderbook\"}","recorded_unix_us":1787932602555762}
{"message":"{\"data\":{\"id\":2044303883464718,\"id_str\":\"2044303883464718\",\"order_type\":1,\"order_subtype\":5,\"datetime\":\"1787932602\",\"microtimestamp\":\"1787932602457000\",\"amount\":0.1,\"amount_str\":\"0.10000000\",\"amount_traded\":\"0\",\"amount_at_create\":\"0.10000000\",\"price\":78522.63,\"price_str\":\"78522.63\",\"is_liquidation\":false},\"channel\":\"live_orders_btcusd\",\"event\":\"order_created\",\"event_id\":\"00065a1d-7fa6-dba8-0000-000103000020\",\"pre_event_id\":\"00065a1d-7fa6-a4f8-0001-000102000020\",\"order_source\":\"orderbook\"}","recorded_unix_us":1787932602555867}
{"message":"{\"data\":{\"id\":2044303883464718,\"id_str\":\"2044303883464718\",\"order_type\":1,\"order_subtype\":5,\"datetime\":\"1787932602\",\"microtimestamp\":\"1787932602457000\",\"amount\":0.1,\"amount_str\":\"0.10000000\",\"amount_traded\":\"0\",\"amount_at_create\":\"0.10000000\",\"price\":78522.63,\"price_str\":\"78522.63\",\"is_liquidation\":false},\"channel\":\"live_orders_btcusd\",\"event\":\"order_deleted\",\"event_id\":\"00065a1d-7fa6-dba8-0001-000100000020\",\"pre_event_id\":\"00065a1d-7fa6-dba8-0000-000103000020\",\"order_source\":\"orderbook\"}","recorded_unix_us":1787932602555971}
{"message":"{\"data\":{\"id\":2044303883493384,\"id_str\":\"2044303883493384\",\"order_type\":1,\"order_subtype\":5,\"datetime\":\"1787932602\",\"microtimestamp\":\"1787932602463000\",\"amount\":1.007365,\"amount_str\":\"1.00736500\",\"amount_traded\":\"0\",\"amount_at_create\":\"1.00736500\",\"price\":0.03160719,\"price_str\":\"0.03160719\",\"is_liquidation\":false},\"channel\":\"live_orders_ethbtc\",\"event\":\"order_created\",\"event_id\":\"00065a1d-7fa6-f318-0000-001103000020\",\"pre_event_id\":\"00065a1d-7fa6-b880-0000-001102000020\",\"order_source\":\"orderbook\"}","recorded_unix_us":1787932602556103}
{"message":"{\"data\":{\"id\":2044303883497482,\"id_str\":\"2044303883497482\",\"order_type\":1,\"order_subtype\":5,\"datetime\":\"1787932602\",\"microtimestamp\":\"1787932602465000\",\"amount\":2.01406611,\"amount_str\":\"2.01406611\",\"amount_traded\":\"0\",\"amount_at_create\":\"2.01406611\",\"price\":0.0316176,\"price_str\":\"0.03161760\",\"is_liquidation\":false},\"channel\":\"live_orders_ethbtc\",\"event\":\"order_created\",\"event_id\":\"00065a1d-7fa6-fae8-0000-001100000020\",\"pre_event_id\":\"00065a1d-7fa6-f318-0000-001103000020\",\"order_source\":\"orderbook\"}","recorded_unix_us":1787932602556221}
{"message":"{\"data\":{\"id\":2044303883501577,\"id_str\":\"2044303883501577\",\"order_type\":0,\"order_subtype\":5,\"datetime\":\"1787932602\",\"microtimestamp\":\"1787932602466000\",\"amount\":0.00140266,\"amount_str\":\"0.00140266\",\"amount_traded\":\"0\",\"amount_at_create\":\"0.00140266\",\"price\":70666.76,\"price_str\":\"70666.76\",\"is_liquidation\":false},\"channel\":\"live_orders_btcusd\",\"event\":\"order_created\",\"event_id\":\"00065a1d-7fa6-fed0-0000-000101000020\",\"pre_event_id\":\"00065a1d-7fa6-dba8-0001-000100000020\",\"order_source\":\"orderbook\"}","recorded_unix_us":1787932602556358}
{"message":"{\"data\":{\"id\":2044303883501576,\"id_str\":\"2044303883501576\",\"order_type\":1,\"order_subtype\":5,\"datetime\":\"1787932602\",\"microtimestamp\":\"1787932602466000\",\"amount\":3.02055629,\"amount_str\":\"3.02055629\",\"amount_traded\":\"0\",\"amount_at_create\":\"3.02055629\",\"price\":0.03162186,\"price_str\":\"0.03162186\",\"is_liquidation\":false},\"channel\":\"live_orders_ethbtc\",\"event\":\"order_created\",\"event_id\":\"00065a1d-7fa6-fed0-0000-001101000020\",\"pre_event_id\":\"00065a1d-7fa6-fae8-0000-001100000020\",\"order_source\":\"orderbook\"}","recorded_unix_us":1787932602556465}
{"message":"{\"data\":{\"id\":2044303883505675,\"id_str\":\"2044303883505675\",\"order_type\":0,\"order_subtype\":5,\"datetime\":\"1787932602\",\"microtimestamp\":\"1787932602467000\",\"amount\":0.60475617,\"amount_str\":\"0.60475617\",\"amount_traded\":\"0\",\"amount_at_create\":\"0.60475617\",\"price\":0.03158982,\"price_str\":\"0.03158982\",\"is_liquidation\":false},\"channel\":\"live_orders_ethbtc\",\"event\":\"order_created\",\"event_id\":\"00065a1d-7fa7-02b8-0000-001102000020\",\"pre_event_id\":\"00065a1d-7fa6-fed0-0000-001101000020\",\"order_source\":\"orderbook\"}","recorded_unix_us":1787932602556623}
{"message":"{\"data\":{\"id\":2044303883509763,\"id_str\":\"2044303883509763\",\"order_type\":0,\"order_subtype\":5,\"datetime\":\"1787932602\",\"microtimestamp\":\"1787932602467000\",\"amount\":1.00801353,\"amount_str\":\"1.00801353\",\"amount_traded\":\"0\",\"amount_at_create\":\"1.00801353\",\"price\":0.03158534,\"price_str\":\"0.03158534\",\"is_liquidation\":false},\"channel\":\"live_orders_ethbtc\",\"event\":\"order_created\",\"event_id\":\"00065a1d-7fa7-02b8-0001-001103000020\",\"pre_event_id\":\"00065a1d-7fa7-02b8-0000-001102000020\",\"order_source\":\"orderbook\"}","recorded_unix_us":1787932602556660}
{"message":"{\"data\":{\"id\":2044303883509765,\"id_str\":\"2044303883509765\",\"order_type\":1,\"order_subtype\":5,\"datetime\":\"1787932602\",\"microtimestamp\":\"1787932602467000\",\"amount\":4.02232075,\"amount_str\":\"4.02232075\",\"amount_traded\":\"0\",\"amount_at_create\":\"4.02232075\",\"price\":0.03165997,\"price_str\":\"0.03165997\",\"is_liquidation\":false},\"channel\":\"live_orders_ethbtc\",\"event\":\"order_created\",\"event_id\":\"00065a1d-7fa7-02b8-0002-001100000020\",\"pre_event_id\":\"00065a1d-7fa7-02b8-0001-001103000020\",\"order_source\":\"orderbook\"}","recorded_unix_us":1787932602556763}
{"message":"{\"data\":{\"id\":2044303883513867,\"id_str\":\"2044303883513867\",\"order_type\":1,\"order_subtype\":5,\"datetime\":\"1787932602\",\"microtimestamp\":\"1787932602468000\",\"amount\":0.06310787,\"amount_str\":\"0.06310787\",\"amount_traded\":\"0\",\"amount_at_create\":\"0.06310787\",\"price\":78520.18,\"price_str\":\"78520.18\",\"is_liquidation\":false},\"channel\":\"live_orders_btcusd\",\"event\":\"order_created\",\"event_id\":\"00065a1d-7fa7-06a0-0000-000102000020\",\"pre_event_id\":\"00065a1d-7fa6-fed0-0000-000101000020\",\"order_source\":\"orderbook\"}","recorded_unix_us":1787932602556882}
{"message":"{\"data\":{\"id\":2044303883513867,\"id_str\":\"2044303883513867\",\"order_type\":1,\"order_subtype\":5,\"datetime\":\"1787932602\",\"microtimestamp\":\"1787932602468000\",\"amount\":0.06310787,\"amount_str\":\"0.06310787\",\"amount_traded\":\"0\",\"amount_at_create\":\"0.06310787\",\"price\":78520.18,\"price_str\":\"78520.18\",\"is_liquidation\":false},\"channel\":\"live_orders_btcusd\",\"event\":\"order_deleted\",\"event_id\":\"00065a1d-7fa7-06a0-0001-000103000020\",\"pre_event_id\":\"00065a1d-7fa7-06a0-0000-000102000020\",\"order_source\":\"orderbook\"}","recorded_unix_us":1787932602556981}
{"message":"{\"data\":{\"id\":2044303878725651,\"id_str\":\"2044303878725651\",\"order_type\":0,\"order_subtype\":5,\"datetime\":\"1787932602\",\"microtimestamp\":\"1787932602469000\",\"amount\":0.0025477,\"amount_str\":\"0.00254770\",\"amount_traded\":\"0\",\"amount_at_create\":\"0.00254770\",\"price\":78502.27,\"price_str\":\"78502.27\",\"is_liquidation\":false},\"channel\":\"live_orders_btcusd\",\"event\":\"order_deleted\",\"event_id\":\"00065a1d-7fa7-0a88-0000-000100000020\",\"pre_event_id\":\"00065a1d-7fa7-06a0-0001-000103000020\",\"order_source\":\"orderbook\"}","recorded_unix_us":1787932602557224}
{"message":"{\"data\":{\"id\":2044303883517953,\"id_str\":\"2044303883517953\",\"order_type\":0,\"order_subtype\":5,\"datetime\":\"1787932602\",\"microtimestamp\":\"1787932602469000\",\"amount\":2.01629689,\"amount_str\":\"2.01629689\",\"amount_traded\":\"0\",\"amount_at_create\":\"2.01629689\",\"price\":0.03157941,\"price_str\":\"0.03157941\",\"is_liquidation\":false},\"channel\":\"live_orders_ethbtc\",\"event\":\"order_created\",\"event_id\":\"00065a1d-7fa7-0a88-0000-001101000020\",\"pre_event_id\":\"00065a1d-7fa7-02b8-0002-001100000020\",\"order_source\":\"orderbook\"}","recorded_unix_us":1787932602557259}
{"message":"{\"data\":{\"id\":2044303883517952,\"id_str\":\"2044303883517952\",\"order_type\":1,\"order_subtype\":5,\"datetime\":\"1787932602\",\"microtimestamp\":\"1787932602469000\",\"amount\":0.06310787,\"amount_str\":\"0.06310787\",\"amount_traded\":\"0\",\"amount_at_create\":\"0.06310787\",\"price\":78522.54,\"price_str\":\"78522.54\",\"is_liquidation\":false},\"channel\":\"live_orders_btcusd\",\"event\":\"order_created\",\"event_id\":\"00065a1d-7fa7-0a88-0001-000101000020\",\"pre_event_id\":\"00065a1d-7fa7-0a88-0000-000100000020\",\"order_source\":\"orderbook\"}","recorded_unix_us":1787932602557287}
{"message":"{\"data\":{\"id\":2044303883517952,\"id_str\":\"2044303883517952\",\"order_type\":1,\"order_subtype\":5,\"datetime\":\"1787932602\",\"microtimestamp\":\"1787932602469000\",\"amount\":0.06310787,\"amount_str\":\"0.06310787\",\"amount_traded\":\"0\",\"amount_at_create\":\"0.06310787\",\"price\":78522.54,\"price_str\":\"78522.54\",\"is_liquidation\":false},\"channel\":\"live_orders_btcusd\",\"event\":\"order_deleted\",\"event_id\":\"00065a1d-7fa7-0a88-0002-000102000020\",\"pre_event_id\":\"00065a1d-7fa7-0a88-0001-000101000020\",\"order_source\":\"orderbook\"}","recorded_unix_us":1787932602557346}
{"message":"{\"data\":{\"id\":2044303883517972,\"id_str\":\"2044303883517972\",\"order_type\":0,\"order_subtype\":5,\"datetime\":\"1787932602\",\"microtimestamp\":\"1787932602470000\",\"amount\":3.02537254,\"amount_str\":\"3.02537254\",\"amount_traded\":\"0\",\"amount_at_create\":\"3.02537254\",\"price\":0.03156999,\"price_str\":\"0.03156999\",\"is_liquidation\":false},\"channel\":\"live_orders_ethbtc\",\"event\":\"order_created\",\"event_id\":\"00065a1d-7fa7-0e70-0000-001102000020\",\"pre_event_id\":\"00065a1d-7fa7-0a88-0000-001101000020\",\"order_source\":\"orderbook\"}","recorded_unix_us":1787932602557454}
{"message":"{\"data\":{\"id\":2044303883522052,\"id_str\":\"2044303883522052\",\"order_type\":0,\"order_subtype\":5,\"datetime\":\"1787932602\",\"microtimestamp\":\"1787932602470000\",\"amount\":4.03662068,\"amount_str\":\"4.03662068\",\"amount_traded\":\"0\",\"amount_at_create\":\"4.03662068\",\"price\":0.03154857,\"price_str\":\"0.03154857\",\"is_liquidation\":false},\"channel\":\"live_orders_ethbtc\",\"event\":\"order_created\",\"event_id\":\"00065a1d-7fa7-0e70-0001-001103000020\",\"pre_event_id\":\"00065a1d-7fa7-0e70-0000-001102000020\",\"order_source\":\"orderbook\"}","recorded_unix_us":1787932602557554}
{"message":"{\"data\":{\"id\":2044303881940997,\"id_str\":\"2044303881940997\",\"order_type\":0,\"order_subtype\":5,\"datetime\":\"1787932602\",\"microtimestamp\":\"1787932602471000\",\"amount\":0.042508,\"amount_str\":\"0.042508\",\"amount_traded\":\"0\",\"amount_at_create\":\"0.042508\",\"price\":2480.8,\"price_str\":\"2480.80\",\"is_liquidation\":false},\"channel\":\"live_orders_ethusd\",\"event\":\"order_deleted\",\"event_id\":\"00065a1d-7fa7-1258-0000-001202000020\",\"pre_event_id\":\"00065a1d-7fa6-85b8-0000-001201000020\",\"order_source\":\"orderbook\"}","recorded_unix_us":1787932602557651}
{"message":"{\"data\":{\"id\":2044303883530245,\"id_str\":\"2044303883530245\",\"order_type\":1,\"order_subtype\":5,\"datetime\":\"1787932602\",\"microtimestamp\":\"1787932602472000\",\"amount\":0.1,\"amount_str\":\"0.10000000\",\"amount_traded\":\"0\",\"amount_at_create\":\"0.10000000\",\"price\":78522.62,\"price_str\":\"78522.62\",\"is_liquidation\":false},\"channel\":\"live_orders_btcusd\",\"event\":\"order_created\",\"event_id\":\"00065a1d-7fa7-1640-0000-000103000020\",\"pre_event_id\":\"00065a1d-7fa7-0a88-0002-000102000020\",\"order_source\":\"orderbook\"}","recorded_unix_us":1787932602557817}
{"message":"{\"data\":{\"id\":2044303883530245,\"id_str\":\"2044303883530245\",\"order_type\":1,\"order_subtype\":5,\"datetime\":\"1787932602\",\"microtimestamp\":\"1787932602472000\",\"amount\":0.1,\"amount_str\":\"0.10000000\",\"amount_traded\":\"0\",\"amount_at_create\":\"0.10000000\",\"price\":78522.62,\"price_str\":\"78522.62\",\"is_liquidation\":false},\"channel\":\"live_orders_btcusd\",\"event\":\"order_deleted\",\"event_id\":\"00065a1d-7fa7-1640-0001-000100000020\",\"pre_event_id\":\"00065a1d-7fa7-1640-0000-000103000020\",\"order_source\":\"orderbook\"}","recorded_unix_us":1787932602557851}
{"message":"{\"data\":{\"id\":2044303881945090,\"id_str\":\"2044303881945090\",\"order_type\":1,\"order_subtype\":5,\"datetime\":\"1787932602\",\"microtimestamp\":\"1787932602473000\",\"amount\":0.043646,\"amount_str\":\"0.043646\",\"amount_traded\":\"0\",\"amount_at_create\":\"0.043646\",\"price\":2480.89,\"price_str\":\"2480.89\",\"is_liquidation\":false},\"channel\":\"live_orders_ethusd\",\"event\":\"order_deleted\",\"event_id\":\"00065a1d-7fa7-1a28-0000-001203000020\",\"pre_event_id\":\"00065a1d-7fa7-1258-0000-001202000020\",\"order_source\":\"orderbook\"}","recorded_unix_us":1787932602557979}
{"message":"{\"data\":{\"id\":2044303876603911,\"id_str\":\"2044303876603911\",\"order_type\":1,\"order_subtype\":5,\"datetime\":\"1787932602\",\"microtimestamp\":\"1787932602473000\",\"amount\":0.00254701,\"amount_str\":\"0.00254701\",\"amount_traded\":\"0\",\"amount_at_create\":\"0.00254701\",\"price\":78523.42,\"price_str\":\"78523.42\",\"is_liquidation\":false},\"channel\":\"live_orders_btcusd\",\"event\":\"order_deleted\",\"event_id\":\"00065a1d-7fa7-1a28-0000-000101000020\",\"pre_event_id\":\"00065a1d-7fa7-1640-0001-000100000020\",\"order_source\":\"orderbook\"}","recorded_unix_us":1787932602558108}
{"message":"{\"data\":{\"id\":2044303881039873,\"id_str\":\"2044303881039873\",\"order_type\":0,\"order_subtype\":5,\"datetime\":\"1787932602\",\"microtimestamp\":\"1787932602487000\",\"amount\":0.336955,\"amount_str\":\"0.336955\",\"amount_traded\":\"0\",\"amount_at_create\":\"0.336955\",\"price\":2480.15,\"price_str\":\"2480.15\",\"is_liquidation\":false},\"channel\":\"live_orders_ethusd\",\"event\":\"order_deleted\",\"event_id\":\"00065a1d-7fa7-50d8-0000-001200000020\",\"pre_event_id\":\"00065a1d-7fa7-1a28-0000-001203000020\",\"order_source\":\"orderbook\"}","recorded_unix_us":1787932602612852}
{"message":"{\"data\":{\"id\":2044303882694659,\"id_str\":\"2044303882694659\",\"order_type\":0,\"order_subtype\":5,\"datetime\":\"1787932602\",\"microtimestamp\":\"1787932602491000\",\"amount\":0.403086,\"amount_str\":\"0.403086\",\"amount_traded\":\"0\",\"amount_at_create\":\"0.403086\",\"price\":2480.16,\"price_str\":\"2480.16\",\"is_liquidation\":false},\"channel\":\"live_orders_ethusd\",\"event\":\"order_deleted\",\"event_id\":\"00065a1d-7fa7-6078-0000-001201000020\",\"pre_event_id\":\"00065a1d-7fa7-50d8-0000-001200000020\",\"order_source\":\"orderbook\"}","recorded_unix_us":1787932602720771}
{"message":"{\"data\":{\"id\":2044303883616265,\"id_str\":\"2044303883616265\",\"order_type\":1,\"order_subtype\":5,\"datetime\":\"1787932602\",\"microtimestamp\":\"1787932602494000\",\"amount\":0.041769,\"amount_str\":\"0.041769\",\"amount_traded\":\"0\",\"amount_at_create\":\"0.041769\",\"price\":2480.85,\"price_str\":\"2480.85\",\"is_liquidation\":false},\"channel\":\"live_orders_ethusd\",\"event\":\"order_created\",\"event_id\":\"00065a1d-7fa7-6c30-0000-001202000020\",\"pre_event_id\":\"00065a1d-7fa7-6078-0000-001201000020\",\"order_source\":\"orderbook\"}","recorded_unix_us":1787932602720887}
{"message":"{\"data\":{\"id\":2044303883636739,\"id_str\":\"2044303883636739\",\"order_type\":0,\"order_subtype\":5,\"datetime\":\"1787932602\",\"microtimestamp\":\"1787932602498000\",\"amount\":0.044416,\"amount_str\":\"0.044416\",\"amount_traded\":\"0\",\"amount_at_create\":\"0.044416\",\"price\":2480.75,\"price_str\":\"2480.75\",\"is_liquidation\":false},\"channel\":\"live_orders_ethusd\",\"event\":\"order_created\",\"event_id\":\"00065a1d-7fa7-7bd0-0000-001203000020\",\"pre_event_id\":\"00065a1d-7fa7-6c30-0000-001202000020\",\"order_source\":\"orderbook\"}","recorded_unix_us":1787932602721010}
{"message":"{\"data\":{\"id\":2044303883640834,\"id_str\":\"2044303883640834\",\"order_type\":0,\"order_subtype\":5,\"datetime\":\"1787932602\",\"microtimestamp\":\"1787932602499000\",\"amount\":0.509959,\"amount_str\":\"0.509959\",\"amount_traded\":\"0\",\"amount_at_create\":\"0.509959\",\"price\":2480.22,\"price_str\":\"2480.22\",\"is_liquidation\":false},\"channel\":\"live_orders_ethusd\",\"event\":\"order_created\",\"event_id\":\"00065a1d-7fa7-7fb8-0000-001200000020\",\"pre_event_id\":\"00065a1d-7fa7-7bd0-0000-001203000020\",\"order_source\":\"orderbook\"}","recorded_unix_us":1787932602721051}
{"message":"{\"data\":{\"id\":2044303883644928,\"id_str\":\"2044303883644928\",\"order_type\":0,\"order_subtype\":5,\"datetime\":\"1787932603\",\"microtimestamp\":\"1787932602500000\",\"amount\":0.403096,\"amount_str\":\"0.403096\",\"amount_traded\":\"0\",\"amount_at_create\":\"0.403096\",\"price\":2480.22,\"price_str\":\"2480.22\",\"is_liquidation\":false},\"channel\":\"live_orders_ethusd\",\"event\":\"order_created\",\"event_id\":\"00065a1d-7fa7-83a0-0000-001201000020\",\"pre_event_id\":\"00065a1d-7fa7-7fb8-0000-001200000020\",\"order_source\":\"orderbook\"}","recorded_unix_us":1787932602721156}
{"message":"{\"data\":{\"id\":2044303883649025,\"id_str\":\"2044303883649025\",\"order_type\":1,\"order_subtype\":5,\"datetime\":\"1787932603\",\"microtimestamp\":\"1787932602501000\",\"amount\":0.1,\"amount_str\":\"0.10000000\",\"amount_traded\":\"0\",\"amount_at_create\":\"0.10000000\",\"price\":78522.63,\"price_str\":\"78522.63\",\"is_liquidation\":false},\"channel\":\"live_orders_btcusd\",\"event\":\"order_created\",\"event_id\":\"00065a1d-7fa7-8788-0000-000102000020\",\"pre_event_id\":\"00065a1d-7fa7-1a28-0000-000101000020\",\"order_source\":\"orderbook\"}","recorded_unix_us":1787932602721291}
{"message":"{\"data\":{\"id\":2044303883649025,\"id_str\":\"2044303883649025\",\"order_type\":1,\"order_subtype\":5,\"datetime\":\"1787932603\",\"microtimestamp\":\"1787932602501000\",\"amount\":0.1,\"amount_str\":\"0.10000000\",\"amount_traded\":\"0\",\"amount_at_create\":\"0.10000000\",\"price\":78522.63,\"price_str\":\"78522.63\",\"is_liquidation\":false},\"channel\":\"live_orders_btcusd\",\"event\":\"order_deleted\",\"event_id\":\"00065a1d-7fa7-8788-0001-000103000020\",\"pre_event_id\":\"00065a1d-7fa7-8788-0000-000102000020\",\"order_source\":\"orderbook\"}","recorded_unix_us":1787932602721319}
{"message":"{\"data\":{\"id\":2044303883649029,\"id_str\":\"2044303883649029\",\"order_type\":1,\"order_subtype\":5,\"datetime\":\"1787932603\",\"microtimestamp\":\"1787932602502000\",\"amount\":0.06310787,\"amount_str\":\"0.06310787\",\"amount_traded\":\"0\",\"amount_at_create\":\"0.06310787\",\"price\":78522.42,\"price_str\":\"78522.42\",\"is_liquidation\":false},\"channel\":\"live_orders_btcusd\",\"event\":\"order_created\",\"event_id\":\"00065a1d-7fa7-8b70-0000-000100000020\",\"pre_event_id\":\"00065a1d-7fa7-8788-0001-000103000020\",\"order_source\":\"orderbook\"}","recorded_unix_us":1787932602721472}
{"message":"{\"data\":{\"id\":2044303883649029,\"id_str\":\"2044303883649029\",\"order_type\":1,\"order_subtype\":5,\"datetime\":\"1787932603\",\"microtimestamp\":\"1787932602502000\",\"amount\":0.06310787,\"amount_str\":\"0.06310787\",\"amount_traded\":\"0\",\"amount_at_create\":\"0.06310787\",\"price\":78522.42,\"price_str\":\"78522.42\",\"is_liquidation\":false},\"channel\":\"live_orders_btcusd\",\"event\":\"order_deleted\",\"event_id\":\"00065a1d-7fa7-8b70-0001-000101000020\",\"pre_event_id\":\"00065a1d-7fa7-8b70-0000-000100000020\",\"order_source\":\"orderbook\"}","recorded_unix_us":1787932602721507}
{"message":"{\"data\":{\"id\":2044303883653123,\"id_str\":\"2044303883653123\",\"order_type\":1,\"order_subtype\":5,\"datetime\":\"1787932603\",\"microtimestamp\":\"1787932602502000\",\"amount\":0.06310787,\"amount_str\":\"0.06310787\",\"amount_traded\":\"0\",\"amount_at_create\":\"0.06310787\",\"price\":78520.06,\"price_str\":\"78520.06\",\"is_liquidation\":false},\"channel\":\"live_orders_btcusd\",\"event\":\"order_created\",\"event_id\":\"00065a1d-7fa7-8b70-0002-000102000020\",\"pre_event_id\":\"00065a1d-7fa7-8b70-0001-000101000020\",\"order_source\":\"orderbook\"}","recorded_unix_us":1787932602721625}
{"message":"{\"data\":{\"id\":2044303883653123,\"id_str\":\"2044303883653123\",\"order_type\":1,\"order_subtype\":5,\"datetime\":\"1787932603\",\"microtimestamp\":\"1787932602502000\",\"amount\":0.06310787,\"amount_str\":\"0.06310787\",\"amount_traded\":\"0\",\"amount_at_create\":\"0.06310787\",\"price\":78520.06,\"price_str\":\"78520.06\",\"is_liquidation\":false},\"channel\":\"live_orders_btcusd\",\"event\":\"order_deleted\",\"event_id\":\"00065a1d-7fa7-8b70-0003-000103000020\",\"pre_event_id\":\"00065a1d-7fa7-8b70-0002-000102000020\",\"order_source\":\"orderbook\"}","recorded_unix_us":1787932602721653}
{"message":"{\"data\":{\"id\":2044303883702276,\"id_str\":\"2044303883702276\",\"order_type\":1,\"order_subtype\":5,\"datetime\":\"1787932603\",\"microtimestamp\":\"1787932602515000\",\"amount\":0.1,\"amount_str\":\"0.10000000\",\"amount_traded\":\"0\",\"amount_at_create\":\"0.10000000\",\"price\":78522.62,\"price_str\":\"78522.62\",\"is_liquidation\":false},\"channel\":\"live_orders_btcusd\",\"event\":\"order_created\",\"event_id\":\"00065a1d-7fa7-be38-0000-000100000020\",\"pre_event_id\":\"00065a1d-7fa7-8b70-0003-000103000020\",\"order_source\":\"orderbook\"}","recorded_unix_us":1787932602721771}
{"message":"{\"data\":{\"id\":2044303883702276,\"id_str\":\"2044303883702276\",\"order_type\":1,\"order_subtype\":5,\"datetime\":\"1787932603\",\"microtimestamp\":\"1787932602515000\",\"amount\":0.1,\"amount_str\":\"0.10000000\",\"amount_traded\":\"0\",\"amount_at_create\":\"0.10000000\",\"price\":78522.62,\"price_str\":\"78522.62\",\"is_liquidation\":false},\"channel\":\"live_orders_btcusd\",\"event\":\"order_deleted\",\"event_id\":\"00065a1d-7fa7-be38-0001-000101000020\",\"pre_event_id\":\"00065a1d-7fa7-be38-0000-000100000020\",\"order_source\":\"orderbook\"}","recorded_unix_us":1787932602721799}
{"message":"{\"data\":{\"id\":2044303883714560,\"id_str\":\"2044303883714560\",\"order_type\":1,\"order_subtype\":5,\"datetime\":\"1787932603\",\"microtimestamp\":\"1787932602517000\",\"amount\":0.06367384,\"amount_str\":\"0.06367384\",\"amount_traded\":\"0\",\"amount_at_create\":\"0.06367384\",\"price\":78525.19,\"price_str\":\"78525.19\",\"is_liquidation\":false},\"channel\":\"live_orders_btcusd\",\"event\":\"order_created\",\"event_id\":\"00065a1d-7fa7-c608-0000-000102000020\",\"pre_event_id\":\"00065a1d-7fa7-be38-0001-000101000020\",\"order_source\":\"orderbook\"}","recorded_unix_us":1787932602722681}
{"message":"{\"data\":{\"id\":2044303883714561,\"id_str\":\"2044303883714561\",\"order_type\":1,\"order_subtype\":5,\"datetime\":\"1787932603\",\"microtimestamp\":\"1787932602518000\",\"amount\":0.06367563,\"amount_str\":\"0.06367563\",\"amount_traded\":\"0\",\"amount_at_create\":\"0.06367563\",\"price\":78522.98,\"price_str\":\"78522.98\",\"is_liquidation\":false},\"channel\":\"live_orders_btcusd\",\"event\":\"order_created\",\"event_id\":\"00065a1d-7fa7-c9f0-0000-000103000020\",\"pre_event_id\":\"00065a1d-7fa7-c608-0000-000102000020\",\"order_source\":\"orderbook\"}","recorded_unix_us":1787932602722791}
{"message":"{\"data\":{\"id\":2044303501205504,\"id_str\":\"2044303501205504\",\"order_type\":0,\"order_subtype\":5,\"datetime\":\"1787932603\",\"microtimestamp\":\"1787932602519000\",\"amount\":0.01,\"amount_str\":\"0.010000\",\"amount_traded\":\"0\",\"amount_at_create\":\"0.010000\",\"price\":2469.5,\"price_str\":\"2469.50\",\"is_liquidation\":false},\"channel\":\"live_orders_ethusd\",\"event\":\"order_deleted\",\"event_id\":\"00065a1d-7fa7-cdd8-0000-001202000020\",\"pre_event_id\":\"00065a1d-7fa7-83a0-0000-001201000020\",\"order_source\":\"orderbook\"}","recorded_unix_us":1787932602722921}
{"message":"{\"data\":{\"id\":2044303883722752,\"id_str\":\"2044303883722752\",\"order_type\":0,\"order_subtype\":5,\"datetime\":\"1787932603\",\"microtimestamp\":\"1787932602519000\",\"amount\":0.12,\"amount_str\":\"0.12000000\",\"amount_traded\":\"0\",\"amount_at_create\":\"0.12000000\",\"price\":78508.87,\"price_str\":\"78508.87\",\"is_liquidation\":false},\"channel\":\"live_orders_btcusd\",\"event\":\"order_created\",\"event_id\":\"00065a1d-7fa7-cdd8-0000-000100000020\",\"pre_event_id\":\"00065a1d-7fa7-c9f0-0000-000103000020\",\"order_source\":\"orderbook\"}","recorded_unix_us":1787932602722952}
{"message":"{\"data\":{\"id\":2044303880900611,\"id_str\":\"2044303880900611\",\"order_type\":0,\"order_subtype\":5,\"datetime\":\"1787932603\",\"microtimestamp\":\"1787932602521000\",\"amount\":0.12,\"amount_str\":\"0.12000000\",\"amount_traded\":\"0\",\"amount_at_create\":\"0.12000000\",\"price\":78508.22,\"price_str\":\"78508.22\",\"is_liquidation\":false},\"channel\":\"live_orders_btcusd\",\"event\":\"order_deleted\",\"event_id\":\"00065a1d-7fa7-d5a8-0000-000101000020\",\"pre_event_id\":\"00065a1d-7fa7-cdd8-0000-000100000020\",\"order_source\":\"orderbook\"}","recorded_unix_us":1787932602723039}
{"message":"{\"data\":{\"id\":2044303883739137,\"id_str\":\"2044303883739137\",\"order_type\":1,\"order_subtype\":5,\"datetime\":\"1787932603\",\"microtimestamp\":\"1787932602523000\",\"amount\":0.25467128,\"amount_str\":\"0.25467128\",\"amount_traded\":\"0\",\"amount_at_create\":\"0.25467128\",\"price\":78532.61,\"price_str\":\"78532.61\",\"is_liquidation\":false},\"channel\":\"live_orders_btcusd\",\"event\":\"order_created\",\"event_id\":\"00065a1d-7fa7-dd78-0000-000102000020\",\"pre_event_id\":\"00065a1d-7fa7-d5a8-0000-000101000020\",\"order_source\":\"orderbook\"}","recorded_unix_us":1787932602723126}
{"message":"{\"data\":{\"id\":2044303883747328,\"id_str\":\"2044303883747328\",\"order_type\":1,\"order_subtype\":5,\"datetime\":\"1787932603\",\"microtimestamp\":\"1787932602526000\",\"amount\":1.27209222,\"amount_str\":\"1.27209222\",\"amount_traded\":\"0\",\"amount_at_create\":\"1.27209222\",\"price\":78610.66,\"price_str\":\"78610.66\",\"is_liquidation\":false},\"channel\":\"live_orders_btcusd\",\"event\":\"order_created\",\"event_id\":\"00065a1d-7fa7-e930-0000-000103000020\",\"pre_event_id\":\"00065a1d-7fa7-dd78-0000-000102000020\",\"order_source\":\"orderbook\"}","recorded_unix_us":1787932602723245}
{"message":"{\"data\":{\"id\":2044303883747329,\"id_str\":\"2044303883747329\",\"order_type\":1,\"order_subtype\":5,\"datetime\":\"1787932603\",\"microtimestamp\":\"1787932602526000\",\"amount\":0.25466146,\"amount_str\":\"0.25466146\",\"amount_traded\":\"0\",\"amount_at_create\":\"0.25466146\",\"price\":78535.64,\"price_str\":\"78535.64\",\"is_liquidation\":false},\"channel\":\"live_orders_btcusd\",\"event\":\"order_created\",\"event_id\":\"00065a1d-7fa7-e930-0001-000100000020\",\"pre_event_id\":\"00065a1d-7fa7-e930-0000-000103000020\",\"order_source\":\"orderbook\"}","recorded_unix_us":1787932602723274}
{"message":"{\"data\":{\"id\":2044303883751424,\"id_str\":\"2044303883751424\",\"order_type\":1,\"order_subtype\":5,\"datetime\":\"1787932603\",\"microtimestamp\":\"1787932602526000\",\"amount\":12.70451953,\"amount_str\":\"12.70451953\",\"amount_traded\":\"0\",\"amount_at_create\":\"12.70451953\",\"price\":78712.15,\"price_str\":\"78712.15\",\"is_liquidation\":false},\"channel\":\"live_orders_btcusd\",\"event\":\"order_created\",\"event_id\":\"00065a1d-7fa7-e930-0002-000101000020\",\"pre_event_id\":\"00065a1d-7fa7-e930-0001-000100000020\",\"order_source\":\"orderbook\"}","recorded_unix_us":1787932602723362}
{"message":"{\"data\":{\"id\":2044303882887181,\"id_str\":\"2044303882887181\",\"order_type\":0,\"order_subtype\":5,\"datetime\":\"1787932603\",\"microtimestamp\":\"1787932602528000\",\"amount\":0.1910377,\"amount_str\":\"0.19103770\",\"amount_traded\":\"0\",\"amount_at_create\":\"0.19103770\",\"price\":78485,\"price_str\":\"78485.00\",\"is_liquidation\":false},\"channel\":\"live_orders_btcusd\",\"event\":\"order_deleted\",\"event_id\":\"00065a1d-7fa7-f100-0000-000102000020\",\"pre_event_id\":\"00065a1d-7fa7-e930-0002-000101000020\",\"order_source\":\"orderbook\"}","recorded_unix_us":1787932602723513}
{"message":"{\"data\":{\"id\":2044303883759619,\"id_str\":\"2044303883759619\",\"order_type\":1,\"order_subtype\":5,\"datetime\":\"1787932603\",\"microtimestamp\":\"1787932602528000\",\"amount\":0.06310787,\"amount_str\":\"0.06310787\",\"amount_traded\":\"0\",\"amount_at_create\":\"0.06310787\",\"price\":78522.42,\"price_str\":\"78522.42\",\"is_liquidation\":false},\"channel\":\"live_orders_btcusd\",\"event\":\"order_created\",\"event_id\":\"00065a1d-7fa7-f100-0001-000103000020\",\"pre_event_id\":\"00065a1d-7fa7-f100-0000-000102000020\",\"order_source\":\"orderbook\"}","recorded_unix_us":1787932602723542}
{"message":"{\"data\":{\"id\":2044303883759619,\"id_str\":\"2044303883759619\",\"order_type\":1,\"order_subtype\":5,\"datetime\":\"1787932603\",\"microtimestamp\":\"1787932602528000\",\"amount\":0.06310787,\"amount_str\":\"0.06310787\",\"amount_traded\":\"0\",\"amount_at_create\":\"0.06310787\",\"price\":78522.42,\"price_str\":\"78522.42\",\"is_liquidation\":false},\"channel\":\"live_orders_btcusd\",\"event\":\"order_deleted\",\"event_id\":\"00065a1d-7fa7-f100-0002-000100000020\",\"pre_event_id\":\"00065a1d-7fa7-f100-0001-000103000020\",\"order_source\":\"orderbook\"}","recorded_unix_us":1787932602723569}
{"message":"{\"data\":{\"id\":2044303883780096,\"id_str\":\"2044303883780096\",\"order_type\":1,\"order_subtype\":5,\"datetime\":\"1787932603\",\"microtimestamp\":\"1787932602533000\",\"amount\":0.1,\"amount_str\":\"0.10000000\",\"amount_traded\":\"0\",\"amount_at_create\":\"0.10000000\",\"price\":78522.63,\"price_str\":\"78522.63\",\"is_liquidation\":false},\"channel\":\"live_orders_btcusd\",\"event\":\"order_created\",\"event_id\":\"00065a1d-7fa8-0488-0000-000101000020\",\"pre_event_id\":\"00065a1d-7fa7-f100-0002-000100000020\",\"order_source\":\"orderbook\"}","recorded_unix_us":1787932602723661}
{"message":"{\"data\":{\"id\":2044303883780096,\"id_str\":\"2044303883780096\",\"order_type\":1,\"order_subtype\":5,\"datetime\":\"1787932603\",\"microtimestamp\":\"1787932602533000\",\"amount\":0.1,\"amount_str\":\"0.10000000\",\"amount_traded\":\"0\",\"amount_at_create\":\"0.10000000\",\"price\":78522.63,\"price_str\":\"78522.63\",\"is_liquidation\":false},\"channel\":\"live_orders_btcusd\",\"event\":\"order_deleted\",\"event_id\":\"00065a1d-7fa8-0488-0001-000102000020\",\"pre_event_id\":\"00065a1d-7fa8-0488-0000-000101000020\",\"order_source\":\"orderbook\"}","recorded_unix_us":1787932602723743}
{"message":"{\"data\":{\"id\":2044303883784192,\"id_str\":\"2044303883784192\",\"order_type\":0,\"order_subtype\":5,\"datetime\":\"1787932603\",\"microtimestamp\":\"1787932602535000\",\"amount\":0.0025477,\"amount_str\":\"0.00254770\",\"amount_traded\":\"0\",\"amount_at_create\":\"0.00254770\",\"price\":78502.27,\"price_str\":\"78502.27\",\"is_liquidation\":false},\"channel\":\"live_orders_btcusd\",\"event\":\"order_created\",\"event_id\":\"00065a1d-7fa8-0c58-0000-000103000020\",\"pre_event_id\":\"00065a1d-7fa8-0488-0001-000102000020\",\"order_source\":\"orderbook\"}","recorded_unix_us":1787932602723877}
{"message":"{\"data\":{\"id\":2044303883788289,\"id_str\":\"2044303883788289\",\"order_type\":1,\"order_subtype\":5,\"datetime\":\"1787932603\",\"microtimestamp\":\"1787932602535000\",\"amount\":1.26970017,\"amount_str\":\"1.26970017\",\"amount_traded\":\"0\",\"amount_at_create\":\"1.26970017\",\"price\":78758.76,\"price_str\":\"78758.76\",\"is_liquidation\":false},\"channel\":\"live_orders_btcusd\",\"event\":\"order_created\",\"event_id\":\"00065a1d-7fa8-0c58-0001-000100000020\",\"pre_event_id\":\"00065a1d-7fa8-0c58-0000-000103000020\",\"order_source\":\"orderbook\"}","recorded_unix_us":1787932602723906}
{"message":"{\"data\":{\"id\":2044303883804675,\"id_str\":\"2044303883804675\",\"order_type\":0,\"order_subtype\":5,\"datetime\":\"1787932603\",\"microtimestamp\":\"1787932602540000\",\"amount\":0.1910375,\"amount_str\":\"0.19103750\",\"amount_traded\":\"0\",\"amount_at_create\":\"0.19103750\",\"price\":78485.88,\"price_str\":\"78485.88\",\"is_liquidation\":false},\"channel\":\"live_orders_btcusd\",\"event\":\"order_created\",\"event_id\":\"00065a1d-7fa8-1fe0-0000-000101000020\",\"pre_event_id\":\"00065a1d-7fa8-0c58-0001-000100000020\",\"order_source\":\"orderbook\"}","recorded_unix_us":1787932602724016}
{"message":"{\"data\":{\"id\":2044303883808770,\"id_str\":\"2044303883808770\",\"order_type\":1,\"order_subtype\":5,\"datetime\":\"1787932603\",\"microtimestamp\":\"1787932602541000\",\"amount\":1.2684012,\"amount_str\":\"1.26840120\",\"amount_traded\":\"0\",\"amount_at_create\":\"1.26840120\",\"price\":78839.41,\"price_str\":\"78839.41\",\"is_liquidation\":false},\"channel\":\"live_orders_btcusd\",\"event\":\"order_created\",\"event_id\":\"00065a1d-7fa8-23c8-0000-000102000020\",\"pre_event_id\":\"00065a1d-7fa8-1fe0-0000-000101000020\",\"order_source\":\"orderbook\"}","recorded_unix_us":1787932602724178}
{"message":"{\"data\":{\"id\":2044303883812868,\"id_str\":\"2044303883812868\",\"order_type\":0,\"order_subtype\":5,\"datetime\":\"1787932603\",\"microtimestamp\":\"1787932602541000\",\"amount\":0.06367953,\"amount_str\":\"0.06367953\",\"amount_traded\":\"0\",\"amount_at_create\":\"0.06367953\",\"price\":78518.15,\"price_str\":\"78518.15\",\"is_liquidation\":false},\"channel\":\"live_orders_btcusd\",\"event\":\"order_created\",\"event_id\":\"00065a1d-7fa8-23c8-0001-000103000020\",\"pre_event_id\":\"00065a1d-7fa8-23c8-0000-000102000020\",\"order_source\":\"orderbook\"}","recorded_unix_us":1787932602724232}
{"message":"{\"data\":{\"id\":2044303883816968,\"id_str\":\"2044303883816968\",\"order_type\":1,\"order_subtype\":5,\"datetime\":\"1787932603\",\"microtimestamp\":\"1787932602542000\",\"amount\":0.06310787,\"amount_str\":\"0.06310787\",\"amount_traded\":\"0\",\"amount_at_create\":\"0.06310787\",\"price\":78520.06,\"price_str\":\"78520.06\",\"is_liquidation\":false},\"channel\":\"live_orders_btcusd\",\"event\":\"order_created\",\"event_id\":\"00065a1d-7fa8-27b0-0000-000100000020\",\"pre_event_id\":\"00065a1d-7fa8-23c8-0001-000103000020\",\"order_source\":\"orderbook\"}","recorded_unix_us":1787932602724341}
{"message":"{\"data\":{\"id\":2044303883816968,\"id_str\":\"2044303883816968\",\"order_type\":1,\"order_subtype\":5,\"datetime\":\"1787932603\",\"microtimestamp\":\"1787932602542000\",\"amount\":0.06310787,\"amount_str\":\"0.06310787\",\"amount_traded\":\"0\",\"amount_at_create\":\"0.06310787\",\"price\":78520.06,\"price_str\":\"78520.06\",\"is_liquidation\":false},\"channel\":\"live_orders_btcusd\",\"event\":\"order_deleted\",\"event_id\":\"00065a1d-7fa8-27b0-0001-000101000020\",\"pre_event_id\":\"00065a1d-7fa8-27b0-0000-000100000020\",\"order_source\":\"orderbook\"}","recorded_unix_us":1787932602724440}
{"message":"{\"data\":{\"id\":2044303883837446,\"id_str\":\"2044303883837446\",\"order_type\":0,\"order_subtype\":5,\"datetime\":\"1787932603\",\"microtimestamp\":\"1787932602547000\",\"amount\":0.00140266,\"amount_str\":\"0.00140266\",\"amount_traded\":\"0\",\"amount_at_create\":\"0.00140266\",\"price\":70666.76,\"price_str\":\"70666.76\",\"is_liquidation\":false},\"channel\":\"live_orders_btcusd\",\"event\":\"order_created\",\"event_id\":\"00065a1d-7fa8-3b38-0000-000102000020\",\"pre_event_id\":\"00065a1d-7fa8-27b0-0001-000101000020\",\"order_source\":\"orderbook\"}","recorded_unix_us":1787932602724590}
{"message":"{\"data\":{\"id\":2044303876780035,\"id_str\":\"2044303876780035\",\"order_type\":0,\"order_subtype\":0,\"datetime\":\"1787932603\",\"microtimestamp\":\"1787932602549000\",\"amount\":1.50014,\"amount_str\":\"1.50014000\",\"amount_traded\":\"0\",\"amount_at_create\":\"1.50014000\",\"price\":0.03017117,\"price_str\":\"0.03017117\",\"is_liquidation\":false},\"channel\":\"live_orders_ethbtc\",\"event\":\"order_deleted\",\"event_id\":\"00065a1d-7fa8-4308-0000-001100000020\",\"pre_event_id\":\"00065a1d-7fa7-0e70-0001-001103000020\",\"order_source\":\"orderbook\"}","recorded_unix_us":1787932602724717}
{"message":"{\"data\":{\"id\":2044303883849734,\"id_str\":\"2044303883849734\",\"order_type\":1,\"order_subtype\":5,\"datetime\":\"1787932603\",\"microtimestamp\":\"1787932602551000\",\"amount\":0.1,\"amount_str\":\"0.10000000\",\"amount_traded\":\"0\",\"amount_at_create\":\"0.10000000\",\"price\":78522.62,\"price_str\":\"78522.62\",\"is_liquidation\":false},\"channel\":\"live_orders_btcusd\",\"event\":\"order_created\",\"event_id\":\"00065a1d-7fa8-4ad8-0000-000103000020\",\"pre_event_id\":\"00065a1d-7fa8-3b38-0000-000102000020\",\"order_source\":\"orderbook\"}","recorded_unix_us":1787932602724836}
{"message":"{\"data\":{\"id\":2044303883849734,\"id_str\":\"2044303883849734\",\"order_type\":1,\"order_subtype\":5,\"datetime\":\"1787932603\",\"microtimestamp\":\"1787932602551000\",\"amount\":0.1,\"amount_str\":\"0.10000000\",\"amount_traded\":\"0\",\"amount_at_create\":\"0.10000000\",\"price\":78522.62,\"price_str\":\"78522.62\",\"is_liquidation\":false},\"channel\":\"live_orders_btcusd\",\"event\":\"order_deleted\",\"event_id\":\"00065a1d-7fa8-4ad8-0001-000100000020\",\"pre_event_id\":\"00065a1d-7fa8-4ad8-0000-000103000020\",\"order_source\":\"orderbook\"}","recorded_unix_us":1787932602724933}
{"message":"{\"data\":{\"id\":2044303883866122,\"id_str\":\"2044303883866122\",\"order_type\":0,\"order_subtype\":5,\"datetime\":\"1787932603\",\"microtimestamp\":\"1787932602555000\",\"amount\":0.06368171,\"amount_str\":\"0.06368171\",\"amount_traded\":\"0\",\"amount_at_create\":\"0.06368171\",\"price\":78515.46,\"price_str\":\"78515.46\",\"is_liquidation\":false},\"channel\":\"live_orders_btcusd\",\"event\":\"order_created\",\"event_id\":\"00065a1d-7fa8-5a78-0000-000101000020\",\"pre_event_id\":\"00065a1d-7fa8-4ad8-0001-000100000020\",\"order_source\":\"orderbook\"}","recorded_unix_us":1787932602725075}
{"message":"{\"data\":{\"id\":2044303883870209,\"id_str\":\"2044303883870209\",\"order_type\":0,\"order_subtype\":5,\"datetime\":\"1787932603\",\"microtimestamp\":\"1787932602556000\",\"amount\":0.25476924,\"amount_str\":\"0.25476924\",\"amount_traded\":\"0\",\"amount_at_create\":\"0.25476924\",\"price\":78502.41,\"price_str\":\"78502.41\",\"is_liquidation\":false},\"channel\":\"live_orders_btcusd\",\"event\":\"order_created\",\"event_id\":\"00065a1d-7fa8-5e60-0000-000102000020\",\"pre_event_id\":\"00065a1d-7fa8-5a78-0000-000101000020\",\"order_source\":\"orderbook\"}","recorded_unix_us":1787932602725106}
{"message":"{\"data\":{\"id\":2044303883874305,\"id_str\":\"2044303883874305\",\"order_type\":1,\"order_subtype\":5,\"datetime\":\"1787932603\",\"microtimestamp\":\"1787932602556000\",\"amount\":0.06310787,\"amount_str\":\"0.06310787\",\"amount_traded\":\"0\",\"amount_at_create\":\"0.06310787\",\"price\":78522.42,\"price_str\":\"78522.42\",\"is_liquidation\":false},\"channel\":\"live_orders_btcusd\",\"event\":\"order_created\",\"event_id\":\"00065a1d-7fa8-5e60-0001-000103000020\",\"pre_event_id\":\"00065a1d-7fa8-5e60-0000-000102000020\",\"order_source\":\"orderbook\"}","recorded_unix_us":1787932602725200}
{"message":"{\"data\":{\"id\":2044303883874305,\"id_str\":\"2044303883874305\",\"order_type\":1,\"order_subtype\":5,\"datetime\":\"1787932603\",\"microtimestamp\":\"1787932602556000\",\"amount\":0.06310787,\"amount_str\":\"0.06310787\",\"amount_traded\":\"0\",\"amount_at_create\":\"0.06310787\",\"price\":78522.42,\"price_str\":\"78522.42\",\"is_liquidation\":false},\"channel\":\"live_orders_btcusd\",\"event\":\"order_deleted\",\"event_id\":\"00065a1d-7fa8-5e60-0002-000100000020\",\"pre_event_id\":\"00065a1d-7fa8-5e60-0001-000103000020\",\"order_source\":\"orderbook\"}","recorded_unix_us":1787932602725310}
{"message":"{\"data\":{\"id\":2044303883882502,\"id_str\":\"2044303883882502\",\"order_type\":0,\"order_subtype\":5,\"datetime\":\"1787932603\",\"microtimestamp\":\"1787932602559000\",\"amount\":2.540413,\"amount_str\":\"2.540413\",\"amount_traded\":\"0\",\"amount_at_create\":\"2.540413\",\"price\":2455.46,\"price_str\":\"2455.46\",\"is_liquidation\":false},\"channel\":\"live_orders_ethusd\",\"event\":\"order_created\",\"event_id\":\"00065a1d-7fa8-6a18-0000-001203000020\",\"pre_event_id\":\"00065a1d-7fa7-cdd8-0000-001202000020\",\"order_source\":\"orderbook\"}","recorded_unix_us":1787932602739367}
{"message":"{\"data\":{\"id\":2044303883882503,\"id_str\":\"2044303883882503\",\"order_type\":1,\"order_subtype\":5,\"datetime\":\"1787932603\",\"microtimestamp\":\"1787932602559000\",\"amount\":0.12,\"amount_str\":\"0.12000000\",\"amount_traded\":\"0\",\"amount_at_create\":\"0.12000000\",\"price\":78541,\"price_str\":\"78541.00\",\"is_liquidation\":false},\"channel\":\"live_orders_btcusd\",\"event\":\"order_created\",\"event_id\":\"00065a1d-7fa8-6a18-0000-000101000020\",\"pre_event_id\":\"00065a1d-7fa8-5e60-0002-000100000020\",\"order_source\":\"orderbook\"}","recorded_unix_us":1787932602739562}
{"message":"{\"data\":{\"id\":2044303883882503,\"id_str\":\"2044303883882503\",\"order_type\":1,\"order_subtype\":5,\"datetime\":\"1787932603\",\"microtimestamp\":\"1787932602565000\",\"amount\":0.12,\"amount_str\":\"0.12000000\",\"amount_traded\":\"0\",\"amount_at_create\":\"0.12000000\",\"price\":78541,\"price_str\":\"78541.00\",\"is_liquidation\":false},\"channel\":\"live_orders_btcusd\",\"event\":\"order_deleted\",\"event_id\":\"00065a1d-7fa8-8188-0000-000102000020\",\"pre_event_id\":\"00065a1d-7fa8-6a18-0000-000101000020\",\"order_source\":\"orderbook\"}","recorded_unix_us":1787932602739737}
{"message":"{\"data\":{\"id\":2044303883919360,\"id_str\":\"2044303883919360\",\"order_type\":0,\"order_subtype\":5,\"datetime\":\"1787932603\",\"microtimestamp\":\"1787932602567000\",\"amount\":0.25478772,\"amount_str\":\"0.25478772\",\"amount_traded\":\"0\",\"amount_at_create\":\"0.25478772\",\"price\":78496.71,\"price_str\":\"78496.71\",\"is_liquidation\":false},\"channel\":\"live_orders_btcusd\",\"event\":\"order_created\",\"event_id\":\"00065a1d-7fa8-8958-0000-000103000020\",\"pre_event_id\":\"00065a1d-7fa8-8188-0000-000102000020\",\"order_source\":\"orderbook\"}","recorded_unix_us":1787932602739874}
{"message":"{\"data\":{\"id\":2044303883927552,\"id_str\":\"2044303883927552\",\"order_type\":0,\"order_subtype\":5,\"datetime\":\"1787932603\",\"microtimestamp\":\"1787932602569000\",\"amount\":1.27507828,\"amount_str\":\"1.27507828\",\"amount_traded\":\"0\",\"amount_at_create\":\"1.27507828\",\"price\":78426.55,\"price_str\":\"78426.55\",\"is_liquidation\":false},\"channel\":\"live_orders_btcusd\",\"event\":\"order_created\",\"event_id\":\"00065a1d-7fa8-9128-0000-000100000020\",\"pre_event_id\":\"00065a1d-7fa8-8958-0000-000103000020\",\"order_source\":\"orderbook\"}","recorded_unix_us":1787932602739992}
{"message":"{\"data\":{\"id\":2044303883931649,\"id_str\":\"2044303883931649\",\"order_type\":0,\"order_subtype\":5,\"datetime\":\"1787932603\",\"microtimestamp\":\"1787932602570000\",\"amount\":0.01,\"amount_str\":\"0.010000\",\"amount_traded\":\"0\",\"amount_at_create\":\"0.010000\",\"price\":2470.54,\"price_str\":\"2470.54\",\"is_liquidation\":false},\"channel\":\"live_orders_ethusd\",\"event\":\"order_created\",\"event_id\":\"00065a1d-7fa8-9510-0000-001200000020\",\"pre_event_id\":\"00065a1d-7fa8-6a18-0000-001203000020\",\"order_source\":\"orderbook\"}","recorded_unix_us":1787932602740150}
{"message":"{\"data\":{\"id\":2044303883931650,\"id_str\":\"2044303883931650\",\"order_type\":1,\"order_subtype\":5,\"datetime\":\"1787932603\",\"microtimestamp\":\"1787932602571000\",\"amount\":2.01528391,\"amount_str\":\"2.01528391\",\"amount_traded\":\"0\",\"amount_at_create\":\"2.01528391\",\"price\":0.03160361,\"price_str\":\"0.03160361\",\"is_liquidation\":false},\"channel\":\"live_orders_ethbtc\",\"event\":\"order_created\",\"event_id\":\"00065a1d-7fa8-98f8-0000-001101000020\",\"pre_event_id\":\"00065a1d-7fa8-4308-0000-001100000020\",\"order_source\":\"orderbook\"}","recorded_unix_us":1787932602740291}
{"message":"{\"data\":{\"id\":2044303883939840,\"id_str\":\"2044303883939840\",\"order_type\":1,\"order_subtype\":5,\"datetime\":\"1787932603\",\"microtimestamp\":\"1787932602572000\",\"amount\":0.1,\"amount_str\":\"0.10000000\",\"amount_traded\":\"0\",\"amount_at_create\":\"0.10000000\",\"price\":78522.63,\"price_str\":\"78522.63\",\"is_liquidation\":false},\"channel\":\"live_orders_btcusd\",\"event\":\"order_created\",\"event_id\":\"00065a1d-7fa8-9ce0-0000-000101000020\",\"pre_event_id\":\"00065a1d-7fa8-9128-0000-000100000020\",\"order_source\":\"orderbook\"}","recorded_unix_us":1787932602740422}
{"message":"{\"data\":{\"id\":2044303883939840,\"id_str\":\"2044303883939840\",\"order_type\":1,\"order_subtype\":5,\"datetime\":\"1787932603\",\"microtimestamp\":\"1787932602572000\",\"amount\":0.1,\"amount_str\":\"0.10000000\",\"amount_traded\":\"0\",\"amount_at_create\":\"0.10000000\",\"price\":78522.63,\"price_str\":\"78522.63\",\"is_liquidation\":false},\"channel\":\"live_orders_btcusd\",\"event\":\"order_deleted\",\"event_id\":\"00065a1d-7fa8-9ce0-0001-000102000020\",\"pre_event_id\":\"00065a1d-7fa8-9ce0-0000-000101000020\",\"order_source\":\"orderbook\"}","recorded_unix_us":1787932602740532}
{"message":"{\"data\":{\"id\":2044303883948035,\"id_str\":\"2044303883948035\",\"order_type\":0,\"order_subtype\":5,\"datetime\":\"1787932603\",\"microtimestamp\":\"1787932602574000\",\"amount\":1.27541152,\"amount_str\":\"1.27541152\",\"amount_traded\":\"0\",\"amount_at_create\":\"1.27541152\",\"price\":78406.06,\"price_str\":\"78406.06\",\"is_liquidation\":false},\"channel\":\"live_orders_btcusd\",\"event\":\"order_created\",\"event_id\":\"00065a1d-7fa8-a4b0-0000-000103000020\",\"pre_event_id\":\"00065a1d-7fa8-9ce0-0001-000102000020\",\"order_source\":\"orderbook\"}","recorded_unix_us":1787932602740670}
{"message":"{\"data\":{\"id\":2044303883952129,\"id_str\":\"2044303883952129\",\"order_type\":0,\"order_subtype\":5,\"datetime\":\"1787932603\",\"microtimestamp\":\"1787932602575000\",\"amount\":1.27567513,\"amount_str\":\"1.27567513\",\"amount_traded\":\"0\",\"amount_at_create\":\"1.27567513\",\"price\":78389.86,\"price_str\":\"78389.86\",\"is_liquidation\":false},\"channel\":\"live_orders_btcusd\",\"event\":\"order_created\",\"event_id\":\"00065a1d-7fa8-a898-0000-000100000020\",\"pre_event_id\":\"00065a1d-7fa8-a4b0-0000-000103000020\",\"order_source\":\"orderbook\"}","recorded_unix_us":1787932602740799}
{"message":"{\"data\":{\"id\":2044303883501577,\"id_str\":\"2044303883501577\",\"order_type\":0,\"order_subtype\":5,\"datetime\":\"1787932603\",\"microtimestamp\":\"1787932602576000\",\"amount\":0.00140266,\"amount_str\":\"0.00140266\",\"amount_traded\":\"0\",\"amount_at_create\":\"0.00140266\",\"price\":70666.76,\"price_str\":\"70666.76\",\"is_liquidation\":false},\"channel\":\"live_orders_btcusd\",\"event\":\"order_deleted\",\"event_id\":\"00065a1d-7fa8-ac80-0000-000101000020\",\"pre_event_id\":\"00065a1d-7fa8-a898-0000-000100000020\",\"order_source\":\"orderbook\"}","recorded_unix_us":1787932602740932}
{"message":"{\"data\":{\"id\":2044303883837446,\"id_str\":\"2044303883837446\",\"order_type\":0,\"order_subtype\":5,\"datetime\":\"1787932603\",\"microtimestamp\":\"1787932602576000\",\"amount\":0.00140266,\"amount_str\":\"0.00140266\",\"amount_traded\":\"0\",\"amount_at_create\":\"0.00140266\",\"price\":70666.76,\"price_str\":\"70666.76\",\"is_liquidation\":false},\"channel\":\"live_orders_btcusd\",\"event\":\"order_deleted\",\"event_id\":\"00065a1d-7fa8-ac80-0001-000102000020\",\"pre_event_id\":\"00065a1d-7fa8-ac80-0000-000101000020\",\"order_source\":\"orderbook\"}","recorded_unix_us":1787932602741191}
{"message":"{\"data\":{\"id\":2044303883956229,\"id_str\":\"2044303883956229\",\"order_type\":0,\"order_subtype\":5,\"datetime\":\"1787932603\",\"microtimestamp\":\"1787932602576000\",\"amount\":12.76418733,\"amount_str\":\"12.76418733\",\"amount_traded\":\"0\",\"amount_at_create\":\"12.76418733\",\"price\":78344.19,\"price_str\":\"78344.19\",\"is_liquidation\":false},\"channel\":\"live_orders_btcusd\",\"event\":\"order_created\",\"event_id\":\"00065a1d-7fa8-ac80-0002-000103000020\",\"pre_event_id\":\"00065a1d-7fa8-ac80-0001-000102000020\",\"order_source\":\"orderbook\"}","recorded_unix_us":1787932602741245}
{"message":"{\"data\":{\"id\":2044303883960321,\"id_str\":\"2044303883960321\",\"order_type\":1,\"order_subtype\":4,\"datetime\":\"1787932603\",\"microtimestamp\":\"1787932602578000\",\"amount\":0.02791,\"amount_str\":\"0.02791000\",\"amount_traded\":\"0\",\"amount_at_create\":\"0.02791000\",\"price\":78513.4,\"price_str\":\"78513.40\",\"is_liquidation\":false},\"channel\":\"live_orders_btcusd\",\"event\":\"order_created\",\"event_id\":\"00065a1d-7fa8-b450-0000-000100000020\",\"pre_event_id\":\"00065a1d-7fa8-ac80-0002-000103000020\",\"order_source\":\"orderbook\"}","recorded_unix_us":1787932602741361}
{"message":"{\"data\":{\"id\":2044303883960321,\"id_str\":\"2044303883960321\",\"order_type\":1,\"order_subtype\":4,\"datetime\":\"1787932603\",\"microtimestamp\":\"1787932602578000\",\"amount\":0,\"amount_str\":\"0\",\"amount_traded\":\"0.02791000\",\"amount_at_create\":\"0.02791000\",\"price\":78522.63,\"price_str\":\"78522.63\",\"is_liquidation\":false},\"channel\":\"live_orders_btcusd\",\"event\":\"order_deleted\",\"event_id\":\"00065a1d-7fa8-b450-0001-000101000020\",\"pre_event_id\":\"00065a1d-7fa8-b450-0000-000100000020\",\"order_source\":\"orderbook\"}","recorded_unix_us":1787932602741395}
{"message":"{\"data\":{\"id\":2044303819288576,\"id_str\":\"2044303819288576\",\"order_type\":0,\"order_subtype\":5,\"datetime\":\"1787932603\",\"microtimestamp\":\"1787932602578000\",\"amount\":0.03222098,\"amount_str\":\"0.03222098\",\"amount_traded\":\"0.02791000\",\"amount_at_create\":\"0.07984607\",\"price\":78522.63,\"price_str\":\"78522.63\",\"is_liquidation\":false},\"channel\":\"live_orders_btcusd\",\"event\":\"order_changed\",\"event_id\":\"00065a1d-7fa8-b450-0002-000102000020\",\"pre_event_id\":\"00065a1d-7fa8-b450-0001-000101000020\",\"order_source\":\"orderbook\"}","recorded_unix_us":1787932602741424}
{"message":"{\"data\":{\"id\":2044303882268672,\"id_str\":\"2044303882268672\",\"order_type\":0,\"order_subtype\":5,\"datetime\":\"1787932603\",\"microtimestamp\":\"1787932602579000\",\"amount\":0.595025,\"amount_str\":\"0.595025\",\"amount_traded\":\"0\",\"amount_at_create\":\"0.595025\",\"price\":2480.16,\"price_str\":\"2480.16\",\"is_liquidation\":false},\"channel\":\"live_orders_ethusd\",\"event\":\"order_deleted\",\"event_id\":\"00065a1d-7fa8-b838-0000-001201000020\",\"pre_event_id\":\"00065a1d-7fa8-9510-0000-001200000020\",\"order_source\":\"orderbook\"}","recorded_unix_us":1787932602741576}
{"message":"{\"data\":{\"id\":2044303883968513,\"id_str\":\"2044303883968513\",\"order_type\":0,\"order_subtype\":5,\"datetime\":\"1787932603\",\"microtimestamp\":\"1787932602579000\",\"amount\":1.27757154,\"amount_str\":\"1.27757154\",\"amount_traded\":\"0\",\"amount_at_create\":\"1.27757154\",\"price\":78273.5,\"price_str\":\"78273.50\",\"is_liquidation\":false},\"channel\":\"live_orders_btcusd\",\"event\":\"order_created\",\"event_id\":\"00065a1d-7fa8-b838-0000-000103000020\",\"pre_event_id\":\"00065a1d-7fa8-b450-0002-000102000020\",\"order_source\":\"orderbook\"}","recorded_unix_us":1787932602741623}
{"message":"{\"data\":{\"id\":2044303883968516,\"id_str\":\"2044303883968516\",\"order_type\":0,\"order_subtype\":5,\"datetime\":\"1787932603\",\"microtimestamp\":\"1787932602579000\",\"amount\":0.007,\"amount_str\":\"0.007000\",\"amount_traded\":\"0\",\"amount_at_create\":\"0.007000\",\"price\":2180.54,\"price_str\":\"2180.54\",\"is_liquidation\":false},\"channel\":\"live_orders_ethusd\",\"event\":\"order_created\",\"event_id\":\"00065a1d-7fa8-b838-0001-001202000020\",\"pre_event_id\":\"00065a1d-7fa8-b838-0000-001201000020\",\"order_source\":\"orderbook\"}","recorded_unix_us":1787932602741861}
{"message":"{\"data\":{\"id\":2044303883984900,\"id_str\":\"2044303883984900\",\"order_type\":1,\"order_subtype\":5,\"datetime\":\"1787932603\",\"microtimestamp\":\"1787932602584000\",\"amount\":12.087822,\"amount_str\":\"12.087822\",\"amount_traded\":\"0\",\"amount_at_create\":\"12.087822\",\"price\":2481.84,\"price_str\":\"2481.84\",\"is_liquidation\":false},\"channel\":\"live_orders_ethusd\",\"event\":\"order_created\",\"event_id\":\"00065a1d-7fa8-cbc0-0000-001203000020\",\"pre_event_id\":\"00065a1d-7fa8-b838-0001-001202000020\",\"order_source\":\"orderbook\"}","recorded_unix_us":1787932602741893}
{"message":"{\"data\":{\"id\":2044303883984903,\"id_str\":\"2044303883984903\",\"order_type\":1,\"order_subtype\":5,\"datetime\":\"1787932603\",\"microtimestamp\":\"1787932602584000\",\"amount\":0.06310787,\"amount_str\":\"0.06310787\",\"amount_traded\":\"0\",\"amount_at_create\":\"0.06310787\",\"price\":78521.6,\"price_str\":\"78521.60\",\"is_liquidation\":false},\"channel\":\"live_orders_btcusd\",\"event\":\"order_created\",\"event_id\":\"00065a1d-7fa8-cbc0-0000-000100000020\",\"pre_event_id\":\"00065a1d-7fa8-b838-0000-000103000020\",\"order_source\":\"orderbook\"}","recorded_unix_us":1787932602742008}
{"message":"{\"data\":{\"id\":2044303883984903,\"id_str\":\"2044303883984903\",\"order_type\":1,\"order_subtype\":5,\"datetime\":\"1787932603\",\"microtimestamp\":\"1787932602584000\",\"amount\":0.06310787,\"amount_str\":\"0.06310787\",\"amount_traded\":\"0\",\"amount_at_create\":\"0.06310787\",\"price\":78521.6,\"price_str\":\"78521.60\",\"is_liquidation\":false},\"channel\":\"live_orders_btcusd\",\"event\":\"order_deleted\",\"event_id\":\"00065a1d-7fa8-cbc0-0001-000101000020\",\"pre_event_id\":\"00065a1d-7fa8-cbc0-0000-000100000020\",\"order_source\":\"orderbook\"}","recorded_unix_us":1787932602742042}
{"message":"{\"data\":{\"id\":2044303883988997,\"id_str\":\"2044303883988997\",\"order_type\":1,\"order_subtype\":5,\"datetime\":\"1787932603\",\"microtimestamp\":\"1787932602584000\",\"amount\":12.086444,\"amount_str\":\"12.086444\",\"amount_traded\":\"0\",\"amount_at_create\":\"12.086444\",\"price\":2482.12,\"price_str\":\"2482.12\",\"is_liquidation\":false},\"channel\":\"live_orders_ethusd\",\"event\":\"order_created\",\"event_id\":\"00065a1d-7fa8-cbc0-0001-001200000020\",\"pre_event_id\":\"00065a1d-7fa8-cbc0-0000-001203000020\",\"order_source\":\"orderbook\"}","recorded_unix_us":1787932602742071}
{"message":"{\"data\":{\"id\":2044303883374610,\"id_str\":\"2044303883374610\",\"order_type\":0,\"order_subtype\":5,\"datetime\":\"1787932603\",\"microtimestamp\":\"1787932602585000\",\"amount\":0.403094,\"amount_str\":\"0.403094\",\"amount_traded\":\"0\",\"amount_at_create\":\"0.403094\",\"price\":2480.02,\"price_str\":\"2480.02\",\"is_liquidation\":false},\"channel\":\"live_orders_ethusd\",\"event\":\"order_deleted\",\"event_id\":\"00065a1d-7fa8-cfa8-0000-001201000020\",\"pre_event_id\":\"00065a1d-7fa8-cbc0-0001-001200000020\",\"order_source\":\"orderbook\"}","recorded_unix_us":1787932602742174}
{"message":"{\"data\":{\"id\":2044303884001280,\"id_str\":\"2044303884001280\",\"order_type\":1,\"order_subtype\":5,\"datetime\":\"1787932603\",\"microtimestamp\":\"1787932602587000\",\"amount\":4.028412,\"amount_str\":\"4.028412\",\"amount_traded\":\"0\",\"amount_at_create\":\"4.028412\",\"price\":2482.37,\"price_str\":\"2482.37\",\"is_liquidation\":false},\"channel\":\"live_orders_ethusd\",\"event\":\"order_created\",\"event_id\":\"00065a1d-7fa8-d778-0000-001202000020\",\"pre_event_id\":\"00065a1d-7fa8-cfa8-0000-001201000020\",\"order_source\":\"orderbook\"}","recorded_unix_us":1787932602742263}
{"message":"{\"data\":{\"id\":2044303884005376,\"id_str\":\"2044303884005376\",\"order_type\":1,\"order_subtype\":5,\"datetime\":\"1787932603\",\"microtimestamp\":\"1787932602588000\",\"amount\":4.027018,\"amount_str\":\"4.027018\",\"amount_traded\":\"0\",\"amount_at_create\":\"4.027018\",\"price\":2483.23,\"price_str\":\"2483.23\",\"is_liquidation\":false},\"channel\":\"live_orders_ethusd\",\"event\":\"order_created\",\"event_id\":\"00065a1d-7fa8-db60-0000-001203000020\",\"pre_event_id\":\"00065a1d-7fa8-d778-0000-001202000020\",\"order_source\":\"orderbook\"}","recorded_unix_us":1787932602742356}
{"message":"{\"data\":{\"id\":2044303884005377,\"id_str\":\"2044303884005377\",\"order_type\":1,\"order_subtype\":5,\"datetime\":\"1787932603\",\"microtimestamp\":\"1787932602588000\",\"amount\":0.1,\"amount_str\":\"0.10000000\",\"amount_traded\":\"0\",\"amount_at_create\":\"0.10000000\",\"price\":78522.62,\"price_str\":\"78522.62\",\"is_liquidation\":false},\"channel\":\"live_orders_btcusd\",\"event\":\"order_created\",\"event_id\":\"00065a1d-7fa8-db60-0000-000102000020\",\"pre_event_id\":\"00065a1d-7fa8-cbc0-0001-000101000020\",\"order_source\":\"orderbook\"}","recorded_unix_us":1787932602742469}
{"message":"{\"data\":{\"id\":2044303884005377,\"id_str\":\"2044303884005377\",\"order_type\":1,\"order_subtype\":5,\"datetime\":\"1787932603\",\"microtimestamp\":\"1787932602588000\",\"amount\":0.1,\"amount_str\":\"0.10000000\",\"amount_traded\":\"0\",\"amount_at_create\":\"0.10000000\",\"price\":78522.62,\"price_str\":\"78522.62\",\"is_liquidation\":false},\"channel\":\"live_orders_btcusd\",\"event\":\"order_deleted\",\"event_id\":\"00065a1d-7fa8-db60-0001-000103000020\",\"pre_event_id\":\"00065a1d-7fa8-db60-0000-000102000020\",\"order_source\":\"orderbook\"}","recorded_unix_us":1787932602742504}
{"message":"{\"data\":{\"id\":2044303884009473,\"id_str\":\"2044303884009473\",\"order_type\":1,\"order_subtype\":5,\"datetime\":\"1787932603\",\"microtimestamp\":\"1787932602589000\",\"amount\":10.06507,\"amount_str\":\"10.065070\",\"amount_traded\":\"0\",\"amount_at_create\":\"10.065070\",\"price\":2483.84,\"price_str\":\"2483.84\",\"is_liquidation\":false},\"channel\":\"live_orders_ethusd\",\"event\":\"order_created\",\"event_id\":\"00065a1d-7fa8-df48-0000-001200000020\",\"pre_event_id\":\"00065a1d-7fa8-db60-0000-001203000020\",\"order_source\":\"orderbook\"}","recorded_unix_us":1787932602742595}
{"message":"{\"data\":{\"id\":2044303884009474,\"id_str\":\"2044303884009474\",\"order_type\":1,\"order_subtype\":5,\"datetime\":\"1787932603\",\"microtimestamp\":\"1787932602589000\",\"amount\":10.057184,\"amount_str\":\"10.057184\",\"amount_traded\":\"0\",\"amount_at_create\":\"10.057184\",\"price\":2485.79,\"price_str\":\"2485.79\",\"is_liquidation\":false},\"channel\":\"live_orders_ethusd\",\"event\":\"order_created\",\"event_id\":\"00065a1d-7fa8-df48-0001-001201000020\",\"pre_event_id\":\"00065a1d-7fa8-df48-0000-001200000020\",\"order_source\":\"orderbook\"}","recorded_unix_us":1787932602742717}
{"message":"{\"data\":{\"id\":2044303884009475,\"id_str\":\"2044303884009475\",\"order_type\":0,\"order_subtype\":5,\"datetime\":\"1787932603\",\"microtimestamp\":\"1787932602590000\",\"amount\":0.598466,\"amount_str\":\"0.598466\",\"amount_traded\":\"0\",\"amount_at_create\":\"0.598466\",\"price\":2480.22,\"price_str\":\"2480.22\",\"is_liquidation\":false},\"channel\":\"live_orders_ethusd\",\"event\":\"order_created\",\"event_id\":\"00065a1d-7fa8-e330-0000-001202000020\",\"pre_event_id\":\"00065a1d-7fa8-df48-0001-001201000020\",\"order_source\":\"orderbook\"}","recorded_unix_us":1787932602742749}
{"message":"{\"data\":{\"id\":2044303884013568,\"id_str\":\"2044303884013568\",\"order_type\":1,\"order_subtype\":5,\"datetime\":\"1787932603\",\"microtimestamp\":\"1787932602591000\",\"amount\":20.088574,\"amount_str\":\"20.088574\",\"amount_traded\":\"0\",\"amount_at_create\":\"20.088574\",\"price\":2488.98,\"price_str\":\"2488.98\",\"is_liquidation\":false},\"channel\":\"live_orders_ethusd\",\"event\":\"order_created\",\"event_id\":\"00065a1d-7fa8-e718-0000-001203000020\",\"pre_event_id\":\"00065a1d-7fa8-e330-0000-001202000020\",\"order_source\":\"orderbook\"}","recorded_unix_us":1787932602742849}
{"message":"{\"data\":{\"id\":2044303884017666,\"id_str\":\"2044303884017666\",\"order_type\":1,\"order_subtype\":5,\"datetime\":\"1787932603\",\"microtimestamp\":\"1787932602591000\",\"amount\":20.097242,\"amount_str\":\"20.097242\",\"amount_traded\":\"0\",\"amount_at_create\":\"20.097242\",\"price\":2487.91,\"price_str\":\"2487.91\",\"is_liquidation\":false},\"channel\":\"live_orders_ethusd\",\"event\":\"order_created\",\"event_id\":\"00065a1d-7fa8-e718-0001-001200000020\",\"pre_event_id\":\"00065a1d-7fa8-e718-0000-001203000020\",\"order_source\":\"orderbook\"}","recorded_unix_us":1787932602742968}
{"message":"{\"data\":{\"id\":2044303884025861,\"id_str\":\"2044303884025861\",\"order_type\":1,\"order_subtype\":5,\"datetime\":\"1787932603\",\"microtimestamp\":\"1787932602594000\",\"amount\":40.09205,\"amount_str\":\"40.092050\",\"amount_traded\":\"0\",\"amount_at_create\":\"40.092050\",\"price\":2494.27,\"price_str\":\"2494.27\",\"is_liquidation\":false},\"channel\":\"live_orders_ethusd\",\"event\":\"order_created\",\"event_id\":\"00065a1d-7fa8-f2d0-0000-001201000020\",\"pre_event_id\":\"00065a1d-7fa8-e718-0001-001200000020\",\"order_source\":\"orderbook\"}","recorded_unix_us":1787932602743053}
{"message":"{\"data\":{\"id\":2044303884025862,\"id_str\":\"2044303884025862\",\"order_type\":1,\"order_subtype\":5,\"datetime\":\"1787932603\",\"microtimestamp\":\"1787932602594000\",\"amount\":39.969006,\"amount_str\":\"39.969006\",\"amount_traded\":\"0\",\"amount_at_create\":\"39.969006\",\"price\":2501.94,\"price_str\":\"2501.94\",\"is_liquidation\":false},\"channel\":\"live_orders_ethusd\",\"event\":\"order_created\",\"event_id\":\"00065a1d-7fa8-f2d0-0001-001202000020\",\"pre_event_id\":\"00065a1d-7fa8-f2d0-0000-001201000020\",\"order_source\":\"orderbook\"}","recorded_unix_us":1787932602743283}
{"message":"{\"data\":{\"id\":2044303882784773,\"id_str\":\"2044303882784773\",\"order_type\":0,\"order_subtype\":5,\"datetime\":\"1787932603\",\"microtimestamp\":\"1787932602595000\",\"amount\":0.26750492,\"amount_str\":\"0.26750492\",\"amount_traded\":\"0\",\"amount_at_create\":\"0.26750492\",\"price\":78485.89,\"price_str\":\"78485.89\",\"is_liquidation\":false},\"channel\":\"live_orders_btcusd\",\"event\":\"order_deleted\",\"event_id\":\"00065a1d-7fa8-f6b8-0000-000100000020\",\"pre_event_id\":\"00065a1d-7fa8-db60-0001-000103000020\",\"order_source\":\"orderbook\"}","recorded_unix_us":1787932602743314}
{"message":"{\"data\":{\"id\":2044303884034048,\"id_str\":\"2044303884034048\",\"order_type\":0,\"order_subtype\":5,\"datetime\":\"1787932603\",\"microtimestamp\":\"1787932602595000\",\"amount\":0.26750492,\"amount_str\":\"0.26750492\",\"amount_traded\":\"0\",\"amount_at_create\":\"0.26750492\",\"price\":78485.89,\"price_str\":\"78485.89\",\"is_liquidation\":false},\"channel\":\"live_orders_btcusd\",\"event\":\"order_created\",\"event_id\":\"00065a1d-7fa8-f6b8-0001-000101000020\",\"pre_event_id\":\"00065a1d-7fa8-f6b8-0000-000100000020\",\"order_source\":\"orderbook\"}","recorded_unix_us":1787932602743340}
{"message":"{\"data\":{\"id\":2044303884034049,\"id_str\":\"2044303884034049\",\"order_type\":0,\"order_subtype\":5,\"datetime\":\"1787932603\",\"microtimestamp\":\"1787932602595000\",\"amount\":0.403091,\"amount_str\":\"0.403091\",\"amount_traded\":\"0\",\"amount_at_create\":\"0.403091\",\"price\":2480.1,\"price_str\":\"2480.10\",\"is_liquidation\":false},\"channel\":\"live_orders_ethusd\",\"event\":\"order_created\",\"event_id\":\"00065a1d-7fa8-f6b8-0000-001203000020\",\"pre_event_id\":\"00065a1d-7fa8-f2d0-0001-001202000020\",\"order_source\":\"orderbook\"}","recorded_unix_us":1787932602743365}
{"message":"{\"data\":{\"id\":2044303884042241,\"id_str\":\"2044303884042241\",\"order_type\":0,\"order_subtype\":5,\"datetime\":\"1787932603\",\"microtimestamp\":\"1787932602598000\",\"amount\":12.095621,\"amount_str\":\"12.095621\",\"amount_traded\":\"0\",\"amount_at_create\":\"12.095621\",\"price\":2480.23,\"price_str\":\"2480.23\",\"is_liquidation\":false},\"channel\":\"live_orders_ethusd\",\"event\":\"order_created\",\"event_id\":\"00065a1d-7fa9-0270-0000-001200000020\",\"pre_event_id\":\"00065a1d-7fa8-f6b8-0000-001203000020\",\"order_source\":\"orderbook\"}","recorded_unix_us":1787932602743489}
{"message":"{\"data\":{\"id\":2044303884046336,\"id_str\":\"2044303884046336\",\"order_type\":1,\"order_subtype\":5,\"datetime\":\"1787932603\",\"microtimestamp\":\"1787932602598000\",\"amount\":1.271772,\"amount_str\":\"1.27177200\",\"amount_traded\":\"0\",\"amount_at_create\":\"1.27177200\",\"price\":78630.45,\"price_str\":\"78630.45\",\"is_liquidation\":false},\"channel\":\"live_orders_btcusd\",\"event\":\"order_created\",\"event_id\":\"00065a1d-7fa9-0270-0000-000102000020\",\"pre_event_id\":\"00065a1d-7fa8-f6b8-0001-000101000020\",\"order_source\":\"orderbook\"}","recorded_unix_us":1787932602743521}
{"message":"{\"data\":{\"id\":2044303884050432,\"id_str\":\"2044303884050432\",\"order_type\":0,\"order_subtype\":5,\"datetime\":\"1787932603\",\"microtimestamp\":\"1787932602599000\",\"amount\":12.096984,\"amount_str\":\"12.096984\",\"amount_traded\":\"0\",\"amount_at_create\":\"12.096984\",\"price\":2479.95,\"price_str\":\"2479.95\",\"is_liquidation\":false},\"channel\":\"live_orders_ethusd\",\"event\":\"order_created\",\"event_id\":\"00065a1d-7fa9-0658-0000-001201000020\",\"pre_event_id\":\"00065a1d-7fa9-0270-0000-001200000020\",\"order_source\":\"orderbook\"}","recorded_unix_us":1787932602743813}
{"message":"{\"data\":{\"id\":2044303884050433,\"id_str\":\"2044303884050433\",\"order_type\":0,\"order_subtype\":5,\"datetime\":\"1787932603\",\"microtimestamp\":\"1787932602599000\",\"amount\":4.032745,\"amount_str\":\"4.032745\",\"amount_traded\":\"0\",\"amount_at_create\":\"4.032745\",\"price\":2479.7,\"price_str\":\"2479.70\",\"is_liquidation\":false},\"channel\":\"live_orders_ethusd\",\"event\":\"order_created\",\"event_id\":\"00065a1d-7fa9-0658-0001-001202000020\",\"pre_event_id\":\"00065a1d-7fa9-0658-0000-001201000020\",\"order_source\":\"orderbook\"}","recorded_unix_us":1787932602743842}
{"message":"{\"data\":{\"id\":2044303884054532,\"id_str\":\"2044303884054532\",\"order_type\":1,\"order_subtype\":5,\"datetime\":\"1787932603\",\"microtimestamp\":\"1787932602601000\",\"amount\":1.26842789,\"amount_str\":\"1.26842789\",\"amount_traded\":\"0\",\"amount_at_create\":\"1.26842789\",\"price\":78837.75,\"price_str\":\"78837.75\",\"is_liquidation\":false},\"channel\":\"live_orders_btcusd\",\"event\":\"order_created\",\"event_id\":\"00065a1d-7fa9-0e28-0000-000103000020\",\"pre_event_id\":\"00065a1d-7fa9-0270-0000-000102000020\",\"order_source\":\"orderbook\"}","recorded_unix_us":1787932602743864}
{"message":"{\"data\":{\"id\":2044303884058625,\"id_str\":\"2044303884058625\",\"order_type\":0,\"order_subtype\":5,\"datetime\":\"1787932603\",\"microtimestamp\":\"1787932602601000\",\"amount\":1.27604867,\"amount_str\":\"1.27604867\",\"amount_traded\":\"0\",\"amount_at_create\":\"1.27604867\",\"price\":78366.91,\"price_str\":\"78366.91\",\"is_liquidation\":false},\"channel\":\"live_orders_btcusd\",\"event\":\"order_created\",\"event_id\":\"00065a1d-7fa9-0e28-0001-000100000020\",\"pre_event_id\":\"00065a1d-7fa9-0e28-0000-000103000020\",\"order_source\":\"orderbook\"}","recorded_unix_us":1787932602743885}
{"message":"{\"data\":{\"id\":2044303884066816,\"id_str\":\"2044303884066816\",\"order_type\":0,\"order_subtype\":4,\"datetime\":\"1787932603\",\"microtimestamp\":\"1787932602603000\",\"amount\":0.00006631,\"amount_str\":\"0.00006631\",\"amount_traded\":\"0\",\"amount_at_create\":\"0.00006631\",\"price\":76166.96,\"price_str\":\"76166.96\",\"is_liquidation\":false},\"channel\":\"live_orders_btcusd\",\"event\":\"order_created\",\"event_id\":\"00065a1d-7fa9-15f8-0000-000101000020\",\"pre_event_id\":\"00065a1d-7fa9-0e28-0001-000100000020\",\"order_source\":\"orderbook\"}","recorded_unix_us":1787932602743909}
{"message":"{\"data\":{\"id\":2044303884066816,\"id_str\":\"2044303884066816\",\"order_type\":0,\"order_subtype\":4,\"datetime\":\"1787932603\",\"microtimestamp\":\"1787932602603000\",\"amount\":0.00006631,\"amount_str\":\"0.00006631\",\"amount_traded\":\"0\",\"amount_at_create\":\"0.00006631\",\"price\":76166.96,\"price_str\":\"76166.96\",\"is_liquidation\":false},\"channel\":\"live_orders_btcusd\",\"event\":\"order_deleted\",\"event_id\":\"00065a1d-7fa9-15f8-0001-000102000020\",\"pre_event_id\":\"00065a1d-7fa9-15f8-0000-000101000020\",\"order_source\":\"orderbook\"}","recorded_unix_us":1787932602743930}
{"message":"{\"data\":{\"id\":2044303884066817,\"id_str\":\"2044303884066817\",\"order_type\":0,\"order_subtype\":5,\"datetime\":\"1787932603\",\"microtimestamp\":\"1787932602604000\",\"amount\":4.033601,\"amount_str\":\"4.033601\",\"amount_traded\":\"0\",\"amount_at_create\":\"4.033601\",\"price\":2479.17,\"price_str\":\"2479.17\",\"is_liquidation\":false},\"channel\":\"live_orders_ethusd\",\"event\":\"order_created\",\"event_id\":\"00065a1d-7fa9-19e0-0000-001203000020\",\"pre_event_id\":\"00065a1d-7fa9-0658-0001-001202000020\",\"order_source\":\"orderbook\"}","recorded_unix_us":1787932602743954}
{"message":"{\"data\":{\"id\":2044303884066818,\"id_str\":\"2044303884066818\",\"order_type\":0,\"order_subtype\":5,\"datetime\":\"1787932603\",\"microtimestamp\":\"1787932602604000\",\"amount\":1.27817952,\"amount_str\":\"1.27817952\",\"amount_traded\":\"0\",\"amount_at_create\":\"1.27817952\",\"price\":78236.27,\"price_str\":\"78236.27\",\"is_liquidation\":false},\"channel\":\"live_orders_btcusd\",\"event\":\"order_created\",\"event_id\":\"00065a1d-7fa9-19e0-0000-000103000020\",\"pre_event_id\":\"00065a1d-7fa9-15f8-0001-000102000020\",\"order_source\":\"orderbook\"}","recorded_unix_us":1787932602743976}
{"message":"{\"data\":{\"id\":2044303884079105,\"id_str\":\"2044303884079105\",\"order_type\":0,\"order_subtype\":5,\"datetime\":\"1787932603\",\"microtimestamp\":\"1787932602606000\",\"amount\":10.090138,\"amount_str\":\"10.090138\",\"amount_traded\":\"0\",\"amount_at_create\":\"10.090138\",\"price\":2477.66,\"price_str\":\"2477.66\",\"is_liquidation\":false},\"channel\":\"live_orders_ethusd\",\"event\":\"order_created\",\"event_id\":\"00065a1d-7fa9-21b0-0000-001200000020\",\"pre_event_id\":\"00065a1d-7fa9-19e0-0000-001203000020\",\"order_source\":\"orderbook\"}","recorded_unix_us":1787932602744181}
{"message":"{\"data\":{\"id\":2044303884079107,\"id_str\":\"2044303884079107\",\"order_type\":1,\"order_subtype\":5,\"datetime\":\"1787932603\",\"microtimestamp\":\"1787932602607000\",\"amount\":0.00254699,\"amount_str\":\"0.00254699\",\"amount_traded\":\"0\",\"amount_at_create\":\"0.00254699\",\"price\":78524.12,\"price_str\":\"78524.12\",\"is_liquidation\":false},\"channel\":\"live_orders_btcusd\",\"event\":\"order_created\",\"event_id\":\"00065a1d-7fa9-2598-0000-000100000020\",\"pre_event_id\":\"00065a1d-7fa9-19e0-0000-000103000020\",\"order_source\":\"orderbook\"}","recorded_unix_us":1787932602744212}
{"message":"{\"data\":{\"id\":2044303884091394,\"id_str\":\"2044303884091394\",\"order_type\":0,\"order_subtype\":5,\"datetime\":\"1787932603\",\"microtimestamp\":\"1787932602610000\",\"amount\":10.095101,\"amount_str\":\"10.095101\",\"amount_traded\":\"0\",\"amount_at_create\":\"10.095101\",\"price\":2476.44,\"price_str\":\"2476.44\",\"is_liquidation\":false},\"channel\":\"live_orders_ethusd\",\"event\":\"order_created\",\"event_id\":\"00065a1d-7fa9-3150-0000-001201000020\",\"pre_event_id\":\"00065a1d-7fa9-21b0-0000-001200000020\",\"order_source\":\"orderbook\"}","recorded_unix_us":1787932602744235}
{"message":"{\"data\":{\"id\":2044303884095493,\"id_str\":\"2044303884095493\",\"order_type\":0,\"order_subtype\":5,\"datetime\":\"1787932603\",\"microtimestamp\":\"1787932602611000\",\"amount\":20.204386,\"amount_str\":\"20.204386\",\"amount_traded\":\"0\",\"amount_at_create\":\"20.204386\",\"price\":2474.71,\"price_str\":\"2474.71\",\"is_liquidation\":false},\"channel\":\"live_orders_ethusd\",\"event\":\"order_created\",\"event_id\":\"00065a1d-7fa9-3538-0000-001202000020\",\"pre_event_id\":\"00065a1d-7fa9-3150-0000-001201000020\",\"order_source\":\"orderbook\"}","recorded_unix_us":1787932602744300}
{"message":"{\"data\":{\"id\":2044303884099584,\"id_str\":\"2044303884099584\",\"order_type\":0,\"order_subtype\":5,\"datetime\":\"1787932603\",\"microtimestamp\":\"1787932602612000\",\"amount\":40.528033,\"amount_str\":\"40.528033\",\"amount_traded\":\"0\",\"amount_at_create\":\"40.528033\",\"price\":2467.42,\"price_str\":\"2467.42\",\"is_liquidation\":false},\"channel\":\"live_orders_ethusd\",\"event\":\"order_created\",\"event_id\":\"00065a1d-7fa9-3920-0000-001203000020\",\"pre_event_id\":\"00065a1d-7fa9-3538-0000-001202000020\",\"order_source\":\"orderbook\"}","recorded_unix_us":1787932602744324}
{"message":"{\"data\":{\"id\":2044303884099585,\"id_str\":\"2044303884099585\",\"order_type\":0,\"order_subtype\":5,\"datetime\":\"1787932603\",\"microtimestamp\":\"1787932602612000\",\"amount\":40.650432,\"amount_str\":\"40.650432\",\"amount_traded\":\"0\",\"amount_at_create\":\"40.650432\",\"price\":2459.99,\"price_str\":\"2459.99\",\"is_liquidation\":false},\"channel\":\"live_orders_ethusd\",\"event\":\"order_created\",\"event_id\":\"00065a1d-7fa9-3920-0001-001200000020\",\"pre_event_id\":\"00065a1d-7fa9-3920-0000-001203000020\",\"order_source\":\"orderbook\"}","recorded_unix_us":1787932602744430}
{"message":"{\"data\":{\"id\":2044303884132354,\"id_str\":\"2044303884132354\",\"order_type\":1,\"order_subtype\":5,\"datetime\":\"1787932603\",\"microtimestamp\":\"1787932602620000\",\"amount\":0.1,\"amount_str\":\"0.10000000\",\"amount_traded\":\"0\",\"amount_at_create\":\"0.10000000\",\"price\":78522.63,\"price_str\":\"78522.63\",\"is_liquidation\":false},\"channel\":\"live_orders_btcusd\",\"event\":\"order_created\",\"event_id\":\"00065a1d-7fa9-5860-0000-000101000020\",\"pre_event_id\":\"00065a1d-7fa9-2598-0000-000100000020\",\"order_source\":\"orderbook\"}","recorded_unix_us":1787932602744568}
{"message":"{\"data\":{\"id\":2044303884132354,\"id_str\":\"2044303884132354\",\"order_type\":1,\"order_subtype\":5,\"datetime\":\"1787932603\",\"microtimestamp\":\"1787932602620000\",\"amount\":0.1,\"amount_str\":\"0.10000000\",\"amount_traded\":\"0\",\"amount_at_create\":\"0.10000000\",\"price\":78522.63,\"price_str\":\"78522.63\",\"is_liquidation\":false},\"channel\":\"live_orders_btcusd\",\"event\":\"order_deleted\",\"event_id\":\"00065a1d-7fa9-5860-0001-000102000020\",\"pre_event_id\":\"00065a1d-7fa9-5860-0000-000101000020\",\"order_source\":\"orderbook\"}","recorded_unix_us":1787932602744594}
{"message":"{\"data\":{\"id\":2044303884136448,\"id_str\":\"2044303884136448\",\"order_type\":1,\"order_subtype\":5,\"datetime\":\"1787932603\",\"microtimestamp\":\"1787932602620000\",\"amount\":0.06310787,\"amount_str\":\"0.06310787\",\"amount_traded\":\"0\",\"amount_at_create\":\"0.06310787\",\"price\":78520.22,\"price_str\":\"78520.22\",\"is_liquidation\":false},\"channel\":\"live_orders_btcusd\",\"event\":\"order_created\",\"event_id\":\"00065a1d-7fa9-5860-0002-000103000020\",\"pre_event_id\":\"00065a1d-7fa9-5860-0001-000102000020\",\"order_source\":\"orderbook\"}","recorded_unix_us":1787932602744616}
{"message":"{\"data\":{\"id\":2044303884136448,\"id_str\":\"2044303884136448\",\"order_type\":1,\"order_subtype\":5,\"datetime\":\"1787932603\",\"microtimestamp\":\"1787932602620000\",\"amount\":0.06310787,\"amount_str\":\"0.06310787\",\"amount_traded\":\"0\",\"amount_at_create\":\"0.06310787\",\"price\":78520.22,\"price_str\":\"78520.22\",\"is_liquidation\":false},\"channel\":\"live_orders_btcusd\",\"event\":\"order_deleted\",\"event_id\":\"00065a1d-7fa9-5860-0003-000100000020\",\"pre_event_id\":\"00065a1d-7fa9-5860-0002-000103000020\",\"order_source\":\"orderbook\"}","recorded_unix_us":1787932602744698}
{"message":"{\"data\":{\"id\":2044303884140545,\"id_str\":\"2044303884140545\",\"order_type\":1,\"order_subtype\":5,\"datetime\":\"1787932603\",\"microtimestamp\":\"1787932602621000\",\"amount\":0.06310787,\"amount_str\":\"0.06310787\",\"amount_traded\":\"0\",\"amount_at_create\":\"0.06310787\",\"price\":78522.58,\"price_str\":\"78522.58\",\"is_liquidation\":false},\"channel\":\"live_orders_btcusd\",\"event\":\"order_created\",\"event_id\":\"00065a1d-7fa9-5c48-0000-000101000020\",\"pre_event_id\":\"00065a1d-7fa9-5860-0003-000100000020\",\"order_source\":\"orderbook\"}","recorded_unix_us":1787932602744813}
{"message":"{\"data\":{\"id\":2044303884140545,\"id_str\":\"2044303884140545\",\"order_type\":1,\"order_subtype\":5,\"datetime\":\"1787932603\",\"microtimestamp\":\"1787932602621000\",\"amount\":0.06310787,\"amount_str\":\"0.06310787\",\"amount_traded\":\"0\",\"amount_at_create\":\"0.06310787\",\"price\":78522.58,\"price_str\":\"78522.58\",\"is_liquidation\":false},\"channel\":\"live_orders_btcusd\",\"event\":\"order_deleted\",\"event_id\":\"00065a1d-7fa9-5c48-0001-000102000020\",\"pre_event_id\":\"00065a1d-7fa9-5c48-0000-000101000020\",\"order_source\":\"orderbook\"}","recorded_unix_us":1787932602744839}
{"message":"{\"data\":{\"id\":2044303884173314,\"id_str\":\"2044303884173314\",\"order_type\":0,\"order_subtype\":5,\"datetime\":\"1787932603\",\"microtimestamp\":\"1787932602629000\",\"amount\":0.00140266,\"amount_str\":\"0.00140266\",\"amount_traded\":\"0\",\"amount_at_create\":\"0.00140266\",\"price\":70668.36,\"price_str\":\"70668.36\",\"is_liquidation\":false},\"channel\":\"live_orders_btcusd\",\"event\":\"order_created\",\"event_id\":\"00065a1d-7fa9-7b88-0000-000103000020\",\"pre_event_id\":\"00065a1d-7fa9-5c48-0001-000102000020\",\"order_source\":\"orderbook\"}","recorded_unix_us":1787932602744922}
{"message":"{\"data\":{\"id\":2044303884173315,\"id_str\":\"2044303884173315\",\"order_type\":1,\"order_subtype\":5,\"datetime\":\"1787932603\",\"microtimestamp\":\"1787932602629000\",\"amount\":4.028003,\"amount_str\":\"4.028003\",\"amount_traded\":\"0\",\"amount_at_create\":\"4.028003\",\"price\":2482.62,\"price_str\":\"2482.62\",\"is_liquidation\":false},\"channel\":\"live_orders_ethusd\",\"event\":\"order_created\",\"event_id\":\"00065a1d-7fa9-7b88-0000-001201000020\",\"pre_event_id\":\"00065a1d-7fa9-3920-0001-001200000020\",\"order_source\":\"orderbook\"}","recorded_unix_us":1787932602745037}
{"message":"{\"data\":{\"id\":2044303884173316,\"id_str\":\"2044303884173316\",\"order_type\":1,\"order_subtype\":5,\"datetime\":\"1787932603\",\"microtimestamp\":\"1787932602629000\",\"amount\":1.27145262,\"amount_str\":\"1.27145262\",\"amount_traded\":\"0\",\"amount_at_create\":\"1.27145262\",\"price\":78650.2,\"price_str\":\"78650.20\",\"is_liquidation\":false},\"channel\":\"live_orders_btcusd\",\"event\":\"order_created\",\"event_id\":\"00065a1d-7fa9-7b88-0001-000100000020\",\"pre_event_id\":\"00065a1d-7fa9-7b88-0000-000103000020\",\"order_source\":\"orderbook\"}","recorded_unix_us":1787932602745066}
{"message":"{\"data\":{\"id\":2044303884189696,\"id_str\":\"2044303884189696\",\"order_type\":0,\"order_subtype\":5,\"datetime\":\"1787932603\",\"microtimestamp\":\"1787932602634000\",\"amount\":20.215084,\"amount_str\":\"20.215084\",\"amount_traded\":\"0\",\"amount_at_create\":\"20.215084\",\"price\":2473.4,\"price_str\":\"2473.40\",\"is_liquidation\":false},\"channel\":\"live_orders_ethusd\",\"event\":\"order_created\",\"event_id\":\"00065a1d-7fa9-8f10-0000-001202000020\",\"pre_event_id\":\"00065a1d-7fa9-7b88-0000-001201000020\",\"order_source\":\"orderbook\"}","recorded_unix_us":1787932602745141}
{"message":"{\"data\":{\"id\":2044303884189704,\"id_str\":\"2044303884189704\",\"order_type\":0,\"order_subtype\":5,\"datetime\":\"1787932603\",\"microtimestamp\":\"1787932602634000\",\"amount\":1.27888333,\"amount_str\":\"1.27888333\",\"amount_traded\":\"0\",\"amount_at_create\":\"1.27888333\",\"price\":78193.21,\"price_str\":\"78193.21\",\"is_liquidation\":false},\"channel\":\"live_orders_btcusd\",\"event\":\"order_created\",\"event_id\":\"00065a1d-7fa9-8f10-0000-000101000020\",\"pre_event_id\":\"00065a1d-7fa9-7b88-0001-000100000020\",\"order_source\":\"orderbook\"}","recorded_unix_us":1787932602745241}
{"message":"{\"data\":{\"id\":2044303884189702,\"id_str\":\"2044303884189702\",\"order_type\":1,\"order_subtype\":5,\"datetime\":\"1787932603\",\"microtimestamp\":\"1787932602634000\",\"amount\":20.077182,\"amount_str\":\"20.077182\",\"amount_traded\":\"0\",\"amount_at_create\":\"20.077182\",\"price\":2490.39,\"price_str\":\"2490.39\",\"is_liquidation\":false},\"channel\":\"live_orders_ethusd\",\"event\":\"order_created\",\"event_id\":\"00065a1d-7fa9-8f10-0001-001203000020\",\"pre_event_id\":\"00065a1d-7fa9-8f10-0000-001202000020\",\"order_source\":\"orderbook\"}","recorded_unix_us":1787932602745266}
{"message":"{\"data\":{\"id\":2044303884189698,\"id_str\":\"2044303884189698\",\"order_type\":1,\"order_subtype\":5,\"datetime\":\"1787932603\",\"microtimestamp\":\"1787932602634000\",\"amount\":10.062547,\"amount_str\":\"10.062547\",\"amount_traded\":\"0\",\"amount_at_create\":\"10.062547\",\"price\":2484.47,\"price_str\":\"2484.47\",\"is_liquidation\":false},\"channel\":\"live_orders_ethusd\",\"event\":\"order_created\",\"event_id\":\"00065a1d-7fa9-8f10-0002-001200000020\",\"pre_event_id\":\"00065a1d-7fa9-8f10-0001-001203000020\",\"order_source\":\"orderbook\"}","recorded_unix_us":1787932602745342}
{"message":"{\"data\":{\"id\":2044303884189703,\"id_str\":\"2044303884189703\",\"order_type\":0,\"order_subtype\":5,\"datetime\":\"1787932603\",\"microtimestamp\":\"1787932602634000\",\"amount\":4.033204,\"amount_str\":\"4.033204\",\"amount_traded\":\"0\",\"amount_at_create\":\"4.033204\",\"price\":2479.41,\"price_str\":\"2479.41\",\"is_liquidation\":false},\"channel\":\"live_orders_ethusd\",\"event\":\"order_created\",\"event_id\":\"00065a1d-7fa9-8f10-0003-001201000020\",\"pre_event_id\":\"00065a1d-7fa9-8f10-0002-001200000020\",\"order_source\":\"orderbook\"}","recorded_unix_us":1787932602745421}
{"message":"{\"data\":{\"id\":2044303884193795,\"id_str\":\"2044303884193795\",\"order_type\":0,\"order_subtype\":5,\"datetime\":\"1787932603\",\"microtimestamp\":\"1787932602634000\",\"amount\":4.034022,\"amount_str\":\"4.034022\",\"amount_traded\":\"0\",\"amount_at_create\":\"4.034022\",\"price\":2478.91,\"price_str\":\"2478.91\",\"is_liquidation\":false},\"channel\":\"live_orders_ethusd\",\"event\":\"order_created\",\"event_id\":\"00065a1d-7fa9-8f10-0004-001202000020\",\"pre_event_id\":\"00065a1d-7fa9-8f10-0003-001201000020\",\"order_source\":\"orderbook\"}","recorded_unix_us":1787932602745545}
{"message":"{\"data\":{\"id\":2044303882551300,\"id_str\":\"2044303882551300\",\"order_type\":1,\"order_subtype\":5,\"datetime\":\"1787932603\",\"microtimestamp\":\"1787932602635000\",\"amount\":0.275637,\"amount_str\":\"0.275637\",\"amount_traded\":\"0\",\"amount_at_create\":\"0.275637\",\"price\":2481.27,\"price_str\":\"2481.27\",\"is_liquidation\":false},\"channel\":\"live_orders_ethusd\",\"event\":\"order_deleted\",\"event_id\":\"00065a1d-7fa9-92f8-0000-001203000020\",\"pre_event_id\":\"00065a1d-7fa9-8f10-0004-001202000020\",\"order_source\":\"orderbook\"}","recorded_unix_us":1787932602745631}
{"message":"{\"data\":{\"id\":2044303884189700,\"id_str\":\"2044303884189700\",\"order_type\":1,\"order_subtype\":5,\"datetime\":\"1787932603\",\"microtimestamp\":\"1787932602635000\",\"amount\":40.051178,\"amount_str\":\"40.051178\",\"amount_traded\":\"0\",\"amount_at_create\":\"40.051178\",\"price\":2496.81,\"price_str\":\"2496.81\",\"is_liquidation\":false},\"channel\":\"live_orders_ethusd\",\"event\":\"order_created\",\"event_id\":\"00065a1d-7fa9-92f8-0001-001200000020\",\"pre_event_id\":\"00065a1d-7fa9-92f8-0000-001203000020\",\"order_source\":\"orderbook\"}","recorded_unix_us":1787932602745732}
{"message":"{\"data\":{\"id\":2044303884193792,\"id_str\":\"2044303884193792\",\"order_type\":0,\"order_subtype\":5,\"datetime\":\"1787932603\",\"microtimestamp\":\"1787932602635000\",\"amount\":10.092689,\"amount_str\":\"10.092689\",\"amount_traded\":\"0\",\"amount_at_create\":\"10.092689\",\"price\":2477.04,\"price_str\":\"2477.04\",\"is_liquidation\":false},\"channel\":\"live_orders_ethusd\",\"event\":\"order_created\",\"event_id\":\"00065a1d-7fa9-92f8-0002-001201000020\",\"pre_event_id\":\"00065a1d-7fa9-92f8-0001-001200000020\",\"order_source\":\"orderbook\"}","recorded_unix_us":1787932602745821}
{"message":"{\"data\":{\"id\":2044303884193801,\"id_str\":\"2044303884193801\",\"order_type\":0,\"order_subtype\":5,\"datetime\":\"1787932603\",\"microtimestamp\":\"1787932602635000\",\"amount\":10.097738,\"amount_str\":\"10.097738\",\"amount_traded\":\"0\",\"amount_at_create\":\"10.097738\",\"price\":2475.8,\"price_str\":\"2475.80\",\"is_liquidation\":false},\"channel\":\"live_orders_ethusd\",\"event\":\"order_created\",\"event_id\":\"00065a1d-7fa9-92f8-0003-001202000020\",\"pre_event_id\":\"00065a1d-7fa9-92f8-0002-001201000020\",\"order_source\":\"orderbook\"}","recorded_unix_us":1787932602745981}
{"message":"{\"data\":{\"id\":2044303884201984,\"id_str\":\"2044303884201984\",\"order_type\":1,\"order_subtype\":5,\"datetime\":\"1787932603\",\"microtimestamp\":\"1787932602637000\",\"amount\":0.1,\"amount_str\":\"0.10000000\",\"amount_traded\":\"0\",\"amount_at_create\":\"0.10000000\",\"price\":78522.62,\"price_str\":\"78522.62\",\"is_liquidation\":false},\"channel\":\"live_orders_btcusd\",\"event\":\"order_created\",\"event_id\":\"00065a1d-7fa9-9ac8-0000-000102000020\",\"pre_event_id\":\"00065a1d-7fa9-8f10-0000-000101000020\",\"order_source\":\"orderbook\"}","recorded_unix_us":1787932602746005}
{"message":"{\"data\":{\"id\":2044303884201984,\"id_str\":\"2044303884201984\",\"order_type\":1,\"order_subtype\":5,\"datetime\":\"1787932603\",\"microtimestamp\":\"1787932602637000\",\"amount\":0.1,\"amount_str\":\"0.10000000\",\"amount_traded\":\"0\",\"amount_at_create\":\"0.10000000\",\"price\":78522.62,\"price_str\":\"78522.62\",\"is_liquidation\":false},\"channel\":\"live_orders_btcusd\",\"event\":\"order_deleted\",\"event_id\":\"00065a1d-7fa9-9ac8-0001-000103000020\",\"pre_event_id\":\"00065a1d-7fa9-9ac8-0000-000102000020\",\"order_source\":\"orderbook\"}","recorded_unix_us":1787932602746025}
{"message":"{\"data\":{\"id\":2044303884201985,\"id_str\":\"2044303884201985\",\"order_type\":0,\"order_subtype\":5,\"datetime\":\"1787932603\",\"microtimestamp\":\"1787932602637000\",\"amount\":40.568517,\"amount_str\":\"40.568517\",\"amount_traded\":\"0\",\"amount_at_create\":\"40.568517\",\"price\":2464.96,\"price_str\":\"2464.96\",\"is_liquidation\":false},\"channel\":\"live_orders_ethusd\",\"event\":\"order_created\",\"event_id\":\"00065a1d-7fa9-9ac8-0000-001203000020\",\"pre_event_id\":\"00065a1d-7fa9-92f8-0003-001202000020\",\"order_source\":\"orderbook\"}","recorded_unix_us":1787932602746045}
{"message":"{\"data\":{\"id\":2044303884271618,\"id_str\":\"2044303884271618\",\"order_type\":1,\"order_subtype\":5,\"datetime\":\"1787932603\",\"microtimestamp\":\"1787932602654000\",\"amount\":0.06310787,\"amount_str\":\"0.06310787\",\"amount_traded\":\"0\",\"amount_at_create\":\"0.06310787\",\"price\":78520.06,\"price_str\":\"78520.06\",\"is_liquidation\":false},\"channel\":\"live_orders_btcusd\",\"event\":\"order_created\",\"event_id\":\"00065a1d-7fa9-dd30-0000-000100000020\",\"pre_event_id\":\"00065a1d-7fa9-9ac8-0001-000103000020\",\"order_source\":\"orderbook\"}","recorded_unix_us":1787932602746160}
{"message":"{\"data\":{\"id\":2044303884271618,\"id_str\":\"2044303884271618\",\"order_type\":1,\"order_subtype\":5,\"datetime\":\"1787932603\",\"microtimestamp\":\"1787932602654000\",\"amount\":0.06310787,\"amount_str\":\"0.06310787\",\"amount_traded\":\"0\",\"amount_at_create\":\"0.06310787\",\"price\":78520.06,\"price_str\":\"78520.06\",\"is_liquidation\":false},\"channel\":\"live_orders_btcusd\",\"event\":\"order_deleted\",\"event_id\":\"00065a1d-7fa9-dd30-0001-000101000020\",\"pre_event_id\":\"00065a1d-7fa9-dd30-0000-000100000020\",\"order_source\":\"orderbook\"}","recorded_unix_us":1787932602746247}
{"message":"{\"data\":{\"id\":2044303884275712,\"id_str\":\"2044303884275712\",\"order_type\":1,\"order_subtype\":5,\"datetime\":\"1787932603\",\"microtimestamp\":\"1787932602654000\",\"amount\":0.06310787,\"amount_str\":\"0.06310787\",\"amount_traded\":\"0\",\"amount_at_create\":\"0.06310787\",\"price\":78522.42,\"price_str\":\"78522.42\",\"is_liquidation\":false},\"channel\":\"live_orders_btcusd\",\"event\":\"order_created\",\"event_id\":\"00065a1d-7fa9-dd30-0002-000102000020\",\"pre_event_id\":\"00065a1d-7fa9-dd30-0001-000101000020\",\"order_source\":\"orderbook\"}","recorded_unix_us":1787932602746270}
{"message":"{\"data\":{\"id\":2044303884275712,\"id_str\":\"2044303884275712\",\"order_type\":1,\"order_subtype\":5,\"datetime\":\"1787932603\",\"microtimestamp\":\"1787932602654000\",\"amount\":0.06310787,\"amount_str\":\"0.06310787\",\"amount_traded\":\"0\",\"amount_at_create\":\"0.06310787\",\"price\":78522.42,\"price_str\":\"78522.42\",\"is_liquidation\":false},\"channel\":\"live_orders_btcusd\",\"event\":\"order_deleted\",\"event_id\":\"00065a1d-7fa9-dd30-0003-000103000020\",\"pre_event_id\":\"00065a1d-7fa9-dd30-0002-000102000020\",\"order_source\":\"orderbook\"}","recorded_unix_us":1787932602746289}
{"message":"{\"data\":{\"id\":2044303884279808,\"id_str\":\"2044303884279808\",\"order_type\":1,\"order_subtype\":5,\"datetime\":\"1787932603\",\"microtimestamp\":\"1787932602656000\",\"amount\":10.059779,\"amount_str\":\"10.059779\",\"amount_traded\":\"0\",\"amount_at_create\":\"10.059779\",\"price\":2485.15,\"price_str\":\"2485.15\",\"is_liquidation\":false},\"channel\":\"live_orders_ethusd\",\"event\":\"order_created\",\"event_id\":\"00065a1d-7fa9-e500-0000-001200000020\",\"pre_event_id\":\"00065a1d-7fa9-9ac8-0000-001203000020\",\"order_source\":\"orderbook\"}","recorded_unix_us":1787932602746362}
{"message":"{\"data\":{\"id\":2044303884283904,\"id_str\":\"2044303884283904\",\"order_type\":1,\"order_subtype\":5,\"datetime\":\"1787932603\",\"microtimestamp\":\"1787932602656000\",\"amount\":4.027586,\"amount_str\":\"4.027586\",\"amount_traded\":\"0\",\"amount_at_create\":\"4.027586\",\"price\":2482.88,\"price_str\":\"2482.88\",\"is_liquidation\":false},\"channel\":\"live_orders_ethusd\",\"event\":\"order_created\",\"event_id\":\"00065a1d-7fa9-e500-0001-001201000020\",\"pre_event_id\":\"00065a1d-7fa9-e500-0000-001200000020\",\"order_source\":\"orderbook\"}","recorded_unix_us":1787932602746448}
{"message":"{\"data\":{\"id\":2044303884283905,\"id_str\":\"2044303884283905\",\"order_type\":0,\"order_subtype\":5,\"datetime\":\"1787932603\",\"microtimestamp\":\"1787932602657000\",\"amount\":20.225289,\"amount_str\":\"20.225289\",\"amount_traded\":\"0\",\"amount_at_create\":\"20.225289\",\"price\":2472.15,\"price_str\":\"2472.15\",\"is_liquidation\":false},\"channel\":\"live_orders_ethusd\",\"event\":\"order_created\",\"event_id\":\"00065a1d-7fa9-e8e8-0000-001202000020\",\"pre_event_id\":\"00065a1d-7fa9-e500-0001-001201000020\",\"order_source\":\"orderbook\"}","recorded_unix_us":1787932602746521}
{"message":"{\"data\":{\"id\":2044303884288000,\"id_str\":\"2044303884288000\",\"order_type\":1,\"order_subtype\":5,\"datetime\":\"1787932603\",\"microtimestamp\":\"1787932602657000\",\"amount\":40.010118,\"amount_str\":\"40.010118\",\"amount_traded\":\"0\",\"amount_at_create\":\"40.010118\",\"price\":2499.37,\"price_str\":\"2499.37\",\"is_liquidation\":false},\"channel\":\"live_orders_ethusd\",\"event\":\"order_created\",\"event_id\":\"00065a1d-7fa9-e8e8-0001-001203000020\",\"pre_event_id\":\"00065a1d-7fa9-e8e8-0000-001202000020\",\"order_source\":\"orderbook\"}","recorded_unix_us":1787932602746640}
{"message":"{\"data\":{\"id\":2044303884292097,\"id_str\":\"2044303884292097\",\"order_type\":1,\"order_subtype\":5,\"datetime\":\"1787932603\",\"microtimestamp\":\"1787932602658000\",\"amount\":20.063885,\"amount_str\":\"20.063885\",\"amount_traded\":\"0\",\"amount_at_create\":\"20.063885\",\"price\":2492.04,\"price_str\":\"2492.04\",\"is_liquidation\":false},\"channel\":\"live_orders_ethusd\",\"event\":\"order_created\",\"event_id\":\"00065a1d-7fa9-ecd0-0000-001200000020\",\"pre_event_id\":\"00065a1d-7fa9-e8e8-0001-001203000020\",\"order_source\":\"orderbook\"}","recorded_unix_us":1787932602746664}
{"message":"{\"data\":{\"id\":2044303884292101,\"id_str\":\"2044303884292101\",\"order_type\":0,\"order_subtype\":5,\"datetime\":\"1787932603\",\"microtimestamp\":\"1787932602659000\",\"amount\":40.609081,\"amount_str\":\"40.609081\",\"amount_traded\":\"0\",\"amount_at_create\":\"40.609081\",\"price\":2462.5,\"price_str\":\"2462.50\",\"is_liquidation\":false},\"channel\":\"live_orders_ethusd\",\"event\":\"order_created\",\"event_id\":\"00065a1d-7fa9-f0b8-0000-001201000020\",\"pre_event_id\":\"00065a1d-7fa9-ecd0-0000-001200000020\",\"order_source\":\"orderbook\"}","recorded_unix_us":1787932602746736}
{"message":"{\"data\":{\"id\":2044303884296193,\"id_str\":\"2044303884296193\",\"order_type\":0,\"order_subtype\":5,\"datetime\":\"1787932603\",\"microtimestamp\":\"1787932602660000\",\"amount\":0.5062,\"amount_str\":\"0.506200\",\"amount_traded\":\"0\",\"amount_at_create\":\"0.506200\",\"price\":2476.79,\"price_str\":\"2476.79\",\"is_liquidation\":false},\"channel\":\"live_orders_ethusd\",\"event\":\"order_created\",\"event_id\":\"00065a1d-7fa9-f4a0-0000-001202000020\",\"pre_event_id\":\"00065a1d-7fa9-f0b8-0000-001201000020\",\"order_source\":\"orderbook\"}","recorded_unix_us":1787932602746837}
{"message":"{\"data\":{\"id\":2044303884300288,\"id_str\":\"2044303884300288\",\"order_type\":1,\"order_subtype\":5,\"datetime\":\"1787932603\",\"microtimestamp\":\"1787932602660000\",\"amount\":0.1,\"amount_str\":\"0.10000000\",\"amount_traded\":\"0\",\"amount_at_create\":\"0.10000000\",\"price\":78522.63,\"price_str\":\"78522.63\",\"is_liquidation\":false},\"channel\":\"live_orders_btcusd\",\"event\":\"order_created\",\"event_id\":\"00065a1d-7fa9-f4a0-0000-000100000020\",\"pre_event_id\":\"00065a1d-7fa9-dd30-0003-000103000020\",\"order_source\":\"orderbook\"}","recorded_unix_us":1787932602746897}
{"message":"{\"data\":{\"id\":2044303884300288,\"id_str\":\"2044303884300288\",\"order_type\":1,\"order_subtype\":5,\"datetime\":\"1787932603\",\"microtimestamp\":\"1787932602660000\",\"amount\":0.1,\"amount_str\":\"0.10000000\",\"amount_traded\":\"0\",\"amount_at_create\":\"0.10000000\",\"price\":78522.63,\"price_str\":\"78522.63\",\"is_liquidation\":false},\"channel\":\"live_orders_btcusd\",\"event\":\"order_deleted\",\"event_id\":\"00065a1d-7fa9-f4a0-0001-000101000020\",\"pre_event_id\":\"00065a1d-7fa9-f4a0-0000-000100000020\",\"order_source\":\"orderbook\"}","recorded_unix_us":1787932602746921}
{"message":"{\"data\":{\"id\":2044303882612741,\"id_str\":\"2044303882612741\",\"order_type\":0,\"order_subtype\":5,\"datetime\":\"1787932603\",\"microtimestamp\":\"1787932602661000\",\"amount\":2.734871,\"amount_str\":\"2.734871\",\"amount_traded\":\"0\",\"amount_at_create\":\"2.734871\",\"price\":2480.21,\"price_str\":\"2480.21\",\"is_liquidation\":false},\"channel\":\"live_orders_ethusd\",\"event\":\"order_deleted\",\"event_id\":\"00065a1d-7fa9-f888-0000-001203000020\",\"pre_event_id\":\"00065a1d-7fa9-f4a0-0000-001202000020\",\"order_source\":\"orderbook\"}","recorded_unix_us":1787932602747036}
{"message":"{\"data\":{\"id\":2044303884357634,\"id_str\":\"2044303884357634\",\"order_type\":0,\"order_subtype\":5,\"datetime\":\"1787932603\",\"microtimestamp\":\"1787932602675000\",\"amount\":20.235437,\"amount_str\":\"20.235437\",\"amount_traded\":\"0\",\"amount_at_create\":\"20.235437\",\"price\":2470.91,\"price_str\":\"2470.91\",\"is_liquidation\":false},\"channel\":\"live_orders_ethusd\",\"event\":\"order_created\",\"event_id\":\"00065a1d-7faa-2f38-0000-001200000020\",\"pre_event_id\":\"00065a1d-7fa9-f888-0000-001203000020\",\"order_source\":\"orderbook\"}","recorded_unix_us":1787932602747058}
{"message":"{\"data\":{\"id\":2044303884365827,\"id_str\":\"2044303884365827\",\"order_type\":1,\"order_subtype\":5,\"datetime\":\"1787932603\",\"microtimestamp\":\"1787932602676000\",\"amount\":0.1,\"amount_str\":\"0.10000000\",\"amount_traded\":\"0\",\"amount_at_create\":\"0.10000000\",\"price\":78522.62,\"price_str\":\"78522.62\",\"is_liquidation\":false},\"channel\":\"live_orders_btcusd\",\"event\":\"order_created\",\"event_id\":\"00065a1d-7faa-3320-0000-000102000020\",\"pre_event_id\":\"00065a1d-7fa9-f4a0-0001-000101000020\",\"order_source\":\"orderbook\"}","recorded_unix_us":1787932602747150}
{"message":"{\"data\":{\"id\":2044303884365827,\"id_str\":\"2044303884365827\",\"order_type\":1,\"order_subtype\":5,\"datetime\":\"1787932603\",\"microtimestamp\":\"1787932602676000\",\"amount\":0.1,\"amount_str\":\"0.10000000\",\"amount_traded\":\"0\",\"amount_at_create\":\"0.10000000\",\"price\":78522.62,\"price_str\":\"78522.62\",\"is_liquidation\":false},\"channel\":\"live_orders_btcusd\",\"event\":\"order_deleted\",\"event_id\":\"00065a1d-7faa-3320-0001-000103000020\",\"pre_event_id\":\"00065a1d-7faa-3320-0000-000102000020\",\"order_source\":\"orderbook\"}","recorded_unix_us":1787932602747173}
{"message":"{\"data\":{\"id\":2044303884398598,\"id_str\":\"2044303884398598\",\"order_type\":1,\"order_subtype\":5,\"datetime\":\"1787932603\",\"microtimestamp\":\"1787932602685000\",\"amount\":0.06310787,\"amount_str\":\"0.06310787\",\"amount_traded\":\"0\",\"amount_at_create\":\"0.06310787\",\"price\":78522.57,\"price_str\":\"78522.57\",\"is_liquidation\":false},\"channel\":\"live_orders_btcusd\",\"event\":\"order_created\",\"event_id\":\"00065a1d-7faa-5648-0000-000100000020\",\"pre_event_id\":\"00065a1d-7faa-3320-0001-000103000020\",\"order_source\":\"orderbook\"}","recorded_unix_us":1787932602747269}
{"message":"{\"data\":{\"id\":2044303884398598,\"id_str\":\"2044303884398598\",\"order_type\":1,\"order_subtype\":5,\"datetime\":\"1787932603\",\"microtimestamp\":\"1787932602685000\",\"amount\":0.06310787,\"amount_str\":\"0.06310787\",\"amount_traded\":\"0\",\"amount_at_create\":\"0.06310787\",\"price\":78522.57,\"price_str\":\"78522.57\",\"is_liquidation\":false},\"channel\":\"live_orders_btcusd\",\"event\":\"order_deleted\",\"event_id\":\"00065a1d-7faa-5648-0001-000101000020\",\"pre_event_id\":\"00065a1d-7faa-5648-0000-000100000020\",\"order_source\":\"orderbook\"}","recorded_unix_us":1787932602747294}
{"message":"{\"data\":{\"id\":2044303884402688,\"id_str\":\"2044303884402688\",\"order_type\":1,\"order_subtype\":5,\"datetime\":\"1787932603\",\"microtimestamp\":\"1787932602685000\",\"amount\":0.06310787,\"amount_str\":\"0.06310787\",\"amount_traded\":\"0\",\"amount_at_create\":\"0.06310787\",\"price\":78520.21,\"price_str\":\"78520.21\",\"is_liquidation\":false},\"channel\":\"live_orders_btcusd\",\"event\":\"order_created\",\"event_id\":\"00065a1d-7faa-5648-0002-000102000020\",\"pre_event_id\":\"00065a1d-7faa-5648-0001-000101000020\",\"order_source\":\"orderbook\"}","recorded_unix_us":1787932602747377}
{"message":"{\"data\":{\"id\":2044303884402688,\"id_str\":\"2044303884402688\",\"order_type\":1,\"order_subtype\":5,\"datetime\":\"1787932603\",\"microtimestamp\":\"1787932602685000\",\"amount\":0.06310787,\"amount_str\":\"0.06310787\",\"amount_traded\":\"0\",\"amount_at_create\":\"0.06310787\",\"price\":78520.21,\"price_str\":\"78520.21\",\"is_liquidation\":false},\"channel\":\"live_orders_btcusd\",\"event\":\"order_deleted\",\"event_id\":\"00065a1d-7faa-5648-0003-000103000020\",\"pre_event_id\":\"00065a1d-7faa-5648-0002-000102000020\",\"order_source\":\"orderbook\"}","recorded_unix_us":1787932602747498}
{"message":"{\"data\":{\"id\":2044303884009475,\"id_str\":\"2044303884009475\",\"order_type\":0,\"order_subtype\":5,\"datetime\":\"1787932603\",\"microtimestamp\":\"1787932602698000\",\"amount\":0.598466,\"amount_str\":\"0.598466\",\"amount_traded\":\"0\",\"amount_at_create\":\"0.598466\",\"price\":2480.22,\"price_str\":\"2480.22\",\"is_liquidation\":false},\"channel\":\"live_orders_ethusd\",\"event\":\"order_deleted\",\"event_id\":\"00065a1d-7faa-8910-0000-001201000020\",\"pre_event_id\":\"00065a1d-7faa-2f38-0000-001200000020\",\"order_source\":\"orderbook\"}","recorded_unix_us":1787932602747520}
{"message":"{\"data\":{\"id\":2044303884464128,\"id_str\":\"2044303884464128\",\"order_type\":1,\"order_subtype\":5,\"datetime\":\"1787932603\",\"microtimestamp\":\"1787932602700000\",\"amount\":0.1,\"amount_str\":\"0.10000000\",\"amount_traded\":\"0\",\"amount_at_create\":\"0.10000000\",\"price\":78522.63,\"price_str\":\"78522.63\",\"is_liquidation\":false},\"channel\":\"live_orders_btcusd\",\"event\":\"order_created\",\"event_id\":\"00065a1d-7faa-90e0-0000-000100000020\",\"pre_event_id\":\"00065a1d-7faa-5648-0003-000103000020\",\"order_source\":\"orderbook\"}","recorded_unix_us":1787932602747628}
{"message":"{\"data\":{\"id\":2044303884464128,\"id_str\":\"2044303884464128\",\"order_type\":1,\"order_subtype\":5,\"datetime\":\"1787932603\",\"microtimestamp\":\"1787932602700000\",\"amount\":0.1,\"amount_str\":\"0.10000000\",\"amount_traded\":\"0\",\"amount_at_create\":\"0.10000000\",\"price\":78522.63,\"price_str\":\"78522.63\",\"is_liquidation\":false},\"channel\":\"live_orders_btcusd\",\"event\":\"order_deleted\",\"event_id\":\"00065a1d-7faa-90e0-0001-000101000020\",\"pre_event_id\":\"00065a1d-7faa-90e0-0000-000100000020\",\"order_source\":\"orderbook\"}","recorded_unix_us":1787932602747651}
{"message":"{\"data\":{\"id\":2044303884468224,\"id_str\":\"2044303884468224\",\"order_type\":1,\"order_subtype\":5,\"datetime\":\"1787932603\",\"microtimestamp\":\"1787932602701000\",\"amount\":5,\"amount_str\":\"5.000000\",\"amount_traded\":\"0\",\"amount_at_create\":\"5.000000\",\"price\":2481.63,\"price_str\":\"2481.63\",\"is_liquidation\":false},\"channel\":\"live_orders_ethusd\",\"event\":\"order_created\",\"event_id\":\"00065a1d-7faa-94c8-0000-001202000020\",\"pre_event_id\":\"00065a1d-7faa-8910-0000-001201000020\",\"order_source\":\"orderbook\"}","recorded_unix_us":1787932602747671}
{"message":"{\"data\":{\"id\":2044303884488705,\"id_str\":\"2044303884488705\",\"order_type\":1,\"order_subtype\":5,\"datetime\":\"1787932603\",\"microtimestamp\":\"1787932602706000\",\"amount\":0.12,\"amount_str\":\"0.12000000\",\"amount_traded\":\"0\",\"amount_at_create\":\"0.12000000\",\"price\":78544,\"price_str\":\"78544.00\",\"is_liquidation\":false},\"channel\":\"live_orders_btcusd\",\"event\":\"order_created\",\"event_id\":\"00065a1d-7faa-a850-0000-000102000020\",\"pre_event_id\":\"00065a1d-7faa-90e0-0001-000101000020\",\"order_source\":\"orderbook\"}","recorded_unix_us":1787932602747742}
{"message":"{\"data\":{\"id\":2044303884492800,\"id_str\":\"2044303884492800\",\"order_type\":0,\"order_subtype\":5,\"datetime\":\"1787932603\",\"microtimestamp\":\"1787932602707000\",\"amount\":0.00140266,\"amount_str\":\"0.00140266\",\"amount_traded\":\"0\",\"amount_at_create\":\"0.00140266\",\"price\":70668.36,\"price_str\":\"70668.36\",\"is_liquidation\":false},\"channel\":\"live_orders_btcusd\",\"event\":\"order_created\",\"event_id\":\"00065a1d-7faa-ac38-0000-000103000020\",\"pre_event_id\":\"00065a1d-7faa-a850-0000-000102000020\",\"order_source\":\"orderbook\"}","recorded_unix_us":1787932602747847}
{"message":"{\"data\":{\"id\":2044303882911744,\"id_str\":\"2044303882911744\",\"order_type\":0,\"order_subtype\":5,\"datetime\":\"1787932603\",\"microtimestamp\":\"1787932602708000\",\"amount\":0.63679235,\"amount_str\":\"0.63679235\",\"amount_traded\":\"0\",\"amount_at_create\":\"0.63679235\",\"price\":78483.04,\"price_str\":\"78483.04\",\"is_liquidation\":false},\"channel\":\"live_orders_btcusd\",\"event\":\"order_deleted\",\"event_id\":\"00065a1d-7faa-b020-0000-000100000020\",\"pre_event_id\":\"00065a1d-7faa-ac38-0000-000103000020\",\"order_source\":\"orderbook\"}","recorded_unix_us":1787932602747870}
{"message":"{\"data\":{\"id\":2044303884500993,\"id_str\":\"2044303884500993\",\"order_type\":0,\"order_subtype\":5,\"datetime\":\"1787932603\",\"microtimestamp\":\"1787932602710000\",\"amount\":0.435648,\"amount_str\":\"0.435648\",\"amount_traded\":\"0\",\"amount_at_create\":\"0.435648\",\"price\":2480.11,\"price_str\":\"2480.11\",\"is_liquidation\":false},\"channel\":\"live_orders_ethusd\",\"event\":\"order_created\",\"event_id\":\"00065a1d-7faa-b7f0-0000-001203000020\",\"pre_event_id\":\"00065a1d-7faa-94c8-0000-001202000020\",\"order_source\":\"orderbook\"}","recorded_unix_us":1787932602790053}
{"message":"{\"data\":{\"id\":2044303884513281,\"id_str\":\"2044303884513281\",\"order_type\":1,\"order_subtype\":5,\"datetime\":\"1787932603\",\"microtimestamp\":\"1787932602713000\",\"amount\":0.06310787,\"amount_str\":\"0.06310787\",\"amount_traded\":\"0\",\"amount_at_create\":\"0.06310787\",\"price\":78522.57,\"price_str\":\"78522.57\",\"is_liquidation\":false},\"channel\":\"live_orders_btcusd\",\"event\":\"order_created\",\"event_id\":\"00065a1d-7faa-c3a8-0000-000101000020\",\"pre_event_id\":\"00065a1d-7faa-b020-0000-000100000020\",\"order_source\":\"orderbook\"}","recorded_unix_us":1787932602790090}
{"message":"{\"data\":{\"id\":2044303884513281,\"id_str\":\"2044303884513281\",\"order_type\":1,\"order_subtype\":5,\"datetime\":\"1787932603\",\"microtimestamp\":\"1787932602713000\",\"amount\":0.06310787,\"amount_str\":\"0.06310787\",\"amount_traded\":\"0\",\"amount_at_create\":\"0.06310787\",\"price\":78522.57,\"price_str\":\"78522.57\",\"is_liquidation\":false},\"channel\":\"live_orders_btcusd\",\"event\":\"order_deleted\",\"event_id\":\"00065a1d-7faa-c3a8-0001-000102000020\",\"pre_event_id\":\"00065a1d-7faa-c3a8-0000-000101000020\",\"order_source\":\"orderbook\"}","recorded_unix_us":1787932602790113}
