{"message":"{\"data\":{\"id\":2044303886573578,\"id_str\":\"2044303886573578\",\"order_type\":1,\"order_subtype\":5,\"datetime\":\"1787932603\",\"microtimestamp\":\"1787932603216000\",\"amount\":0.06310787,\"amount_str\":\"0.06310787\",\"amount_traded\":\"0\",\"amount_at_create\":\"0.06310787\",\"price\":78520.07,\"price_str\":\"78520.07\",\"is_liquidation\":false},\"channel\":\"live_orders_btcusd\",\"event\":\"order_deleted\",\"event_id\":\"00065a1d-7fb2-7080-0001-000101000020\",\"pre_event_id\":\"00065a1d-7fb2-7080-0000-000100000020\",\"order_source\":\"orderbook\"}","recorded_unix_us":1787932603262226}
{"message":"{\"data\":{\"id\":2044303886577683,\"id_str\":\"2044303886577683\",\"order_type\":1,\"order_subtype\":5,\"datetime\":\"1787932603\",\"microtimestamp\":\"1787932603217000\",\"amount\":0.1,\"amount_str\":\"0.10000000\",\"amount_traded\":\"0\",\"amount_at_create\":\"0.10000000\",\"price\":78522.63,\"price_str\":\"78522.63\",\"is_liquidation\":false},\"channel\":\"live_orders_btcusd\",\"event\":\"order_created\",\"event_id\":\"00065a1d-7fb2-7468-0000-000102000020\",\"pre_event_id\":\"00065a1d-7fb2-7080-0001-000101000020\",\"order_source\":\"orderbook\"}","recorded_unix_us":1787932603267805}
{"message":"{\"data\":{\"id\":2044303886577683,\"id_str\":\"2044303886577683\",\"order_type\":1,\"order_subtype\":5,\"datetime\":\"1787932603\",\"microtimestamp\":\"1787932603217000\",\"amount\":0.1,\"amount_str\":\"0.10000000\",\"amount_traded\":\"0\",\"amount_at_create\":\"0.10000000\",\"price\":78522.63,\"price_str\":\"78522.63\",\"is_liquidation\":false},\"channel\":\"live_orders_btcusd\",\"event\":\"order_deleted\",\"event_id\":\"00065a1d-7fb2-7468-0001-000103000020\",\"pre_event_id\":\"00065a1d-7fb2-7468-0000-000102000020\",\"order_source\":\"orderbook\"}","recorded_unix_us":1787932603267891}
{"message":"{\"data\":{\"id\":2044303886577688,\"id_str\":\"2044303886577688\",\"order_type\":1,\"order_subtype\":5,\"datetime\":\"1787932603\",\"microtimestamp\":\"1787932603217000\",\"amount\":0.1,\"amount_str\":\"0.10000000\",\"amount_traded\":\"0\",\"amount_at_create\":\"0.10000000\",\"price\":78522.62,\"price_str\":\"78522.62\",\"is_liquidation\":false},\"channel\":\"live_orders_btcusd\",\"event\":\"order_created\",\"event_id\":\"00065a1d-7fb2-7468-0002-000100000020\",\"pre_event_id\":\"00065a1d-7fb2-7468-0001-000103000020\",\"order_source\":\"orderbook\"}","recorded_unix_us":1787932603267930}
{"message":"{\"data\":{\"id\":2044303886577688,\"id_str\":\"2044303886577688\",\"order_type\":1,\"order_subtype\":5,\"datetime\":\"1787932603\",\"microtimestamp\":\"1787932603217000\",\"amount\":0.1,\"amount_str\":\"0.10000000\",\"amount_traded\":\"0\",\"amount_at_create\":\"0.10000000\",\"price\":78522.62,\"price_str\":\"78522.62\",\"is_liquidation\":false},\"channel\":\"live_orders_btcusd\",\"event\":\"order_deleted\",\"event_id\":\"00065a1d-7fb2-7468-0003-000101000020\",\"pre_event_id\":\"00065a1d-7fb2-7468-0002-000100000020\",\"order_source\":\"orderbook\"}","recorded_unix_us":1787932603267960}
{"message":"{\"data\":{\"id\":2044303886417920,\"id_str\":\"2044303886417920\",\"order_type\":0,\"order_subtype\":5,\"datetime\":\"1787932603\",\"microtimestamp\":\"1787932603220000\",\"amount\":0.045102,\"amount_str\":\"0.045102\",\"amount_traded\":\"0\",\"amount_at_create\":\"0.045102\",\"price\":2480.81,\"price_str\":\"2480.81\",\"is_liquidation\":false},\"channel\":\"live_orders_ethusd\",\"event\":\"order_deleted\",\"event_id\":\"00065a1d-7fb2-8020-0000-001203000020\",\"pre_event_id\":\"00065a1d-7fb2-5cf8-0001-001202000020\",\"order_source\":\"orderbook\"}","recorded_unix_us":1787932603268091}
{"message":"{\"data\":{\"id\":2044303886422018,\"id_str\":\"2044303886422018\",\"order_type\":1,\"order_subtype\":5,\"datetime\":\"1787932603\",\"microtimestamp\":\"1787932603220000\",\"amount\":0.041276,\"amount_str\":\"0.041276\",\"amount_traded\":\"0\",\"amount_at_create\":\"0.041276\",\"price\":2480.87,\"price_str\":\"2480.87\",\"is_liquidation\":false},\"channel\":\"live_orders_ethusd\",\"event\":\"order_deleted\",\"event_id\":\"00065a1d-7fb2-8020-0001-001200000020\",\"pre_event_id\":\"00065a1d-7fb2-8020-0000-001203000020\",\"order_source\":\"orderbook\"}","recorded_unix_us":1787932603268213}
{"message":"{\"data\":{\"id\":2044303885217799,\"id_str\":\"2044303885217799\",\"order_type\":0,\"order_subtype\":5,\"datetime\":\"1787932603\",\"microtimestamp\":\"1787932603225000\",\"amount\":12.095621,\"amount_str\":\"12.095621\",\"amount_traded\":\"0\",\"amount_at_create\":\"12.095621\",\"price\":2480.23,\"price_str\":\"2480.23\",\"is_liquidation\":false},\"channel\":\"live_orders_ethusd\",\"event\":\"order_deleted\",\"event_id\":\"00065a1d-7fb2-93a8-0000-001201000020\",\"pre_event_id\":\"00065a1d-7fb2-8020-0001-001200000020\",\"order_source\":\"orderbook\"}","recorded_unix_us":1787932603268382}
{"message":"{\"data\":{\"id\":2044303885217804,\"id_str\":\"2044303885217804\",\"order_type\":0,\"order_subtype\":5,\"datetime\":\"1787932603\",\"microtimestamp\":\"1787932603225000\",\"amount\":4.032745,\"amount_str\":\"4.032745\",\"amount_traded\":\"0\",\"amount_at_create\":\"4.032745\",\"price\":2479.7,\"price_str\":\"2479.70\",\"is_liquidation\":false},\"channel\":\"live_orders_ethusd\",\"event\":\"order_deleted\",\"event_id\":\"00065a1d-7fb2-93a8-0001-001202000020\",\"pre_event_id\":\"00065a1d-7fb2-93a8-0000-001201000020\",\"order_source\":\"orderbook\"}","recorded_unix_us":1787932603268427}
{"message":"{\"data\":{\"id\":2044303885230091,\"id_str\":\"2044303885230091\",\"order_type\":0,\"order_subtype\":5,\"datetime\":\"1787932603\",\"microtimestamp\":\"1787932603226000\",\"amount\":10.090138,\"amount_str\":\"10.090138\",\"amount_traded\":\"0\",\"amount_at_create\":\"10.090138\",\"price\":2477.66,\"price_str\":\"2477.66\",\"is_liquidation\":false},\"channel\":\"live_orders_ethusd\",\"event\":\"order_deleted\",\"event_id\":\"00065a1d-7fb2-9790-0000-001203000020\",\"pre_event_id\":\"00065a1d-7fb2-93a8-0001-001202000020\",\"order_source\":\"orderbook\"}","recorded_unix_us":1787932603268586}
{"message":"{\"data\":{\"id\":2044303885234180,\"id_str\":\"2044303885234180\",\"order_type\":0,\"order_subtype\":5,\"datetime\":\"1787932603\",\"microtimestamp\":\"1787932603226000\",\"amount\":10.095101,\"amount_str\":\"10.095101\",\"amount_traded\":\"0\",\"amount_at_create\":\"10.095101\",\"price\":2476.44,\"price_str\":\"2476.44\",\"is_liquidation\":false},\"channel\":\"live_orders_ethusd\",\"event\":\"order_deleted\",\"event_id\":\"00065a1d-7fb2-9790-0001-001200000020\",\"pre_event_id\":\"00065a1d-7fb2-9790-0000-001203000020\",\"order_source\":\"orderbook\"}","recorded_unix_us":1787932603268687}
{"message":"{\"data\":{\"id\":2044303885234187,\"id_str\":\"2044303885234187\",\"order_type\":0,\"order_subtype\":5,\"datetime\":\"1787932603\",\"microtimestamp\":\"1787932603226000\",\"amount\":20.204386,\"amount_str\":\"20.204386\",\"amount_traded\":\"0\",\"amount_at_create\":\"20.204386\",\"price\":2474.71,\"price_str\":\"2474.71\",\"is_liquidation\":false},\"channel\":\"live_orders_ethusd\",\"event\":\"order_deleted\",\"event_id\":\"00065a1d-7fb2-9790-0002-001201000020\",\"pre_event_id\":\"00065a1d-7fb2-9790-0001-001200000020\",\"order_source\":\"orderbook\"}","recorded_unix_us":1787932603268721}
{"message":"{\"data\":{\"id\":2044303885238272,\"id_str\":\"2044303885238272\",\"order_type\":0,\"order_subtype\":5,\"datetime\":\"1787932603\",\"microtimestamp\":\"1787932603227000\",\"amount\":4.033601,\"amount_str\":\"4.033601\",\"amount_traded\":\"0\",\"amount_at_create\":\"4.033601\",\"price\":2479.17,\"price_str\":\"2479.17\",\"is_liquidation\":false},\"channel\":\"live_orders_ethusd\",\"event\":\"order_deleted\",\"event_id\":\"00065a1d-7fb2-9b78-0000-001202000020\",\"pre_event_id\":\"00065a1d-7fb2-9790-0002-001201000020\",\"order_source\":\"orderbook\"}","recorded_unix_us":1787932603271022}
{"message":"{\"data\":{\"id\":2044303885242368,\"id_str\":\"2044303885242368\",\"order_type\":0,\"order_subtype\":5,\"datetime\":\"1787932603\",\"microtimestamp\":\"1787932603227000\",\"amount\":40.528033,\"amount_str\":\"40.528033\",\"amount_traded\":\"0\",\"amount_at_create\":\"40.528033\",\"price\":2467.42,\"price_str\":\"2467.42\",\"is_liquidation\":false},\"channel\":\"live_orders_ethusd\",\"event\":\"order_deleted\",\"event_id\":\"00065a1d-7fb2-9b78-0001-001203000020\",\"pre_event_id\":\"00065a1d-7fb2-9b78-0000-001202000020\",\"order_source\":\"orderbook\"}","recorded_unix_us":1787932603271083}
{"message":"{\"data\":{\"id\":2044303885242372,\"id_str\":\"2044303885242372\",\"order_type\":0,\"order_subtype\":5,\"datetime\":\"1787932603\",\"microtimestamp\":\"1787932603227000\",\"amount\":40.650432,\"amount_str\":\"40.650432\",\"amount_traded\":\"0\",\"amount_at_create\":\"40.650432\",\"price\":2459.99,\"price_str\":\"2459.99\",\"is_liquidation\":false},\"channel\":\"live_orders_ethusd\",\"event\":\"order_deleted\",\"event_id\":\"00065a1d-7fb2-9b78-0002-001200000020\",\"pre_event_id\":\"00065a1d-7fb2-9b78-0001-001203000020\",\"order_source\":\"orderbook\"}","recorded_unix_us":1787932603271286}
{"message":"{\"data\":{\"id\":2044303885324299,\"id_str\":\"2044303885324299\",\"order_type\":1,\"order_subtype\":5,\"datetime\":\"1787932603\",\"microtimestamp\":\"1787932603228000\",\"amount\":4.027586,\"amount_str\":\"4.027586\",\"amount_traded\":\"0\",\"amount_at_create\":\"4.027586\",\"price\":2482.88,\"price_str\":\"2482.88\",\"is_liquidation\":false},\"channel\":\"live_orders_ethusd\",\"event\":\"order_deleted\",\"event_id\":\"00065a1d-7fb2-9f60-0000-001201000020\",\"pre_event_id\":\"00065a1d-7fb2-9b78-0002-001200000020\",\"order_source\":\"orderbook\"}","recorded_unix_us":1787932603271323}
{"message":"{\"data\":{\"id\":2044303885336585,\"id_str\":\"2044303885336585\",\"order_type\":1,\"order_subtype\":5,\"datetime\":\"1787932603\",\"microtimestamp\":\"1787932603228000\",\"amount\":10.059779,\"amount_str\":\"10.059779\",\"amount_traded\":\"0\",\"amount_at_create\":\"10.059779\",\"price\":2485.15,\"price_str\":\"2485.15\",\"is_liquidation\":false},\"channel\":\"live_orders_ethusd\",\"event\":\"order_deleted\",\"event_id\":\"00065a1d-7fb2-9f60-0001-001202000020\",\"pre_event_id\":\"00065a1d-7fb2-9f60-0000-001201000020\",\"order_source\":\"orderbook\"}","recorded_unix_us":1787932603271349}
{"message":"{\"data\":{\"id\":2044303885336593,\"id_str\":\"2044303885336593\",\"order_type\":1,\"order_subtype\":5,\"datetime\":\"1787932603\",\"microtimestamp\":\"1787932603228000\",\"amount\":40.010118,\"amount_str\":\"40.010118\",\"amount_traded\":\"0\",\"amount_at_create\":\"40.010118\",\"price\":2499.37,\"price_str\":\"2499.37\",\"is_liquidation\":false},\"channel\":\"live_orders_ethusd\",\"event\":\"order_deleted\",\"event_id\":\"00065a1d-7fb2-9f60-0002-001203000020\",\"pre_event_id\":\"00065a1d-7fb2-9f60-0001-001202000020\",\"order_source\":\"orderbook\"}","recorded_unix_us":1787932603271372}
{"message":"{\"data\":{\"id\":2044303885340675,\"id_str\":\"2044303885340675\",\"order_type\":1,\"order_subtype\":5,\"datetime\":\"1787932603\",\"microtimestamp\":\"1787932603229000\",\"amount\":20.063885,\"amount_str\":\"20.063885\",\"amount_traded\":\"0\",\"amount_at_create\":\"20.063885\",\"price\":2492.04,\"price_str\":\"2492.04\",\"is_liquidation\":false},\"channel\":\"live_orders_ethusd\",\"event\":\"order_deleted\",\"event_id\":\"00065a1d-7fb2-a348-0000-001200000020\",\"pre_event_id\":\"00065a1d-7fb2-9f60-0002-001203000020\",\"order_source\":\"orderbook\"}","recorded_unix_us":1787932603271457}
{"message":"{\"data\":{\"id\":2044303885344777,\"id_str\":\"2044303885344777\",\"order_type\":0,\"order_subtype\":5,\"datetime\":\"1787932603\",\"microtimestamp\":\"1787932603229000\",\"amount\":4.034022,\"amount_str\":\"4.034022\",\"amount_traded\":\"0\",\"amount_at_create\":\"4.034022\",\"price\":2478.91,\"price_str\":\"2478.91\",\"is_liquidation\":false},\"channel\":\"live_orders_ethusd\",\"event\":\"order_deleted\",\"event_id\":\"00065a1d-7fb2-a348-0001-001201000020\",\"pre_event_id\":\"00065a1d-7fb2-a348-0000-001200000020\",\"order_source\":\"orderbook\"}","recorded_unix_us":1787932603271541}
{"message":"{\"data\":{\"id\":2044303885348874,\"id_str\":\"2044303885348874\",\"order_type\":0,\"order_subtype\":5,\"datetime\":\"1787932603\",\"microtimestamp\":\"1787932603229000\",\"amount\":10.092689,\"amount_str\":\"10.092689\",\"amount_traded\":\"0\",\"amount_at_create\":\"10.092689\",\"price\":2477.04,\"price_str\":\"2477.04\",\"is_liquidation\":false},\"channel\":\"live_orders_ethusd\",\"event\":\"order_deleted\",\"event_id\":\"00065a1d-7fb2-a348-0002-001202000020\",\"pre_event_id\":\"00065a1d-7fb2-a348-0001-001201000020\",\"order_source\":\"orderbook\"}","recorded_unix_us":1787932603275028}
{"message":"{\"data\":{\"id\":2044303885361152,\"id_str\":\"2044303885361152\",\"order_type\":0,\"order_subtype\":5,\"datetime\":\"1787932603\",\"microtimestamp\":\"1787932603230000\",\"amount\":10.097738,\"amount_str\":\"10.097738\",\"amount_traded\":\"0\",\"amount_at_create\":\"10.097738\",\"price\":2475.8,\"price_str\":\"2475.80\",\"is_liquidation\":false},\"channel\":\"live_orders_ethusd\",\"event\":\"order_deleted\",\"event_id\":\"00065a1d-7fb2-a730-0000-001203000020\",\"pre_event_id\":\"00065a1d-7fb2-a348-0002-001202000020\",\"order_source\":\"orderbook\"}","recorded_unix_us":1787932603275076}
{"message":"{\"data\":{\"id\":2044303885365251,\"id_str\":\"2044303885365251\",\"order_type\":0,\"order_subtype\":5,\"datetime\":\"1787932603\",\"microtimestamp\":\"1787932603230000\",\"amount\":4.033204,\"amount_str\":\"4.033204\",\"amount_traded\":\"0\",\"amount_at_create\":\"4.033204\",\"price\":2479.41,\"price_str\":\"2479.41\",\"is_liquidation\":false},\"channel\":\"live_orders_ethusd\",\"event\":\"order_deleted\",\"event_id\":\"00065a1d-7fb2-a730-0001-001200000020\",\"pre_event_id\":\"00065a1d-7fb2-a730-0000-001203000020\",\"order_source\":\"orderbook\"}","recorded_unix_us":1787932603275168}
{"message":"{\"data\":{\"id\":2044303885381632,\"id_str\":\"2044303885381632\",\"order_type\":0,\"order_subtype\":5,\"datetime\":\"1787932603\",\"microtimestamp\":\"1787932603230000\",\"amount\":40.568517,\"amount_str\":\"40.568517\",\"amount_traded\":\"0\",\"amount_at_create\":\"40.568517\",\"price\":2464.96,\"price_str\":\"2464.96\",\"is_liquidation\":false},\"channel\":\"live_orders_ethusd\",\"event\":\"order_deleted\",\"event_id\":\"00065a1d-7fb2-a730-0002-001201000020\",\"pre_event_id\":\"00065a1d-7fb2-a730-0001-001200000020\",\"order_source\":\"orderbook\"}","recorded_unix_us":1787932603275290}
{"message":"{\"data\":{\"id\":2044303885385738,\"id_str\":\"2044303885385738\",\"order_type\":0,\"order_subtype\":5,\"datetime\":\"1787932603\",\"microtimestamp\":\"1787932603231000\",\"amount\":20.215084,\"amount_str\":\"20.215084\",\"amount_traded\":\"0\",\"amount_at_create\":\"20.215084\",\"price\":2473.4,\"price_str\":\"2473.40\",\"is_liquidation\":false},\"channel\":\"live_orders_ethusd\",\"event\":\"order_deleted\",\"event_id\":\"00065a1d-7fb2-ab18-0000-001202000020\",\"pre_event_id\":\"00065a1d-7fb2-a730-0002-001201000020\",\"order_source\":\"orderbook\"}","recorded_unix_us":1787932603275322}
{"message":"{\"data\":{\"id\":2044303885463555,\"id_str\":\"2044303885463555\",\"order_type\":0,\"order_subtype\":5,\"datetime\":\"1787932603\",\"microtimestamp\":\"1787932603231000\",\"amount\":20.225289,\"amount_str\":\"20.225289\",\"amount_traded\":\"0\",\"amount_at_create\":\"20.225289\",\"price\":2472.15,\"price_str\":\"2472.15\",\"is_liquidation\":false},\"channel\":\"live_orders_ethusd\",\"event\":\"order_deleted\",\"event_id\":\"00065a1d-7fb2-ab18-0001-001203000020\",\"pre_event_id\":\"00065a1d-7fb2-ab18-0000-001202000020\",\"order_source\":\"orderbook\"}","recorded_unix_us":1787932603275413}
{"message":"{\"data\":{\"id\":2044303885467655,\"id_str\":\"2044303885467655\",\"order_type\":0,\"order_subtype\":5,\"datetime\":\"1787932603\",\"microtimestamp\":\"1787932603231000\",\"amount\":40.609081,\"amount_str\":\"40.609081\",\"amount_traded\":\"0\",\"amount_at_create\":\"40.609081\",\"price\":2462.5,\"price_str\":\"2462.50\",\"is_liquidation\":false},\"channel\":\"live_orders_ethusd\",\"event\":\"order_deleted\",\"event_id\":\"00065a1d-7fb2-ab18-0002-001200000020\",\"pre_event_id\":\"00065a1d-7fb2-ab18-0001-001203000020\",\"order_source\":\"orderbook\"}","recorded_unix_us":1787932603275557}
{"message":"{\"data\":{\"id\":2044303885717505,\"id_str\":\"2044303885717505\",\"order_type\":0,\"order_subtype\":5,\"datetime\":\"1787932603\",\"microtimestamp\":\"1787932603232000\",\"amount\":20.235437,\"amount_str\":\"20.235437\",\"amount_traded\":\"0\",\"amount_at_create\":\"20.235437\",\"price\":2470.91,\"price_str\":\"2470.91\",\"is_liquidation\":false},\"channel\":\"live_orders_ethusd\",\"event\":\"order_deleted\",\"event_id\":\"00065a1d-7fb2-af00-0000-001201000020\",\"pre_event_id\":\"00065a1d-7fb2-ab18-0002-001200000020\",\"order_source\":\"orderbook\"}","recorded_unix_us":1787932603275587}
{"message":"{\"data\":{\"id\":2044303886508033,\"id_str\":\"2044303886508033\",\"order_type\":1,\"order_subtype\":5,\"datetime\":\"1787932603\",\"microtimestamp\":\"1787932603232000\",\"amount\":5,\"amount_str\":\"5.000000\",\"amount_traded\":\"0\",\"amount_at_create\":\"5.000000\",\"price\":2481.68,\"price_str\":\"2481.68\",\"is_liquidation\":false},\"channel\":\"live_orders_ethusd\",\"event\":\"order_deleted\",\"event_id\":\"00065a1d-7fb2-af00-0001-001202000020\",\"pre_event_id\":\"00065a1d-7fb2-af00-0000-001201000020\",\"order_source\":\"orderbook\"}","recorded_unix_us":1787932603275612}
{"message":"{\"data\":{\"id\":2044303886549001,\"id_str\":\"2044303886549001\",\"order_type\":1,\"order_subtype\":5,\"datetime\":\"1787932603\",\"microtimestamp\":\"1787932603233000\",\"amount\":5,\"amount_str\":\"5.000000\",\"amount_traded\":\"0\",\"amount_at_create\":\"5.000000\",\"price\":2481.93,\"price_str\":\"2481.93\",\"is_liquidation\":false},\"channel\":\"live_orders_ethusd\",\"event\":\"order_deleted\",\"event_id\":\"00065a1d-7fb2-b2e8-0000-001203000020\",\"pre_event_id\":\"00065a1d-7fb2-af00-0001-001202000020\",\"order_source\":\"orderbook\"}","recorded_unix_us":1787932603406443}
{"message":"{\"data\":{\"id\":2044303874273283,\"id_str\":\"2044303874273283\",\"order_type\":1,\"order_subtype\":0,\"datetime\":\"1787932603\",\"microtimestamp\":\"1787932603239000\",\"amount\":2.016386,\"amount_str\":\"2.016386\",\"amount_traded\":\"0\",\"amount_at_create\":\"2.016386\",\"price\":2481.65,\"price_str\":\"2481.65\",\"is_liquidation\":false},\"channel\":\"live_orders_ethusd\",\"event\":\"order_deleted\",\"event_id\":\"00065a1d-7fb2-ca58-0000-001200000020\",\"pre_event_id\":\"00065a1d-7fb2-b2e8-0000-001203000020\",\"order_source\":\"orderbook\"}","recorded_unix_us":1787932603406613}
{"message":"{\"data\":{\"id\":2044303883046920,\"id_str\":\"2044303883046920\",\"order_type\":1,\"order_subtype\":5,\"datetime\":\"1787932603\",\"microtimestamp\":\"1787932603240000\",\"amount\":5.206947,\"amount_str\":\"5.206947\",\"amount_traded\":\"0\",\"amount_at_create\":\"5.206947\",\"price\":2482.05,\"price_str\":\"2482.05\",\"is_liquidation\":false},\"channel\":\"live_orders_ethusd\",\"event\":\"order_deleted\",\"event_id\":\"00065a1d-7fb2-ce40-0000-001201000020\",\"pre_event_id\":\"00065a1d-7fb2-ca58-0000-001200000020\",\"order_source\":\"orderbook\"}","recorded_unix_us":1787932603406741}
{"message":"{\"data\":{\"id\":2044303886000129,\"id_str\":\"2044303886000129\",\"order_type\":0,\"order_subtype\":5,\"datetime\":\"1787932603\",\"microtimestamp\":\"1787932603241000\",\"amount\":0.60475617,\"amount_str\":\"0.60475617\",\"amount_traded\":\"0\",\"amount_at_create\":\"0.60475617\",\"price\":0.03158982,\"price_str\":\"0.03158982\",\"is_liquidation\":false},\"channel\":\"live_orders_ethbtc\",\"event\":\"order_deleted\",\"event_id\":\"00065a1d-7fb2-d228-0000-001101000020\",\"pre_event_id\":\"00065a1d-7fb1-d058-0000-001100000020\",\"order_source\":\"orderbook\"}","recorded_unix_us":1787932603406844}
{"message":"{\"data\":{\"id\":2044303886684160,\"id_str\":\"2044303886684160\",\"order_type\":0,\"order_subtype\":5,\"datetime\":\"1787932603\",\"microtimestamp\":\"1787932603242000\",\"amount\":0.041977,\"amount_str\":\"0.041977\",\"amount_traded\":\"0\",\"amount_at_create\":\"0.041977\",\"price\":2480.78,\"price_str\":\"2480.78\",\"is_liquidation\":false},\"channel\":\"live_orders_ethusd\",\"event\":\"order_created\",\"event_id\":\"00065a1d-7fb2-d610-0000-001202000020\",\"pre_event_id\":\"00065a1d-7fb2-ce40-0000-001201000020\",\"order_source\":\"orderbook\"}","recorded_unix_us":1787932603406969}
{"message":"{\"data\":{\"id\":2044303886684162,\"id_str\":\"2044303886684162\",\"order_type\":1,\"order_subtype\":5,\"datetime\":\"1787932603\",\"microtimestamp\":\"1787932603242000\",\"amount\":0.044697,\"amount_str\":\"0.044697\",\"amount_traded\":\"0\",\"amount_at_create\":\"0.044697\",\"price\":2480.83,\"price_str\":\"2480.83\",\"is_liquidation\":false},\"channel\":\"live_orders_ethusd\",\"event\":\"order_created\",\"event_id\":\"00065a1d-7fb2-d610-0001-001203000020\",\"pre_event_id\":\"00065a1d-7fb2-d610-0000-001202000020\",\"order_source\":\"orderbook\"}","recorded_unix_us":1787932603406999}
{"message":"{\"data\":{\"id\":2044303886684174,\"id_str\":\"2044303886684174\",\"order_type\":1,\"order_subtype\":4,\"datetime\":\"1787932603\",\"microtimestamp\":\"1787932603243000\",\"amount\":0.00006244,\"amount_str\":\"0.00006244\",\"amount_traded\":\"0\",\"amount_at_create\":\"0.00006244\",\"price\":80878,\"price_str\":\"80878.00\",\"is_liquidation\":false},\"channel\":\"live_orders_btcusd\",\"event\":\"order_created\",\"event_id\":\"00065a1d-7fb2-d9f8-0000-000102000020\",\"pre_event_id\":\"00065a1d-7fb2-7468-0003-000101000020\",\"order_source\":\"orderbook\"}","recorded_unix_us":1787932603407108}
{"message":"{\"data\":{\"id\":2044303886684174,\"id_str\":\"2044303886684174\",\"order_type\":1,\"order_subtype\":4,\"datetime\":\"1787932603\",\"microtimestamp\":\"1787932603243000\",\"amount\":0.00006244,\"amount_str\":\"0.00006244\",\"amount_traded\":\"0\",\"amount_at_create\":\"0.00006244\",\"price\":80878,\"price_str\":\"80878.00\",\"is_liquidation\":false},\"channel\":\"live_orders_btcusd\",\"event\":\"order_deleted\",\"event_id\":\"00065a1d-7fb2-d9f8-0001-000103000020\",\"pre_event_id\":\"00065a1d-7fb2-d9f8-0000-000102000020\",\"order_source\":\"orderbook\"}","recorded_unix_us":1787932603407137}
{"message":"{\"data\":{\"id\":2044303886712836,\"id_str\":\"2044303886712836\",\"order_type\":1,\"order_subtype\":5,\"datetime\":\"1787932603\",\"microtimestamp\":\"1787932603249000\",\"amount\":0.06310787,\"amount_str\":\"0.06310787\",\"amount_traded\":\"0\",\"amount_at_create\":\"0.06310787\",\"price\":78522.43,\"price_str\":\"78522.43\",\"is_liquidation\":false},\"channel\":\"live_orders_btcusd\",\"event\":\"order_created\",\"event_id\":\"00065a1d-7fb2-f168-0000-000100000020\",\"pre_event_id\":\"00065a1d-7fb2-d9f8-0001-000103000020\",\"order_source\":\"orderbook\"}","recorded_unix_us":1787932603407247}
{"message":"{\"data\":{\"id\":2044303886712836,\"id_str\":\"2044303886712836\",\"order_type\":1,\"order_subtype\":5,\"datetime\":\"1787932603\",\"microtimestamp\":\"1787932603249000\",\"amount\":0.06310787,\"amount_str\":\"0.06310787\",\"amount_traded\":\"0\",\"amount_at_create\":\"0.06310787\",\"price\":78522.43,\"price_str\":\"78522.43\",\"is_liquidation\":false},\"channel\":\"live_orders_btcusd\",\"event\":\"order_deleted\",\"event_id\":\"00065a1d-7fb2-f168-0001-000101000020\",\"pre_event_id\":\"00065a1d-7fb2-f168-0000-000100000020\",\"order_source\":\"orderbook\"}","recorded_unix_us":1787932603407274}
{"message":"{\"data\":{\"id\":2044303886716935,\"id_str\":\"2044303886716935\",\"order_type\":1,\"order_subtype\":5,\"datetime\":\"1787932603\",\"microtimestamp\":\"1787932603250000\",\"amount\":0.06310787,\"amount_str\":\"0.06310787\",\"amount_traded\":\"0\",\"amount_at_create\":\"0.06310787\",\"price\":78519.98,\"price_str\":\"78519.98\",\"is_liquidation\":false},\"channel\":\"live_orders_btcusd\",\"event\":\"order_created\",\"event_id\":\"00065a1d-7fb2-f550-0000-000102000020\",\"pre_event_id\":\"00065a1d-7fb2-f168-0001-000101000020\",\"order_source\":\"orderbook\"}","recorded_unix_us":1787932603407352}
{"message":"{\"data\":{\"id\":2044303886716935,\"id_str\":\"2044303886716935\",\"order_type\":1,\"order_subtype\":5,\"datetime\":\"1787932603\",\"microtimestamp\":\"1787932603250000\",\"amount\":0.06310787,\"amount_str\":\"0.06310787\",\"amount_traded\":\"0\",\"amount_at_create\":\"0.06310787\",\"price\":78519.98,\"price_str\":\"78519.98\",\"is_liquidation\":false},\"channel\":\"live_orders_btcusd\",\"event\":\"order_deleted\",\"event_id\":\"00065a1d-7fb2-f550-0001-000103000020\",\"pre_event_id\":\"00065a1d-7fb2-f550-0000-000102000020\",\"order_source\":\"orderbook\"}","recorded_unix_us":1787932603407437}
{"message":"{\"data\":{\"id\":2044303865454599,\"id_str\":\"2044303865454599\",\"order_type\":0,\"order_subtype\":5,\"datetime\":\"1787932603\",\"microtimestamp\":\"1787932603259000\",\"amount\":6.044921,\"amount_str\":\"6.044921\",\"amount_traded\":\"0\",\"amount_at_create\":\"6.044921\",\"price\":2480,\"price_str\":\"2480.00\",\"is_liquidation\":false},\"channel\":\"live_orders_ethusd\",\"event\":\"order_deleted\",\"event_id\":\"00065a1d-7fb3-1878-0000-001200000020\",\"pre_event_id\":\"00065a1d-7fb2-d610-0001-001203000020\",\"order_source\":\"orderbook\"}","recorded_unix_us":1787932603407515}
{"message":"{\"data\":{\"id\":2044303883640834,\"id_str\":\"2044303883640834\",\"order_type\":0,\"order_subtype\":5,\"datetime\":\"1787932603\",\"microtimestamp\":\"1787932603263000\",\"amount\":0.509959,\"amount_str\":\"0.509959\",\"amount_traded\":\"0\",\"amount_at_create\":\"0.509959\",\"price\":2480.22,\"price_str\":\"2480.22\",\"is_liquidation\":false},\"channel\":\"live_orders_ethusd\",\"event\":\"order_deleted\",\"event_id\":\"00065a1d-7fb3-2818-0000-001201000020\",\"pre_event_id\":\"00065a1d-7fb3-1878-0000-001200000020\",\"order_source\":\"orderbook\"}","recorded_unix_us":1787932603407740}
{"message":"{\"data\":{\"id\":2044303877033997,\"id_str\":\"2044303877033997\",\"order_type\":1,\"order_subtype\":5,\"datetime\":\"1787932603\",\"microtimestamp\":\"1787932603263000\",\"amount\":5,\"amount_str\":\"5.000000\",\"amount_traded\":\"0\",\"amount_at_create\":\"5.000000\",\"price\":2481.03,\"price_str\":\"2481.03\",\"is_liquidation\":false},\"channel\":\"live_orders_ethusd\",\"event\":\"order_deleted\",\"event_id\":\"00065a1d-7fb3-2818-0001-001202000020\",\"pre_event_id\":\"00065a1d-7fb3-2818-0000-001201000020\",\"order_source\":\"orderbook\"}","recorded_unix_us":1787932603407766}
{"message":"{\"data\":{\"id\":2044303886770197,\"id_str\":\"2044303886770197\",\"order_type\":1,\"order_subtype\":5,\"datetime\":\"1787932603\",\"microtimestamp\":\"1787932603264000\",\"amount\":0.1,\"amount_str\":\"0.10000000\",\"amount_traded\":\"0\",\"amount_at_create\":\"0.10000000\",\"price\":78522.63,\"price_str\":\"78522.63\",\"is_liquidation\":false},\"channel\":\"live_orders_btcusd\",\"event\":\"order_created\",\"event_id\":\"00065a1d-7fb3-2c00-0000-000100000020\",\"pre_event_id\":\"00065a1d-7fb2-f550-0001-000103000020\",\"order_source\":\"orderbook\"}","recorded_unix_us":1787932603407787}
{"message":"{\"data\":{\"id\":2044303886770197,\"id_str\":\"2044303886770197\",\"order_type\":1,\"order_subtype\":5,\"datetime\":\"1787932603\",\"microtimestamp\":\"1787932603264000\",\"amount\":0.1,\"amount_str\":\"0.10000000\",\"amount_traded\":\"0\",\"amount_at_create\":\"0.10000000\",\"price\":78522.63,\"price_str\":\"78522.63\",\"is_liquidation\":false},\"channel\":\"live_orders_btcusd\",\"event\":\"order_deleted\",\"event_id\":\"00065a1d-7fb3-2c00-0001-000101000020\",\"pre_event_id\":\"00065a1d-7fb3-2c00-0000-000100000020\",\"order_source\":\"orderbook\"}","recorded_unix_us":1787932603407808}
{"message":"{\"data\":{\"id\":2044303886495753,\"id_str\":\"2044303886495753\",\"order_type\":0,\"order_subtype\":5,\"datetime\":\"1787932603\",\"microtimestamp\":\"1787932603264000\",\"amount\":0.403093,\"amount_str\":\"0.403093\",\"amount_traded\":\"0\",\"amount_at_create\":\"0.403093\",\"price\":2480.07,\"price_str\":\"2480.07\",\"is_liquidation\":false},\"channel\":\"live_orders_ethusd\",\"event\":\"order_deleted\",\"event_id\":\"00065a1d-7fb3-2c00-0000-001203000020\",\"pre_event_id\":\"00065a1d-7fb3-2818-0001-001202000020\",\"order_source\":\"orderbook\"}","recorded_unix_us":1787932603407874}
{"message":"{\"data\":{\"id\":2044303877042179,\"id_str\":\"2044303877042179\",\"order_type\":1,\"order_subtype\":5,\"datetime\":\"1787932603\",\"microtimestamp\":\"1787932603264000\",\"amount\":2.5,\"amount_str\":\"2.500000\",\"amount_traded\":\"0\",\"amount_at_create\":\"2.500000\",\"price\":2480.91,\"price_str\":\"2480.91\",\"is_liquidation\":false},\"channel\":\"live_orders_ethusd\",\"event\":\"order_deleted\",\"event_id\":\"00065a1d-7fb3-2c00-0001-001200000020\",\"pre_event_id\":\"00065a1d-7fb3-2c00-0000-001203000020\",\"order_source\":\"orderbook\"}","recorded_unix_us":1787932603407899}
{"message":"{\"data\":{\"id\":2044303876788227,\"id_str\":\"2044303876788227\",\"order_type\":1,\"order_subtype\":5,\"datetime\":\"1787932603\",\"microtimestamp\":\"1787932603265000\",\"amount\":0.010654,\"amount_str\":\"0.010654\",\"amount_traded\":\"0\",\"amount_at_create\":\"0.010654\",\"price\":2481.07,\"price_str\":\"2481.07\",\"is_liquidation\":false},\"channel\":\"live_orders_ethusd\",\"event\":\"order_deleted\",\"event_id\":\"00065a1d-7fb3-2fe8-0000-001201000020\",\"pre_event_id\":\"00065a1d-7fb3-2c00-0001-001200000020\",\"order_source\":\"orderbook\"}","recorded_unix_us":1787932603407981}
{"message":"{\"data\":{\"id\":2044303879327745,\"id_str\":\"2044303879327745\",\"order_type\":1,\"order_subtype\":5,\"datetime\":\"1787932603\",\"microtimestamp\":\"1787932603265000\",\"amount\":1.732162,\"amount_str\":\"1.732162\",\"amount_traded\":\"0\",\"amount_at_create\":\"1.732162\",\"price\":2481.02,\"price_str\":\"2481.02\",\"is_liquidation\":false},\"channel\":\"live_orders_ethusd\",\"event\":\"order_deleted\",\"event_id\":\"00065a1d-7fb3-2fe8-0001-001202000020\",\"pre_event_id\":\"00065a1d-7fb3-2fe8-0000-001201000020\",\"order_source\":\"orderbook\"}","recorded_unix_us":1787932603408084}
{"message":"{\"data\":{\"id\":2044303848099841,\"id_str\":\"2044303848099841\",\"order_type\":1,\"order_subtype\":0,\"datetime\":\"1787932603\",\"microtimestamp\":\"1787932603265000\",\"amount\":2.016386,\"amount_str\":\"2.016386\",\"amount_traded\":\"0\",\"amount_at_create\":\"2.016386\",\"price\":2481.98,\"price_str\":\"2481.98\",\"is_liquidation\":false},\"channel\":\"live_orders_ethusd\",\"event\":\"order_deleted\",\"event_id\":\"00065a1d-7fb3-2fe8-0002-001203000020\",\"pre_event_id\":\"00065a1d-7fb3-2fe8-0001-001202000020\",\"order_source\":\"orderbook\"}","recorded_unix_us":1787932603408108}
{"message":"{\"data\":{\"id\":2044303880634375,\"id_str\":\"2044303880634375\",\"order_type\":0,\"order_subtype\":5,\"datetime\":\"1787932603\",\"microtimestamp\":\"1787932603265000\",\"amount\":5,\"amount_str\":\"5.000000\",\"amount_traded\":\"0\",\"amount_at_create\":\"5.000000\",\"price\":2480.77,\"price_str\":\"2480.77\",\"is_liquidation\":false},\"channel\":\"live_orders_ethusd\",\"event\":\"order_deleted\",\"event_id\":\"00065a1d-7fb3-2fe8-0003-001200000020\",\"pre_event_id\":\"00065a1d-7fb3-2fe8-0002-001203000020\",\"order_source\":\"orderbook\"}","recorded_unix_us":1787932603408206}
{"message":"{\"data\":{\"id\":2044303876259843,\"id_str\":\"2044303876259843\",\"order_type\":1,\"order_subtype\":5,\"datetime\":\"1787932603\",\"microtimestamp\":\"1787932603265000\",\"amount\":0.06310787,\"amount_str\":\"0.06310787\",\"amount_traded\":\"0\",\"amount_at_create\":\"0.06310787\",\"price\":78525.23,\"price_str\":\"78525.23\",\"is_liquidation\":false},\"channel\":\"live_orders_btcusd\",\"event\":\"order_deleted\",\"event_id\":\"00065a1d-7fb3-2fe8-0000-000102000020\",\"pre_event_id\":\"00065a1d-7fb3-2c00-0001-000101000020\",\"order_source\":\"orderbook\"}","recorded_unix_us":1787932603408230}
{"message":"{\"data\":{\"id\":2044303886782469,\"id_str\":\"2044303886782469\",\"order_type\":0,\"order_subtype\":5,\"datetime\":\"1787932603\",\"microtimestamp\":\"1787932603266000\",\"amount\":0.00140266,\"amount_str\":\"0.00140266\",\"amount_traded\":\"0\",\"amount_at_create\":\"0.00140266\",\"price\":70668.36,\"price_str\":\"70668.36\",\"is_liquidation\":false},\"channel\":\"live_orders_btcusd\",\"event\":\"order_created\",\"event_id\":\"00065a1d-7fb3-33d0-0000-000103000020\",\"pre_event_id\":\"00065a1d-7fb3-2fe8-0000-000102000020\",\"order_source\":\"orderbook\"}","recorded_unix_us":1787932603408353}
{"message":"{\"data\":{\"id\":2044303886782486,\"id_str\":\"2044303886782486\",\"order_type\":1,\"order_subtype\":5,\"datetime\":\"1787932603\",\"microtimestamp\":\"1787932603266000\",\"amount\":0.1,\"amount_str\":\"0.10000000\",\"amount_traded\":\"0\",\"amount_at_create\":\"0.10000000\",\"price\":78522.62,\"price_str\":\"78522.62\",\"is_liquidation\":false},\"channel\":\"live_orders_btcusd\",\"event\":\"order_created\",\"event_id\":\"00065a1d-7fb3-33d0-0001-000100000020\",\"pre_event_id\":\"00065a1d-7fb3-33d0-0000-000103000020\",\"order_source\":\"orderbook\"}","recorded_unix_us":1787932603408415}
{"message":"{\"data\":{\"id\":2044303886782486,\"id_str\":\"2044303886782486\",\"order_type\":1,\"order_subtype\":5,\"datetime\":\"1787932603\",\"microtimestamp\":\"1787932603266000\",\"amount\":0.1,\"amount_str\":\"0.10000000\",\"amount_traded\":\"0\",\"amount_at_create\":\"0.10000000\",\"price\":78522.62,\"price_str\":\"78522.62\",\"is_liquidation\":false},\"channel\":\"live_orders_btcusd\",\"event\":\"order_deleted\",\"event_id\":\"00065a1d-7fb3-33d0-0002-000101000020\",\"pre_event_id\":\"00065a1d-7fb3-33d0-0001-000100000020\",\"order_source\":\"orderbook\"}","recorded_unix_us":1787932603408438}
{"message":"{\"data\":{\"id\":2044303883644928,\"id_str\":\"2044303883644928\",\"order_type\":0,\"order_subtype\":5,\"datetime\":\"1787932603\",\"microtimestamp\":\"1787932603267000\",\"amount\":0.403096,\"amount_str\":\"0.403096\",\"amount_traded\":\"0\",\"amount_at_create\":\"0.403096\",\"price\":2480.22,\"price_str\":\"2480.22\",\"is_liquidation\":false},\"channel\":\"live_orders_ethusd\",\"event\":\"order_deleted\",\"event_id\":\"00065a1d-7fb3-37b8-0000-001201000020\",\"pre_event_id\":\"00065a1d-7fb3-2fe8-0003-001200000020\",\"order_source\":\"orderbook\"}","recorded_unix_us":1787932603408560}
{"message":"{\"data\":{\"id\":2044303883804675,\"id_str\":\"2044303883804675\",\"order_type\":0,\"order_subtype\":5,\"datetime\":\"1787932603\",\"microtimestamp\":\"1787932603268000\",\"amount\":0.1910375,\"amount_str\":\"0.19103750\",\"amount_traded\":\"0\",\"amount_at_create\":\"0.19103750\",\"price\":78485.88,\"price_str\":\"78485.88\",\"is_liquidation\":false},\"channel\":\"live_orders_btcusd\",\"event\":\"order_deleted\",\"event_id\":\"00065a1d-7fb3-3ba0-0000-000102000020\",\"pre_event_id\":\"00065a1d-7fb3-33d0-0002-000101000020\",\"order_source\":\"orderbook\"}","recorded_unix_us":1787932603408583}
{"message":"{\"data\":{\"id\":2044303840563218,\"id_str\":\"2044303840563218\",\"order_type\":0,\"order_subtype\":5,\"datetime\":\"1787932603\",\"microtimestamp\":\"1787932603269000\",\"amount\":4.23144408,\"amount_str\":\"4.23144408\",\"amount_traded\":\"0\",\"amount_at_create\":\"4.23144408\",\"price\":0.03159285,\"price_str\":\"0.03159285\",\"is_liquidation\":false},\"channel\":\"live_orders_ethbtc\",\"event\":\"order_deleted\",\"event_id\":\"00065a1d-7fb3-3f88-0000-001102000020\",\"pre_event_id\":\"00065a1d-7fb2-d228-0000-001101000020\",\"order_source\":\"orderbook\"}","recorded_unix_us":1787932603408705}
{"message":"{\"data\":{\"id\":2044303877287936,\"id_str\":\"2044303877287936\",\"order_type\":1,\"order_subtype\":5,\"datetime\":\"1787932603\",\"microtimestamp\":\"1787932603270000\",\"amount\":1,\"amount_str\":\"1.000000\",\"amount_traded\":\"0\",\"amount_at_create\":\"1.000000\",\"price\":2480.82,\"price_str\":\"2480.82\",\"is_liquidation\":false},\"channel\":\"live_orders_ethusd\",\"event\":\"order_deleted\",\"event_id\":\"00065a1d-7fb3-4370-0000-001202000020\",\"pre_event_id\":\"00065a1d-7fb3-37b8-0000-001201000020\",\"order_source\":\"orderbook\"}","recorded_unix_us":1787932603408768}
{"message":"{\"data\":{\"id\":2044303884533760,\"id_str\":\"2044303884533760\",\"order_type\":0,\"order_subtype\":5,\"datetime\":\"1787932603\",\"microtimestamp\":\"1787932603270000\",\"amount\":0.63679443,\"amount_str\":\"0.63679443\",\"amount_traded\":\"0\",\"amount_at_create\":\"0.63679443\",\"price\":78484.05,\"price_str\":\"78484.05\",\"is_liquidation\":false},\"channel\":\"live_orders_btcusd\",\"event\":\"order_deleted\",\"event_id\":\"00065a1d-7fb3-4370-0000-000103000020\",\"pre_event_id\":\"00065a1d-7fb3-3ba0-0000-000102000020\",\"order_source\":\"orderbook\"}","recorded_unix_us":1787932603408792}
{"message":"{\"data\":{\"id\":2044303885922310,\"id_str\":\"2044303885922310\",\"order_type\":1,\"order_subtype\":5,\"datetime\":\"1787932603\",\"microtimestamp\":\"1787932603270000\",\"amount\":0.224274,\"amount_str\":\"0.224274\",\"amount_traded\":\"0\",\"amount_at_create\":\"0.224274\",\"price\":2481,\"price_str\":\"2481.00\",\"is_liquidation\":false},\"channel\":\"live_orders_ethusd\",\"event\":\"order_deleted\",\"event_id\":\"00065a1d-7fb3-4370-0001-001203000020\",\"pre_event_id\":\"00065a1d-7fb3-4370-0000-001202000020\",\"order_source\":\"orderbook\"}","recorded_unix_us":1787932603408871}
{"message":"{\"data\":{\"id\":2044303820812288,\"id_str\":\"2044303820812288\",\"order_type\":1,\"order_subtype\":5,\"datetime\":\"1787932603\",\"microtimestamp\":\"1787932603270000\",\"amount\":10.045491,\"amount_str\":\"10.045491\",\"amount_traded\":\"0\",\"amount_at_create\":\"10.045491\",\"price\":2483.81,\"price_str\":\"2483.81\",\"is_liquidation\":false},\"channel\":\"live_orders_ethusd\",\"event\":\"order_deleted\",\"event_id\":\"00065a1d-7fb3-4370-0002-001200000020\",\"pre_event_id\":\"00065a1d-7fb3-4370-0001-001203000020\",\"order_source\":\"orderbook\"}","recorded_unix_us":1787932603408958}
{"message":"{\"data\":{\"id\":2044303885201413,\"id_str\":\"2044303885201413\",\"order_type\":0,\"order_subtype\":5,\"datetime\":\"1787932603\",\"microtimestamp\":\"1787932603271000\",\"amount\":0.444921,\"amount_str\":\"0.444921\",\"amount_traded\":\"0\",\"amount_at_create\":\"0.444921\",\"price\":2480.11,\"price_str\":\"2480.11\",\"is_liquidation\":false},\"channel\":\"live_orders_ethusd\",\"event\":\"order_deleted\",\"event_id\":\"00065a1d-7fb3-4758-0000-001201000020\",\"pre_event_id\":\"00065a1d-7fb3-4370-0002-001200000020\",\"order_source\":\"orderbook\"}","recorded_unix_us":1787932603408981}
{"message":"{\"data\":{\"id\":2044303884865544,\"id_str\":\"2044303884865544\",\"order_type\":0,\"order_subtype\":5,\"datetime\":\"1787932603\",\"microtimestamp\":\"1787932603271000\",\"amount\":0.50943342,\"amount_str\":\"0.50943342\",\"amount_traded\":\"0\",\"amount_at_create\":\"0.50943342\",\"price\":78482.12,\"price_str\":\"78482.12\",\"is_liquidation\":false},\"channel\":\"live_orders_btcusd\",\"event\":\"order_deleted\",\"event_id\":\"00065a1d-7fb3-4758-0000-000100000020\",\"pre_event_id\":\"00065a1d-7fb3-4370-0000-000103000020\",\"order_source\":\"orderbook\"}","recorded_unix_us":1787932603409094}
{"message":"{\"data\":{\"id\":2044303882604554,\"id_str\":\"2044303882604554\",\"order_type\":1,\"order_subtype\":5,\"datetime\":\"1787932603\",\"microtimestamp\":\"1787932603272000\",\"amount\":4.23144408,\"amount_str\":\"4.23144408\",\"amount_traded\":\"0\",\"amount_at_create\":\"4.23144408\",\"price\":0.03161011,\"price_str\":\"0.03161011\",\"is_liquidation\":false},\"channel\":\"live_orders_ethbtc\",\"event\":\"order_deleted\",\"event_id\":\"00065a1d-7fb3-4b40-0000-001103000020\",\"pre_event_id\":\"00065a1d-7fb3-3f88-0000-001102000020\",\"order_source\":\"orderbook\"}","recorded_unix_us":1787932603409117}
{"message":"{\"data\":{\"id\":2044303886807062,\"id_str\":\"2044303886807062\",\"order_type\":0,\"order_subtype\":4,\"datetime\":\"1787932603\",\"microtimestamp\":\"1787932603273000\",\"amount\":1,\"amount_str\":\"1.000000\",\"amount_traded\":\"0\",\"amount_at_create\":\"1.000000\",\"price\":2480.86,\"price_str\":\"2480.86\",\"is_liquidation\":false},\"channel\":\"live_orders_ethusd\",\"event\":\"order_created\",\"event_id\":\"00065a1d-7fb3-4f28-0000-001202000020\",\"pre_event_id\":\"00065a1d-7fb3-4758-0000-001201000020\",\"order_source\":\"orderbook\"}","recorded_unix_us":1787932603409270}
{"message":"{\"data\":{\"id\":2044303886807062,\"id_str\":\"2044303886807062\",\"order_type\":0,\"order_subtype\":4,\"datetime\":\"1787932603\",\"microtimestamp\":\"1787932603273000\",\"amount\":0.955303,\"amount_str\":\"0.955303\",\"amount_traded\":\"0.044697\",\"amount_at_create\":\"1.000000\",\"price\":2480.83,\"price_str\":\"2480.83\",\"is_liquidation\":false},\"channel\":\"live_orders_ethusd\",\"event\":\"order_changed\",\"event_id\":\"00065a1d-7fb3-4f28-0001-001203000020\",\"pre_event_id\":\"00065a1d-7fb3-4f28-0000-001202000020\",\"order_source\":\"orderbook\"}","recorded_unix_us":1787932603409293}
{"message":"{\"data\":{\"id\":2044303886684162,\"id_str\":\"2044303886684162\",\"order_type\":1,\"order_subtype\":5,\"datetime\":\"1787932603\",\"microtimestamp\":\"1787932603273000\",\"amount\":0,\"amount_str\":\"0\",\"amount_traded\":\"0.044697\",\"amount_at_create\":\"0.044697\",\"price\":2480.83,\"price_str\":\"2480.83\",\"is_liquidation\":false},\"channel\":\"live_orders_ethusd\",\"event\":\"order_deleted\",\"event_id\":\"00065a1d-7fb3-4f28-0002-001200000020\",\"pre_event_id\":\"00065a1d-7fb3-4f28-0001-001203000020\",\"order_source\":\"orderbook\"}","recorded_unix_us":1787932603409319}
{"message":"{\"data\":{\"id\":2044303886807062,\"id_str\":\"2044303886807062\",\"order_type\":0,\"order_subtype\":4,\"datetime\":\"1787932603\",\"microtimestamp\":\"1787932603273000\",\"amount\":0.955303,\"amount_str\":\"0.955303\",\"amount_traded\":\"0\",\"amount_at_create\":\"1.000000\",\"price\":2480.86,\"price_str\":\"2480.86\",\"is_liquidation\":false},\"channel\":\"live_orders_ethusd\",\"event\":\"order_deleted\",\"event_id\":\"00065a1d-7fb3-4f28-0003-001201000020\",\"pre_event_id\":\"00065a1d-7fb3-4f28-0002-001200000020\",\"order_source\":\"orderbook\"}","recorded_unix_us":1787932603409339}
{"message":"{\"data\":{\"id\":2044303882223618,\"id_str\":\"2044303882223618\",\"order_type\":0,\"order_subtype\":5,\"datetime\":\"1787932603\",\"microtimestamp\":\"1787932603273000\",\"amount\":0.080642,\"amount_str\":\"0.080642\",\"amount_traded\":\"0\",\"amount_at_create\":\"0.080642\",\"price\":2480.1,\"price_str\":\"2480.10\",\"is_liquidation\":false},\"channel\":\"live_orders_ethusd\",\"event\":\"order_deleted\",\"event_id\":\"00065a1d-7fb3-4f28-0004-001202000020\",\"pre_event_id\":\"00065a1d-7fb3-4f28-0003-001201000020\",\"order_source\":\"orderbook\"}","recorded_unix_us":1787932603409454}
{"message":"{\"data\":{\"id\":2044303886815247,\"id_str\":\"2044303886815247\",\"order_type\":0,\"order_subtype\":5,\"datetime\":\"1787932603\",\"microtimestamp\":\"1787932603274000\",\"amount\":0.403093,\"amount_str\":\"0.403093\",\"amount_traded\":\"0\",\"amount_at_create\":\"0.403093\",\"price\":2480.31,\"price_str\":\"2480.31\",\"is_liquidation\":false},\"channel\":\"live_orders_ethusd\",\"event\":\"order_created\",\"event_id\":\"00065a1d-7fb3-5310-0000-001203000020\",\"pre_event_id\":\"00065a1d-7fb3-4f28-0004-001202000020\",\"order_source\":\"orderbook\"}","recorded_unix_us":1787932603409477}
{"message":"{\"data\":{\"id\":2044303886819337,\"id_str\":\"2044303886819337\",\"order_type\":0,\"order_subtype\":5,\"datetime\":\"1787932603\",\"microtimestamp\":\"1787932603275000\",\"amount\":0.403093,\"amount_str\":\"0.403093\",\"amount_traded\":\"0\",\"amount_at_create\":\"0.403093\",\"price\":2480.01,\"price_str\":\"2480.01\",\"is_liquidation\":false},\"channel\":\"live_orders_ethusd\",\"event\":\"order_created\",\"event_id\":\"00065a1d-7fb3-56f8-0000-001200000020\",\"pre_event_id\":\"00065a1d-7fb3-5310-0000-001203000020\",\"order_source\":\"orderbook\"}","recorded_unix_us":1787932603409593}
{"message":"{\"data\":{\"id\":2044303886823431,\"id_str\":\"2044303886823431\",\"order_type\":1,\"order_subtype\":0,\"datetime\":\"1787932603\",\"microtimestamp\":\"1787932603276000\",\"amount\":2.016386,\"amount_str\":\"2.016386\",\"amount_traded\":\"0\",\"amount_at_create\":\"2.016386\",\"price\":2482.16,\"price_str\":\"2482.16\",\"is_liquidation\":false},\"channel\":\"live_orders_ethusd\",\"event\":\"order_created\",\"event_id\":\"00065a1d-7fb3-5ae0-0000-001201000020\",\"pre_event_id\":\"00065a1d-7fb3-56f8-0000-001200000020\",\"order_source\":\"orderbook\"}","recorded_unix_us":1787932603409615}
{"message":"{\"data\":{\"id\":2044303885979653,\"id_str\":\"2044303885979653\",\"order_type\":0,\"order_subtype\":5,\"datetime\":\"1787932603\",\"microtimestamp\":\"1787932603276000\",\"amount\":0.06368171,\"amount_str\":\"0.06368171\",\"amount_traded\":\"0\",\"amount_at_create\":\"0.06368171\",\"price\":78515.46,\"price_str\":\"78515.46\",\"is_liquidation\":false},\"channel\":\"live_orders_btcusd\",\"event\":\"order_deleted\",\"event_id\":\"00065a1d-7fb3-5ae0-0000-000101000020\",\"pre_event_id\":\"00065a1d-7fb3-4758-0000-000100000020\",\"order_source\":\"orderbook\"}","recorded_unix_us":1787932603409726}
{"message":"{\"data\":{\"id\":2044303886819337,\"id_str\":\"2044303886819337\",\"order_type\":0,\"order_subtype\":5,\"datetime\":\"1787932603\",\"microtimestamp\":\"1787932603282000\",\"amount\":0.403093,\"amount_str\":\"0.403093\",\"amount_traded\":\"0\",\"amount_at_create\":\"0.403093\",\"price\":2480.01,\"price_str\":\"2480.01\",\"is_liquidation\":false},\"channel\":\"live_orders_ethusd\",\"event\":\"order_deleted\",\"event_id\":\"00065a1d-7fb3-7250-0000-001202000020\",\"pre_event_id\":\"00065a1d-7fb3-5ae0-0000-001201000020\",\"order_source\":\"orderbook\"}","recorded_unix_us":1787932603409787}
{"message":"{\"data\":{\"id\":2044303886848004,\"id_str\":\"2044303886848004\",\"order_type\":1,\"order_subtype\":0,\"datetime\":\"1787932603\",\"microtimestamp\":\"1787932603283000\",\"amount\":0.06310787,\"amount_str\":\"0.06310787\",\"amount_traded\":\"0\",\"amount_at_create\":\"0.06310787\",\"price\":78549.2,\"price_str\":\"78549.20\",\"is_liquidation\":false},\"channel\":\"live_orders_btcusd\",\"event\":\"order_created\",\"event_id\":\"00065a1d-7fb3-7638-0000-000102000020\",\"pre_event_id\":\"00065a1d-7fb3-5ae0-0000-000101000020\",\"order_source\":\"orderbook\"}","recorded_unix_us":1787932603409811}
{"message":"{\"data\":{\"id\":2044303886835715,\"id_str\":\"2044303886835715\",\"order_type\":0,\"order_subtype\":5,\"datetime\":\"1787932603\",\"microtimestamp\":\"1787932603293000\",\"amount\":0.256121,\"amount_str\":\"0.256121\",\"amount_traded\":\"0\",\"amount_at_create\":\"0.256121\",\"price\":2480.31,\"price_str\":\"2480.31\",\"is_liquidation\":false},\"channel\":\"live_orders_ethusd\",\"event\":\"order_created\",\"event_id\":\"00065a1d-7fb3-9d48-0000-001203000020\",\"pre_event_id\":\"00065a1d-7fb3-7250-0000-001202000020\",\"order_source\":\"orderbook\"}","recorded_unix_us":1787932603409925}
{"message":"{\"data\":{\"id\":2044303886852154,\"id_str\":\"2044303886852154\",\"order_type\":0,\"order_subtype\":5,\"datetime\":\"1787932603\",\"microtimestamp\":\"1787932603293000\",\"amount\":0.19103698,\"amount_str\":\"0.19103698\",\"amount_traded\":\"0\",\"amount_at_create\":\"0.19103698\",\"price\":78487.33,\"price_str\":\"78487.33\",\"is_liquidation\":false},\"channel\":\"live_orders_btcusd\",\"event\":\"order_created\",\"event_id\":\"00065a1d-7fb3-9d48-0000-000103000020\",\"pre_event_id\":\"00065a1d-7fb3-7638-0000-000102000020\",\"order_source\":\"orderbook\"}","recorded_unix_us":1787932603409949}
{"message":"{\"data\":{\"id\":2044303886839809,\"id_str\":\"2044303886839809\",\"order_type\":0,\"order_subtype\":5,\"datetime\":\"1787932603\",\"microtimestamp\":\"1787932603293000\",\"amount\":0.206118,\"amount_str\":\"0.206118\",\"amount_traded\":\"0\",\"amount_at_create\":\"0.206118\",\"price\":2480.51,\"price_str\":\"2480.51\",\"is_liquidation\":false},\"channel\":\"live_orders_ethusd\",\"event\":\"order_created\",\"event_id\":\"00065a1d-7fb3-9d48-0001-001200000020\",\"pre_event_id\":\"00065a1d-7fb3-9d48-0000-001203000020\",\"order_source\":\"orderbook\"}","recorded_unix_us":1787932603410063}
{"message":"{\"data\":{\"id\":2044303886856223,\"id_str\":\"2044303886856223\",\"order_type\":1,\"order_subtype\":0,\"datetime\":\"1787932603\",\"microtimestamp\":\"1787932603294000\",\"amount\":0.06310787,\"amount_str\":\"0.06310787\",\"amount_traded\":\"0\",\"amount_at_create\":\"0.06310787\",\"price\":78553.92,\"price_str\":\"78553.92\",\"is_liquidation\":false},\"channel\":\"live_orders_btcusd\",\"event\":\"order_created\",\"event_id\":\"00065a1d-7fb3-a130-0000-000100000020\",\"pre_event_id\":\"00065a1d-7fb3-9d48-0000-000103000020\",\"order_source\":\"orderbook\"}","recorded_unix_us":1787932603410086}
{"message":"{\"data\":{\"id\":2044303886843908,\"id_str\":\"2044303886843908\",\"order_type\":0,\"order_subtype\":5,\"datetime\":\"1787932603\",\"microtimestamp\":\"1787932603294000\",\"amount\":0.403051,\"amount_str\":\"0.403051\",\"amount_traded\":\"0\",\"amount_at_create\":\"0.403051\",\"price\":2480.25,\"price_str\":\"2480.25\",\"is_liquidation\":false},\"channel\":\"live_orders_ethusd\",\"event\":\"order_created\",\"event_id\":\"00065a1d-7fb3-a130-0000-001201000020\",\"pre_event_id\":\"00065a1d-7fb3-9d48-0001-001200000020\",\"order_source\":\"orderbook\"}","recorded_unix_us":1787932603410166}
{"message":"{\"data\":{\"id\":2044303886860289,\"id_str\":\"2044303886860289\",\"order_type\":0,\"order_subtype\":5,\"datetime\":\"1787932603\",\"microtimestamp\":\"1787932603294000\",\"amount\":0.50943195,\"amount_str\":\"0.50943195\",\"amount_traded\":\"0\",\"amount_at_create\":\"0.50943195\",\"price\":78483.4,\"price_str\":\"78483.40\",\"is_liquidation\":false},\"channel\":\"live_orders_btcusd\",\"event\":\"order_created\",\"event_id\":\"00065a1d-7fb3-a130-0001-000101000020\",\"pre_event_id\":\"00065a1d-7fb3-a130-0000-000100000020\",\"order_source\":\"orderbook\"}","recorded_unix_us":1787932603410270}
{"message":"{\"data\":{\"id\":2044303886843910,\"id_str\":\"2044303886843910\",\"order_type\":0,\"order_subtype\":5,\"datetime\":\"1787932603\",\"microtimestamp\":\"1787932603294000\",\"amount\":0.478855,\"amount_str\":\"0.478855\",\"amount_traded\":\"0\",\"amount_at_create\":\"0.478855\",\"price\":2480.31,\"price_str\":\"2480.31\",\"is_liquidation\":false},\"channel\":\"live_orders_ethusd\",\"event\":\"order_created\",\"event_id\":\"00065a1d-7fb3-a130-0001-001202000020\",\"pre_event_id\":\"00065a1d-7fb3-a130-0000-001201000020\",\"order_source\":\"orderbook\"}","recorded_unix_us":1787932603410332}
{"message":"{\"data\":{\"id\":2044303886860294,\"id_str\":\"2044303886860294\",\"order_type\":0,\"order_subtype\":5,\"datetime\":\"1787932603\",\"microtimestamp\":\"1787932603294000\",\"amount\":0.63678994,\"amount_str\":\"0.63678994\",\"amount_traded\":\"0\",\"amount_at_create\":\"0.63678994\",\"price\":78485.36,\"price_str\":\"78485.36\",\"is_liquidation\":false},\"channel\":\"live_orders_btcusd\",\"event\":\"order_created\",\"event_id\":\"00065a1d-7fb3-a130-0002-000102000020\",\"pre_event_id\":\"00065a1d-7fb3-a130-0001-000101000020\",\"order_source\":\"orderbook\"}","recorded_unix_us":1787932603410355}
{"message":"{\"data\":{\"id\":2044303886815247,\"id_str\":\"2044303886815247\",\"order_type\":0,\"order_subtype\":5,\"datetime\":\"1787932603\",\"microtimestamp\":\"1787932603294000\",\"amount\":0.403093,\"amount_str\":\"0.403093\",\"amount_traded\":\"0\",\"amount_at_create\":\"0.403093\",\"price\":2480.31,\"price_str\":\"2480.31\",\"is_liquidation\":false},\"channel\":\"live_orders_ethusd\",\"event\":\"order_deleted\",\"event_id\":\"00065a1d-7fb3-a130-0002-001203000020\",\"pre_event_id\":\"00065a1d-7fb3-a130-0001-001202000020\",\"order_source\":\"orderbook\"}","recorded_unix_us":1787932603410503}
{"message":"{\"data\":{\"id\":2044303885893633,\"id_str\":\"2044303885893633\",\"order_type\":1,\"order_subtype\":5,\"datetime\":\"1787932603\",\"microtimestamp\":\"1787932603294000\",\"amount\":0.25467128,\"amount_str\":\"0.25467128\",\"amount_traded\":\"0\",\"amount_at_create\":\"0.25467128\",\"price\":78532.61,\"price_str\":\"78532.61\",\"is_liquidation\":false},\"channel\":\"live_orders_btcusd\",\"event\":\"order_deleted\",\"event_id\":\"00065a1d-7fb3-a130-0003-000103000020\",\"pre_event_id\":\"00065a1d-7fb3-a130-0002-000102000020\",\"order_source\":\"orderbook\"}","recorded_unix_us":1787932603410526}
{"message":"{\"data\":{\"id\":2044303877033993,\"id_str\":\"2044303877033993\",\"order_type\":0,\"order_subtype\":5,\"datetime\":\"1787932603\",\"microtimestamp\":\"1787932603294000\",\"amount\":2.5,\"amount_str\":\"2.500000\",\"amount_traded\":\"0\",\"amount_at_create\":\"2.500000\",\"price\":2480.81,\"price_str\":\"2480.81\",\"is_liquidation\":false},\"channel\":\"live_orders_ethusd\",\"event\":\"order_deleted\",\"event_id\":\"00065a1d-7fb3-a130-0003-001200000020\",\"pre_event_id\":\"00065a1d-7fb3-a130-0002-001203000020\",\"order_source\":\"orderbook\"}","recorded_unix_us":1787932603410545}
{"message":"{\"data\":{\"id\":2044303886884865,\"id_str\":\"2044303886884865\",\"order_type\":0,\"order_subtype\":5,\"datetime\":\"1787932603\",\"microtimestamp\":\"1787932603294000\",\"amount\":0.1910349,\"amount_str\":\"0.19103490\",\"amount_traded\":\"0\",\"amount_at_create\":\"0.19103490\",\"price\":78487.72,\"price_str\":\"78487.72\",\"is_liquidation\":false},\"channel\":\"live_orders_btcusd\",\"event\":\"order_created\",\"event_id\":\"00065a1d-7fb3-a130-0004-000100000020\",\"pre_event_id\":\"00065a1d-7fb3-a130-0003-000103000020\",\"order_source\":\"orderbook\"}","recorded_unix_us":1787932603410564}
{"message":"{\"data\":{\"id\":2044303886884864,\"id_str\":\"2044303886884864\",\"order_type\":0,\"order_subtype\":5,\"datetime\":\"1787932603\",\"microtimestamp\":\"1787932603294000\",\"amount\":0.055955,\"amount_str\":\"0.055955\",\"amount_traded\":\"0\",\"amount_at_create\":\"0.055955\",\"price\":2479.34,\"price_str\":\"2479.34\",\"is_liquidation\":false},\"channel\":\"live_orders_ethusd\",\"event\":\"order_created\",\"event_id\":\"00065a1d-7fb3-a130-0004-001201000020\",\"pre_event_id\":\"00065a1d-7fb3-a130-0003-001200000020\",\"order_source\":\"orderbook\"}","recorded_unix_us":1787932603410684}
{"message":"{\"data\":{\"id\":2044303885983753,\"id_str\":\"2044303885983753\",\"order_type\":0,\"order_subtype\":5,\"datetime\":\"1787932603\",\"microtimestamp\":\"1787932603296000\",\"amount\":0.06367953,\"amount_str\":\"0.06367953\",\"amount_traded\":\"0\",\"amount_at_create\":\"0.06367953\",\"price\":78518.15,\"price_str\":\"78518.15\",\"is_liquidation\":false},\"channel\":\"live_orders_btcusd\",\"event\":\"order_deleted\",\"event_id\":\"00065a1d-7fb3-a900-0000-000101000020\",\"pre_event_id\":\"00065a1d-7fb3-a130-0004-000100000020\",\"order_source\":\"orderbook\"}","recorded_unix_us":1787932603410706}
{"message":"{\"data\":{\"id\":2044303886905362,\"id_str\":\"2044303886905362\",\"order_type\":1,\"order_subtype\":5,\"datetime\":\"1787932603\",\"microtimestamp\":\"1787932603297000\",\"amount\":0.1,\"amount_str\":\"0.10000000\",\"amount_traded\":\"0\",\"amount_at_create\":\"0.10000000\",\"price\":78522.63,\"price_str\":\"78522.63\",\"is_liquidation\":false},\"channel\":\"live_orders_btcusd\",\"event\":\"order_created\",\"event_id\":\"00065a1d-7fb3-ace8-0000-000102000020\",\"pre_event_id\":\"00065a1d-7fb3-a900-0000-000101000020\",\"order_source\":\"orderbook\"}","recorded_unix_us":1787932603410818}
{"message":"{\"data\":{\"id\":2044303886905362,\"id_str\":\"2044303886905362\",\"order_type\":1,\"order_subtype\":5,\"datetime\":\"1787932603\",\"microtimestamp\":\"1787932603297000\",\"amount\":0.1,\"amount_str\":\"0.10000000\",\"amount_traded\":\"0\",\"amount_at_create\":\"0.10000000\",\"price\":78522.63,\"price_str\":\"78522.63\",\"is_liquidation\":false},\"channel\":\"live_orders_btcusd\",\"event\":\"order_deleted\",\"event_id\":\"00065a1d-7fb3-ace8-0001-000103000020\",\"pre_event_id\":\"00065a1d-7fb3-ace8-0000-000102000020\",\"order_source\":\"orderbook\"}","recorded_unix_us":1787932603410907}
{"message":"{\"data\":{\"id\":2044303885852688,\"id_str\":\"2044303885852688\",\"order_type\":1,\"order_subtype\":5,\"datetime\":\"1787932603\",\"microtimestamp\":\"1787932603297000\",\"amount\":0.6044871,\"amount_str\":\"0.60448710\",\"amount_traded\":\"0\",\"amount_at_create\":\"0.60448710\",\"price\":0.03160362,\"price_str\":\"0.03160362\",\"is_liquidation\":false},\"channel\":\"live_orders_ethbtc\",\"event\":\"order_deleted\",\"event_id\":\"00065a1d-7fb3-ace8-0000-001100000020\",\"pre_event_id\":\"00065a1d-7fb3-4b40-0000-001103000020\",\"order_source\":\"orderbook\"}","recorded_unix_us":1787932603410931}
{"message":"{\"data\":{\"id\":2044303886835715,\"id_str\":\"2044303886835715\",\"order_type\":0,\"order_subtype\":5,\"datetime\":\"1787932603\",\"microtimestamp\":\"1787932603297000\",\"amount\":0.256121,\"amount_str\":\"0.256121\",\"amount_traded\":\"0\",\"amount_at_create\":\"0.256121\",\"price\":2480.31,\"price_str\":\"2480.31\",\"is_liquidation\":false},\"channel\":\"live_orders_ethusd\",\"event\":\"order_deleted\",\"event_id\":\"00065a1d-7fb3-ace8-0000-001202000020\",\"pre_event_id\":\"00065a1d-7fb3-a130-0004-001201000020\",\"order_source\":\"orderbook\"}","recorded_unix_us":1787932603410952}
{"message":"{\"data\":{\"id\":2044303886852154,\"id_str\":\"2044303886852154\",\"order_type\":0,\"order_subtype\":5,\"datetime\":\"1787932603\",\"microtimestamp\":\"1787932603298000\",\"amount\":0.19103698,\"amount_str\":\"0.19103698\",\"amount_traded\":\"0\",\"amount_at_create\":\"0.19103698\",\"price\":78487.33,\"price_str\":\"78487.33\",\"is_liquidation\":false},\"channel\":\"live_orders_btcusd\",\"event\":\"order_deleted\",\"event_id\":\"00065a1d-7fb3-b0d0-0000-000100000020\",\"pre_event_id\":\"00065a1d-7fb3-ace8-0001-000103000020\",\"order_source\":\"orderbook\"}","recorded_unix_us":1787932603411066}
{"message":"{\"data\":{\"id\":2044303886909460,\"id_str\":\"2044303886909460\",\"order_type\":1,\"order_subtype\":5,\"datetime\":\"1787932603\",\"microtimestamp\":\"1787932603298000\",\"amount\":5,\"amount_str\":\"5.000000\",\"amount_traded\":\"0\",\"amount_at_create\":\"5.000000\",\"price\":2481.2,\"price_str\":\"2481.20\",\"is_liquidation\":false},\"channel\":\"live_orders_ethusd\",\"event\":\"order_created\",\"event_id\":\"00065a1d-7fb3-b0d0-0000-001203000020\",\"pre_event_id\":\"00065a1d-7fb3-ace8-0000-001202000020\",\"order_source\":\"orderbook\"}","recorded_unix_us":1787932603411089}
{"message":"{\"data\":{\"id\":2044303886860294,\"id_str\":\"2044303886860294\",\"order_type\":0,\"order_subtype\":5,\"datetime\":\"1787932603\",\"microtimestamp\":\"1787932603298000\",\"amount\":0.63678994,\"amount_str\":\"0.63678994\",\"amount_traded\":\"0\",\"amount_at_create\":\"0.63678994\",\"price\":78485.36,\"price_str\":\"78485.36\",\"is_liquidation\":false},\"channel\":\"live_orders_btcusd\",\"event\":\"order_deleted\",\"event_id\":\"00065a1d-7fb3-b0d0-0001-000101000020\",\"pre_event_id\":\"00065a1d-7fb3-b0d0-0000-000100000020\",\"order_source\":\"orderbook\"}","recorded_unix_us":1787932603411201}
{"message":"{\"data\":{\"id\":2044303886917637,\"id_str\":\"2044303886917637\",\"order_type\":1,\"order_subtype\":5,\"datetime\":\"1787932603\",\"microtimestamp\":\"1787932603299000\",\"amount\":2.5,\"amount_str\":\"2.500000\",\"amount_traded\":\"0\",\"amount_at_create\":\"2.500000\",\"price\":2481.08,\"price_str\":\"2481.08\",\"is_liquidation\":false},\"channel\":\"live_orders_ethusd\",\"event\":\"order_created\",\"event_id\":\"00065a1d-7fb3-b4b8-0000-001200000020\",\"pre_event_id\":\"00065a1d-7fb3-b0d0-0000-001203000020\",\"order_source\":\"orderbook\"}","recorded_unix_us":1787932603411224}
{"message":"{\"data\":{\"id\":2044303886843908,\"id_str\":\"2044303886843908\",\"order_type\":0,\"order_subtype\":5,\"datetime\":\"1787932603\",\"microtimestamp\":\"1787932603299000\",\"amount\":0.403051,\"amount_str\":\"0.403051\",\"amount_traded\":\"0\",\"amount_at_create\":\"0.403051\",\"price\":2480.25,\"price_str\":\"2480.25\",\"is_liquidation\":false},\"channel\":\"live_orders_ethusd\",\"event\":\"order_deleted\",\"event_id\":\"00065a1d-7fb3-b4b8-0001-001201000020\",\"pre_event_id\":\"00065a1d-7fb3-b4b8-0000-001200000020\",\"order_source\":\"orderbook\"}","recorded_unix_us":1787932603411293}
{"message":"{\"data\":{\"id\":2044303886921732,\"id_str\":\"2044303886921732\",\"order_type\":0,\"order_subtype\":5,\"datetime\":\"1787932603\",\"microtimestamp\":\"1787932603301000\",\"amount\":0.63678247,\"amount_str\":\"0.63678247\",\"amount_traded\":\"0\",\"amount_at_create\":\"0.63678247\",\"price\":78485.8,\"price_str\":\"78485.80\",\"is_liquidation\":false},\"channel\":\"live_orders_btcusd\",\"event\":\"order_created\",\"event_id\":\"00065a1d-7fb3-bc88-0000-000102000020\",\"pre_event_id\":\"00065a1d-7fb3-b0d0-0001-000101000020\",\"order_source\":\"orderbook\"}","recorded_unix_us":1787932603411408}
{"message":"{\"data\":{\"id\":2044303885983754,\"id_str\":\"2044303885983754\",\"order_type\":0,\"order_subtype\":5,\"datetime\":\"1787932603\",\"microtimestamp\":\"1787932603301000\",\"amount\":0.25478772,\"amount_str\":\"0.25478772\",\"amount_traded\":\"0\",\"amount_at_create\":\"0.25478772\",\"price\":78496.71,\"price_str\":\"78496.71\",\"is_liquidation\":false},\"channel\":\"live_orders_btcusd\",\"event\":\"order_deleted\",\"event_id\":\"00065a1d-7fb3-bc88-0001-000103000020\",\"pre_event_id\":\"00065a1d-7fb3-bc88-0000-000102000020\",\"order_source\":\"orderbook\"}","recorded_unix_us":1787932603411431}
{"message":"{\"data\":{\"id\":2044303886925839,\"id_str\":\"2044303886925839\",\"order_type\":0,\"order_subtype\":5,\"datetime\":\"1787932603\",\"microtimestamp\":\"1787932603302000\",\"amount\":0.403054,\"amount_str\":\"0.403054\",\"amount_traded\":\"0\",\"amount_at_create\":\"0.403054\",\"price\":2480.31,\"price_str\":\"2480.31\",\"is_liquidation\":false},\"channel\":\"live_orders_ethusd\",\"event\":\"order_created\",\"event_id\":\"00065a1d-7fb3-c070-0000-001202000020\",\"pre_event_id\":\"00065a1d-7fb3-b4b8-0001-001201000020\",\"order_source\":\"orderbook\"}","recorded_unix_us":1787932603411541}
{"message":"{\"data\":{\"id\":2044303886938114,\"id_str\":\"2044303886938114\",\"order_type\":0,\"order_subtype\":5,\"datetime\":\"1787932603\",\"microtimestamp\":\"1787932603304000\",\"amount\":0.60468718,\"amount_str\":\"0.60468718\",\"amount_traded\":\"0\",\"amount_at_create\":\"0.60468718\",\"price\":0.03159286,\"price_str\":\"0.03159286\",\"is_liquidation\":false},\"channel\":\"live_orders_ethbtc\",\"event\":\"order_created\",\"event_id\":\"00065a1d-7fb3-c840-0000-001101000020\",\"pre_event_id\":\"00065a1d-7fb3-ace8-0000-001100000020\",\"order_source\":\"orderbook\"}","recorded_unix_us":1787932603411564}
{"message":"{\"data\":{\"id\":2044303886938119,\"id_str\":\"2044303886938119\",\"order_type\":1,\"order_subtype\":5,\"datetime\":\"1787932603\",\"microtimestamp\":\"1787932603304000\",\"amount\":0.042369,\"amount_str\":\"0.042369\",\"amount_traded\":\"0\",\"amount_at_create\":\"0.042369\",\"price\":2480.83,\"price_str\":\"2480.83\",\"is_liquidation\":false},\"channel\":\"live_orders_ethusd\",\"event\":\"order_created\",\"event_id\":\"00065a1d-7fb3-c840-0000-001203000020\",\"pre_event_id\":\"00065a1d-7fb3-c070-0000-001202000020\",\"order_source\":\"orderbook\"}","recorded_unix_us":1787932603411645}
{"message":"{\"data\":{\"id\":2044303886917637,\"id_str\":\"2044303886917637\",\"order_type\":1,\"order_subtype\":5,\"datetime\":\"1787932603\",\"microtimestamp\":\"1787932603304000\",\"amount\":2.5,\"amount_str\":\"2.500000\",\"amount_traded\":\"0\",\"amount_at_create\":\"2.500000\",\"price\":2481.08,\"price_str\":\"2481.08\",\"is_liquidation\":false},\"channel\":\"live_orders_ethusd\",\"event\":\"order_deleted\",\"event_id\":\"00065a1d-7fb3-c840-0001-001200000020\",\"pre_event_id\":\"00065a1d-7fb3-c840-0000-001203000020\",\"order_source\":\"orderbook\"}","recorded_unix_us":1787932603411749}
{"message":"{\"data\":{\"id\":2044303886909460,\"id_str\":\"2044303886909460\",\"order_type\":1,\"order_subtype\":5,\"datetime\":\"1787932603\",\"microtimestamp\":\"1787932603305000\",\"amount\":5,\"amount_str\":\"5.000000\",\"amount_traded\":\"0\",\"amount_at_create\":\"5.000000\",\"price\":2481.2,\"price_str\":\"2481.20\",\"is_liquidation\":false},\"channel\":\"live_orders_ethusd\",\"event\":\"order_deleted\",\"event_id\":\"00065a1d-7fb3-cc28-0000-001201000020\",\"pre_event_id\":\"00065a1d-7fb3-c840-0001-001200000020\",\"order_source\":\"orderbook\"}","recorded_unix_us":1787932603411772}
{"message":"{\"data\":{\"id\":2044303886946304,\"id_str\":\"2044303886946304\",\"order_type\":1,\"order_subtype\":5,\"datetime\":\"1787932603\",\"microtimestamp\":\"1787932603306000\",\"amount\":0.06310787,\"amount_str\":\"0.06310787\",\"amount_traded\":\"0\",\"amount_at_create\":\"0.06310787\",\"price\":78525.26,\"price_str\":\"78525.26\",\"is_liquidation\":false},\"channel\":\"live_orders_btcusd\",\"event\":\"order_created\",\"event_id\":\"00065a1d-7fb3-d010-0000-000100000020\",\"pre_event_id\":\"00065a1d-7fb3-bc88-0001-000103000020\",\"order_source\":\"orderbook\"}","recorded_unix_us":1787932603411852}
{"message":"{\"data\":{\"id\":2044303886938119,\"id_str\":\"2044303886938119\",\"order_type\":1,\"order_subtype\":5,\"datetime\":\"1787932603\",\"microtimestamp\":\"1787932603308000\",\"amount\":0.042369,\"amount_str\":\"0.042369\",\"amount_traded\":\"0\",\"amount_at_create\":\"0.042369\",\"price\":2480.83,\"price_str\":\"2480.83\",\"is_liquidation\":false},\"channel\":\"live_orders_ethusd\",\"event\":\"order_deleted\",\"event_id\":\"00065a1d-7fb3-d7e0-0000-001202000020\",\"pre_event_id\":\"00065a1d-7fb3-cc28-0000-001201000020\",\"order_source\":\"orderbook\"}","recorded_unix_us":1787932603411956}
{"message":"{\"data\":{\"id\":2044303886860289,\"id_str\":\"2044303886860289\",\"order_type\":0,\"order_subtype\":5,\"datetime\":\"1787932603\",\"microtimestamp\":\"1787932603309000\",\"amount\":0.50943195,\"amount_str\":\"0.50943195\",\"amount_traded\":\"0\",\"amount_at_create\":\"0.50943195\",\"price\":78483.4,\"price_str\":\"78483.40\",\"is_liquidation\":false},\"channel\":\"live_orders_btcusd\",\"event\":\"order_deleted\",\"event_id\":\"00065a1d-7fb3-dbc8-0000-000101000020\",\"pre_event_id\":\"00065a1d-7fb3-d010-0000-000100000020\",\"order_source\":\"orderbook\"}","recorded_unix_us":1787932603411983}
{"message":"{\"data\":{\"id\":2044303886684160,\"id_str\":\"2044303886684160\",\"order_type\":0,\"order_subtype\":5,\"datetime\":\"1787932603\",\"microtimestamp\":\"1787932603309000\",\"amount\":0.041977,\"amount_str\":\"0.041977\",\"amount_traded\":\"0\",\"amount_at_create\":\"0.041977\",\"price\":2480.78,\"price_str\":\"2480.78\",\"is_liquidation\":false},\"channel\":\"live_orders_ethusd\",\"event\":\"order_deleted\",\"event_id\":\"00065a1d-7fb3-dbc8-0000-001203000020\",\"pre_event_id\":\"00065a1d-7fb3-d7e0-0000-001202000020\",\"order_source\":\"orderbook\"}","recorded_unix_us":1787932603412095}
{"message":"{\"data\":{\"id\":2044303886966789,\"id_str\":\"2044303886966789\",\"order_type\":1,\"order_subtype\":5,\"datetime\":\"1787932603\",\"microtimestamp\":\"1787932603311000\",\"amount\":0.1,\"amount_str\":\"0.10000000\",\"amount_traded\":\"0\",\"amount_at_create\":\"0.10000000\",\"price\":78522.62,\"price_str\":\"78522.62\",\"is_liquidation\":false},\"channel\":\"live_orders_btcusd\",\"event\":\"order_created\",\"event_id\":\"00065a1d-7fb3-e398-0000-000102000020\",\"pre_event_id\":\"00065a1d-7fb3-dbc8-0000-000101000020\",\"order_source\":\"orderbook\"}","recorded_unix_us":1787932603412156}
{"message":"{\"data\":{\"id\":2044303886966789,\"id_str\":\"2044303886966789\",\"order_type\":1,\"order_subtype\":5,\"datetime\":\"1787932603\",\"microtimestamp\":\"1787932603311000\",\"amount\":0.1,\"amount_str\":\"0.10000000\",\"amount_traded\":\"0\",\"amount_at_create\":\"0.10000000\",\"price\":78522.62,\"price_str\":\"78522.62\",\"is_liquidation\":false},\"channel\":\"live_orders_btcusd\",\"event\":\"order_deleted\",\"event_id\":\"00065a1d-7fb3-e398-0001-000103000020\",\"pre_event_id\":\"00065a1d-7fb3-e398-0000-000102000020\",\"order_source\":\"orderbook\"}","recorded_unix_us":1787932603412179}
{"message":"{\"data\":{\"id\":2044303886856223,\"id_str\":\"2044303886856223\",\"order_type\":1,\"order_subtype\":0,\"datetime\":\"1787932603\",\"microtimestamp\":\"1787932603314000\",\"amount\":0.06310787,\"amount_str\":\"0.06310787\",\"amount_traded\":\"0\",\"amount_at_create\":\"0.06310787\",\"price\":78553.92,\"price_str\":\"78553.92\",\"is_liquidation\":false},\"channel\":\"live_orders_btcusd\",\"event\":\"order_deleted\",\"event_id\":\"00065a1d-7fb3-ef50-0000-000100000020\",\"pre_event_id\":\"00065a1d-7fb3-e398-0001-000103000020\",\"order_source\":\"orderbook\"}","recorded_unix_us":1787932603412286}
{"message":"{\"data\":{\"id\":2044303886995459,\"id_str\":\"2044303886995459\",\"order_type\":0,\"order_subtype\":5,\"datetime\":\"1787932603\",\"microtimestamp\":\"1787932603319000\",\"amount\":0.50942567,\"amount_str\":\"0.50942567\",\"amount_traded\":\"0\",\"amount_at_create\":\"0.50942567\",\"price\":78483.91,\"price_str\":\"78483.91\",\"is_liquidation\":false},\"channel\":\"live_orders_btcusd\",\"event\":\"order_created\",\"event_id\":\"00065a1d-7fb4-02d8-0000-000101000020\",\"pre_event_id\":\"00065a1d-7fb3-ef50-0000-000100000020\",\"order_source\":\"orderbook\"}","recorded_unix_us":1787932603412348}
{"message":"{\"data\":{\"id\":2044303886999562,\"id_str\":\"2044303886999562\",\"order_type\":0,\"order_subtype\":5,\"datetime\":\"1787932603\",\"microtimestamp\":\"1787932603319000\",\"amount\":0.403053,\"amount_str\":\"0.403053\",\"amount_traded\":\"0\",\"amount_at_create\":\"0.403053\",\"price\":2480.51,\"price_str\":\"2480.51\",\"is_liquidation\":false},\"channel\":\"live_orders_ethusd\",\"event\":\"order_created\",\"event_id\":\"00065a1d-7fb4-02d8-0000-001200000020\",\"pre_event_id\":\"00065a1d-7fb3-dbc8-0000-001203000020\",\"order_source\":\"orderbook\"}","recorded_unix_us":1787932603412371}
{"message":"{\"data\":{\"id\":2044303870570506,\"id_str\":\"2044303870570506\",\"order_type\":1,\"order_subtype\":5,\"datetime\":\"1787932603\",\"microtimestamp\":\"1787932603322000\",\"amount\":4.087085,\"amount_str\":\"4.087085\",\"amount_traded\":\"0\",\"amount_at_create\":\"4.087085\",\"price\":2505.55,\"price_str\":\"2505.55\",\"is_liquidation\":false},\"channel\":\"live_orders_ethusd\",\"event\":\"order_deleted\",\"event_id\":\"00065a1d-7fb4-0e90-0000-001201000020\",\"pre_event_id\":\"00065a1d-7fb4-02d8-0000-001200000020\",\"order_source\":\"orderbook\"}","recorded_unix_us":1787932603412486}
{"message":"{\"data\":{\"id\":2044303887011852,\"id_str\":\"2044303887011852\",\"order_type\":1,\"order_subtype\":5,\"datetime\":\"1787932603\",\"microtimestamp\":\"1787932603323000\",\"amount\":0.60439221,\"amount_str\":\"0.60439221\",\"amount_traded\":\"0\",\"amount_at_create\":\"0.60439221\",\"price\":0.03160817,\"price_str\":\"0.03160817\",\"is_liquidation\":false},\"channel\":\"live_orders_ethbtc\",\"event\":\"order_created\",\"event_id\":\"00065a1d-7fb4-1278-0000-001102000020\",\"pre_event_id\":\"00065a1d-7fb3-c840-0000-001101000020\",\"order_source\":\"orderbook\"}","recorded_unix_us":1787932603412508}
{"message":"{\"data\":{\"id\":2044303887020039,\"id_str\":\"2044303887020039\",\"order_type\":1,\"order_subtype\":5,\"datetime\":\"1787932603\",\"microtimestamp\":\"1787932603325000\",\"amount\":1,\"amount_str\":\"1.000000\",\"amount_traded\":\"0\",\"amount_at_create\":\"1.000000\",\"price\":2481.09,\"price_str\":\"2481.09\",\"is_liquidation\":false},\"channel\":\"live_orders_ethusd\",\"event\":\"order_created\",\"event_id\":\"00065a1d-7fb4-1a48-0000-001202000020\",\"pre_event_id\":\"00065a1d-7fb4-0e90-0000-001201000020\",\"order_source\":\"orderbook\"}","recorded_unix_us":1787932603412582}
{"message":"{\"data\":{\"id\":2044303887024136,\"id_str\":\"2044303887024136\",\"order_type\":1,\"order_subtype\":5,\"datetime\":\"1787932603\",\"microtimestamp\":\"1787932603325000\",\"amount\":0.06310787,\"amount_str\":\"0.06310787\",\"amount_traded\":\"0\",\"amount_at_create\":\"0.06310787\",\"price\":78521.87,\"price_str\":\"78521.87\",\"is_liquidation\":false},\"channel\":\"live_orders_btcusd\",\"event\":\"order_created\",\"event_id\":\"00065a1d-7fb4-1a48-0000-000102000020\",\"pre_event_id\":\"00065a1d-7fb4-02d8-0000-000101000020\",\"order_source\":\"orderbook\"}","recorded_unix_us":1787932603412664}
{"message":"{\"data\":{\"id\":2044303887024136,\"id_str\":\"2044303887024136\",\"order_type\":1,\"order_subtype\":5,\"datetime\":\"1787932603\",\"microtimestamp\":\"1787932603325000\",\"amount\":0.06310787,\"amount_str\":\"0.06310787\",\"amount_traded\":\"0\",\"amount_at_create\":\"0.06310787\",\"price\":78521.87,\"price_str\":\"78521.87\",\"is_liquidation\":false},\"channel\":\"live_orders_btcusd\",\"event\":\"order_deleted\",\"event_id\":\"00065a1d-7fb4-1a48-0001-000103000020\",\"pre_event_id\":\"00065a1d-7fb4-1a48-0000-000102000020\",\"order_source\":\"orderbook\"}","recorded_unix_us":1787932603412683}
{"message":"{\"data\":{\"id\":2044303881850882,\"id_str\":\"2044303881850882\",\"order_type\":1,\"order_subtype\":5,\"datetime\":\"1787932603\",\"microtimestamp\":\"1787932603326000\",\"amount\":2.015283,\"amount_str\":\"2.015283\",\"amount_traded\":\"0\",\"amount_at_create\":\"2.015283\",\"price\":2481.51,\"price_str\":\"2481.51\",\"is_liquidation\":false},\"channel\":\"live_orders_ethusd\",\"event\":\"order_deleted\",\"event_id\":\"00065a1d-7fb4-1e30-0000-001203000020\",\"pre_event_id\":\"00065a1d-7fb4-1a48-0000-001202000020\",\"order_source\":\"orderbook\"}","recorded_unix_us":1787932603412763}
{"message":"{\"data\":{\"id\":2044303887036416,\"id_str\":\"2044303887036416\",\"order_type\":1,\"order_subtype\":5,\"datetime\":\"1787932603\",\"microtimestamp\":\"1787932603328000\",\"amount\":0.1,\"amount_str\":\"0.10000000\",\"amount_traded\":\"0\",\"amount_at_create\":\"0.10000000\",\"price\":78522.63,\"price_str\":\"78522.63\",\"is_liquidation\":false},\"channel\":\"live_orders_btcusd\",\"event\":\"order_created\",\"event_id\":\"00065a1d-7fb4-2600-0000-000100000020\",\"pre_event_id\":\"00065a1d-7fb4-1a48-0001-000103000020\",\"order_source\":\"orderbook\"}","recorded_unix_us":1787932603412852}
{"message":"{\"data\":{\"id\":2044303887036416,\"id_str\":\"2044303887036416\",\"order_type\":1,\"order_subtype\":5,\"datetime\":\"1787932603\",\"microtimestamp\":\"1787932603328000\",\"amount\":0.1,\"amount_str\":\"0.10000000\",\"amount_traded\":\"0\",\"amount_at_create\":\"0.10000000\",\"price\":78522.63,\"price_str\":\"78522.63\",\"is_liquidation\":false},\"channel\":\"live_orders_btcusd\",\"event\":\"order_deleted\",\"event_id\":\"00065a1d-7fb4-2600-0001-000101000020\",\"pre_event_id\":\"00065a1d-7fb4-2600-0000-000100000020\",\"order_source\":\"orderbook\"}","recorded_unix_us":1787932603412876}
{"message":"{\"data\":{\"id\":2044303887036424,\"id_str\":\"2044303887036424\",\"order_type\":1,\"order_subtype\":5,\"datetime\":\"1787932603\",\"microtimestamp\":\"1787932603328000\",\"amount\":0.25464011,\"amount_str\":\"0.25464011\",\"amount_traded\":\"0\",\"amount_at_create\":\"0.25464011\",\"price\":78542.22,\"price_str\":\"78542.22\",\"is_liquidation\":false},\"channel\":\"live_orders_btcusd\",\"event\":\"order_created\",\"event_id\":\"00065a1d-7fb4-2600-0002-000102000020\",\"pre_event_id\":\"00065a1d-7fb4-2600-0001-000101000020\",\"order_source\":\"orderbook\"}","recorded_unix_us":1787932603412928}
{"message":"{\"data\":{\"id\":2044303887040514,\"id_str\":\"2044303887040514\",\"order_type\":0,\"order_subtype\":5,\"datetime\":\"1787932603\",\"microtimestamp\":\"1787932603329000\",\"amount\":0.06367777,\"amount_str\":\"0.06367777\",\"amount_traded\":\"0\",\"amount_at_create\":\"0.06367777\",\"price\":78520.33,\"price_str\":\"78520.33\",\"is_liquidation\":false},\"channel\":\"live_orders_btcusd\",\"event\":\"order_created\",\"event_id\":\"00065a1d-7fb4-29e8-0000-000103000020\",\"pre_event_id\":\"00065a1d-7fb4-2600-0002-000102000020\",\"order_source\":\"orderbook\"}","recorded_unix_us":1787932603412947}
{"message":"{\"data\":{\"id\":2044303886925839,\"id_str\":\"2044303886925839\",\"order_type\":0,\"order_subtype\":5,\"datetime\":\"1787932603\",\"microtimestamp\":\"1787932603330000\",\"amount\":0.403054,\"amount_str\":\"0.403054\",\"amount_traded\":\"0\",\"amount_at_create\":\"0.403054\",\"price\":2480.31,\"price_str\":\"2480.31\",\"is_liquidation\":false},\"channel\":\"live_orders_ethusd\",\"event\":\"order_deleted\",\"event_id\":\"00065a1d-7fb4-2dd0-0000-001200000020\",\"pre_event_id\":\"00065a1d-7fb4-1e30-0000-001203000020\",\"order_source\":\"orderbook\"}","recorded_unix_us":1787932603413013}
{"message":"{\"data\":{\"id\":2044303887044614,\"id_str\":\"2044303887044614\",\"order_type\":0,\"order_subtype\":5,\"datetime\":\"1787932603\",\"microtimestamp\":\"1787932603331000\",\"amount\":0.06368003,\"amount_str\":\"0.06368003\",\"amount_traded\":\"0\",\"amount_at_create\":\"0.06368003\",\"price\":78517.54,\"price_str\":\"78517.54\",\"is_liquidation\":false},\"channel\":\"live_orders_btcusd\",\"event\":\"order_created\",\"event_id\":\"00065a1d-7fb4-31b8-0000-000100000020\",\"pre_event_id\":\"00065a1d-7fb4-29e8-0000-000103000020\",\"order_source\":\"orderbook\"}","recorded_unix_us":1787932603413098}
{"message":"{\"data\":{\"id\":2044303887048725,\"id_str\":\"2044303887048725\",\"order_type\":1,\"order_subtype\":5,\"datetime\":\"1787932603\",\"microtimestamp\":\"1787932603332000\",\"amount\":14.02,\"amount_str\":\"14.020000\",\"amount_traded\":\"0\",\"amount_at_create\":\"14.020000\",\"price\":2482.32,\"price_str\":\"2482.32\",\"is_liquidation\":false},\"channel\":\"live_orders_ethusd\",\"event\":\"order_created\",\"event_id\":\"00065a1d-7fb4-35a0-0000-001201000020\",\"pre_event_id\":\"00065a1d-7fb4-2dd0-0000-001200000020\",\"order_source\":\"orderbook\"}","recorded_unix_us":1787932603413116}
{"message":"{\"data\":{\"id\":2044303887052800,\"id_str\":\"2044303887052800\",\"order_type\":0,\"order_subtype\":5,\"datetime\":\"1787932603\",\"microtimestamp\":\"1787932603332000\",\"amount\":0.04156,\"amount_str\":\"0.041560\",\"amount_traded\":\"0\",\"amount_at_create\":\"0.041560\",\"price\":2480.81,\"price_str\":\"2480.81\",\"is_liquidation\":false},\"channel\":\"live_orders_ethusd\",\"event\":\"order_created\",\"event_id\":\"00065a1d-7fb4-35a0-0001-001202000020\",\"pre_event_id\":\"00065a1d-7fb4-35a0-0000-001201000020\",\"order_source\":\"orderbook\"}","recorded_unix_us":1787932603413185}
{"message":"{\"data\":{\"id\":2044303887052803,\"id_str\":\"2044303887052803\",\"order_type\":1,\"order_subtype\":5,\"datetime\":\"1787932603\",\"microtimestamp\":\"1787932603332000\",\"amount\":0.041584,\"amount_str\":\"0.041584\",\"amount_traded\":\"0\",\"amount_at_create\":\"0.041584\",\"price\":2480.86,\"price_str\":\"2480.86\",\"is_liquidation\":false},\"channel\":\"live_orders_ethusd\",\"event\":\"order_created\",\"event_id\":\"00065a1d-7fb4-35a0-0002-001203000020\",\"pre_event_id\":\"00065a1d-7fb4-35a0-0001-001202000020\",\"order_source\":\"orderbook\"}","recorded_unix_us":1787932603413272}
{"message":"{\"data\":{\"id\":2044303886483462,\"id_str\":\"2044303886483462\",\"order_type\":0,\"order_subtype\":5,\"datetime\":\"1787932603\",\"microtimestamp\":\"1787932603336000\",\"amount\":0.00140266,\"amount_str\":\"0.00140266\",\"amount_traded\":\"0\",\"amount_at_create\":\"0.00140266\",\"price\":70668.36,\"price_str\":\"70668.36\",\"is_liquidation\":false},\"channel\":\"live_orders_btcusd\",\"event\":\"order_deleted\",\"event_id\":\"00065a1d-7fb4-4540-0000-000101000020\",\"pre_event_id\":\"00065a1d-7fb4-31b8-0000-000100000020\",\"order_source\":\"orderbook\"}","recorded_unix_us":1787932603413290}
{"message":"{\"data\":{\"id\":2044303886782469,\"id_str\":\"2044303886782469\",\"order_type\":0,\"order_subtype\":5,\"datetime\":\"1787932603\",\"microtimestamp\":\"1787932603336000\",\"amount\":0.00140266,\"amount_str\":\"0.00140266\",\"amount_traded\":\"0\",\"amount_at_create\":\"0.00140266\",\"price\":70668.36,\"price_str\":\"70668.36\",\"is_liquidation\":false},\"channel\":\"live_orders_btcusd\",\"event\":\"order_deleted\",\"event_id\":\"00065a1d-7fb4-4540-0001-000102000020\",\"pre_event_id\":\"00065a1d-7fb4-4540-0000-000101000020\",\"order_source\":\"orderbook\"}","recorded_unix_us":1787932603413357}
{"message":"{\"data\":{\"id\":2044303887077403,\"id_str\":\"2044303887077403\",\"order_type\":0,\"order_subtype\":5,\"datetime\":\"1787932603\",\"microtimestamp\":\"1787932603339000\",\"amount\":0.403058,\"amount_str\":\"0.403058\",\"amount_traded\":\"0\",\"amount_at_create\":\"0.403058\",\"price\":2480.25,\"price_str\":\"2480.25\",\"is_liquidation\":false},\"channel\":\"live_orders_ethusd\",\"event\":\"order_created\",\"event_id\":\"00065a1d-7fb4-50f8-0000-001200000020\",\"pre_event_id\":\"00065a1d-7fb4-35a0-0002-001203000020\",\"order_source\":\"orderbook\"}","recorded_unix_us":1787932603413485}
{"message":"{\"data\":{\"id\":2044303886884865,\"id_str\":\"2044303886884865\",\"order_type\":0,\"order_subtype\":5,\"datetime\":\"1787932603\",\"microtimestamp\":\"1787932603341000\",\"amount\":0.1910349,\"amount_str\":\"0.19103490\",\"amount_traded\":\"0\",\"amount_at_create\":\"0.19103490\",\"price\":78487.72,\"price_str\":\"78487.72\",\"is_liquidation\":false},\"channel\":\"live_orders_btcusd\",\"event\":\"order_deleted\",\"event_id\":\"00065a1d-7fb4-58c8-0000-000103000020\",\"pre_event_id\":\"00065a1d-7fb4-4540-0001-000102000020\",\"order_source\":\"orderbook\"}","recorded_unix_us":1787932603413504}
{"message":"{\"data\":{\"id\":2044303887089664,\"id_str\":\"2044303887089664\",\"order_type\":0,\"order_subtype\":5,\"datetime\":\"1787932603\",\"microtimestamp\":\"1787932603341000\",\"amount\":0.2547528,\"amount_str\":\"0.25475280\",\"amount_traded\":\"0\",\"amount_at_create\":\"0.25475280\",\"price\":78507.47,\"price_str\":\"78507.47\",\"is_liquidation\":false},\"channel\":\"live_orders_btcusd\",\"event\":\"order_created\",\"event_id\":\"00065a1d-7fb4-58c8-0001-000100000020\",\"pre_event_id\":\"00065a1d-7fb4-58c8-0000-000103000020\",\"order_source\":\"orderbook\"}","recorded_unix_us":1787932603413520}
{"message":"{\"data\":{\"id\":2044303886921732,\"id_str\":\"2044303886921732\",\"order_type\":0,\"order_subtype\":5,\"datetime\":\"1787932603\",\"microtimestamp\":\"1787932603341000\",\"amount\":0.63678247,\"amount_str\":\"0.63678247\",\"amount_traded\":\"0\",\"amount_at_create\":\"0.63678247\",\"price\":78485.8,\"price_str\":\"78485.80\",\"is_liquidation\":false},\"channel\":\"live_orders_btcusd\",\"event\":\"order_deleted\",\"event_id\":\"00065a1d-7fb4-58c8-0002-000101000020\",\"pre_event_id\":\"00065a1d-7fb4-58c8-0001-000100000020\",\"order_source\":\"orderbook\"}","recorded_unix_us":1787932603413588}
{"message":"{\"data\":{\"id\":2044303886995459,\"id_str\":\"2044303886995459\",\"order_type\":0,\"order_subtype\":5,\"datetime\":\"1787932603\",\"microtimestamp\":\"1787932603342000\",\"amount\":0.50942567,\"amount_str\":\"0.50942567\",\"amount_traded\":\"0\",\"amount_at_create\":\"0.50942567\",\"price\":78483.91,\"price_str\":\"78483.91\",\"is_liquidation\":false},\"channel\":\"live_orders_btcusd\",\"event\":\"order_deleted\",\"event_id\":\"00065a1d-7fb4-5cb0-0000-000102000020\",\"pre_event_id\":\"00065a1d-7fb4-58c8-0002-000101000020\",\"order_source\":\"orderbook\"}","recorded_unix_us":1787932603413648}
{"message":"{\"data\":{\"id\":2044303887110149,\"id_str\":\"2044303887110149\",\"order_type\":0,\"order_subtype\":5,\"datetime\":\"1787932603\",\"microtimestamp\":\"1787932603346000\",\"amount\":0.00140266,\"amount_str\":\"0.00140266\",\"amount_traded\":\"0\",\"amount_at_create\":\"0.00140266\",\"price\":70666.76,\"price_str\":\"70666.76\",\"is_liquidation\":false},\"channel\":\"live_orders_btcusd\",\"event\":\"order_created\",\"event_id\":\"00065a1d-7fb4-6c50-0000-000103000020\",\"pre_event_id\":\"00065a1d-7fb4-5cb0-0000-000102000020\",\"order_source\":\"orderbook\"}","recorded_unix_us":1787932603413706}
{"message":"{\"data\":{\"id\":2044303887118351,\"id_str\":\"2044303887118351\",\"order_type\":1,\"order_subtype\":5,\"datetime\":\"1787932603\",\"microtimestamp\":\"1787932603349000\",\"amount\":0.1,\"amount_str\":\"0.10000000\",\"amount_traded\":\"0\",\"amount_at_create\":\"0.10000000\",\"price\":78522.62,\"price_str\":\"78522.62\",\"is_liquidation\":false},\"channel\":\"live_orders_btcusd\",\"event\":\"order_created\",\"event_id\":\"00065a1d-7fb4-7808-0000-000100000020\",\"pre_event_id\":\"00065a1d-7fb4-6c50-0000-000103000020\",\"order_source\":\"orderbook\"}","recorded_unix_us":1787932603413764}
{"message":"{\"data\":{\"id\":2044303887118351,\"id_str\":\"2044303887118351\",\"order_type\":1,\"order_subtype\":5,\"datetime\":\"1787932603\",\"microtimestamp\":\"1787932603349000\",\"amount\":0.1,\"amount_str\":\"0.10000000\",\"amount_traded\":\"0\",\"amount_at_create\":\"0.10000000\",\"price\":78522.62,\"price_str\":\"78522.62\",\"is_liquidation\":false},\"channel\":\"live_orders_btcusd\",\"event\":\"order_deleted\",\"event_id\":\"00065a1d-7fb4-7808-0001-000101000020\",\"pre_event_id\":\"00065a1d-7fb4-7808-0000-000100000020\",\"order_source\":\"orderbook\"}","recorded_unix_us":1787932603413859}
{"message":"{\"data\":{\"id\":2044303887126541,\"id_str\":\"2044303887126541\",\"order_type\":0,\"order_subtype\":5,\"datetime\":\"1787932603\",\"microtimestamp\":\"1787932603351000\",\"amount\":0.19103465,\"amount_str\":\"0.19103465\",\"amount_traded\":\"0\",\"amount_at_create\":\"0.19103465\",\"price\":78486.74,\"price_str\":\"78486.74\",\"is_liquidation\":false},\"channel\":\"live_orders_btcusd\",\"event\":\"order_created\",\"event_id\":\"00065a1d-7fb4-7fd8-0000-000102000020\",\"pre_event_id\":\"00065a1d-7fb4-7808-0001-000101000020\",\"order_source\":\"orderbook\"}","recorded_unix_us":1787932603413877}
{"message":"{\"data\":{\"id\":2044303887130629,\"id_str\":\"2044303887130629\",\"order_type\":0,\"order_subtype\":5,\"datetime\":\"1787932603\",\"microtimestamp\":\"1787932603351000\",\"amount\":5,\"amount_str\":\"5.000000\",\"amount_traded\":\"0\",\"amount_at_create\":\"5.000000\",\"price\":2480.82,\"price_str\":\"2480.82\",\"is_liquidation\":false},\"channel\":\"live_orders_ethusd\",\"event\":\"order_created\",\"event_id\":\"00065a1d-7fb4-7fd8-0000-001201000020\",\"pre_event_id\":\"00065a1d-7fb4-50f8-0000-001200000020\",\"order_source\":\"orderbook\"}","recorded_unix_us":1787932603413952}
{"message":"{\"data\":{\"id\":2044303887040514,\"id_str\":\"2044303887040514\",\"order_type\":0,\"order_subtype\":5,\"datetime\":\"1787932603\",\"microtimestamp\":\"1787932603352000\",\"amount\":0.06367777,\"amount_str\":\"0.06367777\",\"amount_traded\":\"0\",\"amount_at_create\":\"0.06367777\",\"price\":78520.33,\"price_str\":\"78520.33\",\"is_liquidation\":false},\"channel\":\"live_orders_btcusd\",\"event\":\"order_deleted\",\"event_id\":\"00065a1d-7fb4-83c0-0000-000103000020\",\"pre_event_id\":\"00065a1d-7fb4-7fd8-0000-000102000020\",\"order_source\":\"orderbook\"}","recorded_unix_us":1787932603413973}
{"message":"{\"data\":{\"id\":2044303887134721,\"id_str\":\"2044303887134721\",\"order_type\":0,\"order_subtype\":5,\"datetime\":\"1787932603\",\"microtimestamp\":\"1787932603352000\",\"amount\":2.5,\"amount_str\":\"2.500000\",\"amount_traded\":\"0\",\"amount_at_create\":\"2.500000\",\"price\":2480.82,\"price_str\":\"2480.82\",\"is_liquidation\":false},\"channel\":\"live_orders_ethusd\",\"event\":\"order_created\",\"event_id\":\"00065a1d-7fb4-83c0-0000-001202000020\",\"pre_event_id\":\"00065a1d-7fb4-7fd8-0000-001201000020\",\"order_source\":\"orderbook\"}","recorded_unix_us":1787932603414065}
{"message":"{\"data\":{\"id\":2044303887134740,\"id_str\":\"2044303887134740\",\"order_type\":1,\"order_subtype\":5,\"datetime\":\"1787932603\",\"microtimestamp\":\"1787932603353000\",\"amount\":5,\"amount_str\":\"5.000000\",\"amount_traded\":\"0\",\"amount_at_create\":\"5.000000\",\"price\":2481.2,\"price_str\":\"2481.20\",\"is_liquidation\":false},\"channel\":\"live_orders_ethusd\",\"event\":\"order_created\",\"event_id\":\"00065a1d-7fb4-87a8-0000-001203000020\",\"pre_event_id\":\"00065a1d-7fb4-83c0-0000-001202000020\",\"order_source\":\"orderbook\"}","recorded_unix_us":1787932603414083}
{"message":"{\"data\":{\"id\":2044303887138820,\"id_str\":\"2044303887138820\",\"order_type\":0,\"order_subtype\":5,\"datetime\":\"1787932603\",\"microtimestamp\":\"1787932603353000\",\"amount\":0.63678216,\"amount_str\":\"0.63678216\",\"amount_traded\":\"0\",\"amount_at_create\":\"0.63678216\",\"price\":78484.78,\"price_str\":\"78484.78\",\"is_liquidation\":false},\"channel\":\"live_orders_btcusd\",\"event\":\"order_created\",\"event_id\":\"00065a1d-7fb4-87a8-0000-000100000020\",\"pre_event_id\":\"00065a1d-7fb4-83c0-0000-000103000020\",\"order_source\":\"orderbook\"}","recorded_unix_us":1787932603414149}
{"message":"{\"data\":{\"id\":2044303887138829,\"id_str\":\"2044303887138829\",\"order_type\":1,\"order_subtype\":5,\"datetime\":\"1787932603\",\"microtimestamp\":\"1787932603354000\",\"amount\":2.5,\"amount_str\":\"2.500000\",\"amount_traded\":\"0\",\"amount_at_create\":\"2.500000\",\"price\":2481.08,\"price_str\":\"2481.08\",\"is_liquidation\":false},\"channel\":\"live_orders_ethusd\",\"event\":\"order_created\",\"event_id\":\"00065a1d-7fb4-8b90-0000-001200000020\",\"pre_event_id\":\"00065a1d-7fb4-87a8-0000-001203000020\",\"order_source\":\"orderbook\"}","recorded_unix_us":1787932603414196}
{"message":"{\"data\":{\"id\":2044303887134721,\"id_str\":\"2044303887134721\",\"order_type\":0,\"order_subtype\":5,\"datetime\":\"1787932603\",\"microtimestamp\":\"1787932603356000\",\"amount\":2.5,\"amount_str\":\"2.500000\",\"amount_traded\":\"0\",\"amount_at_create\":\"2.500000\",\"price\":2480.82,\"price_str\":\"2480.82\",\"is_liquidation\":false},\"channel\":\"live_orders_ethusd\",\"event\":\"order_deleted\",\"event_id\":\"00065a1d-7fb4-9360-0000-001201000020\",\"pre_event_id\":\"00065a1d-7fb4-8b90-0000-001200000020\",\"order_source\":\"orderbook\"}","recorded_unix_us":1787932603414292}
{"message":"{\"data\":{\"id\":2044303887151110,\"id_str\":\"2044303887151110\",\"order_type\":0,\"order_subtype\":5,\"datetime\":\"1787932603\",\"microtimestamp\":\"1787932603356000\",\"amount\":0.50942573,\"amount_str\":\"0.50942573\",\"amount_traded\":\"0\",\"amount_at_create\":\"0.50942573\",\"price\":78482.81,\"price_str\":\"78482.81\",\"is_liquidation\":false},\"channel\":\"live_orders_btcusd\",\"event\":\"order_created\",\"event_id\":\"00065a1d-7fb4-9360-0000-000101000020\",\"pre_event_id\":\"00065a1d-7fb4-87a8-0000-000100000020\",\"order_source\":\"orderbook\"}","recorded_unix_us":1787932603414310}
{"message":"{\"data\":{\"id\":2044303887130629,\"id_str\":\"2044303887130629\",\"order_type\":0,\"order_subtype\":5,\"datetime\":\"1787932603\",\"microtimestamp\":\"1787932603357000\",\"amount\":5,\"amount_str\":\"5.000000\",\"amount_traded\":\"0\",\"amount_at_create\":\"5.000000\",\"price\":2480.82,\"price_str\":\"2480.82\",\"is_liquidation\":false},\"channel\":\"live_orders_ethusd\",\"event\":\"order_deleted\",\"event_id\":\"00065a1d-7fb4-9748-0000-001202000020\",\"pre_event_id\":\"00065a1d-7fb4-9360-0000-001201000020\",\"order_source\":\"orderbook\"}","recorded_unix_us":1787932603414420}
{"message":"{\"data\":{\"id\":2044303887110149,\"id_str\":\"2044303887110149\",\"order_type\":0,\"order_subtype\":5,\"datetime\":\"1787932603\",\"microtimestamp\":\"1787932603357000\",\"amount\":0.00140266,\"amount_str\":\"0.00140266\",\"amount_traded\":\"0\",\"amount_at_create\":\"0.00140266\",\"price\":70666.76,\"price_str\":\"70666.76\",\"is_liquidation\":false},\"channel\":\"live_orders_btcusd\",\"event\":\"order_deleted\",\"event_id\":\"00065a1d-7fb4-9748-0000-000102000020\",\"pre_event_id\":\"00065a1d-7fb4-9360-0000-000101000020\",\"order_source\":\"orderbook\"}","recorded_unix_us":1787932603414438}
{"message":"{\"data\":{\"id\":2044303887134740,\"id_str\":\"2044303887134740\",\"order_type\":1,\"order_subtype\":5,\"datetime\":\"1787932603\",\"microtimestamp\":\"1787932603357000\",\"amount\":5,\"amount_str\":\"5.000000\",\"amount_traded\":\"0\",\"amount_at_create\":\"5.000000\",\"price\":2481.2,\"price_str\":\"2481.20\",\"is_liquidation\":false},\"channel\":\"live_orders_ethusd\",\"event\":\"order_deleted\",\"event_id\":\"00065a1d-7fb4-9748-0001-001203000020\",\"pre_event_id\":\"00065a1d-7fb4-9748-0000-001202000020\",\"order_source\":\"orderbook\"}","recorded_unix_us":1787932603414454}
{"message":"{\"data\":{\"id\":2044303887138829,\"id_str\":\"2044303887138829\",\"order_type\":1,\"order_subtype\":5,\"datetime\":\"1787932603\",\"microtimestamp\":\"1787932603358000\",\"amount\":2.5,\"amount_str\":\"2.500000\",\"amount_traded\":\"0\",\"amount_at_create\":\"2.500000\",\"price\":2481.08,\"price_str\":\"2481.08\",\"is_liquidation\":false},\"channel\":\"live_orders_ethusd\",\"event\":\"order_deleted\",\"event_id\":\"00065a1d-7fb4-9b30-0000-001200000020\",\"pre_event_id\":\"00065a1d-7fb4-9748-0001-001203000020\",\"order_source\":\"orderbook\"}","recorded_unix_us":1787932603414513}
{"message":"{\"data\":{\"id\":2044303887171584,\"id_str\":\"2044303887171584\",\"order_type\":1,\"order_subtype\":5,\"datetime\":\"1787932603\",\"microtimestamp\":\"1787932603361000\",\"amount\":0.06310787,\"amount_str\":\"0.06310787\",\"amount_traded\":\"0\",\"amount_at_create\":\"0.06310787\",\"price\":78521.72,\"price_str\":\"78521.72\",\"is_liquidation\":false},\"channel\":\"live_orders_btcusd\",\"event\":\"order_created\",\"event_id\":\"00065a1d-7fb4-a6e8-0000-000103000020\",\"pre_event_id\":\"00065a1d-7fb4-9748-0000-000102000020\",\"order_source\":\"orderbook\"}","recorded_unix_us":1787932603425455}
{"message":"{\"data\":{\"id\":2044303887171584,\"id_str\":\"2044303887171584\",\"order_type\":1,\"order_subtype\":5,\"datetime\":\"1787932603\",\"microtimestamp\":\"1787932603361000\",\"amount\":0.06310787,\"amount_str\":\"0.06310787\",\"amount_traded\":\"0\",\"amount_at_create\":\"0.06310787\",\"price\":78521.72,\"price_str\":\"78521.72\",\"is_liquidation\":false},\"channel\":\"live_orders_btcusd\",\"event\":\"order_deleted\",\"event_id\":\"00065a1d-7fb4-a6e8-0001-000100000020\",\"pre_event_id\":\"00065a1d-7fb4-a6e8-0000-000103000020\",\"order_source\":\"orderbook\"}","recorded_unix_us":1787932603425481}
{"message":"{\"data\":{\"id\":2044303887179782,\"id_str\":\"2044303887179782\",\"order_type\":1,\"order_subtype\":5,\"datetime\":\"1787932603\",\"microtimestamp\":\"1787932603363000\",\"amount\":0.1,\"amount_str\":\"0.10000000\",\"amount_traded\":\"0\",\"amount_at_create\":\"0.10000000\",\"price\":78522.63,\"price_str\":\"78522.63\",\"is_liquidation\":false},\"channel\":\"live_orders_btcusd\",\"event\":\"order_created\",\"event_id\":\"00065a1d-7fb4-aeb8-0000-000101000020\",\"pre_event_id\":\"00065a1d-7fb4-a6e8-0001-000100000020\",\"order_source\":\"orderbook\"}","recorded_unix_us":1787932603428266}
{"message":"{\"data\":{\"id\":2044303887179782,\"id_str\":\"2044303887179782\",\"order_type\":1,\"order_subtype\":5,\"datetime\":\"1787932603\",\"microtimestamp\":\"1787932603363000\",\"amount\":0.1,\"amount_str\":\"0.10000000\",\"amount_traded\":\"0\",\"amount_at_create\":\"0.10000000\",\"price\":78522.63,\"price_str\":\"78522.63\",\"is_liquidation\":false},\"channel\":\"live_orders_btcusd\",\"event\":\"order_deleted\",\"event_id\":\"00065a1d-7fb4-aeb8-0001-000102000020\",\"pre_event_id\":\"00065a1d-7fb4-aeb8-0000-000101000020\",\"order_source\":\"orderbook\"}","recorded_unix_us":1787932603428296}
{"message":"{\"data\":{\"id\":2044303887020039,\"id_str\":\"2044303887020039\",\"order_type\":1,\"order_subtype\":5,\"datetime\":\"1787932603\",\"microtimestamp\":\"1787932603364000\",\"amount\":1,\"amount_str\":\"1.000000\",\"amount_traded\":\"0\",\"amount_at_create\":\"1.000000\",\"price\":2481.09,\"price_str\":\"2481.09\",\"is_liquidation\":false},\"channel\":\"live_orders_ethusd\",\"event\":\"order_deleted\",\"event_id\":\"00065a1d-7fb4-b2a0-0000-001201000020\",\"pre_event_id\":\"00065a1d-7fb4-9b30-0000-001200000020\",\"order_source\":\"orderbook\"}","recorded_unix_us":1787932603428317}
{"message":"{\"data\":{\"id\":2044303887187968,\"id_str\":\"2044303887187968\",\"order_type\":1,\"order_subtype\":5,\"datetime\":\"1787932603\",\"microtimestamp\":\"1787932603365000\",\"amount\":1,\"amount_str\":\"1.000000\",\"amount_traded\":\"0\",\"amount_at_create\":\"1.000000\",\"price\":2480.83,\"price_str\":\"2480.83\",\"is_liquidation\":false},\"channel\":\"live_orders_ethusd\",\"event\":\"order_created\",\"event_id\":\"00065a1d-7fb4-b688-0000-001202000020\",\"pre_event_id\":\"00065a1d-7fb4-b2a0-0000-001201000020\",\"order_source\":\"orderbook\"}","recorded_unix_us":1787932603437306}
{"message":"{\"data\":{\"id\":2044303887187968,\"id_str\":\"2044303887187968\",\"order_type\":1,\"order_subtype\":5,\"datetime\":\"1787932603\",\"microtimestamp\":\"1787932603366000\",\"amount\":1,\"amount_str\":\"1.000000\",\"amount_traded\":\"0\",\"amount_at_create\":\"1.000000\",\"price\":2480.83,\"price_str\":\"2480.83\",\"is_liquidation\":false},\"channel\":\"live_orders_ethusd\",\"event\":\"order_deleted\",\"event_id\":\"00065a1d-7fb4-ba70-0000-001203000020\",\"pre_event_id\":\"00065a1d-7fb4-b688-0000-001202000020\",\"order_source\":\"orderbook\"}","recorded_unix_us":1787932603437388}
{"message":"{\"data\":{\"id\":2044303887192070,\"id_str\":\"2044303887192070\",\"order_type\":0,\"order_subtype\":5,\"datetime\":\"1787932603\",\"microtimestamp\":\"1787932603366000\",\"amount\":0.06367893,\"amount_str\":\"0.06367893\",\"amount_traded\":\"0\",\"amount_at_create\":\"0.06367893\",\"price\":78518.9,\"price_str\":\"78518.90\",\"is_liquidation\":false},\"channel\":\"live_orders_btcusd\",\"event\":\"order_created\",\"event_id\":\"00065a1d-7fb4-ba70-0000-000103000020\",\"pre_event_id\":\"00065a1d-7fb4-aeb8-0001-000102000020\",\"order_source\":\"orderbook\"}","recorded_unix_us":1787932603437418}
{"message":"{\"data\":{\"id\":2044303887220748,\"id_str\":\"2044303887220748\",\"order_type\":1,\"order_subtype\":5,\"datetime\":\"1787932603\",\"microtimestamp\":\"1787932603373000\",\"amount\":0.010654,\"amount_str\":\"0.010654\",\"amount_traded\":\"0\",\"amount_at_create\":\"0.010654\",\"price\":2481.48,\"price_str\":\"2481.48\",\"is_liquidation\":false},\"channel\":\"live_orders_ethusd\",\"event\":\"order_created\",\"event_id\":\"00065a1d-7fb4-d5c8-0000-001200000020\",\"pre_event_id\":\"00065a1d-7fb4-ba70-0000-001203000020\",\"order_source\":\"orderbook\"}","recorded_unix_us":1787932603437496}
{"message":"{\"data\":{\"id\":2044303887294468,\"id_str\":\"2044303887294468\",\"order_type\":1,\"order_subtype\":5,\"datetime\":\"1787932603\",\"microtimestamp\":\"1787932603391000\",\"amount\":0.1,\"amount_str\":\"0.10000000\",\"amount_traded\":\"0\",\"amount_at_create\":\"0.10000000\",\"price\":78522.62,\"price_str\":\"78522.62\",\"is_liquidation\":false},\"channel\":\"live_orders_btcusd\",\"event\":\"order_created\",\"event_id\":\"00065a1d-7fb5-1c18-0000-000100000020\",\"pre_event_id\":\"00065a1d-7fb4-ba70-0000-000103000020\",\"order_source\":\"orderbook\"}","recorded_unix_us":1787932603464866}
{"message":"{\"data\":{\"id\":2044303887294468,\"id_str\":\"2044303887294468\",\"order_type\":1,\"order_subtype\":5,\"datetime\":\"1787932603\",\"microtimestamp\":\"1787932603391000\",\"amount\":0.1,\"amount_str\":\"0.10000000\",\"amount_traded\":\"0\",\"amount_at_create\":\"0.10000000\",\"price\":78522.62,\"price_str\":\"78522.62\",\"is_liquidation\":false},\"channel\":\"live_orders_btcusd\",\"event\":\"order_deleted\",\"event_id\":\"00065a1d-7fb5-1c18-0001-000101000020\",\"pre_event_id\":\"00065a1d-7fb5-1c18-0000-000100000020\",\"order_source\":\"orderbook\"}","recorded_unix_us":1787932603465061}
{"message":"{\"data\":{\"id\":2044303887294474,\"id_str\":\"2044303887294474\",\"order_type\":1,\"order_subtype\":5,\"datetime\":\"1787932603\",\"microtimestamp\":\"1787932603392000\",\"amount\":0.06310787,\"amount_str\":\"0.06310787\",\"amount_traded\":\"0\",\"amount_at_create\":\"0.06310787\",\"price\":78521.89,\"price_str\":\"78521.89\",\"is_liquidation\":false},\"channel\":\"live_orders_btcusd\",\"event\":\"order_created\",\"event_id\":\"00065a1d-7fb5-2000-0000-000102000020\",\"pre_event_id\":\"00065a1d-7fb5-1c18-0001-000101000020\",\"order_source\":\"orderbook\"}","recorded_unix_us":1787932603470282}
{"message":"{\"data\":{\"id\":2044303887294474,\"id_str\":\"2044303887294474\",\"order_type\":1,\"order_subtype\":5,\"datetime\":\"1787932603\",\"microtimestamp\":\"1787932603392000\",\"amount\":0.06310787,\"amount_str\":\"0.06310787\",\"amount_traded\":\"0\",\"amount_at_create\":\"0.06310787\",\"price\":78521.89,\"price_str\":\"78521.89\",\"is_liquidation\":false},\"channel\":\"live_orders_btcusd\",\"event\":\"order_deleted\",\"event_id\":\"00065a1d-7fb5-2000-0001-000103000020\",\"pre_event_id\":\"00065a1d-7fb5-2000-0000-000102000020\",\"order_source\":\"orderbook\"}","recorded_unix_us":1787932603470480}
{"message":"{\"data\":{\"id\":2044303887302660,\"id_str\":\"2044303887302660\",\"order_type\":0,\"order_subtype\":5,\"datetime\":\"1787932603\",\"microtimestamp\":\"1787932603393000\",\"amount\":2.5,\"amount_str\":\"2.500000\",\"amount_traded\":\"0\",\"amount_at_create\":\"2.500000\",\"price\":2480.85,\"price_str\":\"2480.85\",\"is_liquidation\":false},\"channel\":\"live_orders_ethusd\",\"event\":\"order_created\",\"event_id\":\"00065a1d-7fb5-23e8-0000-001201000020\",\"pre_event_id\":\"00065a1d-7fb4-d5c8-0000-001200000020\",\"order_source\":\"orderbook\"}","recorded_unix_us":1787932603470624}
{"message":"{\"data\":{\"id\":2044303887192070,\"id_str\":\"2044303887192070\",\"order_type\":0,\"order_subtype\":5,\"datetime\":\"1787932603\",\"microtimestamp\":\"1787932603394000\",\"amount\":0.06367893,\"amount_str\":\"0.06367893\",\"amount_traded\":\"0\",\"amount_at_create\":\"0.06367893\",\"price\":78518.9,\"price_str\":\"78518.90\",\"is_liquidation\":false},\"channel\":\"live_orders_btcusd\",\"event\":\"order_deleted\",\"event_id\":\"00065a1d-7fb5-27d0-0000-000100000020\",\"pre_event_id\":\"00065a1d-7fb5-2000-0001-000103000020\",\"order_source\":\"orderbook\"}","recorded_unix_us":1787932603470755}
{"message":"{\"data\":{\"id\":2044303887306763,\"id_str\":\"2044303887306763\",\"order_type\":1,\"order_subtype\":5,\"datetime\":\"1787932603\",\"microtimestamp\":\"1787932603395000\",\"amount\":5,\"amount_str\":\"5.000000\",\"amount_traded\":\"0\",\"amount_at_create\":\"5.000000\",\"price\":2481.2,\"price_str\":\"2481.20\",\"is_liquidation\":false},\"channel\":\"live_orders_ethusd\",\"event\":\"order_created\",\"event_id\":\"00065a1d-7fb5-2bb8-0000-001202000020\",\"pre_event_id\":\"00065a1d-7fb5-23e8-0000-001201000020\",\"order_source\":\"orderbook\"}","recorded_unix_us":1787932603470859}
{"message":"{\"data\":{\"id\":2044303887306764,\"id_str\":\"2044303887306764\",\"order_type\":0,\"order_subtype\":5,\"datetime\":\"1787932603\",\"microtimestamp\":\"1787932603395000\",\"amount\":5,\"amount_str\":\"5.000000\",\"amount_traded\":\"0\",\"amount_at_create\":\"5.000000\",\"price\":2480.85,\"price_str\":\"2480.85\",\"is_liquidation\":false},\"channel\":\"live_orders_ethusd\",\"event\":\"order_created\",\"event_id\":\"00065a1d-7fb5-2bb8-0001-001203000020\",\"pre_event_id\":\"00065a1d-7fb5-2bb8-0000-001202000020\",\"order_source\":\"orderbook\"}","recorded_unix_us":1787932603470962}
{"message":"{\"data\":{\"id\":2044303887310851,\"id_str\":\"2044303887310851\",\"order_type\":1,\"order_subtype\":5,\"datetime\":\"1787932603\",\"microtimestamp\":\"1787932603395000\",\"amount\":2.5,\"amount_str\":\"2.500000\",\"amount_traded\":\"0\",\"amount_at_create\":\"2.500000\",\"price\":2481.08,\"price_str\":\"2481.08\",\"is_liquidation\":false},\"channel\":\"live_orders_ethusd\",\"event\":\"order_created\",\"event_id\":\"00065a1d-7fb5-2bb8-0002-001200000020\",\"pre_event_id\":\"00065a1d-7fb5-2bb8-0001-001203000020\",\"order_source\":\"orderbook\"}","recorded_unix_us":1787932603471056}
{"message":"{\"data\":{\"id\":2044303887335425,\"id_str\":\"2044303887335425\",\"order_type\":1,\"order_subtype\":5,\"datetime\":\"1787932603\",\"microtimestamp\":\"1787932603401000\",\"amount\":0.006562,\"amount_str\":\"0.006562\",\"amount_traded\":\"0\",\"amount_at_create\":\"0.006562\",\"price\":2480.82,\"price_str\":\"2480.82\",\"is_liquidation\":false},\"channel\":\"live_orders_ethusd\",\"event\":\"order_created\",\"event_id\":\"00065a1d-7fb5-4328-0000-001201000020\",\"pre_event_id\":\"00065a1d-7fb5-2bb8-0002-001200000020\",\"order_source\":\"orderbook\"}","recorded_unix_us":1787932603471223}
{"message":"{\"data\":{\"id\":2044303887335425,\"id_str\":\"2044303887335425\",\"order_type\":1,\"order_subtype\":5,\"datetime\":\"1787932603\",\"microtimestamp\":\"1787932603401000\",\"amount\":0.006562,\"amount_str\":\"0.006562\",\"amount_traded\":\"0\",\"amount_at_create\":\"0.006562\",\"price\":2480.82,\"price_str\":\"2480.82\",\"is_liquidation\":false},\"channel\":\"live_orders_ethusd\",\"event\":\"order_deleted\",\"event_id\":\"00065a1d-7fb5-4328-0001-001202000020\",\"pre_event_id\":\"00065a1d-7fb5-4328-0000-001201000020\",\"order_source\":\"orderbook\"}","recorded_unix_us":1787932603471335}
{"message":"{\"data\":{\"id\":2044303886196740,\"id_str\":\"2044303886196740\",\"order_type\":0,\"order_subtype\":5,\"datetime\":\"1787932603\",\"microtimestamp\":\"1787932603407000\",\"amount\":1,\"amount_str\":\"1.000000\",\"amount_traded\":\"0\",\"amount_at_create\":\"1.000000\",\"price\":2479.8,\"price_str\":\"2479.80\",\"is_liquidation\":false},\"channel\":\"live_orders_ethusd\",\"event\":\"order_deleted\",\"event_id\":\"00065a1d-7fb5-5a98-0000-001203000020\",\"pre_event_id\":\"00065a1d-7fb5-4328-0001-001202000020\",\"order_source\":\"orderbook\"}","recorded_unix_us":1787932603471470}
{"message":"{\"data\":{\"id\":2044303886180352,\"id_str\":\"2044303886180352\",\"order_type\":0,\"order_subtype\":5,\"datetime\":\"1787932603\",\"microtimestamp\":\"1787932603407000\",\"amount\":3,\"amount_str\":\"3.000000\",\"amount_traded\":\"0\",\"amount_at_create\":\"3.000000\",\"price\":2480.05,\"price_str\":\"2480.05\",\"is_liquidation\":false},\"channel\":\"live_orders_ethusd\",\"event\":\"order_deleted\",\"event_id\":\"00065a1d-7fb5-5a98-0001-001200000020\",\"pre_event_id\":\"00065a1d-7fb5-5a98-0000-001203000020\",\"order_source\":\"orderbook\"}","recorded_unix_us":1787932603471502}
{"message":"{\"data\":{\"id\":2044303886168076,\"id_str\":\"2044303886168076\",\"order_type\":0,\"order_subtype\":5,\"datetime\":\"1787932603\",\"microtimestamp\":\"1787932603407000\",\"amount\":5,\"amount_str\":\"5.000000\",\"amount_traded\":\"0\",\"amount_at_create\":\"5.000000\",\"price\":2479.8,\"price_str\":\"2479.80\",\"is_liquidation\":false},\"channel\":\"live_orders_ethusd\",\"event\":\"order_deleted\",\"event_id\":\"00065a1d-7fb5-5a98-0002-001201000020\",\"pre_event_id\":\"00065a1d-7fb5-5a98-0001-001200000020\",\"order_source\":\"orderbook\"}","recorded_unix_us":1787932603471631}
{"message":"{\"data\":{\"id\":2044303886168078,\"id_str\":\"2044303886168078\",\"order_type\":0,\"order_subtype\":5,\"datetime\":\"1787932603\",\"microtimestamp\":\"1787932603408000\",\"amount\":2,\"amount_str\":\"2.000000\",\"amount_traded\":\"0\",\"amount_at_create\":\"2.000000\",\"price\":2480.05,\"price_str\":\"2480.05\",\"is_liquidation\":false},\"channel\":\"live_orders_ethusd\",\"event\":\"order_deleted\",\"event_id\":\"00065a1d-7fb5-5e80-0000-001202000020\",\"pre_event_id\":\"00065a1d-7fb5-5a98-0002-001201000020\",\"order_source\":\"orderbook\"}","recorded_unix_us":1787932603471663}
{"message":"{\"data\":{\"id\":2044303885762566,\"id_str\":\"2044303885762566\",\"order_type\":1,\"order_subtype\":5,\"datetime\":\"1787932603\",\"microtimestamp\":\"1787932603409000\",\"amount\":1.27113313,\"amount_str\":\"1.27113313\",\"amount_traded\":\"0\",\"amount_at_create\":\"1.27113313\",\"price\":78669.97,\"price_str\":\"78669.97\",\"is_liquidation\":false},\"channel\":\"live_orders_btcusd\",\"event\":\"order_deleted\",\"event_id\":\"00065a1d-7fb5-6268-0000-000101000020\",\"pre_event_id\":\"00065a1d-7fb5-27d0-0000-000100000020\",\"order_source\":\"orderbook\"}","recorded_unix_us":1787932603471796}
{"message":"{\"data\":{\"id\":2044303885873156,\"id_str\":\"2044303885873156\",\"order_type\":1,\"order_subtype\":5,\"datetime\":\"1787932603\",\"microtimestamp\":\"1787932603409000\",\"amount\":0.06367563,\"amount_str\":\"0.06367563\",\"amount_traded\":\"0\",\"amount_at_create\":\"0.06367563\",\"price\":78522.98,\"price_str\":\"78522.98\",\"is_liquidation\":false},\"channel\":\"live_orders_btcusd\",\"event\":\"order_deleted\",\"event_id\":\"00065a1d-7fb5-6268-0001-000102000020\",\"pre_event_id\":\"00065a1d-7fb5-6268-0000-000101000020\",\"order_source\":\"orderbook\"}","recorded_unix_us":1787932603471826}
{"message":"{\"data\":{\"id\":2044303887368201,\"id_str\":\"2044303887368201\",\"order_type\":0,\"order_subtype\":5,\"datetime\":\"1787932603\",\"microtimestamp\":\"1787932603410000\",\"amount\":0.06367811,\"amount_str\":\"0.06367811\",\"amount_traded\":\"0\",\"amount_at_create\":\"0.06367811\",\"price\":78519.91,\"price_str\":\"78519.91\",\"is_liquidation\":false},\"channel\":\"live_orders_btcusd\",\"event\":\"order_created\",\"event_id\":\"00065a1d-7fb5-6650-0000-000103000020\",\"pre_event_id\":\"00065a1d-7fb5-6268-0001-000102000020\",\"order_source\":\"orderbook\"}","recorded_unix_us":1787932603483106}
{"message":"{\"data\":{\"id\":2044303885881344,\"id_str\":\"2044303885881344\",\"order_type\":1,\"order_subtype\":5,\"datetime\":\"1787932603\",\"microtimestamp\":\"1787932603410000\",\"amount\":0.06367384,\"amount_str\":\"0.06367384\",\"amount_traded\":\"0\",\"amount_at_create\":\"0.06367384\",\"price\":78525.19,\"price_str\":\"78525.19\",\"is_liquidation\":false},\"channel\":\"live_orders_btcusd\",\"event\":\"order_deleted\",\"event_id\":\"00065a1d-7fb5-6650-0001-000100000020\",\"pre_event_id\":\"00065a1d-7fb5-6650-0000-000103000020\",\"order_source\":\"orderbook\"}","recorded_unix_us":1787932603483182}
{"message":"{\"data\":{\"id\":2044303885922311,\"id_str\":\"2044303885922311\",\"order_type\":1,\"order_subtype\":5,\"datetime\":\"1787932603\",\"microtimestamp\":\"1787932603410000\",\"amount\":12.70451953,\"amount_str\":\"12.70451953\",\"amount_traded\":\"0\",\"amount_at_create\":\"12.70451953\",\"price\":78712.15,\"price_str\":\"78712.15\",\"is_liquidation\":false},\"channel\":\"live_orders_btcusd\",\"event\":\"order_deleted\",\"event_id\":\"00065a1d-7fb5-6650-0002-000101000020\",\"pre_event_id\":\"00065a1d-7fb5-6650-0001-000100000020\",\"order_source\":\"orderbook\"}","recorded_unix_us":1787932603483349}
{"message":"{\"data\":{\"id\":2044303885926400,\"id_str\":\"2044303885926400\",\"order_type\":1,\"order_subtype\":5,\"datetime\":\"1787932603\",\"microtimestamp\":\"1787932603410000\",\"amount\":0.25466146,\"amount_str\":\"0.25466146\",\"amount_traded\":\"0\",\"amount_at_create\":\"0.25466146\",\"price\":78535.64,\"price_str\":\"78535.64\",\"is_liquidation\":false},\"channel\":\"live_orders_btcusd\",\"event\":\"order_deleted\",\"event_id\":\"00065a1d-7fb5-6650-0003-000102000020\",\"pre_event_id\":\"00065a1d-7fb5-6650-0002-000101000020\",\"order_source\":\"orderbook\"}","recorded_unix_us":1787932603483401}
{"message":"{\"data\":{\"id\":2044303885926405,\"id_str\":\"2044303885926405\",\"order_type\":1,\"order_subtype\":5,\"datetime\":\"1787932603\",\"microtimestamp\":\"1787932603411000\",\"amount\":1.26970017,\"amount_str\":\"1.26970017\",\"amount_traded\":\"0\",\"amount_at_create\":\"1.26970017\",\"price\":78758.76,\"price_str\":\"78758.76\",\"is_liquidation\":false},\"channel\":\"live_orders_btcusd\",\"event\":\"order_deleted\",\"event_id\":\"00065a1d-7fb5-6a38-0000-000103000020\",\"pre_event_id\":\"00065a1d-7fb5-6650-0003-000102000020\",\"order_source\":\"orderbook\"}","recorded_unix_us":1787932603483608}
{"message":"{\"data\":{\"id\":2044303885926406,\"id_str\":\"2044303885926406\",\"order_type\":1,\"order_subtype\":5,\"datetime\":\"1787932603\",\"microtimestamp\":\"1787932603411000\",\"amount\":1.27209222,\"amount_str\":\"1.27209222\",\"amount_traded\":\"0\",\"amount_at_create\":\"1.27209222\",\"price\":78610.66,\"price_str\":\"78610.66\",\"is_liquidation\":false},\"channel\":\"live_orders_btcusd\",\"event\":\"order_deleted\",\"event_id\":\"00065a1d-7fb5-6a38-0001-000100000020\",\"pre_event_id\":\"00065a1d-7fb5-6a38-0000-000103000020\",\"order_source\":\"orderbook\"}","recorded_unix_us":1787932603483655}
{"message":"{\"data\":{\"id\":2044303885934597,\"id_str\":\"2044303885934597\",\"order_type\":1,\"order_subtype\":5,\"datetime\":\"1787932603\",\"microtimestamp\":\"1787932603411000\",\"amount\":1.2684012,\"amount_str\":\"1.26840120\",\"amount_traded\":\"0\",\"amount_at_create\":\"1.26840120\",\"price\":78839.41,\"price_str\":\"78839.41\",\"is_liquidation\":false},\"channel\":\"live_orders_btcusd\",\"event\":\"order_deleted\",\"event_id\":\"00065a1d-7fb5-6a38-0002-000101000020\",\"pre_event_id\":\"00065a1d-7fb5-6a38-0001-000100000020\",\"order_source\":\"orderbook\"}","recorded_unix_us":1787932603483685}
{"message":"{\"data\":{\"id\":2044303885987844,\"id_str\":\"2044303885987844\",\"order_type\":0,\"order_subtype\":5,\"datetime\":\"1787932603\",\"microtimestamp\":\"1787932603412000\",\"amount\":0.25476924,\"amount_str\":\"0.25476924\",\"amount_traded\":\"0\",\"amount_at_create\":\"0.25476924\",\"price\":78502.41,\"price_str\":\"78502.41\",\"is_liquidation\":false},\"channel\":\"live_orders_btcusd\",\"event\":\"order_deleted\",\"event_id\":\"00065a1d-7fb5-6e20-0000-000102000020\",\"pre_event_id\":\"00065a1d-7fb5-6a38-0002-000101000020\",\"order_source\":\"orderbook\"}","recorded_unix_us":1787932603483711}
{"message":"{\"data\":{\"id\":2044303887376393,\"id_str\":\"2044303887376393\",\"order_type\":0,\"order_subtype\":5,\"datetime\":\"1787932603\",\"microtimestamp\":\"1787932603412000\",\"amount\":0.080629,\"amount_str\":\"0.080629\",\"amount_traded\":\"0\",\"amount_at_create\":\"0.080629\",\"price\":2480.49,\"price_str\":\"2480.49\",\"is_liquidation\":false},\"channel\":\"live_orders_ethusd\",\"event\":\"order_created\",\"event_id\":\"00065a1d-7fb5-6e20-0000-001203000020\",\"pre_event_id\":\"00065a1d-7fb5-5e80-0000-001202000020\",\"order_source\":\"orderbook\"}","recorded_unix_us":1787932603493928}
{"message":"{\"data\":{\"id\":2044303887302660,\"id_str\":\"2044303887302660\",\"order_type\":0,\"order_subtype\":5,\"datetime\":\"1787932603\",\"microtimestamp\":\"1787932603418000\",\"amount\":2.5,\"amount_str\":\"2.500000\",\"amount_traded\":\"0\",\"amount_at_create\":\"2.500000\",\"price\":2480.85,\"price_str\":\"2480.85\",\"is_liquidation\":false},\"channel\":\"live_orders_ethusd\",\"event\":\"order_deleted\",\"event_id\":\"00065a1d-7fb5-8590-0000-001200000020\",\"pre_event_id\":\"00065a1d-7fb5-6e20-0000-001203000020\",\"order_source\":\"orderbook\"}","recorded_unix_us":1787932603505314}
{"message":"{\"data\":{\"id\":2044303887306764,\"id_str\":\"2044303887306764\",\"order_type\":0,\"order_subtype\":5,\"datetime\":\"1787932603\",\"microtimestamp\":\"1787932603418000\",\"amount\":5,\"amount_str\":\"5.000000\",\"amount_traded\":\"0\",\"amount_at_create\":\"5.000000\",\"price\":2480.85,\"price_str\":\"2480.85\",\"is_liquidation\":false},\"channel\":\"live_orders_ethusd\",\"event\":\"order_deleted\",\"event_id\":\"00065a1d-7fb5-8590-0001-001201000020\",\"pre_event_id\":\"00065a1d-7fb5-8590-0000-001200000020\",\"order_source\":\"orderbook\"}","recorded_unix_us":1787932603505521}
{"message":"{\"data\":{\"id\":2044303887429638,\"id_str\":\"2044303887429638\",\"order_type\":1,\"order_subtype\":5,\"datetime\":\"1787932603\",\"microtimestamp\":\"1787932603425000\",\"amount\":0.1,\"amount_str\":\"0.10000000\",\"amount_traded\":\"0\",\"amount_at_create\":\"0.10000000\",\"price\":78522.63,\"price_str\":\"78522.63\",\"is_liquidation\":false},\"channel\":\"live_orders_btcusd\",\"event\":\"order_created\",\"event_id\":\"00065a1d-7fb5-a0e8-0000-000103000020\",\"pre_event_id\":\"00065a1d-7fb5-6e20-0000-000102000020\",\"order_source\":\"orderbook\"}","recorded_unix_us":1787932603505658}
{"message":"{\"data\":{\"id\":2044303887429638,\"id_str\":\"2044303887429638\",\"order_type\":1,\"order_subtype\":5,\"datetime\":\"1787932603\",\"microtimestamp\":\"1787932603425000\",\"amount\":0.1,\"amount_str\":\"0.10000000\",\"amount_traded\":\"0\",\"amount_at_create\":\"0.10000000\",\"price\":78522.63,\"price_str\":\"78522.63\",\"is_liquidation\":false},\"channel\":\"live_orders_btcusd\",\"event\":\"order_deleted\",\"event_id\":\"00065a1d-7fb5-a0e8-0001-000100000020\",\"pre_event_id\":\"00065a1d-7fb5-a0e8-0000-000103000020\",\"order_source\":\"orderbook\"}","recorded_unix_us":1787932603505797}
{"message":"{\"data\":{\"id\":2044303887433730,\"id_str\":\"2044303887433730\",\"order_type\":0,\"order_subtype\":5,\"datetime\":\"1787932603\",\"microtimestamp\":\"1787932603426000\",\"amount\":0.00140266,\"amount_str\":\"0.00140266\",\"amount_traded\":\"0\",\"amount_at_create\":\"0.00140266\",\"price\":70668.08,\"price_str\":\"70668.08\",\"is_liquidation\":false},\"channel\":\"live_orders_btcusd\",\"event\":\"order_created\",\"event_id\":\"00065a1d-7fb5-a4d0-0000-000101000020\",\"pre_event_id\":\"00065a1d-7fb5-a0e8-0001-000100000020\",\"order_source\":\"orderbook\"}","recorded_unix_us":1787932603505912}
{"message":"{\"data\":{\"id\":2044303886004224,\"id_str\":\"2044303886004224\",\"order_type\":0,\"order_subtype\":5,\"datetime\":\"1787932603\",\"microtimestamp\":\"1787932603426000\",\"amount\":1.27541152,\"amount_str\":\"1.27541152\",\"amount_traded\":\"0\",\"amount_at_create\":\"1.27541152\",\"price\":78406.06,\"price_str\":\"78406.06\",\"is_liquidation\":false},\"channel\":\"live_orders_btcusd\",\"event\":\"order_deleted\",\"event_id\":\"00065a1d-7fb5-a4d0-0001-000102000020\",\"pre_event_id\":\"00065a1d-7fb5-a4d0-0000-000101000020\",\"order_source\":\"orderbook\"}","recorded_unix_us":1787932603506059}
{"message":"{\"data\":{\"id\":2044303886004226,\"id_str\":\"2044303886004226\",\"order_type\":0,\"order_subtype\":5,\"datetime\":\"1787932603\",\"microtimestamp\":\"1787932603426000\",\"amount\":1.27507828,\"amount_str\":\"1.27507828\",\"amount_traded\":\"0\",\"amount_at_create\":\"1.27507828\",\"price\":78426.55,\"price_str\":\"78426.55\",\"is_liquidation\":false},\"channel\":\"live_orders_btcusd\",\"event\":\"order_deleted\",\"event_id\":\"00065a1d-7fb5-a4d0-0002-000103000020\",\"pre_event_id\":\"00065a1d-7fb5-a4d0-0001-000102000020\",\"order_source\":\"orderbook\"}","recorded_unix_us":1787932603506093}
{"message":"{\"data\":{\"id\":2044303886032900,\"id_str\":\"2044303886032900\",\"order_type\":0,\"order_subtype\":5,\"datetime\":\"1787932603\",\"microtimestamp\":\"1787932603426000\",\"amount\":1.27567513,\"amount_str\":\"1.27567513\",\"amount_traded\":\"0\",\"amount_at_create\":\"1.27567513\",\"price\":78389.86,\"price_str\":\"78389.86\",\"is_liquidation\":false},\"channel\":\"live_orders_btcusd\",\"event\":\"order_deleted\",\"event_id\":\"00065a1d-7fb5-a4d0-0003-000100000020\",\"pre_event_id\":\"00065a1d-7fb5-a4d0-0002-000103000020\",\"order_source\":\"orderbook\"}","recorded_unix_us":1787932603506222}
{"message":"{\"data\":{\"id\":2044303886045190,\"id_str\":\"2044303886045190\",\"order_type\":0,\"order_subtype\":5,\"datetime\":\"1787932603\",\"microtimestamp\":\"1787932603427000\",\"amount\":12.76418733,\"amount_str\":\"12.76418733\",\"amount_traded\":\"0\",\"amount_at_create\":\"12.76418733\",\"price\":78344.19,\"price_str\":\"78344.19\",\"is_liquidation\":false},\"channel\":\"live_orders_btcusd\",\"event\":\"order_deleted\",\"event_id\":\"00065a1d-7fb5-a8b8-0000-000101000020\",\"pre_event_id\":\"00065a1d-7fb5-a4d0-0003-000100000020\",\"order_source\":\"orderbook\"}","recorded_unix_us":1787932603506255}
{"message":"{\"data\":{\"id\":2044303887437833,\"id_str\":\"2044303887437833\",\"order_type\":0,\"order_subtype\":5,\"datetime\":\"1787932603\",\"microtimestamp\":\"1787932603427000\",\"amount\":0.12,\"amount_str\":\"0.12000000\",\"amount_traded\":\"0\",\"amount_at_create\":\"0.12000000\",\"price\":78510.43,\"price_str\":\"78510.43\",\"is_liquidation\":false},\"channel\":\"live_orders_btcusd\",\"event\":\"order_created\",\"event_id\":\"00065a1d-7fb5-a8b8-0001-000102000020\",\"pre_event_id\":\"00065a1d-7fb5-a8b8-0000-000101000020\",\"order_source\":\"orderbook\"}","recorded_unix_us":1787932603506493}
{"message":"{\"data\":{\"id\":2044303886073857,\"id_str\":\"2044303886073857\",\"order_type\":0,\"order_subtype\":5,\"datetime\":\"1787932603\",\"microtimestamp\":\"1787932603427000\",\"amount\":1.27757154,\"amount_str\":\"1.27757154\",\"amount_traded\":\"0\",\"amount_at_create\":\"1.27757154\",\"price\":78273.5,\"price_str\":\"78273.50\",\"is_liquidation\":false},\"channel\":\"live_orders_btcusd\",\"event\":\"order_deleted\",\"event_id\":\"00065a1d-7fb5-a8b8-0002-000103000020\",\"pre_event_id\":\"00065a1d-7fb5-a8b8-0001-000102000020\",\"order_source\":\"orderbook\"}","recorded_unix_us":1787932603506535}
{"message":"{\"data\":{\"id\":2044303886155784,\"id_str\":\"2044303886155784\",\"order_type\":1,\"order_subtype\":5,\"datetime\":\"1787932603\",\"microtimestamp\":\"1787932603427000\",\"amount\":1.26842789,\"amount_str\":\"1.26842789\",\"amount_traded\":\"0\",\"amount_at_create\":\"1.26842789\",\"price\":78837.75,\"price_str\":\"78837.75\",\"is_liquidation\":false},\"channel\":\"live_orders_btcusd\",\"event\":\"order_deleted\",\"event_id\":\"00065a1d-7fb5-a8b8-0003-000100000020\",\"pre_event_id\":\"00065a1d-7fb5-a8b8-0002-000103000020\",\"order_source\":\"orderbook\"}","recorded_unix_us":1787932603506561}
{"message":"{\"data\":{\"id\":2044303886155788,\"id_str\":\"2044303886155788\",\"order_type\":0,\"order_subtype\":5,\"datetime\":\"1787932603\",\"microtimestamp\":\"1787932603428000\",\"amount\":1.27604867,\"amount_str\":\"1.27604867\",\"amount_traded\":\"0\",\"amount_at_create\":\"1.27604867\",\"price\":78366.91,\"price_str\":\"78366.91\",\"is_liquidation\":false},\"channel\":\"live_orders_btcusd\",\"event\":\"order_deleted\",\"event_id\":\"00065a1d-7fb5-aca0-0000-000101000020\",\"pre_event_id\":\"00065a1d-7fb5-a8b8-0003-000100000020\",\"order_source\":\"orderbook\"}","recorded_unix_us":1787932603506586}
{"message":"{\"data\":{\"id\":2044303886155789,\"id_str\":\"2044303886155789\",\"order_type\":1,\"order_subtype\":5,\"datetime\":\"1787932603\",\"microtimestamp\":\"1787932603428000\",\"amount\":1.271772,\"amount_str\":\"1.27177200\",\"amount_traded\":\"0\",\"amount_at_create\":\"1.27177200\",\"price\":78630.45,\"price_str\":\"78630.45\",\"is_liquidation\":false},\"channel\":\"live_orders_btcusd\",\"event\":\"order_deleted\",\"event_id\":\"00065a1d-7fb5-aca0-0001-000102000020\",\"pre_event_id\":\"00065a1d-7fb5-aca0-0000-000101000020\",\"order_source\":\"orderbook\"}","recorded_unix_us":1787932603506612}
{"message":"{\"data\":{\"id\":2044303884546048,\"id_str\":\"2044303884546048\",\"order_type\":0,\"order_subtype\":5,\"datetime\":\"1787932603\",\"microtimestamp\":\"1787932603428000\",\"amount\":0.12,\"amount_str\":\"0.12000000\",\"amount_traded\":\"0\",\"amount_at_create\":\"0.12000000\",\"price\":78509.2,\"price_str\":\"78509.20\",\"is_liquidation\":false},\"channel\":\"live_orders_btcusd\",\"event\":\"order_deleted\",\"event_id\":\"00065a1d-7fb5-aca0-0002-000103000020\",\"pre_event_id\":\"00065a1d-7fb5-aca0-0001-000102000020\",\"order_source\":\"orderbook\"}","recorded_unix_us":1787932603506703}
{"message":"{\"data\":{\"id\":2044303886159882,\"id_str\":\"2044303886159882\",\"order_type\":0,\"order_subtype\":5,\"datetime\":\"1787932603\",\"microtimestamp\":\"1787932603428000\",\"amount\":1.27817952,\"amount_str\":\"1.27817952\",\"amount_traded\":\"0\",\"amount_at_create\":\"1.27817952\",\"price\":78236.27,\"price_str\":\"78236.27\",\"is_liquidation\":false},\"channel\":\"live_orders_btcusd\",\"event\":\"order_deleted\",\"event_id\":\"00065a1d-7fb5-aca0-0003-000100000020\",\"pre_event_id\":\"00065a1d-7fb5-aca0-0002-000103000020\",\"order_source\":\"orderbook\"}","recorded_unix_us":1787932603506799}
{"message":"{\"data\":{\"id\":2044303886225416,\"id_str\":\"2044303886225416\",\"order_type\":1,\"order_subtype\":5,\"datetime\":\"1787932603\",\"microtimestamp\":\"1787932603429000\",\"amount\":1.27145262,\"amount_str\":\"1.27145262\",\"amount_traded\":\"0\",\"amount_at_create\":\"1.27145262\",\"price\":78650.2,\"price_str\":\"78650.20\",\"is_liquidation\":false},\"channel\":\"live_orders_btcusd\",\"event\":\"order_deleted\",\"event_id\":\"00065a1d-7fb5-b088-0000-000101000020\",\"pre_event_id\":\"00065a1d-7fb5-aca0-0003-000100000020\",\"order_source\":\"orderbook\"}","recorded_unix_us":1787932603506888}
{"message":"{\"data\":{\"id\":2044303887433730,\"id_str\":\"2044303887433730\",\"order_type\":0,\"order_subtype\":5,\"datetime\":\"1787932603\",\"microtimestamp\":\"1787932603429000\",\"amount\":0.00140266,\"amount_str\":\"0.00140266\",\"amount_traded\":\"0\",\"amount_at_create\":\"0.00140266\",\"price\":70668.08,\"price_str\":\"70668.08\",\"is_liquidation\":false},\"channel\":\"live_orders_btcusd\",\"event\":\"order_deleted\",\"event_id\":\"00065a1d-7fb5-b088-0001-000102000020\",\"pre_event_id\":\"00065a1d-7fb5-b088-0000-000101000020\",\"order_source\":\"orderbook\"}","recorded_unix_us":1787932603511005}
{"message":"{\"data\":{\"id\":2044303886237698,\"id_str\":\"2044303886237698\",\"order_type\":0,\"order_subtype\":5,\"datetime\":\"1787932603\",\"microtimestamp\":\"1787932603429000\",\"amount\":1.27888333,\"amount_str\":\"1.27888333\",\"amount_traded\":\"0\",\"amount_at_create\":\"1.27888333\",\"price\":78193.21,\"price_str\":\"78193.21\",\"is_liquidation\":false},\"channel\":\"live_orders_btcusd\",\"event\":\"order_deleted\",\"event_id\":\"00065a1d-7fb5-b088-0002-000103000020\",\"pre_event_id\":\"00065a1d-7fb5-b088-0001-000102000020\",\"order_source\":\"orderbook\"}","recorded_unix_us":1787932603511153}
{"message":"{\"data\":{\"id\":2044303878643712,\"id_str\":\"2044303878643712\",\"order_type\":0,\"order_subtype\":5,\"datetime\":\"1787932603\",\"microtimestamp\":\"1787932603434000\",\"amount\":1.65847856,\"amount_str\":\"1.65847856\",\"amount_traded\":\"0\",\"amount_at_create\":\"1.65847856\",\"price\":0.03020012,\"price_str\":\"0.03020012\",\"is_liquidation\":false},\"channel\":\"live_orders_ethbtc\",\"event\":\"order_deleted\",\"event_id\":\"00065a1d-7fb5-c410-0000-001103000020\",\"pre_event_id\":\"00065a1d-7fb4-1278-0000-001102000020\",\"order_source\":\"orderbook\"}","recorded_unix_us":1787932603511269}
{"message":"{\"data\":{\"id\":2044303886884864,\"id_str\":\"2044303886884864\",\"order_type\":0,\"order_subtype\":5,\"datetime\":\"1787932603\",\"microtimestamp\":\"1787932603440000\",\"amount\":0.055955,\"amount_str\":\"0.055955\",\"amount_traded\":\"0\",\"amount_at_create\":\"0.055955\",\"price\":2479.34,\"price_str\":\"2479.34\",\"is_liquidation\":false},\"channel\":\"live_orders_ethusd\",\"event\":\"order_deleted\",\"event_id\":\"00065a1d-7fb5-db80-0000-001202000020\",\"pre_event_id\":\"00065a1d-7fb5-8590-0001-001201000020\",\"order_source\":\"orderbook\"}","recorded_unix_us":1787932603511379}
{"message":"{\"data\":{\"id\":2044303886000130,\"id_str\":\"2044303886000130\",\"order_type\":1,\"order_subtype\":5,\"datetime\":\"1787932603\",\"microtimestamp\":\"1787932603446000\",\"amount\":1.007365,\"amount_str\":\"1.00736500\",\"amount_traded\":\"0\",\"amount_at_create\":\"1.00736500\",\"price\":0.03160719,\"price_str\":\"0.03160719\",\"is_liquidation\":false},\"channel\":\"live_orders_ethbtc\",\"event\":\"order_deleted\",\"event_id\":\"00065a1d-7fb5-f2f0-0000-001100000020\",\"pre_event_id\":\"00065a1d-7fb5-c410-0000-001103000020\",\"order_source\":\"orderbook\"}","recorded_unix_us":1787932603513322}
{"message":"{\"data\":{\"id\":2044303886000131,\"id_str\":\"2044303886000131\",\"order_type\":1,\"order_subtype\":5,\"datetime\":\"1787932603\",\"microtimestamp\":\"1787932603446000\",\"amount\":4.02232075,\"amount_str\":\"4.02232075\",\"amount_traded\":\"0\",\"amount_at_create\":\"4.02232075\",\"price\":0.03165997,\"price_str\":\"0.03165997\",\"is_liquidation\":false},\"channel\":\"live_orders_ethbtc\",\"event\":\"order_deleted\",\"event_id\":\"00065a1d-7fb5-f2f0-0001-001101000020\",\"pre_event_id\":\"00065a1d-7fb5-f2f0-0000-001100000020\",\"order_source\":\"orderbook\"}","recorded_unix_us":1787932603513498}
{"message":"{\"data\":{\"id\":2044303886000133,\"id_str\":\"2044303886000133\",\"order_type\":1,\"order_subtype\":5,\"datetime\":\"1787932603\",\"microtimestamp\":\"1787932603447000\",\"amount\":3.02055629,\"amount_str\":\"3.02055629\",\"amount_traded\":\"0\",\"amount_at_create\":\"3.02055629\",\"price\":0.03162186,\"price_str\":\"0.03162186\",\"is_liquidation\":false},\"channel\":\"live_orders_ethbtc\",\"event\":\"order_deleted\",\"event_id\":\"00065a1d-7fb5-f6d8-0000-001102000020\",\"pre_event_id\":\"00065a1d-7fb5-f2f0-0001-001101000020\",\"order_source\":\"orderbook\"}","recorded_unix_us":1787932603515868}
{"message":"{\"data\":{\"id\":2044303886000134,\"id_str\":\"2044303886000134\",\"order_type\":1,\"order_subtype\":5,\"datetime\":\"1787932603\",\"microtimestamp\":\"1787932603447000\",\"amount\":2.01406611,\"amount_str\":\"2.01406611\",\"amount_traded\":\"0\",\"amount_at_create\":\"2.01406611\",\"price\":0.0316176,\"price_str\":\"0.03161760\",\"is_liquidation\":false},\"channel\":\"live_orders_ethbtc\",\"event\":\"order_deleted\",\"event_id\":\"00065a1d-7fb5-f6d8-0001-001103000020\",\"pre_event_id\":\"00065a1d-7fb5-f6d8-0000-001102000020\",\"order_source\":\"orderbook\"}","recorded_unix_us":1787932603516000}
{"message":"{\"data\":{\"id\":2044303886004225,\"id_str\":\"2044303886004225\",\"order_type\":0,\"order_subtype\":5,\"datetime\":\"1787932603\",\"microtimestamp\":\"1787932603448000\",\"amount\":2.01629689,\"amount_str\":\"2.01629689\",\"amount_traded\":\"0\",\"amount_at_create\":\"2.01629689\",\"price\":0.03157941,\"price_str\":\"0.03157941\",\"is_liquidation\":false},\"channel\":\"live_orders_ethbtc\",\"event\":\"order_deleted\",\"event_id\":\"00065a1d-7fb5-fac0-0000-001100000020\",\"pre_event_id\":\"00065a1d-7fb5-f6d8-0001-001103000020\",\"order_source\":\"orderbook\"}","recorded_unix_us":1787932603516136}
{"message":"{\"data\":{\"id\":2044303886004227,\"id_str\":\"2044303886004227\",\"order_type\":0,\"order_subtype\":5,\"datetime\":\"1787932603\",\"microtimestamp\":\"1787932603448000\",\"amount\":3.02537254,\"amount_str\":\"3.02537254\",\"amount_traded\":\"0\",\"amount_at_create\":\"3.02537254\",\"price\":0.03156999,\"price_str\":\"0.03156999\",\"is_liquidation\":false},\"channel\":\"live_orders_ethbtc\",\"event\":\"order_deleted\",\"event_id\":\"00065a1d-7fb5-fac0-0001-001101000020\",\"pre_event_id\":\"00065a1d-7fb5-fac0-0000-001100000020\",\"order_source\":\"orderbook\"}","recorded_unix_us":1787932603516271}
{"message":"{\"data\":{\"id\":2044303886008320,\"id_str\":\"2044303886008320\",\"order_type\":0,\"order_subtype\":5,\"datetime\":\"1787932603\",\"microtimestamp\":\"1787932603448000\",\"amount\":4.03662068,\"amount_str\":\"4.03662068\",\"amount_traded\":\"0\",\"amount_at_create\":\"4.03662068\",\"price\":0.03154857,\"price_str\":\"0.03154857\",\"is_liquidation\":false},\"channel\":\"live_orders_ethbtc\",\"event\":\"order_deleted\",\"event_id\":\"00065a1d-7fb5-fac0-0002-001102000020\",\"pre_event_id\":\"00065a1d-7fb5-fac0-0001-001101000020\",\"order_source\":\"orderbook\"}","recorded_unix_us":1787932603516426}
{"message":"{\"data\":{\"id\":2044303886008321,\"id_str\":\"2044303886008321\",\"order_type\":0,\"order_subtype\":5,\"datetime\":\"1787932603\",\"microtimestamp\":\"1787932603449000\",\"amount\":1.00801353,\"amount_str\":\"1.00801353\",\"amount_traded\":\"0\",\"amount_at_create\":\"1.00801353\",\"price\":0.03158534,\"price_str\":\"0.03158534\",\"is_liquidation\":false},\"channel\":\"live_orders_ethbtc\",\"event\":\"order_deleted\",\"event_id\":\"00065a1d-7fb5-fea8-0000-001103000020\",\"pre_event_id\":\"00065a1d-7fb5-fac0-0002-001102000020\",\"order_source\":\"orderbook\"}","recorded_unix_us":1787932603516468}
{"message":"{\"data\":{\"id\":2044303881453575,\"id_str\":\"2044303881453575\",\"order_type\":1,\"order_subtype\":5,\"datetime\":\"1787932603\",\"microtimestamp\":\"1787932603452000\",\"amount\":0.20969786,\"amount_str\":\"0.20969786\",\"amount_traded\":\"0\",\"amount_at_create\":\"0.20969786\",\"price\":0.03348999,\"price_str\":\"0.03348999\",\"is_liquidation\":false},\"channel\":\"live_orders_ethbtc\",\"event\":\"order_deleted\",\"event_id\":\"00065a1d-7fb6-0a60-0000-001100000020\",\"pre_event_id\":\"00065a1d-7fb5-fea8-0000-001103000020\",\"order_source\":\"orderbook\"}","recorded_unix_us":1787932603516573}
{"message":"{\"data\":{\"id\":2044303887552521,\"id_str\":\"2044303887552521\",\"order_type\":0,\"order_subtype\":4,\"datetime\":\"1787932603\",\"microtimestamp\":\"1787932603455000\",\"amount\":0.00006631,\"amount_str\":\"0.00006631\",\"amount_traded\":\"0\",\"amount_at_create\":\"0.00006631\",\"price\":76167,\"price_str\":\"76167.00\",\"is_liquidation\":false},\"channel\":\"live_orders_btcusd\",\"event\":\"order_created\",\"event_id\":\"00065a1d-7fb6-1618-0000-000100000020\",\"pre_event_id\":\"00065a1d-7fb5-b088-0002-000103000020\",\"order_source\":\"orderbook\"}","recorded_unix_us":1787932603516682}
{"message":"{\"data\":{\"id\":2044303887552521,\"id_str\":\"2044303887552521\",\"order_type\":0,\"order_subtype\":4,\"datetime\":\"1787932603\",\"microtimestamp\":\"1787932603455000\",\"amount\":0.00006631,\"amount_str\":\"0.00006631\",\"amount_traded\":\"0\",\"amount_at_create\":\"0.00006631\",\"price\":76167,\"price_str\":\"76167.00\",\"is_liquidation\":false},\"channel\":\"live_orders_btcusd\",\"event\":\"order_deleted\",\"event_id\":\"00065a1d-7fb6-1618-0001-000101000020\",\"pre_event_id\":\"00065a1d-7fb6-1618-0000-000100000020\",\"order_source\":\"orderbook\"}","recorded_unix_us":1787932603516793}
{"message":"{\"data\":{\"id\":2044303877459970,\"id_str\":\"2044303877459970\",\"order_type\":0,\"order_subtype\":5,\"datetime\":\"1787932603\",\"microtimestamp\":\"1787932603460000\",\"amount\":1,\"amount_str\":\"1.000000\",\"amount_traded\":\"0\",\"amount_at_create\":\"1.000000\",\"price\":2480.81,\"price_str\":\"2480.81\",\"is_liquidation\":false},\"channel\":\"live_orders_ethusd\",\"event\":\"order_deleted\",\"event_id\":\"00065a1d-7fb6-29a0-0000-001203000020\",\"pre_event_id\":\"00065a1d-7fb5-db80-0000-001202000020\",\"order_source\":\"orderbook\"}","recorded_unix_us":1787932603516916}
{"message":"{\"data\":{\"id\":2044303885987846,\"id_str\":\"2044303885987846\",\"order_type\":0,\"order_subtype\":5,\"datetime\":\"1787932603\",\"microtimestamp\":\"1787932603460000\",\"amount\":3.942649,\"amount_str\":\"3.942649\",\"amount_traded\":\"0\",\"amount_at_create\":\"3.942649\",\"price\":2480.3,\"price_str\":\"2480.30\",\"is_liquidation\":false},\"channel\":\"live_orders_ethusd\",\"event\":\"order_deleted\",\"event_id\":\"00065a1d-7fb6-29a0-0001-001200000020\",\"pre_event_id\":\"00065a1d-7fb6-29a0-0000-001203000020\",\"order_source\":\"orderbook\"}","recorded_unix_us":1787932603517022}
{"message":"{\"data\":{\"id\":2044303887585284,\"id_str\":\"2044303887585284\",\"order_type\":1,\"order_subtype\":5,\"datetime\":\"1787932603\",\"microtimestamp\":\"1787932603462000\",\"amount\":0.06310787,\"amount_str\":\"0.06310787\",\"amount_traded\":\"0\",\"amount_at_create\":\"0.06310787\",\"price\":78521.24,\"price_str\":\"78521.24\",\"is_liquidation\":false},\"channel\":\"live_orders_btcusd\",\"event\":\"order_created\",\"event_id\":\"00065a1d-7fb6-3170-0000-000102000020\",\"pre_event_id\":\"00065a1d-7fb6-1618-0001-000101000020\",\"order_source\":\"orderbook\"}","recorded_unix_us":1787932603517176}
{"message":"{\"data\":{\"id\":2044303887585284,\"id_str\":\"2044303887585284\",\"order_type\":1,\"order_subtype\":5,\"datetime\":\"1787932603\",\"microtimestamp\":\"1787932603462000\",\"amount\":0.06310787,\"amount_str\":\"0.06310787\",\"amount_traded\":\"0\",\"amount_at_create\":\"0.06310787\",\"price\":78521.24,\"price_str\":\"78521.24\",\"is_liquidation\":false},\"channel\":\"live_orders_btcusd\",\"event\":\"order_deleted\",\"event_id\":\"00065a1d-7fb6-3170-0001-000103000020\",\"pre_event_id\":\"00065a1d-7fb6-3170-0000-000102000020\",\"order_source\":\"orderbook\"}","recorded_unix_us":1787932603517349}
{"message":"{\"data\":{\"id\":2044303878680580,\"id_str\":\"2044303878680580\",\"order_type\":1,\"order_subtype\":5,\"datetime\":\"1787932603\",\"microtimestamp\":\"1787932603462000\",\"amount\":0.00254665,\"amount_str\":\"0.00254665\",\"amount_traded\":\"0\",\"amount_at_create\":\"0.00254665\",\"price\":78534.59,\"price_str\":\"78534.59\",\"is_liquidation\":false},\"channel\":\"live_orders_btcusd\",\"event\":\"order_deleted\",\"event_id\":\"00065a1d-7fb6-3170-0002-000100000020\",\"pre_event_id\":\"00065a1d-7fb6-3170-0001-000103000020\",\"order_source\":\"orderbook\"}","recorded_unix_us":1787932603517409}
{"message":"{\"data\":{\"id\":2044303883784192,\"id_str\":\"2044303883784192\",\"order_type\":0,\"order_subtype\":5,\"datetime\":\"1787932603\",\"microtimestamp\":\"1787932603463000\",\"amount\":0.0025477,\"amount_str\":\"0.00254770\",\"amount_traded\":\"0\",\"amount_at_create\":\"0.00254770\",\"price\":78502.27,\"price_str\":\"78502.27\",\"is_liquidation\":false},\"channel\":\"live_orders_btcusd\",\"event\":\"order_deleted\",\"event_id\":\"00065a1d-7fb6-3558-0000-000101000020\",\"pre_event_id\":\"00065a1d-7fb6-3170-0002-000100000020\",\"order_source\":\"orderbook\"}","recorded_unix_us":1787932603530630}
{"message":"{\"data\":{\"id\":2044303887597571,\"id_str\":\"2044303887597571\",\"order_type\":0,\"order_subtype\":5,\"datetime\":\"1787932603\",\"microtimestamp\":\"1787932603465000\",\"amount\":4.23144408,\"amount_str\":\"4.23144408\",\"amount_traded\":\"0\",\"amount_at_create\":\"4.23144408\",\"price\":0.03159626,\"price_str\":\"0.03159626\",\"is_liquidation\":false},\"channel\":\"live_orders_ethbtc\",\"event\":\"order_created\",\"event_id\":\"00065a1d-7fb6-3d28-0000-001101000020\",\"pre_event_id\":\"00065a1d-7fb6-0a60-0000-001100000020\",\"order_source\":\"orderbook\"}","recorded_unix_us":1787932603530896}
{"message":"{\"data\":{\"id\":2044303887597577,\"id_str\":\"2044303887597577\",\"order_type\":1,\"order_subtype\":5,\"datetime\":\"1787932603\",\"microtimestamp\":\"1787932603466000\",\"amount\":0.1,\"amount_str\":\"0.10000000\",\"amount_traded\":\"0\",\"amount_at_create\":\"0.10000000\",\"price\":78522.62,\"price_str\":\"78522.62\",\"is_liquidation\":false},\"channel\":\"live_orders_btcusd\",\"event\":\"order_created\",\"event_id\":\"00065a1d-7fb6-4110-0000-000102000020\",\"pre_event_id\":\"00065a1d-7fb6-3558-0000-000101000020\",\"order_source\":\"orderbook\"}","recorded_unix_us":1787932603531067}
{"message":"{\"data\":{\"id\":2044303887597577,\"id_str\":\"2044303887597577\",\"order_type\":1,\"order_subtype\":5,\"datetime\":\"1787932603\",\"microtimestamp\":\"1787932603466000\",\"amount\":0.1,\"amount_str\":\"0.10000000\",\"amount_traded\":\"0\",\"amount_at_create\":\"0.10000000\",\"price\":78522.62,\"price_str\":\"78522.62\",\"is_liquidation\":false},\"channel\":\"live_orders_btcusd\",\"event\":\"order_deleted\",\"event_id\":\"00065a1d-7fb6-4110-0001-000103000020\",\"pre_event_id\":\"00065a1d-7fb6-4110-0000-000102000020\",\"order_source\":\"orderbook\"}","recorded_unix_us":1787932603531193}
{"message":"{\"data\":{\"id\":2044303887605766,\"id_str\":\"2044303887605766\",\"order_type\":1,\"order_subtype\":5,\"datetime\":\"1787932603\",\"microtimestamp\":\"1787932603468000\",\"amount\":4.088572,\"amount_str\":\"4.088572\",\"amount_traded\":\"0\",\"amount_at_create\":\"4.088572\",\"price\":2507.99,\"price_str\":\"2507.99\",\"is_liquidation\":false},\"channel\":\"live_orders_ethusd\",\"event\":\"order_created\",\"event_id\":\"00065a1d-7fb6-48e0-0000-001201000020\",\"pre_event_id\":\"00065a1d-7fb6-29a0-0001-001200000020\",\"order_source\":\"orderbook\"}","recorded_unix_us":1787932603531333}
{"message":"{\"data\":{\"id\":2044303886839809,\"id_str\":\"2044303886839809\",\"order_type\":0,\"order_subtype\":5,\"datetime\":\"1787932603\",\"microtimestamp\":\"1787932603470000\",\"amount\":0.206118,\"amount_str\":\"0.206118\",\"amount_traded\":\"0\",\"amount_at_create\":\"0.206118\",\"price\":2480.51,\"price_str\":\"2480.51\",\"is_liquidation\":false},\"channel\":\"live_orders_ethusd\",\"event\":\"order_deleted\",\"event_id\":\"00065a1d-7fb6-50b0-0000-001202000020\",\"pre_event_id\":\"00065a1d-7fb6-48e0-0000-001201000020\",\"order_source\":\"orderbook\"}","recorded_unix_us":1787932603531461}
{"message":"{\"data\":{\"id\":2044303887630336,\"id_str\":\"2044303887630336\",\"order_type\":0,\"order_subtype\":5,\"datetime\":\"1787932603\",\"microtimestamp\":\"1787932603473000\",\"amount\":1,\"amount_str\":\"1.000000\",\"amount_traded\":\"0\",\"amount_at_create\":\"1.000000\",\"price\":2480.85,\"price_str\":\"2480.85\",\"is_liquidation\":false},\"channel\":\"live_orders_ethusd\",\"event\":\"order_created\",\"event_id\":\"00065a1d-7fb6-5c68-0000-001203000020\",\"pre_event_id\":\"00065a1d-7fb6-50b0-0000-001202000020\",\"order_source\":\"orderbook\"}","recorded_unix_us":1787932603531579}
{"message":"{\"data\":{\"id\":2044303887630340,\"id_str\":\"2044303887630340\",\"order_type\":0,\"order_subtype\":5,\"datetime\":\"1787932603\",\"microtimestamp\":\"1787932603473000\",\"amount\":0.060107,\"amount_str\":\"0.060107\",\"amount_traded\":\"0\",\"amount_at_create\":\"0.060107\",\"price\":2479.27,\"price_str\":\"2479.27\",\"is_liquidation\":false},\"channel\":\"live_orders_ethusd\",\"event\":\"order_created\",\"event_id\":\"00065a1d-7fb6-5c68-0001-001200000020\",\"pre_event_id\":\"00065a1d-7fb6-5c68-0000-001203000020\",\"order_source\":\"orderbook\"}","recorded_unix_us":1787932603531735}
{"message":"{\"data\":{\"id\":2044303887650816,\"id_str\":\"2044303887650816\",\"order_type\":1,\"order_subtype\":5,\"datetime\":\"1787932603\",\"microtimestamp\":\"1787932603478000\",\"amount\":1,\"amount_str\":\"1.000000\",\"amount_traded\":\"0\",\"amount_at_create\":\"1.000000\",\"price\":2480.87,\"price_str\":\"2480.87\",\"is_liquidation\":false},\"channel\":\"live_orders_ethusd\",\"event\":\"order_created\",\"event_id\":\"00065a1d-7fb6-6ff0-0000-001201000020\",\"pre_event_id\":\"00065a1d-7fb6-5c68-0001-001200000020\",\"order_source\":\"orderbook\"}","recorded_unix_us":1787932603531844}
{"message":"{\"data\":{\"id\":2044303887659017,\"id_str\":\"2044303887659017\",\"order_type\":0,\"order_subtype\":5,\"datetime\":\"1787932603\",\"microtimestamp\":\"1787932603480000\",\"amount\":0.486825,\"amount_str\":\"0.486825\",\"amount_traded\":\"0\",\"amount_at_create\":\"0.486825\",\"price\":2480.31,\"price_str\":\"2480.31\",\"is_liquidation\":false},\"channel\":\"live_orders_ethusd\",\"event\":\"order_created\",\"event_id\":\"00065a1d-7fb6-77c0-0000-001202000020\",\"pre_event_id\":\"00065a1d-7fb6-6ff0-0000-001201000020\",\"order_source\":\"orderbook\"}","recorded_unix_us":1787932603531961}
{"message":"{\"data\":{\"id\":2044303887630336,\"id_str\":\"2044303887630336\",\"order_type\":0,\"order_subtype\":5,\"datetime\":\"1787932603\",\"microtimestamp\":\"1787932603487000\",\"amount\":1,\"amount_str\":\"1.000000\",\"amount_traded\":\"0\",\"amount_at_create\":\"1.000000\",\"price\":2480.85,\"price_str\":\"2480.85\",\"is_liquidation\":false},\"channel\":\"live_orders_ethusd\",\"event\":\"order_deleted\",\"event_id\":\"00065a1d-7fb6-9318-0000-001203000020\",\"pre_event_id\":\"00065a1d-7fb6-77c0-0000-001202000020\",\"order_source\":\"orderbook\"}","recorded_unix_us":1787932603532119}
{"message":"{\"data\":{\"id\":2044303887687685,\"id_str\":\"2044303887687685\",\"order_type\":1,\"order_subtype\":5,\"datetime\":\"1787932603\",\"microtimestamp\":\"1787932603487000\",\"amount\":4.23144408,\"amount_str\":\"4.23144408\",\"amount_traded\":\"0\",\"amount_at_create\":\"4.23144408\",\"price\":0.03161305,\"price_str\":\"0.03161305\",\"is_liquidation\":false},\"channel\":\"live_orders_ethbtc\",\"event\":\"order_created\",\"event_id\":\"00065a1d-7fb6-9318-0000-001102000020\",\"pre_event_id\":\"00065a1d-7fb6-3d28-0000-001101000020\",\"order_source\":\"orderbook\"}","recorded_unix_us":1787932603532158}
{"message":"{\"data\":{\"id\":2044303887712264,\"id_str\":\"2044303887712264\",\"order_type\":1,\"order_subtype\":5,\"datetime\":\"1787932603\",\"microtimestamp\":\"1787932603494000\",\"amount\":0.1,\"amount_str\":\"0.10000000\",\"amount_traded\":\"0\",\"amount_at_create\":\"0.10000000\",\"price\":78522.63,\"price_str\":\"78522.63\",\"is_liquidation\":false},\"channel\":\"live_orders_btcusd\",\"event\":\"order_created\",\"event_id\":\"00065a1d-7fb6-ae70-0000-000100000020\",\"pre_event_id\":\"00065a1d-7fb6-4110-0001-000103000020\",\"order_source\":\"orderbook\"}","recorded_unix_us":1787932603554480}
{"message":"{\"data\":{\"id\":2044303887712264,\"id_str\":\"2044303887712264\",\"order_type\":1,\"order_subtype\":5,\"datetime\":\"1787932603\",\"microtimestamp\":\"1787932603494000\",\"amount\":0.1,\"amount_str\":\"0.10000000\",\"amount_traded\":\"0\",\"amount_at_create\":\"0.10000000\",\"price\":78522.63,\"price_str\":\"78522.63\",\"is_liquidation\":false},\"channel\":\"live_orders_btcusd\",\"event\":\"order_deleted\",\"event_id\":\"00065a1d-7fb6-ae70-0001-000101000020\",\"pre_event_id\":\"00065a1d-7fb6-ae70-0000-000100000020\",\"order_source\":\"orderbook\"}","recorded_unix_us":1787932603554753}
{"message":"{\"data\":{\"id\":2044303887716355,\"id_str\":\"2044303887716355\",\"order_type\":0,\"order_subtype\":5,\"datetime\":\"1787932603\",\"microtimestamp\":\"1787932603494000\",\"amount\":2.5,\"amount_str\":\"2.500000\",\"amount_traded\":\"0\",\"amount_at_create\":\"2.500000\",\"price\":2480.85,\"price_str\":\"2480.85\",\"is_liquidation\":false},\"channel\":\"live_orders_ethusd\",\"event\":\"order_created\",\"event_id\":\"00065a1d-7fb6-ae70-0000-001200000020\",\"pre_event_id\":\"00065a1d-7fb6-9318-0000-001203000020\",\"order_source\":\"orderbook\"}","recorded_unix_us":1787932603554818}
{"message":"{\"data\":{\"id\":2044303887716362,\"id_str\":\"2044303887716362\",\"order_type\":0,\"order_subtype\":5,\"datetime\":\"1787932603\",\"microtimestamp\":\"1787932603495000\",\"amount\":5,\"amount_str\":\"5.000000\",\"amount_traded\":\"0\",\"amount_at_create\":\"5.000000\",\"price\":2480.85,\"price_str\":\"2480.85\",\"is_liquidation\":false},\"channel\":\"live_orders_ethusd\",\"event\":\"order_created\",\"event_id\":\"00065a1d-7fb6-b258-0000-001201000020\",\"pre_event_id\":\"00065a1d-7fb6-ae70-0000-001200000020\",\"order_source\":\"orderbook\"}","recorded_unix_us":1787932603554946}
{"message":"{\"data\":{\"id\":2044303887732741,\"id_str\":\"2044303887732741\",\"order_type\":0,\"order_subtype\":4,\"datetime\":\"1787932603\",\"microtimestamp\":\"1787932603499000\",\"amount\":0.00006631,\"amount_str\":\"0.00006631\",\"amount_traded\":\"0\",\"amount_at_create\":\"0.00006631\",\"price\":76166.96,\"price_str\":\"76166.96\",\"is_liquidation\":false},\"channel\":\"live_orders_btcusd\",\"event\":\"order_created\",\"event_id\":\"00065a1d-7fb6-c1f8-0000-000102000020\",\"pre_event_id\":\"00065a1d-7fb6-ae70-0001-000101000020\",\"order_source\":\"orderbook\"}","recorded_unix_us":1787932603555068}
{"message":"{\"data\":{\"id\":2044303887732741,\"id_str\":\"2044303887732741\",\"order_type\":0,\"order_subtype\":4,\"datetime\":\"1787932603\",\"microtimestamp\":\"1787932603499000\",\"amount\":0.00006631,\"amount_str\":\"0.00006631\",\"amount_traded\":\"0\",\"amount_at_create\":\"0.00006631\",\"price\":76166.96,\"price_str\":\"76166.96\",\"is_liquidation\":false},\"channel\":\"live_orders_btcusd\",\"event\":\"order_deleted\",\"event_id\":\"00065a1d-7fb6-c1f8-0001-000103000020\",\"pre_event_id\":\"00065a1d-7fb6-c1f8-0000-000102000020\",\"order_source\":\"orderbook\"}","recorded_unix_us":1787932603555182}
{"message":"{\"data\":{\"id\":2044303887740936,\"id_str\":\"2044303887740936\",\"order_type\":0,\"order_subtype\":5,\"datetime\":\"1787932604\",\"microtimestamp\":\"1787932603501000\",\"amount\":1,\"amount_str\":\"1.000000\",\"amount_traded\":\"0\",\"amount_at_create\":\"1.000000\",\"price\":2480.82,\"price_str\":\"2480.82\",\"is_liquidation\":false},\"channel\":\"live_orders_ethusd\",\"event\":\"order_created\",\"event_id\":\"00065a1d-7fb6-c9c8-0000-001202000020\",\"pre_event_id\":\"00065a1d-7fb6-b258-0000-001201000020\",\"order_source\":\"orderbook\"}","recorded_unix_us":1787932603555318}
{"message":"{\"data\":{\"id\":2044303887765505,\"id_str\":\"2044303887765505\",\"order_type\":0,\"order_subtype\":5,\"datetime\":\"1787932604\",\"microtimestamp\":\"1787932603506000\",\"amount\":0.00140266,\"amount_str\":\"0.00140266\",\"amount_traded\":\"0\",\"amount_at_create\":\"0.00140266\",\"price\":70669.15,\"price_str\":\"70669.15\",\"is_liquidation\":false},\"channel\":\"live_orders_btcusd\",\"event\":\"order_created\",\"event_id\":\"00065a1d-7fb6-dd50-0000-000100000020\",\"pre_event_id\":\"00065a1d-7fb6-c1f8-0001-000103000020\",\"order_source\":\"orderbook\"}","recorded_unix_us":1787932603555453}
{"message":"{\"data\":{\"id\":2044303887773696,\"id_str\":\"2044303887773696\",\"order_type\":1,\"order_subtype\":5,\"datetime\":\"1787932604\",\"microtimestamp\":\"1787932603508000\",\"amount\":0.06310787,\"amount_str\":\"0.06310787\",\"amount_traded\":\"0\",\"amount_at_create\":\"0.06310787\",\"price\":78521.14,\"price_str\":\"78521.14\",\"is_liquidation\":false},\"channel\":\"live_orders_btcusd\",\"event\":\"order_created\",\"event_id\":\"00065a1d-7fb6-e520-0000-000101000020\",\"pre_event_id\":\"00065a1d-7fb6-dd50-0000-000100000020\",\"order_source\":\"orderbook\"}","recorded_unix_us":1787932603573629}
{"message":"{\"data\":{\"id\":2044303887773696,\"id_str\":\"2044303887773696\",\"order_type\":1,\"order_subtype\":5,\"datetime\":\"1787932604\",\"microtimestamp\":\"1787932603508000\",\"amount\":0.06310787,\"amount_str\":\"0.06310787\",\"amount_traded\":\"0\",\"amount_at_create\":\"0.06310787\",\"price\":78521.14,\"price_str\":\"78521.14\",\"is_liquidation\":false},\"channel\":\"live_orders_btcusd\",\"event\":\"order_deleted\",\"event_id\":\"00065a1d-7fb6-e520-0001-000102000020\",\"pre_event_id\":\"00065a1d-7fb6-e520-0000-000101000020\",\"order_source\":\"orderbook\"}","recorded_unix_us":1787932603573862}
{"message":"{\"data\":{\"id\":2044303887785985,\"id_str\":\"2044303887785985\",\"order_type\":1,\"order_subtype\":5,\"datetime\":\"1787932604\",\"microtimestamp\":\"1787932603512000\",\"amount\":0.1,\"amount_str\":\"0.10000000\",\"amount_traded\":\"0\",\"amount_at_create\":\"0.10000000\",\"price\":78522.62,\"price_str\":\"78522.62\",\"is_liquidation\":false},\"channel\":\"live_orders_btcusd\",\"event\":\"order_created\",\"event_id\":\"00065a1d-7fb6-f4c0-0000-000103000020\",\"pre_event_id\":\"00065a1d-7fb6-e520-0001-000102000020\",\"order_source\":\"orderbook\"}","recorded_unix_us":1787932603574063}
{"message":"{\"data\":{\"id\":2044303887785985,\"id_str\":\"2044303887785985\",\"order_type\":1,\"order_subtype\":5,\"datetime\":\"1787932604\",\"microtimestamp\":\"1787932603512000\",\"amount\":0.1,\"amount_str\":\"0.10000000\",\"amount_traded\":\"0\",\"amount_at_create\":\"0.10000000\",\"price\":78522.62,\"price_str\":\"78522.62\",\"is_liquidation\":false},\"channel\":\"live_orders_btcusd\",\"event\":\"order_deleted\",\"event_id\":\"00065a1d-7fb6-f4c0-0001-000100000020\",\"pre_event_id\":\"00065a1d-7fb6-f4c0-0000-000103000020\",\"order_source\":\"orderbook\"}","recorded_unix_us":1787932603574129}
{"message":"{\"data\":{\"id\":2044303887798272,\"id_str\":\"2044303887798272\",\"order_type\":1,\"order_subtype\":5,\"datetime\":\"1787932604\",\"microtimestamp\":\"1787932603514000\",\"amount\":1.007365,\"amount_str\":\"1.00736500\",\"amount_traded\":\"0\",\"amount_at_create\":\"1.00736500\",\"price\":0.03160719,\"price_str\":\"0.03160719\",\"is_liquidation\":false},\"channel\":\"live_orders_ethbtc\",\"event\":\"order_created\",\"event_id\":\"00065a1d-7fb6-fc90-0000-001103000020\",\"pre_event_id\":\"00065a1d-7fb6-9318-0000-001102000020\",\"order_source\":\"orderbook\"}","recorded_unix_us":1787932603574260}
{"message":"{\"data\":{\"id\":2044303887847425,\"id_str\":\"2044303887847425\",\"order_type\":1,\"order_subtype\":5,\"datetime\":\"1787932604\",\"microtimestamp\":\"1787932603526000\",\"amount\":0.1,\"amount_str\":\"0.10000000\",\"amount_traded\":\"0\",\"amount_at_create\":\"0.10000000\",\"price\":78522.63,\"price_str\":\"78522.63\",\"is_liquidation\":false},\"channel\":\"live_orders_btcusd\",\"event\":\"order_created\",\"event_id\":\"00065a1d-7fb7-2b70-0000-000101000020\",\"pre_event_id\":\"00065a1d-7fb6-f4c0-0001-000100000020\",\"order_source\":\"orderbook\"}","recorded_unix_us":1787932603574540}
{"message":"{\"data\":{\"id\":2044303887847425,\"id_str\":\"2044303887847425\",\"order_type\":1,\"order_subtype\":5,\"datetime\":\"1787932604\",\"microtimestamp\":\"1787932603526000\",\"amount\":0.1,\"amount_str\":\"0.10000000\",\"amount_traded\":\"0\",\"amount_at_create\":\"0.10000000\",\"price\":78522.63,\"price_str\":\"78522.63\",\"is_liquidation\":false},\"channel\":\"live_orders_btcusd\",\"event\":\"order_deleted\",\"event_id\":\"00065a1d-7fb7-2b70-0001-000102000020\",\"pre_event_id\":\"00065a1d-7fb7-2b70-0000-000101000020\",\"order_source\":\"orderbook\"}","recorded_unix_us":1787932603574586}
{"message":"{\"data\":{\"id\":2044303887740936,\"id_str\":\"2044303887740936\",\"order_type\":0,\"order_subtype\":5,\"datetime\":\"1787932604\",\"microtimestamp\":\"1787932603530000\",\"amount\":1,\"amount_str\":\"1.000000\",\"amount_traded\":\"0\",\"amount_at_create\":\"1.000000\",\"price\":2480.82,\"price_str\":\"2480.82\",\"is_liquidation\":false},\"channel\":\"live_orders_ethusd\",\"event\":\"order_deleted\",\"event_id\":\"00065a1d-7fb7-3b10-0000-001203000020\",\"pre_event_id\":\"00065a1d-7fb6-c9c8-0000-001202000020\",\"order_source\":\"orderbook\"}","recorded_unix_us":1787932603574676}
{"message":"{\"data\":{\"id\":2044303887888388,\"id_str\":\"2044303887888388\",\"order_type\":1,\"order_subtype\":5,\"datetime\":\"1787932604\",\"microtimestamp\":\"1787932603536000\",\"amount\":1.27113313,\"amount_str\":\"1.27113313\",\"amount_traded\":\"0\",\"amount_at_create\":\"1.27113313\",\"price\":78669.97,\"price_str\":\"78669.97\",\"is_liquidation\":false},\"channel\":\"live_orders_btcusd\",\"event\":\"order_created\",\"event_id\":\"00065a1d-7fb7-5280-0000-000103000020\",\"pre_event_id\":\"00065a1d-7fb7-2b70-0001-000102000020\",\"order_source\":\"orderbook\"}","recorded_unix_us":1787932603574803}
{"message":"{\"data\":{\"id\":2044303887888392,\"id_str\":\"2044303887888392\",\"order_type\":1,\"order_subtype\":5,\"datetime\":\"1787932604\",\"microtimestamp\":\"1787932603537000\",\"amount\":10.034921,\"amount_str\":\"10.034921\",\"amount_traded\":\"0\",\"amount_at_create\":\"10.034921\",\"price\":2482.9,\"price_str\":\"2482.90\",\"is_liquidation\":false},\"channel\":\"live_orders_ethusd\",\"event\":\"order_created\",\"event_id\":\"00065a1d-7fb7-5668-0000-001200000020\",\"pre_event_id\":\"00065a1d-7fb7-3b10-0000-001203000020\",\"order_source\":\"orderbook\"}","recorded_unix_us":1787932603574990}
{"message":"{\"data\":{\"id\":2044303878234112,\"id_str\":\"2044303878234112\",\"order_type\":0,\"order_subtype\":5,\"datetime\":\"1787932604\",\"microtimestamp\":\"1787932603539000\",\"amount\":0.25,\"amount_str\":\"0.25000000\",\"amount_traded\":\"0\",\"amount_at_create\":\"0.25000000\",\"price\":78511.65,\"price_str\":\"78511.65\",\"is_liquidation\":false},\"channel\":\"live_orders_btcusd\",\"event\":\"order_deleted\",\"event_id\":\"00065a1d-7fb7-5e38-0000-000100000020\",\"pre_event_id\":\"00065a1d-7fb7-5280-0000-000103000020\",\"order_source\":\"orderbook\"}","recorded_unix_us":1787932603575028}
{"message":"{\"data\":{\"id\":2044303887659017,\"id_str\":\"2044303887659017\",\"order_type\":0,\"order_subtype\":5,\"datetime\":\"1787932604\",\"microtimestamp\":\"1787932603539000\",\"amount\":0.486825,\"amount_str\":\"0.486825\",\"amount_traded\":\"0\",\"amount_at_create\":\"0.486825\",\"price\":2480.31,\"price_str\":\"2480.31\",\"is_liquidation\":false},\"channel\":\"live_orders_ethusd\",\"event\":\"order_deleted\",\"event_id\":\"00065a1d-7fb7-5e38-0000-001201000020\",\"pre_event_id\":\"00065a1d-7fb7-5668-0000-001200000020\",\"order_source\":\"orderbook\"}","recorded_unix_us":1787932603575141}
{"message":"{\"data\":{\"id\":2044303887904771,\"id_str\":\"2044303887904771\",\"order_type\":1,\"order_subtype\":5,\"datetime\":\"1787932604\",\"microtimestamp\":\"1787932603540000\",\"amount\":0.06310787,\"amount_str\":\"0.06310787\",\"amount_traded\":\"0\",\"amount_at_create\":\"0.06310787\",\"price\":78521.53,\"price_str\":\"78521.53\",\"is_liquidation\":false},\"channel\":\"live_orders_btcusd\",\"event\":\"order_created\",\"event_id\":\"00065a1d-7fb7-6220-0000-000101000020\",\"pre_event_id\":\"00065a1d-7fb7-5e38-0000-000100000020\",\"order_source\":\"orderbook\"}","recorded_unix_us":1787932603575261}
{"message":"{\"data\":{\"id\":2044303887904771,\"id_str\":\"2044303887904771\",\"order_type\":1,\"order_subtype\":5,\"datetime\":\"1787932604\",\"microtimestamp\":\"1787932603540000\",\"amount\":0.06310787,\"amount_str\":\"0.06310787\",\"amount_traded\":\"0\",\"amount_at_create\":\"0.06310787\",\"price\":78521.53,\"price_str\":\"78521.53\",\"is_liquidation\":false},\"channel\":\"live_orders_btcusd\",\"event\":\"order_deleted\",\"event_id\":\"00065a1d-7fb7-6220-0001-000102000020\",\"pre_event_id\":\"00065a1d-7fb7-6220-0000-000101000020\",\"order_source\":\"orderbook\"}","recorded_unix_us":1787932603575367}
{"message":"{\"data\":{\"id\":2044303887917058,\"id_str\":\"2044303887917058\",\"order_type\":1,\"order_subtype\":5,\"datetime\":\"1787932604\",\"microtimestamp\":\"1787932603543000\",\"amount\":3.02055629,\"amount_str\":\"3.02055629\",\"amount_traded\":\"0\",\"amount_at_create\":\"3.02055629\",\"price\":0.03162186,\"price_str\":\"0.03162186\",\"is_liquidation\":false},\"channel\":\"live_orders_ethbtc\",\"event\":\"order_created\",\"event_id\":\"00065a1d-7fb7-6dd8-0000-001100000020\",\"pre_event_id\":\"00065a1d-7fb6-fc90-0000-001103000020\",\"order_source\":\"orderbook\"}","recorded_unix_us":1787932603586096}
{"message":"{\"data\":{\"id\":2044303887917057,\"id_str\":\"2044303887917057\",\"order_type\":1,\"order_subtype\":5,\"datetime\":\"1787932604\",\"microtimestamp\":\"1787932603543000\",\"amount\":0.1,\"amount_str\":\"0.10000000\",\"amount_traded\":\"0\",\"amount_at_create\":\"0.10000000\",\"price\":78522.62,\"price_str\":\"78522.62\",\"is_liquidation\":false},\"channel\":\"live_orders_btcusd\",\"event\":\"order_created\",\"event_id\":\"00065a1d-7fb7-6dd8-0000-000103000020\",\"pre_event_id\":\"00065a1d-7fb7-6220-0001-000102000020\",\"order_source\":\"orderbook\"}","recorded_unix_us":1787932603586510}
{"message":"{\"data\":{\"id\":2044303887917057,\"id_str\":\"2044303887917057\",\"order_type\":1,\"order_subtype\":5,\"datetime\":\"1787932604\",\"microtimestamp\":\"1787932603543000\",\"amount\":0.1,\"amount_str\":\"0.10000000\",\"amount_traded\":\"0\",\"amount_at_create\":\"0.10000000\",\"price\":78522.62,\"price_str\":\"78522.62\",\"is_liquidation\":false},\"channel\":\"live_orders_btcusd\",\"event\":\"order_deleted\",\"event_id\":\"00065a1d-7fb7-6dd8-0001-000100000020\",\"pre_event_id\":\"00065a1d-7fb7-6dd8-0000-000103000020\",\"order_source\":\"orderbook\"}","recorded_unix_us":1787932603586583}
{"message":"{\"data\":{\"id\":2044303887917056,\"id_str\":\"2044303887917056\",\"order_type\":1,\"order_subtype\":5,\"datetime\":\"1787932604\",\"microtimestamp\":\"1787932603543000\",\"amount\":2.01406611,\"amount_str\":\"2.01406611\",\"amount_traded\":\"0\",\"amount_at_create\":\"2.01406611\",\"price\":0.0316176,\"price_str\":\"0.03161760\",\"is_liquidation\":false},\"channel\":\"live_orders_ethbtc\",\"event\":\"order_created\",\"event_id\":\"00065a1d-7fb7-6dd8-0001-001101000020\",\"pre_event_id\":\"00065a1d-7fb7-6dd8-0000-001100000020\",\"order_source\":\"orderbook\"}","recorded_unix_us":1787932603586620}
{"message":"{\"data\":{\"id\":2044303887921152,\"id_str\":\"2044303887921152\",\"order_type\":0,\"order_subtype\":5,\"datetime\":\"1787932604\",\"microtimestamp\":\"1787932603544000\",\"amount\":1,\"amount_str\":\"1.000000\",\"amount_traded\":\"0\",\"amount_at_create\":\"1.000000\",\"price\":2480.85,\"price_str\":\"2480.85\",\"is_liquidation\":false},\"channel\":\"live_orders_ethusd\",\"event\":\"order_created\",\"event_id\":\"00065a1d-7fb7-71c0-0000-001202000020\",\"pre_event_id\":\"00065a1d-7fb7-5e38-0000-001201000020\",\"order_source\":\"orderbook\"}","recorded_unix_us":1787932603615845}
{"message":"{\"data\":{\"id\":2044303887933447,\"id_str\":\"2044303887933447\",\"order_type\":0,\"order_subtype\":5,\"datetime\":\"1787932604\",\"microtimestamp\":\"1787932603548000\",\"amount\":0.214551,\"amount_str\":\"0.214551\",\"amount_traded\":\"0\",\"amount_at_create\":\"0.214551\",\"price\":2480.51,\"price_str\":\"2480.51\",\"is_liquidation\":false},\"channel\":\"live_orders_ethusd\",\"event\":\"order_created\",\"event_id\":\"00065a1d-7fb7-8160-0000-001203000020\",\"pre_event_id\":\"00065a1d-7fb7-71c0-0000-001202000020\",\"order_source\":\"orderbook\"}","recorded_unix_us":1787932603616208}
{"message":"{\"data\":{\"id\":2044303887949824,\"id_str\":\"2044303887949824\",\"order_type\":0,\"order_subtype\":5,\"datetime\":\"1787932604\",\"microtimestamp\":\"1787932603551000\",\"amount\":1.00801353,\"amount_str\":\"1.00801353\",\"amount_traded\":\"0\",\"amount_at_create\":\"1.00801353\",\"price\":0.03158534,\"price_str\":\"0.03158534\",\"is_liquidation\":false},\"channel\":\"live_orders_ethbtc\",\"event\":\"order_created\",\"event_id\":\"00065a1d-7fb7-8d18-0000-001102000020\",\"pre_event_id\":\"00065a1d-7fb7-6dd8-0001-001101000020\",\"order_source\":\"orderbook\"}","recorded_unix_us":1787932603616438}
{"message":"{\"data\":{\"id\":2044303887953921,\"id_str\":\"2044303887953921\",\"order_type\":1,\"order_subtype\":5,\"datetime\":\"1787932604\",\"microtimestamp\":\"1787932603552000\",\"amount\":4.02232075,\"amount_str\":\"4.02232075\",\"amount_traded\":\"0\",\"amount_at_create\":\"4.02232075\",\"price\":0.03165997,\"price_str\":\"0.03165997\",\"is_liquidation\":false},\"channel\":\"live_orders_ethbtc\",\"event\":\"order_created\",\"event_id\":\"00065a1d-7fb7-9100-0000-001103000020\",\"pre_event_id\":\"00065a1d-7fb7-8d18-0000-001102000020\",\"order_source\":\"orderbook\"}","recorded_unix_us":1787932603616682}
{"message":"{\"data\":{\"id\":2044303887953922,\"id_str\":\"2044303887953922\",\"order_type\":0,\"order_subtype\":5,\"datetime\":\"1787932604\",\"microtimestamp\":\"1787932603552000\",\"amount\":2.01629689,\"amount_str\":\"2.01629689\",\"amount_traded\":\"0\",\"amount_at_create\":\"2.01629689\",\"price\":0.03157941,\"price_str\":\"0.03157941\",\"is_liquidation\":false},\"channel\":\"live_orders_ethbtc\",\"event\":\"order_created\",\"event_id\":\"00065a1d-7fb7-9100-0001-001100000020\",\"pre_event_id\":\"00065a1d-7fb7-9100-0000-001103000020\",\"order_source\":\"orderbook\"}","recorded_unix_us":1787932603616756}
{"message":"{\"data\":{\"id\":2044303887958016,\"id_str\":\"2044303887958016\",\"order_type\":1,\"order_subtype\":5,\"datetime\":\"1787932604\",\"microtimestamp\":\"1787932603553000\",\"amount\":0.1,\"amount_str\":\"0.10000000\",\"amount_traded\":\"0\",\"amount_at_create\":\"0.10000000\",\"price\":78522.63,\"price_str\":\"78522.63\",\"is_liquidation\":false},\"channel\":\"live_orders_btcusd\",\"event\":\"order_created\",\"event_id\":\"00065a1d-7fb7-94e8-0000-000101000020\",\"pre_event_id\":\"00065a1d-7fb7-6dd8-0001-000100000020\",\"order_source\":\"orderbook\"}","recorded_unix_us":1787932603616958}
{"message":"{\"data\":{\"id\":2044303887958016,\"id_str\":\"2044303887958016\",\"order_type\":1,\"order_subtype\":5,\"datetime\":\"1787932604\",\"microtimestamp\":\"1787932603553000\",\"amount\":0.1,\"amount_str\":\"0.10000000\",\"amount_traded\":\"0\",\"amount_at_create\":\"0.10000000\",\"price\":78522.63,\"price_str\":\"78522.63\",\"is_liquidation\":false},\"channel\":\"live_orders_btcusd\",\"event\":\"order_deleted\",\"event_id\":\"00065a1d-7fb7-94e8-0001-000102000020\",\"pre_event_id\":\"00065a1d-7fb7-94e8-0000-000101000020\",\"order_source\":\"orderbook\"}","recorded_unix_us":1787932603617226}
{"message":"{\"data\":{\"id\":2044303887958023,\"id_str\":\"2044303887958023\",\"order_type\":0,\"order_subtype\":5,\"datetime\":\"1787932604\",\"microtimestamp\":\"1787932603554000\",\"amount\":3.02537254,\"amount_str\":\"3.02537254\",\"amount_traded\":\"0\",\"amount_at_create\":\"3.02537254\",\"price\":0.03156999,\"price_str\":\"0.03156999\",\"is_liquidation\":false},\"channel\":\"live_orders_ethbtc\",\"event\":\"order_created\",\"event_id\":\"00065a1d-7fb7-98d0-0000-001101000020\",\"pre_event_id\":\"00065a1d-7fb7-9100-0001-001100000020\",\"order_source\":\"orderbook\"}","recorded_unix_us":1787932603617375}
{"message":"{\"data\":{\"id\":2044303887970307,\"id_str\":\"2044303887970307\",\"order_type\":1,\"order_subtype\":5,\"datetime\":\"1787932604\",\"microtimestamp\":\"1787932603557000\",\"amount\":0.06367563,\"amount_str\":\"0.06367563\",\"amount_traded\":\"0\",\"amount_at_create\":\"0.06367563\",\"price\":78522.98,\"price_str\":\"78522.98\",\"is_liquidation\":false},\"channel\":\"live_orders_btcusd\",\"event\":\"order_created\",\"event_id\":\"00065a1d-7fb7-a488-0000-000103000020\",\"pre_event_id\":\"00065a1d-7fb7-94e8-0001-000102000020\",\"order_source\":\"orderbook\"}","recorded_unix_us":1787932603617508}
{"message":"{\"data\":{\"id\":2044303887970309,\"id_str\":\"2044303887970309\",\"order_type\":1,\"order_subtype\":5,\"datetime\":\"1787932604\",\"microtimestamp\":\"1787932603557000\",\"amount\":0.06367384,\"amount_str\":\"0.06367384\",\"amount_traded\":\"0\",\"amount_at_create\":\"0.06367384\",\"price\":78525.19,\"price_str\":\"78525.19\",\"is_liquidation\":false},\"channel\":\"live_orders_btcusd\",\"event\":\"order_created\",\"event_id\":\"00065a1d-7fb7-a488-0001-000100000020\",\"pre_event_id\":\"00065a1d-7fb7-a488-0000-000103000020\",\"order_source\":\"orderbook\"}","recorded_unix_us":1787932603617702}
{"message":"{\"data\":{\"id\":2044303887974407,\"id_str\":\"2044303887974407\",\"order_type\":1,\"order_subtype\":5,\"datetime\":\"1787932604\",\"microtimestamp\":\"1787932603558000\",\"amount\":0.25466146,\"amount_str\":\"0.25466146\",\"amount_traded\":\"0\",\"amount_at_create\":\"0.25466146\",\"price\":78535.64,\"price_str\":\"78535.64\",\"is_liquidation\":false},\"channel\":\"live_orders_btcusd\",\"event\":\"order_created\",\"event_id\":\"00065a1d-7fb7-a870-0000-000101000020\",\"pre_event_id\":\"00065a1d-7fb7-a488-0001-000100000020\",\"order_source\":\"orderbook\"}","recorded_unix_us":1787932603617881}
{"message":"{\"data\":{\"id\":2044303887978498,\"id_str\":\"2044303887978498\",\"order_type\":1,\"order_subtype\":5,\"datetime\":\"1787932604\",\"microtimestamp\":\"1787932603558000\",\"amount\":1.27209222,\"amount_str\":\"1.27209222\",\"amount_traded\":\"0\",\"amount_at_create\":\"1.27209222\",\"price\":78610.66,\"price_str\":\"78610.66\",\"is_liquidation\":false},\"channel\":\"live_orders_btcusd\",\"event\":\"order_created\",\"event_id\":\"00065a1d-7fb7-a870-0001-000102000020\",\"pre_event_id\":\"00065a1d-7fb7-a870-0000-000101000020\",\"order_source\":\"orderbook\"}","recorded_unix_us":1787932603618060}
{"message":"{\"data\":{\"id\":2044303887978501,\"id_str\":\"2044303887978501\",\"order_type\":1,\"order_subtype\":5,\"datetime\":\"1787932604\",\"microtimestamp\":\"1787932603559000\",\"amount\":12.70451953,\"amount_str\":\"12.70451953\",\"amount_traded\":\"0\",\"amount_at_create\":\"12.70451953\",\"price\":78712.15,\"price_str\":\"78712.15\",\"is_liquidation\":false},\"channel\":\"live_orders_btcusd\",\"event\":\"order_created\",\"event_id\":\"00065a1d-7fb7-ac58-0000-000103000020\",\"pre_event_id\":\"00065a1d-7fb7-a870-0001-000102000020\",\"order_source\":\"orderbook\"}","recorded_unix_us":1787932603618214}
{"message":"{\"data\":{\"id\":2044303887982596,\"id_str\":\"2044303887982596\",\"order_type\":1,\"order_subtype\":5,\"datetime\":\"1787932604\",\"microtimestamp\":\"1787932603559000\",\"amount\":1.26970017,\"amount_str\":\"1.26970017\",\"amount_traded\":\"0\",\"amount_at_create\":\"1.26970017\",\"price\":78758.76,\"price_str\":\"78758.76\",\"is_liquidation\":false},\"channel\":\"live_orders_btcusd\",\"event\":\"order_created\",\"event_id\":\"00065a1d-7fb7-ac58-0001-000100000020\",\"pre_event_id\":\"00065a1d-7fb7-ac58-0000-000103000020\",\"order_source\":\"orderbook\"}","recorded_unix_us":1787932603618466}
{"message":"{\"data\":{\"id\":2044303887982597,\"id_str\":\"2044303887982597\",\"order_type\":1,\"order_subtype\":5,\"datetime\":\"1787932604\",\"microtimestamp\":\"1787932603560000\",\"amount\":1.2684012,\"amount_str\":\"1.26840120\",\"amount_traded\":\"0\",\"amount_at_create\":\"1.26840120\",\"price\":78839.41,\"price_str\":\"78839.41\",\"is_liquidation\":false},\"channel\":\"live_orders_btcusd\",\"event\":\"order_created\",\"event_id\":\"00065a1d-7fb7-b040-0000-000101000020\",\"pre_event_id\":\"00065a1d-7fb7-ac58-0001-000100000020\",\"order_source\":\"orderbook\"}","recorded_unix_us":1787932603618528}
{"message":"{\"data\":{\"id\":2044303878225930,\"id_str\":\"2044303878225930\",\"order_type\":0,\"order_subtype\":5,\"datetime\":\"1787932604\",\"microtimestamp\":\"1787932603560000\",\"amount\":0.5,\"amount_str\":\"0.50000000\",\"amount_traded\":\"0\",\"amount_at_create\":\"0.50000000\",\"price\":78507.73,\"price_str\":\"78507.73\",\"is_liquidation\":false},\"channel\":\"live_orders_btcusd\",\"event\":\"order_deleted\",\"event_id\":\"00065a1d-7fb7-b040-0001-000102000020\",\"pre_event_id\":\"00065a1d-7fb7-b040-0000-000101000020\",\"order_source\":\"orderbook\"}","recorded_unix_us":1787932603618573}
{"message":"{\"data\":{\"id\":2044303887986693,\"id_str\":\"2044303887986693\",\"order_type\":0,\"order_subtype\":5,\"datetime\":\"1787932604\",\"microtimestamp\":\"1787932603560000\",\"amount\":0.25476924,\"amount_str\":\"0.25476924\",\"amount_traded\":\"0\",\"amount_at_create\":\"0.25476924\",\"price\":78502.41,\"price_str\":\"78502.41\",\"is_liquidation\":false},\"channel\":\"live_orders_btcusd\",\"event\":\"order_created\",\"event_id\":\"00065a1d-7fb7-b040-0002-000103000020\",\"pre_event_id\":\"00065a1d-7fb7-b040-0001-000102000020\",\"order_source\":\"orderbook\"}","recorded_unix_us":1787932603619024}
{"message":"{\"data\":{\"id\":2044303887994881,\"id_str\":\"2044303887994881\",\"order_type\":0,\"order_subtype\":5,\"datetime\":\"1787932604\",\"microtimestamp\":\"1787932603562000\",\"amount\":1.27507828,\"amount_str\":\"1.27507828\",\"amount_traded\":\"0\",\"amount_at_create\":\"1.27507828\",\"price\":78426.55,\"price_str\":\"78426.55\",\"is_liquidation\":false},\"channel\":\"live_orders_btcusd\",\"event\":\"order_created\",\"event_id\":\"00065a1d-7fb7-b810-0000-000100000020\",\"pre_event_id\":\"00065a1d-7fb7-b040-0002-000103000020\",\"order_source\":\"orderbook\"}","recorded_unix_us":1787932603619066}
{"message":"{\"data\":{\"id\":2044303885508611,\"id_str\":\"2044303885508611\",\"order_type\":0,\"order_subtype\":5,\"datetime\":\"1787932604\",\"microtimestamp\":\"1787932603563000\",\"amount\":0.26750492,\"amount_str\":\"0.26750492\",\"amount_traded\":\"0\",\"amount_at_create\":\"0.26750492\",\"price\":78484.79,\"price_str\":\"78484.79\",\"is_liquidation\":false},\"channel\":\"live_orders_btcusd\",\"event\":\"order_deleted\",\"event_id\":\"00065a1d-7fb7-bbf8-0000-000101000020\",\"pre_event_id\":\"00065a1d-7fb7-b810-0000-000100000020\",\"order_source\":\"orderbook\"}","recorded_unix_us":1787932603619097}
{"message":"{\"data\":{\"id\":2044303887998976,\"id_str\":\"2044303887998976\",\"order_type\":0,\"order_subtype\":5,\"datetime\":\"1787932604\",\"microtimestamp\":\"1787932603563000\",\"amount\":0.26750492,\"amount_str\":\"0.26750492\",\"amount_traded\":\"0\",\"amount_at_create\":\"0.26750492\",\"price\":78484.79,\"price_str\":\"78484.79\",\"is_liquidation\":false},\"channel\":\"live_orders_btcusd\",\"event\":\"order_created\",\"event_id\":\"00065a1d-7fb7-bbf8-0001-000102000020\",\"pre_event_id\":\"00065a1d-7fb7-bbf8-0000-000101000020\",\"order_source\":\"orderbook\"}","recorded_unix_us":1787932603619126}
{"message":"{\"data\":{\"id\":2044303888007176,\"id_str\":\"2044303888007176\",\"order_type\":0,\"order_subtype\":5,\"datetime\":\"1787932604\",\"microtimestamp\":\"1787932603566000\",\"amount\":1.27541152,\"amount_str\":\"1.27541152\",\"amount_traded\":\"0\",\"amount_at_create\":\"1.27541152\",\"price\":78406.06,\"price_str\":\"78406.06\",\"is_liquidation\":false},\"channel\":\"live_orders_btcusd\",\"event\":\"order_created\",\"event_id\":\"00065a1d-7fb7-c7b0-0000-000103000020\",\"pre_event_id\":\"00065a1d-7fb7-bbf8-0001-000102000020\",\"order_source\":\"orderbook\"}","recorded_unix_us":1787932603619269}
{"message":"{\"data\":{\"id\":2044303888011264,\"id_str\":\"2044303888011264\",\"order_type\":0,\"order_subtype\":5,\"datetime\":\"1787932604\",\"microtimestamp\":\"1787932603566000\",\"amount\":4.03662068,\"amount_str\":\"4.03662068\",\"amount_traded\":\"0\",\"amount_at_create\":\"4.03662068\",\"price\":0.03154857,\"price_str\":\"0.03154857\",\"is_liquidation\":false},\"channel\":\"live_orders_ethbtc\",\"event\":\"order_created\",\"event_id\":\"00065a1d-7fb7-c7b0-0000-001102000020\",\"pre_event_id\":\"00065a1d-7fb7-98d0-0000-001101000020\",\"order_source\":\"orderbook\"}","recorded_unix_us":1787932603619306}
{"message":"{\"data\":{\"id\":2044303888011265,\"id_str\":\"2044303888011265\",\"order_type\":0,\"order_subtype\":5,\"datetime\":\"1787932604\",\"microtimestamp\":\"1787932603566000\",\"amount\":12.76418733,\"amount_str\":\"12.76418733\",\"amount_traded\":\"0\",\"amount_at_create\":\"12.76418733\",\"price\":78344.19,\"price_str\":\"78344.19\",\"is_liquidation\":false},\"channel\":\"live_orders_btcusd\",\"event\":\"order_created\",\"event_id\":\"00065a1d-7fb7-c7b0-0001-000100000020\",\"pre_event_id\":\"00065a1d-7fb7-c7b0-0000-000103000020\",\"order_source\":\"orderbook\"}","recorded_unix_us":1787932603619336}
{"message":"{\"data\":{\"id\":2044303888015362,\"id_str\":\"2044303888015362\",\"order_type\":0,\"order_subtype\":5,\"datetime\":\"1787932604\",\"microtimestamp\":\"1787932603568000\",\"amount\":1.27567513,\"amount_str\":\"1.27567513\",\"amount_traded\":\"0\",\"amount_at_create\":\"1.27567513\",\"price\":78389.86,\"price_str\":\"78389.86\",\"is_liquidation\":false},\"channel\":\"live_orders_btcusd\",\"event\":\"order_created\",\"event_id\":\"00065a1d-7fb7-cf80-0000-000101000020\",\"pre_event_id\":\"00065a1d-7fb7-c7b0-0001-000100000020\",\"order_source\":\"orderbook\"}","recorded_unix_us":1787932603619473}
{"message":"{\"data\":{\"id\":2044303888015366,\"id_str\":\"2044303888015366\",\"order_type\":0,\"order_subtype\":5,\"datetime\":\"1787932604\",\"microtimestamp\":\"1787932603568000\",\"amount\":1.27757154,\"amount_str\":\"1.27757154\",\"amount_traded\":\"0\",\"amount_at_create\":\"1.27757154\",\"price\":78273.5,\"price_str\":\"78273.50\",\"is_liquidation\":false},\"channel\":\"live_orders_btcusd\",\"event\":\"order_created\",\"event_id\":\"00065a1d-7fb7-cf80-0001-000102000020\",\"pre_event_id\":\"00065a1d-7fb7-cf80-0000-000101000020\",\"order_source\":\"orderbook\"}","recorded_unix_us":1787932603619508}
{"message":"{\"data\":{\"id\":2044303887376393,\"id_str\":\"2044303887376393\",\"order_type\":0,\"order_subtype\":5,\"datetime\":\"1787932604\",\"microtimestamp\":\"1787932603568000\",\"amount\":0.080629,\"amount_str\":\"0.080629\",\"amount_traded\":\"0\",\"amount_at_create\":\"0.080629\",\"price\":2480.49,\"price_str\":\"2480.49\",\"is_liquidation\":false},\"channel\":\"live_orders_ethusd\",\"event\":\"order_deleted\",\"event_id\":\"00065a1d-7fb7-cf80-0000-001200000020\",\"pre_event_id\":\"00065a1d-7fb7-8160-0000-001203000020\",\"order_source\":\"orderbook\"}","recorded_unix_us":1787932603619602}
{"message":"{\"data\":{\"id\":2044303888080900,\"id_str\":\"2044303888080900\",\"order_type\":1,\"order_subtype\":5,\"datetime\":\"1787932604\",\"microtimestamp\":\"1787932603584000\",\"amount\":1.271772,\"amount_str\":\"1.27177200\",\"amount_traded\":\"0\",\"amount_at_create\":\"1.27177200\",\"price\":78630.45,\"price_str\":\"78630.45\",\"is_liquidation\":false},\"channel\":\"live_orders_btcusd\",\"event\":\"order_created\",\"event_id\":\"00065a1d-7fb8-0e00-0000-000103000020\",\"pre_event_id\":\"00065a1d-7fb7-cf80-0001-000102000020\",\"order_source\":\"orderbook\"}","recorded_unix_us":1787932603619775}
{"message":"{\"data\":{\"id\":2044303888080898,\"id_str\":\"2044303888080898\",\"order_type\":0,\"order_subtype\":5,\"datetime\":\"1787932604\",\"microtimestamp\":\"1787932603584000\",\"amount\":1.27817952,\"amount_str\":\"1.27817952\",\"amount_traded\":\"0\",\"amount_at_create\":\"1.27817952\",\"price\":78236.27,\"price_str\":\"78236.27\",\"is_liquidation\":false},\"channel\":\"live_orders_btcusd\",\"event\":\"order_created\",\"event_id\":\"00065a1d-7fb8-0e00-0001-000100000020\",\"pre_event_id\":\"00065a1d-7fb8-0e00-0000-000103000020\",\"order_source\":\"orderbook\"}","recorded_unix_us":1787932603619827}
{"message":"{\"data\":{\"id\":2044303888080901,\"id_str\":\"2044303888080901\",\"order_type\":1,\"order_subtype\":5,\"datetime\":\"1787932604\",\"microtimestamp\":\"1787932603584000\",\"amount\":1.26842789,\"amount_str\":\"1.26842789\",\"amount_traded\":\"0\",\"amount_at_create\":\"1.26842789\",\"price\":78837.75,\"price_str\":\"78837.75\",\"is_liquidation\":false},\"channel\":\"live_orders_btcusd\",\"event\":\"order_created\",\"event_id\":\"00065a1d-7fb8-0e00-0002-000101000020\",\"pre_event_id\":\"00065a1d-7fb8-0e00-0001-000100000020\",\"order_source\":\"orderbook\"}","recorded_unix_us":1787932603619906}
{"message":"{\"data\":{\"id\":2044303888084993,\"id_str\":\"2044303888084993\",\"order_type\":0,\"order_subtype\":5,\"datetime\":\"1787932604\",\"microtimestamp\":\"1787932603584000\",\"amount\":1.27604867,\"amount_str\":\"1.27604867\",\"amount_traded\":\"0\",\"amount_at_create\":\"1.27604867\",\"price\":78366.91,\"price_str\":\"78366.91\",\"is_liquidation\":false},\"channel\":\"live_orders_btcusd\",\"event\":\"order_created\",\"event_id\":\"00065a1d-7fb8-0e00-0003-000102000020\",\"pre_event_id\":\"00065a1d-7fb8-0e00-0002-000101000020\",\"order_source\":\"orderbook\"}","recorded_unix_us":1787932603620049}
{"message":"{\"data\":{\"id\":2044303888084997,\"id_str\":\"2044303888084997\",\"order_type\":1,\"order_subtype\":5,\"datetime\":\"1787932604\",\"microtimestamp\":\"1787932603585000\",\"amount\":0.1,\"amount_str\":\"0.10000000\",\"amount_traded\":\"0\",\"amount_at_create\":\"0.10000000\",\"price\":78522.62,\"price_str\":\"78522.62\",\"is_liquidation\":false},\"channel\":\"live_orders_btcusd\",\"event\":\"order_created\",\"event_id\":\"00065a1d-7fb8-11e8-0000-000103000020\",\"pre_event_id\":\"00065a1d-7fb8-0e00-0003-000102000020\",\"order_source\":\"orderbook\"}","recorded_unix_us":1787932603620099}
{"message":"{\"data\":{\"id\":2044303888084997,\"id_str\":\"2044303888084997\",\"order_type\":1,\"order_subtype\":5,\"datetime\":\"1787932604\",\"microtimestamp\":\"1787932603585000\",\"amount\":0.1,\"amount_str\":\"0.10000000\",\"amount_traded\":\"0\",\"amount_at_create\":\"0.10000000\",\"price\":78522.62,\"price_str\":\"78522.62\",\"is_liquidation\":false},\"channel\":\"live_orders_btcusd\",\"event\":\"order_deleted\",\"event_id\":\"00065a1d-7fb8-11e8-0001-000100000020\",\"pre_event_id\":\"00065a1d-7fb8-11e8-0000-000103000020\",\"order_source\":\"orderbook\"}","recorded_unix_us":1787932603620226}
{"message":"{\"data\":{\"id\":2044303888089093,\"id_str\":\"2044303888089093\",\"order_type\":1,\"order_subtype\":5,\"datetime\":\"1787932604\",\"microtimestamp\":\"1787932603585000\",\"amount\":0.1,\"amount_str\":\"0.10000000\",\"amount_traded\":\"0\",\"amount_at_create\":\"0.10000000\",\"price\":78522.63,\"price_str\":\"78522.63\",\"is_liquidation\":false},\"channel\":\"live_orders_btcusd\",\"event\":\"order_created\",\"event_id\":\"00065a1d-7fb8-11e8-0002-000101000020\",\"pre_event_id\":\"00065a1d-7fb8-11e8-0001-000100000020\",\"order_source\":\"orderbook\"}","recorded_unix_us":1787932603620454}
{"message":"{\"data\":{\"id\":2044303888089093,\"id_str\":\"2044303888089093\",\"order_type\":1,\"order_subtype\":5,\"datetime\":\"1787932604\",\"microtimestamp\":\"1787932603585000\",\"amount\":0.1,\"amount_str\":\"0.10000000\",\"amount_traded\":\"0\",\"amount_at_create\":\"0.10000000\",\"price\":78522.63,\"price_str\":\"78522.63\",\"is_liquidation\":false},\"channel\":\"live_orders_btcusd\",\"event\":\"order_deleted\",\"event_id\":\"00065a1d-7fb8-11e8-0003-000102000020\",\"pre_event_id\":\"00065a1d-7fb8-11e8-0002-000101000020\",\"order_source\":\"orderbook\"}","recorded_unix_us":1787932603620488}
{"message":"{\"data\":{\"id\":2044303888093186,\"id_str\":\"2044303888093186\",\"order_type\":0,\"order_subtype\":5,\"datetime\":\"1787932604\",\"microtimestamp\":\"1787932603586000\",\"amount\":0.00140266,\"amount_str\":\"0.00140266\",\"amount_traded\":\"0\",\"amount_at_create\":\"0.00140266\",\"price\":70669.15,\"price_str\":\"70669.15\",\"is_liquidation\":false},\"channel\":\"live_orders_btcusd\",\"event\":\"order_created\",\"event_id\":\"00065a1d-7fb8-15d0-0000-000103000020\",\"pre_event_id\":\"00065a1d-7fb8-11e8-0003-000102000020\",\"order_source\":\"orderbook\"}","recorded_unix_us":1787932603620518}
{"message":"{\"data\":{\"id\":2044303878144016,\"id_str\":\"2044303878144016\",\"order_type\":0,\"order_subtype\":5,\"datetime\":\"1787932604\",\"microtimestamp\":\"1787932603590000\",\"amount\":6.044921,\"amount_str\":\"6.044921\",\"amount_traded\":\"0\",\"amount_at_create\":\"6.044921\",\"price\":2480,\"price_str\":\"2480.00\",\"is_liquidation\":false},\"channel\":\"live_orders_ethusd\",\"event\":\"order_deleted\",\"event_id\":\"00065a1d-7fb8-2570-0000-001201000020\",\"pre_event_id\":\"00065a1d-7fb7-cf80-0000-001200000020\",\"order_source\":\"orderbook\"}","recorded_unix_us":1787932603629770}
{"message":"{\"data\":{\"id\":2044303888113664,\"id_str\":\"2044303888113664\",\"order_type\":1,\"order_subtype\":5,\"datetime\":\"1787932604\",\"microtimestamp\":\"1787932603591000\",\"amount\":0.06310787,\"amount_str\":\"0.06310787\",\"amount_traded\":\"0\",\"amount_at_create\":\"0.06310787\",\"price\":78522.49,\"price_str\":\"78522.49\",\"is_liquidation\":false},\"channel\":\"live_orders_btcusd\",\"event\":\"order_created\",\"event_id\":\"00065a1d-7fb8-2958-0000-000100000020\",\"pre_event_id\":\"00065a1d-7fb8-15d0-0000-000103000020\",\"order_source\":\"orderbook\"}","recorded_unix_us":1787932603639023}
{"message":"{\"data\":{\"id\":2044303888113664,\"id_str\":\"2044303888113664\",\"order_type\":1,\"order_subtype\":5,\"datetime\":\"1787932604\",\"microtimestamp\":\"1787932603591000\",\"amount\":0.06310787,\"amount_str\":\"0.06310787\",\"amount_traded\":\"0\",\"amount_at_create\":\"0.06310787\",\"price\":78522.49,\"price_str\":\"78522.49\",\"is_liquidation\":false},\"channel\":\"live_orders_btcusd\",\"event\":\"order_deleted\",\"event_id\":\"00065a1d-7fb8-2958-0001-000101000020\",\"pre_event_id\":\"00065a1d-7fb8-2958-0000-000100000020\",\"order_source\":\"orderbook\"}","recorded_unix_us":1787932603639156}
{"message":"{\"data\":{\"id\":2044303863476234,\"id_str\":\"2044303863476234\",\"order_type\":1,\"order_subtype\":5,\"datetime\":\"1787932604\",\"microtimestamp\":\"1787932603592000\",\"amount\":6.044921,\"amount_str\":\"6.044921\",\"amount_traded\":\"0\",\"amount_at_create\":\"6.044921\",\"price\":2481.41,\"price_str\":\"2481.41\",\"is_liquidation\":false},\"channel\":\"live_orders_ethusd\",\"event\":\"order_deleted\",\"event_id\":\"00065a1d-7fb8-2d40-0000-001202000020\",\"pre_event_id\":\"00065a1d-7fb8-2570-0000-001201000020\",\"order_source\":\"orderbook\"}","recorded_unix_us":1787932603639324}
{"message":"{\"data\":{\"id\":2044303888117765,\"id_str\":\"2044303888117765\",\"order_type\":1,\"order_subtype\":5,\"datetime\":\"1787932604\",\"microtimestamp\":\"1787932603593000\",\"amount\":5.000119,\"amount_str\":\"5.000119\",\"amount_traded\":\"0\",\"amount_at_create\":\"5.000119\",\"price\":2482.36,\"price_str\":\"2482.36\",\"is_liquidation\":false},\"channel\":\"live_orders_ethusd\",\"event\":\"order_created\",\"event_id\":\"00065a1d-7fb8-3128-0000-001203000020\",\"pre_event_id\":\"00065a1d-7fb8-2d40-0000-001202000020\",\"order_source\":\"orderbook\"}","recorded_unix_us":1787932603639468}
{"message":"{\"data\":{\"id\":2044303888146434,\"id_str\":\"2044303888146434\",\"order_type\":1,\"order_subtype\":5,\"datetime\":\"1787932604\",\"microtimestamp\":\"1787932603599000\",\"amount\":0.00254647,\"amount_str\":\"0.00254647\",\"amount_traded\":\"0\",\"amount_at_create\":\"0.00254647\",\"price\":78539.99,\"price_str\":\"78539.99\",\"is_liquidation\":false},\"channel\":\"live_orders_btcusd\",\"event\":\"order_created\",\"event_id\":\"00065a1d-7fb8-4898-0000-000102000020\",\"pre_event_id\":\"00065a1d-7fb8-2958-0001-000101000020\",\"order_source\":\"orderbook\"}","recorded_unix_us":1787932603639619}
{"message":"{\"data\":{\"id\":2044303888154624,\"id_str\":\"2044303888154624\",\"order_type\":0,\"order_subtype\":5,\"datetime\":\"1787932604\",\"microtimestamp\":\"1787932603601000\",\"amount\":0.25,\"amount_str\":\"0.25000000\",\"amount_traded\":\"0\",\"amount_at_create\":\"0.25000000\",\"price\":78512.46,\"price_str\":\"78512.46\",\"is_liquidation\":false},\"channel\":\"live_orders_btcusd\",\"event\":\"order_created\",\"event_id\":\"00065a1d-7fb8-5068-0000-000103000020\",\"pre_event_id\":\"00065a1d-7fb8-4898-0000-000102000020\",\"order_source\":\"orderbook\"}","recorded_unix_us":1787932603639760}
{"message":"{\"data\":{\"id\":2044303888154627,\"id_str\":\"2044303888154627\",\"order_type\":0,\"order_subtype\":5,\"datetime\":\"1787932604\",\"microtimestamp\":\"1787932603602000\",\"amount\":0.5,\"amount_str\":\"0.50000000\",\"amount_traded\":\"0\",\"amount_at_create\":\"0.50000000\",\"price\":78508.53,\"price_str\":\"78508.53\",\"is_liquidation\":false},\"channel\":\"live_orders_btcusd\",\"event\":\"order_created\",\"event_id\":\"00065a1d-7fb8-5450-0000-000100000020\",\"pre_event_id\":\"00065a1d-7fb8-5068-0000-000103000020\",\"order_source\":\"orderbook\"}","recorded_unix_us":1787932603648136}
{"message":"{\"data\":{\"id\":2044303888166913,\"id_str\":\"2044303888166913\",\"order_type\":0,\"order_subtype\":5,\"datetime\":\"1787932604\",\"microtimestamp\":\"1787932603604000\",\"amount\":6.044921,\"amount_str\":\"6.044921\",\"amount_traded\":\"0\",\"amount_at_create\":\"6.044921\",\"price\":2480.85,\"price_str\":\"2480.85\",\"is_liquidation\":false},\"channel\":\"live_orders_ethusd\",\"event\":\"order_created\",\"event_id\":\"00065a1d-7fb8-5c20-0000-001200000020\",\"pre_event_id\":\"00065a1d-7fb8-3128-0000-001203000020\",\"order_source\":\"orderbook\"}","recorded_unix_us":1787932603648308}
{"message":"{\"data\":{\"id\":2044303888179209,\"id_str\":\"2044303888179209\",\"order_type\":0,\"order_subtype\":5,\"datetime\":\"1787932604\",\"microtimestamp\":\"1787932603607000\",\"amount\":1.65836603,\"amount_str\":\"1.65836603\",\"amount_traded\":\"0\",\"amount_at_create\":\"1.65836603\",\"price\":0.03020014,\"price_str\":\"0.03020014\",\"is_liquidation\":false},\"channel\":\"live_orders_ethbtc\",\"event\":\"order_created\",\"event_id\":\"00065a1d-7fb8-67d8-0000-001103000020\",\"pre_event_id\":\"00065a1d-7fb7-c7b0-0000-001102000020\",\"order_source\":\"orderbook\"}","recorded_unix_us":1787932603648454}
{"message":"{\"data\":{\"id\":2044303888183302,\"id_str\":\"2044303888183302\",\"order_type\":1,\"order_subtype\":5,\"datetime\":\"1787932604\",\"microtimestamp\":\"1787932603608000\",\"amount\":1.731801,\"amount_str\":\"1.731801\",\"amount_traded\":\"0\",\"amount_at_create\":\"1.731801\",\"price\":2481.41,\"price_str\":\"2481.41\",\"is_liquidation\":false},\"channel\":\"live_orders_ethusd\",\"event\":\"order_created\",\"event_id\":\"00065a1d-7fb8-6bc0-0000-001201000020\",\"pre_event_id\":\"00065a1d-7fb8-5c20-0000-001200000020\",\"order_source\":\"orderbook\"}","recorded_unix_us":1787932603648592}
{"message":"{\"data\":{\"id\":2044303885676549,\"id_str\":\"2044303885676549\",\"order_type\":0,\"order_subtype\":5,\"datetime\":\"1787932604\",\"microtimestamp\":\"1787932603609000\",\"amount\":4.837906,\"amount_str\":\"4.837906\",\"amount_traded\":\"0\",\"amount_at_create\":\"4.837906\",\"price\":2480.51,\"price_str\":\"2480.51\",\"is_liquidation\":false},\"channel\":\"live_orders_ethusd\",\"event\":\"order_deleted\",\"event_id\":\"00065a1d-7fb8-6fa8-0000-001202000020\",\"pre_event_id\":\"00065a1d-7fb8-6bc0-0000-001201000020\",\"order_source\":\"orderbook\"}","recorded_unix_us":1787932603648785}
{"message":"{\"data\":{\"id\":2044303888187393,\"id_str\":\"2044303888187393\",\"order_type\":0,\"order_subtype\":5,\"datetime\":\"1787932604\",\"microtimestamp\":\"1787932603609000\",\"amount\":4.837906,\"amount_str\":\"4.837906\",\"amount_traded\":\"0\",\"amount_at_create\":\"4.837906\",\"price\":2480.51,\"price_str\":\"2480.51\",\"is_liquidation\":false},\"channel\":\"live_orders_ethusd\",\"event\":\"order_created\",\"event_id\":\"00065a1d-7fb8-6fa8-0001-001203000020\",\"pre_event_id\":\"00065a1d-7fb8-6fa8-0000-001202000020\",\"order_source\":\"orderbook\"}","recorded_unix_us":1787932603648829}
{"message":"{\"data\":{\"id\":2044303888187394,\"id_str\":\"2044303888187394\",\"order_type\":1,\"order_subtype\":5,\"datetime\":\"1787932604\",\"microtimestamp\":\"1787932603610000\",\"amount\":1.27145262,\"amount_str\":\"1.27145262\",\"amount_traded\":\"0\",\"amount_at_create\":\"1.27145262\",\"price\":78650.2,\"price_str\":\"78650.20\",\"is_liquidation\":false},\"channel\":\"live_orders_btcusd\",\"event\":\"order_created\",\"event_id\":\"00065a1d-7fb8-7390-0000-000101000020\",\"pre_event_id\":\"00065a1d-7fb8-5450-0000-000100000020\",\"order_source\":\"orderbook\"}","recorded_unix_us":1787932603648956}
{"message":"{\"data\":{\"id\":2044303888199680,\"id_str\":\"2044303888199680\",\"order_type\":0,\"order_subtype\":5,\"datetime\":\"1787932604\",\"microtimestamp\":\"1787932603612000\",\"amount\":1.27888333,\"amount_str\":\"1.27888333\",\"amount_traded\":\"0\",\"amount_at_create\":\"1.27888333\",\"price\":78193.21,\"price_str\":\"78193.21\",\"is_liquidation\":false},\"channel\":\"live_orders_btcusd\",\"event\":\"order_created\",\"event_id\":\"00065a1d-7fb8-7b60-0000-000102000020\",\"pre_event_id\":\"00065a1d-7fb8-7390-0000-000101000020\",\"order_source\":\"orderbook\"}","recorded_unix_us":1787932603649076}
{"message":"{\"data\":{\"id\":2044303888207872,\"id_str\":\"2044303888207872\",\"order_type\":1,\"order_subtype\":5,\"datetime\":\"1787932604\",\"microtimestamp\":\"1787932603615000\",\"amount\":0.1,\"amount_str\":\"0.10000000\",\"amount_traded\":\"0\",\"amount_at_create\":\"0.10000000\",\"price\":78522.62,\"price_str\":\"78522.62\",\"is_liquidation\":false},\"channel\":\"live_orders_btcusd\",\"event\":\"order_created\",\"event_id\":\"00065a1d-7fb8-8718-0000-000103000020\",\"pre_event_id\":\"00065a1d-7fb8-7b60-0000-000102000020\",\"order_source\":\"orderbook\"}","recorded_unix_us":1787932603649200}
{"message":"{\"data\":{\"id\":2044303888207872,\"id_str\":\"2044303888207872\",\"order_type\":1,\"order_subtype\":5,\"datetime\":\"1787932604\",\"microtimestamp\":\"1787932603615000\",\"amount\":0.1,\"amount_str\":\"0.10000000\",\"amount_traded\":\"0\",\"amount_at_create\":\"0.10000000\",\"price\":78522.62,\"price_str\":\"78522.62\",\"is_liquidation\":false},\"channel\":\"live_orders_btcusd\",\"event\":\"order_deleted\",\"event_id\":\"00065a1d-7fb8-8718-0001-000100000020\",\"pre_event_id\":\"00065a1d-7fb8-8718-0000-000103000020\",\"order_source\":\"orderbook\"}","recorded_unix_us":1787932603650308}
{"message":"{\"data\":{\"id\":2044303888216064,\"id_str\":\"2044303888216064\",\"order_type\":0,\"order_subtype\":5,\"datetime\":\"1787932604\",\"microtimestamp\":\"1787932603616000\",\"amount\":0.00254752,\"amount_str\":\"0.00254752\",\"amount_traded\":\"0\",\"amount_at_create\":\"0.00254752\",\"price\":78507.67,\"price_str\":\"78507.67\",\"is_liquidation\":false},\"channel\":\"live_orders_btcusd\",\"event\":\"order_created\",\"event_id\":\"00065a1d-7fb8-8b00-0000-000101000020\",\"pre_event_id\":\"00065a1d-7fb8-8718-0001-000100000020\",\"order_source\":\"orderbook\"}","recorded_unix_us":1787932603662309}
{"message":"{\"data\":{\"id\":2044303888232449,\"id_str\":\"2044303888232449\",\"order_type\":1,\"order_subtype\":5,\"datetime\":\"1787932604\",\"microtimestamp\":\"1787932603620000\",\"amount\":0.1,\"amount_str\":\"0.10000000\",\"amount_traded\":\"0\",\"amount_at_create\":\"0.10000000\",\"price\":78522.63,\"price_str\":\"78522.63\",\"is_liquidation\":false},\"channel\":\"live_orders_btcusd\",\"event\":\"order_created\",\"event_id\":\"00065a1d-7fb8-9aa0-0000-000102000020\",\"pre_event_id\":\"00065a1d-7fb8-8b00-0000-000101000020\",\"order_source\":\"orderbook\"}","recorded_unix_us":1787932603662533}
{"message":"{\"data\":{\"id\":2044303888232449,\"id_str\":\"2044303888232449\",\"order_type\":1,\"order_subtype\":5,\"datetime\":\"1787932604\",\"microtimestamp\":\"1787932603620000\",\"amount\":0.1,\"amount_str\":\"0.10000000\",\"amount_traded\":\"0\",\"amount_at_create\":\"0.10000000\",\"price\":78522.63,\"price_str\":\"78522.63\",\"is_liquidation\":false},\"channel\":\"live_orders_btcusd\",\"event\":\"order_deleted\",\"event_id\":\"00065a1d-7fb8-9aa0-0001-000103000020\",\"pre_event_id\":\"00065a1d-7fb8-9aa0-0000-000102000020\",\"order_source\":\"orderbook\"}","recorded_unix_us":1787932603662711}
{"message":"{\"data\":{\"id\":2044303888265220,\"id_str\":\"2044303888265220\",\"order_type\":1,\"order_subtype\":5,\"datetime\":\"1787932604\",\"microtimestamp\":\"1787932603629000\",\"amount\":0.06310787,\"amount_str\":\"0.06310787\",\"amount_traded\":\"0\",\"amount_at_create\":\"0.06310787\",\"price\":78521.28,\"price_str\":\"78521.28\",\"is_liquidation\":false},\"channel\":\"live_orders_btcusd\",\"event\":\"order_created\",\"event_id\":\"00065a1d-7fb8-bdc8-0000-000100000020\",\"pre_event_id\":\"00065a1d-7fb8-9aa0-0001-000103000020\",\"order_source\":\"orderbook\"}","recorded_unix_us":1787932603665804}
{"message":"{\"data\":{\"id\":2044303888265220,\"id_str\":\"2044303888265220\",\"order_type\":1,\"order_subtype\":5,\"datetime\":\"1787932604\",\"microtimestamp\":\"1787932603629000\",\"amount\":0.06310787,\"amount_str\":\"0.06310787\",\"amount_traded\":\"0\",\"amount_at_create\":\"0.06310787\",\"price\":78521.28,\"price_str\":\"78521.28\",\"is_liquidation\":false},\"channel\":\"live_orders_btcusd\",\"event\":\"order_deleted\",\"event_id\":\"00065a1d-7fb8-bdc8-0001-000101000020\",\"pre_event_id\":\"00065a1d-7fb8-bdc8-0000-000100000020\",\"order_source\":\"orderbook\"}","recorded_unix_us":1787932603665881}
{"message":"{\"data\":{\"id\":2044303887933447,\"id_str\":\"2044303887933447\",\"order_type\":0,\"order_subtype\":5,\"datetime\":\"1787932604\",\"microtimestamp\":\"1787932603642000\",\"amount\":0.214551,\"amount_str\":\"0.214551\",\"amount_traded\":\"0\",\"amount_at_create\":\"0.214551\",\"price\":2480.51,\"price_str\":\"2480.51\",\"is_liquidation\":false},\"channel\":\"live_orders_ethusd\",\"event\":\"order_deleted\",\"event_id\":\"00065a1d-7fb8-f090-0000-001200000020\",\"pre_event_id\":\"00065a1d-7fb8-6fa8-0001-001203000020\",\"order_source\":\"orderbook\"}","recorded_unix_us":1787932603683901}
{"message":"{\"data\":{\"id\":2044303888330752,\"id_str\":\"2044303888330752\",\"order_type\":1,\"order_subtype\":5,\"datetime\":\"1787932604\",\"microtimestamp\":\"1787932603646000\",\"amount\":0.1,\"amount_str\":\"0.10000000\",\"amount_traded\":\"0\",\"amount_at_create\":\"0.10000000\",\"price\":78522.62,\"price_str\":\"78522.62\",\"is_liquidation\":false},\"channel\":\"live_orders_btcusd\",\"event\":\"order_created\",\"event_id\":\"00065a1d-7fb9-0030-0000-000102000020\",\"pre_event_id\":\"00065a1d-7fb8-bdc8-0001-000101000020\",\"order_source\":\"orderbook\"}","recorded_unix_us":1787932603684108}
{"message":"{\"data\":{\"id\":2044303888330752,\"id_str\":\"2044303888330752\",\"order_type\":1,\"order_subtype\":5,\"datetime\":\"1787932604\",\"microtimestamp\":\"1787932603646000\",\"amount\":0.1,\"amount_str\":\"0.10000000\",\"amount_traded\":\"0\",\"amount_at_create\":\"0.10000000\",\"price\":78522.62,\"price_str\":\"78522.62\",\"is_liquidation\":false},\"channel\":\"live_orders_btcusd\",\"event\":\"order_deleted\",\"event_id\":\"00065a1d-7fb9-0030-0001-000103000020\",\"pre_event_id\":\"00065a1d-7fb9-0030-0000-000102000020\",\"order_source\":\"orderbook\"}","recorded_unix_us":1787932603684261}
{"message":"{\"data\":{\"id\":2044303888338953,\"id_str\":\"2044303888338953\",\"order_type\":1,\"order_subtype\":5,\"datetime\":\"1787932604\",\"microtimestamp\":\"1787932603647000\",\"amount\":12.086989,\"amount_str\":\"12.086989\",\"amount_traded\":\"0\",\"amount_at_create\":\"12.086989\",\"price\":2482.01,\"price_str\":\"2482.01\",\"is_liquidation\":false},\"channel\":\"live_orders_ethusd\",\"event\":\"order_created\",\"event_id\":\"00065a1d-7fb9-0418-0000-001201000020\",\"pre_event_id\":\"00065a1d-7fb8-f090-0000-001200000020\",\"order_source\":\"orderbook\"}","recorded_unix_us":1787932603691490}
{"message":"{\"data\":{\"id\":2044303888343060,\"id_str\":\"2044303888343060\",\"order_type\":1,\"order_subtype\":5,\"datetime\":\"1787932604\",\"microtimestamp\":\"1787932603648000\",\"amount\":12.085668,\"amount_str\":\"12.085668\",\"amount_traded\":\"0\",\"amount_at_create\":\"12.085668\",\"price\":2482.28,\"price_str\":\"2482.28\",\"is_liquidation\":false},\"channel\":\"live_orders_ethusd\",\"event\":\"order_created\",\"event_id\":\"00065a1d-7fb9-0800-0000-001202000020\",\"pre_event_id\":\"00065a1d-7fb9-0418-0000-001201000020\",\"order_source\":\"orderbook\"}","recorded_unix_us":1787932603691690}
{"message":"{\"data\":{\"id\":2044303888347140,\"id_str\":\"2044303888347140\",\"order_type\":1,\"order_subtype\":5,\"datetime\":\"1787932604\",\"microtimestamp\":\"1787932603648000\",\"amount\":4.027018,\"amount_str\":\"4.027018\",\"amount_traded\":\"0\",\"amount_at_create\":\"4.027018\",\"price\":2483.23,\"price_str\":\"2483.23\",\"is_liquidation\":false},\"channel\":\"live_orders_ethusd\",\"event\":\"order_created\",\"event_id\":\"00065a1d-7fb9-0800-0001-001203000020\",\"pre_event_id\":\"00065a1d-7fb9-0800-0000-001202000020\",\"order_source\":\"orderbook\"}","recorded_unix_us":1787932603691901}
{"message":"{\"data\":{\"id\":2044303888351233,\"id_str\":\"2044303888351233\",\"order_type\":1,\"order_subtype\":5,\"datetime\":\"1787932604\",\"microtimestamp\":\"1787932603649000\",\"amount\":4.028003,\"amount_str\":\"4.028003\",\"amount_traded\":\"0\",\"amount_at_create\":\"4.028003\",\"price\":2482.62,\"price_str\":\"2482.62\",\"is_liquidation\":false},\"channel\":\"live_orders_ethusd\",\"event\":\"order_created\",\"event_id\":\"00065a1d-7fb9-0be8-0000-001200000020\",\"pre_event_id\":\"00065a1d-7fb9-0800-0001-001203000020\",\"order_source\":\"orderbook\"}","recorded_unix_us":1787932603691945}
